{
  "version": 8,
  "blockIdVersion": 11,
  "anchorX": 0,
  "anchorY": 0,
  "anchorZ": 0,
  "blocks": [
    {
      "x": -10,
      "y": 18,
      "z": 1,
      "name": "Rock_Chalk",
      "rotation": 3
    },
    {
      "x": -10,
      "y": 19,
      "z": 1,
      "name": "Soil_Dirt_White",
      "rotation": 3
    },
    {
      "x": -10,
      "y": 20,
      "z": 1,
      "name": "Soil_Grass_Full",
      "rotation": 3
    },
    {
      "x": -10,
      "y": 18,
      "z": 2,
      "name": "Rock_Chalk",
      "rotation": 3
    },
    {
      "x": -10,
      "y": 19,
      "z": 2,
      "name": "Rock_Chalk",
      "rotation": 3
    },
    {
      "x": -10,
      "y": 20,
      "z": 2,
      "name": "Soil_Dirt_White"
    },
    {
      "x": -10,
      "y": 21,
      "z": 2,
      "name": "Soil_Grass_Full"
    },
    {
      "x": -10,
      "y": 18,
      "z": 3,
      "name": "Rock_Chalk",
      "rotation": 3
    },
    {
      "x": -10,
      "y": 19,
      "z": 3,
      "name": "Soil_Dirt_White",
      "rotation": 3
    },
    {
      "x": -10,
      "y": 20,
      "z": 3,
      "name": "Soil_Grass_Full",
      "rotation": 3
    },
    {
      "x": -9,
      "y": 17,
      "z": -1,
      "name": "Rock_Chalk",
      "rotation": 3
    },
    {
      "x": -9,
      "y": 18,
      "z": -1,
      "name": "Rock_Chalk",
      "rotation": 3
    },
    {
      "x": -9,
      "y": 19,
      "z": -1,
      "name": "Rock_Chalk",
      "rotation": 3
    },
    {
      "x": -9,
      "y": 20,
      "z": -1,
      "name": "Soil_Dirt_White",
      "rotation": 3
    },
    {
      "x": -9,
      "y": 21,
      "z": -1,
      "name": "Soil_Grass_Full"
    },
    {
      "x": -9,
      "y": 16,
      "z": 0,
      "name": "Rock_Chalk",
      "rotation": 3
    },
    {
      "x": -9,
      "y": 17,
      "z": 0,
      "name": "Rock_Chalk",
      "rotation": 3
    },
    {
      "x": -9,
      "y": 18,
      "z": 0,
      "name": "Rock_Chalk",
      "rotation": 3
    },
    {
      "x": -9,
      "y": 19,
      "z": 0,
      "name": "Rock_Chalk",
      "rotation": 3
    },
    {
      "x": -9,
      "y": 20,
      "z": 0,
      "name": "Soil_Dirt_White"
    },
    {
      "x": -9,
      "y": 21,
      "z": 0,
      "name": "Soil_Grass_Full"
    },
    {
      "x": -9,
      "y": 15,
      "z": 1,
      "name": "Rock_Chalk",
      "rotation": 3
    },
    {
      "x": -9,
      "y": 16,
      "z": 1,
      "name": "Rock_Chalk",
      "rotation": 3
    },
    {
      "x": -9,
      "y": 17,
      "z": 1,
      "name": "Rock_Chalk",
      "rotation": 3
    },
    {
      "x": -9,
      "y": 18,
      "z": 1,
      "name": "Rock_Chalk",
      "rotation": 3
    },
    {
      "x": -9,
      "y": 19,
      "z": 1,
      "name": "Rock_Chalk",
      "rotation": 3
    },
    {
      "x": -9,
      "y": 20,
      "z": 1,
      "name": "Soil_Dirt_White"
    },
    {
      "x": -9,
      "y": 21,
      "z": 1,
      "name": "Rock_Chalk"
    },
    {
      "x": -9,
      "y": 15,
      "z": 2,
      "name": "Rock_Chalk",
      "rotation": 3
    },
    {
      "x": -9,
      "y": 16,
      "z": 2,
      "name": "Rock_Chalk",
      "rotation": 3
    },
    {
      "x": -9,
      "y": 17,
      "z": 2,
      "name": "Rock_Chalk",
      "rotation": 3
    },
    {
      "x": -9,
      "y": 18,
      "z": 2,
      "name": "Rock_Chalk",
      "rotation": 3
    },
    {
      "x": -9,
      "y": 19,
      "z": 2,
      "name": "Rock_Chalk"
    },
    {
      "x": -9,
      "y": 20,
      "z": 2,
      "name": "Soil_Dirt_White"
    },
    {
      "x": -9,
      "y": 21,
      "z": 2,
      "name": "Rock_Chalk"
    },
    {
      "x": -9,
      "y": 15,
      "z": 3,
      "name": "Rock_Chalk",
      "rotation": 3
    },
    {
      "x": -9,
      "y": 16,
      "z": 3,
      "name": "Rock_Chalk",
      "rotation": 3
    },
    {
      "x": -9,
      "y": 17,
      "z": 3,
      "name": "Rock_Chalk",
      "rotation": 3
    },
    {
      "x": -9,
      "y": 18,
      "z": 3,
      "name": "Rock_Chalk",
      "rotation": 3
    },
    {
      "x": -9,
      "y": 19,
      "z": 3,
      "name": "Rock_Chalk",
      "rotation": 3
    },
    {
      "x": -9,
      "y": 20,
      "z": 3,
      "name": "Soil_Dirt_White"
    },
    {
      "x": -9,
      "y": 21,
      "z": 3,
      "name": "Soil_Grass_Full"
    },
    {
      "x": -9,
      "y": 17,
      "z": 4,
      "name": "Rock_Chalk",
      "rotation": 3
    },
    {
      "x": -9,
      "y": 18,
      "z": 4,
      "name": "Rock_Chalk",
      "rotation": 3
    },
    {
      "x": -9,
      "y": 19,
      "z": 4,
      "name": "Soil_Dirt_White",
      "rotation": 3
    },
    {
      "x": -9,
      "y": 20,
      "z": 4,
      "name": "Soil_Grass_Full",
      "rotation": 3
    },
    {
      "x": -9,
      "y": 17,
      "z": 5,
      "name": "Rock_Chalk",
      "rotation": 3
    },
    {
      "x": -9,
      "y": 18,
      "z": 5,
      "name": "Rock_Chalk",
      "rotation": 3
    },
    {
      "x": -8,
      "y": 19,
      "z": -3,
      "name": "Soil_Dirt_White",
      "rotation": 3
    },
    {
      "x": -8,
      "y": 20,
      "z": -3,
      "name": "Soil_Grass_Full",
      "rotation": 3
    },
    {
      "x": -8,
      "y": 17,
      "z": -2,
      "name": "Rock_Chalk",
      "rotation": 3
    },
    {
      "x": -8,
      "y": 18,
      "z": -2,
      "name": "Rock_Chalk",
      "rotation": 3
    },
    {
      "x": -8,
      "y": 19,
      "z": -2,
      "name": "Soil_Dirt_White",
      "rotation": 3
    },
    {
      "x": -8,
      "y": 20,
      "z": -2,
      "name": "Soil_Grass_Full",
      "rotation": 3
    },
    {
      "x": -8,
      "y": 15,
      "z": -1,
      "name": "Rock_Chalk",
      "rotation": 3
    },
    {
      "x": -8,
      "y": 16,
      "z": -1,
      "name": "Rock_Chalk",
      "rotation": 3
    },
    {
      "x": -8,
      "y": 17,
      "z": -1,
      "name": "Rock_Chalk",
      "rotation": 3
    },
    {
      "x": -8,
      "y": 18,
      "z": -1,
      "name": "Rock_Chalk",
      "rotation": 3
    },
    {
      "x": -8,
      "y": 19,
      "z": -1,
      "name": "Rock_Chalk",
      "rotation": 3
    },
    {
      "x": -8,
      "y": 20,
      "z": -1,
      "name": "Soil_Dirt_White"
    },
    {
      "x": -8,
      "y": 21,
      "z": -1,
      "name": "Soil_Grass_Full"
    },
    {
      "x": -8,
      "y": 15,
      "z": 0,
      "name": "Rock_Chalk",
      "rotation": 3
    },
    {
      "x": -8,
      "y": 16,
      "z": 0,
      "name": "Rock_Chalk",
      "rotation": 3
    },
    {
      "x": -8,
      "y": 17,
      "z": 0,
      "name": "Rock_Chalk",
      "rotation": 3
    },
    {
      "x": -8,
      "y": 18,
      "z": 0,
      "name": "Rock_Chalk",
      "rotation": 3
    },
    {
      "x": -8,
      "y": 19,
      "z": 0,
      "name": "Rock_Chalk"
    },
    {
      "x": -8,
      "y": 20,
      "z": 0,
      "name": "Soil_Dirt_White"
    },
    {
      "x": -8,
      "y": 21,
      "z": 0,
      "name": "Rock_Chalk"
    },
    {
      "x": -8,
      "y": 41,
      "z": 0,
      "name": "Rock_Marble_Brick_Smooth"
    },
    {
      "x": -8,
      "y": 15,
      "z": 1,
      "name": "Rock_Chalk",
      "rotation": 3
    },
    {
      "x": -8,
      "y": 16,
      "z": 1,
      "name": "Rock_Chalk",
      "rotation": 3
    },
    {
      "x": -8,
      "y": 17,
      "z": 1,
      "name": "Rock_Chalk",
      "rotation": 3
    },
    {
      "x": -8,
      "y": 18,
      "z": 1,
      "name": "Rock_Chalk",
      "rotation": 3
    },
    {
      "x": -8,
      "y": 19,
      "z": 1,
      "name": "Rock_Chalk"
    },
    {
      "x": -8,
      "y": 20,
      "z": 1,
      "name": "Rock_Chalk"
    },
    {
      "x": -8,
      "y": 21,
      "z": 1,
      "name": "Rock_Chalk"
    },
    {
      "x": -8,
      "y": 22,
      "z": 1,
      "name": "Rock_Marble_Brick"
    },
    {
      "x": -8,
      "y": 23,
      "z": 1,
      "name": "Rock_Marble_Brick"
    },
    {
      "x": -8,
      "y": 41,
      "z": 1,
      "name": "Rock_Marble_Brick_Smooth"
    },
    {
      "x": -8,
      "y": 15,
      "z": 2,
      "name": "Rock_Chalk",
      "rotation": 3
    },
    {
      "x": -8,
      "y": 16,
      "z": 2,
      "name": "Rock_Chalk",
      "rotation": 3
    },
    {
      "x": -8,
      "y": 17,
      "z": 2,
      "name": "Rock_Chalk",
      "rotation": 3
    },
    {
      "x": -8,
      "y": 18,
      "z": 2,
      "name": "Rock_Chalk",
      "rotation": 3
    },
    {
      "x": -8,
      "y": 19,
      "z": 2,
      "name": "Rock_Chalk"
    },
    {
      "x": -8,
      "y": 20,
      "z": 2,
      "name": "Rock_Chalk"
    },
    {
      "x": -8,
      "y": 21,
      "z": 2,
      "name": "Rock_Chalk"
    },
    {
      "x": -8,
      "y": 22,
      "z": 2,
      "name": "Rock_Marble_Brick"
    },
    {
      "x": -8,
      "y": 23,
      "z": 2,
      "name": "Rock_Marble_Brick"
    },
    {
      "x": -8,
      "y": 15,
      "z": 3,
      "name": "Rock_Chalk",
      "rotation": 3
    },
    {
      "x": -8,
      "y": 16,
      "z": 3,
      "name": "Rock_Chalk",
      "rotation": 3
    },
    {
      "x": -8,
      "y": 17,
      "z": 3,
      "name": "Rock_Chalk",
      "rotation": 3
    },
    {
      "x": -8,
      "y": 18,
      "z": 3,
      "name": "Rock_Chalk",
      "rotation": 3
    },
    {
      "x": -8,
      "y": 19,
      "z": 3,
      "name": "Rock_Chalk"
    },
    {
      "x": -8,
      "y": 20,
      "z": 3,
      "name": "Soil_Dirt_White"
    },
    {
      "x": -8,
      "y": 21,
      "z": 3,
      "name": "Soil_Grass_Full"
    },
    {
      "x": -8,
      "y": 16,
      "z": 4,
      "name": "Rock_Chalk",
      "rotation": 3
    },
    {
      "x": -8,
      "y": 17,
      "z": 4,
      "name": "Rock_Chalk",
      "rotation": 3
    },
    {
      "x": -8,
      "y": 18,
      "z": 4,
      "name": "Rock_Chalk",
      "rotation": 3
    },
    {
      "x": -8,
      "y": 19,
      "z": 4,
      "name": "Soil_Dirt_White"
    },
    {
      "x": -8,
      "y": 20,
      "z": 4,
      "name": "Soil_Grass_Full"
    },
    {
      "x": -8,
      "y": 17,
      "z": 5,
      "name": "Rock_Chalk",
      "rotation": 3
    },
    {
      "x": -8,
      "y": 18,
      "z": 5,
      "name": "Rock_Chalk",
      "rotation": 3
    },
    {
      "x": -8,
      "y": 19,
      "z": 5,
      "name": "Soil_Dirt_White",
      "rotation": 3
    },
    {
      "x": -8,
      "y": 20,
      "z": 5,
      "name": "Soil_Grass_Full"
    },
    {
      "x": -7,
      "y": 19,
      "z": -4,
      "name": "Soil_Dirt_White",
      "rotation": 3
    },
    {
      "x": -7,
      "y": 20,
      "z": -4,
      "name": "Soil_Grass_Full",
      "rotation": 3
    },
    {
      "x": -7,
      "y": 17,
      "z": -3,
      "name": "Rock_Chalk",
      "rotation": 3
    },
    {
      "x": -7,
      "y": 18,
      "z": -3,
      "name": "Rock_Chalk",
      "rotation": 3
    },
    {
      "x": -7,
      "y": 19,
      "z": -3,
      "name": "Soil_Dirt_White",
      "rotation": 3
    },
    {
      "x": -7,
      "y": 20,
      "z": -3,
      "name": "Soil_Grass_Full",
      "rotation": 3
    },
    {
      "x": -7,
      "y": 15,
      "z": -2,
      "name": "Rock_Chalk",
      "rotation": 3
    },
    {
      "x": -7,
      "y": 16,
      "z": -2,
      "name": "Rock_Chalk",
      "rotation": 3
    },
    {
      "x": -7,
      "y": 17,
      "z": -2,
      "name": "Rock_Chalk",
      "rotation": 3
    },
    {
      "x": -7,
      "y": 18,
      "z": -2,
      "name": "Rock_Chalk",
      "rotation": 3
    },
    {
      "x": -7,
      "y": 19,
      "z": -2,
      "name": "Soil_Dirt_White",
      "rotation": 3
    },
    {
      "x": -7,
      "y": 20,
      "z": -2,
      "name": "Soil_Grass_Full"
    },
    {
      "x": -7,
      "y": 14,
      "z": -1,
      "name": "Rock_Chalk",
      "rotation": 3
    },
    {
      "x": -7,
      "y": 15,
      "z": -1,
      "name": "Rock_Chalk",
      "rotation": 3
    },
    {
      "x": -7,
      "y": 16,
      "z": -1,
      "name": "Rock_Chalk",
      "rotation": 3
    },
    {
      "x": -7,
      "y": 17,
      "z": -1,
      "name": "Rock_Chalk",
      "rotation": 3
    },
    {
      "x": -7,
      "y": 18,
      "z": -1,
      "name": "Rock_Chalk",
      "rotation": 3
    },
    {
      "x": -7,
      "y": 19,
      "z": -1,
      "name": "Soil_Dirt_White"
    },
    {
      "x": -7,
      "y": 20,
      "z": -1,
      "name": "Soil_Grass_Full"
    },
    {
      "x": -7,
      "y": 14,
      "z": 0,
      "name": "Rock_Chalk",
      "rotation": 3
    },
    {
      "x": -7,
      "y": 15,
      "z": 0,
      "name": "Rock_Chalk",
      "rotation": 3
    },
    {
      "x": -7,
      "y": 16,
      "z": 0,
      "name": "Rock_Chalk",
      "rotation": 3
    },
    {
      "x": -7,
      "y": 17,
      "z": 0,
      "name": "Rock_Chalk",
      "rotation": 3
    },
    {
      "x": -7,
      "y": 18,
      "z": 0,
      "name": "Rock_Chalk",
      "rotation": 3
    },
    {
      "x": -7,
      "y": 19,
      "z": 0,
      "name": "Rock_Chalk"
    },
    {
      "x": -7,
      "y": 20,
      "z": 0,
      "name": "Rock_Chalk"
    },
    {
      "x": -7,
      "y": 21,
      "z": 0,
      "name": "Rock_Chalk"
    },
    {
      "x": -7,
      "y": 22,
      "z": 0,
      "name": "Rock_Marble_Brick"
    },
    {
      "x": -7,
      "y": 23,
      "z": 0,
      "name": "Rock_Marble_Brick"
    },
    {
      "x": -7,
      "y": 40,
      "z": 0,
      "name": "Rock_Marble_Brick_Smooth"
    },
    {
      "x": -7,
      "y": 41,
      "z": 0,
      "name": "Rock_Marble_Brick_Smooth"
    },
    {
      "x": -7,
      "y": 14,
      "z": 1,
      "name": "Rock_Chalk",
      "rotation": 3
    },
    {
      "x": -7,
      "y": 15,
      "z": 1,
      "name": "Rock_Chalk",
      "rotation": 3
    },
    {
      "x": -7,
      "y": 16,
      "z": 1,
      "name": "Rock_Chalk",
      "rotation": 3
    },
    {
      "x": -7,
      "y": 17,
      "z": 1,
      "name": "Rock_Chalk",
      "rotation": 3
    },
    {
      "x": -7,
      "y": 18,
      "z": 1,
      "name": "Rock_Chalk",
      "rotation": 3
    },
    {
      "x": -7,
      "y": 19,
      "z": 1,
      "name": "Rock_Chalk"
    },
    {
      "x": -7,
      "y": 20,
      "z": 1,
      "name": "Rock_Chalk"
    },
    {
      "x": -7,
      "y": 21,
      "z": 1,
      "name": "Rock_Chalk"
    },
    {
      "x": -7,
      "y": 22,
      "z": 1,
      "name": "Rock_Marble_Brick"
    },
    {
      "x": -7,
      "y": 23,
      "z": 1,
      "name": "Rock_Marble_Brick"
    },
    {
      "x": -7,
      "y": 24,
      "z": 1,
      "name": "Rock_Chalk"
    },
    {
      "x": -7,
      "y": 25,
      "z": 1,
      "name": "Rock_Chalk"
    },
    {
      "x": -7,
      "y": 40,
      "z": 1,
      "name": "Rock_Marble_Brick_Smooth"
    },
    {
      "x": -7,
      "y": 41,
      "z": 1,
      "name": "Rock_Marble_Brick_Smooth"
    },
    {
      "x": -7,
      "y": 14,
      "z": 2,
      "name": "Rock_Chalk",
      "rotation": 3
    },
    {
      "x": -7,
      "y": 15,
      "z": 2,
      "name": "Rock_Chalk",
      "rotation": 3
    },
    {
      "x": -7,
      "y": 16,
      "z": 2,
      "name": "Rock_Chalk",
      "rotation": 3
    },
    {
      "x": -7,
      "y": 17,
      "z": 2,
      "name": "Rock_Chalk",
      "rotation": 3
    },
    {
      "x": -7,
      "y": 18,
      "z": 2,
      "name": "Rock_Chalk"
    },
    {
      "x": -7,
      "y": 19,
      "z": 2,
      "name": "Soil_Dirt_White"
    },
    {
      "x": -7,
      "y": 20,
      "z": 2,
      "name": "Soil_Dirt_White"
    },
    {
      "x": -7,
      "y": 21,
      "z": 2,
      "name": "Rock_Marble_Brick"
    },
    {
      "x": -7,
      "y": 22,
      "z": 2,
      "name": "Rock_Marble_Brick"
    },
    {
      "x": -7,
      "y": 23,
      "z": 2,
      "name": "Rock_Marble_Brick"
    },
    {
      "x": -7,
      "y": 24,
      "z": 2,
      "name": "Rock_Chalk"
    },
    {
      "x": -7,
      "y": 25,
      "z": 2,
      "name": "Rock_Chalk"
    },
    {
      "x": -7,
      "y": 14,
      "z": 3,
      "name": "Rock_Chalk",
      "rotation": 3
    },
    {
      "x": -7,
      "y": 15,
      "z": 3,
      "name": "Rock_Chalk",
      "rotation": 3
    },
    {
      "x": -7,
      "y": 16,
      "z": 3,
      "name": "Rock_Chalk",
      "rotation": 3
    },
    {
      "x": -7,
      "y": 17,
      "z": 3,
      "name": "Rock_Chalk",
      "rotation": 3
    },
    {
      "x": -7,
      "y": 18,
      "z": 3,
      "name": "Rock_Chalk",
      "rotation": 3
    },
    {
      "x": -7,
      "y": 19,
      "z": 3,
      "name": "Soil_Dirt_White"
    },
    {
      "x": -7,
      "y": 20,
      "z": 3,
      "name": "Rock_Chalk"
    },
    {
      "x": -7,
      "y": 21,
      "z": 3,
      "name": "Soil_Dirt_White"
    },
    {
      "x": -7,
      "y": 22,
      "z": 3,
      "name": "Soil_Grass_Full"
    },
    {
      "x": -7,
      "y": 14,
      "z": 4,
      "name": "Rock_Chalk",
      "rotation": 3
    },
    {
      "x": -7,
      "y": 15,
      "z": 4,
      "name": "Rock_Chalk",
      "rotation": 3
    },
    {
      "x": -7,
      "y": 16,
      "z": 4,
      "name": "Rock_Chalk",
      "rotation": 3
    },
    {
      "x": -7,
      "y": 17,
      "z": 4,
      "name": "Rock_Chalk",
      "rotation": 3
    },
    {
      "x": -7,
      "y": 18,
      "z": 4,
      "name": "Rock_Chalk"
    },
    {
      "x": -7,
      "y": 19,
      "z": 4,
      "name": "Soil_Dirt_White"
    },
    {
      "x": -7,
      "y": 20,
      "z": 4,
      "name": "Soil_Grass_Full"
    },
    {
      "x": -7,
      "y": 15,
      "z": 5,
      "name": "Rock_Chalk",
      "rotation": 3
    },
    {
      "x": -7,
      "y": 16,
      "z": 5,
      "name": "Rock_Chalk",
      "rotation": 3
    },
    {
      "x": -7,
      "y": 17,
      "z": 5,
      "name": "Rock_Chalk",
      "rotation": 3
    },
    {
      "x": -7,
      "y": 18,
      "z": 5,
      "name": "Soil_Dirt_White",
      "rotation": 3
    },
    {
      "x": -7,
      "y": 19,
      "z": 5,
      "name": "Soil_Grass_Full"
    },
    {
      "x": -7,
      "y": 16,
      "z": 6,
      "name": "Rock_Chalk",
      "rotation": 3
    },
    {
      "x": -7,
      "y": 17,
      "z": 6,
      "name": "Rock_Chalk",
      "rotation": 3
    },
    {
      "x": -7,
      "y": 18,
      "z": 6,
      "name": "Rock_Chalk",
      "rotation": 3
    },
    {
      "x": -7,
      "y": 19,
      "z": 6,
      "name": "Soil_Grass_Full",
      "rotation": 3
    },
    {
      "x": -6,
      "y": 17,
      "z": -4,
      "name": "Rock_Chalk",
      "rotation": 3
    },
    {
      "x": -6,
      "y": 18,
      "z": -4,
      "name": "Rock_Chalk",
      "rotation": 3
    },
    {
      "x": -6,
      "y": 19,
      "z": -4,
      "name": "Soil_Dirt_White",
      "rotation": 3
    },
    {
      "x": -6,
      "y": 20,
      "z": -4,
      "name": "Soil_Grass_Full",
      "rotation": 3
    },
    {
      "x": -6,
      "y": 15,
      "z": -3,
      "name": "Rock_Chalk",
      "rotation": 3
    },
    {
      "x": -6,
      "y": 16,
      "z": -3,
      "name": "Rock_Chalk",
      "rotation": 3
    },
    {
      "x": -6,
      "y": 17,
      "z": -3,
      "name": "Rock_Chalk",
      "rotation": 3
    },
    {
      "x": -6,
      "y": 18,
      "z": -3,
      "name": "Rock_Chalk",
      "rotation": 3
    },
    {
      "x": -6,
      "y": 19,
      "z": -3,
      "name": "Soil_Dirt_White",
      "rotation": 3
    },
    {
      "x": -6,
      "y": 20,
      "z": -3,
      "name": "Soil_Grass_Full",
      "rotation": 3
    },
    {
      "x": -6,
      "y": 14,
      "z": -2,
      "name": "Rock_Chalk",
      "rotation": 3
    },
    {
      "x": -6,
      "y": 15,
      "z": -2,
      "name": "Rock_Chalk",
      "rotation": 3
    },
    {
      "x": -6,
      "y": 16,
      "z": -2,
      "name": "Rock_Chalk",
      "rotation": 3
    },
    {
      "x": -6,
      "y": 17,
      "z": -2,
      "name": "Rock_Chalk",
      "rotation": 3
    },
    {
      "x": -6,
      "y": 18,
      "z": -2,
      "name": "Rock_Chalk",
      "rotation": 3
    },
    {
      "x": -6,
      "y": 19,
      "z": -2,
      "name": "Soil_Dirt_White",
      "rotation": 3
    },
    {
      "x": -6,
      "y": 20,
      "z": -2,
      "name": "Soil_Grass_Full",
      "rotation": 3
    },
    {
      "x": -6,
      "y": 14,
      "z": -1,
      "name": "Rock_Chalk",
      "rotation": 3
    },
    {
      "x": -6,
      "y": 15,
      "z": -1,
      "name": "Rock_Chalk",
      "rotation": 3
    },
    {
      "x": -6,
      "y": 16,
      "z": -1,
      "name": "Rock_Chalk",
      "rotation": 3
    },
    {
      "x": -6,
      "y": 17,
      "z": -1,
      "name": "Rock_Chalk",
      "rotation": 3
    },
    {
      "x": -6,
      "y": 18,
      "z": -1,
      "name": "Rock_Chalk",
      "rotation": 3
    },
    {
      "x": -6,
      "y": 19,
      "z": -1,
      "name": "Rock_Chalk",
      "rotation": 3
    },
    {
      "x": -6,
      "y": 20,
      "z": -1,
      "name": "Rock_Chalk"
    },
    {
      "x": -6,
      "y": 21,
      "z": -1,
      "name": "Rock_Marble_Brick"
    },
    {
      "x": -6,
      "y": 22,
      "z": -1,
      "name": "Rock_Marble_Brick"
    },
    {
      "x": -6,
      "y": 23,
      "z": -1,
      "name": "Rock_Marble_Brick"
    },
    {
      "x": -6,
      "y": 41,
      "z": -1,
      "name": "Rock_Marble_Brick_Smooth"
    },
    {
      "x": -6,
      "y": 42,
      "z": -1,
      "name": "Rock_Marble_Brick_Wall"
    },
    {
      "x": -6,
      "y": 13,
      "z": 0,
      "name": "Rock_Chalk",
      "rotation": 3
    },
    {
      "x": -6,
      "y": 14,
      "z": 0,
      "name": "Rock_Chalk",
      "rotation": 3
    },
    {
      "x": -6,
      "y": 15,
      "z": 0,
      "name": "Rock_Chalk",
      "rotation": 3
    },
    {
      "x": -6,
      "y": 16,
      "z": 0,
      "name": "Rock_Chalk",
      "rotation": 3
    },
    {
      "x": -6,
      "y": 17,
      "z": 0,
      "name": "Rock_Chalk",
      "rotation": 3
    },
    {
      "x": -6,
      "y": 18,
      "z": 0,
      "name": "Rock_Chalk",
      "rotation": 3
    },
    {
      "x": -6,
      "y": 19,
      "z": 0,
      "name": "Rock_Chalk"
    },
    {
      "x": -6,
      "y": 20,
      "z": 0,
      "name": "Rock_Chalk"
    },
    {
      "x": -6,
      "y": 21,
      "z": 0,
      "name": "Rock_Marble_Brick"
    },
    {
      "x": -6,
      "y": 22,
      "z": 0,
      "name": "Rock_Marble_Brick"
    },
    {
      "x": -6,
      "y": 23,
      "z": 0,
      "name": "Rock_Marble_Brick"
    },
    {
      "x": -6,
      "y": 24,
      "z": 0,
      "name": "Rock_Chalk"
    },
    {
      "x": -6,
      "y": 40,
      "z": 0,
      "name": "Rock_Marble_Brick_Smooth"
    },
    {
      "x": -6,
      "y": 41,
      "z": 0,
      "name": "Rock_Marble_Brick_Smooth"
    },
    {
      "x": -6,
      "y": 13,
      "z": 1,
      "name": "Rock_Chalk",
      "rotation": 3
    },
    {
      "x": -6,
      "y": 14,
      "z": 1,
      "name": "Rock_Chalk",
      "rotation": 3
    },
    {
      "x": -6,
      "y": 15,
      "z": 1,
      "name": "Rock_Chalk",
      "rotation": 3
    },
    {
      "x": -6,
      "y": 16,
      "z": 1,
      "name": "Rock_Chalk",
      "rotation": 3
    },
    {
      "x": -6,
      "y": 17,
      "z": 1,
      "name": "Rock_Chalk",
      "rotation": 3
    },
    {
      "x": -6,
      "y": 18,
      "z": 1,
      "name": "Rock_Chalk"
    },
    {
      "x": -6,
      "y": 19,
      "z": 1,
      "name": "Soil_Dirt_White"
    },
    {
      "x": -6,
      "y": 20,
      "z": 1,
      "name": "Soil_Dirt_White"
    },
    {
      "x": -6,
      "y": 21,
      "z": 1,
      "name": "Rock_Marble_Brick"
    },
    {
      "x": -6,
      "y": 22,
      "z": 1,
      "name": "Rock_Marble_Brick"
    },
    {
      "x": -6,
      "y": 23,
      "z": 1,
      "name": "Rock_Marble_Brick"
    },
    {
      "x": -6,
      "y": 24,
      "z": 1,
      "name": "Rock_Chalk"
    },
    {
      "x": -6,
      "y": 25,
      "z": 1,
      "name": "Rock_Chalk"
    },
    {
      "x": -6,
      "y": 26,
      "z": 1,
      "name": "Rock_Chalk"
    },
    {
      "x": -6,
      "y": 40,
      "z": 1,
      "name": "Rock_Marble_Brick_Smooth"
    },
    {
      "x": -6,
      "y": 41,
      "z": 1,
      "name": "Rock_Marble_Brick_Smooth"
    },
    {
      "x": -6,
      "y": 13,
      "z": 2,
      "name": "Rock_Chalk",
      "rotation": 3
    },
    {
      "x": -6,
      "y": 14,
      "z": 2,
      "name": "Rock_Chalk",
      "rotation": 3
    },
    {
      "x": -6,
      "y": 15,
      "z": 2,
      "name": "Rock_Chalk",
      "rotation": 3
    },
    {
      "x": -6,
      "y": 16,
      "z": 2,
      "name": "Rock_Chalk",
      "rotation": 3
    },
    {
      "x": -6,
      "y": 17,
      "z": 2,
      "name": "Rock_Chalk",
      "rotation": 3
    },
    {
      "x": -6,
      "y": 18,
      "z": 2,
      "name": "Soil_Dirt_White"
    },
    {
      "x": -6,
      "y": 19,
      "z": 2,
      "name": "Soil_Dirt_White"
    },
    {
      "x": -6,
      "y": 20,
      "z": 2,
      "name": "Soil_Dirt_White"
    },
    {
      "x": -6,
      "y": 21,
      "z": 2,
      "name": "Rock_Marble_Brick"
    },
    {
      "x": -6,
      "y": 22,
      "z": 2,
      "name": "Rock_Marble_Brick"
    },
    {
      "x": -6,
      "y": 23,
      "z": 2,
      "name": "Rock_Marble_Brick"
    },
    {
      "x": -6,
      "y": 24,
      "z": 2,
      "name": "Rock_Chalk"
    },
    {
      "x": -6,
      "y": 25,
      "z": 2,
      "name": "Rock_Chalk"
    },
    {
      "x": -6,
      "y": 26,
      "z": 2,
      "name": "Rock_Chalk"
    },
    {
      "x": -6,
      "y": 40,
      "z": 2,
      "name": "Rock_Marble_Brick_Smooth"
    },
    {
      "x": -6,
      "y": 41,
      "z": 2,
      "name": "Rock_Marble_Brick_Smooth"
    },
    {
      "x": -6,
      "y": 42,
      "z": 2,
      "name": "Plant_Moss_Rug_Green_Dark"
    },
    {
      "x": -6,
      "y": 12,
      "z": 3,
      "name": "Rock_Chalk",
      "rotation": 3
    },
    {
      "x": -6,
      "y": 13,
      "z": 3,
      "name": "Rock_Chalk",
      "rotation": 3
    },
    {
      "x": -6,
      "y": 14,
      "z": 3,
      "name": "Rock_Chalk",
      "rotation": 3
    },
    {
      "x": -6,
      "y": 15,
      "z": 3,
      "name": "Rock_Chalk",
      "rotation": 3
    },
    {
      "x": -6,
      "y": 16,
      "z": 3,
      "name": "Rock_Chalk",
      "rotation": 3
    },
    {
      "x": -6,
      "y": 17,
      "z": 3,
      "name": "Soil_Dirt_White"
    },
    {
      "x": -6,
      "y": 18,
      "z": 3,
      "name": "Soil_Dirt_White"
    },
    {
      "x": -6,
      "y": 19,
      "z": 3,
      "name": "Soil_Dirt_White"
    },
    {
      "x": -6,
      "y": 20,
      "z": 3,
      "name": "Rock_Chalk"
    },
    {
      "x": -6,
      "y": 21,
      "z": 3,
      "name": "Soil_Dirt_White"
    },
    {
      "x": -6,
      "y": 22,
      "z": 3,
      "name": "Rock_Marble_Brick"
    },
    {
      "x": -6,
      "y": 10,
      "z": 4,
      "name": "Rock_Chalk",
      "rotation": 3
    },
    {
      "x": -6,
      "y": 11,
      "z": 4,
      "name": "Rock_Chalk",
      "rotation": 3
    },
    {
      "x": -6,
      "y": 12,
      "z": 4,
      "name": "Rock_Chalk",
      "rotation": 3
    },
    {
      "x": -6,
      "y": 13,
      "z": 4,
      "name": "Rock_Chalk",
      "rotation": 3
    },
    {
      "x": -6,
      "y": 14,
      "z": 4,
      "name": "Rock_Chalk",
      "rotation": 3
    },
    {
      "x": -6,
      "y": 15,
      "z": 4,
      "name": "Rock_Chalk",
      "rotation": 3
    },
    {
      "x": -6,
      "y": 16,
      "z": 4,
      "name": "Rock_Chalk",
      "rotation": 3
    },
    {
      "x": -6,
      "y": 17,
      "z": 4,
      "name": "Rock_Chalk"
    },
    {
      "x": -6,
      "y": 18,
      "z": 4,
      "name": "Rock_Chalk"
    },
    {
      "x": -6,
      "y": 19,
      "z": 4,
      "name": "Soil_Dirt_White"
    },
    {
      "x": -6,
      "y": 20,
      "z": 4,
      "name": "Soil_Grass_Full"
    },
    {
      "x": -6,
      "y": 9,
      "z": 5,
      "name": "Rock_Chalk",
      "rotation": 3
    },
    {
      "x": -6,
      "y": 10,
      "z": 5,
      "name": "Rock_Chalk",
      "rotation": 3
    },
    {
      "x": -6,
      "y": 11,
      "z": 5,
      "name": "Rock_Chalk",
      "rotation": 3
    },
    {
      "x": -6,
      "y": 12,
      "z": 5,
      "name": "Rock_Chalk",
      "rotation": 3
    },
    {
      "x": -6,
      "y": 13,
      "z": 5,
      "name": "Rock_Chalk",
      "rotation": 3
    },
    {
      "x": -6,
      "y": 14,
      "z": 5,
      "name": "Rock_Chalk",
      "rotation": 3
    },
    {
      "x": -6,
      "y": 15,
      "z": 5,
      "name": "Rock_Chalk",
      "rotation": 3
    },
    {
      "x": -6,
      "y": 16,
      "z": 5,
      "name": "Rock_Chalk",
      "rotation": 3
    },
    {
      "x": -6,
      "y": 17,
      "z": 5,
      "name": "Rock_Chalk",
      "rotation": 3
    },
    {
      "x": -6,
      "y": 18,
      "z": 5,
      "name": "Rock_Chalk"
    },
    {
      "x": -6,
      "y": 19,
      "z": 5,
      "name": "Soil_Grass_Full"
    },
    {
      "x": -6,
      "y": 11,
      "z": 6,
      "name": "Rock_Chalk",
      "rotation": 3
    },
    {
      "x": -6,
      "y": 12,
      "z": 6,
      "name": "Rock_Chalk",
      "rotation": 3
    },
    {
      "x": -6,
      "y": 13,
      "z": 6,
      "name": "Rock_Chalk",
      "rotation": 3
    },
    {
      "x": -6,
      "y": 14,
      "z": 6,
      "name": "Rock_Chalk",
      "rotation": 3
    },
    {
      "x": -6,
      "y": 15,
      "z": 6,
      "name": "Rock_Chalk",
      "rotation": 3
    },
    {
      "x": -6,
      "y": 16,
      "z": 6,
      "name": "Rock_Chalk",
      "rotation": 3
    },
    {
      "x": -6,
      "y": 17,
      "z": 6,
      "name": "Rock_Chalk",
      "rotation": 3
    },
    {
      "x": -6,
      "y": 18,
      "z": 6,
      "name": "Rock_Chalk",
      "rotation": 3
    },
    {
      "x": -6,
      "y": 19,
      "z": 6,
      "name": "Rock_Chalk"
    },
    {
      "x": -5,
      "y": 16,
      "z": -4,
      "name": "Rock_Chalk",
      "rotation": 3
    },
    {
      "x": -5,
      "y": 17,
      "z": -4,
      "name": "Rock_Chalk",
      "rotation": 3
    },
    {
      "x": -5,
      "y": 18,
      "z": -4,
      "name": "Soil_Dirt_White",
      "rotation": 3
    },
    {
      "x": -5,
      "y": 19,
      "z": -4,
      "name": "Soil_Grass_Full",
      "rotation": 3
    },
    {
      "x": -5,
      "y": 15,
      "z": -3,
      "name": "Rock_Chalk",
      "rotation": 3
    },
    {
      "x": -5,
      "y": 16,
      "z": -3,
      "name": "Rock_Chalk",
      "rotation": 3
    },
    {
      "x": -5,
      "y": 17,
      "z": -3,
      "name": "Rock_Chalk",
      "rotation": 3
    },
    {
      "x": -5,
      "y": 18,
      "z": -3,
      "name": "Soil_Dirt_White",
      "rotation": 3
    },
    {
      "x": -5,
      "y": 19,
      "z": -3,
      "name": "Soil_Grass_Full",
      "rotation": 3
    },
    {
      "x": -5,
      "y": 14,
      "z": -2,
      "name": "Rock_Chalk",
      "rotation": 3
    },
    {
      "x": -5,
      "y": 15,
      "z": -2,
      "name": "Rock_Chalk",
      "rotation": 3
    },
    {
      "x": -5,
      "y": 16,
      "z": -2,
      "name": "Rock_Chalk",
      "rotation": 3
    },
    {
      "x": -5,
      "y": 17,
      "z": -2,
      "name": "Rock_Chalk",
      "rotation": 3
    },
    {
      "x": -5,
      "y": 18,
      "z": -2,
      "name": "Rock_Chalk",
      "rotation": 3
    },
    {
      "x": -5,
      "y": 19,
      "z": -2,
      "name": "Soil_Dirt_White",
      "rotation": 3
    },
    {
      "x": -5,
      "y": 20,
      "z": -2,
      "name": "Soil_Grass_Full",
      "rotation": 3
    },
    {
      "x": -5,
      "y": 13,
      "z": -1,
      "name": "Rock_Chalk",
      "rotation": 3
    },
    {
      "x": -5,
      "y": 14,
      "z": -1,
      "name": "Rock_Chalk",
      "rotation": 3
    },
    {
      "x": -5,
      "y": 15,
      "z": -1,
      "name": "Rock_Chalk",
      "rotation": 3
    },
    {
      "x": -5,
      "y": 16,
      "z": -1,
      "name": "Rock_Chalk",
      "rotation": 3
    },
    {
      "x": -5,
      "y": 17,
      "z": -1,
      "name": "Rock_Chalk",
      "rotation": 3
    },
    {
      "x": -5,
      "y": 18,
      "z": -1,
      "name": "Rock_Chalk",
      "rotation": 3
    },
    {
      "x": -5,
      "y": 19,
      "z": -1,
      "name": "Rock_Chalk"
    },
    {
      "x": -5,
      "y": 20,
      "z": -1,
      "name": "Rock_Chalk"
    },
    {
      "x": -5,
      "y": 21,
      "z": -1,
      "name": "Rock_Marble_Brick"
    },
    {
      "x": -5,
      "y": 22,
      "z": -1,
      "name": "Rock_Marble_Brick"
    },
    {
      "x": -5,
      "y": 23,
      "z": -1,
      "name": "Rock_Marble_Brick"
    },
    {
      "x": -5,
      "y": 40,
      "z": -1,
      "name": "Rock_Marble_Brick_Smooth"
    },
    {
      "x": -5,
      "y": 41,
      "z": -1,
      "name": "Rock_Marble_Brick_Smooth"
    },
    {
      "x": -5,
      "y": 42,
      "z": -1,
      "name": "Rock_Marble_Brick_Wall"
    },
    {
      "x": -5,
      "y": 12,
      "z": 0,
      "name": "Rock_Chalk",
      "rotation": 3
    },
    {
      "x": -5,
      "y": 13,
      "z": 0,
      "name": "Rock_Chalk",
      "rotation": 3
    },
    {
      "x": -5,
      "y": 14,
      "z": 0,
      "name": "Rock_Chalk",
      "rotation": 3
    },
    {
      "x": -5,
      "y": 15,
      "z": 0,
      "name": "Rock_Chalk",
      "rotation": 3
    },
    {
      "x": -5,
      "y": 16,
      "z": 0,
      "name": "Rock_Chalk",
      "rotation": 3
    },
    {
      "x": -5,
      "y": 17,
      "z": 0,
      "name": "Rock_Chalk",
      "rotation": 3
    },
    {
      "x": -5,
      "y": 18,
      "z": 0,
      "name": "Rock_Chalk"
    },
    {
      "x": -5,
      "y": 19,
      "z": 0,
      "name": "Rock_Chalk"
    },
    {
      "x": -5,
      "y": 20,
      "z": 0,
      "name": "Rock_Chalk"
    },
    {
      "x": -5,
      "y": 21,
      "z": 0,
      "name": "Rock_Marble_Brick"
    },
    {
      "x": -5,
      "y": 22,
      "z": 0,
      "name": "Rock_Marble_Brick"
    },
    {
      "x": -5,
      "y": 23,
      "z": 0,
      "name": "Rock_Marble_Brick"
    },
    {
      "x": -5,
      "y": 24,
      "z": 0,
      "name": "Rock_Chalk"
    },
    {
      "x": -5,
      "y": 25,
      "z": 0,
      "name": "Rock_Chalk"
    },
    {
      "x": -5,
      "y": 26,
      "z": 0,
      "name": "Rock_Chalk"
    },
    {
      "x": -5,
      "y": 27,
      "z": 0,
      "name": "Rock_Chalk"
    },
    {
      "x": -5,
      "y": 28,
      "z": 0,
      "name": "Rock_Chalk"
    },
    {
      "x": -5,
      "y": 29,
      "z": 0,
      "name": "Rock_Chalk"
    },
    {
      "x": -5,
      "y": 30,
      "z": 0,
      "name": "Rock_Chalk"
    },
    {
      "x": -5,
      "y": 34,
      "z": 0,
      "name": "Rock_Chalk"
    },
    {
      "x": -5,
      "y": 35,
      "z": 0,
      "name": "Rock_Chalk"
    },
    {
      "x": -5,
      "y": 36,
      "z": 0,
      "name": "Rock_Chalk"
    },
    {
      "x": -5,
      "y": 37,
      "z": 0,
      "name": "Rock_Chalk"
    },
    {
      "x": -5,
      "y": 38,
      "z": 0,
      "name": "Rock_Chalk"
    },
    {
      "x": -5,
      "y": 39,
      "z": 0,
      "name": "Rock_Chalk"
    },
    {
      "x": -5,
      "y": 40,
      "z": 0,
      "name": "Rock_Chalk"
    },
    {
      "x": -5,
      "y": 41,
      "z": 0,
      "name": "Rock_Marble_Brick_Smooth"
    },
    {
      "x": -5,
      "y": 42,
      "z": 0,
      "name": "Plant_Moss_Rug_Green_Dark"
    },
    {
      "x": -5,
      "y": 11,
      "z": 1,
      "name": "Rock_Chalk",
      "rotation": 3
    },
    {
      "x": -5,
      "y": 12,
      "z": 1,
      "name": "Rock_Chalk",
      "rotation": 3
    },
    {
      "x": -5,
      "y": 13,
      "z": 1,
      "name": "Rock_Chalk",
      "rotation": 3
    },
    {
      "x": -5,
      "y": 14,
      "z": 1,
      "name": "Rock_Chalk",
      "rotation": 3
    },
    {
      "x": -5,
      "y": 15,
      "z": 1,
      "name": "Rock_Chalk",
      "rotation": 3
    },
    {
      "x": -5,
      "y": 16,
      "z": 1,
      "name": "Rock_Chalk",
      "rotation": 3
    },
    {
      "x": -5,
      "y": 17,
      "z": 1,
      "name": "Rock_Chalk",
      "rotation": 3
    },
    {
      "x": -5,
      "y": 18,
      "z": 1,
      "name": "Rock_Chalk"
    },
    {
      "x": -5,
      "y": 19,
      "z": 1,
      "name": "Soil_Dirt_White"
    },
    {
      "x": -5,
      "y": 20,
      "z": 1,
      "name": "Soil_Dirt_White"
    },
    {
      "x": -5,
      "y": 21,
      "z": 1,
      "name": "Rock_Marble_Brick"
    },
    {
      "x": -5,
      "y": 22,
      "z": 1,
      "name": "Rock_Marble_Brick"
    },
    {
      "x": -5,
      "y": 23,
      "z": 1,
      "name": "Rock_Marble_Brick"
    },
    {
      "x": -5,
      "y": 24,
      "z": 1,
      "name": "Rock_Chalk"
    },
    {
      "x": -5,
      "y": 25,
      "z": 1,
      "name": "Rock_Chalk"
    },
    {
      "x": -5,
      "y": 26,
      "z": 1,
      "name": "Rock_Chalk"
    },
    {
      "x": -5,
      "y": 27,
      "z": 1,
      "name": "Rock_Chalk"
    },
    {
      "x": -5,
      "y": 28,
      "z": 1,
      "name": "Rock_Chalk"
    },
    {
      "x": -5,
      "y": 29,
      "z": 1,
      "name": "Rock_Chalk"
    },
    {
      "x": -5,
      "y": 30,
      "z": 1,
      "name": "Rock_Chalk"
    },
    {
      "x": -5,
      "y": 34,
      "z": 1,
      "name": "Rock_Chalk"
    },
    {
      "x": -5,
      "y": 35,
      "z": 1,
      "name": "Rock_Chalk"
    },
    {
      "x": -5,
      "y": 36,
      "z": 1,
      "name": "Rock_Chalk"
    },
    {
      "x": -5,
      "y": 37,
      "z": 1,
      "name": "Rock_Chalk"
    },
    {
      "x": -5,
      "y": 38,
      "z": 1,
      "name": "Rock_Chalk"
    },
    {
      "x": -5,
      "y": 39,
      "z": 1,
      "name": "Rock_Chalk"
    },
    {
      "x": -5,
      "y": 40,
      "z": 1,
      "name": "Rock_Marble_Brick_Smooth"
    },
    {
      "x": -5,
      "y": 41,
      "z": 1,
      "name": "Rock_Marble_Brick_Smooth"
    },
    {
      "x": -5,
      "y": 42,
      "z": 1,
      "name": "Plant_Moss_Rug_Green_Dark"
    },
    {
      "x": -5,
      "y": 11,
      "z": 2,
      "name": "Rock_Chalk",
      "rotation": 3
    },
    {
      "x": -5,
      "y": 12,
      "z": 2,
      "name": "Rock_Chalk",
      "rotation": 3
    },
    {
      "x": -5,
      "y": 13,
      "z": 2,
      "name": "Rock_Chalk",
      "rotation": 3
    },
    {
      "x": -5,
      "y": 14,
      "z": 2,
      "name": "Rock_Chalk",
      "rotation": 3
    },
    {
      "x": -5,
      "y": 15,
      "z": 2,
      "name": "Rock_Chalk",
      "rotation": 3
    },
    {
      "x": -5,
      "y": 16,
      "z": 2,
      "name": "Rock_Chalk",
      "rotation": 3
    },
    {
      "x": -5,
      "y": 17,
      "z": 2,
      "name": "Soil_Dirt_White"
    },
    {
      "x": -5,
      "y": 18,
      "z": 2,
      "name": "Soil_Dirt_White"
    },
    {
      "x": -5,
      "y": 19,
      "z": 2,
      "name": "Soil_Dirt_White"
    },
    {
      "x": -5,
      "y": 20,
      "z": 2,
      "name": "Soil_Dirt_White"
    },
    {
      "x": -5,
      "y": 21,
      "z": 2,
      "name": "Rock_Marble_Brick"
    },
    {
      "x": -5,
      "y": 22,
      "z": 2,
      "name": "Rock_Marble_Brick"
    },
    {
      "x": -5,
      "y": 23,
      "z": 2,
      "name": "Rock_Marble_Brick"
    },
    {
      "x": -5,
      "y": 24,
      "z": 2,
      "name": "Rock_Marble_Brick_Smooth"
    },
    {
      "x": -5,
      "y": 25,
      "z": 2,
      "name": "Rock_Marble_Brick_Smooth"
    },
    {
      "x": -5,
      "y": 26,
      "z": 2,
      "name": "Rock_Marble_Brick_Pillar_Base"
    },
    {
      "x": -5,
      "y": 27,
      "z": 2,
      "name": "Rock_Marble_Brick_Pillar_Middle"
    },
    {
      "x": -5,
      "y": 28,
      "z": 2,
      "name": "Rock_Marble_Brick_Pillar_Middle"
    },
    {
      "x": -5,
      "y": 29,
      "z": 2,
      "name": "Rock_Marble_Brick_Pillar_Base",
      "rotation": 8
    },
    {
      "x": -5,
      "y": 40,
      "z": 2,
      "name": "Rock_Marble_Brick_Smooth"
    },
    {
      "x": -5,
      "y": 41,
      "z": 2,
      "name": "Rock_Marble_Brick_Smooth"
    },
    {
      "x": -5,
      "y": 42,
      "z": 2,
      "name": "Plant_Moss_Rug_Green_Dark"
    },
    {
      "x": -5,
      "y": 9,
      "z": 3,
      "name": "Rock_Chalk",
      "rotation": 3
    },
    {
      "x": -5,
      "y": 10,
      "z": 3,
      "name": "Rock_Chalk",
      "rotation": 3
    },
    {
      "x": -5,
      "y": 11,
      "z": 3,
      "name": "Rock_Chalk",
      "rotation": 3
    },
    {
      "x": -5,
      "y": 12,
      "z": 3,
      "name": "Rock_Chalk",
      "rotation": 3
    },
    {
      "x": -5,
      "y": 13,
      "z": 3,
      "name": "Rock_Chalk",
      "rotation": 3
    },
    {
      "x": -5,
      "y": 14,
      "z": 3,
      "name": "Rock_Chalk",
      "rotation": 3
    },
    {
      "x": -5,
      "y": 15,
      "z": 3,
      "name": "Rock_Chalk",
      "rotation": 3
    },
    {
      "x": -5,
      "y": 16,
      "z": 3,
      "name": "Rock_Chalk",
      "rotation": 3
    },
    {
      "x": -5,
      "y": 17,
      "z": 3,
      "name": "Soil_Dirt_White"
    },
    {
      "x": -5,
      "y": 18,
      "z": 3,
      "name": "Soil_Dirt_White"
    },
    {
      "x": -5,
      "y": 19,
      "z": 3,
      "name": "Soil_Dirt_White"
    },
    {
      "x": -5,
      "y": 20,
      "z": 3,
      "name": "Soil_Grass_Full"
    },
    {
      "x": -5,
      "y": 41,
      "z": 3,
      "name": "Plant_Moss_Wall_Green_Dark"
    },
    {
      "x": -5,
      "y": 8,
      "z": 4,
      "name": "Rock_Chalk",
      "rotation": 3
    },
    {
      "x": -5,
      "y": 9,
      "z": 4,
      "name": "Rock_Chalk",
      "rotation": 3
    },
    {
      "x": -5,
      "y": 10,
      "z": 4,
      "name": "Rock_Chalk",
      "rotation": 3
    },
    {
      "x": -5,
      "y": 11,
      "z": 4,
      "name": "Rock_Chalk",
      "rotation": 3
    },
    {
      "x": -5,
      "y": 12,
      "z": 4,
      "name": "Rock_Chalk",
      "rotation": 3
    },
    {
      "x": -5,
      "y": 13,
      "z": 4,
      "name": "Rock_Chalk",
      "rotation": 3
    },
    {
      "x": -5,
      "y": 14,
      "z": 4,
      "name": "Rock_Chalk",
      "rotation": 3
    },
    {
      "x": -5,
      "y": 15,
      "z": 4,
      "name": "Rock_Chalk",
      "rotation": 3
    },
    {
      "x": -5,
      "y": 16,
      "z": 4,
      "name": "Rock_Chalk",
      "rotation": 3
    },
    {
      "x": -5,
      "y": 17,
      "z": 4,
      "name": "Soil_Dirt_White"
    },
    {
      "x": -5,
      "y": 18,
      "z": 4,
      "name": "Soil_Dirt_White"
    },
    {
      "x": -5,
      "y": 19,
      "z": 4,
      "name": "Soil_Dirt_White"
    },
    {
      "x": -5,
      "y": 20,
      "z": 4,
      "name": "Soil_Grass_Full"
    },
    {
      "x": -5,
      "y": 9,
      "z": 5,
      "name": "Rock_Chalk",
      "rotation": 3
    },
    {
      "x": -5,
      "y": 10,
      "z": 5,
      "name": "Rock_Chalk",
      "rotation": 3
    },
    {
      "x": -5,
      "y": 11,
      "z": 5,
      "name": "Rock_Chalk",
      "rotation": 3
    },
    {
      "x": -5,
      "y": 12,
      "z": 5,
      "name": "Rock_Chalk",
      "rotation": 3
    },
    {
      "x": -5,
      "y": 13,
      "z": 5,
      "name": "Rock_Chalk",
      "rotation": 3
    },
    {
      "x": -5,
      "y": 14,
      "z": 5,
      "name": "Rock_Chalk",
      "rotation": 3
    },
    {
      "x": -5,
      "y": 15,
      "z": 5,
      "name": "Rock_Chalk",
      "rotation": 3
    },
    {
      "x": -5,
      "y": 16,
      "z": 5,
      "name": "Rock_Chalk",
      "rotation": 3
    },
    {
      "x": -5,
      "y": 17,
      "z": 5,
      "name": "Rock_Chalk"
    },
    {
      "x": -5,
      "y": 18,
      "z": 5,
      "name": "Rock_Chalk"
    },
    {
      "x": -5,
      "y": 19,
      "z": 5,
      "name": "Soil_Grass_White"
    },
    {
      "x": -5,
      "y": 9,
      "z": 6,
      "name": "Rock_Chalk",
      "rotation": 3
    },
    {
      "x": -5,
      "y": 10,
      "z": 6,
      "name": "Rock_Chalk",
      "rotation": 3
    },
    {
      "x": -5,
      "y": 11,
      "z": 6,
      "name": "Rock_Chalk",
      "rotation": 3
    },
    {
      "x": -5,
      "y": 12,
      "z": 6,
      "name": "Rock_Chalk",
      "rotation": 3
    },
    {
      "x": -5,
      "y": 13,
      "z": 6,
      "name": "Rock_Chalk",
      "rotation": 3
    },
    {
      "x": -5,
      "y": 14,
      "z": 6,
      "name": "Rock_Chalk",
      "rotation": 3
    },
    {
      "x": -5,
      "y": 15,
      "z": 6,
      "name": "Rock_Chalk",
      "rotation": 3
    },
    {
      "x": -5,
      "y": 16,
      "z": 6,
      "name": "Rock_Chalk",
      "rotation": 3
    },
    {
      "x": -5,
      "y": 17,
      "z": 6,
      "name": "Rock_Chalk",
      "rotation": 3
    },
    {
      "x": -5,
      "y": 18,
      "z": 6,
      "name": "Rock_Chalk"
    },
    {
      "x": -5,
      "y": 19,
      "z": 6,
      "name": "Rock_Chalk"
    },
    {
      "x": -5,
      "y": 14,
      "z": 7,
      "name": "Rock_Chalk",
      "rotation": 3
    },
    {
      "x": -5,
      "y": 15,
      "z": 7,
      "name": "Rock_Chalk",
      "rotation": 3
    },
    {
      "x": -5,
      "y": 16,
      "z": 7,
      "name": "Rock_Chalk",
      "rotation": 3
    },
    {
      "x": -5,
      "y": 17,
      "z": 7,
      "name": "Rock_Chalk",
      "rotation": 3
    },
    {
      "x": -5,
      "y": 18,
      "z": 7,
      "name": "Soil_Dirt_White",
      "rotation": 3
    },
    {
      "x": -5,
      "y": 19,
      "z": 7,
      "name": "Rock_Chalk"
    },
    {
      "x": -4,
      "y": 16,
      "z": -4,
      "name": "Rock_Chalk",
      "rotation": 3
    },
    {
      "x": -4,
      "y": 17,
      "z": -4,
      "name": "Rock_Chalk",
      "rotation": 3
    },
    {
      "x": -4,
      "y": 18,
      "z": -4,
      "name": "Soil_Dirt_White",
      "rotation": 3
    },
    {
      "x": -4,
      "y": 19,
      "z": -4,
      "name": "Soil_Grass_Full",
      "rotation": 3
    },
    {
      "x": -4,
      "y": 15,
      "z": -3,
      "name": "Rock_Chalk",
      "rotation": 3
    },
    {
      "x": -4,
      "y": 16,
      "z": -3,
      "name": "Rock_Chalk",
      "rotation": 3
    },
    {
      "x": -4,
      "y": 17,
      "z": -3,
      "name": "Rock_Chalk",
      "rotation": 3
    },
    {
      "x": -4,
      "y": 18,
      "z": -3,
      "name": "Rock_Chalk",
      "rotation": 3
    },
    {
      "x": -4,
      "y": 19,
      "z": -3,
      "name": "Soil_Dirt_White"
    },
    {
      "x": -4,
      "y": 20,
      "z": -3,
      "name": "Soil_Grass_Full"
    },
    {
      "x": -4,
      "y": 14,
      "z": -2,
      "name": "Rock_Chalk",
      "rotation": 3
    },
    {
      "x": -4,
      "y": 15,
      "z": -2,
      "name": "Rock_Chalk",
      "rotation": 3
    },
    {
      "x": -4,
      "y": 16,
      "z": -2,
      "name": "Rock_Chalk",
      "rotation": 3
    },
    {
      "x": -4,
      "y": 17,
      "z": -2,
      "name": "Rock_Chalk",
      "rotation": 3
    },
    {
      "x": -4,
      "y": 18,
      "z": -2,
      "name": "Rock_Chalk"
    },
    {
      "x": -4,
      "y": 19,
      "z": -2,
      "name": "Soil_Dirt_White"
    },
    {
      "x": -4,
      "y": 20,
      "z": -2,
      "name": "Soil_Grass_Full"
    },
    {
      "x": -4,
      "y": 13,
      "z": -1,
      "name": "Rock_Chalk",
      "rotation": 3
    },
    {
      "x": -4,
      "y": 14,
      "z": -1,
      "name": "Rock_Chalk",
      "rotation": 3
    },
    {
      "x": -4,
      "y": 15,
      "z": -1,
      "name": "Rock_Chalk",
      "rotation": 3
    },
    {
      "x": -4,
      "y": 16,
      "z": -1,
      "name": "Rock_Chalk",
      "rotation": 3
    },
    {
      "x": -4,
      "y": 17,
      "z": -1,
      "name": "Rock_Chalk",
      "rotation": 3
    },
    {
      "x": -4,
      "y": 18,
      "z": -1,
      "name": "Rock_Chalk"
    },
    {
      "x": -4,
      "y": 19,
      "z": -1,
      "name": "Soil_Dirt_White"
    },
    {
      "x": -4,
      "y": 20,
      "z": -1,
      "name": "Soil_Grass_Full"
    },
    {
      "x": -4,
      "y": 40,
      "z": -1,
      "name": "Rock_Marble_Brick_Smooth"
    },
    {
      "x": -4,
      "y": 41,
      "z": -1,
      "name": "Rock_Marble_Brick_Smooth"
    },
    {
      "x": -4,
      "y": 42,
      "z": -1,
      "name": "Rock_Marble_Brick_Wall"
    },
    {
      "x": -4,
      "y": 11,
      "z": 0,
      "name": "Rock_Chalk",
      "rotation": 3
    },
    {
      "x": -4,
      "y": 12,
      "z": 0,
      "name": "Rock_Chalk",
      "rotation": 3
    },
    {
      "x": -4,
      "y": 13,
      "z": 0,
      "name": "Rock_Chalk",
      "rotation": 3
    },
    {
      "x": -4,
      "y": 14,
      "z": 0,
      "name": "Rock_Chalk",
      "rotation": 3
    },
    {
      "x": -4,
      "y": 15,
      "z": 0,
      "name": "Rock_Chalk",
      "rotation": 3
    },
    {
      "x": -4,
      "y": 16,
      "z": 0,
      "name": "Rock_Chalk",
      "rotation": 3
    },
    {
      "x": -4,
      "y": 17,
      "z": 0,
      "name": "Rock_Chalk"
    },
    {
      "x": -4,
      "y": 18,
      "z": 0,
      "name": "Rock_Chalk"
    },
    {
      "x": -4,
      "y": 19,
      "z": 0,
      "name": "Rock_Chalk"
    },
    {
      "x": -4,
      "y": 20,
      "z": 0,
      "name": "Rock_Chalk"
    },
    {
      "x": -4,
      "y": 21,
      "z": 0,
      "name": "Rock_Marble_Brick"
    },
    {
      "x": -4,
      "y": 22,
      "z": 0,
      "name": "Rock_Marble_Brick"
    },
    {
      "x": -4,
      "y": 23,
      "z": 0,
      "name": "Rock_Marble_Brick"
    },
    {
      "x": -4,
      "y": 24,
      "z": 0,
      "name": "Rock_Chalk"
    },
    {
      "x": -4,
      "y": 25,
      "z": 0,
      "name": "Rock_Chalk"
    },
    {
      "x": -4,
      "y": 26,
      "z": 0,
      "name": "Rock_Chalk"
    },
    {
      "x": -4,
      "y": 27,
      "z": 0,
      "name": "Rock_Chalk"
    },
    {
      "x": -4,
      "y": 28,
      "z": 0,
      "name": "Rock_Chalk"
    },
    {
      "x": -4,
      "y": 29,
      "z": 0,
      "name": "Rock_Chalk"
    },
    {
      "x": -4,
      "y": 30,
      "z": 0,
      "name": "Rock_Chalk"
    },
    {
      "x": -4,
      "y": 31,
      "z": 0,
      "name": "Rock_Chalk"
    },
    {
      "x": -4,
      "y": 35,
      "z": 0,
      "name": "Rock_Chalk"
    },
    {
      "x": -4,
      "y": 36,
      "z": 0,
      "name": "Rock_Chalk"
    },
    {
      "x": -4,
      "y": 37,
      "z": 0,
      "name": "Rock_Chalk"
    },
    {
      "x": -4,
      "y": 38,
      "z": 0,
      "name": "Rock_Chalk"
    },
    {
      "x": -4,
      "y": 40,
      "z": 0,
      "name": "Rock_Marble_Brick_Smooth"
    },
    {
      "x": -4,
      "y": 41,
      "z": 0,
      "name": "Rock_Marble_Brick_Smooth"
    },
    {
      "x": -4,
      "y": 42,
      "z": 0,
      "name": "Plant_Moss_Rug_Green_Dark"
    },
    {
      "x": -4,
      "y": 9,
      "z": 1,
      "name": "Rock_Chalk",
      "rotation": 3
    },
    {
      "x": -4,
      "y": 10,
      "z": 1,
      "name": "Rock_Chalk",
      "rotation": 3
    },
    {
      "x": -4,
      "y": 11,
      "z": 1,
      "name": "Rock_Chalk",
      "rotation": 3
    },
    {
      "x": -4,
      "y": 12,
      "z": 1,
      "name": "Rock_Chalk",
      "rotation": 3
    },
    {
      "x": -4,
      "y": 13,
      "z": 1,
      "name": "Rock_Chalk",
      "rotation": 3
    },
    {
      "x": -4,
      "y": 14,
      "z": 1,
      "name": "Rock_Chalk",
      "rotation": 3
    },
    {
      "x": -4,
      "y": 15,
      "z": 1,
      "name": "Rock_Chalk",
      "rotation": 3
    },
    {
      "x": -4,
      "y": 16,
      "z": 1,
      "name": "Rock_Chalk",
      "rotation": 3
    },
    {
      "x": -4,
      "y": 17,
      "z": 1,
      "name": "Rock_Chalk",
      "rotation": 3
    },
    {
      "x": -4,
      "y": 18,
      "z": 1,
      "name": "Rock_Chalk"
    },
    {
      "x": -4,
      "y": 19,
      "z": 1,
      "name": "Soil_Dirt_White"
    },
    {
      "x": -4,
      "y": 20,
      "z": 1,
      "name": "Soil_Dirt_White"
    },
    {
      "x": -4,
      "y": 21,
      "z": 1,
      "name": "Rock_Marble_Brick"
    },
    {
      "x": -4,
      "y": 22,
      "z": 1,
      "name": "Rock_Marble_Brick"
    },
    {
      "x": -4,
      "y": 23,
      "z": 1,
      "name": "Rock_Marble_Brick"
    },
    {
      "x": -4,
      "y": 24,
      "z": 1,
      "name": "Rock_Chalk"
    },
    {
      "x": -4,
      "y": 25,
      "z": 1,
      "name": "Rock_Chalk"
    },
    {
      "x": -4,
      "y": 26,
      "z": 1,
      "name": "Rock_Chalk"
    },
    {
      "x": -4,
      "y": 27,
      "z": 1,
      "name": "Rock_Chalk"
    },
    {
      "x": -4,
      "y": 28,
      "z": 1,
      "name": "Rock_Chalk"
    },
    {
      "x": -4,
      "y": 29,
      "z": 1,
      "name": "Rock_Chalk"
    },
    {
      "x": -4,
      "y": 30,
      "z": 1,
      "name": "Rock_Chalk"
    },
    {
      "x": -4,
      "y": 31,
      "z": 1,
      "name": "Rock_Chalk"
    },
    {
      "x": -4,
      "y": 35,
      "z": 1,
      "name": "Rock_Chalk"
    },
    {
      "x": -4,
      "y": 36,
      "z": 1,
      "name": "Rock_Chalk"
    },
    {
      "x": -4,
      "y": 37,
      "z": 1,
      "name": "Rock_Chalk"
    },
    {
      "x": -4,
      "y": 38,
      "z": 1,
      "name": "Rock_Chalk"
    },
    {
      "x": -4,
      "y": 40,
      "z": 1,
      "name": "Rock_Marble_Brick_Smooth"
    },
    {
      "x": -4,
      "y": 41,
      "z": 1,
      "name": "Rock_Marble_Brick_Smooth"
    },
    {
      "x": -4,
      "y": 42,
      "z": 1,
      "name": "Plant_Moss_Rug_Green_Dark"
    },
    {
      "x": -4,
      "y": 6,
      "z": 2,
      "name": "Rock_Chalk",
      "rotation": 3
    },
    {
      "x": -4,
      "y": 7,
      "z": 2,
      "name": "Rock_Chalk",
      "rotation": 3
    },
    {
      "x": -4,
      "y": 8,
      "z": 2,
      "name": "Rock_Chalk",
      "rotation": 3
    },
    {
      "x": -4,
      "y": 9,
      "z": 2,
      "name": "Rock_Chalk",
      "rotation": 3
    },
    {
      "x": -4,
      "y": 10,
      "z": 2,
      "name": "Rock_Chalk",
      "rotation": 3
    },
    {
      "x": -4,
      "y": 11,
      "z": 2,
      "name": "Rock_Chalk",
      "rotation": 3
    },
    {
      "x": -4,
      "y": 12,
      "z": 2,
      "name": "Rock_Chalk",
      "rotation": 3
    },
    {
      "x": -4,
      "y": 13,
      "z": 2,
      "name": "Rock_Chalk",
      "rotation": 3
    },
    {
      "x": -4,
      "y": 14,
      "z": 2,
      "name": "Rock_Chalk",
      "rotation": 3
    },
    {
      "x": -4,
      "y": 15,
      "z": 2,
      "name": "Rock_Chalk",
      "rotation": 3
    },
    {
      "x": -4,
      "y": 16,
      "z": 2,
      "name": "Rock_Chalk",
      "rotation": 3
    },
    {
      "x": -4,
      "y": 17,
      "z": 2,
      "name": "Rock_Chalk",
      "rotation": 3
    },
    {
      "x": -4,
      "y": 18,
      "z": 2,
      "name": "Soil_Dirt_White"
    },
    {
      "x": -4,
      "y": 19,
      "z": 2,
      "name": "Soil_Dirt_White"
    },
    {
      "x": -4,
      "y": 20,
      "z": 2,
      "name": "Soil_Dirt_White"
    },
    {
      "x": -4,
      "y": 21,
      "z": 2,
      "name": "Rock_Marble_Brick"
    },
    {
      "x": -4,
      "y": 22,
      "z": 2,
      "name": "Rock_Marble_Brick"
    },
    {
      "x": -4,
      "y": 23,
      "z": 2,
      "name": "Rock_Marble_Brick"
    },
    {
      "x": -4,
      "y": 24,
      "z": 2,
      "name": "Rock_Marble_Brick_Smooth"
    },
    {
      "x": -4,
      "y": 25,
      "z": 2,
      "name": "Rock_Marble_Brick_Smooth"
    },
    {
      "x": -4,
      "y": 26,
      "z": 2,
      "name": "Rock_Marble_Brick_Pillar_Base"
    },
    {
      "x": -4,
      "y": 27,
      "z": 2,
      "name": "Rock_Marble_Brick_Pillar_Base",
      "rotation": 8
    },
    {
      "x": -4,
      "y": 40,
      "z": 2,
      "name": "Rock_Marble_Brick_Smooth"
    },
    {
      "x": -4,
      "y": 41,
      "z": 2,
      "name": "Rock_Marble_Brick_Smooth"
    },
    {
      "x": -4,
      "y": 42,
      "z": 2,
      "name": "Plant_Moss_Rug_Green_Dark"
    },
    {
      "x": -4,
      "y": 6,
      "z": 3,
      "name": "Rock_Chalk",
      "rotation": 3
    },
    {
      "x": -4,
      "y": 7,
      "z": 3,
      "name": "Rock_Chalk",
      "rotation": 3
    },
    {
      "x": -4,
      "y": 8,
      "z": 3,
      "name": "Rock_Chalk",
      "rotation": 3
    },
    {
      "x": -4,
      "y": 9,
      "z": 3,
      "name": "Rock_Chalk",
      "rotation": 3
    },
    {
      "x": -4,
      "y": 10,
      "z": 3,
      "name": "Rock_Chalk",
      "rotation": 3
    },
    {
      "x": -4,
      "y": 11,
      "z": 3,
      "name": "Rock_Chalk",
      "rotation": 3
    },
    {
      "x": -4,
      "y": 12,
      "z": 3,
      "name": "Rock_Chalk",
      "rotation": 3
    },
    {
      "x": -4,
      "y": 13,
      "z": 3,
      "name": "Rock_Chalk",
      "rotation": 3
    },
    {
      "x": -4,
      "y": 14,
      "z": 3,
      "name": "Rock_Chalk",
      "rotation": 3
    },
    {
      "x": -4,
      "y": 15,
      "z": 3,
      "name": "Rock_Chalk",
      "rotation": 3
    },
    {
      "x": -4,
      "y": 16,
      "z": 3,
      "name": "Rock_Chalk",
      "rotation": 3
    },
    {
      "x": -4,
      "y": 17,
      "z": 3,
      "name": "Soil_Dirt_White"
    },
    {
      "x": -4,
      "y": 18,
      "z": 3,
      "name": "Soil_Dirt_White"
    },
    {
      "x": -4,
      "y": 19,
      "z": 3,
      "name": "Soil_Dirt_White"
    },
    {
      "x": -4,
      "y": 20,
      "z": 3,
      "name": "Rock_Marble_Brick"
    },
    {
      "x": -4,
      "y": 9,
      "z": 4,
      "name": "Rock_Chalk",
      "rotation": 3
    },
    {
      "x": -4,
      "y": 10,
      "z": 4,
      "name": "Rock_Chalk",
      "rotation": 3
    },
    {
      "x": -4,
      "y": 11,
      "z": 4,
      "name": "Rock_Chalk",
      "rotation": 3
    },
    {
      "x": -4,
      "y": 12,
      "z": 4,
      "name": "Rock_Chalk",
      "rotation": 3
    },
    {
      "x": -4,
      "y": 13,
      "z": 4,
      "name": "Rock_Chalk",
      "rotation": 3
    },
    {
      "x": -4,
      "y": 14,
      "z": 4,
      "name": "Rock_Chalk",
      "rotation": 3
    },
    {
      "x": -4,
      "y": 15,
      "z": 4,
      "name": "Rock_Chalk",
      "rotation": 3
    },
    {
      "x": -4,
      "y": 16,
      "z": 4,
      "name": "Rock_Chalk",
      "rotation": 3
    },
    {
      "x": -4,
      "y": 17,
      "z": 4,
      "name": "Soil_Dirt_White"
    },
    {
      "x": -4,
      "y": 18,
      "z": 4,
      "name": "Soil_Dirt_White"
    },
    {
      "x": -4,
      "y": 19,
      "z": 4,
      "name": "Soil_Grass_White"
    },
    {
      "x": -4,
      "y": 9,
      "z": 5,
      "name": "Rock_Chalk",
      "rotation": 3
    },
    {
      "x": -4,
      "y": 10,
      "z": 5,
      "name": "Rock_Chalk",
      "rotation": 3
    },
    {
      "x": -4,
      "y": 11,
      "z": 5,
      "name": "Rock_Chalk",
      "rotation": 3
    },
    {
      "x": -4,
      "y": 12,
      "z": 5,
      "name": "Rock_Chalk",
      "rotation": 3
    },
    {
      "x": -4,
      "y": 13,
      "z": 5,
      "name": "Rock_Chalk",
      "rotation": 3
    },
    {
      "x": -4,
      "y": 14,
      "z": 5,
      "name": "Rock_Chalk",
      "rotation": 3
    },
    {
      "x": -4,
      "y": 15,
      "z": 5,
      "name": "Rock_Chalk",
      "rotation": 3
    },
    {
      "x": -4,
      "y": 16,
      "z": 5,
      "name": "Rock_Chalk",
      "rotation": 3
    },
    {
      "x": -4,
      "y": 17,
      "z": 5,
      "name": "Rock_Chalk"
    },
    {
      "x": -4,
      "y": 18,
      "z": 5,
      "name": "Soil_Dirt_White"
    },
    {
      "x": -4,
      "y": 19,
      "z": 5,
      "name": "Soil_Grass_White"
    },
    {
      "x": -4,
      "y": 9,
      "z": 6,
      "name": "Rock_Chalk",
      "rotation": 3
    },
    {
      "x": -4,
      "y": 10,
      "z": 6,
      "name": "Rock_Chalk",
      "rotation": 3
    },
    {
      "x": -4,
      "y": 11,
      "z": 6,
      "name": "Rock_Chalk",
      "rotation": 3
    },
    {
      "x": -4,
      "y": 12,
      "z": 6,
      "name": "Rock_Chalk",
      "rotation": 3
    },
    {
      "x": -4,
      "y": 13,
      "z": 6,
      "name": "Rock_Chalk",
      "rotation": 3
    },
    {
      "x": -4,
      "y": 14,
      "z": 6,
      "name": "Rock_Chalk",
      "rotation": 3
    },
    {
      "x": -4,
      "y": 15,
      "z": 6,
      "name": "Rock_Chalk",
      "rotation": 3
    },
    {
      "x": -4,
      "y": 16,
      "z": 6,
      "name": "Rock_Chalk",
      "rotation": 3
    },
    {
      "x": -4,
      "y": 17,
      "z": 6,
      "name": "Rock_Chalk"
    },
    {
      "x": -4,
      "y": 18,
      "z": 6,
      "name": "Soil_Dirt_White"
    },
    {
      "x": -4,
      "y": 19,
      "z": 6,
      "name": "Soil_Grass_White"
    },
    {
      "x": -4,
      "y": 11,
      "z": 7,
      "name": "Rock_Chalk",
      "rotation": 3
    },
    {
      "x": -4,
      "y": 12,
      "z": 7,
      "name": "Rock_Chalk",
      "rotation": 3
    },
    {
      "x": -4,
      "y": 13,
      "z": 7,
      "name": "Rock_Chalk",
      "rotation": 3
    },
    {
      "x": -4,
      "y": 14,
      "z": 7,
      "name": "Rock_Chalk",
      "rotation": 3
    },
    {
      "x": -4,
      "y": 15,
      "z": 7,
      "name": "Rock_Chalk",
      "rotation": 3
    },
    {
      "x": -4,
      "y": 16,
      "z": 7,
      "name": "Rock_Chalk",
      "rotation": 3
    },
    {
      "x": -4,
      "y": 17,
      "z": 7,
      "name": "Rock_Chalk",
      "rotation": 3
    },
    {
      "x": -4,
      "y": 18,
      "z": 7,
      "name": "Soil_Dirt_White"
    },
    {
      "x": -4,
      "y": 19,
      "z": 7,
      "name": "Soil_Grass_Full"
    },
    {
      "x": -4,
      "y": 16,
      "z": 8,
      "name": "Rock_Chalk",
      "rotation": 3
    },
    {
      "x": -4,
      "y": 17,
      "z": 8,
      "name": "Soil_Dirt_White",
      "rotation": 3
    },
    {
      "x": -4,
      "y": 18,
      "z": 8,
      "name": "Soil_Grass_Full",
      "rotation": 3
    },
    {
      "x": -3,
      "y": 13,
      "z": -5,
      "name": "Rock_Chalk",
      "rotation": 3
    },
    {
      "x": -3,
      "y": 14,
      "z": -5,
      "name": "Rock_Chalk",
      "rotation": 3
    },
    {
      "x": -3,
      "y": 15,
      "z": -5,
      "name": "Rock_Chalk",
      "rotation": 3
    },
    {
      "x": -3,
      "y": 16,
      "z": -5,
      "name": "Rock_Chalk",
      "rotation": 3
    },
    {
      "x": -3,
      "y": 17,
      "z": -5,
      "name": "Soil_Dirt_White",
      "rotation": 3
    },
    {
      "x": -3,
      "y": 18,
      "z": -5,
      "name": "Soil_Grass_Full",
      "rotation": 3
    },
    {
      "x": -3,
      "y": 6,
      "z": -4,
      "name": "Rock_Chalk",
      "rotation": 3
    },
    {
      "x": -3,
      "y": 7,
      "z": -4,
      "name": "Rock_Chalk",
      "rotation": 3
    },
    {
      "x": -3,
      "y": 8,
      "z": -4,
      "name": "Rock_Chalk",
      "rotation": 3
    },
    {
      "x": -3,
      "y": 9,
      "z": -4,
      "name": "Rock_Chalk",
      "rotation": 3
    },
    {
      "x": -3,
      "y": 10,
      "z": -4,
      "name": "Rock_Chalk",
      "rotation": 3
    },
    {
      "x": -3,
      "y": 11,
      "z": -4,
      "name": "Rock_Chalk",
      "rotation": 3
    },
    {
      "x": -3,
      "y": 12,
      "z": -4,
      "name": "Rock_Chalk",
      "rotation": 3
    },
    {
      "x": -3,
      "y": 13,
      "z": -4,
      "name": "Rock_Chalk",
      "rotation": 3
    },
    {
      "x": -3,
      "y": 14,
      "z": -4,
      "name": "Rock_Chalk",
      "rotation": 3
    },
    {
      "x": -3,
      "y": 15,
      "z": -4,
      "name": "Rock_Chalk",
      "rotation": 3
    },
    {
      "x": -3,
      "y": 16,
      "z": -4,
      "name": "Rock_Chalk",
      "rotation": 3
    },
    {
      "x": -3,
      "y": 17,
      "z": -4,
      "name": "Soil_Dirt_White",
      "rotation": 3
    },
    {
      "x": -3,
      "y": 18,
      "z": -4,
      "name": "Soil_Grass_Full",
      "rotation": 3
    },
    {
      "x": -3,
      "y": 5,
      "z": -3,
      "name": "Rock_Chalk",
      "rotation": 3
    },
    {
      "x": -3,
      "y": 6,
      "z": -3,
      "name": "Rock_Chalk",
      "rotation": 3
    },
    {
      "x": -3,
      "y": 7,
      "z": -3,
      "name": "Rock_Chalk",
      "rotation": 3
    },
    {
      "x": -3,
      "y": 8,
      "z": -3,
      "name": "Rock_Chalk",
      "rotation": 3
    },
    {
      "x": -3,
      "y": 9,
      "z": -3,
      "name": "Rock_Chalk",
      "rotation": 3
    },
    {
      "x": -3,
      "y": 10,
      "z": -3,
      "name": "Rock_Chalk",
      "rotation": 3
    },
    {
      "x": -3,
      "y": 11,
      "z": -3,
      "name": "Rock_Chalk",
      "rotation": 3
    },
    {
      "x": -3,
      "y": 12,
      "z": -3,
      "name": "Rock_Chalk",
      "rotation": 3
    },
    {
      "x": -3,
      "y": 13,
      "z": -3,
      "name": "Rock_Chalk",
      "rotation": 3
    },
    {
      "x": -3,
      "y": 14,
      "z": -3,
      "name": "Rock_Chalk",
      "rotation": 3
    },
    {
      "x": -3,
      "y": 15,
      "z": -3,
      "name": "Rock_Chalk",
      "rotation": 3
    },
    {
      "x": -3,
      "y": 16,
      "z": -3,
      "name": "Rock_Chalk",
      "rotation": 3
    },
    {
      "x": -3,
      "y": 17,
      "z": -3,
      "name": "Rock_Chalk",
      "rotation": 3
    },
    {
      "x": -3,
      "y": 18,
      "z": -3,
      "name": "Rock_Chalk"
    },
    {
      "x": -3,
      "y": 19,
      "z": -3,
      "name": "Soil_Dirt_White"
    },
    {
      "x": -3,
      "y": 20,
      "z": -3,
      "name": "Soil_Grass_Full"
    },
    {
      "x": -3,
      "y": 6,
      "z": -2,
      "name": "Rock_Chalk",
      "rotation": 3
    },
    {
      "x": -3,
      "y": 7,
      "z": -2,
      "name": "Rock_Chalk",
      "rotation": 3
    },
    {
      "x": -3,
      "y": 8,
      "z": -2,
      "name": "Rock_Chalk",
      "rotation": 3
    },
    {
      "x": -3,
      "y": 9,
      "z": -2,
      "name": "Rock_Chalk",
      "rotation": 3
    },
    {
      "x": -3,
      "y": 10,
      "z": -2,
      "name": "Rock_Chalk",
      "rotation": 3
    },
    {
      "x": -3,
      "y": 11,
      "z": -2,
      "name": "Rock_Chalk",
      "rotation": 3
    },
    {
      "x": -3,
      "y": 12,
      "z": -2,
      "name": "Rock_Chalk",
      "rotation": 3
    },
    {
      "x": -3,
      "y": 13,
      "z": -2,
      "name": "Rock_Chalk",
      "rotation": 3
    },
    {
      "x": -3,
      "y": 14,
      "z": -2,
      "name": "Rock_Chalk",
      "rotation": 3
    },
    {
      "x": -3,
      "y": 15,
      "z": -2,
      "name": "Rock_Chalk",
      "rotation": 3
    },
    {
      "x": -3,
      "y": 16,
      "z": -2,
      "name": "Rock_Chalk",
      "rotation": 3
    },
    {
      "x": -3,
      "y": 17,
      "z": -2,
      "name": "Rock_Chalk"
    },
    {
      "x": -3,
      "y": 18,
      "z": -2,
      "name": "Rock_Chalk"
    },
    {
      "x": -3,
      "y": 19,
      "z": -2,
      "name": "Soil_Dirt_White"
    },
    {
      "x": -3,
      "y": 20,
      "z": -2,
      "name": "Soil_Grass_Full"
    },
    {
      "x": -3,
      "y": 5,
      "z": -1,
      "name": "Rock_Chalk",
      "rotation": 3
    },
    {
      "x": -3,
      "y": 6,
      "z": -1,
      "name": "Rock_Chalk",
      "rotation": 3
    },
    {
      "x": -3,
      "y": 7,
      "z": -1,
      "name": "Rock_Chalk",
      "rotation": 3
    },
    {
      "x": -3,
      "y": 8,
      "z": -1,
      "name": "Rock_Chalk",
      "rotation": 3
    },
    {
      "x": -3,
      "y": 9,
      "z": -1,
      "name": "Rock_Chalk",
      "rotation": 3
    },
    {
      "x": -3,
      "y": 10,
      "z": -1,
      "name": "Rock_Chalk",
      "rotation": 3
    },
    {
      "x": -3,
      "y": 11,
      "z": -1,
      "name": "Rock_Chalk",
      "rotation": 3
    },
    {
      "x": -3,
      "y": 12,
      "z": -1,
      "name": "Rock_Chalk",
      "rotation": 3
    },
    {
      "x": -3,
      "y": 13,
      "z": -1,
      "name": "Rock_Chalk",
      "rotation": 3
    },
    {
      "x": -3,
      "y": 14,
      "z": -1,
      "name": "Rock_Chalk",
      "rotation": 3
    },
    {
      "x": -3,
      "y": 15,
      "z": -1,
      "name": "Rock_Chalk",
      "rotation": 3
    },
    {
      "x": -3,
      "y": 16,
      "z": -1,
      "name": "Rock_Chalk",
      "rotation": 3
    },
    {
      "x": -3,
      "y": 17,
      "z": -1,
      "name": "Rock_Chalk"
    },
    {
      "x": -3,
      "y": 18,
      "z": -1,
      "name": "Rock_Chalk"
    },
    {
      "x": -3,
      "y": 19,
      "z": -1,
      "name": "Soil_Dirt_White"
    },
    {
      "x": -3,
      "y": 20,
      "z": -1,
      "name": "Soil_Grass_Full"
    },
    {
      "x": -3,
      "y": 41,
      "z": -1,
      "name": "Rock_Marble_Brick_Smooth"
    },
    {
      "x": -3,
      "y": 42,
      "z": -1,
      "name": "Rock_Marble_Brick_Wall"
    },
    {
      "x": -3,
      "y": 5,
      "z": 0,
      "name": "Rock_Chalk",
      "rotation": 3
    },
    {
      "x": -3,
      "y": 6,
      "z": 0,
      "name": "Rock_Chalk",
      "rotation": 3
    },
    {
      "x": -3,
      "y": 7,
      "z": 0,
      "name": "Rock_Chalk",
      "rotation": 3
    },
    {
      "x": -3,
      "y": 8,
      "z": 0,
      "name": "Rock_Chalk",
      "rotation": 3
    },
    {
      "x": -3,
      "y": 9,
      "z": 0,
      "name": "Rock_Chalk",
      "rotation": 3
    },
    {
      "x": -3,
      "y": 10,
      "z": 0,
      "name": "Rock_Chalk",
      "rotation": 3
    },
    {
      "x": -3,
      "y": 11,
      "z": 0,
      "name": "Rock_Chalk",
      "rotation": 3
    },
    {
      "x": -3,
      "y": 12,
      "z": 0,
      "name": "Rock_Chalk",
      "rotation": 3
    },
    {
      "x": -3,
      "y": 13,
      "z": 0,
      "name": "Rock_Chalk",
      "rotation": 3
    },
    {
      "x": -3,
      "y": 14,
      "z": 0,
      "name": "Rock_Chalk",
      "rotation": 3
    },
    {
      "x": -3,
      "y": 15,
      "z": 0,
      "name": "Rock_Chalk",
      "rotation": 3
    },
    {
      "x": -3,
      "y": 16,
      "z": 0,
      "name": "Rock_Chalk",
      "rotation": 3
    },
    {
      "x": -3,
      "y": 17,
      "z": 0,
      "name": "Rock_Chalk"
    },
    {
      "x": -3,
      "y": 18,
      "z": 0,
      "name": "Rock_Chalk"
    },
    {
      "x": -3,
      "y": 19,
      "z": 0,
      "name": "Soil_Dirt_White"
    },
    {
      "x": -3,
      "y": 20,
      "z": 0,
      "name": "Soil_Grass_Full"
    },
    {
      "x": -3,
      "y": 40,
      "z": 0,
      "name": "Rock_Marble_Brick_Smooth"
    },
    {
      "x": -3,
      "y": 41,
      "z": 0,
      "name": "Rock_Marble_Brick_Smooth"
    },
    {
      "x": -3,
      "y": 4,
      "z": 1,
      "name": "Rock_Chalk",
      "rotation": 3
    },
    {
      "x": -3,
      "y": 5,
      "z": 1,
      "name": "Rock_Chalk",
      "rotation": 3
    },
    {
      "x": -3,
      "y": 6,
      "z": 1,
      "name": "Rock_Chalk",
      "rotation": 3
    },
    {
      "x": -3,
      "y": 7,
      "z": 1,
      "name": "Rock_Chalk",
      "rotation": 3
    },
    {
      "x": -3,
      "y": 8,
      "z": 1,
      "name": "Rock_Chalk",
      "rotation": 3
    },
    {
      "x": -3,
      "y": 9,
      "z": 1,
      "name": "Rock_Chalk",
      "rotation": 3
    },
    {
      "x": -3,
      "y": 10,
      "z": 1,
      "name": "Rock_Chalk",
      "rotation": 3
    },
    {
      "x": -3,
      "y": 11,
      "z": 1,
      "name": "Rock_Chalk",
      "rotation": 3
    },
    {
      "x": -3,
      "y": 12,
      "z": 1,
      "name": "Rock_Chalk",
      "rotation": 3
    },
    {
      "x": -3,
      "y": 13,
      "z": 1,
      "name": "Rock_Chalk",
      "rotation": 3
    },
    {
      "x": -3,
      "y": 14,
      "z": 1,
      "name": "Rock_Chalk",
      "rotation": 3
    },
    {
      "x": -3,
      "y": 15,
      "z": 1,
      "name": "Rock_Chalk",
      "rotation": 3
    },
    {
      "x": -3,
      "y": 16,
      "z": 1,
      "name": "Rock_Chalk",
      "rotation": 3
    },
    {
      "x": -3,
      "y": 17,
      "z": 1,
      "name": "Rock_Chalk"
    },
    {
      "x": -3,
      "y": 18,
      "z": 1,
      "name": "Rock_Chalk"
    },
    {
      "x": -3,
      "y": 19,
      "z": 1,
      "name": "Soil_Dirt_White"
    },
    {
      "x": -3,
      "y": 20,
      "z": 1,
      "name": "Soil_Grass_Full"
    },
    {
      "x": -3,
      "y": 40,
      "z": 1,
      "name": "Rock_Marble_Brick_Smooth"
    },
    {
      "x": -3,
      "y": 41,
      "z": 1,
      "name": "Rock_Marble_Brick_Smooth"
    },
    {
      "x": -3,
      "y": 42,
      "z": 1,
      "name": "Plant_Moss_Rug_Green_Dark"
    },
    {
      "x": -3,
      "y": 4,
      "z": 2,
      "name": "Rock_Chalk",
      "rotation": 3
    },
    {
      "x": -3,
      "y": 5,
      "z": 2,
      "name": "Rock_Chalk",
      "rotation": 3
    },
    {
      "x": -3,
      "y": 6,
      "z": 2,
      "name": "Rock_Chalk",
      "rotation": 3
    },
    {
      "x": -3,
      "y": 7,
      "z": 2,
      "name": "Rock_Chalk",
      "rotation": 3
    },
    {
      "x": -3,
      "y": 8,
      "z": 2,
      "name": "Rock_Chalk",
      "rotation": 3
    },
    {
      "x": -3,
      "y": 9,
      "z": 2,
      "name": "Rock_Chalk",
      "rotation": 3
    },
    {
      "x": -3,
      "y": 10,
      "z": 2,
      "name": "Rock_Chalk",
      "rotation": 3
    },
    {
      "x": -3,
      "y": 11,
      "z": 2,
      "name": "Rock_Chalk",
      "rotation": 3
    },
    {
      "x": -3,
      "y": 12,
      "z": 2,
      "name": "Rock_Chalk",
      "rotation": 3
    },
    {
      "x": -3,
      "y": 13,
      "z": 2,
      "name": "Rock_Chalk",
      "rotation": 3
    },
    {
      "x": -3,
      "y": 14,
      "z": 2,
      "name": "Rock_Chalk",
      "rotation": 3
    },
    {
      "x": -3,
      "y": 15,
      "z": 2,
      "name": "Rock_Chalk",
      "rotation": 3
    },
    {
      "x": -3,
      "y": 16,
      "z": 2,
      "name": "Rock_Chalk",
      "rotation": 3
    },
    {
      "x": -3,
      "y": 17,
      "z": 2,
      "name": "Rock_Chalk"
    },
    {
      "x": -3,
      "y": 18,
      "z": 2,
      "name": "Rock_Chalk"
    },
    {
      "x": -3,
      "y": 19,
      "z": 2,
      "name": "Soil_Dirt_White"
    },
    {
      "x": -3,
      "y": 20,
      "z": 2,
      "name": "Soil_Grass_Full"
    },
    {
      "x": -3,
      "y": 40,
      "z": 2,
      "name": "Rock_Marble_Brick_Smooth"
    },
    {
      "x": -3,
      "y": 41,
      "z": 2,
      "name": "Rock_Marble_Brick_Smooth"
    },
    {
      "x": -3,
      "y": 42,
      "z": 2,
      "name": "Plant_Moss_Rug_Green_Dark"
    },
    {
      "x": -3,
      "y": 5,
      "z": 3,
      "name": "Rock_Chalk",
      "rotation": 3
    },
    {
      "x": -3,
      "y": 6,
      "z": 3,
      "name": "Rock_Chalk",
      "rotation": 3
    },
    {
      "x": -3,
      "y": 7,
      "z": 3,
      "name": "Rock_Chalk",
      "rotation": 3
    },
    {
      "x": -3,
      "y": 8,
      "z": 3,
      "name": "Rock_Chalk",
      "rotation": 3
    },
    {
      "x": -3,
      "y": 9,
      "z": 3,
      "name": "Rock_Chalk",
      "rotation": 3
    },
    {
      "x": -3,
      "y": 10,
      "z": 3,
      "name": "Rock_Chalk",
      "rotation": 3
    },
    {
      "x": -3,
      "y": 11,
      "z": 3,
      "name": "Rock_Chalk",
      "rotation": 3
    },
    {
      "x": -3,
      "y": 12,
      "z": 3,
      "name": "Rock_Chalk",
      "rotation": 3
    },
    {
      "x": -3,
      "y": 13,
      "z": 3,
      "name": "Rock_Chalk",
      "rotation": 3
    },
    {
      "x": -3,
      "y": 14,
      "z": 3,
      "name": "Rock_Chalk",
      "rotation": 3
    },
    {
      "x": -3,
      "y": 15,
      "z": 3,
      "name": "Rock_Chalk",
      "rotation": 3
    },
    {
      "x": -3,
      "y": 16,
      "z": 3,
      "name": "Rock_Chalk",
      "rotation": 3
    },
    {
      "x": -3,
      "y": 17,
      "z": 3,
      "name": "Soil_Dirt_White"
    },
    {
      "x": -3,
      "y": 18,
      "z": 3,
      "name": "Soil_Dirt_White"
    },
    {
      "x": -3,
      "y": 19,
      "z": 3,
      "name": "Soil_Dirt_White"
    },
    {
      "x": -3,
      "y": 20,
      "z": 3,
      "name": "Soil_Grass_Full"
    },
    {
      "x": -3,
      "y": 7,
      "z": 4,
      "name": "Rock_Chalk",
      "rotation": 3
    },
    {
      "x": -3,
      "y": 8,
      "z": 4,
      "name": "Rock_Chalk",
      "rotation": 3
    },
    {
      "x": -3,
      "y": 9,
      "z": 4,
      "name": "Rock_Chalk",
      "rotation": 3
    },
    {
      "x": -3,
      "y": 10,
      "z": 4,
      "name": "Rock_Chalk",
      "rotation": 3
    },
    {
      "x": -3,
      "y": 11,
      "z": 4,
      "name": "Rock_Chalk",
      "rotation": 3
    },
    {
      "x": -3,
      "y": 12,
      "z": 4,
      "name": "Rock_Chalk",
      "rotation": 3
    },
    {
      "x": -3,
      "y": 13,
      "z": 4,
      "name": "Rock_Chalk",
      "rotation": 3
    },
    {
      "x": -3,
      "y": 14,
      "z": 4,
      "name": "Rock_Chalk",
      "rotation": 3
    },
    {
      "x": -3,
      "y": 15,
      "z": 4,
      "name": "Rock_Chalk",
      "rotation": 3
    },
    {
      "x": -3,
      "y": 16,
      "z": 4,
      "name": "Rock_Chalk",
      "rotation": 3
    },
    {
      "x": -3,
      "y": 17,
      "z": 4,
      "name": "Soil_Dirt_White"
    },
    {
      "x": -3,
      "y": 18,
      "z": 4,
      "name": "Soil_Dirt_White"
    },
    {
      "x": -3,
      "y": 19,
      "z": 4,
      "name": "Rock_Marble"
    },
    {
      "x": -3,
      "y": 9,
      "z": 5,
      "name": "Rock_Chalk",
      "rotation": 3
    },
    {
      "x": -3,
      "y": 10,
      "z": 5,
      "name": "Rock_Chalk",
      "rotation": 3
    },
    {
      "x": -3,
      "y": 11,
      "z": 5,
      "name": "Rock_Chalk",
      "rotation": 3
    },
    {
      "x": -3,
      "y": 12,
      "z": 5,
      "name": "Rock_Chalk",
      "rotation": 3
    },
    {
      "x": -3,
      "y": 13,
      "z": 5,
      "name": "Rock_Chalk",
      "rotation": 3
    },
    {
      "x": -3,
      "y": 14,
      "z": 5,
      "name": "Rock_Chalk",
      "rotation": 3
    },
    {
      "x": -3,
      "y": 15,
      "z": 5,
      "name": "Rock_Chalk",
      "rotation": 3
    },
    {
      "x": -3,
      "y": 16,
      "z": 5,
      "name": "Soil_Dirt_White"
    },
    {
      "x": -3,
      "y": 17,
      "z": 5,
      "name": "Soil_Dirt_White"
    },
    {
      "x": -3,
      "y": 18,
      "z": 5,
      "name": "Soil_Dirt_White"
    },
    {
      "x": -3,
      "y": 19,
      "z": 5,
      "name": "Soil_Grass_White"
    },
    {
      "x": -3,
      "y": 9,
      "z": 6,
      "name": "Rock_Chalk",
      "rotation": 3
    },
    {
      "x": -3,
      "y": 10,
      "z": 6,
      "name": "Rock_Chalk",
      "rotation": 3
    },
    {
      "x": -3,
      "y": 11,
      "z": 6,
      "name": "Rock_Chalk",
      "rotation": 3
    },
    {
      "x": -3,
      "y": 12,
      "z": 6,
      "name": "Rock_Chalk",
      "rotation": 3
    },
    {
      "x": -3,
      "y": 13,
      "z": 6,
      "name": "Rock_Chalk",
      "rotation": 3
    },
    {
      "x": -3,
      "y": 14,
      "z": 6,
      "name": "Rock_Chalk",
      "rotation": 3
    },
    {
      "x": -3,
      "y": 15,
      "z": 6,
      "name": "Rock_Chalk",
      "rotation": 3
    },
    {
      "x": -3,
      "y": 16,
      "z": 6,
      "name": "Rock_Chalk"
    },
    {
      "x": -3,
      "y": 17,
      "z": 6,
      "name": "Rock_Chalk"
    },
    {
      "x": -3,
      "y": 18,
      "z": 6,
      "name": "Soil_Dirt_White"
    },
    {
      "x": -3,
      "y": 19,
      "z": 6,
      "name": "Soil_Grass_Full"
    },
    {
      "x": -3,
      "y": 11,
      "z": 7,
      "name": "Rock_Chalk",
      "rotation": 3
    },
    {
      "x": -3,
      "y": 12,
      "z": 7,
      "name": "Rock_Chalk",
      "rotation": 3
    },
    {
      "x": -3,
      "y": 13,
      "z": 7,
      "name": "Rock_Chalk",
      "rotation": 3
    },
    {
      "x": -3,
      "y": 14,
      "z": 7,
      "name": "Rock_Chalk",
      "rotation": 3
    },
    {
      "x": -3,
      "y": 15,
      "z": 7,
      "name": "Rock_Chalk",
      "rotation": 3
    },
    {
      "x": -3,
      "y": 16,
      "z": 7,
      "name": "Rock_Chalk",
      "rotation": 3
    },
    {
      "x": -3,
      "y": 17,
      "z": 7,
      "name": "Soil_Dirt_White"
    },
    {
      "x": -3,
      "y": 18,
      "z": 7,
      "name": "Soil_Grass_Full"
    },
    {
      "x": -3,
      "y": 14,
      "z": 8,
      "name": "Rock_Chalk",
      "rotation": 3
    },
    {
      "x": -3,
      "y": 15,
      "z": 8,
      "name": "Rock_Chalk",
      "rotation": 3
    },
    {
      "x": -3,
      "y": 16,
      "z": 8,
      "name": "Rock_Chalk",
      "rotation": 3
    },
    {
      "x": -3,
      "y": 17,
      "z": 8,
      "name": "Soil_Dirt_White",
      "rotation": 3
    },
    {
      "x": -3,
      "y": 18,
      "z": 8,
      "name": "Soil_Grass_Full"
    },
    {
      "x": -2,
      "y": 12,
      "z": -6,
      "name": "Rock_Chalk",
      "rotation": 3
    },
    {
      "x": -2,
      "y": 13,
      "z": -6,
      "name": "Rock_Chalk",
      "rotation": 3
    },
    {
      "x": -2,
      "y": 14,
      "z": -6,
      "name": "Rock_Chalk",
      "rotation": 3
    },
    {
      "x": -2,
      "y": 15,
      "z": -6,
      "name": "Soil_Dirt_White",
      "rotation": 3
    },
    {
      "x": -2,
      "y": 16,
      "z": -6,
      "name": "Soil_Grass_Full",
      "rotation": 3
    },
    {
      "x": -2,
      "y": 6,
      "z": -5,
      "name": "Rock_Chalk",
      "rotation": 3
    },
    {
      "x": -2,
      "y": 7,
      "z": -5,
      "name": "Rock_Chalk",
      "rotation": 3
    },
    {
      "x": -2,
      "y": 8,
      "z": -5,
      "name": "Rock_Chalk",
      "rotation": 3
    },
    {
      "x": -2,
      "y": 9,
      "z": -5,
      "name": "Rock_Chalk",
      "rotation": 3
    },
    {
      "x": -2,
      "y": 10,
      "z": -5,
      "name": "Rock_Chalk",
      "rotation": 3
    },
    {
      "x": -2,
      "y": 11,
      "z": -5,
      "name": "Rock_Chalk",
      "rotation": 3
    },
    {
      "x": -2,
      "y": 12,
      "z": -5,
      "name": "Rock_Chalk",
      "rotation": 3
    },
    {
      "x": -2,
      "y": 13,
      "z": -5,
      "name": "Rock_Chalk",
      "rotation": 3
    },
    {
      "x": -2,
      "y": 14,
      "z": -5,
      "name": "Rock_Chalk",
      "rotation": 3
    },
    {
      "x": -2,
      "y": 15,
      "z": -5,
      "name": "Rock_Chalk",
      "rotation": 3
    },
    {
      "x": -2,
      "y": 16,
      "z": -5,
      "name": "Rock_Chalk",
      "rotation": 3
    },
    {
      "x": -2,
      "y": 17,
      "z": -5,
      "name": "Soil_Dirt_White",
      "rotation": 3
    },
    {
      "x": -2,
      "y": 18,
      "z": -5,
      "name": "Soil_Grass_Full",
      "rotation": 3
    },
    {
      "x": -2,
      "y": 5,
      "z": -4,
      "name": "Rock_Chalk",
      "rotation": 3
    },
    {
      "x": -2,
      "y": 6,
      "z": -4,
      "name": "Rock_Chalk",
      "rotation": 3
    },
    {
      "x": -2,
      "y": 7,
      "z": -4,
      "name": "Rock_Chalk",
      "rotation": 3
    },
    {
      "x": -2,
      "y": 8,
      "z": -4,
      "name": "Rock_Chalk",
      "rotation": 3
    },
    {
      "x": -2,
      "y": 9,
      "z": -4,
      "name": "Rock_Chalk",
      "rotation": 3
    },
    {
      "x": -2,
      "y": 10,
      "z": -4,
      "name": "Rock_Chalk",
      "rotation": 3
    },
    {
      "x": -2,
      "y": 11,
      "z": -4,
      "name": "Rock_Chalk",
      "rotation": 3
    },
    {
      "x": -2,
      "y": 12,
      "z": -4,
      "name": "Rock_Chalk",
      "rotation": 3
    },
    {
      "x": -2,
      "y": 13,
      "z": -4,
      "name": "Rock_Chalk",
      "rotation": 3
    },
    {
      "x": -2,
      "y": 14,
      "z": -4,
      "name": "Rock_Chalk",
      "rotation": 3
    },
    {
      "x": -2,
      "y": 15,
      "z": -4,
      "name": "Rock_Chalk",
      "rotation": 3
    },
    {
      "x": -2,
      "y": 16,
      "z": -4,
      "name": "Rock_Chalk",
      "rotation": 3
    },
    {
      "x": -2,
      "y": 17,
      "z": -4,
      "name": "Rock_Chalk",
      "rotation": 3
    },
    {
      "x": -2,
      "y": 18,
      "z": -4,
      "name": "Soil_Dirt_White"
    },
    {
      "x": -2,
      "y": 19,
      "z": -4,
      "name": "Soil_Grass_Full"
    },
    {
      "x": -2,
      "y": 4,
      "z": -3,
      "name": "Rock_Chalk",
      "rotation": 3
    },
    {
      "x": -2,
      "y": 5,
      "z": -3,
      "name": "Rock_Chalk",
      "rotation": 3
    },
    {
      "x": -2,
      "y": 6,
      "z": -3,
      "name": "Rock_Chalk",
      "rotation": 3
    },
    {
      "x": -2,
      "y": 7,
      "z": -3,
      "name": "Rock_Chalk",
      "rotation": 3
    },
    {
      "x": -2,
      "y": 8,
      "z": -3,
      "name": "Rock_Chalk",
      "rotation": 3
    },
    {
      "x": -2,
      "y": 9,
      "z": -3,
      "name": "Rock_Chalk",
      "rotation": 3
    },
    {
      "x": -2,
      "y": 10,
      "z": -3,
      "name": "Rock_Chalk",
      "rotation": 3
    },
    {
      "x": -2,
      "y": 11,
      "z": -3,
      "name": "Rock_Chalk",
      "rotation": 3
    },
    {
      "x": -2,
      "y": 12,
      "z": -3,
      "name": "Rock_Chalk",
      "rotation": 3
    },
    {
      "x": -2,
      "y": 13,
      "z": -3,
      "name": "Rock_Chalk",
      "rotation": 3
    },
    {
      "x": -2,
      "y": 14,
      "z": -3,
      "name": "Rock_Chalk",
      "rotation": 3
    },
    {
      "x": -2,
      "y": 15,
      "z": -3,
      "name": "Rock_Chalk",
      "rotation": 3
    },
    {
      "x": -2,
      "y": 16,
      "z": -3,
      "name": "Rock_Chalk",
      "rotation": 3
    },
    {
      "x": -2,
      "y": 17,
      "z": -3,
      "name": "Soil_Dirt_White"
    },
    {
      "x": -2,
      "y": 18,
      "z": -3,
      "name": "Rock_Chalk"
    },
    {
      "x": -2,
      "y": 19,
      "z": -3,
      "name": "Soil_Dirt_White"
    },
    {
      "x": -2,
      "y": 20,
      "z": -3,
      "name": "Soil_Grass_Full"
    },
    {
      "x": -2,
      "y": 3,
      "z": -2,
      "name": "Rock_Chalk",
      "rotation": 3
    },
    {
      "x": -2,
      "y": 4,
      "z": -2,
      "name": "Rock_Chalk",
      "rotation": 3
    },
    {
      "x": -2,
      "y": 5,
      "z": -2,
      "name": "Rock_Chalk",
      "rotation": 3
    },
    {
      "x": -2,
      "y": 6,
      "z": -2,
      "name": "Rock_Chalk",
      "rotation": 3
    },
    {
      "x": -2,
      "y": 7,
      "z": -2,
      "name": "Rock_Chalk",
      "rotation": 3
    },
    {
      "x": -2,
      "y": 8,
      "z": -2,
      "name": "Rock_Chalk",
      "rotation": 3
    },
    {
      "x": -2,
      "y": 9,
      "z": -2,
      "name": "Rock_Chalk",
      "rotation": 3
    },
    {
      "x": -2,
      "y": 10,
      "z": -2,
      "name": "Rock_Chalk",
      "rotation": 3
    },
    {
      "x": -2,
      "y": 11,
      "z": -2,
      "name": "Rock_Chalk",
      "rotation": 3
    },
    {
      "x": -2,
      "y": 12,
      "z": -2,
      "name": "Rock_Chalk",
      "rotation": 3
    },
    {
      "x": -2,
      "y": 13,
      "z": -2,
      "name": "Rock_Chalk",
      "rotation": 3
    },
    {
      "x": -2,
      "y": 14,
      "z": -2,
      "name": "Rock_Chalk",
      "rotation": 3
    },
    {
      "x": -2,
      "y": 15,
      "z": -2,
      "name": "Rock_Chalk",
      "rotation": 3
    },
    {
      "x": -2,
      "y": 16,
      "z": -2,
      "name": "Rock_Chalk",
      "rotation": 3
    },
    {
      "x": -2,
      "y": 17,
      "z": -2,
      "name": "Soil_Dirt_White"
    },
    {
      "x": -2,
      "y": 18,
      "z": -2,
      "name": "Rock_Chalk"
    },
    {
      "x": -2,
      "y": 19,
      "z": -2,
      "name": "Soil_Dirt_White"
    },
    {
      "x": -2,
      "y": 20,
      "z": -2,
      "name": "Soil_Grass_Full"
    },
    {
      "x": -2,
      "y": 3,
      "z": -1,
      "name": "Rock_Chalk",
      "rotation": 3
    },
    {
      "x": -2,
      "y": 4,
      "z": -1,
      "name": "Rock_Chalk",
      "rotation": 3
    },
    {
      "x": -2,
      "y": 5,
      "z": -1,
      "name": "Rock_Chalk",
      "rotation": 3
    },
    {
      "x": -2,
      "y": 6,
      "z": -1,
      "name": "Rock_Chalk",
      "rotation": 3
    },
    {
      "x": -2,
      "y": 7,
      "z": -1,
      "name": "Rock_Chalk",
      "rotation": 3
    },
    {
      "x": -2,
      "y": 8,
      "z": -1,
      "name": "Rock_Chalk",
      "rotation": 3
    },
    {
      "x": -2,
      "y": 9,
      "z": -1,
      "name": "Rock_Chalk",
      "rotation": 3
    },
    {
      "x": -2,
      "y": 10,
      "z": -1,
      "name": "Rock_Chalk",
      "rotation": 3
    },
    {
      "x": -2,
      "y": 11,
      "z": -1,
      "name": "Rock_Chalk",
      "rotation": 3
    },
    {
      "x": -2,
      "y": 12,
      "z": -1,
      "name": "Rock_Chalk",
      "rotation": 3
    },
    {
      "x": -2,
      "y": 13,
      "z": -1,
      "name": "Rock_Chalk",
      "rotation": 3
    },
    {
      "x": -2,
      "y": 14,
      "z": -1,
      "name": "Rock_Chalk",
      "rotation": 3
    },
    {
      "x": -2,
      "y": 15,
      "z": -1,
      "name": "Rock_Chalk",
      "rotation": 3
    },
    {
      "x": -2,
      "y": 16,
      "z": -1,
      "name": "Rock_Chalk",
      "rotation": 3
    },
    {
      "x": -2,
      "y": 17,
      "z": -1,
      "name": "Soil_Dirt_White"
    },
    {
      "x": -2,
      "y": 18,
      "z": -1,
      "name": "Rock_Chalk"
    },
    {
      "x": -2,
      "y": 19,
      "z": -1,
      "name": "Soil_Dirt_White"
    },
    {
      "x": -2,
      "y": 20,
      "z": -1,
      "name": "Soil_Grass_Full"
    },
    {
      "x": -2,
      "y": 3,
      "z": 0,
      "name": "Rock_Chalk",
      "rotation": 3
    },
    {
      "x": -2,
      "y": 4,
      "z": 0,
      "name": "Rock_Chalk",
      "rotation": 3
    },
    {
      "x": -2,
      "y": 5,
      "z": 0,
      "name": "Rock_Chalk",
      "rotation": 3
    },
    {
      "x": -2,
      "y": 6,
      "z": 0,
      "name": "Rock_Chalk",
      "rotation": 3
    },
    {
      "x": -2,
      "y": 7,
      "z": 0,
      "name": "Rock_Chalk",
      "rotation": 3
    },
    {
      "x": -2,
      "y": 8,
      "z": 0,
      "name": "Rock_Chalk",
      "rotation": 3
    },
    {
      "x": -2,
      "y": 9,
      "z": 0,
      "name": "Rock_Chalk",
      "rotation": 3
    },
    {
      "x": -2,
      "y": 10,
      "z": 0,
      "name": "Rock_Chalk",
      "rotation": 3
    },
    {
      "x": -2,
      "y": 11,
      "z": 0,
      "name": "Rock_Chalk",
      "rotation": 3
    },
    {
      "x": -2,
      "y": 12,
      "z": 0,
      "name": "Rock_Chalk",
      "rotation": 3
    },
    {
      "x": -2,
      "y": 13,
      "z": 0,
      "name": "Rock_Chalk",
      "rotation": 3
    },
    {
      "x": -2,
      "y": 14,
      "z": 0,
      "name": "Rock_Chalk",
      "rotation": 3
    },
    {
      "x": -2,
      "y": 15,
      "z": 0,
      "name": "Rock_Chalk",
      "rotation": 3
    },
    {
      "x": -2,
      "y": 16,
      "z": 0,
      "name": "Rock_Chalk",
      "rotation": 3
    },
    {
      "x": -2,
      "y": 17,
      "z": 0,
      "name": "Rock_Chalk"
    },
    {
      "x": -2,
      "y": 18,
      "z": 0,
      "name": "Rock_Chalk"
    },
    {
      "x": -2,
      "y": 19,
      "z": 0,
      "name": "Soil_Dirt_White"
    },
    {
      "x": -2,
      "y": 20,
      "z": 0,
      "name": "Soil_Grass_Full"
    },
    {
      "x": -2,
      "y": 2,
      "z": 1,
      "name": "Rock_Chalk",
      "rotation": 3
    },
    {
      "x": -2,
      "y": 3,
      "z": 1,
      "name": "Rock_Chalk",
      "rotation": 3
    },
    {
      "x": -2,
      "y": 4,
      "z": 1,
      "name": "Rock_Chalk",
      "rotation": 3
    },
    {
      "x": -2,
      "y": 5,
      "z": 1,
      "name": "Rock_Chalk",
      "rotation": 3
    },
    {
      "x": -2,
      "y": 6,
      "z": 1,
      "name": "Rock_Chalk",
      "rotation": 3
    },
    {
      "x": -2,
      "y": 7,
      "z": 1,
      "name": "Rock_Chalk",
      "rotation": 3
    },
    {
      "x": -2,
      "y": 8,
      "z": 1,
      "name": "Rock_Chalk",
      "rotation": 3
    },
    {
      "x": -2,
      "y": 9,
      "z": 1,
      "name": "Rock_Chalk",
      "rotation": 3
    },
    {
      "x": -2,
      "y": 10,
      "z": 1,
      "name": "Rock_Chalk",
      "rotation": 3
    },
    {
      "x": -2,
      "y": 11,
      "z": 1,
      "name": "Rock_Chalk",
      "rotation": 3
    },
    {
      "x": -2,
      "y": 12,
      "z": 1,
      "name": "Rock_Chalk",
      "rotation": 3
    },
    {
      "x": -2,
      "y": 13,
      "z": 1,
      "name": "Rock_Chalk",
      "rotation": 3
    },
    {
      "x": -2,
      "y": 14,
      "z": 1,
      "name": "Rock_Chalk",
      "rotation": 3
    },
    {
      "x": -2,
      "y": 15,
      "z": 1,
      "name": "Rock_Chalk",
      "rotation": 3
    },
    {
      "x": -2,
      "y": 16,
      "z": 1,
      "name": "Rock_Chalk"
    },
    {
      "x": -2,
      "y": 17,
      "z": 1,
      "name": "Rock_Chalk"
    },
    {
      "x": -2,
      "y": 18,
      "z": 1,
      "name": "Rock_Chalk"
    },
    {
      "x": -2,
      "y": 19,
      "z": 1,
      "name": "Soil_Dirt_White"
    },
    {
      "x": -2,
      "y": 20,
      "z": 1,
      "name": "Soil_Grass_Full"
    },
    {
      "x": -2,
      "y": 40,
      "z": 1,
      "name": "Rock_Marble_Brick_Smooth"
    },
    {
      "x": -2,
      "y": 41,
      "z": 1,
      "name": "Rock_Marble_Brick_Smooth"
    },
    {
      "x": -2,
      "y": 42,
      "z": 1,
      "name": "Plant_Moss_Rug_Green_Dark"
    },
    {
      "x": -2,
      "y": 3,
      "z": 2,
      "name": "Rock_Chalk",
      "rotation": 3
    },
    {
      "x": -2,
      "y": 4,
      "z": 2,
      "name": "Rock_Chalk",
      "rotation": 3
    },
    {
      "x": -2,
      "y": 5,
      "z": 2,
      "name": "Rock_Chalk",
      "rotation": 3
    },
    {
      "x": -2,
      "y": 6,
      "z": 2,
      "name": "Rock_Chalk",
      "rotation": 3
    },
    {
      "x": -2,
      "y": 7,
      "z": 2,
      "name": "Rock_Chalk",
      "rotation": 3
    },
    {
      "x": -2,
      "y": 8,
      "z": 2,
      "name": "Rock_Chalk",
      "rotation": 3
    },
    {
      "x": -2,
      "y": 9,
      "z": 2,
      "name": "Rock_Chalk",
      "rotation": 3
    },
    {
      "x": -2,
      "y": 10,
      "z": 2,
      "name": "Rock_Chalk",
      "rotation": 3
    },
    {
      "x": -2,
      "y": 11,
      "z": 2,
      "name": "Rock_Chalk",
      "rotation": 3
    },
    {
      "x": -2,
      "y": 12,
      "z": 2,
      "name": "Rock_Chalk",
      "rotation": 3
    },
    {
      "x": -2,
      "y": 13,
      "z": 2,
      "name": "Rock_Chalk",
      "rotation": 3
    },
    {
      "x": -2,
      "y": 14,
      "z": 2,
      "name": "Rock_Chalk",
      "rotation": 3
    },
    {
      "x": -2,
      "y": 15,
      "z": 2,
      "name": "Rock_Chalk",
      "rotation": 3
    },
    {
      "x": -2,
      "y": 16,
      "z": 2,
      "name": "Rock_Chalk",
      "rotation": 3
    },
    {
      "x": -2,
      "y": 17,
      "z": 2,
      "name": "Rock_Chalk"
    },
    {
      "x": -2,
      "y": 18,
      "z": 2,
      "name": "Rock_Chalk"
    },
    {
      "x": -2,
      "y": 19,
      "z": 2,
      "name": "Soil_Dirt_White"
    },
    {
      "x": -2,
      "y": 20,
      "z": 2,
      "name": "Soil_Grass_Full"
    },
    {
      "x": -2,
      "y": 40,
      "z": 2,
      "name": "Rock_Marble_Brick_Smooth"
    },
    {
      "x": -2,
      "y": 41,
      "z": 2,
      "name": "Rock_Marble_Brick_Smooth"
    },
    {
      "x": -2,
      "y": 42,
      "z": 2,
      "name": "Plant_Moss_Rug_Green_Dark"
    },
    {
      "x": -2,
      "y": 4,
      "z": 3,
      "name": "Rock_Chalk",
      "rotation": 3
    },
    {
      "x": -2,
      "y": 5,
      "z": 3,
      "name": "Rock_Chalk",
      "rotation": 3
    },
    {
      "x": -2,
      "y": 6,
      "z": 3,
      "name": "Rock_Chalk",
      "rotation": 3
    },
    {
      "x": -2,
      "y": 7,
      "z": 3,
      "name": "Rock_Chalk",
      "rotation": 3
    },
    {
      "x": -2,
      "y": 8,
      "z": 3,
      "name": "Rock_Chalk",
      "rotation": 3
    },
    {
      "x": -2,
      "y": 9,
      "z": 3,
      "name": "Rock_Chalk",
      "rotation": 3
    },
    {
      "x": -2,
      "y": 10,
      "z": 3,
      "name": "Rock_Chalk",
      "rotation": 3
    },
    {
      "x": -2,
      "y": 11,
      "z": 3,
      "name": "Rock_Chalk",
      "rotation": 3
    },
    {
      "x": -2,
      "y": 12,
      "z": 3,
      "name": "Rock_Chalk",
      "rotation": 3
    },
    {
      "x": -2,
      "y": 13,
      "z": 3,
      "name": "Rock_Chalk",
      "rotation": 3
    },
    {
      "x": -2,
      "y": 14,
      "z": 3,
      "name": "Rock_Chalk",
      "rotation": 3
    },
    {
      "x": -2,
      "y": 15,
      "z": 3,
      "name": "Rock_Chalk",
      "rotation": 3
    },
    {
      "x": -2,
      "y": 16,
      "z": 3,
      "name": "Rock_Chalk",
      "rotation": 3
    },
    {
      "x": -2,
      "y": 17,
      "z": 3,
      "name": "Rock_Chalk"
    },
    {
      "x": -2,
      "y": 18,
      "z": 3,
      "name": "Soil_Dirt_White"
    },
    {
      "x": -2,
      "y": 19,
      "z": 3,
      "name": "Soil_Dirt_White"
    },
    {
      "x": -2,
      "y": 20,
      "z": 3,
      "name": "Soil_Grass_Full"
    },
    {
      "x": -2,
      "y": 7,
      "z": 4,
      "name": "Rock_Chalk",
      "rotation": 3
    },
    {
      "x": -2,
      "y": 8,
      "z": 4,
      "name": "Rock_Chalk",
      "rotation": 3
    },
    {
      "x": -2,
      "y": 9,
      "z": 4,
      "name": "Rock_Chalk",
      "rotation": 3
    },
    {
      "x": -2,
      "y": 10,
      "z": 4,
      "name": "Rock_Chalk",
      "rotation": 3
    },
    {
      "x": -2,
      "y": 11,
      "z": 4,
      "name": "Rock_Chalk",
      "rotation": 3
    },
    {
      "x": -2,
      "y": 12,
      "z": 4,
      "name": "Rock_Chalk",
      "rotation": 3
    },
    {
      "x": -2,
      "y": 13,
      "z": 4,
      "name": "Rock_Chalk",
      "rotation": 3
    },
    {
      "x": -2,
      "y": 14,
      "z": 4,
      "name": "Rock_Chalk",
      "rotation": 3
    },
    {
      "x": -2,
      "y": 15,
      "z": 4,
      "name": "Rock_Chalk",
      "rotation": 3
    },
    {
      "x": -2,
      "y": 16,
      "z": 4,
      "name": "Soil_Dirt_White"
    },
    {
      "x": -2,
      "y": 17,
      "z": 4,
      "name": "Soil_Dirt_White"
    },
    {
      "x": -2,
      "y": 18,
      "z": 4,
      "name": "Soil_Dirt_White"
    },
    {
      "x": -2,
