{
  "version": 8,
  "blockIdVersion": 11,
  "anchorX": 0,
  "anchorY": 0,
  "anchorZ": 0,
  "blocks": [
    {
      "x": -7,
      "y": 12,
      "z": -5,
      "name": "Soil_Dirt_White"
    },
    {
      "x": -7,
      "y": 13,
      "z": -5,
      "name": "Soil_Grass_Full"
    },
    {
      "x": -7,
      "y": 12,
      "z": -4,
      "name": "Soil_Dirt_White"
    },
    {
      "x": -7,
      "y": 13,
      "z": -4,
      "name": "Soil_Grass_Full"
    },
    {
      "x": -7,
      "y": 12,
      "z": -3,
      "name": "Soil_Dirt_White"
    },
    {
      "x": -7,
      "y": 13,
      "z": -3,
      "name": "Soil_Grass_Full"
    },
    {
      "x": -7,
      "y": 13,
      "z": -2,
      "name": "Soil_Grass_Full"
    },
    {
      "x": -6,
      "y": 12,
      "z": -8,
      "name": "Rock_Chalk"
    },
    {
      "x": -6,
      "y": 11,
      "z": -7,
      "name": "Rock_Chalk"
    },
    {
      "x": -6,
      "y": 12,
      "z": -7,
      "name": "Soil_Dirt_White"
    },
    {
      "x": -6,
      "y": 13,
      "z": -7,
      "name": "Soil_Grass_Full"
    },
    {
      "x": -6,
      "y": 10,
      "z": -6,
      "name": "Rock_Chalk"
    },
    {
      "x": -6,
      "y": 11,
      "z": -6,
      "name": "Rock_Chalk"
    },
    {
      "x": -6,
      "y": 12,
      "z": -6,
      "name": "Rock_Chalk"
    },
    {
      "x": -6,
      "y": 13,
      "z": -6,
      "name": "Soil_Dirt_White"
    },
    {
      "x": -6,
      "y": 14,
      "z": -6,
      "name": "Soil_Grass_Full"
    },
    {
      "x": -6,
      "y": 9,
      "z": -5,
      "name": "Rock_Chalk"
    },
    {
      "x": -6,
      "y": 10,
      "z": -5,
      "name": "Rock_Chalk"
    },
    {
      "x": -6,
      "y": 11,
      "z": -5,
      "name": "Rock_Chalk"
    },
    {
      "x": -6,
      "y": 12,
      "z": -5,
      "name": "Rock_Chalk"
    },
    {
      "x": -6,
      "y": 13,
      "z": -5,
      "name": "Soil_Dirt_White"
    },
    {
      "x": -6,
      "y": 14,
      "z": -5,
      "name": "Soil_Grass_Full"
    },
    {
      "x": -6,
      "y": 9,
      "z": -4,
      "name": "Rock_Chalk"
    },
    {
      "x": -6,
      "y": 10,
      "z": -4,
      "name": "Rock_Chalk"
    },
    {
      "x": -6,
      "y": 11,
      "z": -4,
      "name": "Rock_Chalk"
    },
    {
      "x": -6,
      "y": 12,
      "z": -4,
      "name": "Rock_Chalk"
    },
    {
      "x": -6,
      "y": 13,
      "z": -4,
      "name": "Soil_Dirt_White"
    },
    {
      "x": -6,
      "y": 14,
      "z": -4,
      "name": "Soil_Grass_Full"
    },
    {
      "x": -6,
      "y": 11,
      "z": -3,
      "name": "Rock_Chalk"
    },
    {
      "x": -6,
      "y": 12,
      "z": -3,
      "name": "Rock_Chalk"
    },
    {
      "x": -6,
      "y": 13,
      "z": -3,
      "name": "Soil_Dirt_White"
    },
    {
      "x": -6,
      "y": 14,
      "z": -3,
      "name": "Soil_Grass_Full"
    },
    {
      "x": -6,
      "y": 11,
      "z": -2,
      "name": "Rock_Chalk"
    },
    {
      "x": -6,
      "y": 12,
      "z": -2,
      "name": "Rock_Chalk"
    },
    {
      "x": -6,
      "y": 13,
      "z": -2,
      "name": "Soil_Dirt_White"
    },
    {
      "x": -6,
      "y": 14,
      "z": -2,
      "name": "Soil_Grass_Full"
    },
    {
      "x": -6,
      "y": 12,
      "z": -1,
      "name": "Soil_Dirt_White"
    },
    {
      "x": -6,
      "y": 13,
      "z": -1,
      "name": "Soil_Grass_Full"
    },
    {
      "x": -5,
      "y": 10,
      "z": -9,
      "name": "Rock_Chalk"
    },
    {
      "x": -5,
      "y": 11,
      "z": -9,
      "name": "Rock_Chalk"
    },
    {
      "x": -5,
      "y": 12,
      "z": -9,
      "name": "Rock_Chalk"
    },
    {
      "x": -5,
      "y": 13,
      "z": -9,
      "name": "Soil_Grass_Full"
    },
    {
      "x": -5,
      "y": 9,
      "z": -8,
      "name": "Rock_Chalk"
    },
    {
      "x": -5,
      "y": 10,
      "z": -8,
      "name": "Rock_Chalk"
    },
    {
      "x": -5,
      "y": 11,
      "z": -8,
      "name": "Rock_Chalk"
    },
    {
      "x": -5,
      "y": 12,
      "z": -8,
      "name": "Rock_Chalk"
    },
    {
      "x": -5,
      "y": 13,
      "z": -8,
      "name": "Soil_Dirt_White"
    },
    {
      "x": -5,
      "y": 14,
      "z": -8,
      "name": "Soil_Grass_Full"
    },
    {
      "x": -5,
      "y": 7,
      "z": -7,
      "name": "Rock_Chalk"
    },
    {
      "x": -5,
      "y": 8,
      "z": -7,
      "name": "Rock_Chalk"
    },
    {
      "x": -5,
      "y": 9,
      "z": -7,
      "name": "Rock_Chalk"
    },
    {
      "x": -5,
      "y": 10,
      "z": -7,
      "name": "Rock_Chalk"
    },
    {
      "x": -5,
      "y": 11,
      "z": -7,
      "name": "Rock_Chalk"
    },
    {
      "x": -5,
      "y": 12,
      "z": -7,
      "name": "Rock_Chalk"
    },
    {
      "x": -5,
      "y": 13,
      "z": -7,
      "name": "Soil_Dirt_White"
    },
    {
      "x": -5,
      "y": 14,
      "z": -7,
      "name": "Soil_Grass_Full"
    },
    {
      "x": -5,
      "y": 7,
      "z": -6,
      "name": "Rock_Chalk"
    },
    {
      "x": -5,
      "y": 8,
      "z": -6,
      "name": "Rock_Chalk"
    },
    {
      "x": -5,
      "y": 9,
      "z": -6,
      "name": "Rock_Chalk"
    },
    {
      "x": -5,
      "y": 10,
      "z": -6,
      "name": "Rock_Chalk"
    },
    {
      "x": -5,
      "y": 11,
      "z": -6,
      "name": "Rock_Chalk"
    },
    {
      "x": -5,
      "y": 12,
      "z": -6,
      "name": "Rock_Chalk"
    },
    {
      "x": -5,
      "y": 13,
      "z": -6,
      "name": "Soil_Dirt_White"
    },
    {
      "x": -5,
      "y": 14,
      "z": -6,
      "name": "Soil_Grass_Full"
    },
    {
      "x": -5,
      "y": 7,
      "z": -5,
      "name": "Rock_Chalk"
    },
    {
      "x": -5,
      "y": 8,
      "z": -5,
      "name": "Rock_Chalk"
    },
    {
      "x": -5,
      "y": 9,
      "z": -5,
      "name": "Rock_Chalk"
    },
    {
      "x": -5,
      "y": 10,
      "z": -5,
      "name": "Rock_Chalk"
    },
    {
      "x": -5,
      "y": 11,
      "z": -5,
      "name": "Rock_Chalk"
    },
    {
      "x": -5,
      "y": 12,
      "z": -5,
      "name": "Rock_Chalk"
    },
    {
      "x": -5,
      "y": 13,
      "z": -5,
      "name": "Soil_Dirt_White"
    },
    {
      "x": -5,
      "y": 14,
      "z": -5,
      "name": "Soil_Grass_Full"
    },
    {
      "x": -5,
      "y": 8,
      "z": -4,
      "name": "Rock_Chalk"
    },
    {
      "x": -5,
      "y": 9,
      "z": -4,
      "name": "Rock_Chalk"
    },
    {
      "x": -5,
      "y": 10,
      "z": -4,
      "name": "Rock_Chalk"
    },
    {
      "x": -5,
      "y": 11,
      "z": -4,
      "name": "Rock_Chalk"
    },
    {
      "x": -5,
      "y": 12,
      "z": -4,
      "name": "Rock_Chalk"
    },
    {
      "x": -5,
      "y": 13,
      "z": -4,
      "name": "Rock_Chalk"
    },
    {
      "x": -5,
      "y": 14,
      "z": -4,
      "name": "Soil_Dirt_White"
    },
    {
      "x": -5,
      "y": 15,
      "z": -4,
      "name": "Soil_Grass_Full"
    },
    {
      "x": -5,
      "y": 8,
      "z": -3,
      "name": "Rock_Chalk"
    },
    {
      "x": -5,
      "y": 9,
      "z": -3,
      "name": "Rock_Chalk"
    },
    {
      "x": -5,
      "y": 10,
      "z": -3,
      "name": "Rock_Chalk"
    },
    {
      "x": -5,
      "y": 11,
      "z": -3,
      "name": "Rock_Chalk"
    },
    {
      "x": -5,
      "y": 12,
      "z": -3,
      "name": "Rock_Chalk"
    },
    {
      "x": -5,
      "y": 13,
      "z": -3,
      "name": "Rock_Chalk"
    },
    {
      "x": -5,
      "y": 14,
      "z": -3,
      "name": "Soil_Dirt_White"
    },
    {
      "x": -5,
      "y": 15,
      "z": -3,
      "name": "Soil_Grass_Full"
    },
    {
      "x": -5,
      "y": 7,
      "z": -2,
      "name": "Rock_Chalk"
    },
    {
      "x": -5,
      "y": 8,
      "z": -2,
      "name": "Rock_Chalk"
    },
    {
      "x": -5,
      "y": 9,
      "z": -2,
      "name": "Rock_Chalk"
    },
    {
      "x": -5,
      "y": 10,
      "z": -2,
      "name": "Rock_Chalk"
    },
    {
      "x": -5,
      "y": 11,
      "z": -2,
      "name": "Rock_Chalk"
    },
    {
      "x": -5,
      "y": 12,
      "z": -2,
      "name": "Rock_Chalk"
    },
    {
      "x": -5,
      "y": 13,
      "z": -2,
      "name": "Rock_Chalk"
    },
    {
      "x": -5,
      "y": 14,
      "z": -2,
      "name": "Soil_Dirt_White"
    },
    {
      "x": -5,
      "y": 15,
      "z": -2,
      "name": "Soil_Grass_Full"
    },
    {
      "x": -5,
      "y": 6,
      "z": -1,
      "name": "Rock_Chalk"
    },
    {
      "x": -5,
      "y": 7,
      "z": -1,
      "name": "Rock_Chalk"
    },
    {
      "x": -5,
      "y": 8,
      "z": -1,
      "name": "Rock_Chalk"
    },
    {
      "x": -5,
      "y": 9,
      "z": -1,
      "name": "Rock_Chalk"
    },
    {
      "x": -5,
      "y": 10,
      "z": -1,
      "name": "Rock_Chalk"
    },
    {
      "x": -5,
      "y": 11,
      "z": -1,
      "name": "Rock_Chalk"
    },
    {
      "x": -5,
      "y": 12,
      "z": -1,
      "name": "Rock_Chalk"
    },
    {
      "x": -5,
      "y": 13,
      "z": -1,
      "name": "Soil_Dirt_White"
    },
    {
      "x": -5,
      "y": 14,
      "z": -1,
      "name": "Soil_Grass_Full"
    },
    {
      "x": -5,
      "y": 8,
      "z": 0,
      "name": "Rock_Chalk"
    },
    {
      "x": -5,
      "y": 9,
      "z": 0,
      "name": "Rock_Chalk"
    },
    {
      "x": -5,
      "y": 10,
      "z": 0,
      "name": "Rock_Chalk"
    },
    {
      "x": -5,
      "y": 11,
      "z": 0,
      "name": "Rock_Chalk"
    },
    {
      "x": -5,
      "y": 12,
      "z": 0,
      "name": "Soil_Dirt_White"
    },
    {
      "x": -5,
      "y": 13,
      "z": 0,
      "name": "Soil_Grass_Full"
    },
    {
      "x": -5,
      "y": 28,
      "z": 4,
      "name": "Rock_Marble_Brick_Smooth"
    },
    {
      "x": -5,
      "y": 29,
      "z": 4,
      "name": "Rock_Marble_Brick_Smooth"
    },
    {
      "x": -5,
      "y": 28,
      "z": 5,
      "name": "Rock_Marble_Brick_Smooth"
    },
    {
      "x": -5,
      "y": 29,
      "z": 5,
      "name": "Rock_Marble_Brick_Smooth"
    },
    {
      "x": -5,
      "y": 28,
      "z": 6,
      "name": "Rock_Marble_Brick_Smooth"
    },
    {
      "x": -5,
      "y": 29,
      "z": 6,
      "name": "Rock_Marble_Brick_Smooth"
    },
    {
      "x": -5,
      "y": 30,
      "z": 6,
      "name": "Rock_Marble_Brick_Wall",
      "rotation": 1
    },
    {
      "x": -5,
      "y": 28,
      "z": 7,
      "name": "Rock_Marble_Brick_Smooth"
    },
    {
      "x": -5,
      "y": 29,
      "z": 7,
      "name": "Rock_Marble_Brick_Smooth"
    },
    {
      "x": -5,
      "y": 30,
      "z": 7,
      "name": "Rock_Marble_Brick_Wall",
      "rotation": 1
    },
    {
      "x": -5,
      "y": 28,
      "z": 8,
      "name": "Rock_Marble_Brick_Smooth"
    },
    {
      "x": -5,
      "y": 29,
      "z": 8,
      "name": "Rock_Marble_Brick_Smooth"
    },
    {
      "x": -5,
      "y": 30,
      "z": 8,
      "name": "Rock_Marble_Brick_Wall",
      "rotation": 1
    },
    {
      "x": -4,
      "y": 8,
      "z": -9,
      "name": "Rock_Chalk"
    },
    {
      "x": -4,
      "y": 9,
      "z": -9,
      "name": "Rock_Chalk"
    },
    {
      "x": -4,
      "y": 10,
      "z": -9,
      "name": "Rock_Chalk"
    },
    {
      "x": -4,
      "y": 11,
      "z": -9,
      "name": "Rock_Chalk"
    },
    {
      "x": -4,
      "y": 12,
      "z": -9,
      "name": "Rock_Chalk"
    },
    {
      "x": -4,
      "y": 13,
      "z": -9,
      "name": "Soil_Gravel"
    },
    {
      "x": -4,
      "y": 7,
      "z": -8,
      "name": "Rock_Chalk"
    },
    {
      "x": -4,
      "y": 8,
      "z": -8,
      "name": "Rock_Chalk"
    },
    {
      "x": -4,
      "y": 9,
      "z": -8,
      "name": "Rock_Chalk"
    },
    {
      "x": -4,
      "y": 10,
      "z": -8,
      "name": "Rock_Chalk"
    },
    {
      "x": -4,
      "y": 11,
      "z": -8,
      "name": "Rock_Chalk"
    },
    {
      "x": -4,
      "y": 12,
      "z": -8,
      "name": "Soil_Gravel"
    },
    {
      "x": -4,
      "y": 13,
      "z": -8,
      "name": "Soil_Dirt_White"
    },
    {
      "x": -4,
      "y": 14,
      "z": -8,
      "name": "Soil_Grass_Full"
    },
    {
      "x": -4,
      "y": 26,
      "z": -8,
      "name": "Rock_Marble_Brick_Smooth"
    },
    {
      "x": -4,
      "y": 27,
      "z": -8,
      "name": "Rock_Marble_Brick_Smooth"
    },
    {
      "x": -4,
      "y": 6,
      "z": -7,
      "name": "Rock_Chalk"
    },
    {
      "x": -4,
      "y": 7,
      "z": -7,
      "name": "Rock_Chalk"
    },
    {
      "x": -4,
      "y": 8,
      "z": -7,
      "name": "Rock_Chalk"
    },
    {
      "x": -4,
      "y": 9,
      "z": -7,
      "name": "Rock_Chalk"
    },
    {
      "x": -4,
      "y": 10,
      "z": -7,
      "name": "Rock_Chalk"
    },
    {
      "x": -4,
      "y": 11,
      "z": -7,
      "name": "Rock_Chalk"
    },
    {
      "x": -4,
      "y": 12,
      "z": -7,
      "name": "Rock_Chalk"
    },
    {
      "x": -4,
      "y": 13,
      "z": -7,
      "name": "Soil_Dirt_White"
    },
    {
      "x": -4,
      "y": 14,
      "z": -7,
      "name": "Soil_Grass_Full"
    },
    {
      "x": -4,
      "y": 26,
      "z": -7,
      "name": "Rock_Marble_Brick_Smooth"
    },
    {
      "x": -4,
      "y": 27,
      "z": -7,
      "name": "Rock_Marble_Brick_Smooth"
    },
    {
      "x": -4,
      "y": 5,
      "z": -6,
      "name": "Rock_Chalk"
    },
    {
      "x": -4,
      "y": 6,
      "z": -6,
      "name": "Rock_Chalk"
    },
    {
      "x": -4,
      "y": 7,
      "z": -6,
      "name": "Rock_Chalk"
    },
    {
      "x": -4,
      "y": 8,
      "z": -6,
      "name": "Rock_Chalk"
    },
    {
      "x": -4,
      "y": 9,
      "z": -6,
      "name": "Rock_Chalk"
    },
    {
      "x": -4,
      "y": 10,
      "z": -6,
      "name": "Rock_Chalk"
    },
    {
      "x": -4,
      "y": 11,
      "z": -6,
      "name": "Rock_Chalk"
    },
    {
      "x": -4,
      "y": 12,
      "z": -6,
      "name": "Soil_Gravel"
    },
    {
      "x": -4,
      "y": 13,
      "z": -6,
      "name": "Rock_Chalk"
    },
    {
      "x": -4,
      "y": 14,
      "z": -6,
      "name": "Soil_Dirt_White"
    },
    {
      "x": -4,
      "y": 15,
      "z": -6,
      "name": "Soil_Grass_Full"
    },
    {
      "x": -4,
      "y": 26,
      "z": -6,
      "name": "Rock_Marble_Brick_Smooth"
    },
    {
      "x": -4,
      "y": 27,
      "z": -6,
      "name": "Rock_Marble_Brick_Smooth"
    },
    {
      "x": -4,
      "y": 28,
      "z": -6,
      "name": "Rock_Marble_Brick_Wall",
      "rotation": 1
    },
    {
      "x": -4,
      "y": 5,
      "z": -5,
      "name": "Rock_Chalk"
    },
    {
      "x": -4,
      "y": 6,
      "z": -5,
      "name": "Rock_Chalk"
    },
    {
      "x": -4,
      "y": 7,
      "z": -5,
      "name": "Rock_Chalk"
    },
    {
      "x": -4,
      "y": 8,
      "z": -5,
      "name": "Rock_Chalk"
    },
    {
      "x": -4,
      "y": 9,
      "z": -5,
      "name": "Rock_Chalk"
    },
    {
      "x": -4,
      "y": 10,
      "z": -5,
      "name": "Rock_Chalk"
    },
    {
      "x": -4,
      "y": 11,
      "z": -5,
      "name": "Rock_Chalk"
    },
    {
      "x": -4,
      "y": 12,
      "z": -5,
      "name": "Rock_Chalk"
    },
    {
      "x": -4,
      "y": 13,
      "z": -5,
      "name": "Rock_Chalk"
    },
    {
      "x": -4,
      "y": 14,
      "z": -5,
      "name": "Soil_Dirt_White"
    },
    {
      "x": -4,
      "y": 15,
      "z": -5,
      "name": "Soil_Grass_Full"
    },
    {
      "x": -4,
      "y": 26,
      "z": -5,
      "name": "Rock_Marble_Brick_Smooth"
    },
    {
      "x": -4,
      "y": 27,
      "z": -5,
      "name": "Rock_Marble_Brick_Smooth"
    },
    {
      "x": -4,
      "y": 28,
      "z": -5,
      "name": "Rock_Marble_Brick_Wall",
      "rotation": 1
    },
    {
      "x": -4,
      "y": 6,
      "z": -4,
      "name": "Rock_Chalk"
    },
    {
      "x": -4,
      "y": 7,
      "z": -4,
      "name": "Rock_Chalk"
    },
    {
      "x": -4,
      "y": 8,
      "z": -4,
      "name": "Rock_Chalk"
    },
    {
      "x": -4,
      "y": 9,
      "z": -4,
      "name": "Rock_Chalk"
    },
    {
      "x": -4,
      "y": 10,
      "z": -4,
      "name": "Rock_Chalk"
    },
    {
      "x": -4,
      "y": 11,
      "z": -4,
      "name": "Rock_Chalk"
    },
    {
      "x": -4,
      "y": 12,
      "z": -4,
      "name": "Rock_Chalk"
    },
    {
      "x": -4,
      "y": 13,
      "z": -4,
      "name": "Rock_Chalk"
    },
    {
      "x": -4,
      "y": 14,
      "z": -4,
      "name": "Soil_Dirt_White"
    },
    {
      "x": -4,
      "y": 15,
      "z": -4,
      "name": "Soil_Grass_Full"
    },
    {
      "x": -4,
      "y": 26,
      "z": -4,
      "name": "Rock_Marble_Brick_Smooth"
    },
    {
      "x": -4,
      "y": 27,
      "z": -4,
      "name": "Rock_Marble_Brick_Smooth"
    },
    {
      "x": -4,
      "y": 28,
      "z": -4,
      "name": "Rock_Marble_Brick_Wall",
      "rotation": 1
    },
    {
      "x": -4,
      "y": 6,
      "z": -3,
      "name": "Rock_Chalk"
    },
    {
      "x": -4,
      "y": 7,
      "z": -3,
      "name": "Rock_Chalk"
    },
    {
      "x": -4,
      "y": 8,
      "z": -3,
      "name": "Rock_Chalk"
    },
    {
      "x": -4,
      "y": 9,
      "z": -3,
      "name": "Rock_Chalk"
    },
    {
      "x": -4,
      "y": 10,
      "z": -3,
      "name": "Rock_Chalk"
    },
    {
      "x": -4,
      "y": 11,
      "z": -3,
      "name": "Rock_Chalk"
    },
    {
      "x": -4,
      "y": 12,
      "z": -3,
      "name": "Rock_Chalk"
    },
    {
      "x": -4,
      "y": 13,
      "z": -3,
      "name": "Rock_Chalk"
    },
    {
      "x": -4,
      "y": 14,
      "z": -3,
      "name": "Soil_Dirt_White"
    },
    {
      "x": -4,
      "y": 15,
      "z": -3,
      "name": "Soil_Grass_Full"
    },
    {
      "x": -4,
      "y": 26,
      "z": -3,
      "name": "Rock_Marble_Brick_Smooth"
    },
    {
      "x": -4,
      "y": 27,
      "z": -3,
      "name": "Rock_Marble_Brick_Smooth"
    },
    {
      "x": -4,
      "y": 28,
      "z": -3,
      "name": "Rock_Marble_Brick_Wall",
      "rotation": 1
    },
    {
      "x": -4,
      "y": 5,
      "z": -2,
      "name": "Rock_Chalk"
    },
    {
      "x": -4,
      "y": 6,
      "z": -2,
      "name": "Rock_Chalk"
    },
    {
      "x": -4,
      "y": 7,
      "z": -2,
      "name": "Rock_Chalk"
    },
    {
      "x": -4,
      "y": 8,
      "z": -2,
      "name": "Rock_Chalk"
    },
    {
      "x": -4,
      "y": 9,
      "z": -2,
      "name": "Rock_Chalk"
    },
    {
      "x": -4,
      "y": 10,
      "z": -2,
      "name": "Rock_Chalk"
    },
    {
      "x": -4,
      "y": 11,
      "z": -2,
      "name": "Rock_Chalk"
    },
    {
      "x": -4,
      "y": 12,
      "z": -2,
      "name": "Rock_Chalk"
    },
    {
      "x": -4,
      "y": 13,
      "z": -2,
      "name": "Rock_Chalk"
    },
    {
      "x": -4,
      "y": 14,
      "z": -2,
      "name": "Soil_Dirt_White"
    },
    {
      "x": -4,
      "y": 15,
      "z": -2,
      "name": "Soil_Grass_Full"
    },
    {
      "x": -4,
      "y": 26,
      "z": -2,
      "name": "Rock_Marble_Brick_Smooth"
    },
    {
      "x": -4,
      "y": 27,
      "z": -2,
      "name": "Rock_Marble_Brick_Smooth"
    },
    {
      "x": -4,
      "y": 28,
      "z": -2,
      "name": "Rock_Marble_Brick_Wall",
      "rotation": 1
    },
    {
      "x": -4,
      "y": 5,
      "z": -1,
      "name": "Rock_Chalk"
    },
    {
      "x": -4,
      "y": 6,
      "z": -1,
      "name": "Rock_Chalk"
    },
    {
      "x": -4,
      "y": 7,
      "z": -1,
      "name": "Rock_Chalk"
    },
    {
      "x": -4,
      "y": 8,
      "z": -1,
      "name": "Rock_Chalk"
    },
    {
      "x": -4,
      "y": 9,
      "z": -1,
      "name": "Rock_Chalk"
    },
    {
      "x": -4,
      "y": 10,
      "z": -1,
      "name": "Rock_Chalk"
    },
    {
      "x": -4,
      "y": 11,
      "z": -1,
      "name": "Rock_Chalk"
    },
    {
      "x": -4,
      "y": 12,
      "z": -1,
      "name": "Rock_Chalk"
    },
    {
      "x": -4,
      "y": 13,
      "z": -1,
      "name": "Rock_Chalk"
    },
    {
      "x": -4,
      "y": 14,
      "z": -1,
      "name": "Soil_Dirt_White"
    },
    {
      "x": -4,
      "y": 15,
      "z": -1,
      "name": "Soil_Grass_Full"
    },
    {
      "x": -4,
      "y": 26,
      "z": -1,
      "name": "Rock_Marble_Brick_Smooth"
    },
    {
      "x": -4,
      "y": 27,
      "z": -1,
      "name": "Rock_Marble_Brick_Smooth"
    },
    {
      "x": -4,
      "y": 28,
      "z": -1,
      "name": "Rock_Marble_Brick_Wall",
      "rotation": 1
    },
    {
      "x": -4,
      "y": 6,
      "z": 0,
      "name": "Rock_Chalk"
    },
    {
      "x": -4,
      "y": 7,
      "z": 0,
      "name": "Rock_Chalk"
    },
    {
      "x": -4,
      "y": 8,
      "z": 0,
      "name": "Rock_Chalk"
    },
    {
      "x": -4,
      "y": 9,
      "z": 0,
      "name": "Rock_Chalk"
    },
    {
      "x": -4,
      "y": 10,
      "z": 0,
      "name": "Rock_Chalk"
    },
    {
      "x": -4,
      "y": 11,
      "z": 0,
      "name": "Rock_Chalk"
    },
    {
      "x": -4,
      "y": 12,
      "z": 0,
      "name": "Rock_Chalk"
    },
    {
      "x": -4,
      "y": 13,
      "z": 0,
      "name": "Rock_Chalk"
    },
    {
      "x": -4,
      "y": 14,
      "z": 0,
      "name": "Soil_Dirt_White"
    },
    {
      "x": -4,
      "y": 15,
      "z": 0,
      "name": "Soil_Grass_Full"
    },
    {
      "x": -4,
      "y": 26,
      "z": 0,
      "name": "Rock_Marble_Brick_Smooth"
    },
    {
      "x": -4,
      "y": 27,
      "z": 0,
      "name": "Rock_Marble_Brick_Smooth"
    },
    {
      "x": -4,
      "y": 7,
      "z": 1,
      "name": "Rock_Chalk"
    },
    {
      "x": -4,
      "y": 8,
      "z": 1,
      "name": "Rock_Chalk"
    },
    {
      "x": -4,
      "y": 9,
      "z": 1,
      "name": "Rock_Chalk"
    },
    {
      "x": -4,
      "y": 10,
      "z": 1,
      "name": "Rock_Chalk"
    },
    {
      "x": -4,
      "y": 11,
      "z": 1,
      "name": "Rock_Chalk"
    },
    {
      "x": -4,
      "y": 12,
      "z": 1,
      "name": "Rock_Chalk"
    },
    {
      "x": -4,
      "y": 13,
      "z": 1,
      "name": "Rock_Chalk"
    },
    {
      "x": -4,
      "y": 26,
      "z": 1,
      "name": "Rock_Marble_Brick_Smooth"
    },
    {
      "x": -4,
      "y": 28,
      "z": 3,
      "name": "Rock_Marble_Brick_Smooth"
    },
    {
      "x": -4,
      "y": 29,
      "z": 3,
      "name": "Rock_Marble_Brick_Smooth"
    },
    {
      "x": -4,
      "y": 28,
      "z": 4,
      "name": "Rock_Marble_Brick_Smooth"
    },
    {
      "x": -4,
      "y": 29,
      "z": 4,
      "name": "Rock_Marble_Brick_Smooth"
    },
    {
      "x": -4,
      "y": 26,
      "z": 5,
      "name": "Rock_Chalk"
    },
    {
      "x": -4,
      "y": 27,
      "z": 5,
      "name": "Rock_Chalk"
    },
    {
      "x": -4,
      "y": 28,
      "z": 5,
      "name": "Rock_Marble_Brick_Smooth"
    },
    {
      "x": -4,
      "y": 29,
      "z": 5,
      "name": "Rock_Marble_Brick_Smooth"
    },
    {
      "x": -4,
      "y": 26,
      "z": 6,
      "name": "Rock_Chalk"
    },
    {
      "x": -4,
      "y": 27,
      "z": 6,
      "name": "Rock_Chalk"
    },
    {
      "x": -4,
      "y": 28,
      "z": 6,
      "name": "Rock_Marble_Brick_Smooth"
    },
    {
      "x": -4,
      "y": 29,
      "z": 6,
      "name": "Rock_Marble_Brick_Smooth"
    },
    {
      "x": -4,
      "y": 27,
      "z": 7,
      "name": "Rock_Chalk"
    },
    {
      "x": -4,
      "y": 28,
      "z": 7,
      "name": "Rock_Marble_Brick_Smooth"
    },
    {
      "x": -4,
      "y": 29,
      "z": 7,
      "name": "Rock_Marble_Brick_Smooth"
    },
    {
      "x": -4,
      "y": 28,
      "z": 8,
      "name": "Rock_Marble_Brick_Smooth"
    },
    {
      "x": -4,
      "y": 29,
      "z": 8,
      "name": "Rock_Marble_Brick_Smooth"
    },
    {
      "x": -4,
      "y": 28,
      "z": 9,
      "name": "Plant_Moss_Wall_Green"
    },
    {
      "x": -3,
      "y": 7,
      "z": -9,
      "name": "Rock_Chalk"
    },
    {
      "x": -3,
      "y": 8,
      "z": -9,
      "name": "Rock_Chalk"
    },
    {
      "x": -3,
      "y": 9,
      "z": -9,
      "name": "Rock_Chalk"
    },
    {
      "x": -3,
      "y": 10,
      "z": -9,
      "name": "Rock_Chalk"
    },
    {
      "x": -3,
      "y": 11,
      "z": -9,
      "name": "Rock_Chalk"
    },
    {
      "x": -3,
      "y": 12,
      "z": -9,
      "name": "Rock_Chalk"
    },
    {
      "x": -3,
      "y": 13,
      "z": -9,
      "name": "Soil_Gravel"
    },
    {
      "x": -3,
      "y": 26,
      "z": -9,
      "name": "Rock_Marble_Brick_Smooth"
    },
    {
      "x": -3,
      "y": 27,
      "z": -9,
      "name": "Rock_Marble_Brick_Smooth"
    },
    {
      "x": -3,
      "y": 4,
      "z": -8,
      "name": "Rock_Chalk"
    },
    {
      "x": -3,
      "y": 5,
      "z": -8,
      "name": "Rock_Chalk"
    },
    {
      "x": -3,
      "y": 6,
      "z": -8,
      "name": "Rock_Chalk"
    },
    {
      "x": -3,
      "y": 7,
      "z": -8,
      "name": "Rock_Chalk"
    },
    {
      "x": -3,
      "y": 8,
      "z": -8,
      "name": "Rock_Chalk"
    },
    {
      "x": -3,
      "y": 9,
      "z": -8,
      "name": "Rock_Chalk"
    },
    {
      "x": -3,
      "y": 10,
      "z": -8,
      "name": "Rock_Chalk"
    },
    {
      "x": -3,
      "y": 11,
      "z": -8,
      "name": "Rock_Chalk"
    },
    {
      "x": -3,
      "y": 12,
      "z": -8,
      "name": "Soil_Gravel"
    },
    {
      "x": -3,
      "y": 13,
      "z": -8,
      "name": "Soil_Gravel"
    },
    {
      "x": -3,
      "y": 14,
      "z": -8,
      "name": "Soil_Gravel"
    },
    {
      "x": -3,
      "y": 15,
      "z": -8,
      "name": "Rock_Marble_Brick"
    },
    {
      "x": -3,
      "y": 16,
      "z": -8,
      "name": "Rock_Marble_Brick"
    },
    {
      "x": -3,
      "y": 17,
      "z": -8,
      "name": "Rock_Marble_Brick"
    },
    {
      "x": -3,
      "y": 24,
      "z": -8,
      "name": "Rock_Chalk"
    },
    {
      "x": -3,
      "y": 25,
      "z": -8,
      "name": "Rock_Chalk"
    },
    {
      "x": -3,
      "y": 26,
      "z": -8,
      "name": "Rock_Marble_Brick_Smooth"
    },
    {
      "x": -3,
      "y": 27,
      "z": -8,
      "name": "Rock_Marble_Brick_Smooth"
    },
    {
      "x": -3,
      "y": 4,
      "z": -7,
      "name": "Rock_Chalk"
    },
    {
      "x": -3,
      "y": 5,
      "z": -7,
      "name": "Rock_Chalk"
    },
    {
      "x": -3,
      "y": 6,
      "z": -7,
      "name": "Rock_Chalk"
    },
    {
      "x": -3,
      "y": 7,
      "z": -7,
      "name": "Rock_Chalk"
    },
    {
      "x": -3,
      "y": 8,
      "z": -7,
      "name": "Rock_Chalk"
    },
    {
      "x": -3,
      "y": 9,
      "z": -7,
      "name": "Rock_Chalk"
    },
    {
      "x": -3,
      "y": 10,
      "z": -7,
      "name": "Rock_Chalk"
    },
    {
      "x": -3,
      "y": 11,
      "z": -7,
      "name": "Rock_Chalk"
    },
    {
      "x": -3,
      "y": 12,
      "z": -7,
      "name": "Soil_Gravel"
    },
    {
      "x": -3,
      "y": 13,
      "z": -7,
      "name": "Soil_Gravel"
    },
    {
      "x": -3,
      "y": 14,
      "z": -7,
      "name": "Rock_Chalk"
    },
    {
      "x": -3,
      "y": 15,
      "z": -7,
      "name": "Rock_Marble_Brick"
    },
    {
      "x": -3,
      "y": 16,
      "z": -7,
      "name": "Rock_Marble_Brick"
    },
    {
      "x": -3,
      "y": 17,
      "z": -7,
      "name": "Rock_Marble_Brick"
    },
    {
      "x": -3,
      "y": 18,
      "z": -7,
      "name": "Rock_Chalk"
    },
    {
      "x": -3,
      "y": 19,
      "z": -7,
      "name": "Rock_Chalk"
    },
    {
      "x": -3,
      "y": 20,
      "z": -7,
      "name": "Rock_Chalk"
    },
    {
      "x": -3,
      "y": 21,
      "z": -7,
      "name": "Rock_Chalk"
    },
    {
      "x": -3,
      "y": 22,
      "z": -7,
      "name": "Rock_Chalk"
    },
    {
      "x": -3,
      "y": 23,
      "z": -7,
      "name": "Rock_Chalk"
    },
    {
      "x": -3,
      "y": 24,
      "z": -7,
      "name": "Rock_Chalk"
    },
    {
      "x": -3,
      "y": 25,
      "z": -7,
      "name": "Rock_Chalk"
    },
    {
      "x": -3,
      "y": 26,
      "z": -7,
      "name": "Rock_Marble_Brick_Smooth"
    },
    {
      "x": -3,
      "y": 27,
      "z": -7,
      "name": "Rock_Marble_Brick_Smooth"
    },
    {
      "x": -3,
      "y": 4,
      "z": -6,
      "name": "Rock_Chalk"
    },
    {
      "x": -3,
      "y": 5,
      "z": -6,
      "name": "Rock_Chalk"
    },
    {
      "x": -3,
      "y": 6,
      "z": -6,
      "name": "Rock_Chalk"
    },
    {
      "x": -3,
      "y": 7,
      "z": -6,
      "name": "Rock_Chalk"
    },
    {
      "x": -3,
      "y": 8,
      "z": -6,
      "name": "Rock_Chalk"
    },
    {
      "x": -3,
      "y": 9,
      "z": -6,
      "name": "Rock_Chalk"
    },
    {
      "x": -3,
      "y": 10,
      "z": -6,
      "name": "Rock_Chalk"
    },
    {
      "x": -3,
      "y": 11,
      "z": -6,
      "name": "Rock_Chalk"
    },
    {
      "x": -3,
      "y": 12,
      "z": -6,
      "name": "Rock_Chalk"
    },
    {
      "x": -3,
      "y": 13,
      "z": -6,
      "name": "Rock_Chalk"
    },
    {
      "x": -3,
      "y": 14,
      "z": -6,
      "name": "Rock_Chalk"
    },
    {
      "x": -3,
      "y": 15,
      "z": -6,
      "name": "Rock_Chalk"
    },
    {
      "x": -3,
      "y": 16,
      "z": -6,
      "name": "Rock_Marble_Brick"
    },
    {
      "x": -3,
      "y": 17,
      "z": -6,
      "name": "Rock_Marble_Brick"
    },
    {
      "x": -3,
      "y": 18,
      "z": -6,
      "name": "Rock_Chalk"
    },
    {
      "x": -3,
      "y": 19,
      "z": -6,
      "name": "Rock_Chalk"
    },
    {
      "x": -3,
      "y": 20,
      "z": -6,
      "name": "Rock_Chalk"
    },
    {
      "x": -3,
      "y": 21,
      "z": -6,
      "name": "Rock_Chalk"
    },
    {
      "x": -3,
      "y": 22,
      "z": -6,
      "name": "Rock_Chalk"
    },
    {
      "x": -3,
      "y": 23,
      "z": -6,
      "name": "Rock_Chalk"
    },
    {
      "x": -3,
      "y": 24,
      "z": -6,
      "name": "Rock_Chalk"
    },
    {
      "x": -3,
      "y": 25,
      "z": -6,
      "name": "Rock_Chalk"
    },
    {
      "x": -3,
      "y": 26,
      "z": -6,
      "name": "Rock_Marble_Brick_Smooth"
    },
    {
      "x": -3,
      "y": 27,
      "z": -6,
      "name": "Rock_Marble_Brick_Smooth"
    },
    {
      "x": -3,
      "y": 5,
      "z": -5,
      "name": "Rock_Chalk"
    },
    {
      "x": -3,
      "y": 6,
      "z": -5,
      "name": "Rock_Chalk"
    },
    {
      "x": -3,
      "y": 7,
      "z": -5,
      "name": "Rock_Chalk"
    },
    {
      "x": -3,
      "y": 8,
      "z": -5,
      "name": "Rock_Chalk"
    },
    {
      "x": -3,
      "y": 9,
      "z": -5,
      "name": "Rock_Chalk"
    },
    {
      "x": -3,
      "y": 10,
      "z": -5,
      "name": "Rock_Chalk"
    },
    {
      "x": -3,
      "y": 11,
      "z": -5,
      "name": "Rock_Chalk"
    },
    {
      "x": -3,
      "y": 12,
      "z": -5,
      "name": "Rock_Chalk"
    },
    {
      "x": -3,
      "y": 13,
      "z": -5,
      "name": "Soil_Gravel"
    },
    {
      "x": -3,
      "y": 14,
      "z": -5,
      "name": "Rock_Chalk"
    },
    {
      "x": -3,
      "y": 15,
      "z": -5,
      "name": "Rock_Chalk"
    },
    {
      "x": -3,
      "y": 16,
      "z": -5,
      "name": "Rock_Marble_Brick"
    },
    {
      "x": -3,
      "y": 24,
      "z": -5,
      "name": "Rock_Chalk"
    },
    {
      "x": -3,
      "y": 25,
      "z": -5,
      "name": "Rock_Chalk"
    },
    {
      "x": -3,
      "y": 26,
      "z": -5,
      "name": "Rock_Marble_Brick_Smooth"
    },
    {
      "x": -3,
      "y": 27,
      "z": -5,
      "name": "Rock_Marble_Brick_Smooth"
    },
    {
      "x": -3,
      "y": 5,
      "z": -4,
      "name": "Rock_Chalk"
    },
    {
      "x": -3,
      "y": 6,
      "z": -4,
      "name": "Rock_Chalk"
    },
    {
      "x": -3,
      "y": 7,
      "z": -4,
      "name": "Rock_Chalk"
    },
    {
      "x": -3,
      "y": 8,
      "z": -4,
      "name": "Rock_Chalk"
    },
    {
      "x": -3,
      "y": 9,
      "z": -4,
      "name": "Rock_Chalk"
    },
    {
      "x": -3,
      "y": 10,
      "z": -4,
      "name": "Rock_Chalk"
    },
    {
      "x": -3,
      "y": 11,
      "z": -4,
      "name": "Rock_Chalk"
    },
    {
      "x": -3,
      "y": 12,
      "z": -4,
      "name": "Rock_Chalk"
    },
    {
      "x": -3,
      "y": 13,
      "z": -4,
      "name": "Rock_Chalk"
    },
    {
      "x": -3,
      "y": 14,
      "z": -4,
      "name": "Rock_Chalk"
    },
    {
      "x": -3,
      "y": 15,
      "z": -4,
      "name": "Rock_Chalk"
    },
    {
      "x": -3,
      "y": 16,
      "z": -4,
      "name": "Rock_Marble_Brick"
    },
    {
      "x": -3,
      "y": 25,
      "z": -4,
      "name": "Rock_Chalk"
    },
    {
      "x": -3,
      "y": 26,
      "z": -4,
      "name": "Rock_Marble_Brick_Smooth"
    },
    {
      "x": -3,
      "y": 27,
      "z": -4,
      "name": "Rock_Marble_Brick_Smooth"
    },
    {
      "x": -3,
      "y": 4,
      "z": -3,
      "name": "Rock_Chalk"
    },
    {
      "x": -3,
      "y": 5,
      "z": -3,
      "name": "Rock_Chalk"
    },
    {
      "x": -3,
      "y": 6,
      "z": -3,
      "name": "Rock_Chalk"
    },
    {
      "x": -3,
      "y": 7,
      "z": -3,
      "name": "Rock_Chalk"
    },
    {
      "x": -3,
      "y": 8,
      "z": -3,
      "name": "Rock_Chalk"
    },
    {
      "x": -3,
      "y": 9,
      "z": -3,
      "name": "Rock_Chalk"
    },
    {
      "x": -3,
      "y": 10,
      "z": -3,
      "name": "Rock_Chalk"
    },
    {
      "x": -3,
      "y": 11,
      "z": -3,
      "name": "Rock_Chalk"
    },
    {
      "x": -3,
      "y": 12,
      "z": -3,
      "name": "Rock_Chalk"
    },
    {
      "x": -3,
      "y": 13,
      "z": -3,
      "name": "Rock_Chalk"
    },
    {
      "x": -3,
      "y": 14,
      "z": -3,
      "name": "Rock_Chalk"
    },
    {
      "x": -3,
      "y": 15,
      "z": -3,
      "name": "Rock_Chalk"
    },
    {
      "x": -3,
      "y": 16,
      "z": -3,
      "name": "Rock_Marble_Brick"
    },
    {
      "x": -3,
      "y": 26,
      "z": -3,
      "name": "Rock_Marble_Brick_Smooth"
    },
    {
      "x": -3,
      "y": 27,
      "z": -3,
      "name": "Rock_Marble_Brick_Smooth"
    },
    {
      "x": -3,
      "y": 3,
      "z": -2,
      "name": "Rock_Chalk"
    },
    {
      "x": -3,
      "y": 4,
      "z": -2,
      "name": "Rock_Chalk"
    },
    {
      "x": -3,
      "y": 5,
      "z": -2,
      "name": "Rock_Chalk"
    },
    {
      "x": -3,
      "y": 6,
      "z": -2,
      "name": "Rock_Chalk"
    },
    {
      "x": -3,
      "y": 7,
      "z": -2,
      "name": "Rock_Chalk"
    },
    {
      "x": -3,
      "y": 8,
      "z": -2,
      "name": "Rock_Chalk"
    },
    {
      "x": -3,
      "y": 9,
      "z": -2,
      "name": "Rock_Chalk"
    },
    {
      "x": -3,
      "y": 10,
      "z": -2,
      "name": "Rock_Chalk"
    },
    {
      "x": -3,
      "y": 11,
      "z": -2,
      "name": "Rock_Chalk"
    },
    {
      "x": -3,
      "y": 12,
      "z": -2,
      "name": "Rock_Chalk"
    },
    {
      "x": -3,
      "y": 13,
      "z": -2,
      "name": "Rock_Chalk"
    },
    {
      "x": -3,
      "y": 14,
      "z": -2,
      "name": "Rock_Chalk"
    },
    {
      "x": -3,
      "y": 15,
      "z": -2,
      "name": "Rock_Chalk"
    },
    {
      "x": -3,
      "y": 16,
      "z": -2,
      "name": "Rock_Marble_Brick"
    },
    {
      "x": -3,
      "y": 17,
      "z": -2,
      "name": "Rock_Marble_Brick"
    },
    {
      "x": -3,
      "y": 25,
      "z": -2,
      "name": "Rock_Chalk"
    },
    {
      "x": -3,
      "y": 26,
      "z": -2,
      "name": "Rock_Marble_Brick_Smooth"
    },
    {
      "x": -3,
      "y": 27,
      "z": -2,
      "name": "Rock_Marble_Brick_Smooth"
    },
    {
      "x": -3,
      "y": 4,
      "z": -1,
      "name": "Rock_Chalk"
    },
    {
      "x": -3,
      "y": 5,
      "z": -1,
      "name": "Rock_Chalk"
    },
    {
      "x": -3,
      "y": 6,
      "z": -1,
      "name": "Rock_Chalk"
    },
    {
      "x": -3,
      "y": 7,
      "z": -1,
      "name": "Rock_Chalk"
    },
    {
      "x": -3,
      "y": 8,
      "z": -1,
      "name": "Rock_Chalk"
    },
    {
      "x": -3,
      "y": 9,
      "z": -1,
      "name": "Rock_Chalk"
    },
    {
      "x": -3,
      "y": 10,
      "z": -1,
      "name": "Rock_Chalk"
    },
    {
      "x": -3,
      "y": 11,
      "z": -1,
      "name": "Rock_Chalk"
    },
    {
      "x": -3,
      "y": 12,
      "z": -1,
      "name": "Rock_Chalk"
    },
    {
      "x": -3,
      "y": 13,
      "z": -1,
      "name": "Rock_Chalk"
    },
    {
      "x": -3,
      "y": 14,
      "z": -1,
      "name": "Rock_Chalk"
    },
    {
      "x": -3,
      "y": 15,
      "z": -1,
      "name": "Rock_Chalk"
    },
    {
      "x": -3,
      "y": 16,
      "z": -1,
      "name": "Rock_Marble_Brick"
    },
    {
      "x": -3,
      "y": 17,
      "z": -1,
      "name": "Rock_Marble_Brick"
    },
    {
      "x": -3,
      "y": 18,
      "z": -1,
      "name": "Plant_Moss_Rug_Green"
    },
    {
      "x": -3,
      "y": 24,
      "z": -1,
      "name": "Rock_Chalk"
    },
    {
      "x": -3,
      "y": 25,
      "z": -1,
      "name": "Rock_Chalk"
    },
    {
      "x": -3,
      "y": 26,
      "z": -1,
      "name": "Rock_Marble_Brick_Smooth"
    },
    {
      "x": -3,
      "y": 27,
      "z": -1,
      "name": "Rock_Marble_Brick_Smooth"
    },
    {
      "x": -3,
      "y": 4,
      "z": 0,
      "name": "Rock_Chalk"
    },
    {
      "x": -3,
      "y": 5,
      "z": 0,
      "name": "Rock_Chalk"
    },
    {
      "x": -3,
      "y": 6,
      "z": 0,
      "name": "Rock_Chalk"
    },
    {
      "x": -3,
      "y": 7,
      "z": 0,
      "name": "Rock_Chalk"
    },
    {
      "x": -3,
      "y": 8,
      "z": 0,
      "name": "Rock_Chalk"
    },
    {
      "x": -3,
      "y": 9,
      "z": 0,
      "name": "Rock_Chalk"
    },
    {
      "x": -3,
      "y": 10,
      "z": 0,
      "name": "Rock_Chalk"
    },
    {
      "x": -3,
      "y": 11,
      "z": 0,
      "name": "Rock_Chalk"
    },
    {
      "x": -3,
      "y": 12,
      "z": 0,
      "name": "Rock_Chalk"
    },
    {
      "x": -3,
      "y": 13,
      "z": 0,
      "name": "Rock_Chalk"
    },
    {
      "x": -3,
      "y": 14,
      "z": 0,
      "name": "Rock_Chalk"
    },
    {
      "x": -3,
      "y": 15,
      "z": 0,
      "name": "Rock_Chalk"
    },
    {
      "x": -3,
      "y": 16,
      "z": 0,
      "name": "Rock_Marble_Brick"
    },
    {
      "x": -3,
      "y": 17,
      "z": 0,
      "name": "Rock_Marble_Brick"
    },
    {
      "x": -3,
      "y": 18,
      "z": 0,
      "name": "Rock_Marble_Brick"
    },
    {
      "x": -3,
      "y": 19,
      "z": 0,
      "name": "Rock_Chalk"
    },
    {
      "x": -3,
      "y": 22,
      "z": 0,
      "name": "Rock_Chalk"
    },
    {
      "x": -3,
      "y": 23,
      "z": 0,
      "name": "Rock_Chalk"
    },
    {
      "x": -3,
      "y": 24,
      "z": 0,
      "name": "Rock_Chalk"
    },
    {
      "x": -3,
      "y": 25,
      "z": 0,
      "name": "Rock_Chalk"
    },
    {
      "x": -3,
      "y": 26,
      "z": 0,
      "name": "Rock_Marble_Brick_Smooth"
    },
    {
      "x": -3,
      "y": 27,
      "z": 0,
      "name": "Rock_Marble_Brick_Smooth"
    },
    {
      "x": -3,
      "y": 5,
      "z": 1,
      "name": "Rock_Chalk"
    },
    {
      "x": -3,
      "y": 6,
      "z": 1,
      "name": "Rock_Chalk"
    },
    {
      "x": -3,
      "y": 7,
      "z": 1,
      "name": "Rock_Chalk"
    },
    {
      "x": -3,
      "y": 8,
      "z": 1,
      "name": "Rock_Chalk"
    },
    {
      "x": -3,
      "y": 9,
      "z": 1,
      "name": "Rock_Chalk"
    },
    {
      "x": -3,
      "y": 10,
      "z": 1,
      "name": "Rock_Chalk"
    },
    {
      "x": -3,
      "y": 11,
      "z": 1,
      "name": "Rock_Chalk"
    },
    {
      "x": -3,
      "y": 12,
      "z": 1,
      "name": "Rock_Chalk"
    },
    {
      "x": -3,
      "y": 13,
      "z": 1,
      "name": "Rock_Chalk"
    },
    {
      "x": -3,
      "y": 14,
      "z": 1,
      "name": "Rock_Chalk"
    },
    {
      "x": -3,
      "y": 15,
      "z": 1,
      "name": "Rock_Chalk"
    },
    {
      "x": -3,
      "y": 16,
      "z": 1,
      "name": "Rock_Marble_Brick"
    },
    {
      "x": -3,
      "y": 17,
      "z": 1,
      "name": "Rock_Marble_Brick"
    },
    {
      "x": -3,
      "y": 18,
      "z": 1,
      "name": "Rock_Marble_Brick"
    },
    {
      "x": -3,
      "y": 19,
      "z": 1,
      "name": "Rock_Chalk"
    },
    {
      "x": -3,
      "y": 20,
      "z": 1,
      "name": "Rock_Chalk"
    },
    {
      "x": -3,
      "y": 23,
      "z": 1,
      "name": "Rock_Chalk"
    },
    {
      "x": -3,
      "y": 24,
      "z": 1,
      "name": "Rock_Chalk"
    },
    {
      "x": -3,
      "y": 25,
      "z": 1,
      "name": "Rock_Chalk"
    },
    {
      "x": -3,
      "y": 26,
      "z": 1,
      "name": "Rock_Marble_Brick_Smooth"
    },
    {
      "x": -3,
      "y": 27,
      "z": 1,
      "name": "Rock_Marble_Brick_Smooth"
    },
    {
      "x": -3,
      "y": 6,
      "z": 2,
      "name": "Rock_Chalk"
    },
    {
      "x": -3,
      "y": 7,
      "z": 2,
      "name": "Rock_Chalk"
    },
    {
      "x": -3,
      "y": 8,
      "z": 2,
      "name": "Rock_Chalk"
    },
    {
      "x": -3,
      "y": 9,
      "z": 2,
      "name": "Rock_Chalk"
    },
    {
      "x": -3,
      "y": 10,
      "z": 2,
      "name": "Rock_Chalk"
    },
    {
      "x": -3,
      "y": 11,
      "z": 2,
      "name": "Rock_Chalk"
    },
    {
      "x": -3,
      "y": 12,
      "z": 2,
      "name": "Rock_Chalk"
    },
    {
      "x": -3,
      "y": 13,
      "z": 2,
      "name": "Rock_Chalk"
    },
    {
      "x": -3,
      "y": 14,
      "z": 2,
      "name": "Rock_Chalk"
    },
    {
      "x": -3,
      "y": 15,
      "z": 2,
      "name": "Rock_Chalk"
    },
    {
      "x": -3,
      "y": 28,
      "z": 3,
      "name": "Rock_Marble_Brick_Smooth"
    },
    {
      "x": -3,
      "y": 29,
      "z": 3,
      "name": "Rock_Marble_Brick_Smooth"
    },
    {
      "x": -3,
      "y": 28,
      "z": 4,
      "name": "Rock_Marble_Brick_Smooth"
    },
    {
      "x": -3,
      "y": 29,
      "z": 4,
      "name": "Rock_Marble_Brick_Smooth"
    },
    {
      "x": -3,
      "y": 26,
      "z": 5,
      "name": "Rock_Chalk"
    },
    {
      "x": -3,
      "y": 27,
      "z": 5,
      "name": "Rock_Chalk"
    },
    {
      "x": -3,
      "y": 28,
      "z": 5,
      "name": "Rock_Marble_Brick_Smooth"
    },
    {
      "x": -3,
      "y": 29,
      "z": 5,
      "name": "Rock_Marble_Brick_Smooth"
    },
    {
      "x": -3,
      "y": 26,
      "z": 6,
      "name": "Rock_Chalk"
    },
    {
      "x": -3,
      "y": 27,
      "z": 6,
      "name": "Rock_Chalk"
    },
    {
      "x": -3,
      "y": 28,
      "z": 6,
      "name": "Rock_Marble_Brick_Smooth"
    },
    {
      "x": -3,
      "y": 29,
      "z": 6,
      "name": "Rock_Marble_Brick_Smooth"
    },
    {
      "x": -3,
      "y": 28,
      "z": 7,
      "name": "Rock_Marble_Brick_Smooth"
    },
    {
      "x": -3,
      "y": 29,
      "z": 7,
      "name": "Rock_Marble_Brick_Smooth"
    },
    {
      "x": -3,
      "y": 28,
      "z": 8,
      "name": "Plant_Moss_Wall_Green",
      "rotation": 1
    },
    {
      "x": -3,
      "y": 29,
      "z": 8,
      "name": "Plant_Moss_Wall_Green"
    },
    {
      "x": -2,
      "y": 7,
      "z": -9,
      "name": "Rock_Chalk"
    },
    {
      "x": -2,
      "y": 8,
      "z": -9,
      "name": "Rock_Chalk"
    },
    {
      "x": -2,
      "y": 9,
      "z": -9,
      "name": "Rock_Chalk"
    },
    {
      "x": -2,
      "y": 10,
      "z": -9,
      "name": "Rock_Chalk"
    },
    {
      "x": -2,
      "y": 11,
      "z": -9,
      "name": "Rock_Chalk"
    },
    {
      "x": -2,
      "y": 12,
      "z": -9,
      "name": "Soil_Gravel"
    },
    {
      "x": -2,
      "y": 26,
      "z": -9,
      "name": "Rock_Marble_Brick_Smooth"
    },
    {
      "x": -2,
      "y": 27,
      "z": -9,
      "name": "Rock_Marble_Brick_Smooth"
    },
    {
      "x": -2,
      "y": 5,
      "z": -8,
      "name": "Rock_Chalk"
    },
    {
      "x": -2,
      "y": 6,
      "z": -8,
      "name": "Rock_Chalk"
    },
    {
      "x": -2,
      "y": 7,
      "z": -8,
      "name": "Rock_Chalk"
    },
    {
      "x": -2,
      "y": 8,
      "z": -8,
      "name": "Rock_Chalk"
    },
    {
      "x": -2,
      "y": 9,
      "z": -8,
      "name": "Rock_Chalk"
    },
    {
      "x": -2,
      "y": 10,
      "z": -8,
      "name": "Rock_Chalk"
    },
    {
      "x": -2,
      "y": 11,
      "z": -8,
      "name": "Rock_Chalk"
    },
    {
      "x": -2,
      "y": 12,
      "z": -8,
      "name": "Soil_Gravel"
    },
    {
      "x": -2,
      "y": 13,
      "z": -8,
      "name": "Soil_Gravel"
    },
    {
      "x": -2,
      "y": 14,
      "z": -8,
      "name": "Rock_Marble_Brick"
    },
    {
      "x": -2,
      "y": 15,
      "z": -8,
      "name": "Rock_Marble_Brick"
    },
    {
      "x": -2,
      "y": 16,
      "z": -8,
      "name": "Rock_Marble_Brick"
    },
    {
      "x": -2,
      "y": 17,
      "z": -8,
      "name": "Rock_Marble_Brick"
    },
    {
      "x": -2,
      "y": 24,
      "z": -8,
      "name": "Rock_Chalk"
    },
    {
      "x": -2,
      "y": 25,
      "z": -8,
      "name": "Rock_Chalk"
    },
    {
      "x": -2,
      "y": 26,
      "z": -8,
      "name": "Rock_Marble_Brick_Smooth"
    },
    {
      "x": -2,
      "y": 27,
      "z": -8,
      "name": "Rock_Marble_Brick_Smooth"
    },
    {
      "x": -2,
      "y": 3,
      "z": -7,
      "name": "Rock_Chalk"
    },
    {
      "x": -2,
      "y": 4,
      "z": -7,
      "name": "Rock_Chalk"
    },
    {
      "x": -2,
      "y": 5,
      "z": -7,
      "name": "Rock_Chalk"
    },
    {
      "x": -2,
      "y": 6,
      "z": -7,
      "name": "Rock_Chalk"
    },
    {
      "x": -2,
      "y": 7,
      "z": -7,
      "name": "Rock_Chalk"
    },
    {
      "x": -2,
      "y": 8,
      "z": -7,
      "name": "Rock_Chalk"
    },
    {
      "x": -2,
      "y": 9,
      "z": -7,
      "name": "Rock_Chalk"
    },
    {
      "x": -2,
      "y": 10,
      "z": -7,
      "name": "Rock_Chalk"
    },
    {
      "x": -2,
      "y": 11,
      "z": -7,
      "name": "Rock_Chalk"
    },
    {
      "x": -2,
      "y": 12,
      "z": -7,
      "name": "Soil_Gravel"
    },
    {
      "x": -2,
      "y": 13,
      "z": -7,
      "name": "Rock_Chalk"
    },
    {
      "x": -2,
      "y": 14,
      "z": -7,
      "name": "Rock_Chalk"
    },
    {
      "x": -2,
      "y": 15,
      "z": -7,
      "name": "Rock_Marble_Brick"
    },
    {
      "x": -2,
      "y": 16,
      "z": -7,
      "name": "Rock_Marble_Brick"
    },
    {
      "x": -2,
      "y": 17,
      "z": -7,
      "name": "Rock_Marble_Brick"
    },
    {
      "x": -2,
      "y": 18,
      "z": -7,
      "name": "Rock_Chalk"
    },
    {
      "x": -2,
      "y": 19,
      "z": -7,
      "name": "Rock_Chalk"
    },
    {
      "x": -2,
      "y": 20,
      "z": -7,
      "name": "Rock_Chalk"
    },
    {
      "x": -2,
      "y": 21,
      "z": -7,
      "name": "Rock_Chalk"
    },
    {
      "x": -2,
      "y": 22,
      "z": -7,
      "name": "Rock_Chalk"
    },
    {
      "x": -2,
      "y": 23,
      "z": -7,
      "name": "Rock_Chalk"
    },
    {
      "x": -2,
      "y": 24,
      "z": -7,
      "name": "Rock_Chalk"
    },
    {
      "x": -2,
      "y": 25,
      "z": -7,
      "name": "Rock_Chalk"
    },
    {
      "x": -2,
      "y": 26,
      "z": -7,
      "name": "Rock_Marble_Brick_Smooth"
    },
    {
      "x": -2,
      "y": 27,
      "z": -7,
      "name": "Rock_Marble_Brick_Smooth"
    },
    {
      "x": -2,
      "y": 4,
      "z": -6,
      "name": "Rock_Chalk"
    },
    {
      "x": -2,
      "y": 5,
      "z": -6,
      "name": "Rock_Chalk"
    },
    {
      "x": -2,
      "y": 6,
      "z": -6,
      "name": "Rock_Chalk"
    },
    {
      "x": -2,
      "y": 7,
      "z": -6,
      "name": "Rock_Chalk"
    },
    {
      "x": -2,
      "y": 8,
      "z": -6,
      "name": "Rock_Chalk"
    },
    {
      "x": -2,
      "y": 9,
      "z": -6,
      "name": "Rock_Chalk"
    },
    {
      "x": -2,
      "y": 10,
      "z": -6,
      "name": "Rock_Chalk"
    },
    {
      "x": -2,
      "y": 11,
      "z": -6,
      "name": "Rock_Chalk"
    },
    {
      "x": -2,
      "y": 12,
      "z": -6,
      "name": "Rock_Chalk"
    },
    {
      "x": -2,
      "y": 13,
      "z": -6,
      "name": "Soil_Dirt_White"
    },
    {
      "x": -2,
      "y": 14,
      "z": -6,
      "name": "Soil_Dirt_White"
    },
    {
      "x": -2,
      "y": 15,
      "z": -6,
      "name": "Soil_Dirt_White"
    },
    {
      "x": -2,
      "y": 16,
      "z": -6,
      "name": "Rock_Marble_Brick"
    },
    {
      "x": -2,
      "y": 17,
      "z": -6,
      "name": "Rock_Marble_Brick"
    },
    {
      "x": -2,
      "y": 18,
      "z": -6,
      "name": "Rock_Chalk"
    },
    {
      "x": -2,
      "y": 19,
      "z": -6,
      "name": "Rock_Chalk"
    },
    {
      "x": -2,
      "y": 20,
      "z": -6,
      "name": "Rock_Chalk"
    },
    {
      "x": -2,
      "y": 21,
      "z": -6,
      "name": "Rock_Chalk"
    },
    {
      "x": -2,
      "y": 22,
      "z": -6,
      "name": "Rock_Chalk"
    },
    {
      "x": -2,
      "y": 23,
      "z": -6,
      "name": "Rock_Chalk"
    },
    {
      "x": -2,
      "y": 24,
      "z": -6,
      "name": "Rock_Chalk"
    },
    {
      "x": -2,
      "y": 25,
      "z": -6,
      "name": "Rock_Chalk"
    },
    {
      "x": -2,
      "y": 26,
      "z": -6,
      "name": "Rock_Marble_Brick_Smooth"
    },
    {
      "x": -2,
      "y": 27,
      "z": -6,
      "name": "Rock_Marble_Brick_Smooth"
    },
    {
      "x": -2,
      "y": 4,
      "z": -5,
      "name": "Rock_Chalk"
    },
    {
      "x": -2,
      "y": 5,
      "z": -5,
      "name": "Rock_Chalk"
    },
    {
      "x": -2,
      "y": 6,
      "z": -5,
      "name": "Rock_Chalk"
    },
    {
      "x": -2,
      "y": 7,
      "z": -5,
      "name": "Rock_Chalk"
    },
    {
      "x": -2,
      "y": 8,
      "z": -5,
      "name": "Rock_Chalk"
    },
    {
      "x": -2,
      "y": 9,
      "z": -5,
      "name": "Rock_Chalk"
    },
    {
      "x": -2,
      "y": 10,
      "z": -5,
      "name": "Rock_Chalk"
    },
    {
      "x": -2,
      "y": 11,
      "z": -5,
      "name": "Rock_Chalk"
    },
    {
      "x": -2,
      "y": 12,
      "z": -5,
      "name": "Rock_Chalk"
    },
    {
      "x": -2,
      "y": 13,
      "z": -5,
      "name": "Soil_Dirt_White"
    },
    {
      "x": -2,
      "y": 14,
      "z": -5,
      "name": "Soil_Dirt_White"
    },
    {
      "x": -2,
      "y": 15,
      "z": -5,
      "name": "Soil_Dirt_White"
    },
    {
      "x": -2,
      "y": 16,
      "z": -5,
      "name": "Rock_Marble_Brick"
    },
    {
      "x": -2,
      "y": 24,
      "z": -5,
      "name": "Rock_Chalk"
    },
    {
      "x": -2,
      "y": 26,
      "z": -5,
      "name": "Rock_Marble_Brick_Smooth"
    },
    {
      "x": -2,
      "y": 27,
      "z": -5,
      "name": "Rock_Marble_Brick_Smooth"
    },
    {
      "x": -2,
      "y": 4,
      "z": -4,
      "name": "Rock_Chalk"
    },
    {
      "x": -2,
      "y": 5,
      "z": -4,
      "name": "Rock_Chalk"
    },
    {
      "x": -2,
      "y": 6,
      "z": -4,
      "name": "Rock_Chalk"
    },
    {
      "x": -2,
      "y": 7,
      "z": -4,
      "name": "Rock_Chalk"
    },
    {
      "x": -2,
      "y": 8,
      "z": -4,
      "name": "Rock_Chalk"
    },
    {
      "x": -2,
      "y": 9,
      "z": -4,
      "name": "Rock_Chalk"
    },
    {
      "x": -2,
      "y": 10,
      "z": -4,
      "name": "Rock_Chalk"
    },
    {
      "x": -2,
      "y": 11,
      "z": -4,
      "name": "Rock_Chalk"
    },
    {
      "x": -2,
      "y": 12,
      "z": -4,
      "name": "Rock_Chalk"
    },
    {
      "x": -2,
      "y": 13,
      "z": -4,
      "name": "Soil_Dirt_White"
    },
    {
      "x": -2,
      "y": 14,
      "z": -4,
      "name": "Soil_Dirt_White"
    },
    {
      "x": -2,
      "y": 15,
      "z": -4,
      "name": "Soil_Dirt_White"
    },
    {
      "x": -2,
      "y": 16,
      "z": -4,
      "name": "Rock_Marble_Brick"
    },
    {
      "x": -2,
      "y": 26,
      "z": -4,
      "name": "Rock_Marble_Brick_Smooth"
    },
    {
      "x": -2,
      "y": 27,
      "z": -4,
      "name": "Rock_Marble_Brick_Smooth"
    },
    {
      "x": -2,
      "y": 3,
      "z": -3,
      "name": "Rock_Chalk"
    },
    {
      "x": -2,
      "y": 4,
      "z": -3,
      "name": "Rock_Chalk"
    },
    {
      "x": -2,
      "y": 5,
      "z": -3,
      "name": "Rock_Chalk"
    },
    {
      "x": -2,
      "y": 6,
      "z": -3,
      "name": "Rock_Chalk"
    },
    {
      "x": -2,
      "y": 7,
      "z": -3,
      "name": "Rock_Chalk"
    },
    {
      "x": -2,
      "y": 8,
      "z": -3,
      "name": "Rock_Chalk"
    },
    {
      "x": -2,
      "y": 9,
      "z": -3,
      "name": "Rock_Chalk"
    },
    {
      "x": -2,
      "y": 10,
      "z": -3,
      "name": "Rock_Chalk"
    },
    {
      "x": -2,
      "y": 11,
      "z": -3,
      "name": "Rock_Chalk"
    },
    {
      "x": -2,
      "y": 12,
      "z": -3,
      "name": "Rock_Chalk"
    },
    {
      "x": -2,
      "y": 13,
      "z": -3,
      "name": "Rock_Chalk"
    },
    {
      "x": -2,
      "y": 14,
      "z": -3,
      "name": "Rock_Chalk"
    },
    {
      "x": -2,
      "y": 15,
      "z": -3,
      "name": "Rock_Chalk"
    },
    {
      "x": -2,
      "y": 16,
      "z": -3,
      "name": "Rock_Marble_Brick"
    },
    {
      "x": -2,
      "y": 17,
      "z": -3,
      "name": "Plant_Moss_Rug_Green"
    },
    {
      "x": -2,
      "y": 26,
      "z": -3,
      "name": "Rock_Marble_Brick_Smooth"
    },
    {
      "x": -2,
      "y": 27,
      "z": -3,
      "name": "Rock_Marble_Brick_Smooth"
    },
    {
      "x": -2,
      "y": 3,
      "z": -2,
      "name": "Rock_Chalk"
    },
    {
      "x": -2,
      "y": 4,
      "z": -2,
      "name": "Rock_Chalk"
    },
    {
      "x": -2,
      "y": 5,
      "z": -2,
      "name": "Rock_Chalk"
    },
    {
      "x": -2,
      "y": 6,
      "z": -2,
      "name": "Rock_Chalk"
    },
    {
      "x": -2,
      "y": 7,
      "z": -2,
      "name": "Rock_Chalk"
    },
    {
      "x": -2,
      "y": 8,
      "z": -2,
      "name": "Rock_Chalk"
    },
    {
      "x": -2,
      "y": 9,
      "z": -2,
      "name": "Rock_Chalk"
    },
    {
      "x": -2,
      "y": 10,
      "z": -2,
      "name": "Rock_Chalk"
    },
    {
      "x": -2,
      "y": 11,
      "z": -2,
      "name": "Rock_Chalk"
    },
    {
      "x": -2,
      "y": 12,
      "z": -2,
      "name": "Rock_Chalk"
    },
    {
      "x": -2,
      "y": 13,
      "z": -2,
      "name": "Rock_Chalk"
    },
    {
      "x": -2,
      "y": 14,
      "z": -2,
      "name": "Rock_Chalk"
    },
    {
      "x": -2,
      "y": 15,
      "z": -2,
      "name": "Rock_Chalk"
    },
    {
      "x": -2,
      "y": 16,
      "z": -2,
      "name": "Rock_Marble_Brick"
    },
    {
      "x": -2,
      "y": 17,
      "z": -2,
      "name": "Plant_Moss_Block_Green"
    },
    {
      "x": -2,
      "y": 18,
      "z": -2,
      "name": "Plant_Moss_Rug_Green"
    },
    {
      "x": -2,
      "y": 24,
      "z": -2,
      "name": "Plant_Moss_Cave_Green",
      "rotation": 8
    },
    {
      "x": -2,
      "y": 25,
      "z": -2,
      "name": "Rock_Chalk"
    },
    {
      "x": -2,
      "y": 26,
      "z": -2,
      "name": "Rock_Marble_Brick_Smooth"
    },
    {
      "x": -2,
      "y": 27,
      "z": -2,
      "name": "Rock_Marble_Brick_Smooth"
    },
    {
      "x": -2,
      "y": 3,
      "z": -1,
      "name": "Rock_Chalk"
    },
    {
      "x": -2,
      "y": 4,
      "z": -1,
      "name": "Rock_Chalk"
    },
    {
      "x": -2,
      "y": 5,
      "z": -1,
      "name": "Rock_Chalk"
    },
    {
      "x": -2,
      "y": 6,
      "z": -1,
      "name": "Rock_Chalk"
    },
    {
      "x": -2,
      "y": 7,
      "z": -1,
      "name": "Rock_Chalk"
    },
    {
      "x": -2,
      "y": 8,
      "z": -1,
      "name": "Rock_Chalk"
    },
    {
      "x": -2,
      "y": 9,
      "z": -1,
      "name": "Rock_Chalk"
    },
    {
      "x": -2,
      "y": 10,
      "z": -1,
      "name": "Rock_Chalk"
    },
    {
      "x": -2,
      "y": 11,
      "z": -1,
      "name": "Rock_Chalk"
    },
    {
      "x": -2,
      "y": 12,
      "z": -1,
      "name": "Rock_Chalk"
    },
    {
      "x": -2,
      "y": 13,
      "z": -1,
      "name": "Rock_Chalk"
    },
    {
      "x": -2,
      "y": 14,
      "z": -1,
      "name": "Rock_Chalk"
    },
    {
      "x": -2,
      "y": 15,
      "z": -1,
      "name": "Rock_Chalk"
    },
    {
      "x": -2,
      "y": 16,
      "z": -1,
      "name": "Rock_Marble_Brick"
    },
    {
      "x": -2,
      "y": 17,
      "z": -1,
      "name": "Plant_Moss_Block_Green"
    },
    {
      "x": -2,
      "y": 18,
      "z": -1,
      "name": "Plant_Moss_Rug_Green"
    },
    {
      "x": -2,
      "y": 23,
      "z": -1,
      "name": "Plant_Moss_Cave_Green",
      "rotation": 8
    },
    {
      "x": -2,
      "y": 24,
      "z": -1,
      "name": "Rock_Chalk"
    },
    {
      "x": -2,
      "y": 25,
      "z": -1,
      "name": "Rock_Chalk"
    },
    {
      "x": -2,
      "y": 26,
      "z": -1,
      "name": "Rock_Marble_Brick_Smooth"
    },
    {
      "x": -2,
      "y": 27,
      "z": -1,
      "name": "Rock_Marble_Brick_Smooth"
    },
    {
      "x": -2,
      "y": 2,
      "z": 0,
      "name": "Rock_Chalk"
    },
    {
      "x": -2,
      "y": 3,
      "z": 0,
      "name": "Rock_Chalk"
    },
    {
      "x": -2,
      "y": 4,
      "z": 0,
      "name": "Rock_Chalk"
    },
    {
      "x": -2,
      "y": 5,
      "z": 0,
      "name": "Rock_Chalk"
    },
    {
      "x": -2,
      "y": 6,
      "z": 0,
      "name": "Rock_Chalk"
    },
    {
      "x": -2,
      "y": 7,
      "z": 0,
      "name": "Rock_Chalk"
    },
    {
      "x": -2,
      "y": 8,
      "z": 0,
      "name": "Rock_Chalk"
    },
    {
      "x": -2,
      "y": 9,
      "z": 0,
      "name": "Rock_Chalk"
    },
    {
      "x": -2,
      "y": 10,
      "z": 0,
      "name": "Rock_Chalk"
    },
    {
      "x": -2,
      "y": 11,
      "z": 0,
      "name": "Rock_Chalk"
    },
    {
      "x": -2,
      "y": 12,
      "z": 0,
      "name": "Rock_Chalk"
    },
    {
      "x": -2,
      "y": 13,
      "z": 0,
      "name": "Rock_Chalk"
    },
    {
      "x": -2,
      "y": 14,
      "z": 0,
      "name": "Rock_Chalk"
    },
    {
      "x": -2,
      "y": 15,
      "z": 0,
      "name": "Rock_Chalk"
    },
    {
      "x": -2,
      "y": 16,
      "z": 0,
      "name": "Rock_Marble_Brick"
    },
    {
      "x": -2,
      "y": 17,
      "z": 0,
      "name": "Rock_Marble_Brick"
    },
    {
      "x": -2,
      "y": 18,
      "z": 0,
      "name": "Rock_Marble_Brick"
    },
    {
      "x": -2,
      "y": 19,
      "z": 0,
      "name": "Rock_Chalk"
    },
    {
      "x": -2,
      "y": 22,
      "z": 0,
      "name": "Rock_Chalk"
    },
    {
      "x": -2,
      "y": 23,
      "z": 0,
      "name": "Rock_Chalk"
    },
    {
      "x": -2,
      "y": 24,
      "z": 0,
      "name": "Rock_Chalk"
    },
    {
      "x": -2,
      "y": 25,
      "z": 0,
      "name": "Rock_Chalk"
    },
    {
      "x": -2,
      "y": 26,
      "z": 0,
      "name": "Rock_Marble_Brick_Smooth"
    },
    {
      "x": -2,
      "y": 27,
      "z": 0,
      "name": "Rock_Marble_Brick_Smooth"
    },
    {
      "x": -2,
      "y": 4,
      "z": 1,
      "name": "Rock_Chalk"
    },
    {
      "x": -2,
      "y": 5,
      "z": 1,
      "name": "Rock_Chalk"
    },
    {
      "x": -2,
      "y": 6,
      "z": 1,
      "name": "Rock_Chalk"
    },
    {
      "x": -2,
      "y": 7,
      "z": 1,
      "name": "Rock_Chalk"
    },
    {
      "x": -2,
      "y": 8,
      "z": 1,
      "name": "Rock_Chalk"
    },
    {
      "x": -2,
      "y": 9,
      "z": 1,
      "name": "Rock_Chalk"
    },
    {
      "x": -2,
      "y": 10,
      "z": 1,
      "name": "Rock_Chalk"
    },
    {
      "x": -2,
      "y": 11,
      "z": 1,
      "name": "Rock_Chalk"
    },
    {
      "x": -2,
      "y": 12,
      "z": 1,
      "name": "Rock_Chalk"
    },
    {
      "x": -2,
      "y": 13,
      "z": 1,
      "name": "Rock_Chalk"
    },
    {
      "x": -2,
      "y": 14,
      "z": 1,
      "name": "Rock_Chalk"
    },
    {
      "x": -2,
      "y": 15,
      "z": 1,
      "name": "Rock_Chalk"
    },
    {
      "x": -2,
      "y": 16,
      "z": 1,
      "name": "Rock_Marble_Brick"
    },
    {
      "x": -2,
      "y": 17,
      "z": 1,
      "name": "Rock_Marble_Brick"
    },
    {
      "x": -2,
      "y": 18,
      "z": 1,
      "name": "Rock_Marble_Brick"
    },
    {
      "x": -2,
      "y": 19,
      "z": 1,
      "name": "Rock_Chalk"
    },
    {
      "x": -2,
      "y": 20,
      "z": 1,
      "name": "Rock_Chalk"
    },
    {
      "x": -2,
      "y": 23,
      "z": 1,
      "name": "Rock_Chalk"
    },
    {
      "x": -2,
      "y": 24,
      "z": 1,
      "name": "Rock_Chalk"
    },
    {
      "x": -2,
      "y": 25,
      "z": 1,
      "name": "Rock_Chalk"
    },
    {
      "x": -2,
      "y": 26,
      "z": 1,
      "name": "Rock_Marble_Brick_Smooth"
    },
    {
      "x": -2,
      "y": 27,
      "z": 1,
      "name": "Rock_Marble_Brick_Smooth"
    },
    {
      "x": -2,
      "y": 28,
      "z": 1,
      "name": "Plant_Moss_Rug_Green"
    },
    {
      "x": -2,
      "y": 5,
      "z": 2,
      "name": "Rock_Chalk"
    },
    {
      "x": -2,
      "y": 6,
      "z": 2,
      "name": "Rock_Chalk"
    },
    {
      "x": -2,
      "y": 7,
      "z": 2,
      "name": "Rock_Chalk"
    },
    {
      "x": -2,
      "y": 8,
      "z": 2,
      "name": "Rock_Chalk"
    },
    {
      "x": -2,
      "y": 9,
      "z": 2,
      "name": "Rock_Chalk"
    },
    {
      "x": -2,
      "y": 10,
      "z": 2,
      "name": "Rock_Chalk"
    },
    {
      "x": -2,
      "y": 11,
      "z": 2,
      "name": "Rock_Chalk"
    },
    {
      "x": -2,
      "y": 12,
      "z": 2,
      "name": "Rock_Chalk"
    },
    {
      "x": -2,
      "y": 13,
      "z": 2,
      "name": "Rock_Chalk"
    },
    {
      "x": -2,
      "y": 14,
      "z": 2,
      "name": "Rock_Chalk"
    },
    {
      "x": -2,
      "y": 15,
      "z": 2,
      "name": "Rock_Chalk"
    },
    {
      "x": -2,
      "y": 9,
      "z": 3,
      "name": "Rock_Chalk"
    },
    {
      "x": -2,
      "y": 10,
      "z": 3,
      "name": "Rock_Chalk"
    },
    {
      "x": -2,
      "y": 11,
      "z": 3,
      "name": "Rock_Chalk"
    },
    {
      "x": -2,
      "y": 12,
      "z": 3,
      "name": "Rock_Chalk"
    },
    {
      "x": -2,
      "y": 13,
      "z": 3,
      "name": "Rock_Chalk"
    },
    {
      "x": -2,
      "y": 14,
      "z": 3,
      "name": "Rock_Chalk"
    },
    {
      "x": -2,
      "y": 28,
      "z": 4,
      "name": "Rock_Marble_Brick_Smooth"
    },
    {
      "x": -2,
      "y": 29,
      "z": 4,
      "name": "Rock_Marble_Brick_Smooth"
    },
    {
      "x": -2,
      "y": 30,
      "z": 4,
      "name": "Rock_Marble_Brick_Wall",
      "rotation": 1
    },
    {
      "x": -2,
      "y": 28,
      "z": 5,
      "name": "Rock_Marble_Brick_Smooth"
    },
    {
      "x": -2,
      "y": 29,
      "z": 5,
      "name": "Rock_Marble_Brick_Smooth"
    },
    {
      "x": -2,
      "y": 30,
      "z": 5,
      "name": "Rock_Marble_Brick_Wall",
      "rotation": 1
    },
    {
      "x": -2,
      "y": 28,
      "z": 6,
      "name": "Rock_Marble_Brick_Smooth"
    },
    {
      "x": -2,
      "y": 29,
      "z": 6,
      "name": "Rock_Marble_Brick_Smooth"
    },
    {
      "x": -1,
      "y": 9,
      "z": -9,
      "name": "Rock_Chalk"
    },
    {
      "x": -1,
      "y": 10,
      "z": -9,
      "name": "Rock_Chalk"
    },
    {
      "x": -1,
      "y": 26,
      "z": -9,
      "name": "Rock_Marble_Brick_Smooth"
    },
    {
      "x": -1,
      "y": 27,
      "z": -9,
      "name": "Rock_Marble_Brick_Smooth"
    },
    {
      "x": -1,
      "y": 7,
      "z": -8,
      "name": "Rock_Chalk"
    },
    {
      "x": -1,
      "y": 8,
      "z": -8,
      "name": "Rock_Chalk"
    },
    {
      "x": -1,
      "y": 9,
      "z": -8,
      "name": "Rock_Chalk"
    },
    {
      "x": -1,
      "y": 10,
      "z": -8,
      "name": "Rock_Chalk"
    },
    {
      "x": -1,
      "y": 11,
      "z": -8,
      "name": "Rock_Chalk"
    },
    {
      "x": -1,
      "y": 12,
      "z": -8,
      "name": "Soil_Gravel"
    },
    {
      "x": -1,
      "y": 13,
      "z": -8,
      "name": "Rock_Chalk"
    },
    {
      "x": -1,
      "y": 26,
      "z": -8,
      "name": "Rock_Marble_Brick_Smooth"
    },
    {
      "x": -1,
      "y": 27,
      "z": -8,
      "name": "Rock_Marble_Brick_Smooth"
    },
    {
      "x": -1,
      "y": 4,
      "z": -7,
      "name": "Rock_Chalk"
    },
    {
      "x": -1,
      "y": 5,
      "z": -7,
      "name": "Rock_Chalk"
    },
    {
      "x": -1,
      "y": 6,
      "z": -7,
      "name": "Rock_Chalk"
    },
    {
      "x": -1,
      "y": 7,
      "z": -7,
      "name": "Rock_Chalk"
    },
    {
      "x": -1,
      "y": 8,
      "z": -7,
      "name": "Rock_Chalk"
    },
    {
      "x": -1,
      "y": 9,
      "z": -7,
      "name": "Rock_Chalk"
    },
    {
      "x": -1,
      "y": 10,
      "z": -7,
      "name": "Rock_Chalk"
    },
    {
      "x": -1,
      "y": 11,
      "z": -7,
      "name": "Rock_Chalk"
    },
    {
      "x": -1,
      "y": 12,
      "z": -7,
      "name": "Soil_Dirt_White"
    },
    {
      "x": -1,
      "y": 13,
      "z": -7,
      "name": "Soil_Grass_White"
    },
    {
      "x": -1,
      "y": 26,
      "z": -7,
      "name": "Rock_Marble_Brick_Smooth"
    },
    {
      "x": -1,
      "y": 27,
      "z": -7,
      "name": "Rock_Marble_Brick_Smooth"
    },
    {
      "x": -1,
      "y": 28,
      "z": -7,
      "name": "Rock_Marble_Brick_Wall",
      "rotation": 1
    },
    {
      "x": -1,
      "y": 3,
      "z": -6,
      "name": "Rock_Chalk"
    },
    {
      "x": -1,
      "y": 4,
      "z": -6,
      "name": "Rock_Chalk"
    },
    {
      "x": -1,
      "y": 5,
      "z": -6,
      "name": "Rock_Chalk"
    },
    {
      "x": -1,
      "y": 6,
      "z": -6,
      "name": "Rock_Chalk"
    },
    {
      "x": -1,
      "y": 7,
      "z": -6,
      "name": "Rock_Chalk"
    },
    {
      "x": -1,
      "y": 8,
      "z": -6,
      "name": "Rock_Chalk"
    },
    {
      "x": -1,
      "y": 9,
      "z": -6,
      "name": "Rock_Chalk"
    },
    {
      "x": -1,
      "y": 10,
      "z": -6,
      "name": "Rock_Chalk"
    },
    {
      "x": -1,
      "y": 11,
      "z": -6,
      "name": "Rock_Chalk"
    },
    {
      "x": -1,
      "y": 12,
      "z": -6,
      "name": "Rock_Chalk"
    },
    {
      "x": -1,
      "y": 13,
      "z": -6,
      "name": "Soil_Dirt_White"
    },
    {
      "x": -1,
      "y": 14,
      "z": -6,
      "name": "Soil_Grass_White"
    },
    {
      "x": -1,
      "y": 26,
      "z": -6,
      "name": "Rock_Marble_Brick_Smooth"
    },
    {
      "x": -1,
      "y": 27,
      "z": -6,
      "name": "Rock_Marble_Brick_Smooth"
    },
    {
      "x": -1,
      "y": 28,
      "z": -6,
      "name": "Rock_Marble_Brick_Wall",
      "rotation": 1
    },
    {
      "x": -1,
      "y": 4,
      "z": -5,
      "name": "Rock_Chalk"
    },
    {
      "x": -1,
      "y": 5,
      "z": -5,
      "name": "Rock_Chalk"
    },
    {
      "x": -1,
      "y": 6,
      "z": -5,
      "name": "Rock_Chalk"
    },
    {
      "x": -1,
      "y": 7,
      "z": -5,
      "name": "Rock_Chalk"
    },
    {
      "x": -1,
      "y": 8,
      "z": -5,
      "name": "Rock_Chalk"
    },
    {
      "x": -1,
      "y": 9,
      "z": -5,
      "name": "Rock_Chalk"
    },
    {
      "x": -1,
      "y": 10,
      "z": -5,
      "name": "Rock_Chalk"
    },
    {
      "x": -1,
      "y": 11,
      "z": -5,
      "name": "Soil_Dirt_White"
    },
    {
      "x": -1,
      "y": 12,
      "z": -5,
      "name": "Soil_Dirt_White"
    },
    {
      "x": -1,
      "y": 13,
      "z": -5,
      "name": "Rock_Chalk"
    },
    {
      "x": -1,
      "y": 14,
      "z": -5,
      "name": "Soil_Dirt_White"
    },
    {
      "x": -1,
      "y": 15,
      "z": -5,
      "name": "Soil_Grass_White"
    },
    {
      "x": -1,
      "y": 26,
      "z": -5,
      "name": "Rock_Marble_Brick_Smooth"
    },
    {
      "x": -1,
      "y": 27,
      "z": -5,
      "name": "Rock_Marble_Brick_Smooth"
    },
    {
      "x": -1,
      "y": 4,
      "z": -4,
      "name": "Rock_Chalk"
    },
    {
      "x": -1,
      "y": 5,
      "z": -4,
      "name": "Rock_Chalk"
    },
    {
      "x": -1,
      "y": 6,
      "z": -4,
      "name": "Rock_Chalk"
    },
    {
      "x": -1,
      "y": 7,
      "z": -4,
      "name": "Rock_Chalk"
    },
    {
      "x": -1,
      "y": 8,
      "z": -4,
      "name": "Rock_Chalk"
    },
    {
      "x": -1,
      "y": 9,
      "z": -4,
      "name": "Rock_Chalk"
    },
    {
      "x": -1,
      "y": 10,
      "z": -4,
      "name": "Rock_Chalk"
    },
    {
      "x": -1,
      "y": 11,
      "z": -4,
      "name": "Rock_Chalk"
    },
    {
      "x": -1,
      "y": 12,
      "z": -4,
      "name": "Soil_Dirt_White"
    },
    {
      "x": -1,
      "y": 13,
      "z": -4,
      "name": "Rock_Chalk"
    },
    {
      "x": -1,
      "y": 14,
      "z": -4,
      "name": "Soil_Dirt_White"
    },
    {
      "x": -1,
      "y": 15,
      "z": -4,
      "name": "Soil_Grass_Full"
    },
    {
      "x": -1,
      "y": 28,
      "z": -4,
      "name": "Rock_Marble_Brick_Wall",
      "rotation": 1
    },
    {
      "x": -1,
      "y": 3,
      "z": -3,
      "name": "Rock_Chalk"
    },
    {
      "x": -1,
      "y": 4,
      "z": -3,
      "name": "Rock_Chalk"
    },
    {
      "x": -1,
      "y": 5,
      "z": -3,
      "name": "Rock_Chalk"
    },
    {
      "x": -1,
      "y": 6,
      "z": -3,
      "name": "Rock_Chalk"
    },
    {
      "x": -1,
      "y": 7,
      "z": -3,
      "name": "Rock_Chalk"
    },
    {
      "x": -1,
      "y": 8,
      "z": -3,
      "name": "Rock_Chalk"
    },
    {
      "x": -1,
      "y": 9,
      "z": -3,
      "name": "Rock_Chalk"
    },
    {
      "x": -1,
      "y": 10,
      "z": -3,
      "name": "Rock_Chalk"
    },
    {
      "x": -1,
      "y": 11,
      "z": -3,
      "name": "Rock_Chalk"
    },
    {
      "x": -1,
      "y": 12,
      "z": -3,
      "name": "Rock_Chalk"
    },
    {
      "x": -1,
      "y": 13,
      "z": -3,
      "name": "Soil_Dirt_White"
    },
    {
      "x": -1,
      "y": 14,
      "z": -3,
      "name": "Rock_Chalk"
    },
    {
      "x": -1,
      "y": 15,
      "z": -3,
      "name": "Soil_Grass_White"
    },
    {
      "x": -1,
      "y": 16,
      "z": -3,
      "name": "Plant_Moss_Rug_Green"
    },
    {
      "x": -1,
      "y": 27,
      "z": -3,
      "name": "Rock_Marble_Brick_Smooth"
    },
    {
      "x": -1,
      "y": 28,
      "z": -3,
      "name": "Rock_Marble_Brick_Wall",
      "rotation": 1
    },
    {
      "x": -1,
      "y": 2,
      "z": -2,
      "name": "Rock_Chalk"
    },
    {
      "x": -1,
      "y": 3,
      "z": -2,
      "name": "Rock_Chalk"
    },
    {
      "x": -1,
      "y": 4,
      "z": -2,
      "name": "Rock_Chalk"
    },
    {
      "x": -1,
      "y": 5,
      "z": -2,
      "name": "Rock_Chalk"
    },
    {
      "x": -1,
      "y": 6,
      "z": -2,
      "name": "Rock_Chalk"
    },
    {
      "x": -1,
      "y": 7,
      "z": -2,
      "name": "Rock_Chalk"
    },
    {
      "x": -1,
      "y": 8,
      "z": -2,
      "name": "Rock_Chalk"
    },
    {
      "x": -1,
      "y": 9,
      "z": -2,
      "name": "Rock_Chalk"
    },
    {
      "x": -1,
      "y": 10,
      "z": -2,
      "name": "Rock_Chalk"
    },
    {
      "x": -1,
      "y": 11,
      "z": -2,
      "name": "Rock_Chalk"
    },
    {
      "x": -1,
      "y": 12,
      "z": -2,
      "name": "Rock_Chalk"
    },
    {
      "x": -1,
      "y": 13,
      "z": -2,
      "name": "Soil_Dirt_White"
    },
    {
      "x": -1,
      "y": 14,
      "z": -2,
      "name": "Soil_Dirt_White"
    },
    {
      "x": -1,
      "y": 15,
      "z": -2,
      "name": "Soil_Dirt_White"
    },
    {
      "x": -1,
      "y": 16,
      "z": -2,
      "name": "Plant_Moss_Block_Green"
    },
    {
      "x": -1,
      "y": 17,
      "z": -2,
      "name": "Plant_Moss_Rug_Green"
    },
    {
      "x": -1,
      "y": 26,
      "z": -2,
      "name": "Rock_Marble_Brick_Smooth"
    },
    {
      "x": -1,
      "y": 27,
      "z": -2,
      "name": "Rock_Marble_Brick_Smooth"
    },
    {
      "x": -1,
      "y": 2,
      "z": -1,
      "name": "Rock_Chalk"
    },
    {
      "x": -1,
      "y": 3,
      "z": -1,
      "name": "Rock_Chalk"
    },
    {
      "x": -1,
      "y": 4,
      "z": -1,
      "name": "Rock_Chalk"
    },
    {
      "x": -1,
      "y": 5,
      "z": -1,
      "name": "Rock_Chalk"
    },
    {
      "x": -1,
      "y": 6,
      "z": -1,
      "name": "Rock_Chalk"
    },
    {
      "x": -1,
      "y": 7,
      "z": -1,
      "name": "Rock_Chalk"
    },
    {
      "x": -1,
      "y": 8,
      "z": -1,
      "name": "Rock_Chalk"
    },
    {
      "x": -1,
      "y": 9,
      "z": -1,
      "name": "Rock_Chalk"
    },
    {
      "x": -1,
      "y": 10,
      "z": -1,
      "name": "Rock_Chalk"
    },
    {
      "x": -1,
      "y": 11,
      "z": -1,
      "name": "Rock_Chalk"
    },
    {
      "x": -1,
      "y": 12,
      "z": -1,
      "name": "Rock_Chalk"
    },
    {
      "x": -1,
      "y": 13,
      "z": -1,
      "name": "Rock_Chalk"
    },
    {
      "x": -1,
      "y": 14,
      "z": -1,
      "name": "Rock_Chalk"
    },
    {
      "x": -1,
      "y": 15,
      "z": -1,
      "name": "Rock_Chalk"
    },
    {
      "x": -1,
      "y": 16,
      "z": -1,
      "name": "Plant_Moss_Block_Green"
    },
    {
      "x": -1,
      "y": 17,
      "z": -1,
      "name": "Plant_Moss_Rug_Green"
    },
    {
      "x": -1,
      "y": 26,
      "z": -1,
      "name": "Rock_Marble_Brick_Smooth"
    },
    {
      "x": -1,
      "y": 27,
      "z": -1,
      "name": "Rock_Marble_Brick_Smooth"
    },
    {
      "x": -1,
      "y": 28,
      "z": -1,
      "name": "Rock_Marble_Brick_Wall",
      "rotation": 1
    },
    {
      "x": -1,
      "y": 2,
      "z": 0,
      "name": "Rock_Chalk"
    },
    {
      "x": -1,
      "y": 3,
      "z": 0,
      "name": "Rock_Chalk"
    },
    {
      "x": -1,
      "y": 4,
      "z": 0,
      "name": "Rock_Chalk"
    },
    {
      "x": -1,
      "y": 5,
      "z": 0,
      "name": "Rock_Chalk"
    },
    {
      "x": -1,
      "y": 6,
      "z": 0,
      "name": "Rock_Chalk"
    },
    {
      "x": -1,
      "y": 7,
      "z": 0,
      "name": "Rock_Chalk"
    },
    {
      "x": -1,
      "y": 8,
      "z": 0,
      "name": "Rock_Chalk"
    },
    {
      "x": -1,
      "y": 9,
      "z": 0,
      "name": "Rock_Chalk"
    },
    {
      "x": -1,
      "y": 10,
      "z": 0,
      "name": "Rock_Chalk"
    },
    {
      "x": -1,
      "y": 11,
      "z": 0,
      "name": "Rock_Chalk"
    },
    {
      "x": -1,
      "y": 12,
      "z": 0,
      "name": "Rock_Chalk"
    },
    {
      "x": -1,
      "y": 13,
      "z": 0,
      "name": "Rock_Chalk"
    },
    {
      "x": -1,
      "y": 14,
      "z": 0,
      "name": "Rock_Chalk"
    },
    {
      "x": -1,
      "y": 15,
      "z": 0,
      "name": "Rock_Chalk"
    },
    {
      "x": -1,
      "y": 16,
      "z": 0,
      "name": "Plant_Moss_Block_Green"
    },
    {
      "x": -1,
      "y": 26,
      "z": 0,
      "name": "Rock_Marble_Brick_Smooth"
    },
    {
      "x": -1,
      "y": 27,
      "z": 0,
      "name": "Rock_Marble_Brick_Smooth"
    },
    {
      "x": -1,
      "y": 28,
      "z": 0,
      "name": "Rock_Marble_Brick_Wall",
      "rotation": 1
    },
    {
      "x": -1,
      "y": 2,
      "z": 1,
      "name": "Rock_Chalk"
    },
    {
      "x": -1,
      "y": 3,
      "z": 1,
      "name": "Rock_Chalk"
    },
    {
      "x": -1,
      "y": 4,
      "z": 1,
      "name": "Rock_Chalk"
    },
    {
      "x": -1,
      "y": 5,
      "z": 1,
      "name": "Rock_Chalk"
    },
    {
      "x": -1,
      "y": 6,
      "z": 1,
      "name": "Rock_Chalk"
    },
    {
      "x": -1,
      "y": 7,
      "z": 1,
      "name": "Rock_Chalk"
    },
    {
      "x": -1,
      "y": 8,
      "z": 1,
      "name": "Rock_Chalk"
    },
    {
      "x": -1,
      "y": 9,
      "z": 1,
      "name": "Rock_Chalk"
    },
    {
      "x": -1,
      "y": 10,
      "z": 1,
      "name": "Rock_Chalk"
    },
    {
      "x": -1,
      "y": 11,
      "z": 1,
      "name": "Rock_Chalk"
    },
    {
      "x": -1,
      "y": 12,
      "z": 1,
      "name": "Rock_Chalk"
    },
    {
      "x": -1,
      "y": 13,
      "z": 1,
      "name": "Rock_Chalk"
    },
    {
      "x": -1,
      "y": 14,
      "z": 1,
      "name": "Rock_Chalk"
    },
    {
      "x": -1,
      "y": 15,
      "z": 1,
      "name": "Plant_Moss_Block_Green"
    },
    {
      "x": -1,
      "y": 26,
      "z": 1,
      "name": "Rock_Marble_Brick_Smooth"
    },
    {
      "x": -1,
      "y": 27,
      "z": 1,
      "name": "Rock_Marble_Brick_Smooth"
    },
    {
      "x": -1,
      "y": 28,
      "z": 1,
      "name": "Plant_Moss_Rug_Green"
    },
    {
      "x": -1,
      "y": 4,
      "z": 2,
      "name": "Rock_Chalk"
    },
    {
      "x": -1,
      "y": 5,
      "z": 2,
      "name": "Rock_Chalk"
    },
    {
      "x": -1,
      "y": 6,
      "z": 2,
      "name": "Rock_Chalk"
    },
    {
      "x": -1,
      "y": 7,
      "z": 2,
      "name": "Rock_Chalk"
    },
    {
      "x": -1,
      "y": 8,
      "z": 2,
      "name": "Rock_Chalk"
    },
    {
      "x": -1,
      "y": 9,
      "z": 2,
      "name": "Rock_Chalk"
    },
    {
      "x": -1,
      "y": 10,
      "z": 2,
      "name": "Rock_Chalk"
    },
    {
      "x": -1,
      "y": 11,
      "z": 2,
      "name": "Rock_Chalk"
    },
    {
      "x": -1,
      "y": 12,
      "z": 2,
      "name": "Rock_Chalk"
    },
    {
      "x": -1,
      "y": 13,
      "z": 2,
      "name": "Rock_Chalk"
    },
    {
      "x": -1,
      "y": 14,
      "z": 2,
      "name": "Rock_Chalk"
    },
    {
      "x": -1,
      "y": 15,
      "z": 2,
      "name": "Plant_Moss_Block_Green"
    },
    {
      "x": -1,
      "y": 26,
      "z": 2,
      "name": "Rock_Marble_Brick_Smooth"
    },
    {
      "x": -1,
      "y": 27,
      "z": 2,
      "name": "Rock_Marble_Brick_Smooth"
    },
    {
      "x": -1,
      "y": 28,
      "z": 2,
      "name": "Plant_Moss_Rug_Green"
    },
    {
      "x": -1,
      "y": 6,
      "z": 3,
      "name": "Rock_Chalk"
    },
    {
      "x": -1,
      "y": 7,
      "z": 3,
      "name": "Rock_Chalk"
    },
    {
      "x": -1,
      "y": 8,
      "z": 3,
      "name": "Rock_Chalk"
    },
    {
      "x": -1,
      "y": 9,
      "z": 3,
      "name": "Rock_Chalk"
    },
    {
      "x": -1,
      "y": 10,
      "z": 3,
      "name": "Rock_Chalk"
    },
    {
      "x": -1,
      "y": 11,
      "z": 3,
      "name": "Rock_Chalk"
    },
    {
      "x": -1,
      "y": 12,
      "z": 3,
      "name": "Rock_Chalk"
    },
    {
      "x": -1,
      "y": 13,
      "z": 3,
      "name": "Rock_Chalk"
    },
    {
      "x": -1,
      "y": 14,
      "z": 3,
      "name": "Rock_Chalk"
    },
    {
      "x": 0,
      "y": 8,
      "z": -8,
      "name": "Rock_Chalk"
    },
    {
      "x": 0,
      "y": 9,
      "z": -8,
      "name": "Rock_Chalk"
    },
    {
      "x": 0,
      "y": 10,
      "z": -8,
      "name": "Rock_Chalk"
    },
    {
      "x": 0,
      "y": 11,
      "z": -8,
      "name": "Rock_Chalk"
    },
    {
      "x": 0,
      "y": 6,
      "z": -7,
      "name": "Rock_Chalk"
    },
    {
      "x": 0,
      "y": 7,
      "z": -7,
      "name": "Rock_Chalk"
    },
    {
      "x": 0,
      "y": 8,
      "z": -7,
      "name": "Rock_Chalk"
    },
    {
      "x": 0,
      "y": 9,
      "z": -7,
      "name": "Rock_Chalk"
    },
    {
      "x": 0,
      "y": 10,
      "z": -7,
      "name": "Rock_Chalk"
    },
    {
      "x": 0,
      "y": 11,
      "z": -7,
      "name": "Soil_Dirt_White"
    },
    {
      "x": 0,
      "y": 12,
      "z": -7,
      "name": "Soil_Grass_Full"
    },
    {
      "x": 0,
      "y": 4,
      "z": -6,
      "name": "Rock_Chalk"
    },
    {
      "x": 0,
      "y": 5,
      "z": -6,
      "name": "Rock_Chalk"
    },
    {
      "x": 0,
      "y": 6,
      "z": -6,
      "name": "Rock_Chalk"
    },
    {
      "x": 0,
      "y": 7,
      "z": -6,
      "name": "Rock_Chalk"
    },
    {
      "x": 0,
      "y": 8,
      "z": -6,
      "name": "Rock_Chalk"
    },
    {
      "x": 0,
      "y": 9,
      "z": -6,
      "name": "Rock_Chalk"
    },
    {
      "x": 0,
      "y": 10,
      "z": -6,
      "name": "Rock_Chalk"
    },
    {
      "x": 0,
      "y": 11,
      "z": -6,
      "name": "Rock_Chalk"
    },
    {
      "x": 0,
      "y": 12,
      "z": -6,
      "name": "Soil_Dirt_White"
    },
    {
      "x": 0,
      "y": 13,
      "z": -6,
      "name": "Soil_Grass_Full"
    },
    {
      "x": 0,
      "y": 3,
      "z": -5,
      "name": "Rock_Chalk"
    },
    {
      "x": 0,
      "y": 4,
      "z": -5,
      "name": "Rock_Chalk"
    },
    {
      "x": 0,
      "y": 5,
      "z": -5,
      "name": "Rock_Chalk"
    },
    {
      "x": 0,
      "y": 6,
      "z": -5,
      "name": "Rock_Chalk"
    },
    {
      "x": 0,
      "y": 7,
      "z": -5,
      "name": "Rock_Chalk"
    },
    {
      "x": 0,
      "y": 8,
      "z": -5,
      "name": "Rock_Chalk"
    },
    {
      "x": 0,
      "y": 9,
      "z": -5,
      "name": "Rock_Chalk"
    },
    {
      "x": 0,
      "y": 10,
      "z": -5,
      "name": "Rock_Chalk"
    },
    {
      "x": 0,
      "y": 11,
      "z": -5,
      "name": "Soil_Dirt_White"
    },
    {
      "x": 0,
      "y": 12,
      "z": -5,
      "name": "Rock_Chalk"
    },
    {
      "x": 0,
      "y": 13,
      "z": -5,
      "name": "Soil_Dirt_White"
    },
    {
      "x": 0,
      "y": 14,
      "z": -5,
      "name": "Soil_Grass_Full"
    },
    {
      "x": 0,
      "y": 4,
      "z": -4,
      "name": "Rock_Chalk"
    },
    {
      "x": 0,
      "y": 5,
      "z": -4,
      "name": "Rock_Chalk"
    },
    {
      "x": 0,
      "y": 6,
      "z": -4,
      "name": "Rock_Chalk"
    },
    {
      "x": 0,
      "y": 7,
      "z": -4,
      "name": "Rock_Chalk"
    },
    {
      "x": 0,
      "y": 8,
      "z": -4,
      "name": "Rock_Chalk"
    },
    {
      "x": 0,
      "y": 9,
      "z": -4,
      "name": "Rock_Chalk"
    },
    {
      "x": 0,
      "y": 10,
      "z": -4,
      "name": "Rock_Chalk"
    },
    {
      "x": 0,
      "y": 11,
      "z": -4,
      "name": "Soil_Dirt_White"
    },
    {
      "x": 0,
      "y": 12,
      "z": -4,
      "name": "Rock_Chalk"
    },
    {
      "x": 0,
      "y": 13,
      "z": -4,
      "name": "Soil_Dirt_White"
    },
    {
      "x": 0,
      "y": 14,
      "z": -4,
      "name": "Soil_Grass_Full"
    },
    {
      "x": 0,
      "y": 3,
      "z": -3,
      "name": "Rock_Chalk"
    },
    {
      "x": 0,
      "y": 4,
      "z": -3,
      "name": "Rock_Chalk"
    },
    {
      "x": 0,
      "y": 5,
      "z": -3,
      "name": "Rock_Chalk"
    },
    {
      "x": 0,
      "y": 6,
      "z": -3,
      "name": "Rock_Chalk"
    },
    {
      "x": 0,
      "y": 7,
      "z": -3,
      "name": "Rock_Chalk"
    },
    {
      "x": 0,
      "y": 8,
      "z": -3,
      "name": "Rock_Chalk"
    },
    {
      "x": 0,
      "y": 9,
      "z": -3,
      "name": "Rock_Chalk"
    },
    {
      "x": 0,
      "y": 10,
      "z": -3,
      "name": "Rock_Chalk"
    },
    {
      "x": 0,
      "y": 11,
      "z": -3,
      "name": "Soil_Dirt_White"
    },
    {
      "x": 0,
      "y": 12,
      "z": -3,
      "name": "Soil_Dirt_White"
    },
    {
      "x": 0,
      "y": 13,
      "z": -3,
      "name": "Rock_Chalk"
    },
    {
      "x": 0,
      "y": 14,
      "z": -3,
      "name": "Soil_Dirt_White"
    },
    {
      "x": 0,
      "y": 15,
      "z": -3,
      "name": "Soil_Grass_Full"
    },
    {
      "x": 0,
      "y": 2,
      "z": -2,
      "name": "Rock_Chalk"
    },
    {
      "x": 0,
      "y": 3,
      "z": -2,
      "name": "Rock_Chalk"
    },
    {
      "x": 0,
      "y": 4,
      "z": -2,
      "name": "Rock_Chalk"
    },
    {
      "x": 0,
      "y": 5,
      "z": -2,
      "name": "Rock_Chalk"
    },
    {
      "x": 0,
      "y": 6,
      "z": -2,
      "name": "Rock_Chalk"
    },
    {
      "x": 0,
      "y": 7,
      "z": -2,
      "name": "Rock_Chalk"
    },
    {
      "x": 0,
      "y": 8,
      "z": -2,
      "name": "Rock_Chalk"
    },
    {
      "x": 0,
      "y": 9,
      "z": -2,
      "name": "Rock_Chalk"
    },
    {
      "x": 0,
      "y": 10,
      "z": -2,
      "name": "Rock_Chalk"
    },
    {
      "x": 0,
      "y": 11,
      "z": -2,
      "name": "Rock_Chalk"
    },
    {
      "x": 0,
      "y": 12,
      "z": -2,
      "name": "Soil_Dirt_White"
    },
    {
      "x": 0,
      "y": 13,
      "z": -2,
      "name": "Soil_Dirt_White"
    },
    {
      "x": 0,
      "y": 14,
      "z": -2,
      "name": "Soil_Dirt_White"
    },
    {
      "x": 0,
      "y": 15,
      "z": -2,
      "name": "Plant_Moss_Block_Green"
    },
    {
      "x": 0,
      "y": 2,
      "z": -1,
      "name": "Rock_Chalk"
    },
    {
      "x": 0,
      "y": 3,
      "z": -1,
      "name": "Rock_Chalk"
    },
    {
      "x": 0,
      "y": 4,
      "z": -1,
      "name": "Rock_Chalk"
    },
    {
      "x": 0,
      "y": 5,
      "z": -1,
      "name": "Rock_Chalk"
    },
    {
      "x": 0,
      "y": 6,
      "z": -1,
      "name": "Rock_Chalk"
    },
    {
      "x": 0,
      "y": 7,
      "z": -1,
      "name": "Rock_Chalk"
    },
    {
      "x": 0,
      "y": 8,
      "z": -1,
      "name": "Rock_Chalk"
    },
    {
      "x": 0,
      "y": 9,
      "z": -1,
      "name": "Rock_Chalk"
    },
    {
      "x": 0,
      "y": 10,
      "z": -1,
      "name": "Rock_Chalk"
    },
    {
      "x": 0,
      "y": 11,
      "z": -1,
      "name": "Rock_Chalk"
    },
    {
      "x": 0,
      "y": 12,
      "z": -1,
      "name": "Rock_Chalk"
    },
    {
      "x": 0,
      "y": 13,
      "z": -1,
      "name": "Soil_Dirt_White"
    },
    {
      "x": 0,
      "y": 14,
      "z": -1,
      "name": "Soil_Dirt_White"
    },
    {
      "x": 0,
      "y": 15,
      "z": -1,
      "name": "Plant_Moss_Block_Green"
    },
    {
      "x": 0,
      "y": 1,
      "z": 0,
      "name": "Rock_Chalk"
    },
    {
      "x": 0,
      "y": 2,
      "z": 0,
      "name": "Rock_Chalk"
    },
    {
      "x": 0,
      "y": 3,
      "z": 0,
      "name": "Rock_Chalk"
    },
    {
      "x": 0,
      "y": 4,
      "z": 0,
      "name": "Rock_Chalk"
    },
    {
      "x": 0,
      "y": 5,
      "z": 0,
      "name": "Rock_Chalk"
    },
    {
      "x": 0,
      "y": 6,
      "z": 0,
      "name": "Rock_Chalk"
    },
    {
      "x": 0,
      "y": 7,
      "z": 0,
      "name": "Rock_Chalk"
    },
    {
      "x": 0,
      "y": 8,
      "z": 0,
      "name": "Rock_Chalk"
    },
    {
      "x": 0,
      "y": 9,
      "z": 0,
      "name": "Rock_Chalk"
    },
    {
      "x": 0,
      "y": 10,
      "z": 0,
      "name": "Rock_Chalk"
    },
    {
      "x": 0,
      "y": 11,
      "z": 0,
      "name": "Rock_Chalk"
    },
    {
      "x": 0,
      "y": 12,
      "z": 0,
      "name": "Rock_Chalk"
    },
    {
      "x": 0,
      "y": 13,
      "z": 0,
      "name": "Soil_Dirt_White"
    },
    {
      "x": 0,
      "y": 14,
      "z": 0,
      "name": "Soil_Dirt_White"
    },
    {
      "x": 0,
      "y": 15,
      "z": 0,
      "name": "Plant_Moss_Block_Green"
    },
    {
      "x": 0,
      "y": 1,
      "z": 1,
      "name": "Rock_Chalk"
    },
    {
      "x": 0,
      "y": 2,
      "z": 1,
      "name": "Rock_Chalk"
    },
    {
      "x": 0,
      "y": 3,
      "z": 1,
      "name": "Rock_Chalk"
    },
    {
      "x": 0,
      "y": 4,
      "z": 1,
      "name": "Rock_Chalk"
    },
    {
      "x": 0,
      "y": 5,
      "z": 1,
      "name": "Rock_Chalk"
    },
    {
      "x": 0,
      "y": 6,
      "z": 1,
      "name": "Rock_Chalk"
    },
    {
      "x": 0,
      "y": 7,
      "z": 1,
      "name": "Rock_Chalk"
    },
    {
      "x": 0,
      "y": 8,
      "z": 1,
      "name": "Rock_Chalk"
    },
    {
      "x": 0,
      "y": 9,
      "z": 1,
      "name": "Rock_Chalk"
    },
    {
      "x": 0,
      "y": 10,
      "z": 1,
      "name": "Rock_Chalk"
    },
    {
      "x": 0,
      "y": 11,
      "z": 1,
      "name": "Rock_Chalk"
    },
    {
      "x": 0,
      "y": 12,
      "z": 1,
      "name": "Rock_Chalk"
    },
    {
      "x": 0,
      "y": 13,
      "z": 1,
      "name": "Soil_Dirt_White"
    },
    {
      "x": 0,
      "y": 14,
      "z": 1,
      "name": "Plant_Moss_Block_Green"
    },
    {
      "x": 0,
      "y": 4,
      "z": 2,
      "name": "Rock_Chalk"
    },
    {
      "x": 0,
      "y": 5,
      "z": 2,
      "name": "Rock_Chalk"
    },
    {
      "x": 0,
      "y": 6,
      "z": 2,
      "name": "Rock_Chalk"
    },
    {
      "x": 0,
      "y": 7,
      "z": 2,
      "name": "Rock_Chalk"
    },
    {
      "x": 0,
      "y": 8,
      "z": 2,
      "name": "Rock_Chalk"
    },
    {
      "x": 0,
      "y": 9,
      "z": 2,
      "name": "Rock_Chalk"
    },
    {
      "x": 0,
      "y": 10,
      "z": 2,
      "name": "Rock_Chalk"
    },
    {
      "x": 0,
      "y": 11,
      "z": 2,
      "name": "Rock_Chalk"
    },
    {
      "x": 0,
      "y": 12,
      "z": 2,
      "name": "Rock_Chalk"
    },
    {
      "x": 0,
      "y": 13,
      "z": 2,
      "name": "Soil_Dirt_White"
    },
    {
      "x": 0,
      "y": 14,
      "z": 2,
      "name": "Soil_Grass_White"
    },
    {
      "x": 0,
      "y": 5,
      "z": 3,
      "name": "Rock_Chalk"
    },
    {
      "x": 0,
      "y": 6,
      "z": 3,
      "name": "Rock_Chalk"
    },
    {
      "x": 0,
      "y": 7,
      "z": 3,
      "name": "Rock_Chalk"
    },
    {
      "x": 0,
      "y": 8,
      "z": 3,
      "name": "Rock_Chalk"
    },
    {
      "x": 0,
      "y": 9,
      "z": 3,
      "name": "Rock_Chalk"
    },
    {
      "x": 0,
      "y": 10,
      "z": 3,
      "name": "Rock_Chalk"
    },
    {
      "x": 0,
      "y": 11,
      "z": 3,
      "name": "Rock_Chalk"
    },
    {
      "x": 0,
      "y": 12,
      "z": 3,
      "name": "Rock_Chalk"
    },
    {
      "x": 0,
      "y": 13,
      "z": 3,
      "name": "Soil_Dirt_White"
    },
    {
      "x": 0,
      "y": 14,
      "z": 3,
      "name": "Soil_Grass_Full"
    },
    {
      "x": 1,
      "y": 8,
      "z": -7,
      "name": "Rock_Chalk"
    },
    {
      "x": 1,
      "y": 9,
      "z": -7,
      "name": "Rock_Chalk"
    },
    {
      "x": 1,
      "y": 10,
      "z": -7,
      "name": "Soil_Dirt_White"
    },
    {
      "x": 1,
      "y": 11,
      "z": -7,
      "name": "Soil_Grass_Full"
    },
    {
      "x": 1,
      "y": 5,
      "z": -6,
      "name": "Rock_Chalk"
    },
    {
      "x": 1,
      "y": 6,
      "z": -6,
      "name": "Rock_Chalk"
    },
    {
      "x": 1,
      "y": 7,
      "z": -6,
      "name": "Rock_Chalk"
    },
    {
      "x": 1,
      "y": 8,
      "z": -6,
      "name": "Rock_Chalk"
    },
    {
      "x": 1,
      "y": 9,
      "z": -6,
      "name": "Rock_Chalk"
    },
    {
      "x": 1,
      "y": 10,
      "z": -6,
      "name": "Rock_Chalk"
    },
    {
      "x": 1,
      "y": 11,
      "z": -6,
      "name": "Soil_Dirt_White"
    },
    {
      "x": 1,
      "y": 12,
      "z": -6,
      "name": "Soil_Grass_Full"
    },
    {
      "x": 1,
      "y": 3,
      "z": -5,
      "name": "Rock_Chalk"
    },
    {
      "x": 1,
      "y": 4,
      "z": -5,
      "name": "Rock_Chalk"
    },
    {
      "x": 1,
      "y": 5,
      "z": -5,
      "name": "Rock_Chalk"
    },
    {
      "x": 1,
      "y": 6,
      "z": -5,
      "name": "Rock_Chalk"
    },
    {
      "x": 1,
      "y": 7,
      "z": -5,
      "name": "Rock_Chalk"
    },
    {
      "x": 1,
      "y": 8,
      "z": -5,
      "name": "Rock_Chalk"
    },
    {
      "x": 1,
      "y": 9,
      "z": -5,
      "name": "Rock_Chalk"
    },
    {
      "x": 1,
      "y": 10,
      "z": -5,
      "name": "Rock_Chalk"
    },
    {
      "x": 1,
      "y": 11,
      "z": -5,
      "name": "Rock_Chalk"
    },
    {
      "x": 1,
      "y": 12,
      "z": -5,
      "name": "Soil_Dirt_White"
    },
    {
      "x": 1,
      "y": 13,
      "z": -5,
      "name": "Soil_Grass_Full"
    },
    {
      "x": 1,
      "y": 4,
      "z": -4,
      "name": "Rock_Chalk"
    },
    {
      "x": 1,
      "y": 5,
      "z": -4,
      "name": "Rock_Chalk"
    },
    {
      "x": 1,
      "y": 6,
      "z": -4,
      "name": "Rock_Chalk"
    },
    {
      "x": 1,
      "y": 7,
      "z": -4,
      "name": "Rock_Chalk"
    },
    {
      "x": 1,
      "y": 8,
      "z": -4,
      "name": "Rock_Chalk"
    },
    {
      "x": 1,
      "y": 9,
      "z": -4,
      "name": "Rock_Chalk"
    },
    {
      "x": 1,
      "y": 10,
      "z": -4,
      "name": "Rock_Chalk"
    },
    {
      "x": 1,
      "y": 11,
      "z": -4,
      "name": "Soil_Dirt_White"
    },
    {
      "x": 1,
      "y": 12,
      "z": -4,
      "name": "Rock_Chalk"
    },
    {
      "x": 1,
      "y": 13,
      "z": -4,
      "name": "Soil_Dirt_White"
    },
    {
      "x": 1,
      "y": 14,
      "z": -4,
      "name": "Soil_Grass_Full"
    },
    {
      "x": 1,
      "y": 3,
      "z": -3,
      "name": "Rock_Chalk"
    },
    {
      "x": 1,
      "y": 4,
      "z": -3,
      "name": "Rock_Chalk"
    },
    {
      "x": 1,
      "y": 5,
      "z": -3,
      "name": "Rock_Chalk"
    },
    {
      "x": 1,
      "y": 6,
      "z": -3,
      "name": "Rock_Chalk"
    },
    {
      "x": 1,
      "y": 7,
      "z": -3,
      "name": "Rock_Chalk"
    },
    {
      "x": 1,
      "y": 8,
      "z": -3,
      "name": "Rock_Chalk"
    },
    {
      "x": 1,
      "y": 9,
      "z": -3,
      "name": "Rock_Chalk"
    },
    {
      "x": 1,
      "y": 10,
      "z": -3,
      "name": "Rock_Chalk"
    },
    {
      "x": 1,
      "y": 11,
      "z": -3,
      "name": "Soil_Dirt_White"
    },
    {
      "x": 1,
      "y": 12,
      "z": -3,
      "name": "Rock_Chalk"
    },
    {
      "x": 1,
      "y": 13,
      "z": -3,
      "name": "Soil_Dirt_White"
    },
    {
      "x": 1,
      "y": 14,
      "z": -3,
      "name": "Soil_Grass_Full"
    },
    {
      "x": 1,
      "y": 2,
      "z": -2,
      "name": "Rock_Chalk"
    },
    {
      "x": 1,
      "y": 3,
      "z": -2,
      "name": "Rock_Chalk"
    },
    {
      "x": 1,
      "y": 4,
      "z": -2,
      "name": "Rock_Chalk"
    },
    {
      "x": 1,
      "y": 5,
      "z": -2,
      "name": "Rock_Chalk"
    },
    {
      "x": 1,
      "y": 6,
      "z": -2,
      "name": "Rock_Chalk"
    },
    {
      "x": 1,
      "y": 7,
      "z": -2,
      "name": "Rock_Chalk"
    },
    {
      "x": 1,
      "y": 8,
      "z": -2,
      "name": "Rock_Chalk"
    },
    {
      "x": 1,
      "y": 9,
      "z": -2,
      "name": "Rock_Chalk"
    },
    {
      "x": 1,
      "y": 10,
      "z": -2,
      "name": "Rock_Chalk"
    },
    {
      "x": 1,
      "y": 11,
      "z": -2,
      "name": "Soil_Dirt_White"
    },
    {
      "x": 1,
      "y": 12,
      "z": -2,
      "name": "Soil_Dirt_White"
    },
    {
      "x": 1,
      "y": 13,
      "z": -2,
      "name": "Rock_Chalk"
    },
    {
      "x": 1,
      "y": 14,
      "z": -2,
      "name": "Soil_Dirt_White"
    },
    {
      "x": 1,
      "y": 15,
      "z": -2,
      "name": "Soil_Grass_Full"
    },
    {
      "x": 1,
      "y": 1,
      "z": -1,
      "name": "Rock_Chalk"
    },
    {
      "x": 1,
      "y": 2,
      "z": -1,
      "name": "Rock_Chalk"
    },
    {
      "x": 1,
      "y": 3,
      "z": -1,
      "name": "Rock_Chalk"
    },
    {
      "x": 1,
      "y": 4,
      "z": -1,
      "name": "Rock_Chalk"
    },
    {
      "x": 1,
      "y": 5,
      "z": -1,
      "name": "Rock_Chalk"
    },
    {
      "x": 1,
      "y": 6,
      "z": -1,
      "name": "Rock_Chalk"
    },
    {
      "x": 1,
      "y": 7,
      "z": -1,
      "name": "Rock_Chalk"
    },
    {
      "x": 1,
      "y": 8,
      "z": -1,
      "name": "Rock_Chalk"
    },
    {
      "x": 1,
      "y": 9,
      "z": -1,
      "name": "Rock_Chalk"
    },
    {
      "x": 1,
      "y": 10,
      "z": -1,
      "name": "Rock_Chalk"
    },
    {
      "x": 1,
      "y": 11,
      "z": -1,
      "name": "Rock_Chalk"
    },
    {
      "x": 1,
      "y": 12,
      "z": -1,
      "name": "Rock_Chalk"
    },
    {
      "x": 1,
      "y": 13,
      "z": -1,
      "name": "Rock_Chalk"
    },
    {
      "x": 1,
      "y": 14,
      "z": -1,
      "name": "Soil_Dirt_White"
    },
    {
      "x": 1,
      "y": 15,
      "z": -1,
      "name": "Soil_Grass_Full"
    },
    {
      "x": 1,
      "y": 2,
      "z": 0,
      "name": "Rock_Chalk"
    },
    {
      "x": 1,
      "y": 3,
      "z": 0,
      "name": "Rock_Chalk"
    },
    {
      "x": 1,
      "y": 4,
      "z": 0,
      "name": "Rock_Chalk"
    },
    {
      "x": 1,
      "y": 5,
      "z": 0,
      "name": "Rock_Chalk"
    },
    {
      "x": 1,
      "y": 6,
      "z": 0,
      "name": "Rock_Chalk"
    },
    {
      "x": 1,
      "y": 7,
      "z": 0,
      "name": "Rock_Chalk"
    },
    {
      "x": 1,
      "y": 8,
      "z": 0,
      "name": "Rock_Chalk"
    },
    {
      "x": 1,
      "y": 9,
      "z": 0,
      "name": "Rock_Chalk"
    },
    {
      "x": 1,
      "y": 10,
      "z": 0,
      "name": "Rock_Chalk"
    },
    {
      "x": 1,
      "y": 11,
      "z": 0,
      "name": "Rock_Chalk"
    },
    {
      "x": 1,
      "y": 12,
      "z": 0,
      "name": "Soil_Dirt_White"
    },
    {
      "x": 1,
      "y": 13,
      "z": 0,
      "name": "Soil_Dirt_White"
    },
    {
      "x": 1,
      "y": 14,
      "z": 0,
      "name": "Soil_Grass_Full"
    },
    {
      "x": 1,
      "y": 2,
      "z": 1,
      "name": "Rock_Chalk"
    },
    {
      "x": 1,
      "y": 3,
      "z": 1,
      "name": "Rock_Chalk"
    },
    {
      "x": 1,
      "y": 4,
      "z": 1,
      "name": "Rock_Chalk"
    },
    {
      "x": 1,
      "y": 5,
      "z": 1,
      "name": "Rock_Chalk"
    },
    {
      "x": 1,
      "y": 6,
      "z": 1,
      "name": "Rock_Chalk"
    },
    {
      "x": 1,
      "y": 7,
      "z": 1,
      "name": "Rock_Chalk"
    },
    {
      "x": 1,
      "y": 8,
      "z": 1,
      "name": "Rock_Chalk"
    },
    {
      "x": 1,
      "y": 9,
      "z": 1,
