{
  "version": 8,
  "blockIdVersion": 11,
  "anchorX": 0,
  "anchorY": 0,
  "anchorZ": 0,
  "blocks": [
    {
      "x": -8,
      "y": -2,
      "z": 2,
      "name": "Soil_Grass_White"
    },
    {
      "x": -8,
      "y": -2,
      "z": 3,
      "name": "Soil_Grass_White"
    },
    {
      "x": -8,
      "y": -2,
      "z": 4,
      "name": "Soil_Grass_White"
    },
    {
      "x": -8,
      "y": -1,
      "z": 4,
      "name": "Soil_Grass_White"
    },
    {
      "x": -8,
      "y": -2,
      "z": 5,
      "name": "Soil_Grass_White"
    },
    {
      "x": -7,
      "y": -2,
      "z": -1,
      "name": "Soil_Grass_White"
    },
    {
      "x": -7,
      "y": -2,
      "z": 0,
      "name": "Soil_Grass_White"
    },
    {
      "x": -7,
      "y": -2,
      "z": 1,
      "name": "Soil_Grass_White"
    },
    {
      "x": -7,
      "y": -1,
      "z": 1,
      "name": "Soil_Grass_Full"
    },
    {
      "x": -7,
      "y": -2,
      "z": 2,
      "name": "Soil_Grass_White"
    },
    {
      "x": -7,
      "y": -1,
      "z": 2,
      "name": "Soil_Grass_Full"
    },
    {
      "x": -7,
      "y": -2,
      "z": 3,
      "name": "Soil_Grass_White"
    },
    {
      "x": -7,
      "y": -1,
      "z": 3,
      "name": "Soil_Grass_Full"
    },
    {
      "x": -7,
      "y": -2,
      "z": 4,
      "name": "Soil_Grass_White"
    },
    {
      "x": -7,
      "y": -1,
      "z": 4,
      "name": "Soil_Grass_White"
    },
    {
      "x": -7,
      "y": -2,
      "z": 5,
      "name": "Soil_Grass_White"
    },
    {
      "x": -7,
      "y": -1,
      "z": 5,
      "name": "Soil_Grass_White"
    },
    {
      "x": -7,
      "y": -2,
      "z": 6,
      "name": "Soil_Grass_White"
    },
    {
      "x": -6,
      "y": -2,
      "z": -2,
      "name": "Soil_Grass_White"
    },
    {
      "x": -6,
      "y": -2,
      "z": -1,
      "name": "Soil_Grass_White"
    },
    {
      "x": -6,
      "y": -1,
      "z": -1,
      "name": "Soil_Grass_Full"
    },
    {
      "x": -6,
      "y": -2,
      "z": 0,
      "name": "Soil_Grass_White"
    },
    {
      "x": -6,
      "y": -1,
      "z": 0,
      "name": "Soil_Grass_Full"
    },
    {
      "x": -6,
      "y": -2,
      "z": 1,
      "name": "Soil_Grass_White"
    },
    {
      "x": -6,
      "y": -1,
      "z": 1,
      "name": "Soil_Grass_Full"
    },
    {
      "x": -6,
      "y": -2,
      "z": 2,
      "name": "Soil_Grass_White"
    },
    {
      "x": -6,
      "y": -1,
      "z": 2,
      "name": "Soil_Grass_Full"
    },
    {
      "x": -6,
      "y": 0,
      "z": 2,
      "name": "Soil_Grass_Full"
    },
    {
      "x": -6,
      "y": -2,
      "z": 3,
      "name": "Soil_Grass_White"
    },
    {
      "x": -6,
      "y": -1,
      "z": 3,
      "name": "Soil_Grass_Full"
    },
    {
      "x": -6,
      "y": 0,
      "z": 3,
      "name": "Soil_Grass_Full"
    },
    {
      "x": -6,
      "y": -2,
      "z": 4,
      "name": "Soil_Grass_White"
    },
    {
      "x": -6,
      "y": -1,
      "z": 4,
      "name": "Soil_Grass_Full"
    },
    {
      "x": -6,
      "y": -2,
      "z": 5,
      "name": "Soil_Grass_White"
    },
    {
      "x": -6,
      "y": -1,
      "z": 5,
      "name": "Soil_Grass_White"
    },
    {
      "x": -6,
      "y": -2,
      "z": 6,
      "name": "Soil_Grass_White"
    },
    {
      "x": -5,
      "y": -2,
      "z": -2,
      "name": "Soil_Grass_White"
    },
    {
      "x": -5,
      "y": -2,
      "z": -1,
      "name": "Soil_Grass_White"
    },
    {
      "x": -5,
      "y": -1,
      "z": -1,
      "name": "Soil_Grass_Full"
    },
    {
      "x": -5,
      "y": 0,
      "z": -1,
      "name": "Soil_Grass_Full"
    },
    {
      "x": -5,
      "y": -2,
      "z": 0,
      "name": "Soil_Grass_White"
    },
    {
      "x": -5,
      "y": -1,
      "z": 0,
      "name": "Soil_Grass_Full"
    },
    {
      "x": -5,
      "y": 0,
      "z": 0,
      "name": "Soil_Grass_Full"
    },
    {
      "x": -5,
      "y": -2,
      "z": 1,
      "name": "Soil_Grass_White"
    },
    {
      "x": -5,
      "y": -1,
      "z": 1,
      "name": "Soil_Grass_Full"
    },
    {
      "x": -5,
      "y": 0,
      "z": 1,
      "name": "Soil_Grass_Full"
    },
    {
      "x": -5,
      "y": -2,
      "z": 2,
      "name": "Soil_Grass_White"
    },
    {
      "x": -5,
      "y": -1,
      "z": 2,
      "name": "Soil_Grass_Full"
    },
    {
      "x": -5,
      "y": 0,
      "z": 2,
      "name": "Soil_Grass_Full"
    },
    {
      "x": -5,
      "y": -2,
      "z": 3,
      "name": "Soil_Grass_White"
    },
    {
      "x": -5,
      "y": -1,
      "z": 3,
      "name": "Soil_Grass_Full"
    },
    {
      "x": -5,
      "y": 0,
      "z": 3,
      "name": "Soil_Grass_Full"
    },
    {
      "x": -5,
      "y": -2,
      "z": 4,
      "name": "Soil_Grass_White"
    },
    {
      "x": -5,
      "y": -1,
      "z": 4,
      "name": "Soil_Grass_Full"
    },
    {
      "x": -5,
      "y": 0,
      "z": 4,
      "name": "Plant_Grass_Lush"
    },
    {
      "x": -5,
      "y": -2,
      "z": 5,
      "name": "Soil_Grass_White"
    },
    {
      "x": -5,
      "y": -1,
      "z": 5,
      "name": "Soil_Grass_White"
    },
    {
      "x": -5,
      "y": -2,
      "z": 6,
      "name": "Soil_Grass_White"
    },
    {
      "x": -4,
      "y": -2,
      "z": -4,
      "name": "Soil_Grass_White"
    },
    {
      "x": -4,
      "y": -2,
      "z": -3,
      "name": "Soil_Grass_White"
    },
    {
      "x": -4,
      "y": -1,
      "z": -3,
      "name": "Soil_Grass_Full"
    },
    {
      "x": -4,
      "y": -2,
      "z": -2,
      "name": "Soil_Grass_White"
    },
    {
      "x": -4,
      "y": -1,
      "z": -2,
      "name": "Soil_Grass_Full"
    },
    {
      "x": -4,
      "y": 0,
      "z": -2,
      "name": "Soil_Grass_Full"
    },
    {
      "x": -4,
      "y": -2,
      "z": -1,
      "name": "Soil_Grass_White"
    },
    {
      "x": -4,
      "y": -1,
      "z": -1,
      "name": "Soil_Grass_Full"
    },
    {
      "x": -4,
      "y": 0,
      "z": -1,
      "name": "Soil_Pebbles",
      "support": 15
    },
    {
      "x": -4,
      "y": -2,
      "z": 0,
      "name": "Soil_Grass_White"
    },
    {
      "x": -4,
      "y": -1,
      "z": 0,
      "name": "Soil_Grass_Full"
    },
    {
      "x": -4,
      "y": 0,
      "z": 0,
      "name": "Soil_Grass_Full"
    },
    {
      "x": -4,
      "y": -2,
      "z": 1,
      "name": "Soil_Grass_White"
    },
    {
      "x": -4,
      "y": -1,
      "z": 1,
      "name": "Rock_Marble_Brick"
    },
    {
      "x": -4,
      "y": 0,
      "z": 1,
      "name": "Rock_Marble_Brick"
    },
    {
      "x": -4,
      "y": 1,
      "z": 1,
      "name": "Rock_Marble_Brick_Ornate"
    },
    {
      "x": -4,
      "y": 2,
      "z": 1,
      "name": "Rock_Marble_Brick_Pillar_Base"
    },
    {
      "x": -4,
      "y": 3,
      "z": 1,
      "name": "Rock_Marble_Brick_Pillar_Middle"
    },
    {
      "x": -4,
      "y": 4,
      "z": 1,
      "name": "Rock_Marble_Brick_Pillar_Middle"
    },
    {
      "x": -4,
      "y": 5,
      "z": 1,
      "name": "Rock_Marble_Brick_Pillar_Middle"
    },
    {
      "x": -4,
      "y": 6,
      "z": 1,
      "name": "Rock_Marble_Brick_Pillar_Base",
      "rotation": 8
    },
    {
      "x": -4,
      "y": 7,
      "z": 1,
      "name": "Rock_Marble_Brick"
    },
    {
      "x": -4,
      "y": 8,
      "z": 1,
      "name": "Rock_Marble_Brick"
    },
    {
      "x": -4,
      "y": -2,
      "z": 2,
      "name": "Soil_Grass_White"
    },
    {
      "x": -4,
      "y": -1,
      "z": 2,
      "name": "Rock_Marble_Brick"
    },
    {
      "x": -4,
      "y": 0,
      "z": 2,
      "name": "Rock_Marble_Brick"
    },
    {
      "x": -4,
      "y": -2,
      "z": 3,
      "name": "Soil_Grass_White"
    },
    {
      "x": -4,
      "y": -1,
      "z": 3,
      "name": "Soil_Grass_Full"
    },
    {
      "x": -4,
      "y": 0,
      "z": 3,
      "name": "Soil_Grass_Full"
    },
    {
      "x": -4,
      "y": -2,
      "z": 4,
      "name": "Soil_Grass_White"
    },
    {
      "x": -4,
      "y": -1,
      "z": 4,
      "name": "Soil_Grass_Full"
    },
    {
      "x": -4,
      "y": 0,
      "z": 4,
      "name": "Soil_Grass_Full"
    },
    {
      "x": -4,
      "y": -2,
      "z": 5,
      "name": "Soil_Grass_White"
    },
    {
      "x": -4,
      "y": -1,
      "z": 5,
      "name": "Soil_Grass_Full"
    },
    {
      "x": -4,
      "y": -2,
      "z": 6,
      "name": "Soil_Grass_White"
    },
    {
      "x": -3,
      "y": -2,
      "z": -5,
      "name": "Soil_Grass_White"
    },
    {
      "x": -3,
      "y": -2,
      "z": -4,
      "name": "Soil_Grass_White"
    },
    {
      "x": -3,
      "y": -1,
      "z": -4,
      "name": "Soil_Grass_Full"
    },
    {
      "x": -3,
      "y": -2,
      "z": -3,
      "name": "Soil_Grass_White"
    },
    {
      "x": -3,
      "y": -1,
      "z": -3,
      "name": "Soil_Grass_Full"
    },
    {
      "x": -3,
      "y": 0,
      "z": -3,
      "name": "Soil_Grass_Full"
    },
    {
      "x": -3,
      "y": -2,
      "z": -2,
      "name": "Soil_Grass_White"
    },
    {
      "x": -3,
      "y": -1,
      "z": -2,
      "name": "Soil_Pebbles"
    },
    {
      "x": -3,
      "y": 0,
      "z": -2,
      "name": "Soil_Pebbles",
      "support": 15
    },
    {
      "x": -3,
      "y": -2,
      "z": -1,
      "name": "Soil_Grass_White"
    },
    {
      "x": -3,
      "y": -1,
      "z": -1,
      "name": "Soil_Pebbles"
    },
    {
      "x": -3,
      "y": 0,
      "z": -1,
      "name": "Soil_Pebbles",
      "support": 15
    },
    {
      "x": -3,
      "y": -2,
      "z": 0,
      "name": "Soil_Grass_White"
    },
    {
      "x": -3,
      "y": -1,
      "z": 0,
      "name": "Soil_Grass_White"
    },
    {
      "x": -3,
      "y": 0,
      "z": 0,
      "name": "Soil_Pebbles",
      "support": 15
    },
    {
      "x": -3,
      "y": -2,
      "z": 1,
      "name": "Soil_Grass_White"
    },
    {
      "x": -3,
      "y": -1,
      "z": 1,
      "name": "Rock_Marble_Brick"
    },
    {
      "x": -3,
      "y": 0,
      "z": 1,
      "name": "Rock_Marble_Brick"
    },
    {
      "x": -3,
      "y": 1,
      "z": 1,
      "name": "Rock_Marble_Brick"
    },
    {
      "x": -3,
      "y": 7,
      "z": 1,
      "name": "Rock_Marble_Brick_Stairs",
      "rotation": 11
    },
    {
      "x": -3,
      "y": 8,
      "z": 1,
      "name": "Rock_Marble_Brick_Half"
    },
    {
      "x": -3,
      "y": -2,
      "z": 2,
      "name": "Soil_Grass_White"
    },
    {
      "x": -3,
      "y": -1,
      "z": 2,
      "name": "Rock_Marble_Brick"
    },
    {
      "x": -3,
      "y": 0,
      "z": 2,
      "name": "Rock_Marble_Brick"
    },
    {
      "x": -3,
      "y": -2,
      "z": 3,
      "name": "Soil_Grass_White"
    },
    {
      "x": -3,
      "y": -1,
      "z": 3,
      "name": "Soil_Grass_Full"
    },
    {
      "x": -3,
      "y": 0,
      "z": 3,
      "name": "Soil_Grass_Full"
    },
    {
      "x": -3,
      "y": -2,
      "z": 4,
      "name": "Soil_Grass_White"
    },
    {
      "x": -3,
      "y": -1,
      "z": 4,
      "name": "Soil_Grass_Full"
    },
    {
      "x": -3,
      "y": 0,
      "z": 4,
      "name": "Soil_Grass_Full"
    },
    {
      "x": -3,
      "y": -2,
      "z": 5,
      "name": "Soil_Grass_White"
    },
    {
      "x": -3,
      "y": -1,
      "z": 5,
      "name": "Soil_Grass_Full"
    },
    {
      "x": -3,
      "y": 0,
      "z": 5,
      "name": "Soil_Grass_Full"
    },
    {
      "x": -3,
      "y": -2,
      "z": 6,
      "name": "Soil_Grass_White"
    },
    {
      "x": -3,
      "y": 0,
      "z": 6,
      "name": "Plant_Grass_Sharp"
    },
    {
      "x": -3,
      "y": -2,
      "z": 7,
      "name": "Soil_Grass_White"
    },
    {
      "x": -2,
      "y": -2,
      "z": -6,
      "name": "Soil_Grass_White"
    },
    {
      "x": -2,
      "y": -2,
      "z": -5,
      "name": "Soil_Grass_White"
    },
    {
      "x": -2,
      "y": -1,
      "z": -5,
      "name": "Soil_Grass_Full"
    },
    {
      "x": -2,
      "y": -2,
      "z": -4,
      "name": "Soil_Grass_White"
    },
    {
      "x": -2,
      "y": -1,
      "z": -4,
      "name": "Soil_Grass_Full"
    },
    {
      "x": -2,
      "y": 0,
      "z": -4,
      "name": "Soil_Grass_Full"
    },
    {
      "x": -2,
      "y": -2,
      "z": -3,
      "name": "Soil_Grass_White"
    },
    {
      "x": -2,
      "y": -1,
      "z": -3,
      "name": "Soil_Grass_Full"
    },
    {
      "x": -2,
      "y": 0,
      "z": -3,
      "name": "Soil_Pebbles",
      "support": 15
    },
    {
      "x": -2,
      "y": -2,
      "z": -2,
      "name": "Soil_Grass_White"
    },
    {
      "x": -2,
      "y": -1,
      "z": -2,
      "name": "Soil_Grass_Full"
    },
    {
      "x": -2,
      "y": 0,
      "z": -2,
      "name": "Soil_Grass_Full"
    },
    {
      "x": -2,
      "y": 1,
      "z": -2,
      "name": "Soil_Marble_Gravel_Half",
      "support": 15
    },
    {
      "x": -2,
      "y": -2,
      "z": -1,
      "name": "Soil_Grass_White"
    },
    {
      "x": -2,
      "y": -1,
      "z": -1,
      "name": "Soil_Pebbles"
    },
    {
      "x": -2,
      "y": 0,
      "z": -1,
      "name": "Rock_Marble_Cobble"
    },
    {
      "x": -2,
      "y": -2,
      "z": 0,
      "name": "Soil_Grass_White"
    },
    {
      "x": -2,
      "y": -1,
      "z": 0,
      "name": "Soil_Pebbles"
    },
    {
      "x": -2,
      "y": 0,
      "z": 0,
      "name": "Soil_Pebbles",
      "support": 15
    },
    {
      "x": -2,
      "y": 1,
      "z": 0,
      "name": "Rubble_Marble",
      "support": 15
    },
    {
      "x": -2,
      "y": -2,
      "z": 1,
      "name": "Soil_Grass_White"
    },
    {
      "x": -2,
      "y": -1,
      "z": 1,
      "name": "Rock_Marble_Brick"
    },
    {
      "x": -2,
      "y": 0,
      "z": 1,
      "name": "Rock_Marble_Brick"
    },
    {
      "x": -2,
      "y": 1,
      "z": 1,
      "name": "Rock_Marble_Brick"
    },
    {
      "x": -2,
      "y": 7,
      "z": 1,
      "name": "Rock_Marble_Brick_Stairs",
      "rotation": 9
    },
    {
      "x": -2,
      "y": 8,
      "z": 1,
      "name": "Rock_Marble_Brick_Stairs"
    },
    {
      "x": -2,
      "y": -2,
      "z": 2,
      "name": "Soil_Grass_White"
    },
    {
      "x": -2,
      "y": -1,
      "z": 2,
      "name": "Rock_Marble_Brick"
    },
    {
      "x": -2,
      "y": 0,
      "z": 2,
      "name": "Rock_Marble_Brick"
    },
    {
      "x": -2,
      "y": 1,
      "z": 2,
      "name": "Rubble_Marble",
      "support": 15
    },
    {
      "x": -2,
      "y": -2,
      "z": 3,
      "name": "Soil_Grass_White"
    },
    {
      "x": -2,
      "y": -1,
      "z": 3,
      "name": "Soil_Grass_Full"
    },
    {
      "x": -2,
      "y": 0,
      "z": 3,
      "name": "Soil_Grass_Full"
    },
    {
      "x": -2,
      "y": -2,
      "z": 4,
      "name": "Soil_Grass_White"
    },
    {
      "x": -2,
      "y": 0,
      "z": 4,
      "name": "Soil_Grass_Full"
    },
    {
      "x": -2,
      "y": -2,
      "z": 5,
      "name": "Soil_Grass_White"
    },
    {
      "x": -2,
      "y": 0,
      "z": 5,
      "name": "Soil_Grass_Full"
    },
    {
      "x": -2,
      "y": -2,
      "z": 6,
      "name": "Soil_Grass_White"
    },
    {
      "x": -2,
      "y": -1,
      "z": 6,
      "name": "Soil_Grass_Full"
    },
    {
      "x": -2,
      "y": 0,
      "z": 6,
      "name": "Plant_Grass_Sharp"
    },
    {
      "x": -2,
      "y": -2,
      "z": 7,
      "name": "Soil_Grass_White"
    },
    {
      "x": -1,
      "y": -2,
      "z": -6,
      "name": "Soil_Grass_White"
    },
    {
      "x": -1,
      "y": -1,
      "z": -6,
      "name": "Soil_Grass_Full"
    },
    {
      "x": -1,
      "y": -2,
      "z": -5,
      "name": "Soil_Grass_White"
    },
    {
      "x": -1,
      "y": -1,
      "z": -5,
      "name": "Soil_Grass_Full"
    },
    {
      "x": -1,
      "y": 0,
      "z": -5,
      "name": "Soil_Grass_Full"
    },
    {
      "x": -1,
      "y": -2,
      "z": -4,
      "name": "Soil_Grass_White"
    },
    {
      "x": -1,
      "y": -1,
      "z": -4,
      "name": "Soil_Grass_Full"
    },
    {
      "x": -1,
      "y": 0,
      "z": -4,
      "name": "Soil_Grass_Full"
    },
    {
      "x": -1,
      "y": -2,
      "z": -3,
      "name": "Soil_Grass_White"
    },
    {
      "x": -1,
      "y": -1,
      "z": -3,
      "name": "Soil_Grass_Full"
    },
    {
      "x": -1,
      "y": 0,
      "z": -3,
      "name": "Soil_Pebbles",
      "support": 15
    },
    {
      "x": -1,
      "y": -2,
      "z": -2,
      "name": "Soil_Grass_White"
    },
    {
      "x": -1,
      "y": -1,
      "z": -2,
      "name": "Soil_Grass_Full"
    },
    {
      "x": -1,
      "y": 0,
      "z": -2,
      "name": "Soil_Grass_Full"
    },
    {
      "x": -1,
      "y": 1,
      "z": -2,
      "name": "Soil_Marble_Gravel_Half",
      "support": 15
    },
    {
      "x": -1,
      "y": -2,
      "z": -1,
      "name": "Soil_Grass_White"
    },
    {
      "x": -1,
      "y": -1,
      "z": -1,
      "name": "Soil_Pebbles"
    },
    {
      "x": -1,
      "y": 0,
      "z": -1,
      "name": "Soil_Pebbles",
      "support": 15
    },
    {
      "x": -1,
      "y": 1,
      "z": -1,
      "name": "Rock_Marble_Half"
    },
    {
      "x": -1,
      "y": -2,
      "z": 0,
      "name": "Soil_Grass_White"
    },
    {
      "x": -1,
      "y": -1,
      "z": 0,
      "name": "Soil_Pebbles"
    },
    {
      "x": -1,
      "y": 0,
      "z": 0,
      "name": "Soil_Pebbles",
      "support": 15
    },
    {
      "x": -1,
      "y": 1,
      "z": 0,
      "name": "Rubble_Marble",
      "support": 15
    },
    {
      "x": -1,
      "y": -2,
      "z": 1,
      "name": "Soil_Grass_White"
    },
    {
      "x": -1,
      "y": -1,
      "z": 1,
      "name": "Rock_Marble"
    },
    {
      "x": -1,
      "y": 0,
      "z": 1,
      "name": "Rock_Marble"
    },
    {
      "x": -1,
      "y": 1,
      "z": 1,
      "name": "Rock_Marble_Brick_Ornate"
    },
    {
      "x": -1,
      "y": 2,
      "z": 1,
      "name": "Rock_Marble_Brick_Pillar_Base"
    },
    {
      "x": -1,
      "y": 3,
      "z": 1,
      "name": "Rock_Marble_Brick_Pillar_Middle"
    },
    {
      "x": -1,
      "y": 4,
      "z": 1,
      "name": "Rock_Marble_Brick_Pillar_Middle"
    },
    {
      "x": -1,
      "y": 5,
      "z": 1,
      "name": "Rock_Marble_Brick_Pillar_Middle"
    },
    {
      "x": -1,
      "y": 6,
      "z": 1,
      "name": "Rock_Marble_Brick_Pillar_Base",
      "rotation": 8
    },
    {
      "x": -1,
      "y": 7,
      "z": 1,
      "name": "Rock_Marble_Brick"
    },
    {
      "x": -1,
      "y": 8,
      "z": 1,
      "name": "Rock_Marble_Brick_Half"
    },
    {
      "x": -1,
      "y": -2,
      "z": 2,
      "name": "Soil_Grass_White"
    },
    {
      "x": -1,
      "y": -1,
      "z": 2,
      "name": "Rock_Marble_Brick"
    },
    {
      "x": -1,
      "y": 0,
      "z": 2,
      "name": "Rock_Marble_Brick"
    },
    {
      "x": -1,
      "y": -2,
      "z": 3,
      "name": "Soil_Grass_White"
    },
    {
      "x": -1,
      "y": -1,
      "z": 3,
      "name": "Soil_Grass_Full"
    },
    {
      "x": -1,
      "y": 0,
      "z": 3,
      "name": "Soil_Grass_Full"
    },
    {
      "x": -1,
      "y": -2,
      "z": 4,
      "name": "Soil_Grass_White"
    },
    {
      "x": -1,
      "y": 0,
      "z": 4,
      "name": "Soil_Grass_Full"
    },
    {
      "x": -1,
      "y": 1,
      "z": 4,
      "name": "Rubble_Marble_Medium",
      "support": 15
    },
    {
      "x": -1,
      "y": -2,
      "z": 5,
      "name": "Soil_Grass_White"
    },
    {
      "x": -1,
      "y": -1,
      "z": 5,
      "name": "Soil_Grass_Full"
    },
    {
      "x": -1,
      "y": 0,
      "z": 5,
      "name": "Soil_Grass_Full"
    },
    {
      "x": -1,
      "y": -2,
      "z": 6,
      "name": "Soil_Grass_White"
    },
    {
      "x": -1,
      "y": -1,
      "z": 6,
      "name": "Soil_Grass_Full"
    },
    {
      "x": -1,
      "y": 0,
      "z": 6,
      "name": "Soil_Grass_Full"
    },
    {
      "x": -1,
      "y": -2,
      "z": 7,
      "name": "Soil_Grass_White"
    },
    {
      "x": -1,
      "y": -1,
      "z": 7,
      "name": "Soil_Grass_Full"
    },
    {
      "x": 0,
      "y": -2,
      "z": -6,
      "name": "Soil_Grass_White"
    },
    {
      "x": 0,
      "y": -1,
      "z": -6,
      "name": "Soil_Grass_Full"
    },
    {
      "x": 0,
      "y": -2,
      "z": -5,
      "name": "Soil_Grass_White"
    },
    {
      "x": 0,
      "y": -1,
      "z": -5,
      "name": "Soil_Grass_Full"
    },
    {
      "x": 0,
      "y": 0,
      "z": -5,
      "name": "Soil_Grass_Full"
    },
    {
      "x": 0,
      "y": -2,
      "z": -4,
      "name": "Soil_Grass_White"
    },
    {
      "x": 0,
      "y": -1,
      "z": -4,
      "name": "Soil_Grass_Full"
    },
    {
      "x": 0,
      "y": 0,
      "z": -4,
      "name": "Soil_Grass_Full"
    },
    {
      "x": 0,
      "y": -2,
      "z": -3,
      "name": "Soil_Grass_White"
    },
    {
      "x": 0,
      "y": -1,
      "z": -3,
      "name": "Soil_Grass_Full"
    },
    {
      "x": 0,
      "y": 0,
      "z": -3,
      "name": "Soil_Grass_Full"
    },
    {
      "x": 0,
      "y": -2,
      "z": -2,
      "name": "Soil_Grass_White"
    },
    {
      "x": 0,
      "y": -1,
      "z": -2,
      "name": "Soil_Grass_Full"
    },
    {
      "x": 0,
      "y": 0,
      "z": -2,
      "name": "Soil_Grass_Full"
    },
    {
      "x": 0,
      "y": 1,
      "z": -2,
      "name": "Soil_Marble_Gravel_Half",
      "support": 15
    },
    {
      "x": 0,
      "y": -2,
      "z": -1,
      "name": "Soil_Grass_White"
    },
    {
      "x": 0,
      "y": -1,
      "z": -1,
      "name": "Soil_Pebbles"
    },
    {
      "x": 0,
      "y": 0,
      "z": -1,
      "name": "Soil_Pebbles",
      "support": 15
    },
    {
      "x": 0,
      "y": 1,
      "z": -1,
      "name": "Rock_Marble_Half",
      "rotation": 6
    },
    {
      "x": 0,
      "y": -2,
      "z": 0,
      "name": "Soil_Grass_White"
    },
    {
      "x": 0,
      "y": -1,
      "z": 0,
      "name": "Soil_Pebbles"
    },
    {
      "x": 0,
      "y": 0,
      "z": 0,
      "name": "Soil_Pebbles",
      "support": 15
    },
    {
      "x": 0,
      "y": 1,
      "z": 0,
      "name": "Soil_Marble_Gravel_Half",
      "support": 15
    },
    {
      "x": 0,
      "y": -2,
      "z": 1,
      "name": "Soil_Grass_White"
    },
    {
      "x": 0,
      "y": -1,
      "z": 1,
      "name": "Rock_Marble"
    },
    {
      "x": 0,
      "y": 0,
      "z": 1,
      "name": "Rock_Marble"
    },
    {
      "x": 0,
      "y": 1,
      "z": 1,
      "name": "Rock_Marble_Brick"
    },
    {
      "x": 0,
      "y": -2,
      "z": 2,
      "name": "Soil_Grass_White"
    },
    {
      "x": 0,
      "y": -1,
      "z": 2,
      "name": "Rock_Marble"
    },
    {
      "x": 0,
      "y": 0,
      "z": 2,
      "name": "Rock_Marble"
    },
    {
      "x": 0,
      "y": 1,
      "z": 2,
      "name": "Rock_Marble_Brick"
    },
    {
      "x": 0,
      "y": 2,
      "z": 2,
      "name": "Rubble_Marble_Medium",
      "support": 15
    },
    {
      "x": 0,
      "y": -2,
      "z": 3,
      "name": "Soil_Grass_White"
    },
    {
      "x": 0,
      "y": -1,
      "z": 3,
      "name": "Soil_Grass_Full"
    },
    {
      "x": 0,
      "y": 0,
      "z": 3,
      "name": "Soil_Grass_Full"
    },
    {
      "x": 0,
      "y": -2,
      "z": 4,
      "name": "Soil_Grass_White"
    },
    {
      "x": 0,
      "y": -1,
      "z": 4,
      "name": "Soil_Grass_Full"
    },
    {
      "x": 0,
      "y": 0,
      "z": 4,
      "name": "Soil_Grass_Full"
    },
    {
      "x": 0,
      "y": -2,
      "z": 5,
      "name": "Soil_Grass_White"
    },
    {
      "x": 0,
      "y": -1,
      "z": 5,
      "name": "Soil_Grass_Full"
    },
    {
      "x": 0,
      "y": 0,
      "z": 5,
      "name": "Soil_Grass_Full"
    },
    {
      "x": 0,
      "y": -2,
      "z": 6,
      "name": "Soil_Grass_White"
    },
    {
      "x": 0,
      "y": -1,
      "z": 6,
      "name": "Soil_Grass_Full"
    },
    {
      "x": 0,
      "y": 0,
      "z": 6,
      "name": "Soil_Grass_Full"
    },
    {
      "x": 0,
      "y": -2,
      "z": 7,
      "name": "Soil_Grass_White"
    },
    {
      "x": 0,
      "y": -1,
      "z": 7,
      "name": "Soil_Grass_Full"
    },
    {
      "x": 0,
      "y": -2,
      "z": 8,
      "name": "Soil_Grass_White"
    },
    {
      "x": 1,
      "y": -2,
      "z": -6,
      "name": "Soil_Grass_White"
    },
    {
      "x": 1,
      "y": -1,
      "z": -6,
      "name": "Soil_Grass_Full"
    },
    {
      "x": 1,
      "y": -2,
      "z": -5,
      "name": "Soil_Grass_White"
    },
    {
      "x": 1,
      "y": -1,
      "z": -5,
      "name": "Soil_Grass_Full"
    },
    {
      "x": 1,
      "y": -2,
      "z": -4,
      "name": "Soil_Grass_White"
    },
    {
      "x": 1,
      "y": -1,
      "z": -4,
      "name": "Soil_Grass_Full"
    },
    {
      "x": 1,
      "y": 0,
      "z": -4,
      "name": "Soil_Grass_Full"
    },
    {
      "x": 1,
      "y": -2,
      "z": -3,
      "name": "Soil_Grass_White"
    },
    {
      "x": 1,
      "y": -1,
      "z": -3,
      "name": "Soil_Grass_Full"
    },
    {
      "x": 1,
      "y": 0,
      "z": -3,
      "name": "Soil_Grass_Full"
    },
    {
      "x": 1,
      "y": -2,
      "z": -2,
      "name": "Soil_Grass_White"
    },
    {
      "x": 1,
      "y": -1,
      "z": -2,
      "name": "Soil_Grass_Full"
    },
    {
      "x": 1,
      "y": 0,
      "z": -2,
      "name": "Soil_Grass_Full"
    },
    {
      "x": 1,
      "y": 1,
      "z": -2,
      "name": "Rubble_Marble",
      "support": 15
    },
    {
      "x": 1,
      "y": -2,
      "z": -1,
      "name": "Soil_Grass_White"
    },
    {
      "x": 1,
      "y": -1,
      "z": -1,
      "name": "Soil_Pebbles"
    },
    {
      "x": 1,
      "y": 0,
      "z": -1,
      "name": "Soil_Pebbles",
      "support": 15
    },
    {
      "x": 1,
      "y": 1,
      "z": -1,
      "name": "Rock_Marble_Stairs",
      "rotation": 1
    },
    {
      "x": 1,
      "y": -2,
      "z": 0,
      "name": "Soil_Grass_White"
    },
    {
      "x": 1,
      "y": -1,
      "z": 0,
      "name": "Soil_Grass_White"
    },
    {
      "x": 1,
      "y": 0,
      "z": 0,
      "name": "Rock_Marble_Cobble"
    },
    {
      "x": 1,
      "y": -2,
      "z": 1,
      "name": "Soil_Grass_White"
    },
    {
      "x": 1,
      "y": -1,
      "z": 1,
      "name": "Rock_Marble"
    },
    {
      "x": 1,
      "y": 0,
      "z": 1,
      "name": "Rock_Marble"
    },
    {
      "x": 1,
      "y": 1,
      "z": 1,
      "name": "Rock_Marble_Brick"
    },
    {
      "x": 1,
      "y": -2,
      "z": 2,
      "name": "Soil_Grass_White"
    },
    {
      "x": 1,
      "y": -1,
      "z": 2,
      "name": "Rock_Marble"
    },
    {
      "x": 1,
      "y": 0,
      "z": 2,
      "name": "Rock_Marble"
    },
    {
      "x": 1,
      "y": 1,
      "z": 2,
      "name": "Rock_Marble_Brick"
    },
    {
      "x": 1,
      "y": -2,
      "z": 3,
      "name": "Soil_Grass_White"
    },
    {
      "x": 1,
      "y": -1,
      "z": 3,
      "name": "Soil_Grass_Full"
    },
    {
      "x": 1,
      "y": 0,
      "z": 3,
      "name": "Soil_Grass_Full"
    },
    {
      "x": 1,
      "y": -2,
      "z": 4,
      "name": "Soil_Grass_White"
    },
    {
      "x": 1,
      "y": -1,
      "z": 4,
      "name": "Soil_Grass_Full"
    },
    {
      "x": 1,
      "y": 0,
      "z": 4,
      "name": "Soil_Grass_Full"
    },
    {
      "x": 1,
      "y": -2,
      "z": 5,
      "name": "Soil_Grass_White"
    },
    {
      "x": 1,
      "y": -1,
      "z": 5,
      "name": "Soil_Grass_Full"
    },
    {
      "x": 1,
      "y": 0,
      "z": 5,
      "name": "Soil_Grass_Full"
    },
    {
      "x": 1,
      "y": -2,
      "z": 6,
      "name": "Soil_Grass_White"
    },
    {
      "x": 1,
      "y": -1,
      "z": 6,
      "name": "Soil_Grass_Full"
    },
    {
      "x": 1,
      "y": 0,
      "z": 6,
      "name": "Soil_Grass_Full"
    },
    {
      "x": 1,
      "y": -2,
      "z": 7,
      "name": "Soil_Grass_White"
    },
    {
      "x": 1,
      "y": -1,
      "z": 7,
      "name": "Soil_Grass_Full"
    },
    {
      "x": 1,
      "y": -2,
      "z": 8,
      "name": "Soil_Grass_White"
    },
    {
      "x": 2,
      "y": -2,
      "z": -6,
      "name": "Soil_Grass_White"
    },
    {
      "x": 2,
      "y": -2,
      "z": -5,
      "name": "Soil_Grass_White"
    },
    {
      "x": 2,
      "y": -1,
      "z": -5,
      "name": "Soil_Grass_Full"
    },
    {
      "x": 2,
      "y": -2,
      "z": -4,
      "name": "Soil_Grass_White"
    },
    {
      "x": 2,
      "y": -1,
      "z": -4,
      "name": "Soil_Grass_Full"
    },
    {
      "x": 2,
      "y": 0,
      "z": -4,
      "name": "Soil_Grass_Full"
    },
    {
      "x": 2,
      "y": -2,
      "z": -3,
      "name": "Soil_Grass_White"
    },
    {
      "x": 2,
      "y": -1,
      "z": -3,
      "name": "Soil_Grass_Full"
    },
    {
      "x": 2,
      "y": 0,
      "z": -3,
      "name": "Soil_Grass_Full"
    },
    {
      "x": 2,
      "y": -2,
      "z": -2,
      "name": "Soil_Grass_White"
    },
    {
      "x": 2,
      "y": -1,
      "z": -2,
      "name": "Soil_Grass_Full"
    },
    {
      "x": 2,
      "y": 0,
      "z": -2,
      "name": "Soil_Grass_Full"
    },
    {
      "x": 2,
      "y": -2,
      "z": -1,
      "name": "Soil_Grass_White"
    },
    {
      "x": 2,
      "y": -1,
      "z": -1,
      "name": "Soil_Grass_Full"
    },
    {
      "x": 2,
      "y": 0,
      "z": -1,
      "name": "Rock_Marble_Cobble"
    },
    {
      "x": 2,
      "y": -2,
      "z": 0,
      "name": "Soil_Grass_White"
    },
    {
      "x": 2,
      "y": -1,
      "z": 0,
      "name": "Soil_Grass_White"
    },
    {
      "x": 2,
      "y": 0,
      "z": 0,
      "name": "Rock_Marble_Cobble"
    },
    {
      "x": 2,
      "y": 1,
      "z": 0,
      "name": "Rubble_Marble_Medium",
      "support": 15
    },
    {
      "x": 2,
      "y": -2,
      "z": 1,
      "name": "Soil_Grass_White"
    },
    {
      "x": 2,
      "y": -1,
      "z": 1,
      "name": "Rock_Marble"
    },
    {
      "x": 2,
      "y": 0,
      "z": 1,
      "name": "Rock_Marble"
    },
    {
      "x": 2,
      "y": 1,
      "z": 1,
      "name": "Rock_Marble_Brick_Ornate"
    },
    {
      "x": 2,
      "y": 2,
      "z": 1,
      "name": "Rock_Marble_Brick_Pillar_Base"
    },
    {
      "x": 2,
      "y": 3,
      "z": 1,
      "name": "Rock_Marble_Brick_Pillar_Middle"
    },
    {
      "x": 2,
      "y": 4,
      "z": 1,
      "name": "Rock_Marble_Brick_Pillar_Middle"
    },
    {
      "x": 2,
      "y": 5,
      "z": 1,
      "name": "Rubble_Marble",
      "support": 15
    },
    {
      "x": 2,
      "y": -2,
      "z": 2,
      "name": "Soil_Grass_White"
    },
    {
      "x": 2,
      "y": -1,
      "z": 2,
      "name": "Rock_Marble"
    },
    {
      "x": 2,
      "y": 0,
      "z": 2,
      "name": "Rock_Marble"
    },
    {
      "x": 2,
      "y": -2,
      "z": 3,
      "name": "Soil_Grass_White"
    },
    {
      "x": 2,
      "y": -1,
      "z": 3,
      "name": "Soil_Grass_Full"
    },
    {
      "x": 2,
      "y": 0,
      "z": 3,
      "name": "Soil_Grass_Sunny_Full"
    },
    {
      "x": 2,
      "y": 1,
      "z": 3,
      "name": "Rubble_Marble",
      "support": 15
    },
    {
      "x": 2,
      "y": -2,
      "z": 4,
      "name": "Soil_Grass_White"
    },
    {
      "x": 2,
      "y": -1,
      "z": 4,
      "name": "Soil_Grass_Full"
    },
    {
      "x": 2,
      "y": 0,
      "z": 4,
      "name": "Soil_Grass_Full"
    },
    {
      "x": 2,
      "y": -2,
      "z": 5,
      "name": "Soil_Grass_White"
    },
    {
      "x": 2,
      "y": -1,
      "z": 5,
      "name": "Soil_Grass_Full"
    },
    {
      "x": 2,
      "y": 0,
      "z": 5,
      "name": "Soil_Grass_Full"
    },
    {
      "x": 2,
      "y": -2,
      "z": 6,
      "name": "Soil_Grass_White"
    },
    {
      "x": 2,
      "y": -1,
      "z": 6,
      "name": "Soil_Grass_Full"
    },
    {
      "x": 2,
      "y": 0,
      "z": 6,
      "name": "Soil_Grass_Full"
    },
    {
      "x": 2,
      "y": -2,
      "z": 7,
      "name": "Soil_Grass_White"
    },
    {
      "x": 3,
      "y": -2,
      "z": -5,
      "name": "Soil_Grass_White"
    },
    {
      "x": 3,
      "y": -2,
      "z": -4,
      "name": "Soil_Grass_White"
    },
    {
      "x": 3,
      "y": -1,
      "z": -4,
      "name": "Soil_Grass_Full"
    },
    {
      "x": 3,
      "y": -2,
      "z": -3,
      "name": "Soil_Grass_White"
    },
    {
      "x": 3,
      "y": -1,
      "z": -3,
      "name": "Soil_Grass_Full"
    },
    {
      "x": 3,
      "y": -2,
      "z": -2,
      "name": "Soil_Grass_White"
    },
    {
      "x": 3,
      "y": -1,
      "z": -2,
      "name": "Soil_Grass_Full"
    },
    {
      "x": 3,
      "y": 0,
      "z": -2,
      "name": "Soil_Grass_Full"
    },
    {
      "x": 3,
      "y": -2,
      "z": -1,
      "name": "Soil_Grass_White"
    },
    {
      "x": 3,
      "y": -1,
      "z": -1,
      "name": "Soil_Grass_Full"
    },
    {
      "x": 3,
      "y": 0,
      "z": -1,
      "name": "Soil_Grass_Full"
    },
    {
      "x": 3,
      "y": -2,
      "z": 0,
      "name": "Soil_Grass_White"
    },
    {
      "x": 3,
      "y": -1,
      "z": 0,
      "name": "Soil_Grass_White"
    },
    {
      "x": 3,
      "y": 0,
      "z": 0,
      "name": "Soil_Pebbles",
      "support": 15
    },
    {
      "x": 3,
      "y": -2,
      "z": 1,
      "name": "Soil_Grass_White"
    },
    {
      "x": 3,
      "y": -1,
      "z": 1,
      "name": "Rock_Marble"
    },
    {
      "x": 3,
      "y": 0,
      "z": 1,
      "name": "Rock_Marble"
    },
    {
      "x": 3,
      "y": 1,
      "z": 1,
      "name": "Rock_Marble_Brick"
    },
    {
      "x": 3,
      "y": -2,
      "z": 2,
      "name": "Soil_Grass_White"
    },
    {
      "x": 3,
      "y": -1,
      "z": 2,
      "name": "Rock_Marble"
    },
    {
      "x": 3,
      "y": 0,
      "z": 2,
      "name": "Rock_Marble"
    },
    {
      "x": 3,
      "y": 1,
      "z": 2,
      "name": "Rock_Marble_Brick"
    },
    {
      "x": 3,
      "y": -2,
      "z": 3,
      "name": "Soil_Grass_White"
    },
    {
      "x": 3,
      "y": -1,
      "z": 3,
      "name": "Soil_Grass_Full"
    },
    {
      "x": 3,
      "y": 0,
      "z": 3,
      "name": "Soil_Grass_Full"
    },
    {
      "x": 3,
      "y": -2,
      "z": 4,
      "name": "Soil_Grass_White"
    },
    {
      "x": 3,
      "y": 0,
      "z": 4,
      "name": "Soil_Grass_Full"
    },
    {
      "x": 3,
      "y": -2,
      "z": 5,
      "name": "Soil_Grass_White"
    },
    {
      "x": 3,
      "y": -1,
      "z": 5,
      "name": "Soil_Grass_Full"
    },
    {
      "x": 3,
      "y": 0,
      "z": 5,
      "name": "Soil_Grass_Full"
    },
    {
      "x": 3,
      "y": -2,
      "z": 6,
      "name": "Soil_Grass_White"
    },
    {
      "x": 3,
      "y": -1,
      "z": 6,
      "name": "Soil_Grass_Full"
    },
    {
      "x": 3,
      "y": -2,
      "z": 7,
      "name": "Soil_Grass_White"
    },
    {
      "x": 4,
      "y": -2,
      "z": -4,
      "name": "Soil_Grass_White"
    },
    {
      "x": 4,
      "y": -2,
      "z": -3,
      "name": "Soil_Grass_White"
    },
    {
      "x": 4,
      "y": -1,
      "z": -3,
      "name": "Soil_Grass_White"
    },
    {
      "x": 4,
      "y": -2,
      "z": -2,
      "name": "Soil_Grass_White"
    },
    {
      "x": 4,
      "y": -1,
      "z": -2,
      "name": "Soil_Grass_White"
    },
    {
      "x": 4,
      "y": -2,
      "z": -1,
      "name": "Soil_Grass_White"
    },
    {
      "x": 4,
      "y": -1,
      "z": -1,
      "name": "Soil_Grass_White"
    },
    {
      "x": 4,
      "y": 0,
      "z": -1,
      "name": "Soil_Grass_Full"
    },
    {
      "x": 4,
      "y": -2,
      "z": 0,
      "name": "Soil_Grass_White"
    },
    {
      "x": 4,
      "y": -1,
      "z": 0,
      "name": "Soil_Grass_White"
    },
    {
      "x": 4,
      "y": 0,
      "z": 0,
      "name": "Soil_Grass_Full"
    },
    {
      "x": 4,
      "y": -2,
      "z": 1,
      "name": "Soil_Grass_White"
    },
    {
      "x": 4,
      "y": -1,
      "z": 1,
      "name": "Rock_Marble"
    },
    {
      "x": 4,
      "y": 0,
      "z": 1,
      "name": "Rock_Marble"
    },
    {
      "x": 4,
      "y": 1,
      "z": 1,
      "name": "Rock_Marble_Brick"
    },
    {
      "x": 4,
      "y": -2,
      "z": 2,
      "name": "Soil_Grass_White"
    },
    {
      "x": 4,
      "y": -1,
      "z": 2,
      "name": "Rock_Marble"
    },
    {
      "x": 4,
      "y": 0,
      "z": 2,
      "name": "Rock_Marble_Brick"
    },
    {
      "x": 4,
      "y": -2,
      "z": 3,
      "name": "Soil_Grass_White"
    },
    {
      "x": 4,
      "y": -1,
      "z": 3,
      "name": "Soil_Grass_Full"
    },
    {
      "x": 4,
      "y": 0,
      "z": 3,
      "name": "Soil_Grass_Full"
    },
    {
      "x": 4,
      "y": -2,
      "z": 4,
      "name": "Soil_Grass_White"
    },
    {
      "x": 4,
      "y": -1,
      "z": 4,
      "name": "Soil_Grass_Full"
    },
    {
      "x": 4,
      "y": 0,
      "z": 4,
      "name": "Soil_Grass_Full"
    },
    {
      "x": 4,
      "y": -2,
      "z": 5,
      "name": "Soil_Grass_White"
    },
    {
      "x": 4,
      "y": -1,
      "z": 5,
      "name": "Soil_Grass_Full"
    },
    {
      "x": 4,
      "y": -2,
      "z": 6,
      "name": "Soil_Grass_White"
    },
    {
      "x": 4,
      "y": -1,
      "z": 6,
      "name": "Soil_Grass_Full"
    },
    {
      "x": 4,
      "y": -2,
      "z": 7,
      "name": "Soil_Grass_White"
    },
    {
      "x": 5,
      "y": -2,
      "z": -3,
      "name": "Soil_Grass_White"
    },
    {
      "x": 5,
      "y": -2,
      "z": -2,
      "name": "Soil_Grass_White"
    },
    {
      "x": 5,
      "y": -1,
      "z": -2,
      "name": "Soil_Grass_White"
    },
    {
      "x": 5,
      "y": -2,
      "z": -1,
      "name": "Soil_Grass_White"
    },
    {
      "x": 5,
      "y": -1,
      "z": -1,
      "name": "Soil_Grass_White"
    },
    {
      "x": 5,
      "y": 0,
      "z": -1,
      "name": "Rock_Marble_Brick"
    },
    {
      "x": 5,
      "y": -2,
      "z": 0,
      "name": "Soil_Grass_White"
    },
    {
      "x": 5,
      "y": -1,
      "z": 0,
      "name": "Rock_Marble_Brick"
    },
    {
      "x": 5,
      "y": 0,
      "z": 0,
      "name": "Rock_Marble_Brick"
    },
    {
      "x": 5,
      "y": -2,
      "z": 1,
      "name": "Soil_Grass_White"
    },
    {
      "x": 5,
      "y": -1,
      "z": 1,
      "name": "Rock_Marble_Brick"
    },
    {
      "x": 5,
      "y": 0,
      "z": 1,
      "name": "Rock_Marble_Brick"
    },
    {
      "x": 5,
      "y": 1,
      "z": 1,
      "name": "Rock_Marble_Brick_Ornate"
    },
    {
      "x": 5,
      "y": 2,
      "z": 1,
      "name": "Rock_Marble_Brick_Pillar_Base"
    },
    {
      "x": 5,
      "y": 3,
      "z": 1,
      "name": "Rock_Marble_Brick_Pillar_Middle"
    },
    {
      "x": 5,
      "y": 4,
      "z": 1,
      "name": "Rock_Marble_Brick_Pillar_Middle"
    },
    {
      "x": 5,
      "y": 5,
      "z": 1,
      "name": "Rock_Marble_Brick_Pillar_Middle"
    },
    {
      "x": 5,
      "y": 6,
      "z": 1,
      "name": "Rock_Marble_Brick_Pillar_Base",
      "rotation": 8
    },
    {
      "x": 5,
      "y": 7,
      "z": 1,
      "name": "Rock_Marble_Stairs"
    },
    {
      "x": 5,
      "y": -2,
      "z": 2,
      "name": "Soil_Grass_White"
    },
    {
      "x": 5,
      "y": -1,
      "z": 2,
      "name": "Rock_Marble_Brick"
    },
    {
      "x": 5,
      "y": 0,
      "z": 2,
      "name": "Rock_Marble_Brick"
    },
    {
      "x": 5,
      "y": 1,
      "z": 2,
      "name": "Block_Spawner_Block",
      "components": {
        "Components": {
          "PlacedByInteraction": {
            "WhoPlacedUuid": {
              "$binary": "+u0Lek23TWiDpMOn5L2LqA==",
              "$type": "04"
            }
          },
          "BlockSpawner": {
            "BlockSpawnerId": "Zone4_Encounters_Tier3"
          }
        }
      }
    },
    {
      "x": 5,
      "y": -2,
      "z": 3,
      "name": "Soil_Grass_White"
    },
    {
      "x": 5,
      "y": -1,
      "z": 3,
      "name": "Soil_Grass_Full"
    },
    {
      "x": 5,
      "y": 0,
      "z": 3,
      "name": "Soil_Grass_Full"
    },
    {
      "x": 5,
      "y": -2,
      "z": 4,
      "name": "Soil_Grass_White"
    },
    {
      "x": 5,
      "y": -1,
      "z": 4,
      "name": "Soil_Grass_Full"
    },
    {
      "x": 5,
      "y": 0,
      "z": 4,
      "name": "Soil_Grass_Full"
    },
    {
      "x": 5,
      "y": -2,
      "z": 5,
      "name": "Soil_Grass_White"
    },
    {
      "x": 5,
      "y": -1,
      "z": 5,
      "name": "Soil_Grass_Full"
    },
    {
      "x": 5,
      "y": -2,
      "z": 6,
      "name": "Soil_Grass_White"
    },
    {
      "x": 5,
      "y": -1,
      "z": 6,
      "name": "Soil_Grass_White"
    },
    {
      "x": 6,
      "y": -2,
      "z": -2,
      "name": "Soil_Grass_White"
    },
    {
      "x": 6,
      "y": -2,
      "z": -1,
      "name": "Soil_Grass_White"
    },
    {
      "x": 6,
      "y": -1,
      "z": -1,
      "name": "Rock_Marble_Brick"
    },
    {
      "x": 6,
      "y": -2,
      "z": 0,
      "name": "Soil_Grass_White"
    },
    {
      "x": 6,
      "y": -1,
      "z": 0,
      "name": "Rock_Marble_Brick"
    },
    {
      "x": 6,
      "y": 0,
      "z": 0,
      "name": "Rock_Marble_Brick"
    },
    {
      "x": 6,
      "y": -2,
      "z": 1,
      "name": "Soil_Grass_White"
    },
    {
      "x": 6,
      "y": -1,
      "z": 1,
      "name": "Rock_Marble_Brick"
    },
    {
      "x": 6,
      "y": 0,
      "z": 1,
      "name": "Rock_Marble_Brick"
    },
    {
      "x": 6,
      "y": 1,
      "z": 1,
      "name": "Rock_Marble_Brick"
    },
    {
      "x": 6,
      "y": 2,
      "z": 1,
      "name": "Rubble_Marble",
      "support": 15
    },
    {
      "x": 6,
      "y": -2,
      "z": 2,
      "name": "Soil_Grass_White"
    },
    {
      "x": 6,
      "y": -1,
      "z": 2,
      "name": "Rock_Marble_Brick"
    },
    {
      "x": 6,
      "y": 0,
      "z": 2,
      "name": "Rock_Marble_Brick"
    },
    {
      "x": 6,
      "y": -2,
      "z": 3,
      "name": "Soil_Grass_White"
    },
    {
      "x": 6,
      "y": -1,
      "z": 3,
      "name": "Soil_Grass_Full"
    },
    {
      "x": 6,
      "y": 0,
      "z": 3,
      "name": "Soil_Grass_Full"
    },
    {
      "x": 6,
      "y": -2,
      "z": 4,
      "name": "Soil_Grass_White"
    },
    {
      "x": 6,
      "y": -1,
      "z": 4,
      "name": "Soil_Grass_Full"
    },
    {
      "x": 6,
      "y": 0,
      "z": 4,
      "name": "Soil_Grass_Full"
    },
    {
      "x": 6,
      "y": -2,
      "z": 5,
      "name": "Soil_Grass_White"
    },
    {
      "x": 6,
      "y": -1,
      "z": 5,
      "name": "Soil_Grass_White"
    },
    {
      "x": 7,
      "y": -2,
      "z": -1,
      "name": "Soil_Grass_White"
    },
    {
      "x": 7,
      "y": -2,
      "z": 0,
      "name": "Soil_Grass_White"
    },
    {
      "x": 7,
      "y": -1,
      "z": 0,
      "name": "Rock_Marble_Brick"
    },
    {
      "x": 7,
      "y": -2,
      "z": 1,
      "name": "Soil_Grass_White"
    },
    {
      "x": 7,
      "y": -1,
      "z": 1,
      "name": "Rock_Marble_Brick"
    },
    {
      "x": 7,
      "y": 0,
      "z": 1,
      "name": "Rock_Marble_Brick"
    },
    {
      "x": 7,
      "y": 1,
      "z": 1,
      "name": "Rock_Marble_Brick"
    },
    {
      "x": 7,
      "y": -2,
      "z": 2,
      "name": "Soil_Grass_White"
    },
    {
      "x": 7,
      "y": -1,
      "z": 2,
      "name": "Rock_Marble_Brick"
    },
    {
      "x": 7,
      "y": 0,
      "z": 2,
      "name": "Rock_Marble_Brick"
    },
    {
      "x": 7,
      "y": -2,
      "z": 3,
      "name": "Soil_Grass_White"
    },
    {
      "x": 7,
      "y": -1,
      "z": 3,
      "name": "Soil_Grass_Full"
    },
    {
      "x": 7,
      "y": 0,
      "z": 3,
      "name": "Soil_Grass_Full"
    },
    {
      "x": 7,
      "y": -2,
      "z": 4,
      "name": "Soil_Grass_White"
    },
    {
      "x": 7,
      "y": -1,
      "z": 4,
      "name": "Soil_Grass_Full"
    },
    {
      "x": 7,
      "y": -2,
      "z": 5,
      "name": "Soil_Grass_White"
    },
    {
      "x": 8,
      "y": -2,
      "z": 0,
      "name": "Soil_Grass_White"
    },
    {
      "x": 8,
      "y": -2,
      "z": 2,
      "name": "Soil_Grass_White"
    },
    {
      "x": 8,
      "y": -2,
      "z": 3,
      "name": "Soil_Grass_White"
    },
    {
      "x": 8,
      "y": -1,
      "z": 3,
      "name": "Soil_Grass_Full"
    }
  ]
}