{
  "version": 8,
  "blockIdVersion": 11,
  "anchorX": 0,
  "anchorY": 0,
  "anchorZ": 0,
  "blocks": [
    {
      "x": -9,
      "y": -2,
      "z": -6,
      "name": "Soil_Grass_White"
    },
    {
      "x": -9,
      "y": -2,
      "z": -5,
      "name": "Soil_Grass_White"
    },
    {
      "x": -9,
      "y": -1,
      "z": -5,
      "name": "Soil_Grass_Full"
    },
    {
      "x": -9,
      "y": -2,
      "z": -4,
      "name": "Soil_Grass_White"
    },
    {
      "x": -9,
      "y": -1,
      "z": -4,
      "name": "Soil_Grass_Full"
    },
    {
      "x": -9,
      "y": 0,
      "z": -4,
      "name": "Soil_Grass_Full"
    },
    {
      "x": -9,
      "y": -2,
      "z": -3,
      "name": "Soil_Grass_White"
    },
    {
      "x": -9,
      "y": -1,
      "z": -3,
      "name": "Soil_Grass_Full"
    },
    {
      "x": -9,
      "y": 0,
      "z": -3,
      "name": "Soil_Grass_Full"
    },
    {
      "x": -9,
      "y": -2,
      "z": -2,
      "name": "Soil_Grass_White"
    },
    {
      "x": -9,
      "y": -1,
      "z": -2,
      "name": "Soil_Grass_Full"
    },
    {
      "x": -9,
      "y": 0,
      "z": -2,
      "name": "Soil_Grass_Full"
    },
    {
      "x": -9,
      "y": -2,
      "z": -1,
      "name": "Soil_Grass_White"
    },
    {
      "x": -9,
      "y": -1,
      "z": -1,
      "name": "Soil_Grass_Sunny_Full"
    },
    {
      "x": -9,
      "y": 0,
      "z": -1,
      "name": "Soil_Grass_Sunny_Full"
    },
    {
      "x": -9,
      "y": -2,
      "z": 0,
      "name": "Soil_Grass_White"
    },
    {
      "x": -9,
      "y": -1,
      "z": 0,
      "name": "Soil_Grass_White"
    },
    {
      "x": -9,
      "y": 0,
      "z": 0,
      "name": "Soil_Grass_Full"
    },
    {
      "x": -9,
      "y": -2,
      "z": 1,
      "name": "Soil_Grass_White"
    },
    {
      "x": -9,
      "y": -1,
      "z": 1,
      "name": "Soil_Grass_White"
    },
    {
      "x": -9,
      "y": -2,
      "z": 2,
      "name": "Soil_Grass_White"
    },
    {
      "x": -8,
      "y": -2,
      "z": -7,
      "name": "Soil_Grass_White"
    },
    {
      "x": -8,
      "y": -2,
      "z": -6,
      "name": "Soil_Grass_White"
    },
    {
      "x": -8,
      "y": -1,
      "z": -6,
      "name": "Soil_Grass_Full"
    },
    {
      "x": -8,
      "y": -2,
      "z": -5,
      "name": "Soil_Grass_White"
    },
    {
      "x": -8,
      "y": -1,
      "z": -5,
      "name": "Soil_Grass_Full"
    },
    {
      "x": -8,
      "y": 0,
      "z": -5,
      "name": "Soil_Grass_Full"
    },
    {
      "x": -8,
      "y": -2,
      "z": -4,
      "name": "Soil_Grass_White"
    },
    {
      "x": -8,
      "y": -1,
      "z": -4,
      "name": "Soil_Grass_Full"
    },
    {
      "x": -8,
      "y": 0,
      "z": -4,
      "name": "Soil_Grass_Full"
    },
    {
      "x": -8,
      "y": -2,
      "z": -3,
      "name": "Soil_Grass_White"
    },
    {
      "x": -8,
      "y": -1,
      "z": -3,
      "name": "Soil_Grass_Full"
    },
    {
      "x": -8,
      "y": 0,
      "z": -3,
      "name": "Soil_Grass_Full"
    },
    {
      "x": -8,
      "y": -2,
      "z": -2,
      "name": "Soil_Grass_White"
    },
    {
      "x": -8,
      "y": -1,
      "z": -2,
      "name": "Soil_Grass_Full"
    },
    {
      "x": -8,
      "y": 0,
      "z": -2,
      "name": "Soil_Grass_Sunny_Full"
    },
    {
      "x": -8,
      "y": -2,
      "z": -1,
      "name": "Soil_Grass_White"
    },
    {
      "x": -8,
      "y": -1,
      "z": -1,
      "name": "Soil_Grass_Sunny_Full"
    },
    {
      "x": -8,
      "y": 0,
      "z": -1,
      "name": "Soil_Grass_Sunny_Full"
    },
    {
      "x": -8,
      "y": -2,
      "z": 0,
      "name": "Soil_Grass_White"
    },
    {
      "x": -8,
      "y": -1,
      "z": 0,
      "name": "Soil_Grass_Full"
    },
    {
      "x": -8,
      "y": 0,
      "z": 0,
      "name": "Soil_Grass_Full"
    },
    {
      "x": -8,
      "y": -2,
      "z": 1,
      "name": "Soil_Grass_White"
    },
    {
      "x": -8,
      "y": -1,
      "z": 1,
      "name": "Soil_Grass_Full"
    },
    {
      "x": -8,
      "y": 0,
      "z": 1,
      "name": "Soil_Grass_Full"
    },
    {
      "x": -8,
      "y": -2,
      "z": 2,
      "name": "Soil_Grass_White"
    },
    {
      "x": -8,
      "y": -1,
      "z": 2,
      "name": "Soil_Grass_White"
    },
    {
      "x": -8,
      "y": -2,
      "z": 3,
      "name": "Soil_Grass_White"
    },
    {
      "x": -7,
      "y": -2,
      "z": -8,
      "name": "Soil_Grass_White"
    },
    {
      "x": -7,
      "y": -2,
      "z": -7,
      "name": "Soil_Grass_White"
    },
    {
      "x": -7,
      "y": -1,
      "z": -7,
      "name": "Soil_Grass_Full"
    },
    {
      "x": -7,
      "y": -2,
      "z": -6,
      "name": "Soil_Grass_White"
    },
    {
      "x": -7,
      "y": -1,
      "z": -6,
      "name": "Soil_Grass_Full"
    },
    {
      "x": -7,
      "y": 0,
      "z": -6,
      "name": "Soil_Grass_Sunny_Full"
    },
    {
      "x": -7,
      "y": -2,
      "z": -5,
      "name": "Soil_Grass_White"
    },
    {
      "x": -7,
      "y": -1,
      "z": -5,
      "name": "Soil_Grass_Full"
    },
    {
      "x": -7,
      "y": 0,
      "z": -5,
      "name": "Soil_Grass_Sunny_Full"
    },
    {
      "x": -7,
      "y": -2,
      "z": -4,
      "name": "Soil_Grass_White"
    },
    {
      "x": -7,
      "y": -1,
      "z": -4,
      "name": "Soil_Grass_Full"
    },
    {
      "x": -7,
      "y": 0,
      "z": -4,
      "name": "Soil_Grass_Sunny_Full"
    },
    {
      "x": -7,
      "y": 1,
      "z": -4,
      "name": "Rubble_Marble_Medium",
      "support": 15
    },
    {
      "x": -7,
      "y": -2,
      "z": -3,
      "name": "Soil_Grass_White"
    },
    {
      "x": -7,
      "y": -1,
      "z": -3,
      "name": "Soil_Grass_Sunny_Full"
    },
    {
      "x": -7,
      "y": 0,
      "z": -3,
      "name": "Soil_Grass_Sunny_Full"
    },
    {
      "x": -7,
      "y": 1,
      "z": -3,
      "name": "Rubble_Marble_Medium",
      "support": 15
    },
    {
      "x": -7,
      "y": -2,
      "z": -2,
      "name": "Soil_Grass_White"
    },
    {
      "x": -7,
      "y": -1,
      "z": -2,
      "name": "Soil_Grass_Full"
    },
    {
      "x": -7,
      "y": 0,
      "z": -2,
      "name": "Soil_Grass_Full"
    },
    {
      "x": -7,
      "y": -2,
      "z": -1,
      "name": "Soil_Grass_White"
    },
    {
      "x": -7,
      "y": -1,
      "z": -1,
      "name": "Soil_Grass_Full"
    },
    {
      "x": -7,
      "y": 0,
      "z": -1,
      "name": "Soil_Grass_Full"
    },
    {
      "x": -7,
      "y": -2,
      "z": 0,
      "name": "Soil_Grass_White"
    },
    {
      "x": -7,
      "y": -1,
      "z": 0,
      "name": "Soil_Grass_Full"
    },
    {
      "x": -7,
      "y": 0,
      "z": 0,
      "name": "Soil_Grass_Full"
    },
    {
      "x": -7,
      "y": -2,
      "z": 1,
      "name": "Soil_Grass_White"
    },
    {
      "x": -7,
      "y": -1,
      "z": 1,
      "name": "Soil_Grass_Full"
    },
    {
      "x": -7,
      "y": 0,
      "z": 1,
      "name": "Soil_Grass_Full"
    },
    {
      "x": -7,
      "y": -2,
      "z": 2,
      "name": "Soil_Grass_White"
    },
    {
      "x": -7,
      "y": -1,
      "z": 2,
      "name": "Soil_Grass_Full"
    },
    {
      "x": -7,
      "y": 0,
      "z": 2,
      "name": "Soil_Grass_Full"
    },
    {
      "x": -7,
      "y": -2,
      "z": 3,
      "name": "Soil_Grass_White"
    },
    {
      "x": -7,
      "y": -1,
      "z": 3,
      "name": "Soil_Grass_Full"
    },
    {
      "x": -7,
      "y": -2,
      "z": 4,
      "name": "Soil_Grass_White"
    },
    {
      "x": -7,
      "y": -2,
      "z": 5,
      "name": "Soil_Grass_White"
    },
    {
      "x": -7,
      "y": -2,
      "z": 6,
      "name": "Soil_Grass_White"
    },
    {
      "x": -6,
      "y": -2,
      "z": -9,
      "name": "Soil_Grass_White"
    },
    {
      "x": -6,
      "y": -2,
      "z": -8,
      "name": "Soil_Grass_White"
    },
    {
      "x": -6,
      "y": -1,
      "z": -8,
      "name": "Soil_Grass_Full"
    },
    {
      "x": -6,
      "y": 0,
      "z": -8,
      "name": "Soil_Grass_Full"
    },
    {
      "x": -6,
      "y": -2,
      "z": -7,
      "name": "Soil_Grass_White"
    },
    {
      "x": -6,
      "y": -1,
      "z": -7,
      "name": "Soil_Grass_Full"
    },
    {
      "x": -6,
      "y": 0,
      "z": -7,
      "name": "Soil_Grass_Full"
    },
    {
      "x": -6,
      "y": -2,
      "z": -6,
      "name": "Soil_Grass_White"
    },
    {
      "x": -6,
      "y": -1,
      "z": -6,
      "name": "Soil_Grass_Full"
    },
    {
      "x": -6,
      "y": 0,
      "z": -6,
      "name": "Soil_Grass_Full"
    },
    {
      "x": -6,
      "y": -2,
      "z": -5,
      "name": "Soil_Grass_White"
    },
    {
      "x": -6,
      "y": -1,
      "z": -5,
      "name": "Soil_Grass_Full"
    },
    {
      "x": -6,
      "y": 0,
      "z": -5,
      "name": "Soil_Grass_Full"
    },
    {
      "x": -6,
      "y": 1,
      "z": -5,
      "name": "Plant_Grass_Sharp"
    },
    {
      "x": -6,
      "y": -2,
      "z": -4,
      "name": "Soil_Grass_White"
    },
    {
      "x": -6,
      "y": -1,
      "z": -4,
      "name": "Soil_Grass_Full"
    },
    {
      "x": -6,
      "y": 0,
      "z": -4,
      "name": "Soil_Grass_Full"
    },
    {
      "x": -6,
      "y": -2,
      "z": -3,
      "name": "Soil_Grass_White"
    },
    {
      "x": -6,
      "y": -1,
      "z": -3,
      "name": "Soil_Grass_Full"
    },
    {
      "x": -6,
      "y": 0,
      "z": -3,
      "name": "Soil_Dirt_White"
    },
    {
      "x": -6,
      "y": 1,
      "z": -3,
      "name": "Soil_Pebbles",
      "support": 15
    },
    {
      "x": -6,
      "y": -2,
      "z": -2,
      "name": "Soil_Grass_White"
    },
    {
      "x": -6,
      "y": -1,
      "z": -2,
      "name": "Soil_Grass_Full"
    },
    {
      "x": -6,
      "y": 0,
      "z": -2,
      "name": "Soil_Grass_Full"
    },
    {
      "x": -6,
      "y": 1,
      "z": -2,
      "name": "Rubble_Marble_Medium",
      "support": 15
    },
    {
      "x": -6,
      "y": -2,
      "z": -1,
      "name": "Soil_Grass_White"
    },
    {
      "x": -6,
      "y": -1,
      "z": -1,
      "name": "Soil_Pebbles"
    },
    {
      "x": -6,
      "y": 0,
      "z": -1,
      "name": "Soil_Pebbles",
      "support": 15
    },
    {
      "x": -6,
      "y": -2,
      "z": 0,
      "name": "Soil_Grass_White"
    },
    {
      "x": -6,
      "y": 0,
      "z": 0,
      "name": "Soil_Pebbles",
      "support": 15
    },
    {
      "x": -6,
      "y": -2,
      "z": 1,
      "name": "Soil_Grass_White"
    },
    {
      "x": -6,
      "y": -1,
      "z": 1,
      "name": "Soil_Grass_Full"
    },
    {
      "x": -6,
      "y": 0,
      "z": 1,
      "name": "Soil_Pebbles",
      "support": 15
    },
    {
      "x": -6,
      "y": -2,
      "z": 2,
      "name": "Soil_Grass_White"
    },
    {
      "x": -6,
      "y": -1,
      "z": 2,
      "name": "Soil_Grass_Full"
    },
    {
      "x": -6,
      "y": 0,
      "z": 2,
      "name": "Soil_Grass_Full"
    },
    {
      "x": -6,
      "y": -2,
      "z": 3,
      "name": "Soil_Grass_White"
    },
    {
      "x": -6,
      "y": -1,
      "z": 3,
      "name": "Soil_Grass_Full"
    },
    {
      "x": -6,
      "y": 0,
      "z": 3,
      "name": "Soil_Grass_Full"
    },
    {
      "x": -6,
      "y": -2,
      "z": 4,
      "name": "Soil_Grass_White"
    },
    {
      "x": -6,
      "y": -1,
      "z": 4,
      "name": "Soil_Grass_Full"
    },
    {
      "x": -6,
      "y": -2,
      "z": 5,
      "name": "Soil_Grass_White"
    },
    {
      "x": -6,
      "y": -1,
      "z": 5,
      "name": "Soil_Grass_Full"
    },
    {
      "x": -6,
      "y": -2,
      "z": 6,
      "name": "Soil_Grass_White"
    },
    {
      "x": -6,
      "y": -1,
      "z": 6,
      "name": "Soil_Grass_Full"
    },
    {
      "x": -6,
      "y": -2,
      "z": 7,
      "name": "Soil_Grass_White"
    },
    {
      "x": -5,
      "y": -2,
      "z": -10,
      "name": "Soil_Grass_White"
    },
    {
      "x": -5,
      "y": -2,
      "z": -9,
      "name": "Soil_Grass_White"
    },
    {
      "x": -5,
      "y": -1,
      "z": -9,
      "name": "Soil_Grass_Full"
    },
    {
      "x": -5,
      "y": -2,
      "z": -8,
      "name": "Soil_Grass_White"
    },
    {
      "x": -5,
      "y": -1,
      "z": -8,
      "name": "Soil_Grass_Full"
    },
    {
      "x": -5,
      "y": 0,
      "z": -8,
      "name": "Soil_Grass_Full"
    },
    {
      "x": -5,
      "y": -2,
      "z": -7,
      "name": "Soil_Grass_White"
    },
    {
      "x": -5,
      "y": -1,
      "z": -7,
      "name": "Soil_Grass_Full"
    },
    {
      "x": -5,
      "y": 0,
      "z": -7,
      "name": "Soil_Grass_Full"
    },
    {
      "x": -5,
      "y": -2,
      "z": -6,
      "name": "Soil_Grass_White"
    },
    {
      "x": -5,
      "y": -1,
      "z": -6,
      "name": "Soil_Grass_Full"
    },
    {
      "x": -5,
      "y": 0,
      "z": -6,
      "name": "Soil_Grass_Full"
    },
    {
      "x": -5,
      "y": -2,
      "z": -5,
      "name": "Soil_Grass_White"
    },
    {
      "x": -5,
      "y": -1,
      "z": -5,
      "name": "Soil_Grass_Full"
    },
    {
      "x": -5,
      "y": 0,
      "z": -5,
      "name": "Soil_Grass_Full"
    },
    {
      "x": -5,
      "y": -2,
      "z": -4,
      "name": "Soil_Grass_White"
    },
    {
      "x": -5,
      "y": -1,
      "z": -4,
      "name": "Soil_Grass_Full"
    },
    {
      "x": -5,
      "y": 0,
      "z": -4,
      "name": "Soil_Grass_Full"
    },
    {
      "x": -5,
      "y": 1,
      "z": -4,
      "name": "Rubble_Marble_Medium",
      "support": 15
    },
    {
      "x": -5,
      "y": -2,
      "z": -3,
      "name": "Soil_Grass_White"
    },
    {
      "x": -5,
      "y": -1,
      "z": -3,
      "name": "Soil_Grass_Full"
    },
    {
      "x": -5,
      "y": 0,
      "z": -3,
      "name": "Soil_Grass_Full"
    },
    {
      "x": -5,
      "y": 1,
      "z": -3,
      "name": "Rock_Marble_Brick_Stairs",
      "rotation": 3
    },
    {
      "x": -5,
      "y": 2,
      "z": -3,
      "name": "Rock_Marble_Brick_Stairs",
      "rotation": 3
    },
    {
      "x": -5,
      "y": -2,
      "z": -2,
      "name": "Soil_Grass_White"
    },
    {
      "x": -5,
      "y": -1,
      "z": -2,
      "name": "Soil_Grass_Full"
    },
    {
      "x": -5,
      "y": 0,
      "z": -2,
      "name": "Soil_Grass_Full"
    },
    {
      "x": -5,
      "y": 1,
      "z": -2,
      "name": "Rock_Marble_Brick_Half"
    },
    {
      "x": -5,
      "y": -2,
      "z": -1,
      "name": "Soil_Grass_White"
    },
    {
      "x": -5,
      "y": 0,
      "z": -1,
      "name": "Soil_Pebbles",
      "support": 15
    },
    {
      "x": -5,
      "y": -2,
      "z": 0,
      "name": "Soil_Grass_White"
    },
    {
      "x": -5,
      "y": 0,
      "z": 0,
      "name": "Soil_Grass_Full"
    },
    {
      "x": -5,
      "y": 1,
      "z": 0,
      "name": "Rubble_Marble",
      "support": 15
    },
    {
      "x": -5,
      "y": -2,
      "z": 1,
      "name": "Soil_Grass_White"
    },
    {
      "x": -5,
      "y": -1,
      "z": 1,
      "name": "Soil_Grass_Full"
    },
    {
      "x": -5,
      "y": 0,
      "z": 1,
      "name": "Soil_Grass_Full"
    },
    {
      "x": -5,
      "y": 1,
      "z": 1,
      "name": "Rubble_Marble",
      "support": 15
    },
    {
      "x": -5,
      "y": -2,
      "z": 2,
      "name": "Soil_Grass_White"
    },
    {
      "x": -5,
      "y": -1,
      "z": 2,
      "name": "Soil_Grass_Full"
    },
    {
      "x": -5,
      "y": 0,
      "z": 2,
      "name": "Soil_Grass_Full"
    },
    {
      "x": -5,
      "y": -2,
      "z": 3,
      "name": "Soil_Grass_White"
    },
    {
      "x": -5,
      "y": -1,
      "z": 3,
      "name": "Soil_Grass_Full"
    },
    {
      "x": -5,
      "y": 0,
      "z": 3,
      "name": "Soil_Grass_Full"
    },
    {
      "x": -5,
      "y": 1,
      "z": 3,
      "name": "Plant_Moss_Short_Green"
    },
    {
      "x": -5,
      "y": -2,
      "z": 4,
      "name": "Soil_Grass_White"
    },
    {
      "x": -5,
      "y": -1,
      "z": 4,
      "name": "Soil_Grass_Full"
    },
    {
      "x": -5,
      "y": 0,
      "z": 4,
      "name": "Soil_Grass_Full"
    },
    {
      "x": -5,
      "y": -2,
      "z": 5,
      "name": "Soil_Grass_White"
    },
    {
      "x": -5,
      "y": -1,
      "z": 5,
      "name": "Soil_Grass_Full"
    },
    {
      "x": -5,
      "y": 0,
      "z": 5,
      "name": "Soil_Grass_Full"
    },
    {
      "x": -5,
      "y": -2,
      "z": 6,
      "name": "Soil_Grass_White"
    },
    {
      "x": -5,
      "y": -1,
      "z": 6,
      "name": "Soil_Grass_Full"
    },
    {
      "x": -5,
      "y": 0,
      "z": 6,
      "name": "Soil_Grass_Full"
    },
    {
      "x": -5,
      "y": -2,
      "z": 7,
      "name": "Soil_Grass_White"
    },
    {
      "x": -5,
      "y": -1,
      "z": 7,
      "name": "Soil_Grass_Full"
    },
    {
      "x": -4,
      "y": -2,
      "z": -10,
      "name": "Soil_Grass_White"
    },
    {
      "x": -4,
      "y": -2,
      "z": -9,
      "name": "Soil_Grass_White"
    },
    {
      "x": -4,
      "y": -1,
      "z": -9,
      "name": "Soil_Grass_Full"
    },
    {
      "x": -4,
      "y": -2,
      "z": -8,
      "name": "Soil_Grass_White"
    },
    {
      "x": -4,
      "y": -1,
      "z": -8,
      "name": "Soil_Grass_Full"
    },
    {
      "x": -4,
      "y": 0,
      "z": -8,
      "name": "Soil_Grass_Full"
    },
    {
      "x": -4,
      "y": -2,
      "z": -7,
      "name": "Soil_Grass_White"
    },
    {
      "x": -4,
      "y": -1,
      "z": -7,
      "name": "Soil_Grass_Full"
    },
    {
      "x": -4,
      "y": 0,
      "z": -7,
      "name": "Soil_Grass_Full"
    },
    {
      "x": -4,
      "y": 1,
      "z": -7,
      "name": "Plant_Grass_Sharp"
    },
    {
      "x": -4,
      "y": -2,
      "z": -6,
      "name": "Soil_Grass_White"
    },
    {
      "x": -4,
      "y": -1,
      "z": -6,
      "name": "Soil_Grass_Full"
    },
    {
      "x": -4,
      "y": 0,
      "z": -6,
      "name": "Soil_Grass_Full"
    },
    {
      "x": -4,
      "y": 1,
      "z": -6,
      "name": "Plant_Grass_Sharp"
    },
    {
      "x": -4,
      "y": -2,
      "z": -5,
      "name": "Soil_Grass_White"
    },
    {
      "x": -4,
      "y": -1,
      "z": -5,
      "name": "Soil_Grass_Full"
    },
    {
      "x": -4,
      "y": 0,
      "z": -5,
      "name": "Soil_Grass_Full"
    },
    {
      "x": -4,
      "y": -2,
      "z": -4,
      "name": "Soil_Grass_White"
    },
    {
      "x": -4,
      "y": -1,
      "z": -4,
      "name": "Soil_Grass_Full"
    },
    {
      "x": -4,
      "y": 0,
      "z": -4,
      "name": "Soil_Grass_Full"
    },
    {
      "x": -4,
      "y": -2,
      "z": -3,
      "name": "Soil_Grass_White"
    },
    {
      "x": -4,
      "y": -1,
      "z": -3,
      "name": "Soil_Grass_Full"
    },
    {
      "x": -4,
      "y": 0,
      "z": -3,
      "name": "Soil_Grass_Full"
    },
    {
      "x": -4,
      "y": -2,
      "z": -2,
      "name": "Soil_Grass_White"
    },
    {
      "x": -4,
      "y": -1,
      "z": -2,
      "name": "Soil_Pebbles"
    },
    {
      "x": -4,
      "y": 0,
      "z": -2,
      "name": "Soil_Pebbles",
      "support": 15
    },
    {
      "x": -4,
      "y": -2,
      "z": -1,
      "name": "Soil_Grass_White"
    },
    {
      "x": -4,
      "y": -1,
      "z": -1,
      "name": "Soil_Pebbles"
    },
    {
      "x": -4,
      "y": 0,
      "z": -1,
      "name": "Soil_Pebbles",
      "support": 15
    },
    {
      "x": -4,
      "y": -2,
      "z": 0,
      "name": "Soil_Grass_White"
    },
    {
      "x": -4,
      "y": -1,
      "z": 0,
      "name": "Soil_Grass_Full"
    },
    {
      "x": -4,
      "y": 0,
      "z": 0,
      "name": "Soil_Grass_Full"
    },
    {
      "x": -4,
      "y": -2,
      "z": 1,
      "name": "Soil_Grass_White"
    },
    {
      "x": -4,
      "y": -1,
      "z": 1,
      "name": "Soil_Grass_Full"
    },
    {
      "x": -4,
      "y": 0,
      "z": 1,
      "name": "Soil_Grass_Full"
    },
    {
      "x": -4,
      "y": -2,
      "z": 2,
      "name": "Soil_Grass_White"
    },
    {
      "x": -4,
      "y": -1,
      "z": 2,
      "name": "Soil_Grass_Full"
    },
    {
      "x": -4,
      "y": 0,
      "z": 2,
      "name": "Soil_Grass_Full"
    },
    {
      "x": -4,
      "y": -2,
      "z": 3,
      "name": "Soil_Grass_White"
    },
    {
      "x": -4,
      "y": -1,
      "z": 3,
      "name": "Soil_Grass_Full"
    },
    {
      "x": -4,
      "y": 0,
      "z": 3,
      "name": "Soil_Grass_Full"
    },
    {
      "x": -4,
      "y": -2,
      "z": 4,
      "name": "Soil_Grass_White"
    },
    {
      "x": -4,
      "y": -1,
      "z": 4,
      "name": "Soil_Grass_Full"
    },
    {
      "x": -4,
      "y": 0,
      "z": 4,
      "name": "Soil_Grass_Full"
    },
    {
      "x": -4,
      "y": 1,
      "z": 4,
      "name": "Rubble_Marble",
      "support": 15
    },
    {
      "x": -4,
      "y": -2,
      "z": 5,
      "name": "Soil_Grass_White"
    },
    {
      "x": -4,
      "y": -1,
      "z": 5,
      "name": "Soil_Grass_Full"
    },
    {
      "x": -4,
      "y": 0,
      "z": 5,
      "name": "Soil_Grass_Full"
    },
    {
      "x": -4,
      "y": -2,
      "z": 6,
      "name": "Soil_Grass_White"
    },
    {
      "x": -4,
      "y": -1,
      "z": 6,
      "name": "Soil_Grass_Full"
    },
    {
      "x": -4,
      "y": 0,
      "z": 6,
      "name": "Soil_Grass_Full"
    },
    {
      "x": -4,
      "y": -2,
      "z": 7,
      "name": "Soil_Grass_White"
    },
    {
      "x": -4,
      "y": -1,
      "z": 7,
      "name": "Soil_Grass_Full"
    },
    {
      "x": -4,
      "y": 0,
      "z": 7,
      "name": "Soil_Grass_Full"
    },
    {
      "x": -4,
      "y": 1,
      "z": 7,
      "name": "Plant_Grass_Sharp"
    },
    {
      "x": -4,
      "y": -2,
      "z": 8,
      "name": "Soil_Grass_White"
    },
    {
      "x": -3,
      "y": -2,
      "z": -10,
      "name": "Soil_Grass_White"
    },
    {
      "x": -3,
      "y": -1,
      "z": -10,
      "name": "Soil_Grass_White"
    },
    {
      "x": -3,
      "y": -2,
      "z": -9,
      "name": "Soil_Grass_White"
    },
    {
      "x": -3,
      "y": -1,
      "z": -9,
      "name": "Soil_Grass_Full"
    },
    {
      "x": -3,
      "y": 0,
      "z": -9,
      "name": "Soil_Grass_Full"
    },
    {
      "x": -3,
      "y": -2,
      "z": -8,
      "name": "Soil_Grass_White"
    },
    {
      "x": -3,
      "y": -1,
      "z": -8,
      "name": "Soil_Grass_Full"
    },
    {
      "x": -3,
      "y": 0,
      "z": -8,
      "name": "Soil_Grass_Full"
    },
    {
      "x": -3,
      "y": -2,
      "z": -7,
      "name": "Soil_Grass_White"
    },
    {
      "x": -3,
      "y": -1,
      "z": -7,
      "name": "Soil_Grass_Full"
    },
    {
      "x": -3,
      "y": 0,
      "z": -7,
      "name": "Soil_Grass_Full"
    },
    {
      "x": -3,
      "y": -2,
      "z": -6,
      "name": "Soil_Grass_White"
    },
    {
      "x": -3,
      "y": -1,
      "z": -6,
      "name": "Soil_Grass_Full"
    },
    {
      "x": -3,
      "y": 0,
      "z": -6,
      "name": "Soil_Grass_Full"
    },
    {
      "x": -3,
      "y": 1,
      "z": -6,
      "name": "Plant_Grass_Sharp"
    },
    {
      "x": -3,
      "y": -2,
      "z": -5,
      "name": "Soil_Grass_White"
    },
    {
      "x": -3,
      "y": -1,
      "z": -5,
      "name": "Soil_Grass_Full"
    },
    {
      "x": -3,
      "y": 0,
      "z": -5,
      "name": "Soil_Grass_Full"
    },
    {
      "x": -3,
      "y": -2,
      "z": -4,
      "name": "Soil_Grass_White"
    },
    {
      "x": -3,
      "y": -1,
      "z": -4,
      "name": "Soil_Grass_Full"
    },
    {
      "x": -3,
      "y": 0,
      "z": -4,
      "name": "Soil_Grass_Full"
    },
    {
      "x": -3,
      "y": -2,
      "z": -3,
      "name": "Soil_Grass_White"
    },
    {
      "x": -3,
      "y": -1,
      "z": -3,
      "name": "Soil_Grass_Full"
    },
    {
      "x": -3,
      "y": 0,
      "z": -3,
      "name": "Soil_Grass_Full"
    },
    {
      "x": -3,
      "y": -2,
      "z": -2,
      "name": "Soil_Grass_White"
    },
    {
      "x": -3,
      "y": -1,
      "z": -2,
      "name": "Soil_Pebbles"
    },
    {
      "x": -3,
      "y": 0,
      "z": -2,
      "name": "Soil_Pebbles",
      "support": 15
    },
    {
      "x": -3,
      "y": -2,
      "z": -1,
      "name": "Soil_Grass_White"
    },
    {
      "x": -3,
      "y": -1,
      "z": -1,
      "name": "Soil_Pebbles"
    },
    {
      "x": -3,
      "y": 0,
      "z": -1,
      "name": "Soil_Pebbles",
      "support": 15
    },
    {
      "x": -3,
      "y": 8,
      "z": -1,
      "name": "Rock_Marble_Brick_Half",
      "rotation": 7
    },
    {
      "x": -3,
      "y": -2,
      "z": 0,
      "name": "Soil_Grass_White"
    },
    {
      "x": -3,
      "y": -1,
      "z": 0,
      "name": "Soil_Grass_White"
    },
    {
      "x": -3,
      "y": 0,
      "z": 0,
      "name": "Soil_Grass_Full"
    },
    {
      "x": -3,
      "y": 1,
      "z": 0,
      "name": "Rock_Marble_Brick_Stairs",
      "rotation": 3
    },
    {
      "x": -3,
      "y": -2,
      "z": 1,
      "name": "Soil_Grass_White"
    },
    {
      "x": -3,
      "y": -1,
      "z": 1,
      "name": "Soil_Grass_Full"
    },
    {
      "x": -3,
      "y": 0,
      "z": 1,
      "name": "Soil_Grass_Full"
    },
    {
      "x": -3,
      "y": 1,
      "z": 1,
      "name": "Rock_Marble_Brick_Stairs",
      "rotation": 3
    },
    {
      "x": -3,
      "y": -2,
      "z": 2,
      "name": "Soil_Grass_White"
    },
    {
      "x": -3,
      "y": -1,
      "z": 2,
      "name": "Soil_Grass_Full"
    },
    {
      "x": -3,
      "y": 0,
      "z": 2,
      "name": "Soil_Grass_Full"
    },
    {
      "x": -3,
      "y": 1,
      "z": 2,
      "name": "Rock_Marble_Brick_Stairs",
      "rotation": 3
    },
    {
      "x": -3,
      "y": -2,
      "z": 3,
      "name": "Soil_Grass_White"
    },
    {
      "x": -3,
      "y": -1,
      "z": 3,
      "name": "Soil_Grass_Full"
    },
    {
      "x": -3,
      "y": 0,
      "z": 3,
      "name": "Soil_Grass_Full"
    },
    {
      "x": -3,
      "y": 1,
      "z": 3,
      "name": "Plant_Grass_Lush_Short"
    },
    {
      "x": -3,
      "y": 8,
      "z": 3,
      "name": "Rock_Marble_Brick_Half",
      "rotation": 7
    },
    {
      "x": -3,
      "y": -2,
      "z": 4,
      "name": "Soil_Grass_White"
    },
    {
      "x": -3,
      "y": -1,
      "z": 4,
      "name": "Soil_Grass_Full"
    },
    {
      "x": -3,
      "y": 0,
      "z": 4,
      "name": "Soil_Grass_Full"
    },
    {
      "x": -3,
      "y": -2,
      "z": 5,
      "name": "Soil_Grass_White"
    },
    {
      "x": -3,
      "y": -1,
      "z": 5,
      "name": "Soil_Grass_Full"
    },
    {
      "x": -3,
      "y": 0,
      "z": 5,
      "name": "Soil_Grass_Full"
    },
    {
      "x": -3,
      "y": 1,
      "z": 5,
      "name": "Rock_Marble_Brick_Half"
    },
    {
      "x": -3,
      "y": -2,
      "z": 6,
      "name": "Soil_Grass_White"
    },
    {
      "x": -3,
      "y": -1,
      "z": 6,
      "name": "Soil_Grass_Full"
    },
    {
      "x": -3,
      "y": 0,
      "z": 6,
      "name": "Soil_Grass_Full"
    },
    {
      "x": -3,
      "y": 1,
      "z": 6,
      "name": "Rubble_Marble",
      "support": 15
    },
    {
      "x": -3,
      "y": -2,
      "z": 7,
      "name": "Soil_Grass_White"
    },
    {
      "x": -3,
      "y": -1,
      "z": 7,
      "name": "Soil_Grass_Full"
    },
    {
      "x": -3,
      "y": 0,
      "z": 7,
      "name": "Soil_Grass_Full"
    },
    {
      "x": -3,
      "y": -2,
      "z": 8,
      "name": "Soil_Grass_Full"
    },
    {
      "x": -3,
      "y": -1,
      "z": 8,
      "name": "Soil_Grass_Full"
    },
    {
      "x": -2,
      "y": -2,
      "z": -10,
      "name": "Soil_Grass_White"
    },
    {
      "x": -2,
      "y": -1,
      "z": -10,
      "name": "Soil_Grass_White"
    },
    {
      "x": -2,
      "y": -2,
      "z": -9,
      "name": "Soil_Grass_White"
    },
    {
      "x": -2,
      "y": -1,
      "z": -9,
      "name": "Soil_Grass_Full"
    },
    {
      "x": -2,
      "y": 0,
      "z": -9,
      "name": "Soil_Grass_Full"
    },
    {
      "x": -2,
      "y": -2,
      "z": -8,
      "name": "Soil_Grass_White"
    },
    {
      "x": -2,
      "y": -1,
      "z": -8,
      "name": "Soil_Grass_Full"
    },
    {
      "x": -2,
      "y": 0,
      "z": -8,
      "name": "Soil_Grass_Full"
    },
    {
      "x": -2,
      "y": -2,
      "z": -7,
      "name": "Soil_Grass_White"
    },
    {
      "x": -2,
      "y": -1,
      "z": -7,
      "name": "Soil_Grass_Full"
    },
    {
      "x": -2,
      "y": 0,
      "z": -7,
      "name": "Soil_Grass_Full"
    },
    {
      "x": -2,
      "y": -2,
      "z": -6,
      "name": "Soil_Grass_White"
    },
    {
      "x": -2,
      "y": -1,
      "z": -6,
      "name": "Soil_Grass_Full"
    },
    {
      "x": -2,
      "y": 0,
      "z": -6,
      "name": "Soil_Grass_Full"
    },
    {
      "x": -2,
      "y": -2,
      "z": -5,
      "name": "Soil_Grass_White"
    },
    {
      "x": -2,
      "y": -1,
      "z": -5,
      "name": "Soil_Grass_Full"
    },
    {
      "x": -2,
      "y": 0,
      "z": -5,
      "name": "Soil_Grass_Full"
    },
    {
      "x": -2,
      "y": -2,
      "z": -4,
      "name": "Soil_Grass_White"
    },
    {
      "x": -2,
      "y": -1,
      "z": -4,
      "name": "Soil_Grass_Full"
    },
    {
      "x": -2,
      "y": 0,
      "z": -4,
      "name": "Soil_Grass_Full"
    },
    {
      "x": -2,
      "y": -2,
      "z": -3,
      "name": "Soil_Grass_White"
    },
    {
      "x": -2,
      "y": -1,
      "z": -3,
      "name": "Soil_Grass_Full"
    },
    {
      "x": -2,
      "y": 0,
      "z": -3,
      "name": "Soil_Grass_Full"
    },
    {
      "x": -2,
      "y": -2,
      "z": -2,
      "name": "Soil_Grass_White"
    },
    {
      "x": -2,
      "y": -1,
      "z": -2,
      "name": "Soil_Grass_Full"
    },
    {
      "x": -2,
      "y": 0,
      "z": -2,
      "name": "Soil_Grass_Full"
    },
    {
      "x": -2,
      "y": 1,
      "z": -2,
      "name": "Plant_Grass_Lush"
    },
    {
      "x": -2,
      "y": 8,
      "z": -2,
      "name": "Rock_Marble_Brick_Half",
      "rotation": 6
    },
    {
      "x": -2,
      "y": -2,
      "z": -1,
      "name": "Soil_Grass_White"
    },
    {
      "x": -2,
      "y": -1,
      "z": -1,
      "name": "Soil_Dirt_White"
    },
    {
      "x": -2,
      "y": 0,
      "z": -1,
      "name": "Soil_Dirt_White"
    },
    {
      "x": -2,
      "y": 1,
      "z": -1,
      "name": "Rock_Marble_Brick"
    },
    {
      "x": -2,
      "y": 2,
      "z": -1,
      "name": "Rock_Marble_Brick_Pillar_Base"
    },
    {
      "x": -2,
      "y": 3,
      "z": -1,
      "name": "Rock_Marble_Brick_Pillar_Middle"
    },
    {
      "x": -2,
      "y": 4,
      "z": -1,
      "name": "Rock_Marble_Brick_Pillar_Middle"
    },
    {
      "x": -2,
      "y": 5,
      "z": -1,
      "name": "Rock_Marble_Brick_Pillar_Middle"
    },
    {
      "x": -2,
      "y": 6,
      "z": -1,
      "name": "Rock_Marble_Brick_Pillar_Base",
      "rotation": 8
    },
    {
      "x": -2,
      "y": 7,
      "z": -1,
      "name": "Rock_Marble_Brick"
    },
    {
      "x": -2,
      "y": 8,
      "z": -1,
      "name": "Rock_Marble_Brick"
    },
    {
      "x": -2,
      "y": 9,
      "z": -1,
      "name": "Rubble_Marble",
      "support": 15
    },
    {
      "x": -2,
      "y": -2,
      "z": 0,
      "name": "Soil_Grass_White"
    },
    {
      "x": -2,
      "y": -1,
      "z": 0,
      "name": "Soil_Dirt_White"
    },
    {
      "x": -2,
      "y": 0,
      "z": 0,
      "name": "Soil_Dirt_White"
    },
    {
      "x": -2,
      "y": 1,
      "z": 0,
      "name": "Rock_Marble_Brick"
    },
    {
      "x": -2,
      "y": 2,
      "z": 0,
      "name": "Rubble_Marble",
      "support": 15
    },
    {
      "x": -2,
      "y": 7,
      "z": 0,
      "name": "Rock_Marble_Brick_Stairs",
      "rotation": 10
    },
    {
      "x": -2,
      "y": 8,
      "z": 0,
      "name": "Rubble_Marble_Medium",
      "support": 15
    },
    {
      "x": -2,
      "y": -2,
      "z": 1,
      "name": "Soil_Grass_White"
    },
    {
      "x": -2,
      "y": -1,
      "z": 1,
      "name": "Soil_Dirt_White"
    },
    {
      "x": -2,
      "y": 0,
      "z": 1,
      "name": "Soil_Dirt_White"
    },
    {
      "x": -2,
      "y": 1,
      "z": 1,
      "name": "Rock_Marble_Brick"
    },
    {
      "x": -2,
      "y": -2,
      "z": 2,
      "name": "Soil_Grass_White"
    },
    {
      "x": -2,
      "y": -1,
      "z": 2,
      "name": "Soil_Dirt_White"
    },
    {
      "x": -2,
      "y": 0,
      "z": 2,
      "name": "Soil_Dirt_White"
    },
    {
      "x": -2,
      "y": 1,
      "z": 2,
      "name": "Rock_Marble_Brick"
    },
    {
      "x": -2,
      "y": 7,
      "z": 2,
      "name": "Rock_Marble_Brick_Stairs",
      "rotation": 8
    },
    {
      "x": -2,
      "y": 8,
      "z": 2,
      "name": "Rock_Marble_Brick_Stairs",
      "rotation": 2
    },
    {
      "x": -2,
      "y": -2,
      "z": 3,
      "name": "Soil_Grass_White"
    },
    {
      "x": -2,
      "y": -1,
      "z": 3,
      "name": "Soil_Dirt_White"
    },
    {
      "x": -2,
      "y": 0,
      "z": 3,
      "name": "Soil_Dirt_White"
    },
    {
      "x": -2,
      "y": 1,
      "z": 3,
      "name": "Rock_Marble_Brick"
    },
    {
      "x": -2,
      "y": 2,
      "z": 3,
      "name": "Rock_Marble_Brick_Pillar_Base"
    },
    {
      "x": -2,
      "y": 3,
      "z": 3,
      "name": "Rock_Marble_Brick_Pillar_Middle"
    },
    {
      "x": -2,
      "y": 4,
      "z": 3,
      "name": "Rock_Marble_Brick_Pillar_Middle"
    },
    {
      "x": -2,
      "y": 5,
      "z": 3,
      "name": "Rock_Marble_Brick_Pillar_Middle"
    },
    {
      "x": -2,
      "y": 6,
      "z": 3,
      "name": "Rock_Marble_Brick_Pillar_Base",
      "rotation": 8
    },
    {
      "x": -2,
      "y": 7,
      "z": 3,
      "name": "Rock_Marble_Brick"
    },
    {
      "x": -2,
      "y": 8,
      "z": 3,
      "name": "Rock_Marble_Brick"
    },
    {
      "x": -2,
      "y": -2,
      "z": 4,
      "name": "Soil_Grass_White"
    },
    {
      "x": -2,
      "y": -1,
      "z": 4,
      "name": "Soil_Grass_Full"
    },
    {
      "x": -2,
      "y": 0,
      "z": 4,
      "name": "Soil_Grass_Full"
    },
    {
      "x": -2,
      "y": 8,
      "z": 4,
      "name": "Rock_Marble_Brick_Half",
      "rotation": 4
    },
    {
      "x": -2,
      "y": -2,
      "z": 5,
      "name": "Soil_Grass_White"
    },
    {
      "x": -2,
      "y": -1,
      "z": 5,
      "name": "Soil_Grass_Full"
    },
    {
      "x": -2,
      "y": 0,
      "z": 5,
      "name": "Soil_Grass_Full"
    },
    {
      "x": -2,
      "y": 1,
      "z": 5,
      "name": "Rock_Marble_Brick_Stairs",
      "rotation": 1
    },
    {
      "x": -2,
      "y": -2,
      "z": 6,
      "name": "Soil_Grass_White"
    },
    {
      "x": -2,
      "y": -1,
      "z": 6,
      "name": "Soil_Grass_Full"
    },
    {
      "x": -2,
      "y": 0,
      "z": 6,
      "name": "Soil_Grass_Full"
    },
    {
      "x": -2,
      "y": 1,
      "z": 6,
      "name": "Rubble_Marble_Medium",
      "support": 15
    },
    {
      "x": -2,
      "y": -2,
      "z": 7,
      "name": "Soil_Grass_White"
    },
    {
      "x": -2,
      "y": -1,
      "z": 7,
      "name": "Soil_Grass_Full"
    },
    {
      "x": -2,
      "y": 0,
      "z": 7,
      "name": "Soil_Grass_Full"
    },
    {
      "x": -2,
      "y": -2,
      "z": 8,
      "name": "Soil_Grass_Full"
    },
    {
      "x": -2,
      "y": -1,
      "z": 8,
      "name": "Soil_Grass_Full"
    },
    {
      "x": -2,
      "y": -2,
      "z": 9,
      "name": "Soil_Grass_Full"
    },
    {
      "x": -1,
      "y": -2,
      "z": -10,
      "name": "Soil_Grass_White"
    },
    {
      "x": -1,
      "y": -1,
      "z": -10,
      "name": "Soil_Grass_White"
    },
    {
      "x": -1,
      "y": -2,
      "z": -9,
      "name": "Soil_Grass_White"
    },
    {
      "x": -1,
      "y": -1,
      "z": -9,
      "name": "Soil_Grass_Full"
    },
    {
      "x": -1,
      "y": 0,
      "z": -9,
      "name": "Soil_Grass_Full"
    },
    {
      "x": -1,
      "y": -2,
      "z": -8,
      "name": "Soil_Grass_White"
    },
    {
      "x": -1,
      "y": -1,
      "z": -8,
      "name": "Soil_Grass_Full"
    },
    {
      "x": -1,
      "y": 0,
      "z": -8,
      "name": "Soil_Grass_Full"
    },
    {
      "x": -1,
      "y": -2,
      "z": -7,
      "name": "Soil_Grass_White"
    },
    {
      "x": -1,
      "y": -1,
      "z": -7,
      "name": "Soil_Grass_Full"
    },
    {
      "x": -1,
      "y": 0,
      "z": -7,
      "name": "Soil_Grass_Full"
    },
    {
      "x": -1,
      "y": -2,
      "z": -6,
      "name": "Soil_Grass_White"
    },
    {
      "x": -1,
      "y": -1,
      "z": -6,
      "name": "Soil_Grass_Full"
    },
    {
      "x": -1,
      "y": 0,
      "z": -6,
      "name": "Soil_Grass_Full"
    },
    {
      "x": -1,
      "y": -2,
      "z": -5,
      "name": "Soil_Grass_White"
    },
    {
      "x": -1,
      "y": -1,
      "z": -5,
      "name": "Soil_Grass_Full"
    },
    {
      "x": -1,
      "y": 0,
      "z": -5,
      "name": "Soil_Grass_Full"
    },
    {
      "x": -1,
      "y": 1,
      "z": -5,
      "name": "Plant_Grass_Lush"
    },
    {
      "x": -1,
      "y": -2,
      "z": -4,
      "name": "Soil_Grass_White"
    },
    {
      "x": -1,
      "y": -1,
      "z": -4,
      "name": "Soil_Grass_Full"
    },
    {
      "x": -1,
      "y": 0,
      "z": -4,
      "name": "Soil_Grass_Full"
    },
    {
      "x": -1,
      "y": -2,
      "z": -3,
      "name": "Soil_Grass_White"
    },
    {
      "x": -1,
      "y": -1,
      "z": -3,
      "name": "Soil_Grass_Full"
    },
    {
      "x": -1,
      "y": 0,
      "z": -3,
      "name": "Soil_Grass_Full"
    },
    {
      "x": -1,
      "y": -2,
      "z": -2,
      "name": "Soil_Grass_White"
    },
    {
      "x": -1,
      "y": -1,
      "z": -2,
      "name": "Soil_Grass_Full"
    },
    {
      "x": -1,
      "y": 0,
      "z": -2,
      "name": "Rock_Marble"
    },
    {
      "x": -1,
      "y": 1,
      "z": -2,
      "name": "Rubble_Marble_Medium",
      "support": 15
    },
    {
      "x": -1,
      "y": -2,
      "z": -1,
      "name": "Soil_Grass_White"
    },
    {
      "x": -1,
      "y": -1,
      "z": -1,
      "name": "Soil_Dirt_White"
    },
    {
      "x": -1,
      "y": 0,
      "z": -1,
      "name": "Soil_Dirt_White"
    },
    {
      "x": -1,
      "y": 1,
      "z": -1,
      "name": "Rock_Marble_Brick"
    },
    {
      "x": -1,
      "y": 2,
      "z": -1,
      "name": "Rubble_Marble_Medium",
      "support": 15
    },
    {
      "x": -1,
      "y": -2,
      "z": 0,
      "name": "Soil_Grass_White"
    },
    {
      "x": -1,
      "y": -1,
      "z": 0,
      "name": "Soil_Dirt_White"
    },
    {
      "x": -1,
      "y": 0,
      "z": 0,
      "name": "Soil_Dirt_White"
    },
    {
      "x": -1,
      "y": 1,
      "z": 0,
      "name": "Rock_Marble"
    },
    {
      "x": -1,
      "y": -2,
      "z": 1,
      "name": "Soil_Grass_White"
    },
    {
      "x": -1,
      "y": -1,
      "z": 1,
      "name": "Soil_Dirt_White"
    },
    {
      "x": -1,
      "y": 0,
      "z": 1,
      "name": "Soil_Dirt_White"
    },
    {
      "x": -1,
      "y": 1,
      "z": 1,
      "name": "Rock_Marble"
    },
    {
      "x": -1,
      "y": -2,
      "z": 2,
      "name": "Soil_Grass_White"
    },
    {
      "x": -1,
      "y": -1,
      "z": 2,
      "name": "Soil_Dirt_White"
    },
    {
      "x": -1,
      "y": 0,
      "z": 2,
      "name": "Soil_Dirt_White"
    },
    {
      "x": -1,
      "y": 1,
      "z": 2,
      "name": "Soil_Pebbles",
      "support": 15
    },
    {
      "x": -1,
      "y": -2,
      "z": 3,
      "name": "Soil_Grass_White"
    },
    {
      "x": -1,
      "y": -1,
      "z": 3,
      "name": "Soil_Dirt_White"
    },
    {
      "x": -1,
      "y": 0,
      "z": 3,
      "name": "Soil_Dirt_White"
    },
    {
      "x": -1,
      "y": 1,
      "z": 3,
      "name": "Soil_Pebbles",
      "support": 15
    },
    {
      "x": -1,
      "y": 7,
      "z": 3,
      "name": "Rock_Marble_Brick_Stairs",
      "rotation": 11
    },
    {
      "x": -1,
      "y": 8,
      "z": 3,
      "name": "Rock_Marble_Brick"
    },
    {
      "x": -1,
      "y": 9,
      "z": 3,
      "name": "Rubble_Marble_Medium",
      "support": 15
    },
    {
      "x": -1,
      "y": -2,
      "z": 4,
      "name": "Soil_Grass_White"
    },
    {
      "x": -1,
      "y": -1,
      "z": 4,
      "name": "Soil_Grass_Full"
    },
    {
      "x": -1,
      "y": 0,
      "z": 4,
      "name": "Soil_Grass_Full"
    },
    {
      "x": -1,
      "y": 1,
      "z": 4,
      "name": "Soil_Marble_Gravel_Half",
      "support": 15
    },
    {
      "x": -1,
      "y": 8,
      "z": 4,
      "name": "Rock_Marble_Brick_Half",
      "rotation": 4
    },
    {
      "x": -1,
      "y": -2,
      "z": 5,
      "name": "Soil_Grass_White"
    },
    {
      "x": -1,
      "y": -1,
      "z": 5,
      "name": "Soil_Grass_Full"
    },
    {
      "x": -1,
      "y": 0,
      "z": 5,
      "name": "Soil_Grass_Full"
    },
    {
      "x": -1,
      "y": 1,
      "z": 5,
      "name": "Plant_Grass_Lush"
    },
    {
      "x": -1,
      "y": -2,
      "z": 6,
      "name": "Soil_Grass_White"
    },
    {
      "x": -1,
      "y": -1,
      "z": 6,
      "name": "Soil_Grass_Full"
    },
    {
      "x": -1,
      "y": 0,
      "z": 6,
      "name": "Soil_Grass_Full"
    },
    {
      "x": -1,
      "y": -2,
      "z": 7,
      "name": "Soil_Grass_Full"
    },
    {
      "x": -1,
      "y": -1,
      "z": 7,
      "name": "Soil_Grass_Full"
    },
    {
      "x": -1,
      "y": 0,
      "z": 7,
      "name": "Soil_Grass_Full"
    },
    {
      "x": -1,
      "y": 1,
      "z": 7,
      "name": "Plant_Flower_Water_Duckweed"
    },
    {
      "x": -1,
      "y": -2,
      "z": 8,
      "name": "Soil_Grass_Full"
    },
    {
      "x": -1,
      "y": -1,
      "z": 8,
      "name": "Soil_Grass_Full"
    },
    {
      "x": -1,
      "y": 0,
      "z": 8,
      "name": "Soil_Grass_Full"
    },
    {
      "x": -1,
      "y": -2,
      "z": 9,
      "name": "Soil_Grass_Full"
    },
    {
      "x": -1,
      "y": -1,
      "z": 9,
      "name": "Soil_Grass_Full"
    },
    {
      "x": 0,
      "y": -2,
      "z": -10,
      "name": "Soil_Grass_White"
    },
    {
      "x": 0,
      "y": -2,
      "z": -9,
      "name": "Soil_Grass_White"
    },
    {
      "x": 0,
      "y": -1,
      "z": -9,
      "name": "Soil_Grass_Full"
    },
    {
      "x": 0,
      "y": -2,
      "z": -8,
      "name": "Soil_Grass_White"
    },
    {
      "x": 0,
      "y": -1,
      "z": -8,
      "name": "Soil_Grass_Full"
    },
    {
      "x": 0,
      "y": 0,
      "z": -8,
      "name": "Soil_Grass_Full"
    },
    {
      "x": 0,
      "y": -2,
      "z": -7,
      "name": "Soil_Grass_White"
    },
    {
      "x": 0,
      "y": -1,
      "z": -7,
      "name": "Soil_Grass_Full"
    },
    {
      "x": 0,
      "y": 0,
      "z": -7,
      "name": "Soil_Grass_Full"
    },
    {
      "x": 0,
      "y": -2,
      "z": -6,
      "name": "Soil_Grass_White"
    },
    {
      "x": 0,
      "y": -1,
      "z": -6,
      "name": "Soil_Grass_Full"
    },
    {
      "x": 0,
      "y": 0,
      "z": -6,
      "name": "Soil_Grass_Full"
    },
    {
      "x": 0,
      "y": -2,
      "z": -5,
      "name": "Soil_Grass_White"
    },
    {
      "x": 0,
      "y": -1,
      "z": -5,
      "name": "Soil_Grass_Full"
    },
    {
      "x": 0,
      "y": 0,
      "z": -5,
      "name": "Soil_Grass_Full"
    },
    {
      "x": 0,
      "y": -2,
      "z": -4,
      "name": "Soil_Grass_White"
    },
    {
      "x": 0,
      "y": -1,
      "z": -4,
      "name": "Soil_Grass_Full"
    },
    {
      "x": 0,
      "y": 0,
      "z": -4,
      "name": "Soil_Grass_Full"
    },
    {
      "x": 0,
      "y": -2,
      "z": -3,
      "name": "Soil_Grass_White"
    },
    {
      "x": 0,
      "y": -1,
      "z": -3,
      "name": "Soil_Grass_Full"
    },
    {
      "x": 0,
      "y": 0,
      "z": -3,
      "name": "Soil_Grass_Full"
    },
    {
      "x": 0,
      "y": 1,
      "z": -3,
      "name": "Plant_Grass_Lush"
    },
    {
      "x": 0,
      "y": -2,
      "z": -2,
      "name": "Soil_Grass_White"
    },
    {
      "x": 0,
      "y": -1,
      "z": -2,
      "name": "Soil_Grass_Full"
    },
    {
      "x": 0,
      "y": 0,
      "z": -2,
      "name": "Soil_Grass_Full"
    },
    {
      "x": 0,
      "y": 1,
      "z": -2,
      "name": "Rock_Marble_Brick_Stairs",
      "rotation": 2
    },
    {
      "x": 0,
      "y": -2,
      "z": -1,
      "name": "Soil_Grass_White"
    },
    {
      "x": 0,
      "y": -1,
      "z": -1,
      "name": "Soil_Dirt_White"
    },
    {
      "x": 0,
      "y": 0,
      "z": -1,
      "name": "Soil_Dirt_White"
    },
    {
      "x": 0,
      "y": 1,
      "z": -1,
      "name": "Rock_Marble"
    },
    {
      "x": 0,
      "y": -2,
      "z": 0,
      "name": "Soil_Grass_White"
    },
    {
      "x": 0,
      "y": -1,
      "z": 0,
      "name": "Soil_Dirt_White"
    },
    {
      "x": 0,
      "y": 0,
      "z": 0,
      "name": "Soil_Dirt_White"
    },
    {
      "x": 0,
      "y": 1,
      "z": 0,
      "name": "Rock_Marble_Brick"
    },
    {
      "x": 0,
      "y": -2,
      "z": 1,
      "name": "Soil_Grass_White"
    },
    {
      "x": 0,
      "y": -1,
      "z": 1,
      "name": "Soil_Dirt_White"
    },
    {
      "x": 0,
      "y": 0,
      "z": 1,
      "name": "Soil_Dirt_White"
    },
    {
      "x": 0,
      "y": 1,
      "z": 1,
      "name": "Rock_Marble_Brick"
    },
    {
      "x": 0,
      "y": 2,
      "z": 1,
      "name": "Block_Spawner_Block",
      "components": {
        "Components": {
          "PlacedByInteraction": {
            "WhoPlacedUuid": {
              "$binary": "+u0Lek23TWiDpMOn5L2LqA==",
              "$type": "04"
            }
          },
          "BlockSpawner": {
            "BlockSpawnerId": "Zone4_Encounters_Tier2"
          }
        }
      },
      "rotation": 1
    },
    {
      "x": 0,
      "y": -2,
      "z": 2,
      "name": "Soil_Grass_White"
    },
    {
      "x": 0,
      "y": -1,
      "z": 2,
      "name": "Soil_Dirt_White"
    },
    {
      "x": 0,
      "y": 0,
      "z": 2,
      "name": "Soil_Dirt_White"
    },
    {
      "x": 0,
      "y": 1,
      "z": 2,
      "name": "Soil_Pebbles",
      "support": 15
    },
    {
      "x": 0,
      "y": -2,
      "z": 3,
      "name": "Soil_Grass_White"
    },
    {
      "x": 0,
      "y": -1,
      "z": 3,
      "name": "Soil_Dirt_White"
    },
    {
      "x": 0,
      "y": 0,
      "z": 3,
      "name": "Soil_Dirt_White"
    },
    {
      "x": 0,
      "y": 1,
      "z": 3,
      "name": "Rock_Marble_Brick"
    },
    {
      "x": 0,
      "y": 2,
      "z": 3,
      "name": "Rock_Marble_Brick_Pillar_Base",
      "rotation": 5
    },
    {
      "x": 0,
      "y": 8,
      "z": 3,
      "name": "Rock_Marble_Brick"
    },
    {
      "x": 0,
      "y": 9,
      "z": 3,
      "name": "Rock_Marble_Brick_Half"
    },
    {
      "x": 0,
      "y": -2,
      "z": 4,
      "name": "Soil_Grass_White"
    },
    {
      "x": 0,
      "y": -1,
      "z": 4,
      "name": "Soil_Grass_Full"
    },
    {
      "x": 0,
      "y": 0,
      "z": 4,
      "name": "Soil_Grass_Full"
    },
    {
      "x": 0,
      "y": 1,
      "z": 4,
      "name": "Rock_Marble_Brick_Stairs"
    },
    {
      "x": 0,
      "y": -2,
      "z": 5,
      "name": "Soil_Grass_White"
    },
    {
      "x": 0,
      "y": -1,
      "z": 5,
      "name": "Soil_Grass_Full"
    },
    {
      "x": 0,
      "y": 0,
      "z": 5,
      "name": "Soil_Grass_Full"
    },
    {
      "x": 0,
      "y": -2,
      "z": 6,
      "name": "Soil_Grass_White"
    },
    {
      "x": 0,
      "y": -1,
      "z": 6,
      "name": "Soil_Grass_Full"
    },
    {
      "x": 0,
      "y": 0,
      "z": 6,
      "name": "Soil_Grass_Full"
    },
    {
      "x": 0,
      "y": -2,
      "z": 7,
      "name": "Soil_Grass_Full"
    },
    {
      "x": 0,
      "y": -1,
      "z": 7,
      "name": "Soil_Grass_Full"
    },
    {
      "x": 0,
      "y": 0,
      "z": 7,
      "name": "Soil_Grass_Full"
    },
    {
      "x": 0,
      "y": 1,
      "z": 7,
      "name": "Plant_Grass_Lush"
    },
    {
      "x": 0,
      "y": -2,
      "z": 8,
      "name": "Soil_Grass_Full"
    },
    {
      "x": 0,
      "y": -1,
      "z": 8,
      "name": "Soil_Grass_Full"
    },
    {
      "x": 0,
      "y": 0,
      "z": 8,
      "name": "Soil_Grass_Full"
    },
    {
      "x": 0,
      "y": -2,
      "z": 9,
      "name": "Soil_Grass_Full"
    },
    {
      "x": 0,
      "y": -1,
      "z": 9,
      "name": "Soil_Grass_Full"
    },
    {
      "x": 1,
      "y": -2,
      "z": -9,
      "name": "Soil_Grass_White"
    },
    {
      "x": 1,
      "y": -1,
      "z": -9,
      "name": "Soil_Grass_Full"
    },
    {
      "x": 1,
      "y": -2,
      "z": -8,
      "name": "Soil_Grass_White"
    },
    {
      "x": 1,
      "y": -1,
      "z": -8,
      "name": "Soil_Grass_Full"
    },
    {
      "x": 1,
      "y": 0,
      "z": -8,
      "name": "Soil_Grass_Full"
    },
    {
      "x": 1,
      "y": -2,
      "z": -7,
      "name": "Soil_Grass_White"
    },
    {
      "x": 1,
      "y": -1,
      "z": -7,
      "name": "Soil_Grass_Full"
    },
    {
      "x": 1,
      "y": 0,
      "z": -7,
      "name": "Soil_Grass_Full"
    },
    {
      "x": 1,
      "y": 1,
      "z": -7,
      "name": "Plant_Grass_Lush_Short"
    },
    {
      "x": 1,
      "y": -2,
      "z": -6,
      "name": "Soil_Grass_White"
    },
    {
      "x": 1,
      "y": -1,
      "z": -6,
      "name": "Soil_Grass_Full"
    },
    {
      "x": 1,
      "y": 0,
      "z": -6,
      "name": "Soil_Grass_Full"
    },
    {
      "x": 1,
      "y": 1,
      "z": -6,
      "name": "Plant_Grass_Lush_Short"
    },
    {
      "x": 1,
      "y": -2,
      "z": -5,
      "name": "Soil_Grass_White"
    },
    {
      "x": 1,
      "y": -1,
      "z": -5,
      "name": "Soil_Grass_Full"
    },
    {
      "x": 1,
      "y": 0,
      "z": -5,
      "name": "Soil_Grass_Full"
    },
    {
      "x": 1,
      "y": 1,
      "z": -5,
      "name": "Plant_Grass_Lush_Short"
    },
    {
      "x": 1,
      "y": -2,
      "z": -4,
      "name": "Soil_Grass_White"
    },
    {
      "x": 1,
      "y": -1,
      "z": -4,
      "name": "Soil_Grass_Full"
    },
    {
      "x": 1,
      "y": 0,
      "z": -4,
      "name": "Soil_Grass_Full"
    },
    {
      "x": 1,
      "y": 1,
      "z": -4,
      "name": "Plant_Grass_Lush"
    },
    {
      "x": 1,
      "y": -2,
      "z": -3,
      "name": "Soil_Grass_White"
    },
    {
      "x": 1,
      "y": -1,
      "z": -3,
      "name": "Soil_Grass_Full"
    },
    {
      "x": 1,
      "y": 0,
      "z": -3,
      "name": "Soil_Pebbles",
      "support": 15
    },
    {
      "x": 1,
      "y": -2,
      "z": -2,
      "name": "Soil_Grass_White"
    },
    {
      "x": 1,
      "y": -1,
      "z": -2,
      "name": "Soil_Grass_Full"
    },
    {
      "x": 1,
      "y": 0,
      "z": -2,
      "name": "Soil_Grass_Full"
    },
    {
      "x": 1,
      "y": 1,
      "z": -2,
      "name": "Rock_Marble_Brick_Stairs",
      "rotation": 2
    },
    {
      "x": 1,
      "y": -2,
      "z": -1,
      "name": "Soil_Grass_White"
    },
    {
      "x": 1,
      "y": -1,
      "z": -1,
      "name": "Soil_Dirt_White"
    },
    {
      "x": 1,
      "y": 0,
      "z": -1,
      "name": "Soil_Dirt_White"
    },
    {
      "x": 1,
      "y": 1,
      "z": -1,
      "name": "Rock_Marble_Brick"
    },
    {
      "x": 1,
      "y": -2,
      "z": 0,
      "name": "Soil_Grass_White"
    },
    {
      "x": 1,
      "y": -1,
      "z": 0,
      "name": "Soil_Dirt_White"
    },
    {
      "x": 1,
      "y": 0,
      "z": 0,
      "name": "Soil_Dirt_White"
    },
    {
      "x": 1,
      "y": 1,
      "z": 0,
      "name": "Rock_Marble_Brick"
    },
    {
      "x": 1,
      "y": -2,
      "z": 1,
      "name": "Soil_Grass_White"
    },
    {
      "x": 1,
      "y": -1,
      "z": 1,
      "name": "Soil_Dirt_White"
    },
    {
      "x": 1,
      "y": 0,
      "z": 1,
      "name": "Soil_Dirt_White"
    },
    {
      "x": 1,
      "y": 1,
      "z": 1,
      "name": "Rock_Marble_Brick"
    },
    {
      "x": 1,
      "y": -2,
      "z": 2,
      "name": "Soil_Grass_White"
    },
    {
      "x": 1,
      "y": -1,
      "z": 2,
      "name": "Soil_Dirt_White"
    },
    {
      "x": 1,
      "y": 0,
      "z": 2,
      "name": "Soil_Dirt_White"
    },
    {
      "x": 1,
      "y": 1,
      "z": 2,
      "name": "Rock_Marble_Brick"
    },
    {
      "x": 1,
      "y": -2,
      "z": 3,
      "name": "Soil_Grass_White"
    },
    {
      "x": 1,
      "y": -1,
      "z": 3,
      "name": "Soil_Dirt_White"
    },
    {
      "x": 1,
      "y": 0,
      "z": 3,
      "name": "Soil_Dirt_White"
    },
    {
      "x": 1,
      "y": 1,
      "z": 3,
      "name": "Rock_Marble_Brick"
    },
    {
      "x": 1,
      "y": 2,
      "z": 3,
      "name": "Rubble_Marble",
      "support": 15
    },
    {
      "x": 1,
      "y": -2,
      "z": 4,
      "name": "Soil_Grass_White"
    },
    {
      "x": 1,
      "y": -1,
      "z": 4,
      "name": "Soil_Grass_Full"
    },
    {
      "x": 1,
      "y": 0,
      "z": 4,
      "name": "Soil_Grass_Full"
    },
    {
      "x": 1,
      "y": 1,
      "z": 4,
      "name": "Rock_Marble_Brick_Stairs"
    },
    {
      "x": 1,
      "y": -2,
      "z": 5,
      "name": "Soil_Grass_White"
    },
    {
      "x": 1,
      "y": -1,
      "z": 5,
      "name": "Soil_Grass_Full"
    },
    {
      "x": 1,
      "y": 0,
      "z": 5,
      "name": "Soil_Grass_Full"
    },
    {
      "x": 1,
      "y": 1,
      "z": 5,
      "name": "Plant_Grass_Lush"
    },
    {
      "x": 1,
      "y": -2,
      "z": 6,
      "name": "Soil_Grass_Full"
    },
    {
      "x": 1,
      "y": -1,
      "z": 6,
      "name": "Soil_Grass_Full"
    },
    {
      "x": 1,
      "y": 0,
      "z": 6,
      "name": "Soil_Grass_Full"
    },
    {
      "x": 1,
      "y": 1,
      "z": 6,
      "name": "Plant_Grass_Lush"
    },
    {
      "x": 1,
      "y": -2,
      "z": 7,
      "name": "Soil_Grass_Full"
    },
    {
      "x": 1,
      "y": -1,
      "z": 7,
      "name": "Soil_Grass_Full"
    },
    {
      "x": 1,
      "y": 0,
      "z": 7,
      "name": "Soil_Grass_Full"
    },
    {
      "x": 1,
      "y": -2,
      "z": 8,
      "name": "Soil_Grass_Full"
    },
    {
      "x": 1,
      "y": -1,
      "z": 8,
      "name": "Soil_Grass_Full"
    },
    {
      "x": 1,
      "y": -2,
      "z": 9,
      "name": "Soil_Grass_Full"
    },
    {
      "x": 2,
      "y": -2,
      "z": -9,
      "name": "Soil_Grass_White"
    },
    {
      "x": 2,
      "y": -1,
      "z": -9,
      "name": "Soil_Grass_Full"
    },
    {
      "x": 2,
      "y": -2,
      "z": -8,
      "name": "Soil_Grass_White"
    },
    {
      "x": 2,
      "y": -1,
      "z": -8,
      "name": "Soil_Grass_Full"
    },
    {
      "x": 2,
      "y": 0,
      "z": -8,
      "name": "Soil_Grass_Full"
    },
    {
      "x": 2,
      "y": -2,
      "z": -7,
      "name": "Soil_Grass_White"
    },
    {
      "x": 2,
      "y": -1,
      "z": -7,
      "name": "Soil_Grass_Full"
    },
    {
      "x": 2,
      "y": 0,
      "z": -7,
      "name": "Soil_Grass_Full"
    },
    {
      "x": 2,
      "y": -2,
      "z": -6,
      "name": "Soil_Grass_White"
    },
    {
      "x": 2,
      "y": -1,
      "z": -6,
      "name": "Soil_Grass_Full"
    },
    {
      "x": 2,
      "y": 0,
      "z": -6,
      "name": "Soil_Grass_Full"
    },
    {
      "x": 2,
      "y": -2,
      "z": -5,
      "name": "Soil_Grass_White"
    },
    {
      "x": 2,
      "y": -1,
      "z": -5,
      "name": "Soil_Grass_Full"
    },
    {
      "x": 2,
      "y": 0,
      "z": -5,
      "name": "Soil_Grass_Full"
    },
    {
      "x": 2,
      "y": -2,
      "z": -4,
      "name": "Soil_Grass_White"
    },
    {
      "x": 2,
      "y": -1,
      "z": -4,
      "name": "Soil_Grass_Full"
    },
    {
      "x": 2,
      "y": 0,
      "z": -4,
      "name": "Soil_Grass_Full"
    },
    {
      "x": 2,
      "y": 1,
      "z": -4,
      "name": "Rock_Marble_Brick_Pillar_Base",
      "rotation": 4
    },
    {
      "x": 2,
      "y": -2,
      "z": -3,
      "name": "Soil_Grass_White"
    },
    {
      "x": 2,
      "y": -1,
      "z": -3,
      "name": "Soil_Pebbles"
    },
    {
      "x": 2,
      "y": 0,
      "z": -3,
      "name": "Soil_Pebbles",
      "support": 15
    },
    {
      "x": 2,
      "y": 1,
      "z": -3,
      "name": "Rock_Marble_Brick_Pillar_Middle",
      "rotation": 4
    },
    {
      "x": 2,
      "y": -2,
      "z": -2,
      "name": "Soil_Grass_White"
    },
    {
      "x": 2,
      "y": -1,
      "z": -2,
      "name": "Soil_Pebbles"
    },
    {
      "x": 2,
      "y": 0,
      "z": -2,
      "name": "Soil_Pebbles",
      "support": 15
    },
    {
      "x": 2,
      "y": 1,
      "z": -2,
      "name": "Rubble_Marble_Medium",
      "support": 15
    },
    {
      "x": 2,
      "y": -2,
      "z": -1,
      "name": "Soil_Grass_White"
    },
    {
      "x": 2,
      "y": -1,
      "z": -1,
      "name": "Soil_Dirt_White"
    },
    {
      "x": 2,
      "y": 0,
      "z": -1,
      "name": "Soil_Dirt_White"
    },
    {
      "x": 2,
      "y": 1,
      "z": -1,
      "name": "Rock_Marble_Brick"
    },
    {
      "x": 2,
      "y": 2,
      "z": -1,
      "name": "Rock_Marble_Brick_Pillar_Base"
    },
    {
      "x": 2,
      "y": 3,
      "z": -1,
      "name": "Rock_Marble_Brick_Pillar_Middle"
    },
    {
      "x": 2,
      "y": 4,
      "z": -1,
      "name": "Rubble_Marble",
      "support": 15
    },
    {
      "x": 2,
      "y": -2,
      "z": 0,
      "name": "Soil_Grass_White"
    },
    {
      "x": 2,
      "y": -1,
      "z": 0,
      "name": "Soil_Dirt_White"
    },
    {
      "x": 2,
      "y": 0,
      "z": 0,
      "name": "Soil_Dirt_White"
    },
    {
      "x": 2,
      "y": 1,
      "z": 0,
      "name": "Rock_Marble_Brick"
    },
    {
      "x": 2,
      "y": -2,
      "z": 1,
      "name": "Soil_Grass_White"
    },
    {
      "x": 2,
      "y": -1,
      "z": 1,
      "name": "Soil_Dirt_White"
    },
    {
      "x": 2,
      "y": 0,
      "z": 1,
      "name": "Soil_Dirt_White"
    },
    {
      "x": 2,
      "y": 1,
      "z": 1,
      "name": "Rock_Marble_Brick"
    },
    {
      "x": 2,
      "y": -2,
      "z": 2,
      "name": "Soil_Grass_White"
    },
    {
      "x": 2,
      "y": -1,
      "z": 2,
      "name": "Soil_Dirt_White"
    },
    {
      "x": 2,
      "y": 0,
      "z": 2,
      "name": "Soil_Dirt_White"
    },
    {
      "x": 2,
      "y": 1,
      "z": 2,
      "name": "Rock_Marble_Brick"
    },
    {
      "x": 2,
      "y": -2,
      "z": 3,
      "name": "Soil_Grass_White"
    },
    {
      "x": 2,
      "y": -1,
      "z": 3,
      "name": "Soil_Dirt_White"
    },
    {
      "x": 2,
      "y": 0,
      "z": 3,
      "name": "Soil_Dirt_White"
    },
    {
      "x": 2,
      "y": 1,
      "z": 3,
      "name": "Rock_Marble_Brick"
    },
    {
      "x": 2,
      "y": 2,
      "z": 3,
      "name": "Rock_Marble_Brick_Pillar_Base"
    },
    {
      "x": 2,
      "y": 3,
      "z": 3,
      "name": "Rock_Marble_Brick_Pillar_Middle"
    },
    {
      "x": 2,
      "y": 4,
      "z": 3,
      "name": "Rock_Marble_Brick_Pillar_Middle"
    },
    {
      "x": 2,
      "y": 5,
      "z": 3,
      "name": "Rock_Marble_Brick_Pillar_Middle"
    },
    {
      "x": 2,
      "y": -2,
      "z": 4,
      "name": "Soil_Grass_White"
    },
    {
      "x": 2,
      "y": -1,
      "z": 4,
      "name": "Soil_Grass_Full"
    },
    {
      "x": 2,
      "y": 0,
      "z": 4,
      "name": "Soil_Grass_Full"
    },
    {
      "x": 2,
      "y": -2,
      "z": 5,
      "name": "Soil_Grass_Full"
    },
    {
      "x": 2,
      "y": -1,
      "z": 5,
      "name": "Soil_Grass_Full"
    },
    {
      "x": 2,
      "y": 0,
      "z": 5,
      "name": "Soil_Grass_Full"
    },
    {
      "x": 2,
      "y": -2,
      "z": 6,
      "name": "Soil_Grass_Full"
    },
    {
      "x": 2,
      "y": -1,
      "z": 6,
      "name": "Soil_Grass_Full"
    },
    {
      "x": 2,
      "y": 0,
      "z": 6,
      "name": "Soil_Grass_Full"
    },
    {
      "x": 2,
      "y": -2,
      "z": 7,
      "name": "Soil_Grass_Full"
    },
    {
      "x": 2,
      "y": -1,
      "z": 7,
      "name": "Soil_Grass_Full"
    },
    {
      "x": 2,
      "y": -2,
      "z": 8,
      "name": "Soil_Grass_Full"
    },
    {
      "x": 2,
      "y": -1,
      "z": 8,
      "name": "Soil_Grass_Full"
    },
    {
      "x": 2,
      "y": -2,
      "z": 9,
      "name": "Soil_Grass_Full"
    },
    {
      "x": 3,
      "y": -2,
      "z": -9,
      "name": "Soil_Grass_White"
    },
    {
      "x": 3,
      "y": -1,
      "z": -9,
      "name": "Soil_Grass_Full"
    },
    {
      "x": 3,
      "y": -2,
      "z": -8,
      "name": "Soil_Grass_Full"
    },
    {
      "x": 3,
      "y": -1,
      "z": -8,
      "name": "Soil_Grass_Full"
    },
    {
      "x": 3,
      "y": 0,
      "z": -8,
      "name": "Soil_Grass_Full"
    },
    {
      "x": 3,
      "y": -2,
      "z": -7,
      "name": "Soil_Grass_White"
    },
    {
      "x": 3,
      "y": -1,
      "z": -7,
      "name": "Soil_Grass_Full"
    },
    {
      "x": 3,
      "y": 0,
      "z": -7,
      "name": "Soil_Grass_Full"
    },
    {
      "x": 3,
      "y": 1,
      "z": -7,
      "name": "Plant_Fern_Wet_Big"
    },
    {
      "x": 3,
      "y": -2,
      "z": -6,
      "name": "Soil_Grass_White"
    },
    {
      "x": 3,
      "y": -1,
      "z": -6,
      "name": "Soil_Grass_Full"
    },
    {
      "x": 3,
      "y": 0,
      "z": -6,
      "name": "Soil_Grass_Full"
    },
    {
      "x": 3,
      "y": -2,
      "z": -5,
      "name": "Soil_Grass_White"
    },
    {
      "x": 3,
      "y": -1,
      "z": -5,
      "name": "Soil_Grass_Full"
    },
    {
      "x": 3,
      "y": 0,
      "z": -5,
      "name": "Soil_Grass_Full"
    },
    {
      "x": 3,
      "y": 1,
      "z": -5,
      "name": "Plant_Grass_Lush_Short"
    },
    {
      "x": 3,
      "y": -2,
      "z": -4,
      "name": "Soil_Grass_White"
    },
    {
      "x": 3,
      "y": -1,
      "z": -4,
      "name": "Soil_Grass_Full"
    },
    {
      "x": 3,
      "y": 0,
      "z": -4,
      "name": "Soil_Grass_Full"
    },
    {
      "x": 3,
      "y": -2,
      "z": -3,
      "name": "Soil_Grass_White"
    },
    {
      "x": 3,
      "y": -1,
      "z": -3,
      "name": "Soil_Pebbles"
    },
    {
      "x": 3,
      "y": 0,
      "z": -3,
      "name": "Soil_Grass_Full"
    },
    {
      "x": 3,
      "y": 1,
      "z": -3,
      "name": "Plant_Grass_Lush"
    },
    {
      "x": 3,
      "y": -2,
      "z": -2,
      "name": "Soil_Grass_White"
    },
    {
      "x": 3,
      "y": -1,
      "z": -2,
      "name": "Soil_Pebbles"
    },
    {
      "x": 3,
      "y": 0,
      "z": -2,
      "name": "Soil_Pebbles",
      "support": 15
    },
    {
      "x": 3,
      "y": -2,
      "z": -1,
      "name": "Soil_Grass_White"
    },
    {
      "x": 3,
      "y": -1,
      "z": -1,
      "name": "Soil_Grass_Full"
    },
    {
      "x": 3,
      "y": 0,
      "z": -1,
      "name": "Soil_Grass_Full"
    },
    {
      "x": 3,
      "y": -2,
      "z": 0,
      "name": "Soil_Grass_White"
    },
    {
      "x": 3,
      "y": -1,
      "z": 0,
      "name": "Soil_Grass_Full"
    },
    {
      "x": 3,
      "y": 0,
      "z": 0,
      "name": "Soil_Grass_Full"
    },
    {
      "x": 3,
      "y": 1,
      "z": 0,
      "name": "Rock_Marble_Brick_Stairs",
      "rotation": 1
    },
    {
      "x": 3,
      "y": -2,
      "z": 1,
      "name": "Soil_Grass_White"
    },
    {
      "x": 3,
      "y": -1,
      "z": 1,
      "name": "Soil_Grass_Full"
    },
    {
      "x": 3,
      "y": 0,
      "z": 1,
      "name": "Soil_Grass_Full"
    },
    {
      "x": 3,
      "y": 1,
      "z": 1,
      "name": "Rock_Marble_Brick_Stairs",
      "rotation": 1
    },
    {
      "x": 3,
      "y": -2,
      "z": 2,
      "name": "Soil_Grass_White"
    },
    {
      "x": 3,
      "y": -1,
      "z": 2,
      "name": "Soil_Grass_Full"
    },
    {
      "x": 3,
      "y": 0,
      "z": 2,
      "name": "Soil_Grass_Full"
    },
    {
      "x": 3,
      "y": 1,
      "z": 2,
      "name": "Rubble_Marble_Medium",
      "support": 15
    },
    {
      "x": 3,
      "y": -2,
      "z": 3,
      "name": "Soil_Grass_Full"
    },
    {
      "x": 3,
      "y": -1,
      "z": 3,
      "name": "Soil_Grass_Full"
    },
    {
      "x": 3,
      "y": 0,
      "z": 3,
      "name": "Soil_Grass_Full"
    },
    {
      "x": 3,
      "y": -2,
      "z": 4,
      "name": "Soil_Grass_Full"
    },
    {
      "x": 3,
      "y": -1,
      "z": 4,
      "name": "Soil_Grass_Full"
    },
    {
      "x": 3,
      "y": 0,
      "z": 4,
      "name": "Soil_Grass_Full"
    },
    {
      "x": 3,
      "y": -2,
      "z": 5,
      "name": "Soil_Grass_Full"
    },
    {
      "x": 3,
      "y": -1,
      "z": 5,
      "name": "Soil_Grass_Full"
    },
    {
      "x": 3,
      "y": 0,
      "z": 5,
      "name": "Soil_Grass_Full"
    },
    {
      "x": 3,
      "y": -2,
      "z": 6,
      "name": "Soil_Grass_Full"
    },
    {
      "x": 3,
      "y": -1,
      "z": 6,
      "name": "Soil_Grass_Full"
    },
    {
      "x": 3,
      "y": -2,
      "z": 7,
      "name": "Soil_Grass_Full"
    },
    {
      "x": 3,
      "y": -1,
      "z": 7,
      "name": "Soil_Grass_Full"
    },
    {
      "x": 3,
      "y": -2,
      "z": 8,
      "name": "Soil_Grass_Full"
    },
    {
      "x": 4,
      "y": -2,
      "z": -9,
      "name": "Soil_Grass_Full"
    },
    {
      "x": 4,
      "y": -1,
      "z": -9,
      "name": "Soil_Grass_Full"
    },
    {
      "x": 4,
      "y": -2,
      "z": -8,
      "name": "Soil_Grass_Full"
    },
    {
      "x": 4,
      "y": -1,
      "z": -8,
      "name": "Soil_Grass_Full"
    },
    {
      "x": 4,
      "y": 0,
      "z": -8,
      "name": "Soil_Grass_Full"
    },
    {
      "x": 4,
      "y": -2,
      "z": -7,
      "name": "Soil_Grass_Full"
    },
    {
      "x": 4,
      "y": -1,
      "z": -7,
      "name": "Soil_Grass_Full"
    },
    {
      "x": 4,
      "y": 0,
      "z": -7,
      "name": "Soil_Grass_Sunny_Full"
    },
    {
      "x": 4,
      "y": 1,
      "z": -7,
      "name": "Plant_Fern_Wet_Big"
    },
    {
      "x": 4,
      "y": -2,
      "z": -6,
      "name": "Soil_Grass_White"
    },
    {
      "x": 4,
      "y": -1,
      "z": -6,
      "name": "Soil_Grass_Full"
    },
    {
      "x": 4,
      "y": 0,
      "z": -6,
      "name": "Soil_Grass_Sunny_Full"
    },
    {
      "x": 4,
      "y": -2,
      "z": -5,
      "name": "Soil_Grass_White"
    },
    {
      "x": 4,
      "y": -1,
      "z": -5,
      "name": "Soil_Grass_Full"
    },
    {
      "x": 4,
      "y": 0,
      "z": -5,
      "name": "Soil_Grass_Sunny_Full"
    },
    {
      "x": 4,
      "y": -2,
      "z": -4,
      "name": "Soil_Grass_White"
    },
    {
      "x": 4,
      "y": -1,
      "z": -4,
      "name": "Soil_Grass_Full"
    },
    {
      "x": 4,
      "y": 0,
      "z": -4,
      "name": "Soil_Grass_Sunny_Full"
    },
    {
      "x": 4,
      "y": -2,
      "z": -3,
      "name": "Soil_Grass_White"
    },
    {
      "x": 4,
      "y": -1,
      "z": -3,
      "name": "Soil_Pebbles"
    },
    {
      "x": 4,
      "y": 0,
      "z": -3,
      "name": "Soil_Pebbles",
      "support": 15
    },
    {
      "x": 4,
      "y": -2,
      "z": -2,
      "name": "Soil_Grass_White"
    },
    {
      "x": 4,
      "y": -1,
      "z": -2,
      "name": "Soil_Pebbles"
    },
    {
      "x": 4,
      "y": 0,
      "z": -2,
      "name": "Soil_Pebbles",
      "support": 15
    },
    {
      "x": 4,
      "y": -2,
      "z": -1,
      "name": "Soil_Grass_White"
    },
    {
      "x": 4,
      "y": -1,
      "z": -1,
      "name": "Soil_Grass_Full"
    },
    {
      "x": 4,
      "y": 0,
      "z": -1,
      "name": "Rock_Marble"
    },
    {
      "x": 4,
      "y": -2,
      "z": 0,
      "name": "Soil_Grass_Full"
    },
    {
      "x": 4,
      "y": -1,
      "z": 0,
      "name": "Soil_Grass_Full"
    },
    {
      "x": 4,
      "y": 0,
      "z": 0,
      "name": "Soil_Grass_Full"
    },
    {
      "x": 4,
      "y": -2,
      "z": 1,
      "name": "Soil_Grass_Full"
    },
    {
      "x": 4,
      "y": -1,
      "z": 1,
      "name": "Soil_Grass_Full"
    },
    {
      "x": 4,
      "y": 0,
      "z": 1,
      "name": "Soil_Grass_Full"
    },
    {
      "x": 4,
      "y": -2,
      "z": 2,
      "name": "Soil_Grass_Full"
    },
    {
      "x": 4,
      "y": -1,
      "z": 2,
      "name": "Soil_Grass_Full"
    },
    {
      "x": 4,
      "y": 0,
      "z": 2,
      "name": "Soil_Grass_Full"
    },
    {
      "x": 4,
      "y": 1,
      "z": 2,
      "name": "Plant_Grass_Sharp"
    },
    {
      "x": 4,
      "y": -2,
      "z": 3,
      "name": "Soil_Grass_Full"
    },
    {
      "x": 4,
      "y": -1,
      "z": 3,
      "name": "Soil_Grass_Full"
    },
    {
      "x": 4,
      "y": 0,
      "z": 3,
      "name": "Soil_Grass_Full"
    },
    {
      "x": 4,
      "y": 1,
      "z": 3,
      "name": "Plant_Grass_Sharp"
    },
    {
      "x": 4,
      "y": -2,
      "z": 4,
      "name": "Soil_Grass_Full"
    },
    {
      "x": 4,
      "y": -1,
      "z": 4,
      "name": "Soil_Grass_Full"
    },
    {
      "x": 4,
      "y": 0,
      "z": 4,
      "name": "Soil_Grass_Full"
    },
    {
      "x": 4,
      "y": -2,
      "z": 5,
      "name": "Soil_Grass_Full"
    },
    {
      "x": 4,
      "y": -1,
      "z": 5,
      "name": "Soil_Grass_Full"
    },
    {
      "x": 4,
      "y": 0,
      "z": 5,
      "name": "Soil_Grass_Full"
    },
    {
      "x": 4,
      "y": -2,
      "z": 6,
      "name": "Soil_Grass_Full"
    },
    {
      "x": 4,
      "y": -1,
      "z": 6,
      "name": "Soil_Grass_Full"
    },
    {
      "x": 4,
      "y": -2,
      "z": 7,
      "name": "Soil_Grass_Full"
    },
    {
      "x": 5,
      "y": -2,
      "z": -9,
      "name": "Soil_Grass_Full"
    },
    {
      "x": 5,
      "y": -1,
      "z": -9,
      "name": "Soil_Grass_Full"
    },
    {
      "x": 5,
      "y": -2,
      "z": -8,
      "name": "Soil_Grass_Full"
    },
    {
      "x": 5,
      "y": -1,
      "z": -8,
      "name": "Soil_Grass_Full"
    },
    {
      "x": 5,
      "y": 0,
      "z": -8,
      "name": "Soil_Grass_Full"
    },
    {
      "x": 5,
      "y": -2,
      "z": -7,
      "name": "Soil_Grass_Full"
    },
    {
      "x": 5,
      "y": -1,
      "z": -7,
      "name": "Soil_Grass_Full"
    },
    {
      "x": 5,
      "y": 0,
      "z": -7,
      "name": "Soil_Grass_Full"
    },
    {
      "x": 5,
      "y": -2,
      "z": -6,
      "name": "Soil_Grass_Full"
    },
    {
      "x": 5,
      "y": -1,
      "z": -6,
      "name": "Soil_Grass_Full"
    },
    {
      "x": 5,
      "y": 0,
      "z": -6,
      "name": "Soil_Grass_Full"
    },
    {
      "x": 5,
      "y": -2,
      "z": -5,
      "name": "Soil_Grass_Full"
    },
    {
      "x": 5,
      "y": -1,
      "z": -5,
      "name": "Soil_Grass_Full"
    },
    {
      "x": 5,
      "y": 0,
      "z": -5,
      "name": "Soil_Grass_Full"
    },
    {
      "x": 5,
      "y": 1,
      "z": -5,
      "name": "Plant_Grass_Lush_Short"
    },
    {
      "x": 5,
      "y": -2,
      "z": -4,
      "name": "Soil_Grass_Full"
    },
    {
      "x": 5,
      "y": -1,
      "z": -4,
      "name": "Soil_Grass_Full"
    },
    {
      "x": 5,
      "y": 0,
      "z": -4,
      "name": "Soil_Grass_Full"
    },
    {
      "x": 5,
      "y": 1,
      "z": -4,
      "name": "Plant_Grass_Lush"
    },
    {
      "x": 5,
      "y": -2,
      "z": -3,
      "name": "Soil_Grass_White"
    },
    {
      "x": 5,
      "y": -1,
      "z": -3,
      "name": "Soil_Pebbles"
    },
    {
      "x": 5,
      "y": 0,
      "z": -3,
      "name": "Soil_Pebbles",
      "support": 15
    },
    {
      "x": 5,
      "y": -2,
      "z": -2,
      "name": "Soil_Grass_White"
    },
    {
      "x": 5,
      "y": -1,
      "z": -2,
      "name": "Soil_Pebbles"
    },
    {
      "x": 5,
      "y": 0,
      "z": -2,
      "name": "Soil_Pebbles",
      "support": 15
    },
    {
      "x": 5,
      "y": -2,
      "z": -1,
      "name": "Soil_Grass_Full"
    },
    {
      "x": 5,
      "y": -1,
      "z": -1,
      "name": "Rock_Marble"
    },
    {
      "x": 5,
      "y": 0,
      "z": -1,
      "name": "Rock_Marble"
    },
    {
      "x": 5,
      "y": -2,
      "z": 0,
      "name": "Soil_Grass_Full"
    },
    {
      "x": 5,
      "y": -1,
      "z": 0,
      "name": "Soil_Grass_Full"
    },
    {
      "x": 5,
      "y": 0,
      "z": 0,
      "name": "Soil_Grass_Full"
    },
    {
      "x": 5,
      "y": 1,
      "z": 0,
      "name": "Plant_Grass_Sharp"
    },
    {
      "x": 5,
      "y": -2,
      "z": 1,
      "name": "Soil_Grass_Full"
    },
    {
      "x": 5,
      "y": -1,
      "z": 1,
      "name": "Soil_Grass_Full"
    },
    {
      "x": 5,
      "y": 0,
      "z": 1,
      "name": "Soil_Grass_Full"
    },
    {
      "x": 5,
      "y": 1,
      "z": 1,
      "name": "Plant_Grass_Sharp"
    },
    {
      "x": 5,
      "y": -2,
      "z": 2,
      "name": "Soil_Grass_Full"
    },
    {
      "x": 5,
      "y": -1,
      "z": 2,
      "name": "Soil_Grass_Full"
    },
    {
      "x": 5,
      "y": 0,
      "z": 2,
      "name": "Soil_Grass_Full"
    },
    {
      "x": 5,
      "y": -2,
      "z": 3,
      "name": "Soil_Grass_Full"
    },
    {
      "x": 5,
      "y": -1,
      "z": 3,
      "name": "Soil_Grass_Full"
    },
    {
      "x": 5,
      "y": 0,
      "z": 3,
      "name": "Soil_Grass_Full"
    },
    {
      "x": 5,
      "y": 1,
      "z": 3,
      "name": "Plant_Grass_Sharp"
    },
    {
      "x": 5,
      "y": -2,
      "z": 4,
      "name": "Soil_Grass_Full"
    },
    {
      "x": 5,
      "y": -1,
      "z": 4,
      "name": "Soil_Grass_Full"
    },
    {
      "x": 5,
      "y": 0,
      "z": 4,
      "name": "Soil_Grass_Full"
    },
    {
      "x": 5,
      "y": -2,
      "z": 5,
      "name": "Soil_Grass_Full"
    },
    {
      "x": 5,
      "y": -1,
      "z": 5,
      "name": "Soil_Grass_Full"
    },
    {
      "x": 5,
      "y": 0,
      "z": 5,
      "name": "Soil_Grass_Full"
    },
    {
      "x": 5,
      "y": -2,
      "z": 6,
      "name": "Soil_Grass_Full"
    },
    {
      "x": 5,
      "y": -1,
      "z": 6,
      "name": "Soil_Grass_Full"
    },
    {
      "x": 5,
      "y": -2,
      "z": 7,
      "name": "Soil_Grass_Full"
    },
    {
      "x": 6,
      "y": -2,
      "z": -9,
      "name": "Soil_Grass_Full"
    },
    {
      "x": 6,
      "y": -2,
      "z": -8,
      "name": "Soil_Grass_Full"
    },
    {
      "x": 6,
      "y": -1,
      "z": -8,
      "name": "Soil_Grass_Full"
    },
    {
      "x": 6,
      "y": -2,
      "z": -7,
      "name": "Soil_Grass_Full"
    },
    {
      "x": 6,
      "y": -1,
      "z": -7,
      "name": "Soil_Grass_Full"
    },
    {
      "x": 6,
      "y": 0,
      "z": -7,
      "name": "Soil_Grass_Full"
    },
    {
      "x": 6,
      "y": -2,
      "z": -6,
      "name": "Soil_Grass_Full"
    },
    {
      "x": 6,
      "y": -1,
      "z": -6,
      "name": "Soil_Grass_Full"
    },
    {
      "x": 6,
      "y": 0,
      "z": -6,
      "name": "Soil_Grass_Full"
    },
    {
      "x": 6,
      "y": -2,
      "z": -5,
      "name": "Soil_Grass_Full"
    },
    {
      "x": 6,
      "y": -1,
      "z": -5,
      "name": "Soil_Grass_Full"
    },
    {
      "x": 6,
      "y": 0,
      "z": -5,
      "name": "Soil_Grass_Full"
    },
    {
      "x": 6,
      "y": 1,
      "z": -5,
      "name": "Plant_Grass_Lush"
    },
    {
      "x": 6,
      "y": -2,
      "z": -4,
      "name": "Soil_Grass_Full"
    },
    {
      "x": 6,
      "y": -1,
      "z": -4,
      "name": "Soil_Grass_Full"
    },
    {
      "x": 6,
      "y": 0,
      "z": -4,
      "name": "Soil_Grass_Full"
    },
    {
      "x": 6,
      "y": 1,
      "z": -4,
      "name": "Plant_Grass_Lush"
    },
    {
      "x": 6,
      "y": -2,
      "z": -3,
      "name": "Soil_Grass_Full"
    },
    {
      "x": 6,
      "y": -1,
      "z": -3,
      "name": "Soil_Grass_Full"
    },
    {
      "x": 6,
      "y": 0,
      "z": -3,
      "name": "Soil_Grass_Full"
    },
    {
      "x": 6,
      "y": 1,
      "z": -3,
      "name": "Plant_Grass_Lush"
    },
    {
      "x": 6,
      "y": -2,
      "z": -2,
      "name": "Soil_Grass_Full"
    },
    {
      "x": 6,
      "y": -1,
      "z": -2,
      "name": "Soil_Grass_Full"
    },
    {
      "x": 6,
      "y": 0,
      "z": -2,
      "name": "Soil_Grass_Full"
    },
    {
      "x": 6,
      "y": -2,
      "z": -1,
      "name": "Soil_Grass_Full"
    },
    {
      "x": 6,
      "y": -1,
      "z": -1,
      "name": "Soil_Grass_Full"
    },
    {
      "x": 6,
      "y": 0,
      "z": -1,
      "name": "Soil_Pebbles",
      "support": 15
    },
    {
      "x": 6,
      "y": -2,
      "z": 0,
      "name": "Soil_Grass_Full"
    },
    {
      "x": 6,
      "y": -1,
      "z": 0,
      "name": "Soil_Grass_Full"
    },
    {
      "x": 6,
      "y": 0,
      "z": 0,
      "name": "Soil_Grass_Sunny_Full"
    },
    {
      "x": 6,
      "y": -2,
      "z": 1,
      "name": "Soil_Grass_Full"
    },
    {
      "x": 6,
      "y": -1,
      "z": 1,
      "name": "Soil_Grass_Full"
    },
    {
      "x": 6,
      "y": 0,
      "z": 1,
      "name": "Soil_Grass_Full"
    },
    {
      "x": 6,
      "y": -2,
      "z": 2,
      "name": "Soil_Grass_Full"
    },
    {
      "x": 6,
      "y": -1,
      "z": 2,
      "name": "Soil_Grass_Full"
    },
    {
      "x": 6,
      "y": 0,
      "z": 2,
      "name": "Soil_Grass_Full"
    },
    {
      "x": 6,
      "y": -2,
      "z": 3,
      "name": "Soil_Grass_Full"
    },
    {
      "x": 6,
      "y": -1,
      "z": 3,
      "name": "Soil_Grass_Full"
    },
    {
      "x": 6,
      "y": 0,
      "z": 3,
      "name": "Soil_Grass_Full"
    },
    {
      "x": 6,
      "y": -2,
      "z": 4,
      "name": "Soil_Grass_Full"
    },
    {
      "x": 6,
      "y": -1,
      "z": 4,
      "name": "Soil_Grass_Full"
    },
    {
      "x": 6,
      "y": 0,
      "z": 4,
      "name": "Soil_Grass_Full"
    },
    {
      "x": 6,
      "y": -2,
      "z": 5,
      "name": "Soil_Grass_Full"
    },
    {
      "x": 6,
      "y": -1,
      "z": 5,
      "name": "Soil_Grass_Full"
    },
    {
      "x": 6,
      "y": 0,
      "z": 5,
      "name": "Soil_Grass_Full"
    },
    {
      "x": 6,
      "y": -2,
      "z": 6,
      "name": "Soil_Grass_Full"
    },
    {
      "x": 6,
      "y": -1,
      "z": 6,
      "name": "Soil_Grass_Full"
    },
    {
      "x": 7,
      "y": -2,
      "z": -8,
      "name": "Soil_Grass_Full"
    },
    {
      "x": 7,
      "y": -2,
      "z": -7,
      "name": "Soil_Grass_Full"
    },
    {
      "x": 7,
      "y": -1,
      "z": -7,
      "name": "Soil_Grass_Full"
    },
    {
      "x": 7,
      "y": -2,
      "z": -6,
      "name": "Soil_Grass_Full"
    },
    {
      "x": 7,
      "y": -1,
      "z": -6,
      "name": "Soil_Grass_Full"
    },
    {
      "x": 7,
      "y": -2,
      "z": -5,
      "name": "Soil_Grass_Full"
    },
    {
      "x": 7,
      "y": -1,
      "z": -5,
      "name": "Soil_Grass_Full"
    },
    {
      "x": 7,
      "y": 0,
      "z": -5,
      "name": "Soil_Grass_Full"
    },
    {
      "x": 7,
      "y": -2,
      "z": -4,
      "name": "Soil_Grass_Full"
    },
    {
      "x": 7,
      "y": -1,
      "z": -4,
      "name": "Soil_Grass_Full"
    },
    {
      "x": 7,
      "y": 0,
      "z": -4,
      "name": "Soil_Grass_Full"
    },
    {
      "x": 7,
      "y": 1,
      "z": -4,
      "name": "Plant_Grass_Lush"
    },
    {
      "x": 7,
      "y": -2,
      "z": -3,
      "name": "Soil_Grass_Full"
    },
    {
      "x": 7,
      "y": -1,
      "z": -3,
      "name": "Soil_Grass_Full"
    },
    {
      "x": 7,
      "y": 0,
      "z": -3,
      "name": "Soil_Grass_Full"
    },
    {
      "x": 7,
      "y": -2,
      "z": -2,
      "name": "Soil_Grass_Full"
    },
    {
      "x": 7,
      "y": -1,
      "z": -2,
      "name": "Soil_Grass_Full"
    },
    {
      "x": 7,
      "y": 0,
      "z": -2,
      "name": "Soil_Grass_Full"
    },
    {
      "x": 7,
      "y": 1,
      "z": -2,
      "name": "Plant_Grass_Lush"
    },
    {
      "x": 7,
      "y": -2,
      "z": -1,
      "name": "Soil_Grass_Full"
    },
    {
      "x": 7,
      "y": -1,
      "z": -1,
      "name": "Soil_Grass_Full"
    },
    {
      "x": 7,
      "y": 0,
      "z": -1,
      "name": "Soil_Grass_Full"
    },
    {
      "x": 7,
      "y": 1,
      "z": -1,
      "name": "Plant_Grass_Lush"
    },
    {
      "x": 7,
      "y": -2,
      "z": 0,
      "name": "Soil_Grass_Full"
    },
    {
      "x": 7,
      "y": -1,
      "z": 0,
      "name": "Soil_Grass_Full"
    },
    {
      "x": 7,
      "y": 0,
      "z": 0,
      "name": "Soil_Grass_Full"
    },
    {
      "x": 7,
      "y": -2,
      "z": 1,
      "name": "Soil_Grass_Full"
    },
    {
      "x": 7,
      "y": -1,
      "z": 1,
      "name": "Soil_Grass_Full"
    },
    {
      "x": 7,
      "y": 0,
      "z": 1,
      "name": "Soil_Grass_Sunny_Full"
    },
    {
      "x": 7,
      "y": 1,
      "z": 1,
      "name": "Plant_Grass_Lush"
    },
    {
      "x": 7,
      "y": -2,
      "z": 2,
      "name": "Soil_Grass_Full"
    },
    {
      "x": 7,
      "y": -1,
      "z": 2,
      "name": "Soil_Grass_Full"
    },
    {
      "x": 7,
      "y": 0,
      "z": 2,
      "name": "Soil_Grass_Full"
    },
    {
      "x": 7,
      "y": 1,
      "z": 2,
      "name": "Plant_Flower_Water_Duckweed"
    },
    {
      "x": 7,
      "y": -2,
      "z": 3,
      "name": "Soil_Grass_Full"
    },
    {
      "x": 7,
      "y": -1,
      "z": 3,
      "name": "Soil_Grass_Full"
    },
    {
      "x": 7,
      "y": 0,
      "z": 3,
      "name": "Soil_Grass_Full"
    },
    {
      "x": 7,
      "y": -2,
      "z": 4,
      "name": "Soil_Grass_Full"
    },
    {
      "x": 7,
      "y": -1,
      "z": 4,
      "name": "Soil_Grass_Full"
    },
    {
      "x": 7,
      "y": 0,
      "z": 4,
      "name": "Soil_Grass_Full"
    },
    {
      "x": 7,
      "y": -2,
      "z": 5,
      "name": "Soil_Grass_Full"
    },
    {
      "x": 7,
      "y": -1,
      "z": 5,
      "name": "Soil_Grass_Full"
    },
    {
      "x": 7,
      "y": -2,
      "z": 6,
      "name": "Soil_Grass_Full"
    },
    {
      "x": 8,
      "y": -2,
      "z": -7,
      "name": "Soil_Grass_Full"
    },
    {
      "x": 8,
      "y": -2,
      "z": -6,
      "name": "Soil_Grass_Full"
    },
    {
      "x": 8,
      "y": -1,
      "z": -6,
      "name": "Soil_Grass_Full"
    },
    {
      "x": 8,
      "y": -2,
      "z": -5,
      "name": "Soil_Grass_Full"
    },
    {
      "x": 8,
      "y": -1,
      "z": -5,
      "name": "Soil_Grass_Full"
    },
    {
      "x": 8,
      "y": -2,
      "z": -4,
      "name": "Soil_Grass_Full"
    },
    {
      "x": 8,
      "y": -1,
      "z": -4,
      "name": "Soil_Grass_Full"
    },
    {
      "x": 8,
      "y": -2,
      "z": -3,
      "name": "Soil_Grass_Full"
    },
    {
      "x": 8,
      "y": -1,
      "z": -3,
      "name": "Soil_Grass_Full"
    },
    {
      "x": 8,
      "y": 1,
      "z": -3,
      "name": "Plant_Grass_Lush_Short"
    },
    {
      "x": 8,
      "y": -2,
      "z": -2,
      "name": "Soil_Grass_Full"
    },
    {
      "x": 8,
      "y": -1,
      "z": -2,
      "name": "Soil_Grass_Full"
    },
    {
      "x": 8,
      "y": 1,
      "z": -2,
      "name": "Plant_Grass_Lush_Short"
    },
    {
      "x": 8,
      "y": -2,
      "z": -1,
      "name": "Soil_Grass_Full"
    },
    {
      "x": 8,
      "y": -1,
      "z": -1,
      "name": "Soil_Grass_Full"
    },
    {
      "x": 8,
      "y": -2,
      "z": 0,
      "name": "Soil_Grass_Full"
    },
    {
      "x": 8,
      "y": -1,
      "z": 0,
      "name": "Soil_Grass_Full"
    },
    {
      "x": 8,
      "y": -2,
      "z": 1,
      "name": "Soil_Grass_Full"
    },
    {
      "x": 8,
      "y": -1,
      "z": 1,
      "name": "Soil_Grass_Full"
    },
    {
      "x": 8,
      "y": 1,
      "z": 1,
      "name": "Plant_Grass_Lush"
    },
    {
      "x": 8,
      "y": -2,
      "z": 2,
      "name": "Soil_Grass_Full"
    },
    {
      "x": 8,
      "y": -1,
      "z": 2,
      "name": "Soil_Grass_Full"
    },
    {
      "x": 8,
      "y": -2,
      "z": 3,
      "name": "Soil_Grass_Full"
    },
    {
      "x": 8,
      "y": -1,
      "z": 3,
      "name": "Soil_Grass_Full"
    },
    {
      "x": 8,
      "y": -2,
      "z": 4,
      "name": "Soil_Grass_Full"
    },
    {
      "x": 8,
      "y": -1,
      "z": 4,
      "name": "Soil_Grass_Full"
    },
    {
      "x": 8,
      "y": -2,
      "z": 5,
      "name": "Soil_Grass_Full"
    },
    {
      "x": 9,
      "y": -2,
      "z": -6,
      "name": "Soil_Grass_Full"
    },
    {
      "x": 9,
      "y": -2,
      "z": -5,
      "name": "Soil_Grass_Full"
    },
    {
      "x": 9,
      "y": -2,
      "z": -4,
      "name": "Soil_Grass_Full"
    },
    {
      "x": 9,
      "y": -2,
      "z": -3,
      "name": "Soil_Grass_Full"
    },
    {
      "x": 9,
      "y": -2,
      "z": -2,
      "name": "Soil_Grass_Full"
    },
    {
      "x": 9,
      "y": -2,
      "z": -1,
      "name": "Soil_Grass_Full"
    },
    {
      "x": 9,
      "y": -2,
      "z": 0,
      "name": "Soil_Grass_Full"
    },
    {
      "x": 9,
      "y": -2,
      "z": 1,
      "name": "Soil_Grass_Full"
    },
    {
      "x": 9,
      "y": -2,
      "z": 2,
      "name": "Soil_Grass_Full"
    },
    {
      "x": 9,
      "y": -2,
      "z": 3,
      "name": "Soil_Grass_Full"
    },
    {
      "x": 9,
      "y": -2,
      "z": 4,
      "name": "Soil_Grass_Full"
    }
  ]
}