{
  "version": 8,
  "blockIdVersion": 11,
  "anchorX": 0,
  "anchorY": 0,
  "anchorZ": 0,
  "blocks": [
    {
      "x": -7,
      "y": -2,
      "z": -4,
      "name": "Soil_Grass_White"
    },
    {
      "x": -7,
      "y": -2,
      "z": -3,
      "name": "Soil_Grass_White"
    },
    {
      "x": -7,
      "y": -2,
      "z": -2,
      "name": "Soil_Grass_White"
    },
    {
      "x": -7,
      "y": -2,
      "z": 0,
      "name": "Soil_Grass_White"
    },
    {
      "x": -7,
      "y": -1,
      "z": 0,
      "name": "Soil_Grass_White"
    },
    {
      "x": -7,
      "y": -2,
      "z": 1,
      "name": "Soil_Grass_White"
    },
    {
      "x": -7,
      "y": -1,
      "z": 1,
      "name": "Soil_Grass_White"
    },
    {
      "x": -7,
      "y": -2,
      "z": 2,
      "name": "Soil_Grass_White"
    },
    {
      "x": -7,
      "y": -1,
      "z": 2,
      "name": "Soil_Grass_White"
    },
    {
      "x": -7,
      "y": -2,
      "z": 3,
      "name": "Soil_Grass_White"
    },
    {
      "x": -7,
      "y": -1,
      "z": 3,
      "name": "Soil_Grass_Full"
    },
    {
      "x": -6,
      "y": -2,
      "z": -7,
      "name": "Soil_Grass_White"
    },
    {
      "x": -6,
      "y": -2,
      "z": -6,
      "name": "Soil_Grass_White"
    },
    {
      "x": -6,
      "y": -1,
      "z": -6,
      "name": "Soil_Grass_Full"
    },
    {
      "x": -6,
      "y": -2,
      "z": -5,
      "name": "Soil_Grass_White"
    },
    {
      "x": -6,
      "y": -1,
      "z": -5,
      "name": "Soil_Grass_Full"
    },
    {
      "x": -6,
      "y": -2,
      "z": -4,
      "name": "Soil_Grass_White"
    },
    {
      "x": -6,
      "y": -1,
      "z": -4,
      "name": "Soil_Grass_Full"
    },
    {
      "x": -6,
      "y": 0,
      "z": -4,
      "name": "Soil_Grass_Full"
    },
    {
      "x": -6,
      "y": -2,
      "z": -3,
      "name": "Soil_Grass_White"
    },
    {
      "x": -6,
      "y": -1,
      "z": -3,
      "name": "Soil_Grass_Full"
    },
    {
      "x": -6,
      "y": 0,
      "z": -3,
      "name": "Soil_Grass_Full"
    },
    {
      "x": -6,
      "y": -2,
      "z": -2,
      "name": "Soil_Grass_White"
    },
    {
      "x": -6,
      "y": -1,
      "z": -2,
      "name": "Soil_Grass_Full"
    },
    {
      "x": -6,
      "y": -2,
      "z": -1,
      "name": "Soil_Grass_White"
    },
    {
      "x": -6,
      "y": -1,
      "z": -1,
      "name": "Soil_Grass_Full"
    },
    {
      "x": -6,
      "y": 0,
      "z": -1,
      "name": "Soil_Grass_Full"
    },
    {
      "x": -6,
      "y": -2,
      "z": 0,
      "name": "Soil_Grass_White"
    },
    {
      "x": -6,
      "y": -1,
      "z": 0,
      "name": "Soil_Grass_Full"
    },
    {
      "x": -6,
      "y": 0,
      "z": 0,
      "name": "Soil_Grass_Full"
    },
    {
      "x": -6,
      "y": -2,
      "z": 1,
      "name": "Soil_Grass_White"
    },
    {
      "x": -6,
      "y": -1,
      "z": 1,
      "name": "Soil_Grass_White"
    },
    {
      "x": -6,
      "y": 0,
      "z": 1,
      "name": "Soil_Grass_Full"
    },
    {
      "x": -6,
      "y": -2,
      "z": 2,
      "name": "Soil_Grass_White"
    },
    {
      "x": -6,
      "y": -1,
      "z": 2,
      "name": "Soil_Grass_Full"
    },
    {
      "x": -6,
      "y": 0,
      "z": 2,
      "name": "Soil_Grass_Full"
    },
    {
      "x": -6,
      "y": -2,
      "z": 3,
      "name": "Soil_Grass_White"
    },
    {
      "x": -6,
      "y": -1,
      "z": 3,
      "name": "Soil_Grass_Full"
    },
    {
      "x": -6,
      "y": 0,
      "z": 3,
      "name": "Soil_Grass_Full"
    },
    {
      "x": -6,
      "y": -2,
      "z": 4,
      "name": "Soil_Grass_White"
    },
    {
      "x": -6,
      "y": -1,
      "z": 4,
      "name": "Soil_Grass_Full"
    },
    {
      "x": -6,
      "y": 0,
      "z": 4,
      "name": "Soil_Grass_Full"
    },
    {
      "x": -6,
      "y": -2,
      "z": 5,
      "name": "Soil_Grass_White"
    },
    {
      "x": -6,
      "y": -1,
      "z": 5,
      "name": "Soil_Grass_Full"
    },
    {
      "x": -6,
      "y": -2,
      "z": 6,
      "name": "Soil_Grass_White"
    },
    {
      "x": -5,
      "y": -2,
      "z": -8,
      "name": "Soil_Grass_White"
    },
    {
      "x": -5,
      "y": -2,
      "z": -7,
      "name": "Soil_Grass_White"
    },
    {
      "x": -5,
      "y": -1,
      "z": -7,
      "name": "Soil_Grass_Full"
    },
    {
      "x": -5,
      "y": -2,
      "z": -6,
      "name": "Soil_Grass_White"
    },
    {
      "x": -5,
      "y": -1,
      "z": -6,
      "name": "Soil_Grass_Full"
    },
    {
      "x": -5,
      "y": 0,
      "z": -6,
      "name": "Soil_Grass_Full"
    },
    {
      "x": -5,
      "y": -2,
      "z": -5,
      "name": "Soil_Grass_White"
    },
    {
      "x": -5,
      "y": -1,
      "z": -5,
      "name": "Soil_Grass_Full"
    },
    {
      "x": -5,
      "y": 0,
      "z": -5,
      "name": "Soil_Grass_Full"
    },
    {
      "x": -5,
      "y": -2,
      "z": -4,
      "name": "Soil_Grass_White"
    },
    {
      "x": -5,
      "y": -1,
      "z": -4,
      "name": "Soil_Grass_Full"
    },
    {
      "x": -5,
      "y": 0,
      "z": -4,
      "name": "Soil_Grass_Full"
    },
    {
      "x": -5,
      "y": -2,
      "z": -3,
      "name": "Soil_Grass_White"
    },
    {
      "x": -5,
      "y": -1,
      "z": -3,
      "name": "Soil_Grass_Full"
    },
    {
      "x": -5,
      "y": 0,
      "z": -3,
      "name": "Soil_Grass_Full"
    },
    {
      "x": -5,
      "y": -2,
      "z": -2,
      "name": "Soil_Grass_White"
    },
    {
      "x": -5,
      "y": -1,
      "z": -2,
      "name": "Soil_Grass_Full"
    },
    {
      "x": -5,
      "y": 0,
      "z": -2,
      "name": "Soil_Grass_Full"
    },
    {
      "x": -5,
      "y": -2,
      "z": -1,
      "name": "Soil_Grass_White"
    },
    {
      "x": -5,
      "y": -1,
      "z": -1,
      "name": "Soil_Grass_Full"
    },
    {
      "x": -5,
      "y": 0,
      "z": -1,
      "name": "Soil_Grass_Full"
    },
    {
      "x": -5,
      "y": 1,
      "z": -1,
      "name": "Plant_Fern_Wet_Big"
    },
    {
      "x": -5,
      "y": -2,
      "z": 0,
      "name": "Soil_Grass_White"
    },
    {
      "x": -5,
      "y": -1,
      "z": 0,
      "name": "Soil_Grass_Full"
    },
    {
      "x": -5,
      "y": 0,
      "z": 0,
      "name": "Soil_Grass_Full"
    },
    {
      "x": -5,
      "y": 1,
      "z": 0,
      "name": "Plant_Grass_Lush_Short"
    },
    {
      "x": -5,
      "y": -2,
      "z": 1,
      "name": "Soil_Grass_White"
    },
    {
      "x": -5,
      "y": -1,
      "z": 1,
      "name": "Soil_Grass_Full"
    },
    {
      "x": -5,
      "y": 0,
      "z": 1,
      "name": "Soil_Grass_Full"
    },
    {
      "x": -5,
      "y": -2,
      "z": 2,
      "name": "Soil_Grass_White"
    },
    {
      "x": -5,
      "y": -1,
      "z": 2,
      "name": "Soil_Grass_Full"
    },
    {
      "x": -5,
      "y": 0,
      "z": 2,
      "name": "Soil_Grass_Full"
    },
    {
      "x": -5,
      "y": -2,
      "z": 3,
      "name": "Soil_Grass_White"
    },
    {
      "x": -5,
      "y": -1,
      "z": 3,
      "name": "Soil_Grass_Full"
    },
    {
      "x": -5,
      "y": 0,
      "z": 3,
      "name": "Soil_Grass_Full"
    },
    {
      "x": -5,
      "y": -2,
      "z": 4,
      "name": "Soil_Grass_White"
    },
    {
      "x": -5,
      "y": -1,
      "z": 4,
      "name": "Soil_Grass_Full"
    },
    {
      "x": -5,
      "y": -2,
      "z": 5,
      "name": "Soil_Grass_White"
    },
    {
      "x": -5,
      "y": -1,
      "z": 5,
      "name": "Soil_Grass_Full"
    },
    {
      "x": -5,
      "y": 0,
      "z": 5,
      "name": "Soil_Pebbles"
    },
    {
      "x": -5,
      "y": -2,
      "z": 6,
      "name": "Soil_Grass_White"
    },
    {
      "x": -5,
      "y": -1,
      "z": 6,
      "name": "Soil_Pebbles"
    },
    {
      "x": -5,
      "y": -2,
      "z": 7,
      "name": "Soil_Grass_White"
    },
    {
      "x": -4,
      "y": -2,
      "z": -9,
      "name": "Soil_Grass_White"
    },
    {
      "x": -4,
      "y": -2,
      "z": -8,
      "name": "Soil_Grass_White"
    },
    {
      "x": -4,
      "y": -1,
      "z": -8,
      "name": "Soil_Grass_Full"
    },
    {
      "x": -4,
      "y": -2,
      "z": -7,
      "name": "Soil_Grass_White"
    },
    {
      "x": -4,
      "y": -1,
      "z": -7,
      "name": "Soil_Grass_Full"
    },
    {
      "x": -4,
      "y": 0,
      "z": -7,
      "name": "Soil_Grass_Full"
    },
    {
      "x": -4,
      "y": 1,
      "z": -7,
      "name": "Plant_Grass_Lush"
    },
    {
      "x": -4,
      "y": -2,
      "z": -6,
      "name": "Soil_Grass_White"
    },
    {
      "x": -4,
      "y": -1,
      "z": -6,
      "name": "Soil_Grass_Full"
    },
    {
      "x": -4,
      "y": 0,
      "z": -6,
      "name": "Soil_Grass_Full"
    },
    {
      "x": -4,
      "y": 1,
      "z": -6,
      "name": "Plant_Grass_Lush_Short"
    },
    {
      "x": -4,
      "y": -2,
      "z": -5,
      "name": "Soil_Grass_White"
    },
    {
      "x": -4,
      "y": -1,
      "z": -5,
      "name": "Soil_Grass_Full"
    },
    {
      "x": -4,
      "y": 0,
      "z": -5,
      "name": "Soil_Grass_Full"
    },
    {
      "x": -4,
      "y": 1,
      "z": -5,
      "name": "Plant_Grass_Lush_Short"
    },
    {
      "x": -4,
      "y": -2,
      "z": -4,
      "name": "Soil_Grass_White"
    },
    {
      "x": -4,
      "y": -1,
      "z": -4,
      "name": "Soil_Grass_Full"
    },
    {
      "x": -4,
      "y": 0,
      "z": -4,
      "name": "Soil_Grass_Full"
    },
    {
      "x": -4,
      "y": -2,
      "z": -3,
      "name": "Soil_Grass_White"
    },
    {
      "x": -4,
      "y": -1,
      "z": -3,
      "name": "Soil_Grass_Full"
    },
    {
      "x": -4,
      "y": 0,
      "z": -3,
      "name": "Soil_Grass_Full"
    },
    {
      "x": -4,
      "y": 1,
      "z": -3,
      "name": "Plant_Fern_Wet_Big"
    },
    {
      "x": -4,
      "y": -2,
      "z": -2,
      "name": "Soil_Grass_White"
    },
    {
      "x": -4,
      "y": -1,
      "z": -2,
      "name": "Soil_Grass_Full"
    },
    {
      "x": -4,
      "y": 0,
      "z": -2,
      "name": "Soil_Grass_Full"
    },
    {
      "x": -4,
      "y": -2,
      "z": -1,
      "name": "Soil_Grass_White"
    },
    {
      "x": -4,
      "y": -1,
      "z": -1,
      "name": "Soil_Grass_Full"
    },
    {
      "x": -4,
      "y": 0,
      "z": -1,
      "name": "Soil_Grass_Full"
    },
    {
      "x": -4,
      "y": 1,
      "z": -1,
      "name": "Plant_Grass_Lush_Short"
    },
    {
      "x": -4,
      "y": -2,
      "z": 0,
      "name": "Soil_Grass_White"
    },
    {
      "x": -4,
      "y": -1,
      "z": 0,
      "name": "Soil_Grass_Full"
    },
    {
      "x": -4,
      "y": 0,
      "z": 0,
      "name": "Soil_Grass_Full"
    },
    {
      "x": -4,
      "y": -2,
      "z": 1,
      "name": "Soil_Grass_White"
    },
    {
      "x": -4,
      "y": -1,
      "z": 1,
      "name": "Soil_Grass_Full"
    },
    {
      "x": -4,
      "y": 0,
      "z": 1,
      "name": "Soil_Grass_Full"
    },
    {
      "x": -4,
      "y": 1,
      "z": 1,
      "name": "Plant_Grass_Lush"
    },
    {
      "x": -4,
      "y": -2,
      "z": 2,
      "name": "Soil_Grass_White"
    },
    {
      "x": -4,
      "y": -1,
      "z": 2,
      "name": "Soil_Grass_Full"
    },
    {
      "x": -4,
      "y": 0,
      "z": 2,
      "name": "Soil_Grass_Full"
    },
    {
      "x": -4,
      "y": 1,
      "z": 2,
      "name": "Plant_Grass_Lush"
    },
    {
      "x": -4,
      "y": -2,
      "z": 3,
      "name": "Soil_Grass_White"
    },
    {
      "x": -4,
      "y": -1,
      "z": 3,
      "name": "Soil_Grass_Full"
    },
    {
      "x": -4,
      "y": 0,
      "z": 3,
      "name": "Soil_Grass_Full"
    },
    {
      "x": -4,
      "y": 1,
      "z": 3,
      "name": "Plant_Grass_Lush"
    },
    {
      "x": -4,
      "y": -2,
      "z": 4,
      "name": "Soil_Grass_White"
    },
    {
      "x": -4,
      "y": -1,
      "z": 4,
      "name": "Soil_Grass_Full"
    },
    {
      "x": -4,
      "y": 0,
      "z": 4,
      "name": "Soil_Grass_Full"
    },
    {
      "x": -4,
      "y": 1,
      "z": 4,
      "name": "Plant_Grass_Lush"
    },
    {
      "x": -4,
      "y": -2,
      "z": 5,
      "name": "Soil_Grass_White"
    },
    {
      "x": -4,
      "y": -1,
      "z": 5,
      "name": "Soil_Pebbles"
    },
    {
      "x": -4,
      "y": 0,
      "z": 5,
      "name": "Soil_Pebbles"
    },
    {
      "x": -4,
      "y": -2,
      "z": 6,
      "name": "Soil_Grass_White"
    },
    {
      "x": -4,
      "y": -1,
      "z": 6,
      "name": "Soil_Pebbles"
    },
    {
      "x": -4,
      "y": 0,
      "z": 6,
      "name": "Soil_Pebbles"
    },
    {
      "x": -4,
      "y": -2,
      "z": 7,
      "name": "Soil_Grass_White"
    },
    {
      "x": -4,
      "y": -1,
      "z": 7,
      "name": "Soil_Pebbles"
    },
    {
      "x": -4,
      "y": -2,
      "z": 8,
      "name": "Soil_Grass_White"
    },
    {
      "x": -4,
      "y": -1,
      "z": 8,
      "name": "Soil_Pebbles"
    },
    {
      "x": -3,
      "y": -2,
      "z": -9,
      "name": "Soil_Grass_White"
    },
    {
      "x": -3,
      "y": -1,
      "z": -9,
      "name": "Soil_Grass_Full"
    },
    {
      "x": -3,
      "y": -2,
      "z": -8,
      "name": "Soil_Grass_White"
    },
    {
      "x": -3,
      "y": -1,
      "z": -8,
      "name": "Soil_Grass_Full"
    },
    {
      "x": -3,
      "y": 0,
      "z": -8,
      "name": "Soil_Grass_Full"
    },
    {
      "x": -3,
      "y": -2,
      "z": -7,
      "name": "Soil_Grass_White"
    },
    {
      "x": -3,
      "y": -1,
      "z": -7,
      "name": "Soil_Grass_Full"
    },
    {
      "x": -3,
      "y": 0,
      "z": -7,
      "name": "Soil_Grass_Full"
    },
    {
      "x": -3,
      "y": -2,
      "z": -6,
      "name": "Soil_Grass_White"
    },
    {
      "x": -3,
      "y": -1,
      "z": -6,
      "name": "Soil_Grass_Full"
    },
    {
      "x": -3,
      "y": 0,
      "z": -6,
      "name": "Soil_Grass_Full"
    },
    {
      "x": -3,
      "y": -2,
      "z": -5,
      "name": "Soil_Grass_White"
    },
    {
      "x": -3,
      "y": -1,
      "z": -5,
      "name": "Soil_Grass_Full"
    },
    {
      "x": -3,
      "y": 0,
      "z": -5,
      "name": "Soil_Grass_Full"
    },
    {
      "x": -3,
      "y": -2,
      "z": -4,
      "name": "Soil_Grass_White"
    },
    {
      "x": -3,
      "y": -1,
      "z": -4,
      "name": "Soil_Grass_Full"
    },
    {
      "x": -3,
      "y": 0,
      "z": -4,
      "name": "Soil_Grass_Full"
    },
    {
      "x": -3,
      "y": 1,
      "z": -4,
      "name": "Plant_Fern_Wet_Big"
    },
    {
      "x": -3,
      "y": -2,
      "z": -3,
      "name": "Soil_Grass_White"
    },
    {
      "x": -3,
      "y": -1,
      "z": -3,
      "name": "Soil_Grass_Full"
    },
    {
      "x": -3,
      "y": 0,
      "z": -3,
      "name": "Soil_Grass_Full"
    },
    {
      "x": -3,
      "y": 1,
      "z": -3,
      "name": "Plant_Fern_Wet_Big"
    },
    {
      "x": -3,
      "y": -2,
      "z": -2,
      "name": "Soil_Grass_White"
    },
    {
      "x": -3,
      "y": -1,
      "z": -2,
      "name": "Soil_Grass_Full"
    },
    {
      "x": -3,
      "y": 0,
      "z": -2,
      "name": "Soil_Grass_Full"
    },
    {
      "x": -3,
      "y": 1,
      "z": -2,
      "name": "Plant_Fern_Wet_Big"
    },
    {
      "x": -3,
      "y": 7,
      "z": -2,
      "name": "Rock_Marble_Brick_Half",
      "rotation": 7
    },
    {
      "x": -3,
      "y": -2,
      "z": -1,
      "name": "Soil_Grass_White"
    },
    {
      "x": -3,
      "y": -1,
      "z": -1,
      "name": "Soil_Grass_Full"
    },
    {
      "x": -3,
      "y": 0,
      "z": -1,
      "name": "Soil_Grass_Full"
    },
    {
      "x": -3,
      "y": 1,
      "z": -1,
      "name": "Rock_Marble_Brick_Half",
      "rotation": 7
    },
    {
      "x": -3,
      "y": 7,
      "z": -1,
      "name": "Rock_Marble_Brick_Half",
      "rotation": 7
    },
    {
      "x": -3,
      "y": 8,
      "z": -1,
      "name": "Rock_Marble_Brick_Half",
      "rotation": 7
    },
    {
      "x": -3,
      "y": -2,
      "z": 0,
      "name": "Soil_Grass_White"
    },
    {
      "x": -3,
      "y": -1,
      "z": 0,
      "name": "Soil_Grass_Full"
    },
    {
      "x": -3,
      "y": 0,
      "z": 0,
      "name": "Soil_Grass_Full"
    },
    {
      "x": -3,
      "y": 1,
      "z": 0,
      "name": "Rock_Marble_Brick_Half",
      "rotation": 7
    },
    {
      "x": -3,
      "y": 7,
      "z": 0,
      "name": "Rock_Marble_Brick_Half",
      "rotation": 7
    },
    {
      "x": -3,
      "y": 8,
      "z": 0,
      "name": "Rock_Marble_Brick_Half",
      "rotation": 7
    },
    {
      "x": -3,
      "y": -2,
      "z": 1,
      "name": "Soil_Grass_White"
    },
    {
      "x": -3,
      "y": 0,
      "z": 1,
      "name": "Soil_Grass_Full"
    },
    {
      "x": -3,
      "y": 1,
      "z": 1,
      "name": "Plant_Grass_Lush_Short",
      "rotation": 2
    },
    {
      "x": -3,
      "y": 7,
      "z": 1,
      "name": "Rock_Marble_Brick_Half",
      "rotation": 7
    },
    {
      "x": -3,
      "y": -2,
      "z": 2,
      "name": "Soil_Grass_White"
    },
    {
      "x": -3,
      "y": -1,
      "z": 2,
      "name": "Soil_Grass_Full"
    },
    {
      "x": -3,
      "y": 0,
      "z": 2,
      "name": "Soil_Grass_Full"
    },
    {
      "x": -3,
      "y": -2,
      "z": 3,
      "name": "Soil_Grass_White"
    },
    {
      "x": -3,
      "y": -1,
      "z": 3,
      "name": "Soil_Grass_Full"
    },
    {
      "x": -3,
      "y": 0,
      "z": 3,
      "name": "Soil_Grass_Full"
    },
    {
      "x": -3,
      "y": -2,
      "z": 4,
      "name": "Soil_Grass_White"
    },
    {
      "x": -3,
      "y": -1,
      "z": 4,
      "name": "Soil_Grass_Full"
    },
    {
      "x": -3,
      "y": 0,
      "z": 4,
      "name": "Soil_Pebbles",
      "support": 15
    },
    {
      "x": -3,
      "y": -2,
      "z": 5,
      "name": "Soil_Grass_White"
    },
    {
      "x": -3,
      "y": -1,
      "z": 5,
      "name": "Soil_Pebbles"
    },
    {
      "x": -3,
      "y": 0,
      "z": 5,
      "name": "Soil_Pebbles",
      "support": 15
    },
    {
      "x": -3,
      "y": -2,
      "z": 6,
      "name": "Soil_Grass_White"
    },
    {
      "x": -3,
      "y": -1,
      "z": 6,
      "name": "Soil_Pebbles"
    },
    {
      "x": -3,
      "y": 0,
      "z": 6,
      "name": "Soil_Pebbles"
    },
    {
      "x": -3,
      "y": -2,
      "z": 7,
      "name": "Soil_Grass_White"
    },
    {
      "x": -3,
      "y": -1,
      "z": 7,
      "name": "Soil_Pebbles"
    },
    {
      "x": -3,
      "y": 0,
      "z": 7,
      "name": "Soil_Pebbles"
    },
    {
      "x": -3,
      "y": -2,
      "z": 8,
      "name": "Soil_Grass_White"
    },
    {
      "x": -3,
      "y": -1,
      "z": 8,
      "name": "Soil_Pebbles"
    },
    {
      "x": -2,
      "y": -2,
      "z": -10,
      "name": "Soil_Grass_White"
    },
    {
      "x": -2,
      "y": -2,
      "z": -9,
      "name": "Soil_Grass_White"
    },
    {
      "x": -2,
      "y": -1,
      "z": -9,
      "name": "Soil_Grass_Full"
    },
    {
      "x": -2,
      "y": -2,
      "z": -8,
      "name": "Soil_Grass_White"
    },
    {
      "x": -2,
      "y": -1,
      "z": -8,
      "name": "Soil_Grass_Full"
    },
    {
      "x": -2,
      "y": 0,
      "z": -8,
      "name": "Soil_Grass_Full"
    },
    {
      "x": -2,
      "y": 1,
      "z": -8,
      "name": "Plant_Grass_Lush"
    },
    {
      "x": -2,
      "y": -2,
      "z": -7,
      "name": "Soil_Grass_White"
    },
    {
      "x": -2,
      "y": -1,
      "z": -7,
      "name": "Soil_Grass_Full"
    },
    {
      "x": -2,
      "y": 0,
      "z": -7,
      "name": "Soil_Grass_Full"
    },
    {
      "x": -2,
      "y": -2,
      "z": -6,
      "name": "Soil_Grass_White"
    },
    {
      "x": -2,
      "y": -1,
      "z": -6,
      "name": "Soil_Grass_Full"
    },
    {
      "x": -2,
      "y": 0,
      "z": -6,
      "name": "Soil_Grass_Full"
    },
    {
      "x": -2,
      "y": -2,
      "z": -5,
      "name": "Soil_Grass_White"
    },
    {
      "x": -2,
      "y": -1,
      "z": -5,
      "name": "Soil_Grass_Full"
    },
    {
      "x": -2,
      "y": 0,
      "z": -5,
      "name": "Soil_Grass_Full"
    },
    {
      "x": -2,
      "y": 1,
      "z": -5,
      "name": "Plant_Grass_Lush_Short"
    },
    {
      "x": -2,
      "y": -2,
      "z": -4,
      "name": "Soil_Grass_White"
    },
    {
      "x": -2,
      "y": -1,
      "z": -4,
      "name": "Soil_Grass_Full"
    },
    {
      "x": -2,
      "y": 0,
      "z": -4,
      "name": "Soil_Grass_Full"
    },
    {
      "x": -2,
      "y": -2,
      "z": -3,
      "name": "Soil_Grass_White"
    },
    {
      "x": -2,
      "y": -1,
      "z": -3,
      "name": "Soil_Grass_Full"
    },
    {
      "x": -2,
      "y": 0,
      "z": -3,
      "name": "Soil_Grass_Full"
    },
    {
      "x": -2,
      "y": 1,
      "z": -3,
      "name": "Plant_Grass_Lush",
      "rotation": 2
    },
    {
      "x": -2,
      "y": 7,
      "z": -3,
      "name": "Rock_Marble_Brick_Stairs",
      "rotation": 19
    },
    {
      "x": -2,
      "y": 14,
      "z": -3,
      "name": "Rock_Marble_Brick_Stairs",
      "rotation": 19
    },
    {
      "x": -2,
      "y": -2,
      "z": -2,
      "name": "Soil_Grass_White"
    },
    {
      "x": -2,
      "y": -1,
      "z": -2,
      "name": "Soil_Grass_Full"
    },
    {
      "x": -2,
      "y": 0,
      "z": -2,
      "name": "Soil_Dirt_White"
    },
    {
      "x": -2,
      "y": 1,
      "z": -2,
      "name": "Rock_Marble_Brick"
    },
    {
      "x": -2,
      "y": 2,
      "z": -2,
      "name": "Rock_Marble_Brick_Pillar_Base"
    },
    {
      "x": -2,
      "y": 3,
      "z": -2,
      "name": "Rock_Marble_Brick_Pillar_Middle"
    },
    {
      "x": -2,
      "y": 4,
      "z": -2,
      "name": "Rock_Marble_Brick_Pillar_Middle"
    },
    {
      "x": -2,
      "y": 5,
      "z": -2,
      "name": "Rock_Marble_Brick_Pillar_Middle"
    },
    {
      "x": -2,
      "y": 6,
      "z": -2,
      "name": "Rock_Marble_Brick_Pillar_Base",
      "rotation": 34
    },
    {
      "x": -2,
      "y": 7,
      "z": -2,
      "name": "Rock_Marble_Brick"
    },
    {
      "x": -2,
      "y": 8,
      "z": -2,
      "name": "Rock_Marble_Brick"
    },
    {
      "x": -2,
      "y": 9,
      "z": -2,
      "name": "Rock_Marble_Brick_Pillar_Base",
      "rotation": 3
    },
    {
      "x": -2,
      "y": 10,
      "z": -2,
      "name": "Rock_Marble_Brick_Pillar_Middle",
      "rotation": 3
    },
    {
      "x": -2,
      "y": 11,
      "z": -2,
      "name": "Rock_Marble_Brick_Pillar_Middle",
      "rotation": 3
    },
    {
      "x": -2,
      "y": 12,
      "z": -2,
      "name": "Rock_Marble_Brick_Pillar_Middle",
      "rotation": 3
    },
    {
      "x": -2,
      "y": 13,
      "z": -2,
      "name": "Rock_Marble_Brick_Pillar_Base",
      "rotation": 33
    },
    {
      "x": -2,
      "y": 14,
      "z": -2,
      "name": "Rock_Marble_Brick",
      "rotation": 3
    },
    {
      "x": -2,
      "y": 15,
      "z": -2,
      "name": "Rock_Marble_Half",
      "rotation": 7
    },
    {
      "x": -2,
      "y": -2,
      "z": -1,
      "name": "Soil_Grass_White"
    },
    {
      "x": -2,
      "y": -1,
      "z": -1,
      "name": "Soil_Dirt_White"
    },
    {
      "x": -2,
      "y": 0,
      "z": -1,
      "name": "Soil_Dirt_White"
    },
    {
      "x": -2,
      "y": 1,
      "z": -1,
      "name": "Rock_Marble_Brick",
      "rotation": 2
    },
    {
      "x": -2,
      "y": 2,
      "z": -1,
      "name": "Rock_Marble_Cobble",
      "rotation": 2
    },
    {
      "x": -2,
      "y": 3,
      "z": -1,
      "name": "Rock_Marble_Cobble_Stairs"
    },
    {
      "x": -2,
      "y": 4,
      "z": -1,
      "name": "Soil_Marble_Gravel_Half",
      "support": 15,
      "rotation": 4
    },
    {
      "x": -2,
      "y": 6,
      "z": -1,
      "name": "Rock_Marble_Cobble_Stairs",
      "rotation": 32
    },
    {
      "x": -2,
      "y": 7,
      "z": -1,
      "name": "Rock_Marble_Brick"
    },
    {
      "x": -2,
      "y": 8,
      "z": -1,
      "name": "Rock_Marble_Brick"
    },
    {
      "x": -2,
      "y": 9,
      "z": -1,
      "name": "Rock_Marble_Cobble",
      "rotation": 1
    },
    {
      "x": -2,
      "y": 10,
      "z": -1,
      "name": "Rock_Marble_Stairs"
    },
    {
      "x": -2,
      "y": 11,
      "z": -1,
      "name": "Rock_Marble_Half",
      "rotation": 4
    },
    {
      "x": -2,
      "y": 12,
      "z": -1,
      "name": "Rock_Marble_Stairs",
      "rotation": 32
    },
    {
      "x": -2,
      "y": 13,
      "z": -1,
      "name": "Rock_Marble"
    },
    {
      "x": -2,
      "y": 14,
      "z": -1,
      "name": "Rock_Marble_Brick",
      "rotation": 3
    },
    {
      "x": -2,
      "y": 15,
      "z": -1,
      "name": "Rock_Marble"
    },
    {
      "x": -2,
      "y": 16,
      "z": -1,
      "name": "Rock_Marble_Half",
      "rotation": 7
    },
    {
      "x": -2,
      "y": -2,
      "z": 0,
      "name": "Soil_Grass_White"
    },
    {
      "x": -2,
      "y": -1,
      "z": 0,
      "name": "Soil_Dirt_White"
    },
    {
      "x": -2,
      "y": 0,
      "z": 0,
      "name": "Soil_Dirt_White"
    },
    {
      "x": -2,
      "y": 1,
      "z": 0,
      "name": "Rock_Marble_Brick",
      "rotation": 1
    },
    {
      "x": -2,
      "y": 2,
      "z": 0,
      "name": "Rock_Marble_Cobble",
      "rotation": 2
    },
    {
      "x": -2,
      "y": 3,
      "z": 0,
      "name": "Rock_Marble_Stairs",
      "rotation": 2
    },
    {
      "x": -2,
      "y": 6,
      "z": 0,
      "name": "Rock_Marble"
    },
    {
      "x": -2,
      "y": 7,
      "z": 0,
      "name": "Rock_Marble_Brick",
      "rotation": 1
    },
    {
      "x": -2,
      "y": 8,
      "z": 0,
      "name": "Rock_Marble_Brick",
      "rotation": 1
    },
    {
      "x": -2,
      "y": 9,
      "z": 0,
      "name": "Rock_Marble_Cobble",
      "rotation": 1
    },
    {
      "x": -2,
      "y": 10,
      "z": 0,
      "name": "Rock_Marble_Stairs",
      "rotation": 2
    },
    {
      "x": -2,
      "y": 11,
      "z": 0,
      "name": "Rock_Marble_Half",
      "rotation": 6
    },
    {
      "x": -2,
      "y": 12,
      "z": 0,
      "name": "Rock_Marble_Stairs",
      "rotation": 34
    },
    {
      "x": -2,
      "y": 13,
      "z": 0,
      "name": "Rock_Marble"
    },
    {
      "x": -2,
      "y": 14,
      "z": 0,
      "name": "Rock_Marble_Brick",
      "rotation": 3
    },
    {
      "x": -2,
      "y": 15,
      "z": 0,
      "name": "Rock_Marble"
    },
    {
      "x": -2,
      "y": 16,
      "z": 0,
      "name": "Rock_Marble_Half",
      "rotation": 7
    },
    {
      "x": -2,
      "y": -2,
      "z": 1,
      "name": "Soil_Grass_White"
    },
    {
      "x": -2,
      "y": -1,
      "z": 1,
      "name": "Soil_Dirt_White"
    },
    {
      "x": -2,
      "y": 0,
      "z": 1,
      "name": "Soil_Dirt_White"
    },
    {
      "x": -2,
      "y": 1,
      "z": 1,
      "name": "Rock_Marble_Brick",
      "rotation": 1
    },
    {
      "x": -2,
      "y": 2,
      "z": 1,
      "name": "Rock_Marble_Brick_Pillar_Base",
      "rotation": 1
    },
    {
      "x": -2,
      "y": 3,
      "z": 1,
      "name": "Rock_Marble_Brick_Pillar_Middle",
      "rotation": 1
    },
    {
      "x": -2,
      "y": 4,
      "z": 1,
      "name": "Rock_Marble_Brick_Pillar_Middle",
      "rotation": 1
    },
    {
      "x": -2,
      "y": 5,
      "z": 1,
      "name": "Rock_Marble_Brick_Pillar_Middle",
      "rotation": 1
    },
    {
      "x": -2,
      "y": 6,
      "z": 1,
      "name": "Rock_Marble_Brick_Pillar_Base",
      "rotation": 35
    },
    {
      "x": -2,
      "y": 7,
      "z": 1,
      "name": "Rock_Marble_Brick",
      "rotation": 1
    },
    {
      "x": -2,
      "y": 8,
      "z": 1,
      "name": "Rock_Marble_Brick",
      "rotation": 1
    },
    {
      "x": -2,
      "y": 9,
      "z": 1,
      "name": "Rock_Marble_Brick_Pillar_Base",
      "rotation": 2
    },
    {
      "x": -2,
      "y": 10,
      "z": 1,
      "name": "Rock_Marble_Brick_Pillar_Middle",
      "rotation": 2
    },
    {
      "x": -2,
      "y": 11,
      "z": 1,
      "name": "Rock_Marble_Brick_Pillar_Middle",
      "rotation": 2
    },
    {
      "x": -2,
      "y": 12,
      "z": 1,
      "name": "Rock_Marble_Brick_Pillar_Middle",
      "rotation": 2
    },
    {
      "x": -2,
      "y": 13,
      "z": 1,
      "name": "Rock_Marble_Brick_Pillar_Base",
      "rotation": 32
    },
    {
      "x": -2,
      "y": 14,
      "z": 1,
      "name": "Rock_Marble_Brick",
      "rotation": 3
    },
    {
      "x": -2,
      "y": 15,
      "z": 1,
      "name": "Rock_Marble_Half",
      "rotation": 7
    },
    {
      "x": -2,
      "y": -2,
      "z": 2,
      "name": "Soil_Grass_White"
    },
    {
      "x": -2,
      "y": -1,
      "z": 2,
      "name": "Soil_Dirt_White"
    },
    {
      "x": -2,
      "y": 0,
      "z": 2,
      "name": "Soil_Grass_Full"
    },
    {
      "x": -2,
      "y": 1,
      "z": 2,
      "name": "Plant_Grass_Lush",
      "rotation": 2
    },
    {
      "x": -2,
      "y": 7,
      "z": 2,
      "name": "Rock_Marble_Brick_Stairs",
      "rotation": 16
    },
    {
      "x": -2,
      "y": 14,
      "z": 2,
      "name": "Rock_Marble_Brick_Stairs",
      "rotation": 16
    },
    {
      "x": -2,
      "y": -2,
      "z": 3,
      "name": "Soil_Grass_White"
    },
    {
      "x": -2,
      "y": -1,
      "z": 3,
      "name": "Soil_Grass_Full"
    },
    {
      "x": -2,
      "y": 0,
      "z": 3,
      "name": "Soil_Grass_Full"
    },
    {
      "x": -2,
      "y": -2,
      "z": 4,
      "name": "Soil_Grass_White"
    },
    {
      "x": -2,
      "y": -1,
      "z": 4,
      "name": "Soil_Grass_Full"
    },
    {
      "x": -2,
      "y": 0,
      "z": 4,
      "name": "Soil_Grass_Full"
    },
    {
      "x": -2,
      "y": 1,
      "z": 4,
      "name": "Soil_Marble_Gravel_Half",
      "support": 15
    },
    {
      "x": -2,
      "y": -2,
      "z": 5,
      "name": "Soil_Grass_White"
    },
    {
      "x": -2,
      "y": -1,
      "z": 5,
      "name": "Soil_Grass_Full"
    },
    {
      "x": -2,
      "y": 0,
      "z": 5,
      "name": "Soil_Pebbles",
      "support": 15
    },
    {
      "x": -2,
      "y": -2,
      "z": 6,
      "name": "Soil_Grass_White"
    },
    {
      "x": -2,
      "y": -1,
      "z": 6,
      "name": "Soil_Pebbles"
    },
    {
      "x": -2,
      "y": 0,
      "z": 6,
      "name": "Soil_Pebbles",
      "support": 15
    },
    {
      "x": -2,
      "y": -2,
      "z": 7,
      "name": "Soil_Grass_White"
    },
    {
      "x": -2,
      "y": -1,
      "z": 7,
      "name": "Soil_Pebbles"
    },
    {
      "x": -2,
      "y": 0,
      "z": 7,
      "name": "Soil_Grass_Full"
    },
    {
      "x": -2,
      "y": -2,
      "z": 8,
      "name": "Soil_Grass_White"
    },
    {
      "x": -2,
      "y": -1,
      "z": 8,
      "name": "Soil_Pebbles"
    },
    {
      "x": -2,
      "y": 0,
      "z": 8,
      "name": "Soil_Pebbles"
    },
    {
      "x": -1,
      "y": -2,
      "z": -10,
      "name": "Soil_Grass_White"
    },
    {
      "x": -1,
      "y": -2,
      "z": -9,
      "name": "Soil_Grass_White"
    },
    {
      "x": -1,
      "y": -1,
      "z": -9,
      "name": "Soil_Grass_Full"
    },
    {
      "x": -1,
      "y": -2,
      "z": -8,
      "name": "Soil_Grass_White"
    },
    {
      "x": -1,
      "y": -1,
      "z": -8,
      "name": "Soil_Grass_Full"
    },
    {
      "x": -1,
      "y": 0,
      "z": -8,
      "name": "Soil_Grass_Full"
    },
    {
      "x": -1,
      "y": 1,
      "z": -8,
      "name": "Plant_Grass_Lush"
    },
    {
      "x": -1,
      "y": -2,
      "z": -7,
      "name": "Soil_Grass_White"
    },
    {
      "x": -1,
      "y": -1,
      "z": -7,
      "name": "Soil_Grass_Full"
    },
    {
      "x": -1,
      "y": 0,
      "z": -7,
      "name": "Soil_Grass_Full"
    },
    {
      "x": -1,
      "y": -2,
      "z": -6,
      "name": "Soil_Grass_White"
    },
    {
      "x": -1,
      "y": -1,
      "z": -6,
      "name": "Soil_Grass_Full"
    },
    {
      "x": -1,
      "y": 0,
      "z": -6,
      "name": "Soil_Grass_Full"
    },
    {
      "x": -1,
      "y": 1,
      "z": -6,
      "name": "Plant_Grass_Lush"
    },
    {
      "x": -1,
      "y": -2,
      "z": -5,
      "name": "Soil_Grass_White"
    },
    {
      "x": -1,
      "y": 0,
      "z": -5,
      "name": "Soil_Grass_Full"
    },
    {
      "x": -1,
      "y": -2,
      "z": -4,
      "name": "Soil_Grass_White"
    },
    {
      "x": -1,
      "y": -1,
      "z": -4,
      "name": "Soil_Grass_Full"
    },
    {
      "x": -1,
      "y": 0,
      "z": -4,
      "name": "Soil_Grass_Full"
    },
    {
      "x": -1,
      "y": 1,
      "z": -4,
      "name": "Rubble_Marble_Medium",
      "support": 15,
      "rotation": 2
    },
    {
      "x": -1,
      "y": 7,
      "z": -4,
      "name": "Rock_Marble_Brick_Half",
      "rotation": 6
    },
    {
      "x": -1,
      "y": 14,
      "z": -4,
      "name": "Rock_Marble_Brick_Half",
      "rotation": 6
    },
    {
      "x": -1,
      "y": -2,
      "z": -3,
      "name": "Soil_Grass_White"
    },
    {
      "x": -1,
      "y": 0,
      "z": -3,
      "name": "Soil_Dirt_White"
    },
    {
      "x": -1,
      "y": 1,
      "z": -3,
      "name": "Rock_Marble_Brick"
    },
    {
      "x": -1,
      "y": 2,
      "z": -3,
      "name": "Rock_Marble_Brick_Pillar_Base"
    },
    {
      "x": -1,
      "y": 3,
      "z": -3,
      "name": "Rock_Marble_Brick_Pillar_Middle"
    },
    {
      "x": -1,
      "y": 4,
      "z": -3,
      "name": "Rock_Marble_Brick_Pillar_Middle"
    },
    {
      "x": -1,
      "y": 5,
      "z": -3,
      "name": "Rock_Marble_Brick_Pillar_Middle"
    },
    {
      "x": -1,
      "y": 6,
      "z": -3,
      "name": "Rock_Marble_Brick_Pillar_Base",
      "rotation": 34
    },
    {
      "x": -1,
      "y": 7,
      "z": -3,
      "name": "Rock_Marble_Brick"
    },
    {
      "x": -1,
      "y": 8,
      "z": -3,
      "name": "Rock_Marble_Brick"
    },
    {
      "x": -1,
      "y": 9,
      "z": -3,
      "name": "Rock_Marble_Brick_Pillar_Base"
    },
    {
      "x": -1,
      "y": 10,
      "z": -3,
      "name": "Rock_Marble_Brick_Pillar_Middle"
    },
    {
      "x": -1,
      "y": 11,
      "z": -3,
      "name": "Rock_Marble_Brick_Pillar_Middle"
    },
    {
      "x": -1,
      "y": 12,
      "z": -3,
      "name": "Rock_Marble_Brick_Pillar_Middle"
    },
    {
      "x": -1,
      "y": 13,
      "z": -3,
      "name": "Rock_Marble_Brick_Pillar_Base",
      "rotation": 34
    },
    {
      "x": -1,
      "y": 14,
      "z": -3,
      "name": "Rock_Marble_Brick"
    },
    {
      "x": -1,
      "y": 15,
      "z": -3,
      "name": "Rock_Marble_Half",
      "rotation": 6
    },
    {
      "x": -1,
      "y": -2,
      "z": -2,
      "name": "Soil_Grass_White"
    },
    {
      "x": -1,
      "y": -1,
      "z": -2,
      "name": "Soil_Grass_Full"
    },
    {
      "x": -1,
      "y": 0,
      "z": -2,
      "name": "Rock_Marble"
    },
    {
      "x": -1,
      "y": 1,
      "z": -2,
      "name": "Rock_Marble_Brick_Stairs",
      "rotation": 48
    },
    {
      "x": -1,
      "y": 2,
      "z": -2,
      "name": "Rock_Marble_Brick_Stairs",
      "rotation": 48
    },
    {
      "x": -1,
      "y": 3,
      "z": -2,
      "name": "Rock_Marble_Brick_Stairs",
      "rotation": 48
    },
    {
      "x": -1,
      "y": 4,
      "z": -2,
      "name": "Rock_Marble_Brick_Stairs",
      "rotation": 48
    },
    {
      "x": -1,
      "y": 5,
      "z": -2,
      "name": "Rock_Marble_Brick_Stairs",
      "rotation": 48
    },
    {
      "x": -1,
      "y": 6,
      "z": -2,
      "name": "Rock_Marble_Brick_Stairs",
      "rotation": 48
    },
    {
      "x": -1,
      "y": 7,
      "z": -2,
      "name": "Rock_Marble_Brick"
    },
    {
      "x": -1,
      "y": 8,
      "z": -2,
      "name": "Rock_Marble_Brick_Stairs",
      "rotation": 17
    },
    {
      "x": -1,
      "y": 9,
      "z": -2,
      "name": "Rock_Marble_Brick_Stairs",
      "rotation": 17
    },
    {
      "x": -1,
      "y": 10,
      "z": -2,
      "name": "Rock_Marble_Brick_Stairs",
      "rotation": 17
    },
    {
      "x": -1,
      "y": 11,
      "z": -2,
      "name": "Rock_Marble_Brick_Stairs",
      "rotation": 17
    },
    {
      "x": -1,
      "y": 12,
      "z": -2,
      "name": "Rock_Marble_Brick_Stairs",
      "rotation": 17
    },
    {
      "x": -1,
      "y": 13,
      "z": -2,
      "name": "Rock_Marble_Brick_Stairs",
      "rotation": 17
    },
    {
      "x": -1,
      "y": 14,
      "z": -2,
      "name": "Rock_Marble_Brick"
    },
    {
      "x": -1,
      "y": 15,
      "z": -2,
      "name": "Rock_Marble"
    },
    {
      "x": -1,
      "y": 16,
      "z": -2,
      "name": "Rock_Marble_Stairs",
      "rotation": 2
    },
    {
      "x": -1,
      "y": -2,
      "z": -1,
      "name": "Soil_Grass_White"
    },
    {
      "x": -1,
      "y": -1,
      "z": -1,
      "name": "Soil_Grass_Full"
    },
    {
      "x": -1,
      "y": 0,
      "z": -1,
      "name": "Rock_Marble"
    },
    {
      "x": -1,
      "y": 7,
      "z": -1,
      "name": "Rock_Marble_Brick"
    },
    {
      "x": -1,
      "y": 16,
      "z": -1,
      "name": "Rock_Marble"
    },
    {
      "x": -1,
      "y": 17,
      "z": -1,
      "name": "Rock_Marble_Half",
      "rotation": 3
    },
    {
      "x": -1,
      "y": -2,
      "z": 0,
      "name": "Soil_Grass_White"
    },
    {
      "x": -1,
      "y": -1,
      "z": 0,
      "name": "Soil_Grass_Full"
    },
    {
      "x": -1,
      "y": 0,
      "z": 0,
      "name": "Rock_Marble"
    },
    {
      "x": -1,
      "y": 7,
      "z": 0,
      "name": "Rock_Marble_Brick",
      "rotation": 1
    },
    {
      "x": -1,
      "y": 8,
      "z": 0,
      "name": "Rubble_Marble_Medium",
      "support": 15
    },
    {
      "x": -1,
      "y": 16,
      "z": 0,
      "name": "Rock_Marble"
    },
    {
      "x": -1,
      "y": 17,
      "z": 0,
      "name": "Rock_Marble_Half"
    },
    {
      "x": -1,
      "y": -2,
      "z": 1,
      "name": "Soil_Grass_White"
    },
    {
      "x": -1,
      "y": -1,
      "z": 1,
      "name": "Soil_Grass_Full"
    },
    {
      "x": -1,
      "y": 0,
      "z": 1,
      "name": "Rock_Marble"
    },
    {
      "x": -1,
      "y": 1,
      "z": 1,
      "name": "Rock_Marble_Brick_Stairs",
      "rotation": 49
    },
    {
      "x": -1,
      "y": 2,
      "z": 1,
      "name": "Rock_Marble_Brick_Stairs",
      "rotation": 49
    },
    {
      "x": -1,
      "y": 3,
      "z": 1,
      "name": "Rock_Marble_Brick_Stairs",
      "rotation": 49
    },
    {
      "x": -1,
      "y": 4,
      "z": 1,
      "name": "Rock_Marble_Brick_Stairs",
      "rotation": 49
    },
    {
      "x": -1,
      "y": 5,
      "z": 1,
      "name": "Rock_Marble_Brick_Stairs",
      "rotation": 49
    },
    {
      "x": -1,
      "y": 6,
      "z": 1,
      "name": "Rock_Marble_Brick_Stairs",
      "rotation": 49
    },
    {
      "x": -1,
      "y": 7,
      "z": 1,
      "name": "Rock_Marble_Brick",
      "rotation": 1
    },
    {
      "x": -1,
      "y": 8,
      "z": 1,
      "name": "Rock_Marble_Brick_Stairs",
      "rotation": 49
    },
    {
      "x": -1,
      "y": 14,
      "z": 1,
      "name": "Rock_Marble_Brick"
    },
    {
      "x": -1,
      "y": 15,
      "z": 1,
      "name": "Rock_Marble"
    },
    {
      "x": -1,
      "y": 16,
      "z": 1,
      "name": "Rock_Marble_Stairs",
      "rotation": 3
    },
    {
      "x": -1,
      "y": -2,
      "z": 2,
      "name": "Soil_Grass_White"
    },
    {
      "x": -1,
      "y": -1,
      "z": 2,
      "name": "Soil_Dirt_White"
    },
    {
      "x": -1,
      "y": 0,
      "z": 2,
      "name": "Soil_Dirt_White"
    },
    {
      "x": -1,
      "y": 1,
      "z": 2,
      "name": "Rock_Marble_Brick",
      "rotation": 1
    },
    {
      "x": -1,
      "y": 2,
      "z": 2,
      "name": "Rock_Marble_Brick_Pillar_Base",
      "rotation": 1
    },
    {
      "x": -1,
      "y": 3,
      "z": 2,
      "name": "Rock_Marble_Brick_Pillar_Middle",
      "rotation": 1
    },
    {
      "x": -1,
      "y": 4,
      "z": 2,
      "name": "Rock_Marble_Brick_Pillar_Middle",
      "rotation": 1
    },
    {
      "x": -1,
      "y": 5,
      "z": 2,
      "name": "Rock_Marble_Brick_Pillar_Middle",
      "rotation": 1
    },
    {
      "x": -1,
      "y": 6,
      "z": 2,
      "name": "Rock_Marble_Brick_Pillar_Base",
      "rotation": 35
    },
    {
      "x": -1,
      "y": 7,
      "z": 2,
      "name": "Rock_Marble_Brick",
      "rotation": 1
    },
    {
      "x": -1,
      "y": 8,
      "z": 2,
      "name": "Rock_Marble_Brick"
    },
    {
      "x": -1,
      "y": 9,
      "z": 2,
      "name": "Rock_Marble_Brick_Pillar_Base",
      "rotation": 1
    },
    {
      "x": -1,
      "y": 10,
      "z": 2,
      "name": "Rock_Marble_Brick_Pillar_Middle",
      "rotation": 1
    },
    {
      "x": -1,
      "y": 11,
      "z": 2,
      "name": "Rock_Marble_Brick_Pillar_Middle",
      "rotation": 1
    },
    {
      "x": -1,
      "y": 12,
      "z": 2,
      "name": "Rock_Marble_Brick_Pillar_Middle",
      "rotation": 1
    },
    {
      "x": -1,
      "y": 13,
      "z": 2,
      "name": "Rock_Marble_Brick_Pillar_Base",
      "rotation": 35
    },
    {
      "x": -1,
      "y": 14,
      "z": 2,
      "name": "Rock_Marble_Brick",
      "rotation": 2
    },
    {
      "x": -1,
      "y": 15,
      "z": 2,
      "name": "Rock_Marble_Half",
      "rotation": 4
    },
    {
      "x": -1,
      "y": -2,
      "z": 3,
      "name": "Soil_Grass_White"
    },
    {
      "x": -1,
      "y": -1,
      "z": 3,
      "name": "Soil_Grass_Full"
    },
    {
      "x": -1,
      "y": 0,
      "z": 3,
      "name": "Soil_Grass_Full"
    },
    {
      "x": -1,
      "y": 1,
      "z": 3,
      "name": "Rock_Marble_Half"
    },
    {
      "x": -1,
      "y": -2,
      "z": 4,
      "name": "Soil_Grass_White"
    },
    {
      "x": -1,
      "y": -1,
      "z": 4,
      "name": "Soil_Grass_Full"
    },
    {
      "x": -1,
      "y": 0,
      "z": 4,
      "name": "Soil_Grass_Full"
    },
    {
      "x": -1,
      "y": 1,
      "z": 4,
      "name": "Rock_Marble_Stairs",
      "rotation": 3
    },
    {
      "x": -1,
      "y": -2,
      "z": 5,
      "name": "Soil_Grass_White"
    },
    {
      "x": -1,
      "y": -1,
      "z": 5,
      "name": "Soil_Grass_Full"
    },
    {
      "x": -1,
      "y": 0,
      "z": 5,
      "name": "Soil_Grass_Full"
    },
    {
      "x": -1,
      "y": 1,
      "z": 5,
      "name": "Soil_Marble_Gravel_Half",
      "support": 15
    },
    {
      "x": -1,
      "y": -2,
      "z": 6,
      "name": "Soil_Grass_White"
    },
    {
      "x": -1,
      "y": -1,
      "z": 6,
      "name": "Soil_Grass_Full"
    },
    {
      "x": -1,
      "y": 0,
      "z": 6,
      "name": "Soil_Pebbles",
      "support": 15
    },
    {
      "x": -1,
      "y": -2,
      "z": 7,
      "name": "Soil_Grass_White"
    },
    {
      "x": -1,
      "y": -1,
      "z": 7,
      "name": "Soil_Dirt_White"
    },
    {
      "x": -1,
      "y": 0,
      "z": 7,
      "name": "Soil_Pebbles",
      "support": 15
    },
    {
      "x": -1,
      "y": -2,
      "z": 8,
      "name": "Soil_Grass_White"
    },
    {
      "x": -1,
      "y": -1,
      "z": 8,
      "name": "Soil_Grass_White"
    },
    {
      "x": -1,
      "y": 0,
      "z": 8,
      "name": "Soil_Pebbles"
    },
    {
      "x": 0,
      "y": -2,
      "z": -10,
      "name": "Soil_Grass_White"
    },
    {
      "x": 0,
      "y": -1,
      "z": -10,
      "name": "Soil_Grass_Full"
    },
    {
      "x": 0,
      "y": -2,
      "z": -9,
      "name": "Soil_Grass_White"
    },
    {
      "x": 0,
      "y": -1,
      "z": -9,
      "name": "Soil_Grass_Full"
    },
    {
      "x": 0,
      "y": -2,
      "z": -8,
      "name": "Soil_Grass_White"
    },
    {
      "x": 0,
      "y": -1,
      "z": -8,
      "name": "Soil_Grass_Full"
    },
    {
      "x": 0,
      "y": 0,
      "z": -8,
      "name": "Soil_Grass_Full"
    },
    {
      "x": 0,
      "y": -2,
      "z": -7,
      "name": "Soil_Grass_White"
    },
    {
      "x": 0,
      "y": -1,
      "z": -7,
      "name": "Soil_Grass_Full"
    },
    {
      "x": 0,
      "y": 0,
      "z": -7,
      "name": "Soil_Grass_Full"
    },
    {
      "x": 0,
      "y": -2,
      "z": -6,
      "name": "Soil_Grass_White"
    },
    {
      "x": 0,
      "y": -1,
      "z": -6,
      "name": "Soil_Grass_Full"
    },
    {
      "x": 0,
      "y": 0,
      "z": -6,
      "name": "Soil_Grass_Full"
    },
    {
      "x": 0,
      "y": -2,
      "z": -5,
      "name": "Soil_Grass_White"
    },
    {
      "x": 0,
      "y": -1,
      "z": -5,
      "name": "Soil_Grass_Full"
    },
    {
      "x": 0,
      "y": 0,
      "z": -5,
      "name": "Soil_Grass_Full"
    },
    {
      "x": 0,
      "y": -2,
      "z": -4,
      "name": "Soil_Grass_White"
    },
    {
      "x": 0,
      "y": -1,
      "z": -4,
      "name": "Soil_Grass_Full"
    },
    {
      "x": 0,
      "y": 0,
      "z": -4,
      "name": "Soil_Grass_Full"
    },
    {
      "x": 0,
      "y": 1,
      "z": -4,
      "name": "Plant_Grass_Lush"
    },
    {
      "x": 0,
      "y": 7,
      "z": -4,
      "name": "Rock_Marble_Brick_Half",
      "rotation": 6
    },
    {
      "x": 0,
      "y": 8,
      "z": -4,
      "name": "Rock_Marble_Brick_Half",
      "rotation": 6
    },
    {
      "x": 0,
      "y": 14,
      "z": -4,
      "name": "Rock_Marble_Brick_Half",
      "rotation": 6
    },
    {
      "x": 0,
      "y": -2,
      "z": -3,
      "name": "Soil_Grass_Full"
    },
    {
      "x": 0,
      "y": -1,
      "z": -3,
      "name": "Soil_Grass_Full"
    },
    {
      "x": 0,
      "y": 0,
      "z": -3,
      "name": "Rock_Marble"
    },
    {
      "x": 0,
      "y": 3,
      "z": -3,
      "name": "Rock_Chalk_Brick_Stairs",
      "rotation": 34
    },
    {
      "x": 0,
      "y": 4,
      "z": -3,
      "name": "Rock_Marble"
    },
    {
      "x": 0,
      "y": 5,
      "z": -3,
      "name": "Rock_Marble"
    },
    {
      "x": 0,
      "y": 6,
      "z": -3,
      "name": "Rock_Marble"
    },
    {
      "x": 0,
      "y": 7,
      "z": -3,
      "name": "Rock_Marble_Brick"
    },
    {
      "x": 0,
      "y": 8,
      "z": -3,
      "name": "Rock_Marble_Brick"
    },
    {
      "x": 0,
      "y": 9,
      "z": -3,
      "name": "Rock_Marble_Cobble",
      "rotation": 2
    },
    {
      "x": 0,
      "y": 10,
      "z": -3,
      "name": "Rock_Marble_Stairs",
      "rotation": 1
    },
    {
      "x": 0,
      "y": 11,
      "z": -3,
      "name": "Rock_Marble_Half",
      "rotation": 5
    },
    {
      "x": 0,
      "y": 12,
      "z": -3,
      "name": "Rock_Marble_Stairs",
      "rotation": 33
    },
    {
      "x": 0,
      "y": 13,
      "z": -3,
      "name": "Rock_Marble"
    },
    {
      "x": 0,
      "y": 14,
      "z": -3,
      "name": "Rock_Marble_Brick"
    },
    {
      "x": 0,
      "y": 15,
      "z": -3,
      "name": "Rock_Marble"
    },
    {
      "x": 0,
      "y": 16,
      "z": -3,
      "name": "Rock_Marble_Half",
      "rotation": 6
    },
    {
      "x": 0,
      "y": -2,
      "z": -2,
      "name": "Soil_Grass_Full"
    },
    {
      "x": 0,
      "y": -1,
      "z": -2,
      "name": "Soil_Grass_Full"
    },
    {
      "x": 0,
      "y": 0,
      "z": -2,
      "name": "Rock_Marble"
    },
    {
      "x": 0,
      "y": 7,
      "z": -2,
      "name": "Rock_Marble_Brick"
    },
    {
      "x": 0,
      "y": 16,
      "z": -2,
      "name": "Rock_Marble"
    },
    {
      "x": 0,
      "y": 17,
      "z": -2,
      "name": "Rock_Marble_Half",
      "rotation": 3
    },
    {
      "x": 0,
      "y": -2,
      "z": -1,
      "name": "Soil_Grass_Full"
    },
    {
      "x": 0,
      "y": -1,
      "z": -1,
      "name": "Soil_Grass_Full"
    },
    {
      "x": 0,
      "y": 0,
      "z": -1,
      "name": "Rock_Marble"
    },
    {
      "x": 0,
      "y": 7,
      "z": -1,
      "name": "Rock_Marble_Brick"
    },
    {
      "x": 0,
      "y": 16,
      "z": -1,
      "name": "Rock_Marble"
    },
    {
      "x": 0,
      "y": 17,
      "z": -1,
      "name": "Rock_Marble"
    },
    {
      "x": 0,
      "y": -2,
      "z": 0,
      "name": "Soil_Grass_White"
    },
    {
      "x": 0,
      "y": -1,
      "z": 0,
      "name": "Soil_Grass_Full"
    },
    {
      "x": 0,
      "y": 0,
      "z": 0,
      "name": "Rock_Marble"
    },
    {
      "x": 0,
      "y": 7,
      "z": 0,
      "name": "Rock_Marble_Brick",
      "rotation": 1
    },
    {
      "x": 0,
      "y": 16,
      "z": 0,
      "name": "Rock_Marble"
    },
    {
      "x": 0,
      "y": 17,
      "z": 0,
      "name": "Rock_Marble"
    },
    {
      "x": 0,
      "y": -2,
      "z": 1,
      "name": "Soil_Grass_White"
    },
    {
      "x": 0,
      "y": -1,
      "z": 1,
      "name": "Soil_Grass_Full"
    },
    {
      "x": 0,
      "y": 0,
      "z": 1,
      "name": "Rock_Marble"
    },
    {
      "x": 0,
      "y": 7,
      "z": 1,
      "name": "Rock_Marble_Brick",
      "rotation": 1
    },
    {
      "x": 0,
      "y": 16,
      "z": 1,
      "name": "Rock_Marble"
    },
    {
      "x": 0,
      "y": 17,
      "z": 1,
      "name": "Rock_Marble_Half"
    },
    {
      "x": 0,
      "y": -2,
      "z": 2,
      "name": "Soil_Grass_White"
    },
    {
      "x": 0,
      "y": -1,
      "z": 2,
      "name": "Soil_Dirt_White"
    },
    {
      "x": 0,
      "y": 0,
      "z": 2,
      "name": "Soil_Dirt_White"
    },
    {
      "x": 0,
      "y": 1,
      "z": 2,
      "name": "Rock_Marble_Brick",
      "rotation": 1
    },
    {
      "x": 0,
      "y": 2,
      "z": 2,
      "name": "Rock_Marble"
    },
    {
      "x": 0,
      "y": 3,
      "z": 2,
      "name": "Rock_Marble"
    },
    {
      "x": 0,
      "y": 4,
      "z": 2,
      "name": "Rock_Marble"
    },
    {
      "x": 0,
      "y": 5,
      "z": 2,
      "name": "Rock_Marble"
    },
    {
      "x": 0,
      "y": 6,
      "z": 2,
      "name": "Rock_Marble"
    },
    {
      "x": 0,
      "y": 7,
      "z": 2,
      "name": "Rock_Marble_Brick",
      "rotation": 1
    },
    {
      "x": 0,
      "y": 8,
      "z": 2,
      "name": "Rock_Marble_Brick",
      "rotation": 1
    },
    {
      "x": 0,
      "y": 9,
      "z": 2,
      "name": "Rock_Marble_Cobble"
    },
    {
      "x": 0,
      "y": 10,
      "z": 2,
      "name": "Rock_Marble_Stairs",
      "rotation": 1
    },
    {
      "x": 0,
      "y": 11,
      "z": 2,
      "name": "Rock_Marble_Half",
      "rotation": 5
    },
    {
      "x": 0,
      "y": 12,
      "z": 2,
      "name": "Rock_Marble_Stairs",
      "rotation": 33
    },
    {
      "x": 0,
      "y": 13,
      "z": 2,
      "name": "Rock_Marble"
    },
    {
      "x": 0,
      "y": 14,
      "z": 2,
      "name": "Rock_Marble_Brick",
      "rotation": 2
    },
    {
      "x": 0,
      "y": 15,
      "z": 2,
      "name": "Rock_Marble"
    },
    {
      "x": 0,
      "y": 16,
      "z": 2,
      "name": "Rock_Marble_Half",
      "rotation": 4
    },
    {
      "x": 0,
      "y": -2,
      "z": 3,
      "name": "Soil_Grass_White"
    },
    {
      "x": 0,
      "y": -1,
      "z": 3,
      "name": "Soil_Dirt_White"
    },
    {
      "x": 0,
      "y": 0,
      "z": 3,
      "name": "Soil_Dirt_White"
    },
    {
      "x": 0,
      "y": 1,
      "z": 3,
      "name": "Rock_Marble"
    },
    {
      "x": 0,
      "y": 2,
      "z": 3,
      "name": "Rock_Marble"
    },
    {
      "x": 0,
      "y": 3,
      "z": 3,
      "name": "Rock_Marble"
    },
    {
      "x": 0,
      "y": 4,
      "z": 3,
      "name": "Rock_Marble_Cobble"
    },
    {
      "x": 0,
      "y": 5,
      "z": 3,
      "name": "Rock_Marble_Cobble"
    },
    {
      "x": 0,
      "y": 6,
      "z": 3,
      "name": "Rubble_Marble",
      "support": 15
    },
    {
      "x": 0,
      "y": -2,
      "z": 4,
      "name": "Soil_Grass_White"
    },
    {
      "x": 0,
      "y": -1,
      "z": 4,
      "name": "Soil_Grass_Full"
    },
    {
      "x": 0,
      "y": 0,
      "z": 4,
      "name": "Soil_Grass_Full"
    },
    {
      "x": 0,
      "y": 1,
      "z": 4,
      "name": "Rock_Marble"
    },
    {
      "x": 0,
      "y": 2,
      "z": 4,
      "name": "Rock_Marble"
    },
    {
      "x": 0,
      "y": 3,
      "z": 4,
      "name": "Rock_Marble_Cobble"
    },
    {
      "x": 0,
      "y": 4,
      "z": 4,
      "name": "Soil_Pebbles",
      "support": 15
    },
    {
      "x": 0,
      "y": 5,
      "z": 4,
      "name": "Rock_Marble_Stairs",
      "rotation": 10
    },
    {
      "x": 0,
      "y": -2,
      "z": 5,
      "name": "Soil_Grass_White"
    },
    {
      "x": 0,
      "y": -1,
      "z": 5,
      "name": "Soil_Grass_Full"
    },
    {
      "x": 0,
      "y": 0,
      "z": 5,
      "name": "Soil_Grass_Full"
    },
    {
      "x": 0,
      "y": 1,
      "z": 5,
      "name": "Rock_Marble"
    },
    {
      "x": 0,
      "y": 2,
      "z": 5,
      "name": "Rock_Marble_Cobble"
    },
    {
      "x": 0,
      "y": 3,
      "z": 5,
      "name": "Soil_Pebbles",
      "support": 15
    },
    {
      "x": 0,
      "y": 4,
      "z": 5,
      "name": "Rubble_Marble_Medium",
      "support": 15
    },
    {
      "x": 0,
      "y": -2,
      "z": 6,
      "name": "Soil_Grass_White"
    },
    {
      "x": 0,
      "y": -1,
      "z": 6,
      "name": "Soil_Grass_Full"
    },
    {
      "x": 0,
      "y": 0,
      "z": 6,
      "name": "Soil_Grass_Full"
    },
    {
      "x": 0,
      "y": 1,
      "z": 6,
      "name": "Rock_Marble"
    },
    {
      "x": 0,
      "y": 2,
      "z": 6,
      "name": "Rock_Marble_Cobble"
    },
    {
      "x": 0,
      "y": 3,
      "z": 6,
      "name": "Rock_Marble_Stairs"
    },
    {
      "x": 0,
      "y": -2,
      "z": 7,
      "name": "Soil_Grass_White"
    },
    {
      "x": 0,
      "y": -1,
      "z": 7,
      "name": "Soil_Dirt_White"
    },
    {
      "x": 0,
      "y": 0,
      "z": 7,
      "name": "Soil_Dirt_White"
    },
    {
      "x": 0,
      "y": 1,
      "z": 7,
      "name": "Rock_Marble"
    },
    {
      "x": 0,
      "y": -2,
      "z": 8,
      "name": "Soil_Grass_White"
    },
    {
      "x": 0,
      "y": -1,
      "z": 8,
      "name": "Soil_Grass_White"
    },
    {
      "x": 0,
      "y": 0,
      "z": 8,
      "name": "Rock_Marble"
    },
    {
      "x": 1,
      "y": -2,
      "z": -10,
      "name": "Soil_Grass_White"
    },
    {
      "x": 1,
      "y": -2,
      "z": -9,
      "name": "Soil_Grass_White"
    },
    {
      "x": 1,
      "y": -1,
      "z": -9,
      "name": "Soil_Grass_Full"
    },
    {
      "x": 1,
      "y": -2,
      "z": -8,
      "name": "Soil_Grass_White"
    },
    {
      "x": 1,
      "y": -1,
      "z": -8,
      "name": "Soil_Grass_Full"
    },
    {
      "x": 1,
      "y": 0,
      "z": -8,
      "name": "Soil_Grass_Full"
    },
    {
      "x": 1,
      "y": -2,
      "z": -7,
      "name": "Soil_Grass_White"
    },
    {
      "x": 1,
      "y": -1,
      "z": -7,
      "name": "Soil_Grass_Full"
    },
    {
      "x": 1,
      "y": 0,
      "z": -7,
      "name": "Soil_Grass_Full"
    },
    {
      "x": 1,
      "y": -2,
      "z": -6,
      "name": "Soil_Grass_White"
    },
    {
      "x": 1,
      "y": -1,
      "z": -6,
      "name": "Soil_Grass_Full"
    },
    {
      "x": 1,
      "y": 0,
      "z": -6,
      "name": "Soil_Grass_Full"
    },
    {
      "x": 1,
      "y": 1,
      "z": -6,
      "name": "Plant_Grass_Sharp"
    },
    {
      "x": 1,
      "y": -2,
      "z": -5,
      "name": "Soil_Grass_White"
    },
    {
      "x": 1,
      "y": -1,
      "z": -5,
      "name": "Soil_Grass_Full"
    },
    {
      "x": 1,
      "y": 0,
      "z": -5,
      "name": "Soil_Grass_Full"
    },
    {
      "x": 1,
      "y": -2,
      "z": -4,
      "name": "Soil_Grass_White"
    },
    {
      "x": 1,
      "y": -1,
      "z": -4,
      "name": "Soil_Grass_Full"
    },
    {
      "x": 1,
      "y": 0,
      "z": -4,
      "name": "Soil_Grass_Full"
    },
    {
      "x": 1,
      "y": 1,
      "z": -4,
      "name": "Plant_Grass_Lush",
      "rotation": 2
    },
    {
      "x": 1,
      "y": 7,
      "z": -4,
      "name": "Rock_Marble_Brick_Half",
      "rotation": 6
    },
    {
      "x": 1,
      "y": 8,
      "z": -4,
      "name": "Rock_Marble_Brick_Half",
      "rotation": 6
    },
    {
      "x": 1,
      "y": 14,
      "z": -4,
      "name": "Rock_Marble_Brick_Half",
      "rotation": 6
    },
    {
      "x": 1,
      "y": -2,
      "z": -3,
      "name": "Soil_Grass_White"
    },
    {
      "x": 1,
      "y": -1,
      "z": -3,
      "name": "Soil_Grass_Full"
    },
    {
      "x": 1,
      "y": 0,
      "z": -3,
      "name": "Rock_Marble"
    },
    {
      "x": 1,
      "y": 4,
      "z": -3,
      "name": "Rubble_Marble_Medium",
      "rotation": 32
    },
    {
      "x": 1,
      "y": 5,
      "z": -3,
      "name": "Rock_Marble"
    },
    {
      "x": 1,
      "y": 6,
      "z": -3,
      "name": "Rock_Marble"
    },
    {
      "x": 1,
      "y": 7,
      "z": -3,
      "name": "Rock_Marble_Brick",
      "rotation": 3
    },
    {
      "x": 1,
      "y": 8,
      "z": -3,
      "name": "Rock_Marble_Brick",
      "rotation": 3
    },
    {
      "x": 1,
      "y": 9,
      "z": -3,
      "name": "Rock_Marble_Cobble",
      "rotation": 2
    },
    {
      "x": 1,
      "y": 10,
      "z": -3,
      "name": "Rock_Marble_Stairs",
      "rotation": 3
    },
    {
      "x": 1,
      "y": 11,
      "z": -3,
      "name": "Rock_Marble_Half",
      "rotation": 7
    },
    {
      "x": 1,
      "y": 12,
      "z": -3,
      "name": "Rock_Marble_Stairs",
      "rotation": 35
    },
    {
      "x": 1,
      "y": 13,
      "z": -3,
      "name": "Rock_Marble"
    },
    {
      "x": 1,
      "y": 14,
      "z": -3,
      "name": "Rock_Marble_Brick"
    },
    {
      "x": 1,
      "y": 15,
      "z": -3,
      "name": "Rock_Marble"
    },
    {
      "x": 1,
      "y": 16,
      "z": -3,
      "name": "Rock_Marble_Half",
      "rotation": 6
    },
    {
      "x": 1,
      "y": -2,
      "z": -2,
      "name": "Soil_Grass_White"
    },
    {
      "x": 1,
      "y": -1,
      "z": -2,
      "name": "Soil_Grass_Full"
    },
    {
      "x": 1,
      "y": 0,
      "z": -2,
      "name": "Rock_Marble"
    },
    {
      "x": 1,
      "y": 7,
      "z": -2,
      "name": "Rock_Marble_Brick",
      "rotation": 3
    },
    {
      "x": 1,
      "y": 8,
      "z": -2,
      "name": "Block_Spawner_Block",
      "components": {
        "Components": {
          "PlacedByInteraction": {
            "WhoPlacedUuid": {
              "$binary": "+u0Lek23TWiDpMOn5L2LqA==",
              "$type": "04"
            }
          },
          "BlockSpawner": {
            "BlockSpawnerId": "Zone4_Encounters_Tier4"
          }
        }
      }
    },
    {
      "x": 1,
      "y": 16,
      "z": -2,
      "name": "Rock_Marble"
    },
    {
      "x": 1,
      "y": 17,
      "z": -2,
      "name": "Rock_Marble_Half",
      "rotation": 2
    },
    {
      "x": 1,
      "y": -2,
      "z": -1,
      "name": "Soil_Grass_Full"
    },
    {
      "x": 1,
      "y": -1,
      "z": -1,
      "name": "Soil_Grass_Full"
    },
    {
      "x": 1,
      "y": 0,
      "z": -1,
      "name": "Rock_Marble"
    },
    {
      "x": 1,
      "y": 7,
      "z": -1,
      "name": "Rock_Marble_Brick",
      "rotation": 3
    },
    {
      "x": 1,
      "y": 8,
      "z": -1,
      "name": "Rubble_Marble_Medium",
      "support": 15,
      "rotation": 2
    },
    {
      "x": 1,
      "y": 16,
      "z": -1,
      "name": "Rock_Marble"
    },
    {
      "x": 1,
      "y": 17,
      "z": -1,
      "name": "Rock_Marble"
    },
    {
      "x": 1,
      "y": -2,
      "z": 0,
      "name": "Soil_Grass_White"
    },
    {
      "x": 1,
      "y": -1,
      "z": 0,
      "name": "Soil_Grass_Full"
    },
    {
      "x": 1,
      "y": 0,
      "z": 0,
      "name": "Rock_Marble"
    },
    {
      "x": 1,
      "y": 7,
      "z": 0,
      "name": "Rock_Marble_Brick",
      "rotation": 3
    },
    {
      "x": 1,
      "y": 16,
      "z": 0,
      "name": "Rock_Marble"
    },
    {
      "x": 1,
      "y": 17,
      "z": 0,
      "name": "Rock_Marble"
    },
    {
      "x": 1,
      "y": -2,
      "z": 1,
      "name": "Soil_Grass_White"
    },
    {
      "x": 1,
      "y": -1,
      "z": 1,
      "name": "Soil_Grass_Full"
    },
    {
      "x": 1,
      "y": 0,
      "z": 1,
      "name": "Rock_Marble"
    },
    {
      "x": 1,
      "y": 7,
      "z": 1,
      "name": "Rock_Marble_Brick",
      "rotation": 2
    },
    {
      "x": 1,
      "y": 16,
      "z": 1,
      "name": "Rock_Marble"
    },
    {
      "x": 1,
      "y": 17,
      "z": 1,
      "name": "Rock_Marble_Half",
      "rotation": 1
    },
    {
      "x": 1,
      "y": -2,
      "z": 2,
      "name": "Soil_Grass_White"
    },
    {
      "x": 1,
      "y": -1,
      "z": 2,
      "name": "Soil_Dirt_White"
    },
    {
      "x": 1,
      "y": 0,
      "z": 2,
      "name": "Soil_Dirt_White"
    },
    {
      "x": 1,
      "y": 1,
      "z": 2,
      "name": "Rock_Marble_Brick",
      "rotation": 2
    },
    {
      "x": 1,
      "y": 2,
      "z": 2,
      "name": "Rock_Marble"
    },
    {
      "x": 1,
      "y": 3,
      "z": 2,
      "name": "Rock_Marble"
    },
    {
      "x": 1,
      "y": 4,
      "z": 2,
      "name": "Rock_Marble"
    },
    {
      "x": 1,
      "y": 5,
      "z": 2,
      "name": "Rock_Marble"
    },
    {
      "x": 1,
      "y": 6,
      "z": 2,
      "name": "Rock_Marble"
    },
    {
      "x": 1,
      "y": 7,
      "z": 2,
      "name": "Rock_Marble_Brick",
      "rotation": 2
    },
    {
      "x": 1,
      "y": 8,
      "z": 2,
      "name": "Rock_Marble_Brick",
      "rotation": 2
    },
    {
      "x": 1,
      "y": 9,
      "z": 2,
      "name": "Rock_Marble_Cobble"
    },
    {
      "x": 1,
      "y": 10,
      "z": 2,
      "name": "Rock_Marble_Stairs",
      "rotation": 3
    },
    {
      "x": 1,
      "y": 11,
      "z": 2,
      "name": "Rock_Marble_Half",
      "rotation": 7
    },
    {
      "x": 1,
      "y": 12,
      "z": 2,
      "name": "Rock_Marble_Stairs",
      "rotation": 35
    },
    {
      "x": 1,
      "y": 13,
      "z": 2,
      "name": "Rock_Marble"
    },
    {
      "x": 1,
      "y": 14,
      "z": 2,
      "name": "Rock_Marble_Brick",
      "rotation": 2
    },
    {
      "x": 1,
      "y": 15,
      "z": 2,
      "name": "Rock_Marble"
    },
    {
      "x": 1,
      "y": 16,
      "z": 2,
      "name": "Rock_Marble_Half",
      "rotation": 4
    },
    {
      "x": 1,
      "y": -2,
      "z": 3,
      "name": "Soil_Grass_White"
    },
    {
      "x": 1,
      "y": -1,
      "z": 3,
      "name": "Soil_Dirt_White"
    },
    {
      "x": 1,
      "y": 0,
      "z": 3,
      "name": "Soil_Dirt_White"
    },
    {
      "x": 1,
      "y": 1,
      "z": 3,
      "name": "Rock_Marble"
    },
    {
      "x": 1,
      "y": 2,
      "z": 3,
      "name": "Rock_Marble"
    },
    {
      "x": 1,
      "y": 3,
      "z": 3,
      "name": "Rock_Marble"
    },
    {
      "x": 1,
      "y": 4,
      "z": 3,
      "name": "Soil_Pebbles",
      "support": 15
    },
    {
      "x": 1,
      "y": 5,
      "z": 3,
      "name": "Rock_Marble_Cobble"
    },
    {
      "x": 1,
      "y": 6,
      "z": 3,
      "name": "Rock_Marble_Stairs"
    },
    {
      "x": 1,
      "y": -2,
      "z": 4,
      "name": "Soil_Grass_White"
    },
    {
      "x": 1,
      "y": -1,
      "z": 4,
      "name": "Soil_Grass_Full"
    },
    {
      "x": 1,
      "y": 0,
      "z": 4,
      "name": "Soil_Grass_Full"
    },
    {
      "x": 1,
      "y": 1,
      "z": 4,
      "name": "Rock_Marble_Cobble"
    },
    {
      "x": 1,
      "y": 2,
      "z": 4,
      "name": "Rock_Marble"
    },
    {
      "x": 1,
      "y": 3,
      "z": 4,
      "name": "Rock_Marble"
    },
    {
      "x": 1,
      "y": 4,
      "z": 4,
      "name": "Rock_Marble_Cobble"
    },
    {
      "x": 1,
      "y": -2,
      "z": 5,
      "name": "Soil_Grass_White"
    },
    {
      "x": 1,
      "y": -1,
      "z": 5,
      "name": "Soil_Grass_Full"
    },
    {
      "x": 1,
      "y": 0,
      "z": 5,
      "name": "Soil_Grass_Full"
    },
    {
      "x": 1,
      "y": 1,
      "z": 5,
      "name": "Rock_Marble"
    },
    {
      "x": 1,
      "y": 2,
      "z": 5,
      "name": "Rock_Marble"
    },
    {
      "x": 1,
      "y": 3,
      "z": 5,
      "name": "Rock_Marble"
    },
    {
      "x": 1,
      "y": 4,
      "z": 5,
      "name": "Rock_Marble_Stairs"
    },
    {
      "x": 1,
      "y": -2,
      "z": 6,
      "name": "Soil_Grass_White"
    },
    {
      "x": 1,
      "y": -1,
      "z": 6,
      "name": "Soil_Grass_Full"
    },
    {
      "x": 1,
      "y": 0,
      "z": 6,
      "name": "Soil_Dirt_White"
    },
    {
      "x": 1,
      "y": 1,
      "z": 6,
      "name": "Rock_Marble"
    },
    {
      "x": 1,
      "y": 2,
      "z": 6,
      "name": "Rock_Marble_Cobble"
    },
    {
      "x": 1,
      "y": -2,
      "z": 7,
      "name": "Soil_Grass_White"
    },
    {
      "x": 1,
      "y": -1,
      "z": 7,
      "name": "Soil_Pebbles"
    },
    {
      "x": 1,
      "y": 0,
      "z": 7,
      "name": "Soil_Pebbles",
      "support": 15
    },
    {
      "x": 1,
      "y": 1,
      "z": 7,
      "name": "Rock_Marble"
    },
    {
      "x": 1,
      "y": -2,
      "z": 8,
      "name": "Soil_Grass_White"
    },
    {
      "x": 2,
      "y": -2,
      "z": -10,
      "name": "Soil_Grass_White"
    },
    {
      "x": 2,
      "y": -2,
      "z": -9,
      "name": "Soil_Grass_White"
    },
    {
      "x": 2,
      "y": -1,
      "z": -9,
      "name": "Soil_Grass_White"
    },
    {
      "x": 2,
      "y": -2,
      "z": -8,
      "name": "Soil_Grass_White"
    },
    {
      "x": 2,
      "y": -1,
      "z": -8,
      "name": "Soil_Grass_Full"
    },
    {
      "x": 2,
      "y": -2,
      "z": -7,
      "name": "Soil_Grass_White"
    },
    {
      "x": 2,
      "y": -1,
      "z": -7,
      "name": "Soil_Grass_Full"
    },
    {
      "x": 2,
      "y": 0,
      "z": -7,
      "name": "Soil_Grass_Full"
    },
    {
      "x": 2,
      "y": 1,
      "z": -7,
      "name": "Plant_Grass_Sharp"
    },
    {
      "x": 2,
      "y": -2,
      "z": -6,
      "name": "Soil_Grass_White"
    },
    {
      "x": 2,
      "y": -1,
      "z": -6,
      "name": "Soil_Grass_Full"
    },
    {
      "x": 2,
      "y": 0,
      "z": -6,
      "name": "Soil_Grass_Full"
    },
    {
      "x": 2,
      "y": 1,
      "z": -6,
      "name": "Plant_Grass_Sharp"
    },
    {
      "x": 2,
      "y": -2,
      "z": -5,
      "name": "Soil_Grass_White"
    },
    {
      "x": 2,
      "y": -1,
      "z": -5,
      "name": "Soil_Grass_Full"
    },
    {
      "x": 2,
      "y": 0,
      "z": -5,
      "name": "Soil_Grass_Full"
    },
    {
      "x": 2,
      "y": 1,
      "z": -5,
      "name": "Plant_Grass_Sharp"
    },
    {
      "x": 2,
      "y": -2,
      "z": -4,
      "name": "Soil_Grass_White"
    },
    {
      "x": 2,
      "y": -1,
      "z": -4,
      "name": "Soil_Grass_Full"
    },
    {
      "x": 2,
      "y": 0,
      "z": -4,
      "name": "Soil_Grass_Full"
    },
    {
      "x": 2,
      "y": 1,
      "z": -4,
      "name": "Plant_Grass_Lush",
      "rotation": 2
    },
    {
      "x": 2,
      "y": 7,
      "z": -4,
      "name": "Rock_Marble_Brick_Half",
      "rotation": 6
    },
    {
      "x": 2,
      "y": -2,
      "z": -3,
      "name": "Soil_Grass_White"
    },
    {
      "x": 2,
      "y": 0,
      "z": -3,
      "name": "Soil_Dirt_White"
    },
    {
      "x": 2,
      "y": 1,
      "z": -3,
      "name": "Rock_Marble_Brick",
      "rotation": 3
    },
    {
      "x": 2,
      "y": 2,
      "z": -3,
      "name": "Rock_Marble_Brick_Pillar_Base",
      "rotation": 3
    },
    {
      "x": 2,
      "y": 3,
      "z": -3,
      "name": "Rock_Marble_Brick_Pillar_Middle",
      "rotation": 3
    },
    {
      "x": 2,
      "y": 4,
      "z": -3,
      "name": "Rock_Marble_Brick_Pillar_Middle",
      "rotation": 3
    },
    {
      "x": 2,
      "y": 5,
      "z": -3,
      "name": "Rock_Marble_Brick_Pillar_Middle",
      "rotation": 3
    },
    {
      "x": 2,
      "y": 6,
      "z": -3,
      "name": "Rock_Marble_Brick_Pillar_Base",
      "rotation": 33
    },
    {
      "x": 2,
      "y": 7,
      "z": -3,
      "name": "Rock_Marble_Brick",
      "rotation": 3
    },
    {
      "x": 2,
      "y": 8,
      "z": -3,
      "name": "Rock_Marble_Brick",
      "rotation": 3
    },
    {
      "x": 2,
      "y": 9,
      "z": -3,
      "name": "Rock_Marble_Brick_Pillar_Base",
      "rotation": 3
    },
    {
      "x": 2,
      "y": 10,
      "z": -3,
      "name": "Rock_Marble_Brick_Pillar_Middle",
      "rotation": 3
    },
    {
      "x": 2,
      "y": 11,
      "z": -3,
      "name": "Rock_Marble_Brick_Pillar_Middle",
      "rotation": 3
    },
    {
      "x": 2,
      "y": 12,
      "z": -3,
      "name": "Rock_Marble_Brick_Pillar_Middle",
      "rotation": 3
    },
    {
      "x": 2,
      "y": 13,
      "z": -3,
      "name": "Rock_Marble_Brick_Pillar_Base",
      "rotation": 33
    },
    {
      "x": 2,
      "y": 14,
      "z": -3,
      "name": "Rock_Marble_Brick"
    },
    {
      "x": 2,
      "y": 15,
      "z": -3,
      "name": "Rock_Marble_Half",
      "rotation": 6
    },
    {
      "x": 2,
      "y": -2,
      "z": -2,
      "name": "Soil_Grass_White"
    },
    {
      "x": 2,
      "y": -1,
      "z": -2,
      "name": "Soil_Grass_Full"
    },
    {
      "x": 2,
      "y": 0,
      "z": -2,
      "name": "Rock_Marble"
    },
    {
      "x": 2,
      "y": 1,
      "z": -2,
      "name": "Rock_Marble_Brick_Stairs",
      "rotation": 51
    },
    {
      "x": 2,
      "y": 2,
      "z": -2,
      "name": "Rock_Marble_Brick_Stairs",
      "rotation": 51
    },
    {
      "x": 2,
      "y": 3,
      "z": -2,
      "name": "Rock_Marble_Brick_Stairs",
      "rotation": 51
    },
    {
      "x": 2,
      "y": 4,
      "z": -2,
      "name": "Rock_Marble_Brick_Stairs",
      "rotation": 51
    },
    {
      "x": 2,
      "y": 5,
      "z": -2,
      "name": "Rock_Marble_Brick_Stairs",
      "rotation": 51
    },
    {
      "x": 2,
      "y": 6,
      "z": -2,
      "name": "Rock_Marble_Brick_Stairs",
      "rotation": 51
    },
    {
      "x": 2,
      "y": 7,
      "z": -2,
      "name": "Rock_Marble_Brick",
      "rotation": 3
    },
    {
      "x": 2,
      "y": 8,
      "z": -2,
      "name": "Rock_Marble_Brick_Stairs",
      "rotation": 51
    },
    {
      "x": 2,
      "y": 9,
      "z": -2,
      "name": "Rock_Marble_Brick_Stairs",
      "rotation": 51
    },
    {
      "x": 2,
      "y": 10,
      "z": -2,
      "name": "Rock_Marble_Brick_Stairs",
      "rotation": 51
    },
    {
      "x": 2,
      "y": 11,
      "z": -2,
      "name": "Rock_Marble_Brick_Stairs",
      "rotation": 51
    },
    {
      "x": 2,
      "y": 12,
      "z": -2,
      "name": "Rock_Marble_Brick_Stairs",
      "rotation": 51
    },
    {
      "x": 2,
      "y": 13,
      "z": -2,
      "name": "Rock_Marble_Brick_Stairs",
      "rotation": 51
    },
    {
      "x": 2,
      "y": 14,
      "z": -2,
      "name": "Rock_Marble_Brick"
    },
    {
      "x": 2,
      "y": 15,
      "z": -2,
      "name": "Rock_Marble"
    },
    {
      "x": 2,
      "y": 16,
      "z": -2,
      "name": "Rock_Marble_Stairs",
      "rotation": 1
    },
    {
      "x": 2,
      "y": -2,
      "z": -1,
      "name": "Soil_Grass_White"
    },
    {
      "x": 2,
      "y": -1,
      "z": -1,
      "name": "Soil_Grass_Full"
    },
    {
      "x": 2,
      "y": 0,
      "z": -1,
      "name": "Rock_Marble"
    },
    {
      "x": 2,
      "y": 7,
      "z": -1,
      "name": "Rock_Marble_Brick",
      "rotation": 3
    },
    {
      "x": 2,
      "y": 8,
      "z": -1,
      "name": "Rock_Chalk_Brick_Stairs",
      "rotation": 3
    },
    {
      "x": 2,
      "y": 16,
      "z": -1,
      "name": "Rock_Marble"
    },
    {
      "x": 2,
      "y": 17,
      "z": -1,
      "name": "Rock_Marble_Half",
      "rotation": 2
    },
    {
      "x": 2,
      "y": -2,
      "z": 0,
      "name": "Soil_Grass_White"
    },
    {
      "x": 2,
      "y": -1,
      "z": 0,
      "name": "Soil_Grass_Full"
    },
    {
      "x": 2,
      "y": 0,
      "z": 0,
      "name": "Rock_Marble"
    },
    {
      "x": 2,
      "y": 7,
      "z": 0,
      "name": "Rock_Marble_Brick",
      "rotation": 3
    },
    {
      "x": 2,
      "y": 16,
      "z": 0,
      "name": "Rock_Marble"
    },
    {
      "x": 2,
      "y": 17,
      "z": 0,
      "name": "Rock_Marble_Half",
      "rotation": 1
    },
    {
      "x": 2,
      "y": -2,
      "z": 1,
      "name": "Soil_Grass_White"
    },
    {
      "x": 2,
      "y": -1,
      "z": 1,
      "name": "Soil_Grass_Full"
    },
    {
      "x": 2,
      "y": 0,
      "z": 1,
      "name": "Rock_Marble"
    },
    {
      "x": 2,
      "y": 1,
      "z": 1,
      "name": "Rock_Marble_Brick_Stairs",
      "rotation": 50
    },
    {
      "x": 2,
      "y": 2,
      "z": 1,
      "name": "Rock_Marble_Brick_Stairs",
      "rotation": 50
    },
    {
      "x": 2,
      "y": 3,
      "z": 1,
      "name": "Rock_Marble_Brick_Stairs",
      "rotation": 50
    },
    {
      "x": 2,
      "y": 4,
      "z": 1,
      "name": "Rock_Marble_Brick_Stairs",
      "rotation": 50
    },
    {
      "x": 2,
      "y": 5,
      "z": 1,
      "name": "Rock_Marble_Brick_Stairs",
      "rotation": 50
    },
    {
      "x": 2,
      "y": 6,
      "z": 1,
      "name": "Rock_Marble_Brick_Stairs",
      "rotation": 50
    },
    {
      "x": 2,
      "y": 7,
      "z": 1,
      "name": "Rock_Marble_Brick",
      "rotation": 2
    },
    {
      "x": 2,
      "y": 8,
      "z": 1,
      "name": "Rock_Marble_Brick_Stairs",
      "rotation": 50
    },
    {
      "x": 2,
      "y": 9,
      "z": 1,
      "name": "Rock_Marble_Brick_Stairs",
      "rotation": 50
    },
    {
      "x": 2,
      "y": -2,
      "z": 2,
      "name": "Soil_Grass_White"
    },
    {
      "x": 2,
      "y": 0,
      "z": 2,
      "name": "Soil_Dirt_White"
    },
    {
      "x": 2,
      "y": 1,
      "z": 2,
      "name": "Rock_Marble_Brick",
      "rotation": 2
    },
    {
      "x": 2,
      "y": 2,
      "z": 2,
      "name": "Rock_Marble_Brick_Pillar_Base",
      "rotation": 2
    },
    {
      "x": 2,
      "y": 3,
      "z": 2,
      "name": "Rock_Marble_Brick_Pillar_Middle",
      "rotation": 2
    },
    {
      "x": 2,
      "y": 4,
      "z": 2,
      "name": "Rock_Marble_Brick_Pillar_Middle",
      "rotation": 2
    },
    {
      "x": 2,
      "y": 5,
      "z": 2,
      "name": "Rock_Marble_Brick_Pillar_Middle",
      "rotation": 2
    },
    {
      "x": 2,
      "y": 6,
      "z": 2,
      "name": "Rock_Marble_Brick_Pillar_Base",
      "rotation": 32
    },
    {
      "x": 2,
      "y": 7,
      "z": 2,
      "name": "Rock_Marble_Brick",
      "rotation": 2
    },
    {
      "x": 2,
      "y": 8,
      "z": 2,
      "name": "Rock_Marble_Brick",
      "rotation": 2
    },
    {
      "x": 2,
      "y": 9,
      "z": 2,
      "name": "Rock_Marble_Brick_Pillar_Base",
      "rotation": 2
    },
    {
      "x": 2,
      "y": 10,
      "z": 2,
      "name": "Rock_Marble_Brick_Pillar_Middle",
      "rotation": 2
    },
    {
      "x": 2,
      "y": 11,
      "z": 2,
      "name": "Rock_Marble_Brick_Pillar_Middle",
      "rotation": 2
    },
    {
      "x": 2,
      "y": 12,
      "z": 2,
      "name": "Rock_Marble_Brick_Pillar_Middle",
      "rotation": 2
    },
    {
      "x": 2,
      "y": 13,
      "z": 2,
      "name": "Rock_Marble_Brick_Pillar_Base",
      "rotation": 32
    },
    {
      "x": 2,
      "y": 14,
      "z": 2,
      "name": "Rock_Marble_Brick",
      "rotation": 2
    },
    {
      "x": 2,
      "y": -2,
      "z": 3,
      "name": "Soil_Grass_White"
    },
    {
      "x": 2,
      "y": 0,
      "z": 3,
      "name": "Soil_Pebbles",
      "support": 15
    },
    {
      "x": 2,
      "y": -2,
      "z": 4,
      "name": "Soil_Grass_White"
    },
    {
      "x": 2,
      "y": -1,
      "z": 4,
      "name": "Soil_Pebbles"
    },
    {
      "x": 2,
      "y": 0,
      "z": 4,
      "name": "Soil_Pebbles",
      "support": 15
    },
    {
      "x": 2,
      "y": 1,
      "z": 4,
      "name": "*Rock_Marble_Stairs_State_Definitions_Inverted_Corner_Left"
    },
    {
      "x": 2,
      "y": -2,
      "z": 5,
      "name": "Soil_Grass_White"
    },
    {
      "x": 2,
      "y": 0,
      "z": 5,
      "name": "Soil_Pebbles",
      "support": 15
    },
    {
      "x": 2,
      "y": 1,
      "z": 5,
      "name": "Rock_Marble_Stairs",
      "rotation": 1
    },
    {
      "x": 2,
      "y": -2,
      "z": 6,
      "name": "Soil_Grass_White"
    },
    {
      "x": 2,
      "y": -1,
      "z": 6,
      "name": "Soil_Pebbles"
    },
    {
      "x": 2,
      "y": 0,
      "z": 6,
      "name": "Soil_Pebbles",
      "support": 15
    },
    {
      "x": 2,
      "y": 1,
      "z": 6,
      "name": "Rubble_Marble_Medium",
      "support": 15
    },
    {
      "x": 2,
      "y": -2,
      "z": 7,
      "name": "Soil_Grass_White"
    },
    {
      "x": 2,
      "y": -1,
      "z": 7,
      "name": "Soil_Pebbles"
    },
    {
      "x": 2,
      "y": 0,
      "z": 7,
      "name": "Soil_Pebbles",
      "support": 15
    },
    {
      "x": 2,
      "y": -2,
      "z": 8,
      "name": "Soil_Grass_White"
    },
    {
      "x": 3,
      "y": -2,
      "z": -9,
      "name": "Soil_Grass_White"
    },
    {
      "x": 3,
      "y": -1,
      "z": -9,
      "name": "Soil_Grass_White"
    },
    {
      "x": 3,
      "y": -2,
      "z": -8,
      "name": "Soil_Grass_White"
    },
    {
      "x": 3,
      "y": -1,
      "z": -8,
      "name": "Soil_Grass_Full"
    },
    {
      "x": 3,
      "y": -2,
      "z": -7,
      "name": "Soil_Grass_White"
    },
    {
      "x": 3,
      "y": 0,
      "z": -7,
      "name": "Soil_Grass_Full"
    },
    {
      "x": 3,
      "y": -2,
      "z": -6,
      "name": "Soil_Grass_White"
    },
    {
      "x": 3,
      "y": -1,
      "z": -6,
      "name": "Soil_Grass_Full"
    },
    {
      "x": 3,
      "y": 0,
      "z": -6,
      "name": "Soil_Grass_Full"
    },
    {
      "x": 3,
      "y": 1,
      "z": -6,
      "name": "Plant_Grass_Sharp"
    },
    {
      "x": 3,
      "y": -2,
      "z": -5,
      "name": "Soil_Grass_White"
    },
    {
      "x": 3,
      "y": -1,
      "z": -5,
      "name": "Soil_Grass_Full"
    },
    {
      "x": 3,
      "y": 0,
      "z": -5,
      "name": "Soil_Grass_Full"
    },
    {
      "x": 3,
      "y": -2,
      "z": -4,
      "name": "Soil_Grass_White"
    },
    {
      "x": 3,
      "y": -1,
      "z": -4,
      "name": "Soil_Grass_Full"
    },
    {
      "x": 3,
      "y": 0,
      "z": -4,
      "name": "Soil_Grass_Full"
    },
    {
      "x": 3,
      "y": 1,
      "z": -4,
      "name": "Plant_Grass_Lush",
      "rotation": 2
    },
    {
      "x": 3,
      "y": -2,
      "z": -3,
      "name": "Soil_Grass_White"
    },
    {
      "x": 3,
      "y": 0,
      "z": -3,
      "name": "Soil_Grass_Full"
    },
    {
      "x": 3,
      "y": 1,
      "z": -3,
      "name": "Plant_Grass_Lush",
      "rotation": 2
    },
    {
      "x": 3,
      "y": 7,
      "z": -3,
      "name": "Rock_Marble_Brick_Stairs",
      "rotation": 18
    },
    {
      "x": 3,
      "y": 14,
      "z": -3,
      "name": "Rock_Marble_Brick_Stairs",
      "rotation": 18
    },
    {
      "x": 3,
      "y": -2,
      "z": -2,
      "name": "Soil_Grass_White"
    },
    {
      "x": 3,
      "y": -1,
      "z": -2,
      "name": "Soil_Dirt_White"
    },
    {
      "x": 3,
      "y": 0,
      "z": -2,
      "name": "Soil_Dirt_White"
    },
    {
      "x": 3,
      "y": 1,
      "z": -2,
      "name": "Rock_Marble_Brick",
      "rotation": 3
    },
    {
      "x": 3,
      "y": 2,
      "z": -2,
      "name": "Rock_Marble_Brick_Pillar_Base",
      "rotation": 3
    },
    {
      "x": 3,
      "y": 3,
      "z": -2,
      "name": "Rock_Marble_Brick_Pillar_Middle",
      "rotation": 3
    },
    {
      "x": 3,
      "y": 4,
      "z": -2,
      "name": "Rock_Marble_Brick_Pillar_Middle",
      "rotation": 3
    },
    {
      "x": 3,
      "y": 5,
      "z": -2,
      "name": "Rock_Marble_Brick_Pillar_Middle",
      "rotation": 3
    },
    {
      "x": 3,
      "y": 6,
      "z": -2,
      "name": "Rock_Marble_Brick_Pillar_Base",
      "rotation": 33
    },
    {
      "x": 3,
      "y": 7,
      "z": -2,
      "name": "Rock_Marble_Brick",
      "rotation": 3
    },
    {
      "x": 3,
      "y": 8,
      "z": -2,
      "name": "Rock_Marble_Brick",
      "rotation": 3
    },
    {
      "x": 3,
      "y": 9,
      "z": -2,
      "name": "Rock_Marble_Brick_Pillar_Base"
    },
    {
      "x": 3,
      "y": 10,
      "z": -2,
      "name": "Rock_Marble_Brick_Pillar_Middle"
    },
    {
      "x": 3,
      "y": 11,
      "z": -2,
      "name": "Rock_Marble_Brick_Pillar_Middle"
    },
    {
      "x": 3,
      "y": 12,
      "z": -2,
      "name": "Rock_Marble_Brick_Pillar_Middle"
    },
    {
      "x": 3,
      "y": 13,
      "z": -2,
      "name": "Rock_Marble_Brick_Pillar_Base",
      "rotation": 34
    },
    {
      "x": 3,
      "y": 14,
      "z": -2,
      "name": "Rock_Marble_Brick",
      "rotation": 1
    },
    {
      "x": 3,
      "y": 15,
      "z": -2,
      "name": "Rock_Marble_Half",
      "rotation": 5
    },
    {
      "x": 3,
      "y": -2,
      "z": -1,
      "name": "Soil_Grass_White"
    },
    {
      "x": 3,
      "y": -1,
      "z": -1,
      "name": "Soil_Dirt_White"
    },
    {
      "x": 3,
      "y": 0,
      "z": -1,
      "name": "Soil_Dirt_White"
    },
    {
      "x": 3,
      "y": 1,
      "z": -1,
      "name": "Rock_Marble_Brick",
      "rotation": 3
    },
    {
      "x": 3,
      "y": 2,
      "z": -1,
      "name": "Rock_Marble_Cobble",
      "rotation": 2
    },
    {
      "x": 3,
      "y": 3,
      "z": -1,
      "name": "Rock_Marble_Stairs"
    },
    {
      "x": 3,
      "y": 4,
      "z": -1,
      "name": "Rock_Marble_Half",
      "rotation": 4
    },
    {
      "x": 3,
      "y": 5,
      "z": -1,
      "name": "Rock_Marble_Stairs",
      "rotation": 32
    },
    {
      "x": 3,
      "y": 6,
      "z": -1,
      "name": "Rock_Marble"
    },
    {
      "x": 3,
      "y": 7,
      "z": -1,
      "name": "Rock_Marble_Brick",
      "rotation": 3
    },
    {
      "x": 3,
      "y": 8,
      "z": -1,
      "name": "Rock_Marble_Brick",
      "rotation": 3
    },
    {
      "x": 3,
      "y": 9,
      "z": -1,
      "name": "Rock_Marble_Cobble",
      "rotation": 3
    },
    {
      "x": 3,
      "y": 10,
      "z": -1,
      "name": "Rock_Marble_Stairs"
    },
    {
      "x": 3,
      "y": 11,
      "z": -1,
      "name": "Rock_Marble_Half",
      "rotation": 4
    },
    {
      "x": 3,
      "y": 12,
      "z": -1,
      "name": "Rock_Marble_Stairs",
      "rotation": 32
    },
    {
      "x": 3,
      "y": 13,
      "z": -1,
      "name": "Rock_Marble"
    },
    {
      "x": 3,
      "y": 14,
      "z": -1,
      "name": "Rock_Marble_Brick",
      "rotation": 1
    },
    {
      "x": 3,
      "y": 15,
      "z": -1,
      "name": "Rock_Marble"
    },
    {
      "x": 3,
      "y": 16,
      "z": -1,
      "name": "Rock_Marble_Half",
      "rotation": 5
    },
    {
      "x": 3,
      "y": -2,
      "z": 0,
      "name": "Soil_Grass_White"
    },
    {
      "x": 3,
      "y": 0,
      "z": 0,
      "name": "Soil_Dirt_White"
    },
    {
      "x": 3,
      "y": 1,
      "z": 0,
      "name": "Rock_Marble_Brick",
      "rotation": 3
    },
    {
      "x": 3,
      "y": 2,
      "z": 0,
      "name": "Rock_Marble_Cobble",
      "rotation": 2
    },
    {
      "x": 3,
      "y": 3,
      "z": 0,
      "name": "Rock_Marble_Stairs",
      "rotation": 2
    },
    {
      "x": 3,
      "y": 4,
      "z": 0,
      "name": "Rock_Marble_Half",
      "rotation": 6
    },
    {
      "x": 3,
      "y": 5,
      "z": 0,
      "name": "Rock_Marble_Stairs",
      "rotation": 34
    },
    {
      "x": 3,
      "y": 6,
      "z": 0,
      "name": "Rock_Marble"
    },
    {
      "x": 3,
      "y": 7,
      "z": 0,
      "name": "Rock_Marble_Brick",
      "rotation": 3
    },
    {
      "x": 3,
      "y": 8,
      "z": 0,
      "name": "Rock_Marble_Brick",
      "rotation": 3
    },
    {
      "x": 3,
      "y": 9,
      "z": 0,
      "name": "Rock_Marble_Cobble",
      "rotation": 3
    },
    {
      "x": 3,
      "y": 10,
      "z": 0,
      "name": "Rock_Marble_Stairs",
      "rotation": 2
    },
    {
      "x": 3,
      "y": 14,
      "z": 0,
      "name": "Rock_Marble_Brick",
      "rotation": 1
    },
    {
      "x": 3,
      "y": 15,
      "z": 0,
      "name": "Rock_Marble"
    },
    {
      "x": 3,
      "y": 16,
      "z": 0,
      "name": "Rock_Marble_Half",
      "rotation": 5
    },
    {
      "x": 3,
      "y": -2,
      "z": 1,
      "name": "Soil_Grass_White"
    },
    {
      "x": 3,
      "y": 0,
      "z": 1,
      "name": "Soil_Dirt_White"
    },
    {
      "x": 3,
      "y": 1,
      "z": 1,
      "name": "Rock_Marble_Brick",
      "rotation": 2
    },
    {
      "x": 3,
      "y": 2,
      "z": 1,
      "name": "Rock_Marble_Brick_Pillar_Base",
      "rotation": 2
    },
    {
      "x": 3,
      "y": 3,
      "z": 1,
      "name": "Rock_Marble_Brick_Pillar_Middle",
      "rotation": 2
    },
    {
      "x": 3,
      "y": 4,
      "z": 1,
      "name": "Rock_Marble_Brick_Pillar_Middle",
      "rotation": 2
    },
    {
      "x": 3,
      "y": 5,
      "z": 1,
      "name": "Rock_Marble_Brick_Pillar_Middle",
      "rotation": 2
    },
    {
      "x": 3,
      "y": 6,
      "z": 1,
      "name": "Rock_Marble_Brick_Pillar_Base",
      "rotation": 32
    },
    {
      "x": 3,
      "y": 7,
      "z": 1,
      "name": "Rock_Marble_Brick",
      "rotation": 2
    },
    {
      "x": 3,
      "y": 8,
      "z": 1,
      "name": "Rock_Marble_Brick",
      "rotation": 2
    },
    {
      "x": 3,
      "y": 9,
      "z": 1,
      "name": "Rubble_Marble",
      "support": 15
    },
    {
      "x": 3,
      "y": -2,
      "z": 2,
      "name": "Soil_Grass_White"
    },
    {
      "x": 3,
      "y": 0,
      "z": 2,
      "name": "Soil_Grass_Full"
    },
    {
      "x": 3,
      "y": 7,
      "z": 2,
      "name": "Rock_Marble_Brick_Stairs",
      "rotation": 17
    },
    {
      "x": 3,
      "y": -2,
      "z": 3,
      "name": "Soil_Grass_White"
    },
    {
      "x": 3,
      "y": -1,
      "z": 3,
      "name": "Soil_Pebbles"
    },
    {
      "x": 3,
      "y": 0,
      "z": 3,
      "name": "Soil_Pebbles",
      "support": 15
    },
    {
      "x": 3,
      "y": 1,
      "z": 3,
      "name": "Rubble_Marble",
      "support": 15
    },
    {
      "x": 3,
      "y": -2,
      "z": 4,
      "name": "Soil_Grass_White"
    },
    {
      "x": 3,
      "y": -1,
      "z": 4,
      "name": "Soil_Pebbles"
    },
    {
      "x": 3,
      "y": 0,
      "z": 4,
      "name": "Soil_Pebbles",
      "support": 15
    },
    {
      "x": 3,
      "y": 1,
      "z": 4,
      "name": "Rock_Marble_Half"
    },
    {
      "x": 3,
      "y": -2,
      "z": 5,
      "name": "Soil_Grass_White"
    },
    {
      "x": 3,
      "y": -1,
      "z": 5,
      "name": "Soil_Pebbles"
    },
    {
      "x": 3,
      "y": 0,
      "z": 5,
      "name": "Soil_Pebbles",
      "support": 15
    },
    {
      "x": 3,
      "y": 1,
      "z": 5,
      "name": "Rubble_Marble",
      "support": 15
    },
    {
      "x": 3,
      "y": -2,
      "z": 6,
      "name": "Soil_Grass_White"
    },
    {
      "x": 3,
      "y": -1,
      "z": 6,
      "name": "Soil_Pebbles"
    },
    {
      "x": 3,
      "y": 0,
      "z": 6,
      "name": "Soil_Pebbles",
      "support": 15
    },
    {
      "x": 3,
      "y": -2,
      "z": 7,
      "name": "Soil_Grass_White"
    },
    {
      "x": 3,
      "y": -1,
      "z": 7,
      "name": "Soil_Pebbles"
    },
    {
      "x": 3,
      "y": 0,
      "z": 7,
      "name": "Soil_Grass_Full"
    },
    {
      "x": 3,
      "y": -2,
      "z": 8,
      "name": "Soil_Grass_White"
    },
    {
      "x": 4,
      "y": -2,
      "z": -9,
      "name": "Soil_Grass_White"
    },
    {
      "x": 4,
      "y": -2,
      "z": -8,
      "name": "Soil_Grass_White"
    },
    {
      "x": 4,
      "y": -1,
      "z": -8,
      "name": "Soil_Grass_Full"
    },
    {
      "x": 4,
      "y": -2,
      "z": -7,
      "name": "Soil_Grass_White"
    },
    {
      "x": 4,
      "y": -1,
      "z": -7,
      "name": "Soil_Grass_Full"
    },
    {
      "x": 4,
      "y": -2,
      "z": -6,
      "name": "Soil_Grass_White"
    },
    {
      "x": 4,
      "y": -1,
      "z": -6,
      "name": "Soil_Grass_Full"
    },
    {
      "x": 4,
      "y": 0,
      "z": -6,
      "name": "Soil_Grass_Full"
    },
    {
      "x": 4,
      "y": 1,
      "z": -6,
      "name": "Plant_Grass_Sharp"
    },
    {
      "x": 4,
      "y": -2,
      "z": -5,
      "name": "Soil_Grass_White"
    },
    {
      "x": 4,
      "y": -1,
      "z": -5,
      "name": "Soil_Grass_Full"
    },
    {
      "x": 4,
      "y": 0,
      "z": -5,
      "name": "Soil_Grass_Full"
    },
    {
      "x": 4,
      "y": 1,
      "z": -5,
      "name": "Plant_Grass_Sharp"
    },
    {
      "x": 4,
      "y": -2,
      "z": -4,
      "name": "Soil_Grass_White"
    },
    {
      "x": 4,
      "y": -1,
      "z": -4,
      "name": "Soil_Grass_Full"
    },
    {
      "x": 4,
      "y": 0,
      "z": -4,
      "name": "Soil_Grass_Full"
    },
    {
      "x": 4,
      "y": 1,
      "z": -4,
      "name": "Plant_Flower_Water_Duckweed",
      "rotation": 2
    },
    {
      "x": 4,
      "y": -2,
      "z": -3,
      "name": "Soil_Grass_White"
    },
    {
      "x": 4,
      "y": -1,
      "z": -3,
      "name": "Soil_Grass_Full"
    },
    {
      "x": 4,
      "y": 0,
      "z": -3,
      "name": "Soil_Grass_Full"
    },
    {
      "x": 4,
      "y": 1,
      "z": -3,
      "name": "Plant_Grass_Sharp",
      "rotation": 3
    },
    {
      "x": 4,
      "y": -2,
      "z": -2,
      "name": "Soil_Grass_White"
    },
    {
      "x": 4,
      "y": -1,
      "z": -2,
      "name": "Soil_Grass_Full"
    },
    {
      "x": 4,
      "y": 0,
      "z": -2,
      "name": "Soil_Grass_Full"
    },
    {
      "x": 4,
      "y": 1,
      "z": -2,
      "name": "Plant_Flower_Water_Duckweed"
    },
    {
      "x": 4,
      "y": 7,
      "z": -2,
      "name": "Rock_Marble_Brick_Half",
      "rotation": 5
    },
    {
      "x": 4,
      "y": -2,
      "z": -1,
      "name": "Soil_Grass_White"
    },
    {
      "x": 4,
      "y": -1,
      "z": -1,
      "name": "Soil_Pebbles"
    },
    {
      "x": 4,
      "y": 0,
      "z": -1,
      "name": "Soil_Pebbles",
      "support": 15
    },
    {
      "x": 4,
      "y": 1,
      "z": -1,
      "name": "Rock_Marble_Brick_Half",
      "rotation": 5
    },
    {
      "x": 4,
      "y": 7,
      "z": -1,
      "name": "Rock_Marble_Brick_Half",
      "rotation": 5
    },
    {
      "x": 4,
      "y": 8,
      "z": -1,
      "name": "Rock_Marble_Brick_Half",
      "rotation": 5
    },
    {
      "x": 4,
      "y": 14,
      "z": -1,
      "name": "Rock_Marble_Brick_Half",
      "rotation": 5
    },
    {
      "x": 4,
      "y": -2,
      "z": 0,
      "name": "Soil_Grass_White"
    },
    {
      "x": 4,
      "y": 0,
      "z": 0,
      "name": "Soil_Pebbles",
      "support": 15
    },
    {
      "x": 4,
      "y": 1,
      "z": 0,
      "name": "Rock_Marble_Half",
      "rotation": 5
    },
    {
      "x": 4,
      "y": 7,
      "z": 0,
      "name": "Rock_Marble_Brick_Half",
      "rotation": 5
    },
    {
      "x": 4,
      "y": 8,
      "z": 0,
      "name": "Rock_Marble_Brick_Half",
      "rotation": 5
    },
    {
      "x": 4,
      "y": 14,
      "z": 0,
      "name": "Rock_Marble_Brick_Half",
      "rotation": 5
    },
    {
      "x": 4,
      "y": -2,
      "z": 1,
      "name": "Soil_Grass_White"
    },
    {
      "x": 4,
      "y": -1,
      "z": 1,
      "name": "Soil_Pebbles"
    },
    {
      "x": 4,
      "y": 0,
      "z": 1,
      "name": "Soil_Pebbles",
      "support": 15
    },
    {
      "x": 4,
      "y": 7,
      "z": 1,
      "name": "Rock_Marble_Brick_Half",
      "rotation": 5
    },
    {
      "x": 4,
      "y": -2,
      "z": 2,
      "name": "Soil_Grass_White"
    },
    {
      "x": 4,
      "y": -1,
      "z": 2,
      "name": "Soil_Grass_Full"
    },
    {
      "x": 4,
      "y": 0,
      "z": 2,
      "name": "Soil_Grass_Full"
    },
    {
      "x": 4,
      "y": 1,
      "z": 2,
      "name": "Rock_Marble_Brick_Pillar_Middle",
      "rotation": 5
    },
    {
      "x": 4,
      "y": -2,
      "z": 3,
      "name": "Soil_Grass_White"
    },
    {
      "x": 4,
      "y": -1,
      "z": 3,
      "name": "Soil_Pebbles"
    },
    {
      "x": 4,
      "y": 0,
      "z": 3,
      "name": "Soil_Grass_Full"
    },
    {
      "x": 4,
      "y": 1,
      "z": 3,
      "name": "Rubble_Marble_Medium",
      "support": 15
    },
    {
      "x": 4,
      "y": -2,
      "z": 4,
      "name": "Soil_Grass_White"
    },
    {
      "x": 4,
      "y": -1,
      "z": 4,
      "name": "Soil_Pebbles"
    },
    {
      "x": 4,
      "y": 0,
      "z": 4,
      "name": "Soil_Pebbles",
      "support": 15
    },
    {
      "x": 4,
      "y": -2,
      "z": 5,
      "name": "Soil_Grass_White"
    },
    {
      "x": 4,
      "y": -1,
      "z": 5,
      "name": "Soil_Pebbles"
    },
    {
      "x": 4,
      "y": 0,
      "z": 5,
      "name": "Soil_Pebbles",
      "support": 15
    },
    {
      "x": 4,
      "y": -2,
      "z": 6,
      "name": "Soil_Grass_White"
    },
    {
      "x": 4,
      "y": -1,
      "z": 6,
      "name": "Soil_Pebbles"
    },
    {
      "x": 4,
      "y": 0,
      "z": 6,
      "name": "Soil_Grass_Full"
    },
    {
      "x": 4,
      "y": -2,
      "z": 7,
      "name": "Soil_Grass_White"
    },
    {
      "x": 4,
      "y": -1,
      "z": 7,
      "name": "Soil_Grass_White"
    },
    {
      "x": 4,
      "y": -2,
      "z": 8,
      "name": "Soil_Grass_White"
    },
    {
      "x": 5,
      "y": -2,
      "z": -8,
      "name": "Soil_Grass_White"
    },
    {
      "x": 5,
      "y": -1,
      "z": -8,
      "name": "Soil_Grass_White"
    },
    {
      "x": 5,
      "y": -2,
      "z": -7,
      "name": "Soil_Grass_White"
    },
    {
      "x": 5,
      "y": -1,
      "z": -7,
      "name": "Soil_Grass_Full"
    },
    {
      "x": 5,
      "y": -2,
      "z": -6,
      "name": "Soil_Grass_White"
    },
    {
      "x": 5,
      "y": -1,
      "z": -6,
      "name": "Soil_Grass_Full"
    },
    {
      "x": 5,
      "y": -2,
      "z": -5,
      "name": "Soil_Grass_White"
    },
    {
      "x": 5,
      "y": -1,
      "z": -5,
      "name": "Soil_Grass_Full"
    },
    {
      "x": 5,
      "y": 0,
      "z": -5,
      "name": "Soil_Grass_Full"
    },
    {
      "x": 5,
      "y": -2,
      "z": -4,
      "name": "Soil_Grass_White"
    },
    {
      "x": 5,
      "y": -1,
      "z": -4,
      "name": "Soil_Grass_Full"
    },
    {
      "x": 5,
      "y": 0,
      "z": -4,
      "name": "Soil_Grass_Full"
    },
    {
      "x": 5,
      "y": -2,
      "z": -3,
      "name": "Soil_Grass_White"
    },
    {
      "x": 5,
      "y": -1,
      "z": -3,
      "name": "Soil_Grass_Full"
    },
    {
      "x": 5,
      "y": 0,
      "z": -3,
      "name": "Soil_Grass_Full"
    },
    {
      "x": 5,
      "y": -2,
      "z": -2,
      "name": "Soil_Grass_White"
    },
    {
      "x": 5,
      "y": -1,
      "z": -2,
      "name": "Soil_Grass_Full"
    },
    {
      "x": 5,
      "y": 0,
      "z": -2,
      "name": "Soil_Grass_Full"
    },
    {
      "x": 5,
      "y": -2,
      "z": -1,
      "name": "Soil_Grass_White"
    },
    {
      "x": 5,
      "y": -1,
      "z": -1,
      "name": "Soil_Grass_Full"
    },
    {
      "x": 5,
      "y": 0,
      "z": -1,
      "name": "Soil_Grass_Full"
    },
    {
      "x": 5,
      "y": -2,
      "z": 0,
      "name": "Soil_Grass_White"
    },
    {
      "x": 5,
      "y": -1,
      "z": 0,
      "name": "Soil_Pebbles"
    },
    {
      "x": 5,
      "y": 0,
      "z": 0,
      "name": "Soil_Pebbles",
      "support": 15
    },
    {
      "x": 5,
      "y": -2,
      "z": 1,
      "name": "Soil_Grass_White"
    },
    {
      "x": 5,
      "y": -1,
      "z": 1,
      "name": "Soil_Pebbles"
    },
    {
      "x": 5,
      "y": 0,
      "z": 1,
      "name": "Soil_Pebbles",
      "support": 15
    },
    {
      "x": 5,
      "y": 1,
      "z": 1,
      "name": "Rubble_Marble_Medium",
      "support": 15
    },
    {
      "x": 5,
      "y": -2,
      "z": 2,
      "name": "Soil_Grass_White"
    },
    {
      "x": 5,
      "y": -1,
      "z": 2,
      "name": "Soil_Grass_Full"
    },
    {
      "x": 5,
      "y": 0,
      "z": 2,
      "name": "Soil_Pebbles",
      "support": 15
    },
    {
      "x": 5,
      "y": 1,
      "z": 2,
      "name": "Rock_Marble_Brick_Pillar_Middle",
      "rotation": 5
    },
    {
      "x": 5,
      "y": -2,
      "z": 3,
      "name": "Soil_Grass_White"
    },
    {
      "x": 5,
      "y": -1,
      "z": 3,
      "name": "Soil_Grass_Full"
    },
    {
      "x": 5,
      "y": 0,
      "z": 3,
      "name": "Soil_Grass_Full"
    },
    {
      "x": 5,
      "y": 1,
      "z": 3,
      "name": "Plant_Grass_Lush_Short"
    },
    {
      "x": 5,
      "y": -2,
      "z": 4,
      "name": "Soil_Grass_White"
    },
    {
      "x": 5,
      "y": -1,
      "z": 4,
      "name": "Soil_Grass_Full"
    },
    {
      "x": 5,
      "y": 0,
      "z": 4,
      "name": "Soil_Grass_Full"
    },
    {
      "x": 5,
      "y": -2,
      "z": 5,
      "name": "Soil_Grass_White"
    },
    {
      "x": 5,
      "y": -1,
      "z": 5,
      "name": "Soil_Grass_White"
    },
    {
      "x": 5,
      "y": -2,
      "z": 6,
      "name": "Soil_Grass_White"
    },
    {
      "x": 5,
      "y": -1,
      "z": 6,
      "name": "Soil_Grass_White"
    },
    {
      "x": 5,
      "y": -2,
      "z": 7,
      "name": "Soil_Grass_White"
    },
    {
      "x": 6,
      "y": -2,
      "z": -8,
      "name": "Soil_Grass_White"
    },
    {
      "x": 6,
      "y": -2,
      "z": -7,
      "name": "Soil_Grass_White"
    },
    {
      "x": 6,
      "y": -2,
      "z": -6,
      "name": "Soil_Grass_White"
    },
    {
      "x": 6,
      "y": -1,
      "z": -6,
      "name": "Soil_Grass_Full"
    },
    {
      "x": 6,
      "y": -2,
      "z": -5,
      "name": "Soil_Grass_White"
    },
    {
