{
  "version": 8,
  "blockIdVersion": 11,
  "anchorX": 0,
  "anchorY": 0,
  "anchorZ": 0,
  "blocks": [
    {
      "x": -23,
      "y": 0,
      "z": -27,
      "name": "Rock_Chalk_Brick"
    },
    {
      "x": -23,
      "y": 0,
      "z": -26,
      "name": "Rock_Chalk_Brick"
    },
    {
      "x": -23,
      "y": 0,
      "z": -25,
      "name": "Rock_Chalk_Brick"
    },
    {
      "x": -23,
      "y": 0,
      "z": -24,
      "name": "Rock_Chalk_Brick"
    },
    {
      "x": -23,
      "y": 0,
      "z": -23,
      "name": "Rock_Chalk_Brick"
    },
    {
      "x": -23,
      "y": 0,
      "z": -22,
      "name": "Rock_Chalk_Brick"
    },
    {
      "x": -23,
      "y": 0,
      "z": -21,
      "name": "Rock_Chalk_Brick"
    },
    {
      "x": -23,
      "y": 0,
      "z": -20,
      "name": "Rock_Chalk_Brick"
    },
    {
      "x": -23,
      "y": 0,
      "z": -19,
      "name": "Rock_Chalk_Brick"
    },
    {
      "x": -23,
      "y": 0,
      "z": -18,
      "name": "Rock_Chalk_Brick"
    },
    {
      "x": -23,
      "y": 0,
      "z": -17,
      "name": "Rock_Chalk_Brick"
    },
    {
      "x": -23,
      "y": 0,
      "z": -16,
      "name": "Rock_Chalk_Brick"
    },
    {
      "x": -23,
      "y": 19,
      "z": -16,
      "name": "*Rock_Marble_Brick_Wall_State_Definitions_Corner",
      "rotation": 1
    },
    {
      "x": -23,
      "y": 20,
      "z": -16,
      "name": "Rock_Marble_Brick_Roof_Shallow",
      "rotation": 2
    },
    {
      "x": -23,
      "y": 0,
      "z": -15,
      "name": "Rock_Chalk_Brick"
    },
    {
      "x": -23,
      "y": 17,
      "z": -15,
      "name": "Rock_Marble_Brick_Half",
      "rotation": 7
    },
    {
      "x": -23,
      "y": 18,
      "z": -15,
      "name": "Furniture_Temple_Light_Ladder",
      "rotation": 3
    },
    {
      "x": -23,
      "y": 19,
      "z": -15,
      "name": "Rock_Marble_Brick_Wall",
      "rotation": 3
    },
    {
      "x": -23,
      "y": 20,
      "z": -15,
      "name": "Rock_Marble_Brick_Roof_Shallow",
      "filler": 32,
      "rotation": 2
    },
    {
      "x": -23,
      "y": 0,
      "z": -14,
      "name": "Rock_Chalk_Brick"
    },
    {
      "x": -23,
      "y": 17,
      "z": -14,
      "name": "Rock_Marble_Brick_Half",
      "rotation": 7
    },
    {
      "x": -23,
      "y": 19,
      "z": -14,
      "name": "Rock_Marble_Brick_Wall",
      "rotation": 3
    },
    {
      "x": -23,
      "y": 20,
      "z": -14,
      "name": "Rock_Marble_Brick",
      "rotation": 3
    },
    {
      "x": -23,
      "y": 21,
      "z": -14,
      "name": "Rock_Marble_Brick_Roof_Shallow",
      "rotation": 2
    },
    {
      "x": -23,
      "y": 0,
      "z": -13,
      "name": "Rock_Chalk_Brick"
    },
    {
      "x": -23,
      "y": 17,
      "z": -13,
      "name": "Rock_Marble_Brick_Half",
      "rotation": 7
    },
    {
      "x": -23,
      "y": 18,
      "z": -13,
      "name": "Furniture_Temple_Light_Ladder",
      "rotation": 3
    },
    {
      "x": -23,
      "y": 19,
      "z": -13,
      "name": "Rock_Marble_Brick_Wall",
      "rotation": 3
    },
    {
      "x": -23,
      "y": 20,
      "z": -13,
      "name": "Rock_Marble_Brick_Stairs",
      "rotation": 3
    },
    {
      "x": -23,
      "y": 21,
      "z": -13,
      "name": "Rock_Marble_Brick_Roof_Shallow",
      "filler": 32,
      "rotation": 2
    },
    {
      "x": -23,
      "y": 0,
      "z": -12,
      "name": "Rock_Chalk_Brick"
    },
    {
      "x": -23,
      "y": 17,
      "z": -12,
      "name": "Rock_Marble_Brick_Half",
      "rotation": 7
    },
    {
      "x": -23,
      "y": 19,
      "z": -12,
      "name": "Rock_Marble_Brick_Wall",
      "rotation": 3
    },
    {
      "x": -23,
      "y": 20,
      "z": -12,
      "name": "Rock_Marble_Brick_Stairs",
      "rotation": 3
    },
    {
      "x": -23,
      "y": 21,
      "z": -12,
      "name": "Rock_Marble_Brick_Half",
      "rotation": 11
    },
    {
      "x": -23,
      "y": 22,
      "z": -12,
      "name": "Rock_Marble_Brick_Roof_Shallow",
      "rotation": 2
    },
    {
      "x": -23,
      "y": 0,
      "z": -11,
      "name": "Rock_Chalk_Brick"
    },
    {
      "x": -23,
      "y": 17,
      "z": -11,
      "name": "Rock_Marble_Brick_Half",
      "rotation": 7
    },
    {
      "x": -23,
      "y": 18,
      "z": -11,
      "name": "Furniture_Temple_Light_Ladder",
      "rotation": 3
    },
    {
      "x": -23,
      "y": 19,
      "z": -11,
      "name": "Rock_Marble_Brick_Wall",
      "rotation": 3
    },
    {
      "x": -23,
      "y": 20,
      "z": -11,
      "name": "Rock_Marble_Brick_Stairs",
      "rotation": 3
    },
    {
      "x": -23,
      "y": 22,
      "z": -11,
      "name": "Rock_Marble_Brick_Roof_Shallow",
      "filler": 32,
      "rotation": 2
    },
    {
      "x": -23,
      "y": 0,
      "z": -10,
      "name": "Rock_Chalk_Brick"
    },
    {
      "x": -23,
      "y": 17,
      "z": -10,
      "name": "Rock_Marble_Brick_Half",
      "rotation": 7
    },
    {
      "x": -23,
      "y": 19,
      "z": -10,
      "name": "Rock_Marble_Brick_Wall",
      "rotation": 3
    },
    {
      "x": -23,
      "y": 20,
      "z": -10,
      "name": "Rock_Marble_Brick_Stairs",
      "rotation": 3
    },
    {
      "x": -23,
      "y": 22,
      "z": -10,
      "name": "Rock_Marble_Brick_Half",
      "rotation": 11
    },
    {
      "x": -23,
      "y": 23,
      "z": -10,
      "name": "Rock_Marble_Brick_Stairs",
      "rotation": 2
    },
    {
      "x": -23,
      "y": 0,
      "z": -9,
      "name": "Rock_Chalk_Brick"
    },
    {
      "x": -23,
      "y": 17,
      "z": -9,
      "name": "Rock_Marble_Brick_Half",
      "rotation": 7
    },
    {
      "x": -23,
      "y": 19,
      "z": -9,
      "name": "Rock_Marble_Brick_Wall",
      "rotation": 3
    },
    {
      "x": -23,
      "y": 20,
      "z": -9,
      "name": "Rock_Marble_Brick_Stairs",
      "rotation": 3
    },
    {
      "x": -23,
      "y": 22,
      "z": -9,
      "name": "Rock_Marble_Brick_Half",
      "rotation": 11
    },
    {
      "x": -23,
      "y": 23,
      "z": -9,
      "name": "Rock_Marble_Brick_Stairs"
    },
    {
      "x": -23,
      "y": 0,
      "z": -8,
      "name": "Rock_Chalk_Brick"
    },
    {
      "x": -23,
      "y": 17,
      "z": -8,
      "name": "Rock_Marble_Brick_Half",
      "rotation": 7
    },
    {
      "x": -23,
      "y": 18,
      "z": -8,
      "name": "Furniture_Temple_Light_Ladder",
      "rotation": 3
    },
    {
      "x": -23,
      "y": 19,
      "z": -8,
      "name": "Rock_Marble_Brick_Wall",
      "rotation": 3
    },
    {
      "x": -23,
      "y": 20,
      "z": -8,
      "name": "Rock_Marble_Brick_Stairs",
      "rotation": 3
    },
    {
      "x": -23,
      "y": 22,
      "z": -8,
      "name": "Rock_Marble_Brick_Roof_Shallow",
      "filler": 992
    },
    {
      "x": -23,
      "y": 0,
      "z": -7,
      "name": "Rock_Chalk_Brick"
    },
    {
      "x": -23,
      "y": 17,
      "z": -7,
      "name": "Rock_Marble_Brick_Half",
      "rotation": 7
    },
    {
      "x": -23,
      "y": 19,
      "z": -7,
      "name": "Rock_Marble_Brick_Wall",
      "rotation": 3
    },
    {
      "x": -23,
      "y": 20,
      "z": -7,
      "name": "Rock_Marble_Brick_Stairs",
      "rotation": 3
    },
    {
      "x": -23,
      "y": 21,
      "z": -7,
      "name": "Rock_Marble_Brick_Half",
      "rotation": 11
    },
    {
      "x": -23,
      "y": 22,
      "z": -7,
      "name": "Rock_Marble_Brick_Roof_Shallow"
    },
    {
      "x": -23,
      "y": 0,
      "z": -6,
      "name": "Rock_Chalk_Brick"
    },
    {
      "x": -23,
      "y": 17,
      "z": -6,
      "name": "Rock_Marble_Brick_Half",
      "rotation": 7
    },
    {
      "x": -23,
      "y": 18,
      "z": -6,
      "name": "Furniture_Temple_Light_Ladder",
      "rotation": 3
    },
    {
      "x": -23,
      "y": 19,
      "z": -6,
      "name": "Rock_Marble_Brick_Wall",
      "rotation": 3
    },
    {
      "x": -23,
      "y": 20,
      "z": -6,
      "name": "Rock_Marble_Brick_Stairs",
      "rotation": 3
    },
    {
      "x": -23,
      "y": 21,
      "z": -6,
      "name": "Rock_Marble_Brick_Roof_Shallow",
      "filler": 992
    },
    {
      "x": -23,
      "y": 0,
      "z": -5,
      "name": "Rock_Chalk_Brick"
    },
    {
      "x": -23,
      "y": 17,
      "z": -5,
      "name": "Rock_Marble_Brick_Half",
      "rotation": 7
    },
    {
      "x": -23,
      "y": 19,
      "z": -5,
      "name": "Rock_Marble_Brick_Wall",
      "rotation": 3
    },
    {
      "x": -23,
      "y": 20,
      "z": -5,
      "name": "Rock_Marble_Brick",
      "rotation": 3
    },
    {
      "x": -23,
      "y": 21,
      "z": -5,
      "name": "Rock_Marble_Brick_Roof_Shallow"
    },
    {
      "x": -23,
      "y": 0,
      "z": -4,
      "name": "Rock_Chalk_Brick"
    },
    {
      "x": -23,
      "y": 17,
      "z": -4,
      "name": "Rock_Marble_Brick_Half",
      "rotation": 7
    },
    {
      "x": -23,
      "y": 18,
      "z": -4,
      "name": "Furniture_Temple_Light_Ladder",
      "rotation": 3
    },
    {
      "x": -23,
      "y": 19,
      "z": -4,
      "name": "Rock_Marble_Brick_Wall",
      "rotation": 3
    },
    {
      "x": -23,
      "y": 20,
      "z": -4,
      "name": "Rock_Marble_Brick_Roof_Shallow",
      "filler": 992
    },
    {
      "x": -23,
      "y": 0,
      "z": -3,
      "name": "Rock_Chalk_Brick"
    },
    {
      "x": -23,
      "y": 19,
      "z": -3,
      "name": "*Rock_Marble_Brick_Wall_State_Definitions_Corner",
      "rotation": 2
    },
    {
      "x": -23,
      "y": 20,
      "z": -3,
      "name": "Rock_Marble_Brick_Roof_Shallow"
    },
    {
      "x": -23,
      "y": 0,
      "z": -2,
      "name": "Rock_Chalk_Brick"
    },
    {
      "x": -23,
      "y": 0,
      "z": -1,
      "name": "Rock_Chalk_Brick"
    },
    {
      "x": -23,
      "y": 0,
      "z": 0,
      "name": "Rock_Chalk_Brick"
    },
    {
      "x": -23,
      "y": 0,
      "z": 1,
      "name": "Rock_Chalk_Brick"
    },
    {
      "x": -23,
      "y": 0,
      "z": 2,
      "name": "Rock_Chalk_Brick"
    },
    {
      "x": -23,
      "y": 0,
      "z": 3,
      "name": "Rock_Chalk_Brick"
    },
    {
      "x": -23,
      "y": 0,
      "z": 4,
      "name": "Rock_Chalk_Brick"
    },
    {
      "x": -23,
      "y": 0,
      "z": 5,
      "name": "Rock_Chalk_Brick"
    },
    {
      "x": -23,
      "y": 0,
      "z": 6,
      "name": "Rock_Chalk_Brick"
    },
    {
      "x": -23,
      "y": 0,
      "z": 7,
      "name": "Rock_Chalk_Brick"
    },
    {
      "x": -23,
      "y": 0,
      "z": 8,
      "name": "Rock_Chalk_Brick"
    },
    {
      "x": -23,
      "y": 0,
      "z": 9,
      "name": "Rock_Chalk_Brick"
    },
    {
      "x": -23,
      "y": 0,
      "z": 10,
      "name": "Rock_Chalk_Brick"
    },
    {
      "x": -23,
      "y": 0,
      "z": 11,
      "name": "Rock_Chalk_Brick"
    },
    {
      "x": -23,
      "y": 0,
      "z": 12,
      "name": "Rock_Chalk_Brick"
    },
    {
      "x": -23,
      "y": 0,
      "z": 13,
      "name": "Rock_Chalk_Brick"
    },
    {
      "x": -23,
      "y": 0,
      "z": 14,
      "name": "Rock_Chalk_Brick"
    },
    {
      "x": -23,
      "y": 0,
      "z": 15,
      "name": "Rock_Chalk_Brick"
    },
    {
      "x": -23,
      "y": 0,
      "z": 16,
      "name": "Rock_Chalk_Brick"
    },
    {
      "x": -23,
      "y": 0,
      "z": 17,
      "name": "Rock_Chalk_Brick"
    },
    {
      "x": -23,
      "y": 0,
      "z": 18,
      "name": "Rock_Chalk_Brick"
    },
    {
      "x": -23,
      "y": 0,
      "z": 19,
      "name": "Rock_Chalk_Brick"
    },
    {
      "x": -23,
      "y": 0,
      "z": 20,
      "name": "Rock_Chalk_Brick"
    },
    {
      "x": -23,
      "y": 0,
      "z": 21,
      "name": "Rock_Chalk_Brick"
    },
    {
      "x": -23,
      "y": 0,
      "z": 22,
      "name": "Rock_Chalk_Brick"
    },
    {
      "x": -23,
      "y": 0,
      "z": 23,
      "name": "Rock_Chalk_Brick"
    },
    {
      "x": -23,
      "y": 0,
      "z": 24,
      "name": "Rock_Chalk_Brick"
    },
    {
      "x": -23,
      "y": 0,
      "z": 25,
      "name": "Rock_Chalk_Brick"
    },
    {
      "x": -23,
      "y": 0,
      "z": 26,
      "name": "Rock_Chalk_Brick"
    },
    {
      "x": -23,
      "y": 0,
      "z": 27,
      "name": "Rock_Chalk_Brick"
    },
    {
      "x": -23,
      "y": 0,
      "z": 28,
      "name": "Rock_Chalk_Brick"
    },
    {
      "x": -23,
      "y": 0,
      "z": 29,
      "name": "Rock_Chalk_Brick"
    },
    {
      "x": -22,
      "y": 0,
      "z": -27,
      "name": "Rock_Chalk_Brick"
    },
    {
      "x": -22,
      "y": 0,
      "z": -26,
      "name": "Rock_Chalk_Brick"
    },
    {
      "x": -22,
      "y": 0,
      "z": -25,
      "name": "Rock_Chalk_Brick"
    },
    {
      "x": -22,
      "y": 0,
      "z": -24,
      "name": "Rock_Chalk_Brick"
    },
    {
      "x": -22,
      "y": 0,
      "z": -23,
      "name": "Rock_Chalk_Brick"
    },
    {
      "x": -22,
      "y": 0,
      "z": -22,
      "name": "Rock_Chalk_Brick"
    },
    {
      "x": -22,
      "y": 0,
      "z": -21,
      "name": "Rock_Chalk_Brick"
    },
    {
      "x": -22,
      "y": 0,
      "z": -20,
      "name": "Rock_Chalk_Brick"
    },
    {
      "x": -22,
      "y": 0,
      "z": -19,
      "name": "Rock_Chalk_Brick"
    },
    {
      "x": -22,
      "y": 0,
      "z": -18,
      "name": "Rock_Chalk_Brick"
    },
    {
      "x": -22,
      "y": 0,
      "z": -17,
      "name": "Rock_Chalk_Brick"
    },
    {
      "x": -22,
      "y": 0,
      "z": -16,
      "name": "Rock_Chalk_Brick"
    },
    {
      "x": -22,
      "y": 17,
      "z": -16,
      "name": "Rock_Marble_Brick_Half",
      "rotation": 6
    },
    {
      "x": -22,
      "y": 18,
      "z": -16,
      "name": "Furniture_Temple_Light_Ladder",
      "rotation": 2
    },
    {
      "x": -22,
      "y": 19,
      "z": -16,
      "name": "Rock_Marble_Brick_Wall"
    },
    {
      "x": -22,
      "y": 20,
      "z": -16,
      "name": "Rock_Chalk_Brick_Roof_Shallow",
      "rotation": 2
    },
    {
      "x": -22,
      "y": 0,
      "z": -15,
      "name": "Rock_Chalk_Brick"
    },
    {
      "x": -22,
      "y": 1,
      "z": -15,
      "name": "Rock_Marble_Brick_Pillar_Base",
      "rotation": 2
    },
    {
      "x": -22,
      "y": 2,
      "z": -15,
      "name": "Rock_Marble_Brick_Pillar_Middle",
      "rotation": 32
    },
    {
      "x": -22,
      "y": 3,
      "z": -15,
      "name": "Rock_Marble_Brick_Pillar_Middle",
      "rotation": 32
    },
    {
      "x": -22,
      "y": 4,
      "z": -15,
      "name": "Rock_Marble_Brick_Pillar_Base",
      "rotation": 32
    },
    {
      "x": -22,
      "y": 5,
      "z": -15,
      "name": "Rock_Marble_Brick",
      "rotation": 2
    },
    {
      "x": -22,
      "y": 6,
      "z": -15,
      "name": "Rock_Marble_Brick_Pillar_Base",
      "rotation": 2
    },
    {
      "x": -22,
      "y": 7,
      "z": -15,
      "name": "Rock_Marble_Brick_Pillar_Middle",
      "rotation": 32
    },
    {
      "x": -22,
      "y": 8,
      "z": -15,
      "name": "Rock_Marble_Brick_Pillar_Middle",
      "rotation": 32
    },
    {
      "x": -22,
      "y": 9,
      "z": -15,
      "name": "Rock_Marble_Brick_Pillar_Middle",
      "rotation": 32
    },
    {
      "x": -22,
      "y": 10,
      "z": -15,
      "name": "Rock_Marble_Brick_Pillar_Middle",
      "rotation": 32
    },
    {
      "x": -22,
      "y": 11,
      "z": -15,
      "name": "Rock_Marble_Brick_Pillar_Middle",
      "rotation": 32
    },
    {
      "x": -22,
      "y": 12,
      "z": -15,
      "name": "Rock_Marble_Brick_Pillar_Middle",
      "rotation": 32
    },
    {
      "x": -22,
      "y": 13,
      "z": -15,
      "name": "Rock_Marble_Brick_Pillar_Middle",
      "rotation": 32
    },
    {
      "x": -22,
      "y": 14,
      "z": -15,
      "name": "Rock_Marble_Brick_Pillar_Middle",
      "rotation": 32
    },
    {
      "x": -22,
      "y": 15,
      "z": -15,
      "name": "Rock_Marble_Brick_Pillar_Middle",
      "rotation": 32
    },
    {
      "x": -22,
      "y": 16,
      "z": -15,
      "name": "Rock_Marble_Brick_Pillar_Base",
      "rotation": 32
    },
    {
      "x": -22,
      "y": 17,
      "z": -15,
      "name": "Rock_Marble_Brick",
      "rotation": 3
    },
    {
      "x": -22,
      "y": 18,
      "z": -15,
      "name": "Rock_Marble_Brick_Decorative",
      "rotation": 11
    },
    {
      "x": -22,
      "y": 19,
      "z": -15,
      "name": "Rock_Marble_Brick",
      "rotation": 3
    },
    {
      "x": -22,
      "y": 20,
      "z": -15,
      "name": "Rock_Chalk_Brick_Roof_Shallow",
      "filler": 32,
      "rotation": 2
    },
    {
      "x": -22,
      "y": 0,
      "z": -14,
      "name": "Rock_Chalk_Brick"
    },
    {
      "x": -22,
      "y": 5,
      "z": -14,
      "name": "Rock_Marble_Brick_Half",
      "rotation": 7
    },
    {
      "x": -22,
      "y": 11,
      "z": -14,
      "name": "Rock_Marble_Brick_Half",
      "rotation": 7
    },
    {
      "x": -22,
      "y": 17,
      "z": -14,
      "name": "Rock_Marble_Brick",
      "rotation": 3
    },
    {
      "x": -22,
      "y": 18,
      "z": -14,
      "name": "Rock_Marble_Brick_Decorative",
      "rotation": 11
    },
    {
      "x": -22,
      "y": 19,
      "z": -14,
      "name": "Rock_Marble_Brick",
      "rotation": 3
    },
    {
      "x": -22,
      "y": 20,
      "z": -14,
      "name": "Rock_Chalk"
    },
    {
      "x": -22,
      "y": 21,
      "z": -14,
      "name": "Rock_Chalk_Brick_Roof_Shallow",
      "rotation": 2
    },
    {
      "x": -22,
      "y": 0,
      "z": -13,
      "name": "Rock_Chalk_Brick"
    },
    {
      "x": -22,
      "y": 5,
      "z": -13,
      "name": "Rock_Marble_Brick_Half",
      "rotation": 7
    },
    {
      "x": -22,
      "y": 11,
      "z": -13,
      "name": "Rock_Marble_Brick_Half",
      "rotation": 7
    },
    {
      "x": -22,
      "y": 17,
      "z": -13,
      "name": "Rock_Marble_Brick",
      "rotation": 3
    },
    {
      "x": -22,
      "y": 18,
      "z": -13,
      "name": "Rock_Marble_Brick_Decorative",
      "rotation": 11
    },
    {
      "x": -22,
      "y": 19,
      "z": -13,
      "name": "Rock_Marble_Brick",
      "rotation": 3
    },
    {
      "x": -22,
      "y": 20,
      "z": -13,
      "name": "Rock_Chalk"
    },
    {
      "x": -22,
      "y": 21,
      "z": -13,
      "name": "Rock_Chalk_Brick_Roof_Shallow",
      "filler": 32,
      "rotation": 2
    },
    {
      "x": -22,
      "y": 0,
      "z": -12,
      "name": "Rock_Chalk_Brick"
    },
    {
      "x": -22,
      "y": 1,
      "z": -12,
      "name": "Rock_Marble_Brick_Pillar_Base",
      "rotation": 2
    },
    {
      "x": -22,
      "y": 2,
      "z": -12,
      "name": "Rock_Marble_Brick_Pillar_Middle",
      "rotation": 32
    },
    {
      "x": -22,
      "y": 3,
      "z": -12,
      "name": "Rock_Marble_Brick_Pillar_Middle",
      "rotation": 32
    },
    {
      "x": -22,
      "y": 4,
      "z": -12,
      "name": "Rock_Marble_Brick_Pillar_Base",
      "rotation": 32
    },
    {
      "x": -22,
      "y": 5,
      "z": -12,
      "name": "Rock_Marble_Brick",
      "rotation": 2
    },
    {
      "x": -22,
      "y": 6,
      "z": -12,
      "name": "Rock_Marble_Brick_Pillar_Base",
      "rotation": 2
    },
    {
      "x": -22,
      "y": 7,
      "z": -12,
      "name": "Rock_Marble_Brick_Pillar_Middle",
      "rotation": 32
    },
    {
      "x": -22,
      "y": 8,
      "z": -12,
      "name": "Rock_Marble_Brick_Pillar_Middle",
      "rotation": 32
    },
    {
      "x": -22,
      "y": 9,
      "z": -12,
      "name": "Rock_Marble_Brick_Pillar_Middle",
      "rotation": 32
    },
    {
      "x": -22,
      "y": 10,
      "z": -12,
      "name": "Rock_Marble_Brick_Pillar_Middle",
      "rotation": 32
    },
    {
      "x": -22,
      "y": 11,
      "z": -12,
      "name": "Rock_Marble_Brick_Pillar_Middle",
      "rotation": 32
    },
    {
      "x": -22,
      "y": 12,
      "z": -12,
      "name": "Rock_Marble_Brick_Pillar_Middle",
      "rotation": 32
    },
    {
      "x": -22,
      "y": 13,
      "z": -12,
      "name": "Rock_Marble_Brick_Pillar_Middle",
      "rotation": 32
    },
    {
      "x": -22,
      "y": 14,
      "z": -12,
      "name": "Rock_Marble_Brick_Pillar_Middle",
      "rotation": 32
    },
    {
      "x": -22,
      "y": 15,
      "z": -12,
      "name": "Rock_Marble_Brick_Pillar_Middle",
      "rotation": 32
    },
    {
      "x": -22,
      "y": 16,
      "z": -12,
      "name": "Rock_Marble_Brick_Pillar_Base",
      "rotation": 32
    },
    {
      "x": -22,
      "y": 17,
      "z": -12,
      "name": "Rock_Marble_Brick",
      "rotation": 3
    },
    {
      "x": -22,
      "y": 18,
      "z": -12,
      "name": "Rock_Marble_Brick_Decorative",
      "rotation": 11
    },
    {
      "x": -22,
      "y": 19,
      "z": -12,
      "name": "Rock_Marble_Brick",
      "rotation": 3
    },
    {
      "x": -22,
      "y": 20,
      "z": -12,
      "name": "Rock_Chalk"
    },
    {
      "x": -22,
      "y": 21,
      "z": -12,
      "name": "Rock_Chalk"
    },
    {
      "x": -22,
      "y": 22,
      "z": -12,
      "name": "Rock_Chalk_Brick_Roof_Shallow",
      "rotation": 2
    },
    {
      "x": -22,
      "y": 0,
      "z": -11,
      "name": "Rock_Chalk_Brick"
    },
    {
      "x": -22,
      "y": 5,
      "z": -11,
      "name": "Rock_Marble_Brick_Half",
      "rotation": 7
    },
    {
      "x": -22,
      "y": 11,
      "z": -11,
      "name": "Rock_Marble_Brick_Half",
      "rotation": 7
    },
    {
      "x": -22,
      "y": 17,
      "z": -11,
      "name": "Rock_Marble_Brick",
      "rotation": 3
    },
    {
      "x": -22,
      "y": 18,
      "z": -11,
      "name": "Rock_Marble_Brick_Decorative",
      "rotation": 11
    },
    {
      "x": -22,
      "y": 19,
      "z": -11,
      "name": "Rock_Marble_Brick",
      "rotation": 3
    },
    {
      "x": -22,
      "y": 20,
      "z": -11,
      "name": "Rock_Marble_Brick",
      "rotation": 3
    },
    {
      "x": -22,
      "y": 21,
      "z": -11,
      "name": "Rock_Chalk"
    },
    {
      "x": -22,
      "y": 22,
      "z": -11,
      "name": "Rock_Chalk_Brick_Roof_Shallow",
      "filler": 32,
      "rotation": 2
    },
    {
      "x": -22,
      "y": 0,
      "z": -10,
      "name": "Rock_Chalk_Brick"
    },
    {
      "x": -22,
      "y": 5,
      "z": -10,
      "name": "Rock_Marble_Brick_Half",
      "rotation": 7
    },
    {
      "x": -22,
      "y": 11,
      "z": -10,
      "name": "Rock_Marble_Brick_Half",
      "rotation": 7
    },
    {
      "x": -22,
      "y": 17,
      "z": -10,
      "name": "Rock_Marble_Brick",
      "rotation": 3
    },
    {
      "x": -22,
      "y": 18,
      "z": -10,
      "name": "Rock_Marble_Brick_Decorative",
      "rotation": 11
    },
    {
      "x": -22,
      "y": 19,
      "z": -10,
      "name": "Rock_Marble_Brick",
      "rotation": 3
    },
    {
      "x": -22,
      "y": 20,
      "z": -10,
      "name": "Rock_Marble_Brick",
      "rotation": 3
    },
    {
      "x": -22,
      "y": 21,
      "z": -10,
      "name": "Rock_Chalk"
    },
    {
      "x": -22,
      "y": 22,
      "z": -10,
      "name": "Rock_Chalk"
    },
    {
      "x": -22,
      "y": 23,
      "z": -10,
      "name": "Rock_Marble_Brick_Stairs",
      "rotation": 2
    },
    {
      "x": -22,
      "y": 0,
      "z": -9,
      "name": "Rock_Chalk_Brick"
    },
    {
      "x": -22,
      "y": 5,
      "z": -9,
      "name": "Rock_Marble_Brick_Half",
      "rotation": 7
    },
    {
      "x": -22,
      "y": 11,
      "z": -9,
      "name": "Rock_Marble_Brick_Half",
      "rotation": 7
    },
    {
      "x": -22,
      "y": 17,
      "z": -9,
      "name": "Rock_Marble_Brick",
      "rotation": 3
    },
    {
      "x": -22,
      "y": 18,
      "z": -9,
      "name": "Rock_Marble_Brick_Decorative",
      "rotation": 33
    },
    {
      "x": -22,
      "y": 19,
      "z": -9,
      "name": "Rock_Marble_Brick",
      "rotation": 3
    },
    {
      "x": -22,
      "y": 20,
      "z": -9,
      "name": "Rock_Marble_Brick",
      "rotation": 3
    },
    {
      "x": -22,
      "y": 21,
      "z": -9,
      "name": "Rock_Chalk",
      "rotation": 2
    },
    {
      "x": -22,
      "y": 22,
      "z": -9,
      "name": "Rock_Chalk",
      "rotation": 2
    },
    {
      "x": -22,
      "y": 23,
      "z": -9,
      "name": "Rock_Marble_Brick_Stairs"
    },
    {
      "x": -22,
      "y": 0,
      "z": -8,
      "name": "Rock_Chalk_Brick"
    },
    {
      "x": -22,
      "y": 5,
      "z": -8,
      "name": "Rock_Marble_Brick_Half",
      "rotation": 7
    },
    {
      "x": -22,
      "y": 11,
      "z": -8,
      "name": "Rock_Marble_Brick_Half",
      "rotation": 7
    },
    {
      "x": -22,
      "y": 17,
      "z": -8,
      "name": "Rock_Marble_Brick",
      "rotation": 3
    },
    {
      "x": -22,
      "y": 18,
      "z": -8,
      "name": "Rock_Marble_Brick_Decorative",
      "rotation": 33
    },
    {
      "x": -22,
      "y": 19,
      "z": -8,
      "name": "Rock_Marble_Brick",
      "rotation": 3
    },
    {
      "x": -22,
      "y": 20,
      "z": -8,
      "name": "Rock_Marble_Brick",
      "rotation": 3
    },
    {
      "x": -22,
      "y": 21,
      "z": -8,
      "name": "Rock_Chalk",
      "rotation": 2
    },
    {
      "x": -22,
      "y": 22,
      "z": -8,
      "name": "Rock_Chalk_Brick_Roof_Shallow",
      "filler": 992
    },
    {
      "x": -22,
      "y": 0,
      "z": -7,
      "name": "Rock_Chalk_Brick"
    },
    {
      "x": -22,
      "y": 1,
      "z": -7,
      "name": "Rock_Marble_Brick_Pillar_Base"
    },
    {
      "x": -22,
      "y": 2,
      "z": -7,
      "name": "Rock_Marble_Brick_Pillar_Middle",
      "rotation": 8
    },
    {
      "x": -22,
      "y": 3,
      "z": -7,
      "name": "Rock_Marble_Brick_Pillar_Middle",
      "rotation": 8
    },
    {
      "x": -22,
      "y": 4,
      "z": -7,
      "name": "Rock_Marble_Brick_Pillar_Base",
      "rotation": 8
    },
    {
      "x": -22,
      "y": 5,
      "z": -7,
      "name": "Rock_Marble_Brick"
    },
    {
      "x": -22,
      "y": 6,
      "z": -7,
      "name": "Rock_Marble_Brick_Pillar_Base"
    },
    {
      "x": -22,
      "y": 7,
      "z": -7,
      "name": "Rock_Marble_Brick_Pillar_Middle",
      "rotation": 8
    },
    {
      "x": -22,
      "y": 8,
      "z": -7,
      "name": "Rock_Marble_Brick_Pillar_Middle",
      "rotation": 8
    },
    {
      "x": -22,
      "y": 9,
      "z": -7,
      "name": "Rock_Marble_Brick_Pillar_Middle",
      "rotation": 8
    },
    {
      "x": -22,
      "y": 10,
      "z": -7,
      "name": "Rock_Marble_Brick_Pillar_Middle",
      "rotation": 8
    },
    {
      "x": -22,
      "y": 11,
      "z": -7,
      "name": "Rock_Marble_Brick_Pillar_Middle",
      "rotation": 8
    },
    {
      "x": -22,
      "y": 12,
      "z": -7,
      "name": "Rock_Marble_Brick_Pillar_Middle",
      "rotation": 8
    },
    {
      "x": -22,
      "y": 13,
      "z": -7,
      "name": "Rock_Marble_Brick_Pillar_Middle",
      "rotation": 8
    },
    {
      "x": -22,
      "y": 14,
      "z": -7,
      "name": "Rock_Marble_Brick_Pillar_Middle",
      "rotation": 8
    },
    {
      "x": -22,
      "y": 15,
      "z": -7,
      "name": "Rock_Marble_Brick_Pillar_Middle",
      "rotation": 8
    },
    {
      "x": -22,
      "y": 16,
      "z": -7,
      "name": "Rock_Marble_Brick_Pillar_Base",
      "rotation": 8
    },
    {
      "x": -22,
      "y": 17,
      "z": -7,
      "name": "Rock_Marble_Brick",
      "rotation": 3
    },
    {
      "x": -22,
      "y": 18,
      "z": -7,
      "name": "Rock_Marble_Brick_Decorative",
      "rotation": 33
    },
    {
      "x": -22,
      "y": 19,
      "z": -7,
      "name": "Rock_Marble_Brick",
      "rotation": 3
    },
    {
      "x": -22,
      "y": 20,
      "z": -7,
      "name": "Rock_Chalk",
      "rotation": 2
    },
    {
      "x": -22,
      "y": 21,
      "z": -7,
      "name": "Rock_Chalk",
      "rotation": 2
    },
    {
      "x": -22,
      "y": 22,
      "z": -7,
      "name": "Rock_Chalk_Brick_Roof_Shallow"
    },
    {
      "x": -22,
      "y": 0,
      "z": -6,
      "name": "Rock_Chalk_Brick"
    },
    {
      "x": -22,
      "y": 5,
      "z": -6,
      "name": "Rock_Marble_Brick_Half",
      "rotation": 7
    },
    {
      "x": -22,
      "y": 11,
      "z": -6,
      "name": "Rock_Marble_Brick_Half",
      "rotation": 7
    },
    {
      "x": -22,
      "y": 17,
      "z": -6,
      "name": "Rock_Marble_Brick",
      "rotation": 3
    },
    {
      "x": -22,
      "y": 18,
      "z": -6,
      "name": "Rock_Marble_Brick_Decorative",
      "rotation": 33
    },
    {
      "x": -22,
      "y": 19,
      "z": -6,
      "name": "Rock_Marble_Brick",
      "rotation": 3
    },
    {
      "x": -22,
      "y": 20,
      "z": -6,
      "name": "Rock_Chalk",
      "rotation": 2
    },
    {
      "x": -22,
      "y": 21,
      "z": -6,
      "name": "Rock_Chalk_Brick_Roof_Shallow",
      "filler": 992
    },
    {
      "x": -22,
      "y": 0,
      "z": -5,
      "name": "Rock_Chalk_Brick"
    },
    {
      "x": -22,
      "y": 5,
      "z": -5,
      "name": "Rock_Marble_Brick_Half",
      "rotation": 7
    },
    {
      "x": -22,
      "y": 11,
      "z": -5,
      "name": "Rock_Marble_Brick_Half",
      "rotation": 7
    },
    {
      "x": -22,
      "y": 17,
      "z": -5,
      "name": "Rock_Marble_Brick",
      "rotation": 3
    },
    {
      "x": -22,
      "y": 18,
      "z": -5,
      "name": "Rock_Marble_Brick_Decorative",
      "rotation": 33
    },
    {
      "x": -22,
      "y": 19,
      "z": -5,
      "name": "Rock_Marble_Brick",
      "rotation": 3
    },
    {
      "x": -22,
      "y": 20,
      "z": -5,
      "name": "Rock_Chalk",
      "rotation": 2
    },
    {
      "x": -22,
      "y": 21,
      "z": -5,
      "name": "Rock_Chalk_Brick_Roof_Shallow"
    },
    {
      "x": -22,
      "y": 0,
      "z": -4,
      "name": "Rock_Chalk_Brick"
    },
    {
      "x": -22,
      "y": 1,
      "z": -4,
      "name": "Rock_Marble_Brick_Pillar_Base"
    },
    {
      "x": -22,
      "y": 2,
      "z": -4,
      "name": "Rock_Marble_Brick_Pillar_Middle",
      "rotation": 8
    },
    {
      "x": -22,
      "y": 3,
      "z": -4,
      "name": "Rock_Marble_Brick_Pillar_Middle",
      "rotation": 8
    },
    {
      "x": -22,
      "y": 4,
      "z": -4,
      "name": "Rock_Marble_Brick_Pillar_Base",
      "rotation": 8
    },
    {
      "x": -22,
      "y": 5,
      "z": -4,
      "name": "Rock_Marble_Brick"
    },
    {
      "x": -22,
      "y": 6,
      "z": -4,
      "name": "Rock_Marble_Brick_Pillar_Base"
    },
    {
      "x": -22,
      "y": 7,
      "z": -4,
      "name": "Rock_Marble_Brick_Pillar_Middle",
      "rotation": 8
    },
    {
      "x": -22,
      "y": 8,
      "z": -4,
      "name": "Rock_Marble_Brick_Pillar_Middle",
      "rotation": 8
    },
    {
      "x": -22,
      "y": 9,
      "z": -4,
      "name": "Rock_Marble_Brick_Pillar_Middle",
      "rotation": 8
    },
    {
      "x": -22,
      "y": 10,
      "z": -4,
      "name": "Rock_Marble_Brick_Pillar_Middle",
      "rotation": 8
    },
    {
      "x": -22,
      "y": 11,
      "z": -4,
      "name": "Rock_Marble_Brick_Pillar_Middle",
      "rotation": 8
    },
    {
      "x": -22,
      "y": 12,
      "z": -4,
      "name": "Rock_Marble_Brick_Pillar_Middle",
      "rotation": 8
    },
    {
      "x": -22,
      "y": 13,
      "z": -4,
      "name": "Rock_Marble_Brick_Pillar_Middle",
      "rotation": 8
    },
    {
      "x": -22,
      "y": 14,
      "z": -4,
      "name": "Rock_Marble_Brick_Pillar_Middle",
      "rotation": 8
    },
    {
      "x": -22,
      "y": 15,
      "z": -4,
      "name": "Rock_Marble_Brick_Pillar_Middle",
      "rotation": 8
    },
    {
      "x": -22,
      "y": 16,
      "z": -4,
      "name": "Rock_Marble_Brick_Pillar_Base",
      "rotation": 8
    },
    {
      "x": -22,
      "y": 17,
      "z": -4,
      "name": "Rock_Marble_Brick",
      "rotation": 3
    },
    {
      "x": -22,
      "y": 18,
      "z": -4,
      "name": "Rock_Marble_Brick_Decorative",
      "rotation": 33
    },
    {
      "x": -22,
      "y": 19,
      "z": -4,
      "name": "Rock_Marble_Brick",
      "rotation": 3
    },
    {
      "x": -22,
      "y": 20,
      "z": -4,
      "name": "Rock_Chalk_Brick_Roof_Shallow",
      "filler": 992
    },
    {
      "x": -22,
      "y": 0,
      "z": -3,
      "name": "Rock_Chalk_Brick"
    },
    {
      "x": -22,
      "y": 17,
      "z": -3,
      "name": "Rock_Marble_Brick_Half",
      "rotation": 4
    },
    {
      "x": -22,
      "y": 18,
      "z": -3,
      "name": "Furniture_Temple_Light_Ladder"
    },
    {
      "x": -22,
      "y": 19,
      "z": -3,
      "name": "Rock_Marble_Brick_Wall",
      "rotation": 2
    },
    {
      "x": -22,
      "y": 20,
      "z": -3,
      "name": "Rock_Chalk_Brick_Roof_Shallow"
    },
    {
      "x": -22,
      "y": 0,
      "z": -2,
      "name": "Rock_Chalk_Brick"
    },
    {
      "x": -22,
      "y": 0,
      "z": -1,
      "name": "Rock_Chalk_Brick"
    },
    {
      "x": -22,
      "y": 0,
      "z": 0,
      "name": "Rock_Chalk_Brick"
    },
    {
      "x": -22,
      "y": 0,
      "z": 1,
      "name": "Rock_Chalk_Brick"
    },
    {
      "x": -22,
      "y": 0,
      "z": 2,
      "name": "Rock_Chalk_Brick"
    },
    {
      "x": -22,
      "y": 0,
      "z": 3,
      "name": "Rock_Chalk_Brick"
    },
    {
      "x": -22,
      "y": 0,
      "z": 4,
      "name": "Rock_Chalk_Brick"
    },
    {
      "x": -22,
      "y": 0,
      "z": 5,
      "name": "Rock_Chalk_Brick"
    },
    {
      "x": -22,
      "y": 0,
      "z": 6,
      "name": "Rock_Chalk_Brick"
    },
    {
      "x": -22,
      "y": 0,
      "z": 7,
      "name": "Rock_Chalk_Brick"
    },
    {
      "x": -22,
      "y": 0,
      "z": 8,
      "name": "Rock_Chalk_Brick"
    },
    {
      "x": -22,
      "y": 0,
      "z": 9,
      "name": "Rock_Chalk_Brick"
    },
    {
      "x": -22,
      "y": 0,
      "z": 10,
      "name": "Rock_Chalk_Brick"
    },
    {
      "x": -22,
      "y": 0,
      "z": 11,
      "name": "Rock_Chalk_Brick"
    },
    {
      "x": -22,
      "y": 0,
      "z": 12,
      "name": "Rock_Chalk_Brick"
    },
    {
      "x": -22,
      "y": 0,
      "z": 13,
      "name": "Rock_Chalk_Brick"
    },
    {
      "x": -22,
      "y": 0,
      "z": 14,
      "name": "Rock_Chalk_Brick"
    },
    {
      "x": -22,
      "y": 0,
      "z": 15,
      "name": "Rock_Chalk_Brick"
    },
    {
      "x": -22,
      "y": 0,
      "z": 16,
      "name": "Rock_Chalk_Brick"
    },
    {
      "x": -22,
      "y": 0,
      "z": 17,
      "name": "Rock_Chalk_Brick"
    },
    {
      "x": -22,
      "y": 0,
      "z": 18,
      "name": "Rock_Chalk_Brick"
    },
    {
      "x": -22,
      "y": 0,
      "z": 19,
      "name": "Rock_Chalk_Brick"
    },
    {
      "x": -22,
      "y": 0,
      "z": 20,
      "name": "Rock_Chalk_Brick"
    },
    {
      "x": -22,
      "y": 0,
      "z": 21,
      "name": "Rock_Chalk_Brick"
    },
    {
      "x": -22,
      "y": 0,
      "z": 22,
      "name": "Rock_Chalk_Brick"
    },
    {
      "x": -22,
      "y": 0,
      "z": 23,
      "name": "Rock_Chalk_Brick"
    },
    {
      "x": -22,
      "y": 0,
      "z": 24,
      "name": "Rock_Chalk_Brick"
    },
    {
      "x": -22,
      "y": 0,
      "z": 25,
      "name": "Rock_Chalk_Brick"
    },
    {
      "x": -22,
      "y": 0,
      "z": 26,
      "name": "Rock_Chalk_Brick"
    },
    {
      "x": -22,
      "y": 0,
      "z": 27,
      "name": "Rock_Chalk_Brick"
    },
    {
      "x": -22,
      "y": 0,
      "z": 28,
      "name": "Rock_Chalk_Brick"
    },
    {
      "x": -22,
      "y": 0,
      "z": 29,
      "name": "Rock_Chalk_Brick"
    },
    {
      "x": -21,
      "y": 0,
      "z": -27,
      "name": "Rock_Chalk_Brick"
    },
    {
      "x": -21,
      "y": 0,
      "z": -26,
      "name": "Rock_Chalk_Brick"
    },
    {
      "x": -21,
      "y": 0,
      "z": -25,
      "name": "Rock_Chalk_Brick"
    },
    {
      "x": -21,
      "y": 0,
      "z": -24,
      "name": "Rock_Chalk_Brick"
    },
    {
      "x": -21,
      "y": 0,
      "z": -23,
      "name": "Rock_Chalk_Brick"
    },
    {
      "x": -21,
      "y": 0,
      "z": -22,
      "name": "Rock_Chalk_Brick"
    },
    {
      "x": -21,
      "y": 0,
      "z": -21,
      "name": "Rock_Chalk_Brick"
    },
    {
      "x": -21,
      "y": 0,
      "z": -20,
      "name": "Rock_Chalk_Brick"
    },
    {
      "x": -21,
      "y": 0,
      "z": -19,
      "name": "Rock_Chalk_Brick"
    },
    {
      "x": -21,
      "y": 0,
      "z": -18,
      "name": "Rock_Chalk_Brick"
    },
    {
      "x": -21,
      "y": 0,
      "z": -17,
      "name": "Rock_Chalk_Brick"
    },
    {
      "x": -21,
      "y": 0,
      "z": -16,
      "name": "Rock_Chalk_Brick"
    },
    {
      "x": -21,
      "y": 17,
      "z": -16,
      "name": "Rock_Marble_Brick_Half",
      "rotation": 6
    },
    {
      "x": -21,
      "y": 19,
      "z": -16,
      "name": "Rock_Marble_Brick_Wall"
    },
    {
      "x": -21,
      "y": 20,
      "z": -16,
      "name": "Rock_Chalk_Brick_Roof_Shallow",
      "rotation": 2
    },
    {
      "x": -21,
      "y": 0,
      "z": -15,
      "name": "Rock_Chalk_Brick"
    },
    {
      "x": -21,
      "y": 5,
      "z": -15,
      "name": "Rock_Marble_Brick_Half",
      "rotation": 6
    },
    {
      "x": -21,
      "y": 17,
      "z": -15,
      "name": "Rock_Marble_Brick",
      "rotation": 3
    },
    {
      "x": -21,
      "y": 18,
      "z": -15,
      "name": "Rock_Marble_Brick_Decorative",
      "rotation": 11
    },
    {
      "x": -21,
      "y": 19,
      "z": -15,
      "name": "Rock_Marble_Brick",
      "rotation": 3
    },
    {
      "x": -21,
      "y": 20,
      "z": -15,
      "name": "Rock_Chalk_Brick_Roof_Shallow",
      "filler": 32,
      "rotation": 2
    },
    {
      "x": -21,
      "y": 0,
      "z": -14,
      "name": "Rock_Chalk_Brick"
    },
    {
      "x": -21,
      "y": 5,
      "z": -14,
      "name": "Rock_Marble_Brick",
      "rotation": 2
    },
    {
      "x": -21,
      "y": 6,
      "z": -14,
      "name": "Rock_Marble_Brick_Smooth",
      "rotation": 2
    },
    {
      "x": -21,
      "y": 7,
      "z": -14,
      "name": "Rock_Marble_Brick_Smooth",
      "rotation": 2
    },
    {
      "x": -21,
      "y": 8,
      "z": -14,
      "name": "Rock_Marble_Brick_Smooth",
      "rotation": 2
    },
    {
      "x": -21,
      "y": 9,
      "z": -14,
      "name": "Rock_Marble_Brick_Smooth",
      "rotation": 2
    },
    {
      "x": -21,
      "y": 10,
      "z": -14,
      "name": "Rock_Marble_Brick_Smooth",
      "rotation": 2
    },
    {
      "x": -21,
      "y": 11,
      "z": -14,
      "name": "Rock_Marble_Brick",
      "rotation": 2
    },
    {
      "x": -21,
      "y": 12,
      "z": -14,
      "name": "Rock_Marble_Brick_Smooth",
      "rotation": 2
    },
    {
      "x": -21,
      "y": 13,
      "z": -14,
      "name": "Rock_Marble_Brick_Smooth",
      "rotation": 2
    },
    {
      "x": -21,
      "y": 14,
      "z": -14,
      "name": "Rock_Marble_Brick_Smooth",
      "rotation": 2
    },
    {
      "x": -21,
      "y": 15,
      "z": -14,
      "name": "Rock_Marble_Brick_Smooth",
      "rotation": 2
    },
    {
      "x": -21,
      "y": 16,
      "z": -14,
      "name": "Rock_Marble_Brick_Smooth",
      "rotation": 2
    },
    {
      "x": -21,
      "y": 17,
      "z": -14,
      "name": "Rock_Marble_Brick_Smooth"
    },
    {
      "x": -21,
      "y": 18,
      "z": -14,
      "name": "Rock_Marble_Brick_Smooth"
    },
    {
      "x": -21,
      "y": 19,
      "z": -14,
      "name": "Rock_Marble_Brick_Smooth"
    },
    {
      "x": -21,
      "y": 20,
      "z": -14,
      "name": "Rock_Chalk"
    },
    {
      "x": -21,
      "y": 21,
      "z": -14,
      "name": "Rock_Chalk_Brick_Roof_Shallow",
      "rotation": 2
    },
    {
      "x": -21,
      "y": 0,
      "z": -13,
      "name": "Rock_Chalk_Brick"
    },
    {
      "x": -21,
      "y": 5,
      "z": -13,
      "name": "Rock_Marble_Brick",
      "rotation": 2
    },
    {
      "x": -21,
      "y": 6,
      "z": -13,
      "name": "Rock_Marble_Brick_Smooth",
      "rotation": 2
    },
    {
      "x": -21,
      "y": 7,
      "z": -13,
      "name": "Rock_Marble_Brick_Smooth",
      "rotation": 2
    },
    {
      "x": -21,
      "y": 8,
      "z": -13,
      "name": "Rock_Marble_Brick_Smooth",
      "rotation": 2
    },
    {
      "x": -21,
      "y": 9,
      "z": -13,
      "name": "Rock_Marble_Brick_Smooth",
      "rotation": 2
    },
    {
      "x": -21,
      "y": 10,
      "z": -13,
      "name": "Rock_Marble_Brick_Smooth",
      "rotation": 2
    },
    {
      "x": -21,
      "y": 11,
      "z": -13,
      "name": "Rock_Marble_Brick",
      "rotation": 2
    },
    {
      "x": -21,
      "y": 12,
      "z": -13,
      "name": "Rock_Marble_Brick_Smooth",
      "rotation": 2
    },
    {
      "x": -21,
      "y": 13,
      "z": -13,
      "name": "Rock_Marble_Brick_Smooth",
      "rotation": 2
    },
    {
      "x": -21,
      "y": 14,
      "z": -13,
      "name": "Rock_Marble_Brick_Smooth",
      "rotation": 2
    },
    {
      "x": -21,
      "y": 15,
      "z": -13,
      "name": "Rock_Marble_Brick_Smooth",
      "rotation": 2
    },
    {
      "x": -21,
      "y": 16,
      "z": -13,
      "name": "Rock_Marble_Brick_Smooth",
      "rotation": 2
    },
    {
      "x": -21,
      "y": 17,
      "z": -13,
      "name": "Rock_Marble_Brick",
      "rotation": 3
    },
    {
      "x": -21,
      "y": 21,
      "z": -13,
      "name": "Rock_Chalk_Brick_Roof_Shallow",
      "filler": 32,
      "rotation": 2
    },
    {
      "x": -21,
      "y": 0,
      "z": -12,
      "name": "Rock_Chalk_Brick"
    },
    {
      "x": -21,
      "y": 5,
      "z": -12,
      "name": "Rock_Marble_Brick",
      "rotation": 2
    },
    {
      "x": -21,
      "y": 6,
      "z": -12,
      "name": "Rock_Marble_Brick",
      "rotation": 2
    },
    {
      "x": -21,
      "y": 7,
      "z": -12,
      "name": "Rock_Marble_Brick",
      "rotation": 2
    },
    {
      "x": -21,
      "y": 8,
      "z": -12,
      "name": "Rock_Marble_Brick",
      "rotation": 2
    },
    {
      "x": -21,
      "y": 9,
      "z": -12,
      "name": "Rock_Marble_Brick",
      "rotation": 2
    },
    {
      "x": -21,
      "y": 10,
      "z": -12,
      "name": "Rock_Marble_Brick",
      "rotation": 2
    },
    {
      "x": -21,
      "y": 11,
      "z": -12,
      "name": "Rock_Marble_Brick",
      "rotation": 2
    },
    {
      "x": -21,
      "y": 12,
      "z": -12,
      "name": "Rock_Marble_Brick",
      "rotation": 2
    },
    {
      "x": -21,
      "y": 13,
      "z": -12,
      "name": "Rock_Marble_Brick",
      "rotation": 2
    },
    {
      "x": -21,
      "y": 14,
      "z": -12,
      "name": "Rock_Marble_Brick",
      "rotation": 2
    },
    {
      "x": -21,
      "y": 15,
      "z": -12,
      "name": "Rock_Marble_Brick",
      "rotation": 2
    },
    {
      "x": -21,
      "y": 16,
      "z": -12,
      "name": "Rock_Marble_Brick",
      "rotation": 2
    },
    {
      "x": -21,
      "y": 17,
      "z": -12,
      "name": "Rock_Marble_Brick",
      "rotation": 3
    },
    {
      "x": -21,
      "y": 21,
      "z": -12,
      "name": "Rock_Marble_Brick"
    },
    {
      "x": -21,
      "y": 22,
      "z": -12,
      "name": "Rock_Chalk_Brick_Roof_Shallow",
      "rotation": 2
    },
    {
      "x": -21,
      "y": 0,
      "z": -11,
      "name": "Rock_Chalk_Brick"
    },
    {
      "x": -21,
      "y": 5,
      "z": -11,
      "name": "Rock_Marble_Brick",
      "rotation": 2
    },
    {
      "x": -21,
      "y": 6,
      "z": -11,
      "name": "Rock_Marble_Brick_Stairs",
      "rotation": 51
    },
    {
      "x": -21,
      "y": 7,
      "z": -11,
      "name": "Rock_Marble_Brick_Half",
      "rotation": 4
    },
    {
      "x": -21,
      "y": 8,
      "z": -11,
      "name": "Rock_Marble_Brick_Half",
      "rotation": 4
    },
    {
      "x": -21,
      "y": 9,
      "z": -11,
      "name": "Rock_Marble_Brick",
      "rotation": 2
    },
    {
      "x": -21,
      "y": 10,
      "z": -11,
      "name": "Rock_Marble_Brick",
      "rotation": 2
    },
    {
      "x": -21,
      "y": 11,
      "z": -11,
      "name": "Rock_Marble_Brick",
      "rotation": 2
    },
    {
      "x": -21,
      "y": 12,
      "z": -11,
      "name": "Rock_Marble_Brick_Stairs",
      "rotation": 51
    },
    {
      "x": -21,
      "y": 13,
      "z": -11,
      "name": "Rock_Marble_Brick_Half",
      "rotation": 4
    },
    {
      "x": -21,
      "y": 14,
      "z": -11,
      "name": "Rock_Marble_Brick_Half",
      "rotation": 4
    },
    {
      "x": -21,
      "y": 15,
      "z": -11,
      "name": "Rock_Marble_Brick",
      "rotation": 2
    },
    {
      "x": -21,
      "y": 16,
      "z": -11,
      "name": "Rock_Marble_Brick",
      "rotation": 2
    },
    {
      "x": -21,
      "y": 17,
      "z": -11,
      "name": "Rock_Marble_Brick"
    },
    {
      "x": -21,
      "y": 21,
      "z": -11,
      "name": "Rock_Marble_Brick_Stairs",
      "rotation": 10
    },
    {
      "x": -21,
      "y": 22,
      "z": -11,
      "name": "Rock_Chalk_Brick_Roof_Shallow",
      "filler": 32,
      "rotation": 2
    },
    {
      "x": -21,
      "y": 0,
      "z": -10,
      "name": "Rock_Chalk_Brick"
    },
    {
      "x": -21,
      "y": 5,
      "z": -10,
      "name": "Rock_Marble_Brick",
      "rotation": 2
    },
    {
      "x": -21,
      "y": 6,
      "z": -10,
      "name": "Rock_Marble_Brick_Half",
      "rotation": 7
    },
    {
      "x": -21,
      "y": 10,
      "z": -10,
      "name": "Rock_Marble_Brick_Stairs",
      "rotation": 32
    },
    {
      "x": -21,
      "y": 11,
      "z": -10,
      "name": "Rock_Marble_Brick",
      "rotation": 2
    },
    {
      "x": -21,
      "y": 12,
      "z": -10,
      "name": "Rock_Marble_Brick_Half",
      "rotation": 7
    },
    {
      "x": -21,
      "y": 16,
      "z": -10,
      "name": "Rock_Marble_Brick_Stairs",
      "rotation": 32
    },
    {
      "x": -21,
      "y": 17,
      "z": -10,
      "name": "Rock_Marble_Brick"
    },
    {
      "x": -21,
      "y": 22,
      "z": -10,
      "name": "Rock_Marble_Brick"
    },
    {
      "x": -21,
      "y": 23,
      "z": -10,
      "name": "Rock_Marble_Brick_Stairs",
      "rotation": 2
    },
    {
      "x": -21,
      "y": 0,
      "z": -9,
      "name": "Rock_Chalk_Brick"
    },
    {
      "x": -21,
      "y": 5,
      "z": -9,
      "name": "Rock_Marble_Brick"
    },
    {
      "x": -21,
      "y": 6,
      "z": -9,
      "name": "Rock_Marble_Brick_Half",
      "rotation": 7
    },
    {
      "x": -21,
      "y": 10,
      "z": -9,
      "name": "Rock_Marble_Brick_Stairs",
      "rotation": 8
    },
    {
      "x": -21,
      "y": 11,
      "z": -9,
      "name": "Rock_Marble_Brick"
    },
    {
      "x": -21,
      "y": 12,
      "z": -9,
      "name": "Rock_Marble_Brick_Half",
      "rotation": 7
    },
    {
      "x": -21,
      "y": 16,
      "z": -9,
      "name": "Rock_Marble_Brick_Stairs",
      "rotation": 8
    },
    {
      "x": -21,
      "y": 17,
      "z": -9,
      "name": "Rock_Marble_Brick"
    },
    {
      "x": -21,
      "y": 22,
      "z": -9,
      "name": "Rock_Marble_Brick"
    },
    {
      "x": -21,
      "y": 23,
      "z": -9,
      "name": "Rock_Marble_Brick_Stairs"
    },
    {
      "x": -21,
      "y": 0,
      "z": -8,
      "name": "Rock_Chalk_Brick"
    },
    {
      "x": -21,
      "y": 5,
      "z": -8,
      "name": "Rock_Marble_Brick"
    },
    {
      "x": -21,
      "y": 6,
      "z": -8,
      "name": "Rock_Marble_Brick_Stairs",
      "rotation": 19
    },
    {
      "x": -21,
      "y": 7,
      "z": -8,
      "name": "Rock_Marble_Brick_Half",
      "rotation": 6
    },
    {
      "x": -21,
      "y": 8,
      "z": -8,
      "name": "Rock_Marble_Brick_Half",
      "rotation": 6
    },
    {
      "x": -21,
      "y": 9,
      "z": -8,
      "name": "Rock_Marble_Brick"
    },
    {
      "x": -21,
      "y": 10,
      "z": -8,
      "name": "Rock_Marble_Brick"
    },
    {
      "x": -21,
      "y": 11,
      "z": -8,
      "name": "Rock_Marble_Brick"
    },
    {
      "x": -21,
      "y": 12,
      "z": -8,
      "name": "Rock_Marble_Brick_Stairs",
      "rotation": 19
    },
    {
      "x": -21,
      "y": 13,
      "z": -8,
      "name": "Rock_Marble_Brick_Half",
      "rotation": 6
    },
    {
      "x": -21,
      "y": 14,
      "z": -8,
      "name": "Rock_Marble_Brick_Half",
      "rotation": 6
    },
    {
      "x": -21,
      "y": 15,
      "z": -8,
      "name": "Rock_Marble_Brick"
    },
    {
      "x": -21,
      "y": 16,
      "z": -8,
      "name": "Rock_Marble_Brick"
    },
    {
      "x": -21,
      "y": 17,
      "z": -8,
      "name": "Rock_Marble_Brick"
    },
    {
      "x": -21,
      "y": 21,
      "z": -8,
      "name": "Rock_Marble_Brick_Stairs",
      "rotation": 8
    },
    {
      "x": -21,
      "y": 22,
      "z": -8,
      "name": "Rock_Chalk_Brick_Roof_Shallow",
      "filler": 992
    },
    {
      "x": -21,
      "y": 0,
      "z": -7,
      "name": "Rock_Chalk_Brick"
    },
    {
      "x": -21,
      "y": 5,
      "z": -7,
      "name": "Rock_Marble_Brick"
    },
    {
      "x": -21,
      "y": 6,
      "z": -7,
      "name": "Rock_Marble_Brick"
    },
    {
      "x": -21,
      "y": 7,
      "z": -7,
      "name": "Rock_Marble_Brick"
    },
    {
      "x": -21,
      "y": 8,
      "z": -7,
      "name": "Rock_Marble_Brick"
    },
    {
      "x": -21,
      "y": 9,
      "z": -7,
      "name": "Rock_Marble_Brick"
    },
    {
      "x": -21,
      "y": 10,
      "z": -7,
      "name": "Rock_Marble_Brick"
    },
    {
      "x": -21,
      "y": 11,
      "z": -7,
      "name": "Rock_Marble_Brick"
    },
    {
      "x": -21,
      "y": 12,
      "z": -7,
      "name": "Rock_Marble_Brick"
    },
    {
      "x": -21,
      "y": 13,
      "z": -7,
      "name": "Rock_Marble_Brick"
    },
    {
      "x": -21,
      "y": 14,
      "z": -7,
      "name": "Rock_Marble_Brick"
    },
    {
      "x": -21,
      "y": 15,
      "z": -7,
      "name": "Rock_Marble_Brick"
    },
    {
      "x": -21,
      "y": 16,
      "z": -7,
      "name": "Rock_Marble_Brick"
    },
    {
      "x": -21,
      "y": 17,
      "z": -7,
      "name": "Rock_Marble_Brick",
      "rotation": 3
    },
    {
      "x": -21,
      "y": 21,
      "z": -7,
      "name": "Rock_Marble_Brick"
    },
    {
      "x": -21,
      "y": 22,
      "z": -7,
      "name": "Rock_Chalk_Brick_Roof_Shallow"
    },
    {
      "x": -21,
      "y": 0,
      "z": -6,
      "name": "Rock_Chalk_Brick"
    },
    {
      "x": -21,
      "y": 5,
      "z": -6,
      "name": "Rock_Marble_Brick"
    },
    {
      "x": -21,
      "y": 6,
      "z": -6,
      "name": "Rock_Marble_Brick_Smooth"
    },
    {
      "x": -21,
      "y": 7,
      "z": -6,
      "name": "Rock_Marble_Brick_Smooth"
    },
    {
      "x": -21,
      "y": 8,
      "z": -6,
      "name": "Rock_Marble_Brick_Smooth"
    },
    {
      "x": -21,
      "y": 9,
      "z": -6,
      "name": "Rock_Marble_Brick_Smooth"
    },
    {
      "x": -21,
      "y": 10,
      "z": -6,
      "name": "Rock_Marble_Brick_Smooth"
    },
    {
      "x": -21,
      "y": 11,
      "z": -6,
      "name": "Rock_Marble_Brick"
    },
    {
      "x": -21,
      "y": 12,
      "z": -6,
      "name": "Rock_Marble_Brick_Smooth"
    },
    {
      "x": -21,
      "y": 13,
      "z": -6,
      "name": "Rock_Marble_Brick_Smooth"
    },
    {
      "x": -21,
      "y": 14,
      "z": -6,
      "name": "Rock_Marble_Brick_Smooth"
    },
    {
      "x": -21,
      "y": 15,
      "z": -6,
      "name": "Rock_Marble_Brick_Smooth"
    },
    {
      "x": -21,
      "y": 16,
      "z": -6,
      "name": "Rock_Marble_Brick_Smooth"
    },
    {
      "x": -21,
      "y": 17,
      "z": -6,
      "name": "Rock_Marble_Brick",
      "rotation": 3
    },
    {
      "x": -21,
      "y": 21,
      "z": -6,
      "name": "Rock_Chalk_Brick_Roof_Shallow",
      "filler": 992
    },
    {
      "x": -21,
      "y": 0,
      "z": -5,
      "name": "Rock_Chalk_Brick"
    },
    {
      "x": -21,
      "y": 5,
      "z": -5,
      "name": "Rock_Marble_Brick"
    },
    {
      "x": -21,
      "y": 6,
      "z": -5,
      "name": "Rock_Marble_Brick_Smooth"
    },
    {
      "x": -21,
      "y": 7,
      "z": -5,
      "name": "Rock_Marble_Brick_Smooth"
    },
    {
      "x": -21,
      "y": 8,
      "z": -5,
      "name": "Rock_Marble_Brick_Smooth"
    },
    {
      "x": -21,
      "y": 9,
      "z": -5,
      "name": "Rock_Marble_Brick_Smooth"
    },
    {
      "x": -21,
      "y": 10,
      "z": -5,
      "name": "Rock_Marble_Brick_Smooth"
    },
    {
      "x": -21,
      "y": 11,
      "z": -5,
      "name": "Rock_Marble_Brick"
    },
    {
      "x": -21,
      "y": 12,
      "z": -5,
      "name": "Rock_Marble_Brick_Smooth"
    },
    {
      "x": -21,
      "y": 13,
      "z": -5,
      "name": "Rock_Marble_Brick_Smooth"
    },
    {
      "x": -21,
      "y": 14,
      "z": -5,
      "name": "Rock_Marble_Brick_Smooth"
    },
    {
      "x": -21,
      "y": 15,
      "z": -5,
      "name": "Rock_Marble_Brick_Smooth"
    },
    {
      "x": -21,
      "y": 16,
      "z": -5,
      "name": "Rock_Marble_Brick_Smooth"
    },
    {
      "x": -21,
      "y": 17,
      "z": -5,
      "name": "Rock_Marble_Brick_Smooth",
      "rotation": 2
    },
    {
      "x": -21,
      "y": 18,
      "z": -5,
      "name": "Rock_Marble_Brick_Smooth",
      "rotation": 2
    },
    {
      "x": -21,
      "y": 19,
      "z": -5,
      "name": "Rock_Marble_Brick_Smooth",
      "rotation": 2
    },
    {
      "x": -21,
      "y": 20,
      "z": -5,
      "name": "Rock_Chalk"
    },
    {
      "x": -21,
      "y": 21,
      "z": -5,
      "name": "Rock_Chalk_Brick_Roof_Shallow"
    },
    {
      "x": -21,
      "y": 0,
      "z": -4,
      "name": "Rock_Chalk_Brick"
    },
    {
      "x": -21,
      "y": 5,
      "z": -4,
      "name": "Rock_Marble_Brick_Half",
      "rotation": 4
    },
    {
      "x": -21,
      "y": 11,
      "z": -4,
      "name": "Rock_Marble_Brick_Half",
      "rotation": 4
    },
    {
      "x": -21,
      "y": 17,
      "z": -4,
      "name": "Rock_Marble_Brick",
      "rotation": 3
    },
    {
      "x": -21,
      "y": 18,
      "z": -4,
      "name": "Rock_Marble_Brick_Decorative",
      "rotation": 33
    },
    {
      "x": -21,
      "y": 19,
      "z": -4,
      "name": "Rock_Marble_Brick",
      "rotation": 3
    },
    {
      "x": -21,
      "y": 20,
      "z": -4,
      "name": "Rock_Chalk_Brick_Roof_Shallow",
      "filler": 992
    },
    {
      "x": -21,
      "y": 0,
      "z": -3,
      "name": "Rock_Chalk_Brick"
    },
    {
      "x": -21,
      "y": 17,
      "z": -3,
      "name": "Rock_Marble_Brick_Half",
      "rotation": 4
    },
    {
      "x": -21,
      "y": 19,
      "z": -3,
      "name": "Rock_Marble_Brick_Wall",
      "rotation": 2
    },
    {
      "x": -21,
      "y": 20,
      "z": -3,
      "name": "Rock_Chalk_Brick_Roof_Shallow"
    },
    {
      "x": -21,
      "y": 0,
      "z": -2,
      "name": "Rock_Chalk_Brick"
    },
    {
      "x": -21,
      "y": 0,
      "z": -1,
      "name": "Rock_Chalk_Brick"
    },
    {
      "x": -21,
      "y": 0,
      "z": 0,
      "name": "Rock_Chalk_Brick"
    },
    {
      "x": -21,
      "y": 0,
      "z": 1,
      "name": "Rock_Chalk_Brick"
    },
    {
      "x": -21,
      "y": 0,
      "z": 2,
      "name": "Rock_Chalk_Brick"
    },
    {
      "x": -21,
      "y": 0,
      "z": 3,
      "name": "Rock_Chalk_Brick"
    },
    {
      "x": -21,
      "y": 0,
      "z": 4,
      "name": "Rock_Chalk_Brick"
    },
    {
      "x": -21,
      "y": 0,
      "z": 5,
      "name": "Rock_Chalk_Brick"
    },
    {
      "x": -21,
      "y": 0,
      "z": 6,
      "name": "Rock_Chalk_Brick"
    },
    {
      "x": -21,
      "y": 0,
      "z": 7,
      "name": "Rock_Chalk_Brick"
    },
    {
      "x": -21,
      "y": 0,
      "z": 8,
      "name": "Rock_Chalk_Brick"
    },
    {
      "x": -21,
      "y": 0,
      "z": 9,
      "name": "Rock_Chalk_Brick"
    },
    {
      "x": -21,
      "y": 0,
      "z": 10,
      "name": "Rock_Chalk_Brick"
    },
    {
      "x": -21,
      "y": 0,
      "z": 11,
      "name": "Rock_Chalk_Brick"
    },
    {
      "x": -21,
      "y": 0,
      "z": 12,
      "name": "Rock_Chalk_Brick"
    },
    {
      "x": -21,
      "y": 0,
      "z": 13,
      "name": "Rock_Chalk_Brick"
    },
    {
      "x": -21,
      "y": 0,
      "z": 14,
      "name": "Rock_Chalk_Brick"
    },
    {
      "x": -21,
      "y": 0,
      "z": 15,
      "name": "Rock_Chalk_Brick"
    },
    {
      "x": -21,
      "y": 0,
      "z": 16,
      "name": "Rock_Chalk_Brick"
    },
    {
      "x": -21,
      "y": 0,
      "z": 17,
      "name": "Rock_Chalk_Brick"
    },
    {
      "x": -21,
      "y": 0,
      "z": 18,
      "name": "Rock_Chalk_Brick"
    },
    {
      "x": -21,
      "y": 0,
      "z": 19,
      "name": "Rock_Chalk_Brick"
    },
    {
      "x": -21,
      "y": 0,
      "z": 20,
      "name": "Rock_Chalk_Brick"
    },
    {
      "x": -21,
      "y": 0,
      "z": 21,
      "name": "Rock_Chalk_Brick"
    },
    {
      "x": -21,
      "y": 0,
      "z": 22,
      "name": "Rock_Chalk_Brick"
    },
    {
      "x": -21,
      "y": 0,
      "z": 23,
      "name": "Rock_Chalk_Brick"
    },
    {
      "x": -21,
      "y": 0,
      "z": 24,
      "name": "Rock_Chalk_Brick"
    },
    {
      "x": -21,
      "y": 0,
      "z": 25,
      "name": "Rock_Chalk_Brick"
    },
    {
      "x": -21,
      "y": 0,
      "z": 26,
      "name": "Rock_Chalk_Brick"
    },
    {
      "x": -21,
      "y": 0,
      "z": 27,
      "name": "Rock_Chalk_Brick"
    },
    {
      "x": -21,
      "y": 0,
      "z": 28,
      "name": "Rock_Chalk_Brick"
    },
    {
      "x": -21,
      "y": 0,
      "z": 29,
      "name": "Rock_Chalk_Brick"
    },
    {
      "x": -20,
      "y": 0,
      "z": -27,
      "name": "Rock_Chalk_Brick"
    },
    {
      "x": -20,
      "y": 0,
      "z": -26,
      "name": "Rock_Chalk_Brick"
    },
    {
      "x": -20,
      "y": 0,
      "z": -25,
      "name": "Rock_Chalk_Brick"
    },
    {
      "x": -20,
      "y": 0,
      "z": -24,
      "name": "Rock_Chalk_Brick"
    },
    {
      "x": -20,
      "y": 0,
      "z": -23,
      "name": "Rock_Chalk_Brick"
    },
    {
      "x": -20,
      "y": 0,
      "z": -22,
      "name": "Rock_Chalk_Brick"
    },
    {
      "x": -20,
      "y": 0,
      "z": -21,
      "name": "Rock_Chalk_Brick"
    },
    {
      "x": -20,
      "y": 0,
      "z": -20,
      "name": "Rock_Chalk_Brick"
    },
    {
      "x": -20,
      "y": 0,
      "z": -19,
      "name": "Rock_Chalk_Brick"
    },
    {
      "x": -20,
      "y": 0,
      "z": -18,
      "name": "Rock_Chalk_Brick"
    },
    {
      "x": -20,
      "y": 0,
      "z": -17,
      "name": "Rock_Chalk_Brick"
    },
    {
      "x": -20,
      "y": 0,
      "z": -16,
      "name": "Rock_Chalk_Brick"
    },
    {
      "x": -20,
      "y": 17,
      "z": -16,
      "name": "Rock_Marble_Brick_Half",
      "rotation": 6
    },
    {
      "x": -20,
      "y": 18,
      "z": -16,
      "name": "Furniture_Temple_Light_Ladder",
      "rotation": 2
    },
    {
      "x": -20,
      "y": 19,
      "z": -16,
      "name": "Rock_Marble_Brick_Wall"
    },
    {
      "x": -20,
      "y": 20,
      "z": -16,
      "name": "Rock_Chalk_Brick_Roof_Shallow",
      "rotation": 2
    },
    {
      "x": -20,
      "y": 0,
      "z": -15,
      "name": "Rock_Chalk_Brick"
    },
    {
      "x": -20,
      "y": 5,
      "z": -15,
      "name": "Rock_Marble_Brick_Half",
      "rotation": 6
    },
    {
      "x": -20,
      "y": 17,
      "z": -15,
      "name": "Rock_Marble_Brick",
      "rotation": 3
    },
    {
      "x": -20,
      "y": 18,
      "z": -15,
      "name": "Rock_Marble_Brick_Decorative",
      "rotation": 11
    },
    {
      "x": -20,
      "y": 19,
      "z": -15,
      "name": "Rock_Marble_Brick",
      "rotation": 3
    },
    {
      "x": -20,
      "y": 20,
      "z": -15,
      "name": "Rock_Chalk_Brick_Roof_Shallow",
      "filler": 32,
      "rotation": 2
    },
    {
      "x": -20,
      "y": 0,
      "z": -14,
      "name": "Rock_Chalk_Brick"
    },
    {
      "x": -20,
      "y": 5,
      "z": -14,
      "name": "Rock_Marble_Brick",
      "rotation": 2
    },
    {
      "x": -20,
      "y": 6,
      "z": -14,
      "name": "Rock_Marble_Brick_Smooth",
      "rotation": 2
    },
    {
      "x": -20,
      "y": 7,
      "z": -14,
      "name": "Rock_Marble_Brick_Smooth",
      "rotation": 2
    },
    {
      "x": -20,
      "y": 8,
      "z": -14,
      "name": "Rock_Marble_Brick_Smooth",
      "rotation": 2
    },
    {
      "x": -20,
      "y": 9,
      "z": -14,
      "name": "Rock_Marble_Brick_Smooth",
      "rotation": 2
    },
    {
      "x": -20,
      "y": 10,
      "z": -14,
      "name": "Rock_Marble_Brick_Smooth",
      "rotation": 2
    },
    {
      "x": -20,
      "y": 11,
      "z": -14,
      "name": "Rock_Marble_Brick",
      "rotation": 2
    },
    {
      "x": -20,
      "y": 12,
      "z": -14,
      "name": "Rock_Marble_Brick_Smooth",
      "rotation": 2
    },
    {
      "x": -20,
      "y": 13,
      "z": -14,
      "name": "Rock_Marble_Brick_Smooth",
      "rotation": 2
    },
    {
      "x": -20,
      "y": 14,
      "z": -14,
      "name": "Rock_Marble_Brick_Smooth",
      "rotation": 2
    },
    {
      "x": -20,
      "y": 15,
      "z": -14,
      "name": "Rock_Marble_Brick_Smooth",
      "rotation": 2
    },
    {
      "x": -20,
      "y": 16,
      "z": -14,
      "name": "Rock_Marble_Brick_Smooth",
      "rotation": 2
    },
    {
      "x": -20,
      "y": 17,
      "z": -14,
      "name": "Rock_Marble_Brick",
      "rotation": 3
    },
    {
      "x": -20,
      "y": 18,
      "z": -14,
      "name": "Rock_Marble_Brick_Decorative",
      "rotation": 11
    },
    {
      "x": -20,
      "y": 19,
      "z": -14,
      "name": "Rock_Marble_Brick",
      "rotation": 3
    },
    {
      "x": -20,
      "y": 20,
      "z": -14,
      "name": "Rock_Chalk"
    },
    {
      "x": -20,
      "y": 21,
      "z": -14,
      "name": "Rock_Chalk_Brick_Roof_Shallow",
      "rotation": 2
    },
    {
      "x": -20,
      "y": 0,
      "z": -13,
      "name": "Rock_Chalk_Brick"
    },
    {
      "x": -20,
      "y": 5,
      "z": -13,
      "name": "Rock_Marble_Brick_Smooth"
    },
    {
      "x": -20,
      "y": 11,
      "z": -13,
      "name": "Rock_Chalk_Brick"
    },
    {
      "x": -20,
      "y": 17,
      "z": -13,
      "name": "Rock_Marble_Brick"
    },
    {
      "x": -20,
      "y": 20,
      "z": -13,
      "name": "Rock_Marble_Brick_Stairs",
      "rotation": 10
    },
    {
      "x": -20,
      "y": 21,
      "z": -13,
      "name": "Rock_Chalk_Brick_Roof_Shallow",
      "filler": 32,
      "rotation": 2
    },
    {
      "x": -20,
      "y": 0,
      "z": -12,
      "name": "Rock_Chalk_Brick"
    },
    {
      "x": -20,
      "y": 5,
      "z": -12,
      "name": "Rock_Marble_Brick_Smooth"
    },
    {
      "x": -20,
      "y": 11,
      "z": -12,
      "name": "Rock_Marble_Brick"
    },
    {
      "x": -20,
      "y": 13,
      "z": -12,
      "name": "*Wood_Torch_Wall_State_Definitions_Off",
      "rotation": 1
    },
    {
      "x": -20,
      "y": 17,
      "z": -12,
      "name": "Rock_Marble_Brick"
    },
    {
      "x": -20,
      "y": 21,
      "z": -12,
      "name": "Rock_Marble_Brick"
    },
    {
      "x": -20,
      "y": 22,
      "z": -12,
      "name": "Rock_Chalk_Brick_Roof_Shallow",
      "rotation": 2
    },
    {
      "x": -20,
      "y": 0,
      "z": -11,
      "name": "Rock_Chalk_Brick"
    },
    {
      "x": -20,
      "y": 5,
      "z": -11,
      "name": "Rock_Marble_Brick_Smooth"
    },
    {
      "x": -20,
      "y": 11,
      "z": -11,
      "name": "Rock_Chalk_Brick"
    },
    {
      "x": -20,
      "y": 17,
      "z": -11,
      "name": "Rock_Chalk_Brick"
    },
    {
      "x": -20,
      "y": 21,
      "z": -11,
      "name": "Rock_Marble_Brick_Stairs",
      "rotation": 10
    },
    {
      "x": -20,
      "y": 22,
      "z": -11,
      "name": "Rock_Chalk_Brick_Roof_Shallow",
      "filler": 32,
      "rotation": 2
    },
    {
      "x": -20,
      "y": 0,
      "z": -10,
      "name": "Rock_Chalk_Brick"
    },
    {
      "x": -20,
      "y": 5,
      "z": -10,
      "name": "Rock_Marble_Brick_Smooth"
    },
    {
      "x": -20,
      "y": 11,
      "z": -10,
      "name": "Rock_Chalk_Brick"
    },
    {
      "x": -20,
      "y": 17,
      "z": -10,
      "name": "Rock_Chalk_Brick"
    },
    {
      "x": -20,
      "y": 22,
      "z": -10,
      "name": "Rock_Marble_Brick"
    },
    {
      "x": -20,
      "y": 23,
      "z": -10,
      "name": "Rock_Marble_Brick_Stairs",
      "rotation": 2
    },
    {
      "x": -20,
      "y": 0,
      "z": -9,
      "name": "Rock_Chalk_Brick"
    },
    {
      "x": -20,
      "y": 5,
      "z": -9,
      "name": "Rock_Marble_Brick_Smooth"
    },
    {
      "x": -20,
      "y": 11,
      "z": -9,
      "name": "Rock_Chalk_Brick"
    },
    {
      "x": -20,
      "y": 17,
      "z": -9,
      "name": "Rock_Chalk_Brick"
    },
    {
      "x": -20,
      "y": 22,
      "z": -9,
      "name": "Rock_Marble_Brick"
    },
    {
      "x": -20,
      "y": 23,
      "z": -9,
      "name": "Rock_Marble_Brick_Stairs"
    },
    {
      "x": -20,
      "y": 0,
      "z": -8,
      "name": "Rock_Chalk_Brick"
    },
    {
      "x": -20,
      "y": 5,
      "z": -8,
      "name": "Rock_Marble_Brick_Smooth"
    },
    {
      "x": -20,
      "y": 11,
      "z": -8,
      "name": "Rock_Chalk_Brick"
    },
    {
      "x": -20,
      "y": 17,
      "z": -8,
      "name": "Rock_Chalk_Brick"
    },
    {
      "x": -20,
      "y": 21,
      "z": -8,
      "name": "Rock_Marble_Brick_Stairs",
      "rotation": 8
    },
    {
      "x": -20,
      "y": 22,
      "z": -8,
      "name": "Rock_Chalk_Brick_Roof_Shallow",
      "filler": 992
    },
    {
      "x": -20,
      "y": 0,
      "z": -7,
      "name": "Rock_Chalk_Brick"
    },
    {
      "x": -20,
      "y": 5,
      "z": -7,
      "name": "Rock_Marble_Brick_Smooth"
    },
    {
      "x": -20,
      "y": 11,
      "z": -7,
      "name": "Rock_Marble_Brick"
    },
    {
      "x": -20,
      "y": 13,
      "z": -7,
      "name": "*Wood_Torch_Wall_State_Definitions_Off",
      "rotation": 1
    },
    {
      "x": -20,
      "y": 17,
      "z": -7,
      "name": "Rock_Marble_Brick"
    },
    {
      "x": -20,
      "y": 21,
      "z": -7,
      "name": "Rock_Marble_Brick"
    },
    {
      "x": -20,
      "y": 22,
      "z": -7,
      "name": "Rock_Chalk_Brick_Roof_Shallow"
    },
    {
      "x": -20,
      "y": 0,
      "z": -6,
      "name": "Rock_Chalk_Brick"
    },
    {
      "x": -20,
      "y": 5,
      "z": -6,
      "name": "Rock_Marble_Brick_Smooth"
    },
    {
      "x": -20,
      "y": 11,
      "z": -6,
      "name": "Rock_Chalk_Brick"
    },
    {
      "x": -20,
      "y": 17,
      "z": -6,
      "name": "Rock_Marble_Brick"
    },
    {
      "x": -20,
      "y": 20,
      "z": -6,
      "name": "Rock_Marble_Brick_Stairs",
      "rotation": 8
    },
    {
      "x": -20,
      "y": 21,
      "z": -6,
      "name": "Rock_Chalk_Brick_Roof_Shallow",
      "filler": 992
    },
    {
      "x": -20,
      "y": 0,
      "z": -5,
      "name": "Rock_Chalk_Brick"
    },
    {
      "x": -20,
      "y": 5,
      "z": -5,
      "name": "Rock_Marble_Brick"
    },
    {
      "x": -20,
      "y": 6,
      "z": -5,
      "name": "Rock_Marble_Brick_Smooth"
    },
    {
      "x": -20,
      "y": 7,
      "z": -5,
      "name": "Rock_Marble_Brick_Smooth"
    },
    {
      "x": -20,
      "y": 8,
      "z": -5,
      "name": "Rock_Marble_Brick_Smooth"
    },
    {
      "x": -20,
      "y": 9,
      "z": -5,
      "name": "Rock_Marble_Brick_Smooth"
    },
    {
      "x": -20,
      "y": 10,
      "z": -5,
      "name": "Rock_Marble_Brick_Smooth"
    },
    {
      "x": -20,
      "y": 11,
      "z": -5,
      "name": "Rock_Marble_Brick"
    },
    {
      "x": -20,
      "y": 12,
      "z": -5,
      "name": "Rock_Marble_Brick_Smooth"
    },
    {
      "x": -20,
      "y": 13,
      "z": -5,
      "name": "Rock_Marble_Brick_Smooth"
    },
    {
      "x": -20,
      "y": 14,
      "z": -5,
      "name": "Rock_Marble_Brick_Smooth"
    },
    {
      "x": -20,
      "y": 15,
      "z": -5,
      "name": "Rock_Marble_Brick_Smooth"
    },
    {
      "x": -20,
      "y": 16,
      "z": -5,
      "name": "Rock_Marble_Brick_Smooth"
    },
    {
      "x": -20,
      "y": 17,
      "z": -5,
      "name": "Rock_Marble_Brick",
      "rotation": 3
    },
    {
      "x": -20,
      "y": 18,
      "z": -5,
      "name": "Rock_Marble_Brick_Decorative",
      "rotation": 33
    },
    {
      "x": -20,
      "y": 19,
      "z": -5,
      "name": "Rock_Marble_Brick",
      "rotation": 3
    },
    {
      "x": -20,
      "y": 20,
      "z": -5,
      "name": "Rock_Chalk",
      "rotation": 2
    },
    {
      "x": -20,
      "y": 21,
      "z": -5,
      "name": "Rock_Chalk_Brick_Roof_Shallow"
    },
    {
      "x": -20,
      "y": 0,
      "z": -4,
      "name": "Rock_Chalk_Brick"
    },
    {
      "x": -20,
      "y": 5,
      "z": -4,
      "name": "Rock_Marble_Brick_Half",
      "rotation": 4
    },
    {
      "x": -20,
      "y": 6,
      "z": -4,
      "name": "Rock_Marble_Brick_Half",
      "rotation": 4
    },
    {
      "x": -20,
      "y": 7,
      "z": -4,
      "name": "Rock_Marble_Brick_Half",
      "rotation": 4
    },
    {
      "x": -20,
      "y": 8,
      "z": -4,
      "name": "Rock_Marble_Brick_Half",
      "rotation": 4
    },
    {
      "x": -20,
      "y": 9,
      "z": -4,
      "name": "Rock_Marble_Brick_Half",
      "rotation": 4
    },
    {
      "x": -20,
      "y": 10,
      "z": -4,
      "name": "Rock_Marble_Brick_Half",
      "rotation": 4
    },
    {
      "x": -20,
      "y": 11,
      "z": -4,
      "name": "Rock_Marble_Brick_Half",
      "rotation": 4
    },
    {
      "x": -20,
      "y": 12,
      "z": -4,
      "name": "Rock_Marble_Brick_Half",
      "rotation": 4
    },
    {
      "x": -20,
      "y": 13,
      "z": -4,
      "name": "Rock_Marble_Brick_Half",
      "rotation": 4
    },
    {
      "x": -20,
      "y": 14,
      "z": -4,
      "name": "Rock_Marble_Brick_Half",
      "rotation": 4
    },
    {
      "x": -20,
      "y": 15,
      "z": -4,
      "name": "Rock_Marble_Brick_Half",
      "rotation": 4
    },
    {
      "x": -20,
      "y": 16,
      "z": -4,
      "name": "Rock_Marble_Brick_Half",
      "rotation": 4
    },
    {
      "x": -20,
      "y": 17,
      "z": -4,
      "name": "Rock_Marble_Brick",
      "rotation": 3
    },
    {
      "x": -20,
      "y": 18,
      "z": -4,
      "name": "Rock_Marble_Brick_Decorative",
      "rotation": 33
    },
    {
      "x": -20,
      "y": 19,
      "z": -4,
      "name": "Rock_Marble_Brick",
      "rotation": 3
    },
    {
      "x": -20,
      "y": 20,
      "z": -4,
      "name": "Rock_Chalk_Brick_Roof_Shallow",
      "filler": 992
    },
    {
      "x": -20,
      "y": 0,
      "z": -3,
      "name": "Rock_Chalk_Brick"
    },
    {
      "x": -20,
      "y": 17,
      "z": -3,
      "name": "Rock_Marble_Brick_Half",
      "rotation": 4
    },
    {
      "x": -20,
      "y": 18,
      "z": -3,
      "name": "Furniture_Temple_Light_Ladder"
    },
    {
      "x": -20,
      "y": 19,
      "z": -3,
      "name": "Rock_Marble_Brick_Wall",
      "rotation": 2
    },
    {
      "x": -20,
      "y": 20,
      "z": -3,
      "name": "Rock_Chalk_Brick_Roof_Shallow"
    },
    {
      "x": -20,
      "y": 0,
      "z": -2,
      "name": "Rock_Chalk_Brick"
    },
    {
      "x": -20,
      "y": 0,
      "z": -1,
      "name": "Rock_Chalk_Brick"
    },
    {
      "x": -20,
      "y": 0,
      "z": 0,
      "name": "Rock_Chalk_Brick"
    },
    {
      "x": -20,
      "y": 0,
      "z": 1,
      "name": "Rock_Chalk_Brick"
    },
    {
      "x": -20,
      "y": 0,
      "z": 2,
      "name": "Rock_Chalk_Brick"
    },
    {
      "x": -20,
      "y": 0,
      "z": 3,
      "name": "Rock_Chalk_Brick"
    },
    {
      "x": -20,
      "y": 0,
      "z": 4,
      "name": "Rock_Chalk_Brick"
    },
    {
      "x": -20,
      "y": 0,
      "z": 5,
      "name": "Rock_Chalk_Brick"
    },
    {
      "x": -20,
      "y": 0,
      "z": 6,
      "name": "Rock_Chalk_Brick"
    },
    {
      "x": -20,
      "y": 0,
      "z": 7,
      "name": "Rock_Chalk_Brick"
    },
    {
      "x": -20,
      "y": 0,
      "z": 8,
      "name": "Rock_Chalk_Brick"
    },
    {
      "x": -20,
      "y": 0,
      "z": 9,
      "name": "Rock_Chalk_Brick"
    },
    {
      "x": -20,
      "y": 1,
      "z": 9,
      "name": "Rock_Marble_Brick_Half",
      "rotation": 7
    },
    {
      "x": -20,
      "y": 0,
      "z": 10,
      "name": "Rock_Chalk_Brick"
    },
    {
      "x": -20,
      "y": 0,
      "z": 11,
      "name": "Rock_Chalk_Brick"
    },
    {
      "x": -20,
      "y": 0,
      "z": 12,
      "name": "Rock_Chalk_Brick"
    },
    {
      "x": -20,
      "y": 0,
      "z": 13,
      "name": "Rock_Chalk_Brick"
    },
    {
      "x": -20,
      "y": 0,
      "z": 14,
      "name": "Rock_Chalk_Brick"
    },
    {
      "x": -20,
      "y": 0,
      "z": 15,
      "name": "Rock_Chalk_Brick"
    },
    {
      "x": -20,
      "y": 0,
      "z": 16,
      "name": "Rock_Chalk_Brick"
    },
    {
      "x": -20,
      "y": 0,
      "z": 17,
      "name": "Rock_Chalk_Brick"
    },
    {
      "x": -20,
      "y": 0,
      "z": 18,
      "name": "Rock_Chalk_Brick"
    },
    {
      "x": -20,
      "y": 0,
      "z": 19,
      "name": "Rock_Chalk_Brick"
    },
    {
      "x": -20,
      "y": 0,
      "z": 20,
      "name": "Rock_Chalk_Brick"
    },
    {
      "x": -20,
      "y": 0,
      "z": 21,
      "name": "Rock_Chalk_Brick"
    },
    {
      "x": -20,
      "y": 0,
      "z": 22,
      "name": "Rock_Chalk_Brick"
    },
    {
      "x": -20,
      "y": 0,
      "z": 23,
      "name": "Rock_Chalk_Brick"
    },
    {
      "x": -20,
      "y": 0,
      "z": 24,
      "name": "Rock_Chalk_Brick"
    },
    {
      "x": -20,
      "y": 0,
      "z": 25,
      "name": "Rock_Chalk_Brick"
    },
    {
      "x": -20,
      "y": 0,
      "z": 26,
      "name": "Rock_Chalk_Brick"
    },
    {
      "x": -20,
      "y": 0,
      "z": 27,
      "name": "Rock_Chalk_Brick"
    },
    {
      "x": -20,
      "y": 0,
      "z": 28,
      "name": "Rock_Chalk_Brick"
    },
    {
      "x": -20,
      "y": 0,
      "z": 29,
      "name": "Rock_Chalk_Brick"
    },
    {
      "x": -19,
      "y": 0,
      "z": -27,
      "name": "Rock_Chalk_Brick"
    },
    {
      "x": -19,
      "y": 0,
      "z": -26,
      "name": "Rock_Chalk_Brick"
    },
    {
      "x": -19,
      "y": 0,
      "z": -25,
      "name": "Rock_Chalk_Brick"
    },
    {
      "x": -19,
      "y": 0,
      "z": -24,
      "name": "Rock_Chalk_Brick"
    },
    {
      "x": -19,
      "y": 0,
      "z": -23,
      "name": "Rock_Chalk_Brick"
    },
    {
      "x": -19,
      "y": 0,
      "z": -22,
      "name": "Rock_Chalk_Brick"
    },
    {
      "x": -19,
      "y": 0,
      "z": -21,
      "name": "Rock_Chalk_Brick"
    },
    {
      "x": -19,
      "y": 0,
      "z": -20,
      "name": "Rock_Chalk_Brick"
    },
    {
      "x": -19,
      "y": 0,
      "z": -19,
      "name": "Rock_Chalk_Brick"
    },
    {
      "x": -19,
      "y": 0,
      "z": -18,
      "name": "Rock_Chalk_Brick"
    },
    {
      "x": -19,
      "y": 0,
      "z": -17,
      "name": "Rock_Chalk_Brick"
    },
    {
      "x": -19,
      "y": 0,
      "z": -16,
      "name": "Rock_Chalk_Brick"
    },
    {
      "x": -19,
      "y": 17,
      "z": -16,
      "name": "Rock_Marble_Brick_Half",
      "rotation": 6
    },
    {
      "x": -19,
      "y": 19,
      "z": -16,
      "name": "Rock_Marble_Brick_Wall"
    },
    {
      "x": -19,
      "y": 20,
      "z": -16,
      "name": "Rock_Chalk_Brick_Roof_Shallow",
      "rotation": 2
    },
    {
      "x": -19,
      "y": 0,
      "z": -15,
      "name": "Rock_Chalk_Brick"
    },
    {
      "x": -19,
      "y": 1,
      "z": -15,
      "name": "Rock_Marble_Brick_Half",
      "rotation": 7
    },
    {
      "x": -19,
      "y": 5,
      "z": -15,
      "name": "Rock_Marble_Brick_Half",
      "rotation": 6
    },
    {
      "x": -19,
      "y": 17,
      "z": -15,
      "name": "Rock_Marble_Brick",
      "rotation": 3
    },
    {
      "x": -19,
      "y": 18,
      "z": -15,
      "name": "Rock_Marble_Brick_Decorative",
      "rotation": 11
    },
    {
      "x": -19,
      "y": 19,
      "z": -15,
      "name": "Rock_Marble_Brick",
      "rotation": 3
    },
    {
      "x": -19,
      "y": 20,
      "z": -15,
      "name": "Rock_Chalk_Brick_Roof_Shallow",
      "filler": 32,
      "rotation": 2
    },
    {
      "x": -19,
      "y": 0,
      "z": -14,
      "name": "Rock_Chalk_Brick"
    },
    {
      "x": -19,
      "y": 5,
      "z": -14,
      "name": "Rock_Marble_Brick",
      "rotation": 2
    },
    {
      "x": -19,
      "y": 6,
      "z": -14,
      "name": "Rock_Marble_Brick_Smooth",
      "rotation": 2
    },
    {
      "x": -19,
      "y": 7,
      "z": -14,
      "name": "Rock_Marble_Brick_Smooth",
      "rotation": 2
    },
    {
      "x": -19,
      "y": 8,
      "z": -14,
      "name": "Rock_Marble_Brick_Smooth",
      "rotation": 2
    },
    {
      "x": -19,
      "y": 9,
      "z": -14,
      "name": "Rock_Marble_Brick_Smooth",
      "rotation": 2
    },
    {
      "x": -19,
      "y": 10,
      "z": -14,
      "name": "Rock_Marble_Brick_Smooth",
      "rotation": 2
    },
    {
      "x": -19,
      "y": 11,
      "z": -14,
      "name": "Rock_Marble_Brick",
      "rotation": 2
    },
    {
      "x": -19,
      "y": 12,
      "z": -14,
      "name": "Rock_Marble_Brick_Smooth",
      "rotation": 2
    },
    {
      "x": -19,
      "y": 13,
      "z": -14,
      "name": "Rock_Marble_Brick_Smooth",
      "rotation": 2
    },
    {
      "x": -19,
      "y": 14,
      "z": -14,
      "name": "Rock_Marble_Brick_Smooth",
      "rotation": 2
    },
    {
      "x": -19,
      "y": 15,
      "z": -14,
      "name": "Rock_Marble_Brick_Smooth",
      "rotation": 2
    },
    {
      "x": -19,
      "y": 16,
      "z": -14,
      "name": "Rock_Marble_Brick_Smooth",
      "rotation": 2
    },
    {
      "x": -19,
      "y": 17,
      "z": -14,
      "name": "Rock_Marble_Brick_Smooth"
    },
    {
      "x": -19,
      "y": 18,
      "z": -14,
      "name": "Rock_Marble_Brick_Smooth"
    },
    {
      "x": -19,
      "y": 19,
      "z": -14,
      "name": "Rock_Marble_Brick_Smooth"
    },
    {
      "x": -19,
      "y": 20,
      "z": -14,
      "name": "Rock_Chalk"
    },
    {
      "x": -19,
      "y": 21,
      "z": -14,
      "name": "Rock_Chalk_Brick_Roof_Shallow",
      "rotation": 2
    },
    {
      "x": -19,
      "y": 0,
      "z": -13,
      "name": "Rock_Chalk_Brick"
    },
    {
      "x": -19,
      "y": 5,
      "z": -13,
      "name": "Rock_Marble_Brick_Smooth"
    },
    {
      "x": -19,
      "y": 11,
      "z": -13,
      "name": "Rock_Chalk_Brick"
    },
    {
      "x": -19,
      "y": 17,
      "z": -13,
      "name": "Rock_Marble_Brick"
    },
    {
      "x": -19,
      "y": 21,
      "z": -13,
      "name": "Rock_Chalk_Brick_Roof_Shallow",
      "filler": 32,
      "rotation": 2
    },
    {
      "x": -19,
      "y": 0,
      "z": -12,
      "name": "Rock_Chalk_Brick"
    },
    {
      "x": -19,
      "y": 1,
      "z": -12,
      "name": "Rock_Marble_Brick_Half",
      "rotation": 7
    },
    {
      "x": -19,
      "y": 5,
      "z": -12,
      "name": "Rock_Marble_Brick_Smooth"
    },
    {
      "x": -19,
      "y": 11,
      "z": -12,
      "name": "Rock_Marble_Brick"
    },
    {
      "x": -19,
      "y": 17,
      "z": -12,
      "name": "Rock_Marble_Brick"
    },
    {
      "x": -19,
      "y": 21,
      "z": -12,
      "name": "Rock_Marble_Brick"
    },
    {
      "x": -19,
      "y": 22,
      "z": -12,
      "name": "Rock_Chalk_Brick_Roof_Shallow",
      "rotation": 2
    },
    {
      "x": -19,
      "y": 0,
      "z": -11,
      "name": "Rock_Chalk_Brick"
    },
    {
      "x": -19,
      "y": 5,
      "z": -11,
      "name": "Rock_Marble_Brick_Smooth"
    },
    {
      "x": -19,
      "y": 11,
      "z": -11,
      "name": "Rock_Chalk_Brick"
    },
    {
      "x": -19,
      "y": 17,
      "z": -11,
      "name": "Rock_Chalk_Brick"
    },
    {
      "x": -19,
      "y": 21,
      "z": -11,
      "name": "Rock_Marble_Brick_Stairs",
      "rotation": 10
    },
    {
      "x": -19,
      "y": 22,
      "z": -11,
      "name": "Rock_Chalk_Brick_Roof_Shallow",
      "filler": 32,
      "rotation": 2
    },
    {
      "x": -19,
      "y": 0,
      "z": -10,
      "name": "Rock_Chalk_Brick"
    },
    {
      "x": -19,
      "y": 5,
      "z": -10,
      "name": "Rock_Marble_Brick_Smooth"
    },
    {
      "x": -19,
      "y": 11,
      "z": -10,
      "name": "Rock_Chalk_Brick"
    },
    {
      "x": -19,
      "y": 17,
      "z": -10,
      "name": "Rock_Chalk_Brick"
    },
    {
      "x": -19,
      "y": 22,
      "z": -10,
      "name": "Rock_Marble_Brick"
    },
    {
      "x": -19,
      "y": 23,
      "z": -10,
      "name": "Rock_Marble_Brick_Stairs",
      "rotation": 2
    },
    {
      "x": -19,
      "y": 0,
      "z": -9,
      "name": "Rock_Chalk_Brick"
    },
    {
      "x": -19,
      "y": 5,
      "z": -9,
      "name": "Rock_Marble_Brick_Smooth"
    },
    {
      "x": -19,
      "y": 11,
      "z": -9,
      "name": "Rock_Chalk_Brick"
    },
    {
      "x": -19,
      "y": 17,
      "z": -9,
      "name": "Rock_Chalk_Brick"
    },
    {
      "x": -19,
      "y": 22,
      "z": -9,
      "name": "Rock_Marble_Brick"
    },
    {
      "x": -19,
      "y": 23,
      "z": -9,
      "name": "Rock_Marble_Brick_Stairs"
    },
    {
      "x": -19,
      "y": 0,
      "z": -8,
      "name": "Rock_Chalk_Brick"
    },
    {
      "x": -19,
      "y": 5,
      "z": -8,
      "name": "Rock_Marble_Brick_Smooth"
    },
    {
      "x": -19,
      "y": 11,
      "z": -8,
      "name": "Rock_Chalk_Brick"
    },
    {
      "x": -19,
      "y": 17,
      "z": -8,
      "name": "Rock_Chalk_Brick"
    },
    {
      "x": -19,
      "y": 21,
      "z": -8,
      "name": "Rock_Marble_Brick_Stairs",
      "rotation": 8
    },
    {
      "x": -19,
      "y": 22,
      "z": -8,
      "name": "Rock_Chalk_Brick_Roof_Shallow",
      "filler": 992
    },
    {
      "x": -19,
      "y": 0,
      "z": -7,
      "name": "Rock_Chalk_Brick"
    },
    {
      "x": -19,
      "y": 1,
      "z": -7,
      "name": "Rock_Marble_Brick_Half",
      "rotation": 7
    },
    {
      "x": -19,
      "y": 5,
      "z": -7,
      "name": "Rock_Marble_Brick_Smooth"
    },
    {
      "x": -19,
      "y": 11,
      "z": -7,
      "name": "Rock_Marble_Brick"
    },
    {
      "x": -19,
      "y": 17,
      "z": -7,
      "name": "Rock_Marble_Brick"
    },
    {
      "x": -19,
      "y": 21,
      "z": -7,
      "name": "Rock_Marble_Brick"
    },
    {
      "x": -19,
      "y": 22,
      "z": -7,
      "name": "Rock_Chalk_Brick_Roof_Shallow"
    },
    {
      "x": -19,
      "y": 0,
      "z": -6,
      "name": "Rock_Chalk_Brick"
    },
    {
      "x": -19,
      "y": 5,
      "z": -6,
      "name": "Rock_Marble_Brick_Smooth"
    },
    {
      "x": -19,
      "y": 11,
      "z": -6,
      "name": "Rock_Chalk_Brick"
    },
    {
      "x": -19,
      "y": 17,
      "z": -6,
      "name": "Rock_Marble_Brick"
    },
    {
      "x": -19,
      "y": 21,
      "z": -6,
      "name": "Rock_Chalk_Brick_Roof_Shallow",
      "filler": 992
    },
    {
      "x": -19,
      "y": 0,
      "z": -5,
      "name": "Rock_Chalk_Brick"
    },
    {
      "x": -19,
      "y": 5,
      "z": -5,
      "name": "Rock_Marble_Brick"
    },
    {
      "x": -19,
      "y": 6,
      "z": -5,
      "name": "Rock_Marble_Brick_Smooth"
    },
    {
      "x": -19,
      "y": 7,
      "z": -5,
      "name": "Rock_Marble_Brick_Smooth"
    },
    {
      "x": -19,
      "y": 8,
      "z": -5,
      "name": "Rock_Marble_Brick_Smooth"
    },
    {
      "x": -19,
      "y": 9,
      "z": -5,
      "name": "Rock_Marble_Brick_Smooth"
    },
    {
      "x": -19,
      "y": 10,
      "z": -5,
      "name": "Rock_Marble_Brick_Smooth"
    },
    {
      "x": -19,
      "y": 11,
      "z": -5,
      "name": "Rock_Marble_Brick"
    },
    {
      "x": -19,
      "y": 12,
      "z": -5,
      "name": "Rock_Marble_Brick_Smooth"
    },
    {
      "x": -19,
      "y": 13,
      "z": -5,
      "name": "Rock_Marble_Brick_Smooth"
    },
    {
      "x": -19,
      "y": 14,
      "z": -5,
      "name": "Rock_Marble_Brick_Smooth"
    },
    {
      "x": -19,
      "y": 15,
      "z": -5,
      "name": "Rock_Marble_Brick_Smooth"
    },
    {
      "x": -19,
      "y": 16,
      "z": -5,
      "name": "Rock_Marble_Brick_Smooth"
    },
    {
      "x": -19,
      "y": 17,
      "z": -5,
      "name": "Rock_Marble_Brick_Smooth",
      "rotation": 2
    },
    {
      "x": -19,
      "y": 18,
      "z": -5,
      "name": "Rock_Marble_Brick_Smooth",
      "rotation": 2
    },
    {
      "x": -19,
      "y": 19,
      "z": -5,
      "name": "Rock_Marble_Brick_Smooth",
      "rotation": 2
    },
    {
      "x": -19,
      "y": 20,
      "z": -5,
      "name": "Rock_Chalk"
    },
    {
      "x": -19,
      "y": 21,
      "z": -5,
      "name": "Rock_Chalk_Brick_Roof_Shallow"
    },
    {
      "x": -19,
      "y": 0,
      "z": -4,
      "name": "Rock_Chalk_Brick"
    },
    {
      "x": -19,
      "y": 1,
      "z": -4,
      "name": "Rock_Marble_Brick_Half",
      "rotation": 7
    },
    {
      "x": -19,
      "y": 5,
      "z": -4,
      "name": "Rock_Marble_Brick_Half",
      "rotation": 4
    },
    {
      "x": -19,
      "y": 11,
      "z": -4,
      "name": "Rock_Marble_Brick_Half",
      "rotation": 4
    },
    {
      "x": -19,
      "y": 13,
      "z": -4,
      "name": "Rock_Marble_Brick_Half",
      "rotation": 7
    },
    {
      "x": -19,
      "y": 15,
      "z": -4,
      "name": "Rock_Marble_Brick_Wall",
      "rotation": 1
    },
    {
      "x": -19,
      "y": 16,
      "z": -4,
      "name": "Rock_Chalk_Brick_Roof",
      "rotation": 3
    },
    {
      "x": -19,
      "y": 17,
      "z": -4,
      "name": "Rock_Marble_Brick",
      "rotation": 3
    },
    {
      "x": -19,
      "y": 18,
      "z": -4,
      "name": "Rock_Marble_Brick_Decorative",
      "rotation": 33
    },
    {
      "x": -19,
      "y": 19,
      "z": -4,
      "name": "Rock_Marble_Brick",
      "rotation": 3
    },
    {
      "x": -19,
      "y": 20,
      "z": -4,
      "name": "Rock_Chalk_Brick_Roof_Shallow",
      "filler": 992
    },
    {
      "x": -19,
      "y": 0,
      "z": -3,
      "name": "Rock_Chalk_Brick"
    },
    {
      "x": -19,
      "y": 13,
      "z": -3,
      "name": "Rock_Marble_Brick_Half",
      "rotation": 7
    },
    {
      "x": -19,
      "y": 14,
      "z": -3,
      "name": "Furniture_Temple_Light_Ladder",
      "rotation": 3
    },
    {
      "x": -19,
      "y": 15,
      "z": -3,
      "name": "Rock_Marble_Brick_Wall",
      "rotation": 1
    },
    {
      "x": -19,
      "y": 16,
      "z": -3,
      "name": "Rock_Chalk_Brick_Roof",
      "rotation": 3
    },
    {
      "x": -19,
      "y": 17,
      "z": -3,
      "name": "Rock_Marble_Brick_Half",
      "rotation": 4
    },
    {
      "x": -19,
      "y": 19,
      "z": -3,
      "name": "Rock_Marble_Brick_Wall",
      "rotation": 2
    },
    {
      "x": -19,
      "y": 20,
      "z": -3,
      "name": "Rock_Chalk_Brick_Roof_Shallow"
    },
    {
      "x": -19,
      "y": 0,
      "z": -2,
      "name": "Rock_Chalk_Brick"
    },
    {
      "x": -19,
      "y": 13,
      "z": -2,
      "name": "Rock_Marble_Brick_Half",
      "rotation": 7
    },
    {
      "x": -19,
      "y": 15,
      "z": -2,
      "name": "Rock_Marble_Brick_Wall",
      "rotation": 1
    },
    {
      "x": -19,
      "y": 16,
      "z": -2,
      "name": "Rock_Chalk_Brick_Roof",
      "rotation": 3
    },
    {
      "x": -19,
      "y": 0,
      "z": -1,
      "name": "Rock_Chalk_Brick"
    },
    {
      "x": -19,
      "y": 13,
      "z": -1,
      "name": "Rock_Marble_Brick_Half",
      "rotation": 7
    },
    {
      "x": -19,
      "y": 14,
      "z": -1,
      "name": "Furniture_Temple_Light_Ladder",
      "rotation": 3
    },
    {
      "x": -19,
      "y": 15,
      "z": -1,
      "name": "Rock_Marble_Brick_Wall",
      "rotation": 1
    },
    {
      "x": -19,
      "y": 16,
      "z": -1,
      "name": "Rock_Chalk_Brick_Roof",
      "rotation": 3
    },
    {
      "x": -19,
      "y": 0,
      "z": 0,
      "name": "Rock_Chalk_Brick"
    },
    {
      "x": -19,
      "y": 1,
      "z": 0,
      "name": "Rock_Marble_Brick_Half",
      "rotation": 7
    },
    {
      "x": -19,
      "y": 13,
      "z": 0,
      "name": "Rock_Marble_Brick_Half",
      "rotation": 7
    },
    {
      "x": -19,
      "y": 15,
      "z": 0,
      "name": "Rock_Marble_Brick_Wall",
      "rotation": 1
    },
    {
      "x": -19,
      "y": 16,
      "z": 0,
      "name": "Rock_Chalk_Brick_Roof",
      "rotation": 3
    },
    {
      "x": -19,
      "y": 0,
      "z": 1,
      "name": "Rock_Chalk_Brick"
    },
    {
      "x": -19,
      "y": 13,
      "z": 1,
      "name": "Rock_Marble_Brick_Half",
      "rotation": 7
    },
    {
      "x": -19,
      "y": 14,
      "z": 1,
      "name": "Furniture_Temple_Light_Ladder",
      "rotation": 3
    },
    {
      "x": -19,
      "y": 15,
      "z": 1,
      "name": "Rock_Marble_Brick_Wall",
      "rotation": 1
    },
    {
      "x": -19,
      "y": 16,
      "z": 1,
      "name": "Rock_Chalk_Brick_Roof_Hollow",
      "rotation": 3
    },
    {
      "x": -19,
      "y": 0,
      "z": 2,
      "name": "Rock_Chalk_Brick"
    },
    {
      "x": -19,
      "y": 13,
      "z": 2,
      "name": "Rock_Marble_Brick_Half",
      "rotation": 7
    },
    {
      "x": -19,
      "y": 15,
      "z": 2,
      "name": "Rock_Marble_Brick_Wall",
      "rotation": 1
    },
    {
      "x": -19,
      "y": 16,
      "z": 2,
      "name": "Rock_Chalk_Brick_Roof",
      "rotation": 3
    },
    {
      "x": -19,
      "y": 0,
      "z": 3,
      "name": "Rock_Chalk_Brick"
    },
    {
      "x": -19,
      "y": 13,
      "z": 3,
      "name": "Rock_Marble_Brick_Half",
      "rotation": 7
    },
    {
      "x": -19,
      "y": 14,
      "z": 3,
      "name": "Furniture_Temple_Light_Ladder",
      "rotation": 3
    },
    {
      "x": -19,
      "y": 15,
      "z": 3,
      "name": "Rock_Marble_Brick_Wall",
      "rotation": 1
    },
    {
      "x": -19,
      "y": 16,
      "z": 3,
      "name": "Rock_Chalk_Brick_Roof",
      "rotation": 3
    },
    {
      "x": -19,
      "y": 0,
      "z": 4,
      "name": "Rock_Chalk_Brick"
    },
    {
      "x": -19,
      "y": 13,
      "z": 4,
      "name": "Rock_Marble_Brick_Half",
      "rotation": 7
    },
    {
      "x": -19,
      "y": 15,
      "z": 4,
      "name": "Rock_Marble_Brick_Wall",
      "rotation": 1
    },
    {
      "x": -19,
      "y": 16,
      "z": 4,
      "name": "Rock_Chalk_Brick_Roof",
      "rotation": 3
    },
    {
      "x": -19,
      "y": 0,
      "z": 5,
      "name": "Rock_Chalk_Brick"
    },
    {
      "x": -19,
      "y": 1,
      "z": 5,
      "name": "Rock_Marble_Brick_Half",
      "rotation": 7
    },
    {
      "x": -19,
      "y": 13,
      "z": 5,
      "name": "Rock_Marble_Brick_Half",
      "rotation": 7
    },
    {
      "x": -19,
      "y": 14,
      "z": 5,
      "name": "Furniture_Temple_Light_Ladder",
      "rotation": 3
    },
    {
      "x": -19,
      "y": 15,
      "z": 5,
      "name": "Rock_Marble_Brick_Wall",
      "rotation": 1
    },
    {
      "x": -19,
      "y": 16,
      "z": 5,
      "name": "Rock_Chalk_Brick_Roof",
      "rotation": 3
    },
    {
      "x": -19,
      "y": 0,
      "z": 6,
      "name": "Rock_Chalk_Brick"
    },
    {
      "x": -19,
      "y": 13,
      "z": 6,
      "name": "Rock_Marble_Brick_Half",
      "rotation": 7
    },
    {
      "x": -19,
      "y": 15,
      "z": 6,
      "name": "Rock_Marble_Brick_Wall",
      "rotation": 1
    },
    {
      "x": -19,
      "y": 16,
      "z": 6,
      "name": "Rock_Chalk_Brick_Roof",
      "rotation": 3
    },
    {
      "x": -19,
      "y": 0,
      "z": 7,
      "name": "Rock_Chalk_Brick"
    },
    {
      "x": -19,
      "y": 13,
      "z": 7,
      "name": "Rock_Marble_Brick_Half",
      "rotation": 7
    },
    {
      "x": -19,
      "y": 14,
      "z": 7,
      "name": "Furniture_Temple_Light_Ladder",
      "rotation": 3
    },
    {
      "x": -19,
      "y": 15,
      "z": 7,
      "name": "Rock_Marble_Brick_Wall",
      "rotation": 1
    },
    {
      "x": -19,
      "y": 16,
      "z": 7,
      "name": "Rock_Chalk_Brick_Roof",
      "rotation": 3
    },
    {
      "x": -19,
      "y": 0,
      "z": 8,
      "name": "Rock_Chalk_Brick"
    },
    {
      "x": -19,
      "y": 1,
      "z": 8,
      "name": "Rock_Marble_Brick_Stairs",
      "rotation": 19
    },
    {
      "x": -19,
      "y": 13,
      "z": 8,
      "name": "Rock_Marble_Brick_Half",
      "rotation": 7
    },
    {
      "x": -19,
      "y": 15,
      "z": 8,
      "name": "Rock_Marble_Brick_Wall",
      "rotation": 1
    },
    {
      "x": -19,
      "y": 16,
      "z": 8,
      "name": "Rock_Chalk_Brick_Roof",
      "rotation": 3
    },
    {
      "x": -19,
      "y": 0,
      "z": 9,
      "name": "Rock_Chalk_Brick"
    },
    {
      "x": -19,
      "y": 1,
      "z": 9,
      "name": "Rock_Marble_Brick_Smooth"
    },
    {
      "x": -19,
      "y": 2,
      "z": 9,
      "name": "Rock_Marble_Brick"
    },
    {
      "x": -19,
      "y": 3,
      "z": 9,
      "name": "Rock_Marble_Brick_Ornate"
    },
    {
      "x": -19,
      "y": 4,
      "z": 9,
      "name": "Rock_Marble_Brick_Half",
      "rotation": 7
    },
    {
      "x": -19,
      "y": 5,
      "z": 9,
      "name": "Rock_Marble_Brick_Half",
      "rotation": 7
    },
    {
      "x": -19,
      "y": 6,
      "z": 9,
      "name": "Rock_Marble_Brick_Smooth_Half",
      "rotation": 7
    },
    {
      "x": -19,
      "y": 7,
      "z": 9,
      "name": "Rock_Marble_Brick_Smooth_Half",
      "rotation": 7
    },
    {
      "x": -19,
      "y": 8,
      "z": 9,
      "name": "Rock_Marble_Brick_Smooth_Half",
      "rotation": 7
    },
    {
      "x": -19,
      "y": 9,
      "z": 9,
      "name": "Rock_Marble_Brick_Smooth_Half",
      "rotation": 7
    },
    {
      "x": -19,
      "y": 10,
      "z": 9,
      "name": "Rock_Marble_Brick_Smooth_Half",
      "rotation": 7
    },
    {
      "x": -19,
      "y": 11,
      "z": 9,
      "name": "Rock_Marble_Brick_Smooth_Half",
      "rotation": 7
    },
    {
      "x": -19,
      "y": 12,
      "z": 9,
      "name": "Rock_Marble_Brick_Smooth_Half",
      "rotation": 7
    },
    {
      "x": -19,
      "y": 13,
      "z": 9,
      "name": "Rock_Marble_Brick_Half",
      "rotation": 7
    },
    {
      "x": -19,
      "y": 14,
      "z": 9,
      "name": "Rock_Marble_Brick"
    },
    {
      "x": -19,
      "y": 15,
      "z": 9,
      "name": "Rock_Marble_Brick"
    },
    {
      "x": -19,
      "y": 16,
      "z": 9,
      "name": "Rock_Marble_Brick_Roof",
      "rotation": 3
    },
    {
      "x": -19,
      "y": 0,
      "z": 10,
      "name": "Rock_Chalk_Brick"
    },
    {
      "x": -19,
      "y": 1,
      "z": 10,
      "name": "Rock_Marble_Brick_Stairs",
      "rotation": 16
    },
    {
      "x": -19,
      "y": 15,
      "z": 10,
      "name": "Rock_Marble_Brick_Ornate"
    },
    {
      "x": -19,
      "y": 16,
      "z": 10,
      "name": "*Rock_Marble_Brick_Roof_State_Definitions_Corner_Left",
      "rotation": 3
    },
    {
      "x": -19,
      "y": 0,
      "z": 11,
      "name": "Rock_Chalk_Brick"
    },
    {
      "x": -19,
      "y": 0,
      "z": 12,
      "name": "Rock_Chalk_Brick"
    },
    {
      "x": -19,
      "y": 0,
      "z": 13,
      "name": "Rock_Chalk_Brick"
    },
    {
      "x": -19,
      "y": 0,
      "z": 14,
      "name": "Rock_Chalk_Brick"
    },
    {
      "x": -19,
      "y": 0,
      "z": 15,
      "name": "Rock_Chalk_Brick"
    },
    {
      "x": -19,
      "y": 0,
      "z": 16,
      "name": "Rock_Chalk_Brick"
    },
    {
      "x": -19,
      "y": 0,
      "z": 17,
      "name": "Rock_Chalk_Brick"
    },
    {
      "x": -19,
      "y": 0,
      "z": 18,
      "name": "Rock_Chalk_Brick"
    },
    {
      "x": -19,
      "y": 0,
      "z": 19,
      "name": "Rock_Chalk_Brick"
    },
    {
      "x": -19,
      "y": 0,
      "z": 20,
      "name": "Rock_Chalk_Brick"
    },
    {
      "x": -19,
      "y": 0,
      "z": 21,
      "name": "Rock_Chalk_Brick"
    },
    {
      "x": -19,
      "y": 0,
      "z": 22,
      "name": "Rock_Chalk_Brick"
    },
    {
      "x": -19,
      "y": 0,
      "z": 23,
      "name": "Rock_Chalk_Brick"
    },
    {
      "x": -19,
      "y": 0,
      "z": 24,
      "name": "Rock_Chalk_Brick"
    },
    {
      "x": -19,
      "y": 0,
      "z": 25,
      "name": "Rock_Chalk_Brick"
    },
    {
      "x": -19,
      "y": 0,
      "z": 26,
      "name": "Rock_Chalk_Brick"
    },
    {
      "x": -19,
      "y": 0,
      "z": 27,
      "name": "Rock_Chalk_Brick"
    },
    {
      "x": -19,
      "y": 0,
      "z": 28,
      "name": "Rock_Chalk_Brick"
    },
    {
      "x": -19,
      "y": 0,
      "z": 29,
      "name": "Rock_Chalk_Brick"
    },
    {
      "x": -18,
      "y": 0,
      "z": -27,
      "name": "Rock_Chalk_Brick"
    },
    {
      "x": -18,
      "y": 0,
      "z": -26,
      "name": "Rock_Chalk_Brick"
    },
    {
      "x": -18,
      "y": 0,
      "z": -25,
      "name": "Rock_Chalk_Brick"
    },
    {
      "x": -18,
      "y": 0,
      "z": -24,
      "name": "Rock_Chalk_Brick"
    },
    {
      "x": -18,
      "y": 0,
      "z": -23,
      "name": "Rock_Chalk_Brick"
    },
    {
      "x": -18,
      "y": 0,
      "z": -22,
      "name": "Rock_Chalk_Brick"
    },
    {
      "x": -18,
      "y": 0,
      "z": -21,
      "name": "Rock_Chalk_Brick"
    },
    {
      "x": -18,
      "y": 0,
      "z": -20,
      "name": "Rock_Chalk_Brick"
    },
    {
      "x": -18,
      "y": 0,
      "z": -19,
      "name": "Rock_Chalk_Brick"
    },
    {
      "x": -18,
      "y": 0,
      "z": -18,
      "name": "Rock_Chalk_Brick"
    },
    {
      "x": -18,
      "y": 0,
      "z": -17,
      "name": "Rock_Chalk_Brick"
    },
    {
      "x": -18,
      "y": 0,
      "z": -16,
