{
  "version": 8,
  "blockIdVersion": 11,
  "anchorX": 1,
  "anchorY": 14,
  "anchorZ": 1,
  "blocks": [
    {
      "x": -33,
      "y": 5,
      "z": -15,
      "name": "Rock_Marble"
    },
    {
      "x": -33,
      "y": 6,
      "z": -15,
      "name": "Soil_Dirt_White"
    },
    {
      "x": -33,
      "y": 7,
      "z": -15,
      "name": "Rock_Marble"
    },
    {
      "x": -33,
      "y": 8,
      "z": -15,
      "name": "Soil_Dirt_White"
    },
    {
      "x": -33,
      "y": 9,
      "z": -15,
      "name": "Soil_Grass_Full"
    },
    {
      "x": -33,
      "y": 4,
      "z": -14,
      "name": "Rock_Marble"
    },
    {
      "x": -33,
      "y": 5,
      "z": -14,
      "name": "Rock_Marble"
    },
    {
      "x": -33,
      "y": 6,
      "z": -14,
      "name": "Rock_Marble"
    },
    {
      "x": -33,
      "y": 7,
      "z": -14,
      "name": "Rock_Marble"
    },
    {
      "x": -33,
      "y": 8,
      "z": -14,
      "name": "Soil_Dirt_White"
    },
    {
      "x": -33,
      "y": 9,
      "z": -14,
      "name": "Soil_Grass_Full"
    },
    {
      "x": -33,
      "y": 4,
      "z": -13,
      "name": "Rock_Marble"
    },
    {
      "x": -33,
      "y": 5,
      "z": -13,
      "name": "Rock_Marble"
    },
    {
      "x": -33,
      "y": 6,
      "z": -13,
      "name": "Soil_Dirt_White"
    },
    {
      "x": -33,
      "y": 7,
      "z": -13,
      "name": "Rock_Marble"
    },
    {
      "x": -33,
      "y": 8,
      "z": -13,
      "name": "Soil_Dirt_White"
    },
    {
      "x": -33,
      "y": 9,
      "z": -13,
      "name": "Soil_Grass_Full"
    },
    {
      "x": -33,
      "y": 4,
      "z": -12,
      "name": "Rock_Marble"
    },
    {
      "x": -33,
      "y": 5,
      "z": -12,
      "name": "Rock_Marble"
    },
    {
      "x": -33,
      "y": 6,
      "z": -12,
      "name": "Soil_Dirt_White"
    },
    {
      "x": -33,
      "y": 7,
      "z": -12,
      "name": "Rock_Marble"
    },
    {
      "x": -33,
      "y": 8,
      "z": -12,
      "name": "Soil_Dirt_White"
    },
    {
      "x": -33,
      "y": 9,
      "z": -12,
      "name": "Soil_Grass_Full"
    },
    {
      "x": -33,
      "y": 5,
      "z": -11,
      "name": "Rock_Marble"
    },
    {
      "x": -33,
      "y": 6,
      "z": -11,
      "name": "Soil_Dirt_White"
    },
    {
      "x": -33,
      "y": 7,
      "z": -11,
      "name": "Rock_Marble"
    },
    {
      "x": -33,
      "y": 8,
      "z": -11,
      "name": "Soil_Dirt_White"
    },
    {
      "x": -33,
      "y": 5,
      "z": -10,
      "name": "Rock_Marble"
    },
    {
      "x": -33,
      "y": 6,
      "z": -10,
      "name": "Soil_Dirt_White"
    },
    {
      "x": -33,
      "y": 7,
      "z": -10,
      "name": "Soil_Dirt_White"
    },
    {
      "x": -33,
      "y": 8,
      "z": -10,
      "name": "Soil_Grass_Full"
    },
    {
      "x": -33,
      "y": 5,
      "z": -9,
      "name": "Rock_Marble"
    },
    {
      "x": -33,
      "y": 6,
      "z": -9,
      "name": "Soil_Dirt_White"
    },
    {
      "x": -33,
      "y": 7,
      "z": -9,
      "name": "Soil_Dirt_White"
    },
    {
      "x": -33,
      "y": 5,
      "z": -8,
      "name": "Soil_Dirt_White"
    },
    {
      "x": -33,
      "y": 6,
      "z": -8,
      "name": "Soil_Dirt_White"
    },
    {
      "x": -33,
      "y": 7,
      "z": -8,
      "name": "Soil_Dirt_White"
    },
    {
      "x": -33,
      "y": 5,
      "z": -7,
      "name": "Soil_Dirt_White"
    },
    {
      "x": -33,
      "y": 6,
      "z": -7,
      "name": "Soil_Dirt_White"
    },
    {
      "x": -33,
      "y": 7,
      "z": -7,
      "name": "Soil_Grass_White"
    },
    {
      "x": -33,
      "y": 6,
      "z": -6,
      "name": "Soil_Dirt_White"
    },
    {
      "x": -33,
      "y": 7,
      "z": -6,
      "name": "Soil_Grass_White"
    },
    {
      "x": -32,
      "y": 5,
      "z": -20,
      "name": "Rock_Marble"
    },
    {
      "x": -32,
      "y": 4,
      "z": -19,
      "name": "Rock_Marble"
    },
    {
      "x": -32,
      "y": 5,
      "z": -19,
      "name": "Rock_Marble"
    },
    {
      "x": -32,
      "y": 6,
      "z": -19,
      "name": "Soil_Dirt_White"
    },
    {
      "x": -32,
      "y": 7,
      "z": -19,
      "name": "Soil_Dirt_White"
    },
    {
      "x": -32,
      "y": 8,
      "z": -19,
      "name": "Soil_Grass_Full"
    },
    {
      "x": -32,
      "y": 3,
      "z": -18,
      "name": "Rock_Marble"
    },
    {
      "x": -32,
      "y": 4,
      "z": -18,
      "name": "Rock_Marble"
    },
    {
      "x": -32,
      "y": 5,
      "z": -18,
      "name": "Rock_Marble"
    },
    {
      "x": -32,
      "y": 6,
      "z": -18,
      "name": "Soil_Dirt_White"
    },
    {
      "x": -32,
      "y": 7,
      "z": -18,
      "name": "Rock_Marble"
    },
    {
      "x": -32,
      "y": 8,
      "z": -18,
      "name": "Soil_Dirt_White"
    },
    {
      "x": -32,
      "y": 9,
      "z": -18,
      "name": "Soil_Grass_Full"
    },
    {
      "x": -32,
      "y": 2,
      "z": -17,
      "name": "Rock_Marble"
    },
    {
      "x": -32,
      "y": 3,
      "z": -17,
      "name": "Rock_Marble"
    },
    {
      "x": -32,
      "y": 4,
      "z": -17,
      "name": "Rock_Marble"
    },
    {
      "x": -32,
      "y": 5,
      "z": -17,
      "name": "Rock_Marble"
    },
    {
      "x": -32,
      "y": 6,
      "z": -17,
      "name": "Soil_Dirt_White"
    },
    {
      "x": -32,
      "y": 7,
      "z": -17,
      "name": "Rock_Marble"
    },
    {
      "x": -32,
      "y": 8,
      "z": -17,
      "name": "Soil_Dirt_White"
    },
    {
      "x": -32,
      "y": 9,
      "z": -17,
      "name": "Soil_Grass_Full"
    },
    {
      "x": -32,
      "y": 0,
      "z": -16,
      "name": "Soil_Grass"
    },
    {
      "x": -32,
      "y": 2,
      "z": -16,
      "name": "Rock_Marble"
    },
    {
      "x": -32,
      "y": 3,
      "z": -16,
      "name": "Rock_Marble"
    },
    {
      "x": -32,
      "y": 4,
      "z": -16,
      "name": "Rock_Marble"
    },
    {
      "x": -32,
      "y": 5,
      "z": -16,
      "name": "Rock_Marble"
    },
    {
      "x": -32,
      "y": 6,
      "z": -16,
      "name": "Soil_Dirt_White"
    },
    {
      "x": -32,
      "y": 7,
      "z": -16,
      "name": "Rock_Marble"
    },
    {
      "x": -32,
      "y": 8,
      "z": -16,
      "name": "Soil_Dirt_White"
    },
    {
      "x": -32,
      "y": 9,
      "z": -16,
      "name": "Soil_Grass_Full"
    },
    {
      "x": -32,
      "y": 0,
      "z": -15,
      "name": "Rock_Marble"
    },
    {
      "x": -32,
      "y": 1,
      "z": -15,
      "name": "Rock_Marble"
    },
    {
      "x": -32,
      "y": 2,
      "z": -15,
      "name": "Rock_Marble"
    },
    {
      "x": -32,
      "y": 3,
      "z": -15,
      "name": "Rock_Marble"
    },
    {
      "x": -32,
      "y": 4,
      "z": -15,
      "name": "Rock_Marble"
    },
    {
      "x": -32,
      "y": 5,
      "z": -15,
      "name": "Rock_Marble"
    },
    {
      "x": -32,
      "y": 6,
      "z": -15,
      "name": "Soil_Dirt_White"
    },
    {
      "x": -32,
      "y": 7,
      "z": -15,
      "name": "Rock_Marble"
    },
    {
      "x": -32,
      "y": 8,
      "z": -15,
      "name": "Soil_Dirt_White"
    },
    {
      "x": -32,
      "y": 9,
      "z": -15,
      "name": "Soil_Grass_Full"
    },
    {
      "x": -32,
      "y": 0,
      "z": -14,
      "name": "Rock_Marble"
    },
    {
      "x": -32,
      "y": 1,
      "z": -14,
      "name": "Rock_Marble"
    },
    {
      "x": -32,
      "y": 2,
      "z": -14,
      "name": "Rock_Marble"
    },
    {
      "x": -32,
      "y": 3,
      "z": -14,
      "name": "Rock_Marble"
    },
    {
      "x": -32,
      "y": 4,
      "z": -14,
      "name": "Rock_Marble"
    },
    {
      "x": -32,
      "y": 5,
      "z": -14,
      "name": "Rock_Marble"
    },
    {
      "x": -32,
      "y": 6,
      "z": -14,
      "name": "Rock_Marble"
    },
    {
      "x": -32,
      "y": 7,
      "z": -14,
      "name": "Rock_Marble"
    },
    {
      "x": -32,
      "y": 8,
      "z": -14,
      "name": "Soil_Dirt_White"
    },
    {
      "x": -32,
      "y": 9,
      "z": -14,
      "name": "Soil_Grass_Full"
    },
    {
      "x": -32,
      "y": 0,
      "z": -13,
      "name": "Rock_Marble"
    },
    {
      "x": -32,
      "y": 1,
      "z": -13,
      "name": "Rock_Marble"
    },
    {
      "x": -32,
      "y": 2,
      "z": -13,
      "name": "Rock_Marble"
    },
    {
      "x": -32,
      "y": 3,
      "z": -13,
      "name": "Rock_Marble"
    },
    {
      "x": -32,
      "y": 4,
      "z": -13,
      "name": "Rock_Marble"
    },
    {
      "x": -32,
      "y": 5,
      "z": -13,
      "name": "Rock_Marble"
    },
    {
      "x": -32,
      "y": 6,
      "z": -13,
      "name": "Soil_Dirt_White"
    },
    {
      "x": -32,
      "y": 7,
      "z": -13,
      "name": "Soil_Dirt_White"
    },
    {
      "x": -32,
      "y": 8,
      "z": -13,
      "name": "Rock_Marble"
    },
    {
      "x": -32,
      "y": 9,
      "z": -13,
      "name": "Soil_Dirt_White"
    },
    {
      "x": -32,
      "y": 10,
      "z": -13,
      "name": "Soil_Grass_Full"
    },
    {
      "x": -32,
      "y": 0,
      "z": -12,
      "name": "Soil_Grass"
    },
    {
      "x": -32,
      "y": 1,
      "z": -12,
      "name": "Rock_Marble"
    },
    {
      "x": -32,
      "y": 2,
      "z": -12,
      "name": "Rock_Marble"
    },
    {
      "x": -32,
      "y": 3,
      "z": -12,
      "name": "Rock_Marble"
    },
    {
      "x": -32,
      "y": 4,
      "z": -12,
      "name": "Rock_Marble"
    },
    {
      "x": -32,
      "y": 5,
      "z": -12,
      "name": "Rock_Marble"
    },
    {
      "x": -32,
      "y": 6,
      "z": -12,
      "name": "Soil_Dirt_White"
    },
    {
      "x": -32,
      "y": 7,
      "z": -12,
      "name": "Soil_Dirt_White"
    },
    {
      "x": -32,
      "y": 8,
      "z": -12,
      "name": "Rock_Marble"
    },
    {
      "x": -32,
      "y": 9,
      "z": -12,
      "name": "Soil_Dirt_White"
    },
    {
      "x": -32,
      "y": 10,
      "z": -12,
      "name": "Soil_Grass_Full"
    },
    {
      "x": -32,
      "y": 0,
      "z": -11,
      "name": "Soil_Grass"
    },
    {
      "x": -32,
      "y": 1,
      "z": -11,
      "name": "Rock_Marble"
    },
    {
      "x": -32,
      "y": 2,
      "z": -11,
      "name": "Rock_Marble"
    },
    {
      "x": -32,
      "y": 3,
      "z": -11,
      "name": "Rock_Marble"
    },
    {
      "x": -32,
      "y": 4,
      "z": -11,
      "name": "Rock_Marble"
    },
    {
      "x": -32,
      "y": 5,
      "z": -11,
      "name": "Rock_Marble"
    },
    {
      "x": -32,
      "y": 6,
      "z": -11,
      "name": "Soil_Dirt_White"
    },
    {
      "x": -32,
      "y": 7,
      "z": -11,
      "name": "Rock_Marble"
    },
    {
      "x": -32,
      "y": 8,
      "z": -11,
      "name": "Soil_Dirt_White"
    },
    {
      "x": -32,
      "y": 9,
      "z": -11,
      "name": "Soil_Grass_Full"
    },
    {
      "x": -32,
      "y": 0,
      "z": -10,
      "name": "Soil_Grass"
    },
    {
      "x": -32,
      "y": 1,
      "z": -10,
      "name": "Rock_Marble"
    },
    {
      "x": -32,
      "y": 2,
      "z": -10,
      "name": "Rock_Marble"
    },
    {
      "x": -32,
      "y": 3,
      "z": -10,
      "name": "Rock_Marble"
    },
    {
      "x": -32,
      "y": 4,
      "z": -10,
      "name": "Rock_Marble"
    },
    {
      "x": -32,
      "y": 5,
      "z": -10,
      "name": "Rock_Marble"
    },
    {
      "x": -32,
      "y": 6,
      "z": -10,
      "name": "Soil_Dirt_White"
    },
    {
      "x": -32,
      "y": 7,
      "z": -10,
      "name": "Soil_Dirt_White"
    },
    {
      "x": -32,
      "y": 8,
      "z": -10,
      "name": "Soil_Dirt_White"
    },
    {
      "x": -32,
      "y": 9,
      "z": -10,
      "name": "Soil_Grass_Full"
    },
    {
      "x": -32,
      "y": 2,
      "z": -9,
      "name": "Rock_Marble"
    },
    {
      "x": -32,
      "y": 3,
      "z": -9,
      "name": "Rock_Marble"
    },
    {
      "x": -32,
      "y": 4,
      "z": -9,
      "name": "Rock_Marble"
    },
    {
      "x": -32,
      "y": 5,
      "z": -9,
      "name": "Rock_Marble"
    },
    {
      "x": -32,
      "y": 6,
      "z": -9,
      "name": "Soil_Dirt_White"
    },
    {
      "x": -32,
      "y": 7,
      "z": -9,
      "name": "Soil_Dirt_White"
    },
    {
      "x": -32,
      "y": 8,
      "z": -9,
      "name": "Soil_Dirt_White"
    },
    {
      "x": -32,
      "y": 9,
      "z": -9,
      "name": "Soil_Grass_Full"
    },
    {
      "x": -32,
      "y": 2,
      "z": -8,
      "name": "Rock_Marble"
    },
    {
      "x": -32,
      "y": 3,
      "z": -8,
      "name": "Rock_Marble"
    },
    {
      "x": -32,
      "y": 4,
      "z": -8,
      "name": "Rock_Marble"
    },
    {
      "x": -32,
      "y": 5,
      "z": -8,
      "name": "Soil_Dirt_White"
    },
    {
      "x": -32,
      "y": 6,
      "z": -8,
      "name": "Soil_Dirt_White"
    },
    {
      "x": -32,
      "y": 7,
      "z": -8,
      "name": "Soil_Dirt_White"
    },
    {
      "x": -32,
      "y": 8,
      "z": -8,
      "name": "Soil_Grass_White"
    },
    {
      "x": -32,
      "y": 2,
      "z": -7,
      "name": "Rock_Marble"
    },
    {
      "x": -32,
      "y": 3,
      "z": -7,
      "name": "Rock_Marble"
    },
    {
      "x": -32,
      "y": 4,
      "z": -7,
      "name": "Rock_Marble"
    },
    {
      "x": -32,
      "y": 5,
      "z": -7,
      "name": "Soil_Dirt_White"
    },
    {
      "x": -32,
      "y": 6,
      "z": -7,
      "name": "Soil_Dirt_White"
    },
    {
      "x": -32,
      "y": 7,
      "z": -7,
      "name": "Soil_Dirt_White"
    },
    {
      "x": -32,
      "y": 8,
      "z": -7,
      "name": "Soil_Grass_White"
    },
    {
      "x": -32,
      "y": 2,
      "z": -6,
      "name": "Rock_Marble"
    },
    {
      "x": -32,
      "y": 3,
      "z": -6,
      "name": "Rock_Marble"
    },
    {
      "x": -32,
      "y": 4,
      "z": -6,
      "name": "Rock_Marble"
    },
    {
      "x": -32,
      "y": 5,
      "z": -6,
      "name": "Soil_Dirt_White"
    },
    {
      "x": -32,
      "y": 6,
      "z": -6,
      "name": "Soil_Dirt_White"
    },
    {
      "x": -32,
      "y": 7,
      "z": -6,
      "name": "Soil_Dirt_White"
    },
    {
      "x": -32,
      "y": 8,
      "z": -6,
      "name": "Soil_Grass_White"
    },
    {
      "x": -32,
      "y": 1,
      "z": -5,
      "name": "Rock_Marble"
    },
    {
      "x": -32,
      "y": 2,
      "z": -5,
      "name": "Rock_Marble"
    },
    {
      "x": -32,
      "y": 3,
      "z": -5,
      "name": "Rock_Marble"
    },
    {
      "x": -32,
      "y": 4,
      "z": -5,
      "name": "Rock_Marble"
    },
    {
      "x": -32,
      "y": 5,
      "z": -5,
      "name": "Soil_Dirt_White"
    },
    {
      "x": -32,
      "y": 6,
      "z": -5,
      "name": "Soil_Dirt_White"
    },
    {
      "x": -32,
      "y": 7,
      "z": -5,
      "name": "Soil_Dirt_White"
    },
    {
      "x": -32,
      "y": 8,
      "z": -5,
      "name": "Soil_Grass_White"
    },
    {
      "x": -32,
      "y": 4,
      "z": -4,
      "name": "Rock_Marble"
    },
    {
      "x": -32,
      "y": 5,
      "z": -4,
      "name": "Rock_Marble"
    },
    {
      "x": -32,
      "y": 6,
      "z": -4,
      "name": "Soil_Dirt_White"
    },
    {
      "x": -32,
      "y": 7,
      "z": -4,
      "name": "Soil_Dirt_White"
    },
    {
      "x": -32,
      "y": 8,
      "z": -4,
      "name": "Soil_Grass_White"
    },
    {
      "x": -32,
      "y": 5,
      "z": -3,
      "name": "Rock_Marble"
    },
    {
      "x": -32,
      "y": 6,
      "z": -3,
      "name": "Soil_Dirt_White"
    },
    {
      "x": -32,
      "y": 7,
      "z": -3,
      "name": "Soil_Grass_White"
    },
    {
      "x": -32,
      "y": 6,
      "z": -2,
      "name": "Soil_Dirt_White"
    },
    {
      "x": -32,
      "y": 0,
      "z": -1,
      "name": "Soil_Grass"
    },
    {
      "x": -32,
      "y": 4,
      "z": -1,
      "name": "Rock_Marble"
    },
    {
      "x": -32,
      "y": 5,
      "z": -1,
      "name": "Rock_Marble"
    },
    {
      "x": -32,
      "y": 0,
      "z": 0,
      "name": "Soil_Grass"
    },
    {
      "x": -32,
      "y": 3,
      "z": 0,
      "name": "Rock_Marble"
    },
    {
      "x": -32,
      "y": 4,
      "z": 0,
      "name": "Rock_Marble"
    },
    {
      "x": -32,
      "y": 5,
      "z": 0,
      "name": "Rock_Marble"
    },
    {
      "x": -32,
      "y": 6,
      "z": 0,
      "name": "Rock_Marble"
    },
    {
      "x": -32,
      "y": 0,
      "z": 1,
      "name": "Rock_Marble"
    },
    {
      "x": -32,
      "y": 1,
      "z": 1,
      "name": "Rock_Marble"
    },
    {
      "x": -32,
      "y": 3,
      "z": 1,
      "name": "Rock_Marble"
    },
    {
      "x": -32,
      "y": 4,
      "z": 1,
      "name": "Rock_Marble"
    },
    {
      "x": -32,
      "y": 5,
      "z": 1,
      "name": "Rock_Marble"
    },
    {
      "x": -32,
      "y": 0,
      "z": 2,
      "name": "Soil_Grass"
    },
    {
      "x": -32,
      "y": 1,
      "z": 2,
      "name": "Rock_Marble"
    },
    {
      "x": -32,
      "y": 0,
      "z": 3,
      "name": "Soil_Grass"
    },
    {
      "x": -32,
      "y": 0,
      "z": 4,
      "name": "Soil_Grass"
    },
    {
      "x": -31,
      "y": 3,
      "z": -22,
      "name": "Rock_Marble"
    },
    {
      "x": -31,
      "y": 4,
      "z": -22,
      "name": "Rock_Marble"
    },
    {
      "x": -31,
      "y": 5,
      "z": -22,
      "name": "Rock_Marble"
    },
    {
      "x": -31,
      "y": 2,
      "z": -21,
      "name": "Rock_Marble"
    },
    {
      "x": -31,
      "y": 3,
      "z": -21,
      "name": "Rock_Marble"
    },
    {
      "x": -31,
      "y": 4,
      "z": -21,
      "name": "Rock_Marble"
    },
    {
      "x": -31,
      "y": 5,
      "z": -21,
      "name": "Rock_Marble"
    },
    {
      "x": -31,
      "y": 6,
      "z": -21,
      "name": "Soil_Dirt_White"
    },
    {
      "x": -31,
      "y": 7,
      "z": -21,
      "name": "Soil_Grass_White"
    },
    {
      "x": -31,
      "y": 1,
      "z": -20,
      "name": "Rock_Marble"
    },
    {
      "x": -31,
      "y": 2,
      "z": -20,
      "name": "Rock_Marble"
    },
    {
      "x": -31,
      "y": 3,
      "z": -20,
      "name": "Rock_Marble"
    },
    {
      "x": -31,
      "y": 4,
      "z": -20,
      "name": "Rock_Marble"
    },
    {
      "x": -31,
      "y": 5,
      "z": -20,
      "name": "Rock_Marble"
    },
    {
      "x": -31,
      "y": 6,
      "z": -20,
      "name": "Soil_Dirt_White"
    },
    {
      "x": -31,
      "y": 7,
      "z": -20,
      "name": "Soil_Dirt_White"
    },
    {
      "x": -31,
      "y": 8,
      "z": -20,
      "name": "Soil_Grass_Full"
    },
    {
      "x": -31,
      "y": 0,
      "z": -19,
      "name": "Rock_Marble"
    },
    {
      "x": -31,
      "y": 1,
      "z": -19,
      "name": "Rock_Marble"
    },
    {
      "x": -31,
      "y": 2,
      "z": -19,
      "name": "Rock_Marble"
    },
    {
      "x": -31,
      "y": 3,
      "z": -19,
      "name": "Rock_Marble"
    },
    {
      "x": -31,
      "y": 4,
      "z": -19,
      "name": "Rock_Marble"
    },
    {
      "x": -31,
      "y": 5,
      "z": -19,
      "name": "Rock_Marble"
    },
    {
      "x": -31,
      "y": 6,
      "z": -19,
      "name": "Soil_Dirt_White"
    },
    {
      "x": -31,
      "y": 7,
      "z": -19,
      "name": "Rock_Marble"
    },
    {
      "x": -31,
      "y": 8,
      "z": -19,
      "name": "Soil_Dirt_White"
    },
    {
      "x": -31,
      "y": 9,
      "z": -19,
      "name": "Soil_Grass_Full"
    },
    {
      "x": -31,
      "y": 1,
      "z": -18,
      "name": "Rock_Marble"
    },
    {
      "x": -31,
      "y": 2,
      "z": -18,
      "name": "Rock_Marble"
    },
    {
      "x": -31,
      "y": 3,
      "z": -18,
      "name": "Rock_Marble"
    },
    {
      "x": -31,
      "y": 4,
      "z": -18,
      "name": "Rock_Marble"
    },
    {
      "x": -31,
      "y": 5,
      "z": -18,
      "name": "Rock_Marble"
    },
    {
      "x": -31,
      "y": 6,
      "z": -18,
      "name": "Soil_Dirt_White"
    },
    {
      "x": -31,
      "y": 7,
      "z": -18,
      "name": "Soil_Dirt_White"
    },
    {
      "x": -31,
      "y": 8,
      "z": -18,
      "name": "Rock_Marble"
    },
    {
      "x": -31,
      "y": 9,
      "z": -18,
      "name": "Soil_Dirt_White"
    },
    {
      "x": -31,
      "y": 10,
      "z": -18,
      "name": "Soil_Grass_Full"
    },
    {
      "x": -31,
      "y": 1,
      "z": -17,
      "name": "Rock_Marble"
    },
    {
      "x": -31,
      "y": 2,
      "z": -17,
      "name": "Rock_Marble"
    },
    {
      "x": -31,
      "y": 3,
      "z": -17,
      "name": "Rock_Marble"
    },
    {
      "x": -31,
      "y": 4,
      "z": -17,
      "name": "Rock_Marble"
    },
    {
      "x": -31,
      "y": 5,
      "z": -17,
      "name": "Rock_Marble"
    },
    {
      "x": -31,
      "y": 6,
      "z": -17,
      "name": "Soil_Dirt_White"
    },
    {
      "x": -31,
      "y": 7,
      "z": -17,
      "name": "Soil_Dirt_White"
    },
    {
      "x": -31,
      "y": 8,
      "z": -17,
      "name": "Rock_Marble"
    },
    {
      "x": -31,
      "y": 9,
      "z": -17,
      "name": "Soil_Dirt_White"
    },
    {
      "x": -31,
      "y": 10,
      "z": -17,
      "name": "Soil_Grass_Full"
    },
    {
      "x": -31,
      "y": 0,
      "z": -16,
      "name": "Rock_Marble"
    },
    {
      "x": -31,
      "y": 1,
      "z": -16,
      "name": "Rock_Marble"
    },
    {
      "x": -31,
      "y": 2,
      "z": -16,
      "name": "Rock_Marble"
    },
    {
      "x": -31,
      "y": 3,
      "z": -16,
      "name": "Rock_Marble"
    },
    {
      "x": -31,
      "y": 4,
      "z": -16,
      "name": "Rock_Marble"
    },
    {
      "x": -31,
      "y": 5,
      "z": -16,
      "name": "Rock_Marble"
    },
    {
      "x": -31,
      "y": 6,
      "z": -16,
      "name": "Soil_Dirt_White"
    },
    {
      "x": -31,
      "y": 7,
      "z": -16,
      "name": "Soil_Dirt_White"
    },
    {
      "x": -31,
      "y": 8,
      "z": -16,
      "name": "Rock_Marble"
    },
    {
      "x": -31,
      "y": 9,
      "z": -16,
      "name": "Soil_Dirt_White"
    },
    {
      "x": -31,
      "y": 10,
      "z": -16,
      "name": "Soil_Grass_Full"
    },
    {
      "x": -31,
      "y": 0,
      "z": -15,
      "name": "Rock_Marble"
    },
    {
      "x": -31,
      "y": 1,
      "z": -15,
      "name": "Rock_Marble"
    },
    {
      "x": -31,
      "y": 2,
      "z": -15,
      "name": "Rock_Marble"
    },
    {
      "x": -31,
      "y": 3,
      "z": -15,
      "name": "Rock_Marble"
    },
    {
      "x": -31,
      "y": 4,
      "z": -15,
      "name": "Rock_Marble"
    },
    {
      "x": -31,
      "y": 5,
      "z": -15,
      "name": "Rock_Marble"
    },
    {
      "x": -31,
      "y": 6,
      "z": -15,
      "name": "Soil_Dirt_White"
    },
    {
      "x": -31,
      "y": 7,
      "z": -15,
      "name": "Soil_Dirt_White"
    },
    {
      "x": -31,
      "y": 8,
      "z": -15,
      "name": "Rock_Marble"
    },
    {
      "x": -31,
      "y": 9,
      "z": -15,
      "name": "Soil_Dirt_White"
    },
    {
      "x": -31,
      "y": 10,
      "z": -15,
      "name": "Soil_Grass_Full"
    },
    {
      "x": -31,
      "y": 0,
      "z": -14,
      "name": "Rock_Marble"
    },
    {
      "x": -31,
      "y": 1,
      "z": -14,
      "name": "Rock_Marble"
    },
    {
      "x": -31,
      "y": 2,
      "z": -14,
      "name": "Rock_Marble"
    },
    {
      "x": -31,
      "y": 3,
      "z": -14,
      "name": "Rock_Marble"
    },
    {
      "x": -31,
      "y": 4,
      "z": -14,
      "name": "Rock_Marble"
    },
    {
      "x": -31,
      "y": 5,
      "z": -14,
      "name": "Rock_Marble"
    },
    {
      "x": -31,
      "y": 6,
      "z": -14,
      "name": "Rock_Marble"
    },
    {
      "x": -31,
      "y": 7,
      "z": -14,
      "name": "Soil_Dirt_White"
    },
    {
      "x": -31,
      "y": 8,
      "z": -14,
      "name": "Rock_Marble"
    },
    {
      "x": -31,
      "y": 9,
      "z": -14,
      "name": "Soil_Dirt_White"
    },
    {
      "x": -31,
      "y": 10,
      "z": -14,
      "name": "Soil_Grass_Full"
    },
    {
      "x": -31,
      "y": 0,
      "z": -13,
      "name": "Rock_Marble"
    },
    {
      "x": -31,
      "y": 1,
      "z": -13,
      "name": "Rock_Marble"
    },
    {
      "x": -31,
      "y": 2,
      "z": -13,
      "name": "Rock_Marble"
    },
    {
      "x": -31,
      "y": 3,
      "z": -13,
      "name": "Rock_Marble"
    },
    {
      "x": -31,
      "y": 4,
      "z": -13,
      "name": "Rock_Marble"
    },
    {
      "x": -31,
      "y": 5,
      "z": -13,
      "name": "Rock_Marble"
    },
    {
      "x": -31,
      "y": 6,
      "z": -13,
      "name": "Soil_Dirt_White"
    },
    {
      "x": -31,
      "y": 7,
      "z": -13,
      "name": "Soil_Dirt_White"
    },
    {
      "x": -31,
      "y": 8,
      "z": -13,
      "name": "Rock_Marble"
    },
    {
      "x": -31,
      "y": 9,
      "z": -13,
      "name": "Soil_Dirt_White"
    },
    {
      "x": -31,
      "y": 10,
      "z": -13,
      "name": "Soil_Grass_Full"
    },
    {
      "x": -31,
      "y": 0,
      "z": -12,
      "name": "Rock_Marble"
    },
    {
      "x": -31,
      "y": 1,
      "z": -12,
      "name": "Rock_Marble"
    },
    {
      "x": -31,
      "y": 2,
      "z": -12,
      "name": "Rock_Marble"
    },
    {
      "x": -31,
      "y": 3,
      "z": -12,
      "name": "Rock_Marble"
    },
    {
      "x": -31,
      "y": 4,
      "z": -12,
      "name": "Rock_Marble"
    },
    {
      "x": -31,
      "y": 5,
      "z": -12,
      "name": "Rock_Marble"
    },
    {
      "x": -31,
      "y": 6,
      "z": -12,
      "name": "Soil_Dirt_White"
    },
    {
      "x": -31,
      "y": 7,
      "z": -12,
      "name": "Soil_Dirt_White"
    },
    {
      "x": -31,
      "y": 8,
      "z": -12,
      "name": "Rock_Marble"
    },
    {
      "x": -31,
      "y": 9,
      "z": -12,
      "name": "Soil_Dirt_White"
    },
    {
      "x": -31,
      "y": 10,
      "z": -12,
      "name": "Soil_Grass_Full"
    },
    {
      "x": -31,
      "y": 0,
      "z": -11,
      "name": "Rock_Marble"
    },
    {
      "x": -31,
      "y": 1,
      "z": -11,
      "name": "Rock_Marble"
    },
    {
      "x": -31,
      "y": 2,
      "z": -11,
      "name": "Rock_Marble"
    },
    {
      "x": -31,
      "y": 3,
      "z": -11,
      "name": "Rock_Marble"
    },
    {
      "x": -31,
      "y": 4,
      "z": -11,
      "name": "Rock_Marble"
    },
    {
      "x": -31,
      "y": 5,
      "z": -11,
      "name": "Rock_Marble"
    },
    {
      "x": -31,
      "y": 6,
      "z": -11,
      "name": "Soil_Dirt_White"
    },
    {
      "x": -31,
      "y": 7,
      "z": -11,
      "name": "Soil_Dirt_White"
    },
    {
      "x": -31,
      "y": 8,
      "z": -11,
      "name": "Rock_Marble"
    },
    {
      "x": -31,
      "y": 9,
      "z": -11,
      "name": "Soil_Dirt_White"
    },
    {
      "x": -31,
      "y": 10,
      "z": -11,
      "name": "Soil_Grass_Full"
    },
    {
      "x": -31,
      "y": 0,
      "z": -10,
      "name": "Rock_Marble"
    },
    {
      "x": -31,
      "y": 1,
      "z": -10,
      "name": "Rock_Marble"
    },
    {
      "x": -31,
      "y": 2,
      "z": -10,
      "name": "Rock_Marble"
    },
    {
      "x": -31,
      "y": 3,
      "z": -10,
      "name": "Rock_Marble"
    },
    {
      "x": -31,
      "y": 4,
      "z": -10,
      "name": "Rock_Marble"
    },
    {
      "x": -31,
      "y": 5,
      "z": -10,
      "name": "Rock_Marble"
    },
    {
      "x": -31,
      "y": 6,
      "z": -10,
      "name": "Soil_Dirt_White"
    },
    {
      "x": -31,
      "y": 7,
      "z": -10,
      "name": "Soil_Dirt_White"
    },
    {
      "x": -31,
      "y": 8,
      "z": -10,
      "name": "Rock_Marble"
    },
    {
      "x": -31,
      "y": 9,
      "z": -10,
      "name": "Soil_Dirt_White"
    },
    {
      "x": -31,
      "y": 10,
      "z": -10,
      "name": "Soil_Grass_Full"
    },
    {
      "x": -31,
      "y": 1,
      "z": -9,
      "name": "Rock_Marble"
    },
    {
      "x": -31,
      "y": 2,
      "z": -9,
      "name": "Rock_Marble"
    },
    {
      "x": -31,
      "y": 3,
      "z": -9,
      "name": "Rock_Marble"
    },
    {
      "x": -31,
      "y": 4,
      "z": -9,
      "name": "Rock_Marble"
    },
    {
      "x": -31,
      "y": 5,
      "z": -9,
      "name": "Rock_Marble"
    },
    {
      "x": -31,
      "y": 6,
      "z": -9,
      "name": "Soil_Dirt_White"
    },
    {
      "x": -31,
      "y": 7,
      "z": -9,
      "name": "Soil_Dirt_White"
    },
    {
      "x": -31,
      "y": 8,
      "z": -9,
      "name": "Rock_Marble"
    },
    {
      "x": -31,
      "y": 9,
      "z": -9,
      "name": "Soil_Dirt_White"
    },
    {
      "x": -31,
      "y": 10,
      "z": -9,
      "name": "Soil_Grass_Full"
    },
    {
      "x": -31,
      "y": 1,
      "z": -8,
      "name": "Rock_Marble"
    },
    {
      "x": -31,
      "y": 2,
      "z": -8,
      "name": "Rock_Marble"
    },
    {
      "x": -31,
      "y": 3,
      "z": -8,
      "name": "Rock_Marble"
    },
    {
      "x": -31,
      "y": 4,
      "z": -8,
      "name": "Rock_Marble"
    },
    {
      "x": -31,
      "y": 5,
      "z": -8,
      "name": "Soil_Dirt_White"
    },
    {
      "x": -31,
      "y": 6,
      "z": -8,
      "name": "Soil_Dirt_White"
    },
    {
      "x": -31,
      "y": 7,
      "z": -8,
      "name": "Soil_Dirt_White"
    },
    {
      "x": -31,
      "y": 8,
      "z": -8,
      "name": "Soil_Dirt_White"
    },
    {
      "x": -31,
      "y": 9,
      "z": -8,
      "name": "Soil_Grass_Full"
    },
    {
      "x": -31,
      "y": 0,
      "z": -7,
      "name": "Rock_Marble"
    },
    {
      "x": -31,
      "y": 1,
      "z": -7,
      "name": "Rock_Marble"
    },
    {
      "x": -31,
      "y": 2,
      "z": -7,
      "name": "Rock_Marble"
    },
    {
      "x": -31,
      "y": 3,
      "z": -7,
      "name": "Rock_Marble"
    },
    {
      "x": -31,
      "y": 4,
      "z": -7,
      "name": "Rock_Marble"
    },
    {
      "x": -31,
      "y": 5,
      "z": -7,
      "name": "Soil_Dirt_White"
    },
    {
      "x": -31,
      "y": 6,
      "z": -7,
      "name": "Soil_Dirt_White"
    },
    {
      "x": -31,
      "y": 7,
      "z": -7,
      "name": "Soil_Dirt_White"
    },
    {
      "x": -31,
      "y": 8,
      "z": -7,
      "name": "Soil_Dirt_White"
    },
    {
      "x": -31,
      "y": 9,
      "z": -7,
      "name": "Soil_Grass_Full"
    },
    {
      "x": -31,
      "y": 0,
      "z": -6,
      "name": "Rock_Marble"
    },
    {
      "x": -31,
      "y": 1,
      "z": -6,
      "name": "Rock_Marble"
    },
    {
      "x": -31,
      "y": 2,
      "z": -6,
      "name": "Rock_Marble"
    },
    {
      "x": -31,
      "y": 3,
      "z": -6,
      "name": "Rock_Marble"
    },
    {
      "x": -31,
      "y": 4,
      "z": -6,
      "name": "Rock_Marble"
    },
    {
      "x": -31,
      "y": 5,
      "z": -6,
      "name": "Soil_Dirt_White"
    },
    {
      "x": -31,
      "y": 6,
      "z": -6,
      "name": "Soil_Dirt_White"
    },
    {
      "x": -31,
      "y": 7,
      "z": -6,
      "name": "Soil_Dirt_White"
    },
    {
      "x": -31,
      "y": 8,
      "z": -6,
      "name": "Soil_Dirt_White"
    },
    {
      "x": -31,
      "y": 9,
      "z": -6,
      "name": "Soil_Grass_Full"
    },
    {
      "x": -31,
      "y": 0,
      "z": -5,
      "name": "Rock_Marble"
    },
    {
      "x": -31,
      "y": 1,
      "z": -5,
      "name": "Rock_Marble"
    },
    {
      "x": -31,
      "y": 2,
      "z": -5,
      "name": "Rock_Marble"
    },
    {
      "x": -31,
      "y": 3,
      "z": -5,
      "name": "Rock_Marble"
    },
    {
      "x": -31,
      "y": 4,
      "z": -5,
      "name": "Rock_Marble"
    },
    {
      "x": -31,
      "y": 5,
      "z": -5,
      "name": "Soil_Dirt_White"
    },
    {
      "x": -31,
      "y": 6,
      "z": -5,
      "name": "Soil_Dirt_White"
    },
    {
      "x": -31,
      "y": 7,
      "z": -5,
      "name": "Soil_Dirt_White"
    },
    {
      "x": -31,
      "y": 8,
      "z": -5,
      "name": "Soil_Dirt_White"
    },
    {
      "x": -31,
      "y": 9,
      "z": -5,
      "name": "Soil_Grass_White"
    },
    {
      "x": -31,
      "y": 0,
      "z": -4,
      "name": "Rock_Marble"
    },
    {
      "x": -31,
      "y": 1,
      "z": -4,
      "name": "Rock_Marble"
    },
    {
      "x": -31,
      "y": 2,
      "z": -4,
      "name": "Rock_Marble"
    },
    {
      "x": -31,
      "y": 3,
      "z": -4,
      "name": "Rock_Marble"
    },
    {
      "x": -31,
      "y": 4,
      "z": -4,
      "name": "Rock_Marble"
    },
    {
      "x": -31,
      "y": 5,
      "z": -4,
      "name": "Rock_Marble"
    },
    {
      "x": -31,
      "y": 6,
      "z": -4,
      "name": "Soil_Dirt_White"
    },
    {
      "x": -31,
      "y": 7,
      "z": -4,
      "name": "Soil_Dirt_White"
    },
    {
      "x": -31,
      "y": 8,
      "z": -4,
      "name": "Soil_Dirt_White"
    },
    {
      "x": -31,
      "y": 9,
      "z": -4,
      "name": "Soil_Grass_Full"
    },
    {
      "x": -31,
      "y": 0,
      "z": -3,
      "name": "Rock_Marble"
    },
    {
      "x": -31,
      "y": 1,
      "z": -3,
      "name": "Rock_Marble"
    },
    {
      "x": -31,
      "y": 2,
      "z": -3,
      "name": "Rock_Marble"
    },
    {
      "x": -31,
      "y": 3,
      "z": -3,
      "name": "Rock_Marble"
    },
    {
      "x": -31,
      "y": 4,
      "z": -3,
      "name": "Rock_Marble"
    },
    {
      "x": -31,
      "y": 5,
      "z": -3,
      "name": "Rock_Marble"
    },
    {
      "x": -31,
      "y": 6,
      "z": -3,
      "name": "Soil_Dirt_White"
    },
    {
      "x": -31,
      "y": 7,
      "z": -3,
      "name": "Soil_Dirt_White"
    },
    {
      "x": -31,
      "y": 8,
      "z": -3,
      "name": "Soil_Grass_White"
    },
    {
      "x": -31,
      "y": 0,
      "z": -2,
      "name": "Rock_Marble"
    },
    {
      "x": -31,
      "y": 1,
      "z": -2,
      "name": "Rock_Marble"
    },
    {
      "x": -31,
      "y": 2,
      "z": -2,
      "name": "Rock_Marble"
    },
    {
      "x": -31,
      "y": 3,
      "z": -2,
      "name": "Rock_Marble"
    },
    {
      "x": -31,
      "y": 4,
      "z": -2,
      "name": "Rock_Marble"
    },
    {
      "x": -31,
      "y": 5,
      "z": -2,
      "name": "Rock_Marble"
    },
    {
      "x": -31,
      "y": 6,
      "z": -2,
      "name": "Soil_Dirt_White"
    },
    {
      "x": -31,
      "y": 7,
      "z": -2,
      "name": "Soil_Dirt_White"
    },
    {
      "x": -31,
      "y": 8,
      "z": -2,
      "name": "Soil_Grass_White"
    },
    {
      "x": -31,
      "y": 0,
      "z": -1,
      "name": "Rock_Marble"
    },
    {
      "x": -31,
      "y": 1,
      "z": -1,
      "name": "Rock_Marble"
    },
    {
      "x": -31,
      "y": 2,
      "z": -1,
      "name": "Rock_Marble"
    },
    {
      "x": -31,
      "y": 3,
      "z": -1,
      "name": "Rock_Marble"
    },
    {
      "x": -31,
      "y": 4,
      "z": -1,
      "name": "Rock_Marble"
    },
    {
      "x": -31,
      "y": 5,
      "z": -1,
      "name": "Rock_Marble"
    },
    {
      "x": -31,
      "y": 6,
      "z": -1,
      "name": "Soil_Dirt_White"
    },
    {
      "x": -31,
      "y": 7,
      "z": -1,
      "name": "Soil_Dirt_White"
    },
    {
      "x": -31,
      "y": 8,
      "z": -1,
      "name": "Soil_Dirt_White"
    },
    {
      "x": -31,
      "y": 0,
      "z": 0,
      "name": "Rock_Marble"
    },
    {
      "x": -31,
      "y": 1,
      "z": 0,
      "name": "Rock_Marble"
    },
    {
      "x": -31,
      "y": 2,
      "z": 0,
      "name": "Rock_Marble"
    },
    {
      "x": -31,
      "y": 3,
      "z": 0,
      "name": "Rock_Marble"
    },
    {
      "x": -31,
      "y": 4,
      "z": 0,
      "name": "Rock_Marble"
    },
    {
      "x": -31,
      "y": 5,
      "z": 0,
      "name": "Rock_Marble"
    },
    {
      "x": -31,
      "y": 6,
      "z": 0,
      "name": "Rock_Marble"
    },
    {
      "x": -31,
      "y": 7,
      "z": 0,
      "name": "Soil_Dirt_White"
    },
    {
      "x": -31,
      "y": 8,
      "z": 0,
      "name": "Soil_Dirt_White"
    },
    {
      "x": -31,
      "y": 0,
      "z": 1,
      "name": "Rock_Marble"
    },
    {
      "x": -31,
      "y": 1,
      "z": 1,
      "name": "Rock_Marble"
    },
    {
      "x": -31,
      "y": 2,
      "z": 1,
      "name": "Rock_Marble"
    },
    {
      "x": -31,
      "y": 3,
      "z": 1,
      "name": "Rock_Marble"
    },
    {
      "x": -31,
      "y": 4,
      "z": 1,
      "name": "Rock_Marble"
    },
    {
      "x": -31,
      "y": 5,
      "z": 1,
      "name": "Rock_Marble"
    },
    {
      "x": -31,
      "y": 6,
      "z": 1,
      "name": "Rock_Marble"
    },
    {
      "x": -31,
      "y": 7,
      "z": 1,
      "name": "Soil_Dirt_White"
    },
    {
      "x": -31,
      "y": 0,
      "z": 2,
      "name": "Rock_Marble"
    },
    {
      "x": -31,
      "y": 1,
      "z": 2,
      "name": "Rock_Marble"
    },
    {
      "x": -31,
      "y": 2,
      "z": 2,
      "name": "Rock_Marble"
    },
    {
      "x": -31,
      "y": 3,
      "z": 2,
      "name": "Rock_Marble"
    },
    {
      "x": -31,
      "y": 4,
      "z": 2,
      "name": "Rock_Marble"
    },
    {
      "x": -31,
      "y": 5,
      "z": 2,
      "name": "Rock_Marble"
    },
    {
      "x": -31,
      "y": 6,
      "z": 2,
      "name": "Soil_Dirt_White"
    },
    {
      "x": -31,
      "y": 7,
      "z": 2,
      "name": "Soil_Dirt_White"
    },
    {
      "x": -31,
      "y": 0,
      "z": 3,
      "name": "Rock_Marble"
    },
    {
      "x": -31,
      "y": 1,
      "z": 3,
      "name": "Rock_Marble"
    },
    {
      "x": -31,
      "y": 2,
      "z": 3,
      "name": "Rock_Marble"
    },
    {
      "x": -31,
      "y": 3,
      "z": 3,
      "name": "Rock_Marble"
    },
    {
      "x": -31,
      "y": 4,
      "z": 3,
      "name": "Rock_Marble"
    },
    {
      "x": -31,
      "y": 5,
      "z": 3,
      "name": "Rock_Marble"
    },
    {
      "x": -31,
      "y": 6,
      "z": 3,
      "name": "Soil_Dirt_White"
    },
    {
      "x": -31,
      "y": 7,
      "z": 3,
      "name": "Soil_Dirt_White"
    },
    {
      "x": -31,
      "y": 0,
      "z": 4,
      "name": "Rock_Marble"
    },
    {
      "x": -31,
      "y": 1,
      "z": 4,
      "name": "Rock_Marble"
    },
    {
      "x": -31,
      "y": 2,
      "z": 4,
      "name": "Rock_Marble"
    },
    {
      "x": -31,
      "y": 3,
      "z": 4,
      "name": "Rock_Marble"
    },
    {
      "x": -31,
      "y": 4,
      "z": 4,
      "name": "Rock_Marble"
    },
    {
      "x": -31,
      "y": 5,
      "z": 4,
      "name": "Rock_Marble"
    },
    {
      "x": -31,
      "y": 6,
      "z": 4,
      "name": "Soil_Dirt_White"
    },
    {
      "x": -31,
      "y": 0,
      "z": 5,
      "name": "Rock_Marble"
    },
    {
      "x": -31,
      "y": 1,
      "z": 5,
      "name": "Rock_Marble"
    },
    {
      "x": -31,
      "y": 2,
      "z": 5,
      "name": "Rock_Marble"
    },
    {
      "x": -31,
      "y": 3,
      "z": 5,
      "name": "Rock_Marble"
    },
    {
      "x": -31,
      "y": 4,
      "z": 5,
      "name": "Rock_Marble"
    },
    {
      "x": -31,
      "y": 5,
      "z": 5,
      "name": "Rock_Marble"
    },
    {
      "x": -31,
      "y": 6,
      "z": 5,
      "name": "Soil_Dirt_White"
    },
    {
      "x": -31,
      "y": 0,
      "z": 6,
      "name": "Soil_Grass"
    },
    {
      "x": -31,
      "y": 1,
      "z": 6,
      "name": "Rock_Marble"
    },
    {
      "x": -31,
      "y": 2,
      "z": 6,
      "name": "Rock_Marble"
    },
    {
      "x": -31,
      "y": 3,
      "z": 6,
      "name": "Rock_Marble"
    },
    {
      "x": -31,
      "y": 4,
      "z": 6,
      "name": "Rock_Marble"
    },
    {
      "x": -31,
      "y": 5,
      "z": 6,
      "name": "Rock_Marble"
    },
    {
      "x": -31,
      "y": 0,
      "z": 7,
      "name": "Soil_Grass"
    },
    {
      "x": -30,
      "y": 5,
      "z": -24,
      "name": "Rock_Marble"
    },
    {
      "x": -30,
      "y": 2,
      "z": -23,
      "name": "Rock_Marble"
    },
    {
      "x": -30,
      "y": 3,
      "z": -23,
      "name": "Rock_Marble"
    },
    {
      "x": -30,
      "y": 4,
      "z": -23,
      "name": "Rock_Marble"
    },
    {
      "x": -30,
      "y": 5,
      "z": -23,
      "name": "Rock_Marble"
    },
    {
      "x": -30,
      "y": 6,
      "z": -23,
      "name": "Rock_Marble"
    },
    {
      "x": -30,
      "y": 1,
      "z": -22,
      "name": "Rock_Marble"
    },
    {
      "x": -30,
      "y": 2,
      "z": -22,
      "name": "Rock_Marble"
    },
    {
      "x": -30,
      "y": 3,
      "z": -22,
      "name": "Rock_Marble"
    },
    {
      "x": -30,
      "y": 4,
      "z": -22,
      "name": "Rock_Marble"
    },
    {
      "x": -30,
      "y": 5,
      "z": -22,
      "name": "Rock_Marble"
    },
    {
      "x": -30,
      "y": 6,
      "z": -22,
      "name": "Soil_Dirt_White"
    },
    {
      "x": -30,
      "y": 7,
      "z": -22,
      "name": "Soil_Grass_White"
    },
    {
      "x": -30,
      "y": 1,
      "z": -21,
      "name": "Rock_Marble"
    },
    {
      "x": -30,
      "y": 2,
      "z": -21,
      "name": "Rock_Marble"
    },
    {
      "x": -30,
      "y": 3,
      "z": -21,
      "name": "Rock_Marble"
    },
    {
      "x": -30,
      "y": 4,
      "z": -21,
      "name": "Rock_Marble"
    },
    {
      "x": -30,
      "y": 5,
      "z": -21,
      "name": "Rock_Marble"
    },
    {
      "x": -30,
      "y": 6,
      "z": -21,
      "name": "Soil_Dirt_White"
    },
    {
      "x": -30,
      "y": 7,
      "z": -21,
      "name": "Soil_Dirt_White"
    },
    {
      "x": -30,
      "y": 8,
      "z": -21,
      "name": "Soil_Grass_Full"
    },
    {
      "x": -30,
      "y": 0,
      "z": -20,
      "name": "Rock_Marble"
    },
    {
      "x": -30,
      "y": 1,
      "z": -20,
      "name": "Rock_Marble"
    },
    {
      "x": -30,
      "y": 2,
      "z": -20,
      "name": "Rock_Marble"
    },
    {
      "x": -30,
      "y": 3,
      "z": -20,
      "name": "Rock_Marble"
    },
    {
      "x": -30,
      "y": 4,
      "z": -20,
      "name": "Rock_Marble"
    },
    {
      "x": -30,
      "y": 5,
      "z": -20,
      "name": "Rock_Marble"
    },
    {
      "x": -30,
      "y": 6,
      "z": -20,
      "name": "Soil_Dirt_White"
    },
    {
      "x": -30,
      "y": 7,
      "z": -20,
      "name": "Rock_Marble"
    },
    {
      "x": -30,
      "y": 8,
      "z": -20,
      "name": "Soil_Dirt_White"
    },
    {
      "x": -30,
      "y": 9,
      "z": -20,
      "name": "Soil_Grass_Full"
    },
    {
      "x": -30,
      "y": 0,
      "z": -19,
      "name": "Rock_Marble"
    },
    {
      "x": -30,
      "y": 1,
      "z": -19,
      "name": "Rock_Marble"
    },
    {
      "x": -30,
      "y": 2,
      "z": -19,
      "name": "Rock_Marble"
    },
    {
      "x": -30,
      "y": 3,
      "z": -19,
      "name": "Rock_Marble"
    },
    {
      "x": -30,
      "y": 4,
      "z": -19,
      "name": "Rock_Marble"
    },
    {
      "x": -30,
      "y": 5,
      "z": -19,
      "name": "Rock_Marble"
    },
    {
      "x": -30,
      "y": 6,
      "z": -19,
      "name": "Soil_Dirt_White"
    },
    {
      "x": -30,
      "y": 7,
      "z": -19,
      "name": "Soil_Dirt_White"
    },
    {
      "x": -30,
      "y": 8,
      "z": -19,
      "name": "Rock_Marble"
    },
    {
      "x": -30,
      "y": 9,
      "z": -19,
      "name": "Soil_Dirt_White"
    },
    {
      "x": -30,
      "y": 10,
      "z": -19,
      "name": "Soil_Grass_Full"
    },
    {
      "x": -30,
      "y": 0,
      "z": -18,
      "name": "Rock_Marble"
    },
    {
      "x": -30,
      "y": 1,
      "z": -18,
      "name": "Rock_Marble"
    },
    {
      "x": -30,
      "y": 2,
      "z": -18,
      "name": "Rock_Marble"
    },
    {
      "x": -30,
      "y": 3,
      "z": -18,
      "name": "Rock_Marble"
    },
    {
      "x": -30,
      "y": 4,
      "z": -18,
      "name": "Rock_Marble"
    },
    {
      "x": -30,
      "y": 5,
      "z": -18,
      "name": "Rock_Marble"
    },
    {
      "x": -30,
      "y": 6,
      "z": -18,
      "name": "Soil_Dirt_White"
    },
    {
      "x": -30,
      "y": 7,
      "z": -18,
      "name": "Soil_Dirt_White"
    },
    {
      "x": -30,
      "y": 8,
      "z": -18,
      "name": "Rock_Marble"
    },
    {
      "x": -30,
      "y": 9,
      "z": -18,
      "name": "Soil_Dirt_White"
    },
    {
      "x": -30,
      "y": 10,
      "z": -18,
      "name": "Soil_Grass_Full"
    },
    {
      "x": -30,
      "y": 0,
      "z": -17,
      "name": "Rock_Marble"
    },
    {
      "x": -30,
      "y": 1,
      "z": -17,
      "name": "Rock_Marble"
    },
    {
      "x": -30,
      "y": 2,
      "z": -17,
      "name": "Rock_Marble"
    },
    {
      "x": -30,
      "y": 3,
      "z": -17,
      "name": "Rock_Marble"
    },
    {
      "x": -30,
      "y": 4,
      "z": -17,
      "name": "Rock_Marble"
    },
    {
      "x": -30,
      "y": 5,
      "z": -17,
      "name": "Rock_Marble"
    },
    {
      "x": -30,
      "y": 6,
      "z": -17,
      "name": "Soil_Dirt_White"
    },
    {
      "x": -30,
      "y": 7,
      "z": -17,
      "name": "Soil_Dirt_White"
    },
    {
      "x": -30,
      "y": 8,
      "z": -17,
      "name": "Rock_Marble"
    },
    {
      "x": -30,
      "y": 9,
      "z": -17,
      "name": "Soil_Dirt_White"
    },
    {
      "x": -30,
      "y": 10,
      "z": -17,
      "name": "Soil_Grass_Full"
    },
    {
      "x": -30,
      "y": 0,
      "z": -16,
      "name": "Rock_Marble"
    },
    {
      "x": -30,
      "y": 1,
      "z": -16,
      "name": "Rock_Marble"
    },
    {
      "x": -30,
      "y": 2,
      "z": -16,
      "name": "Rock_Marble"
    },
    {
      "x": -30,
      "y": 3,
      "z": -16,
      "name": "Rock_Marble"
    },
    {
      "x": -30,
      "y": 4,
      "z": -16,
      "name": "Rock_Marble"
    },
    {
      "x": -30,
      "y": 5,
      "z": -16,
      "name": "Rock_Marble"
    },
    {
      "x": -30,
      "y": 6,
      "z": -16,
      "name": "Soil_Dirt_White"
    },
    {
      "x": -30,
      "y": 7,
      "z": -16,
      "name": "Soil_Dirt_White"
    },
    {
      "x": -30,
      "y": 8,
      "z": -16,
      "name": "Soil_Dirt_White"
    },
    {
      "x": -30,
      "y": 9,
      "z": -16,
      "name": "Soil_Dirt_White"
    },
    {
      "x": -30,
      "y": 10,
      "z": -16,
      "name": "Soil_Grass_Full"
    },
    {
      "x": -30,
      "y": 0,
      "z": -15,
      "name": "Rock_Marble"
    },
    {
      "x": -30,
      "y": 1,
      "z": -15,
      "name": "Rock_Marble"
    },
    {
      "x": -30,
      "y": 2,
      "z": -15,
      "name": "Rock_Marble"
    },
    {
      "x": -30,
      "y": 3,
      "z": -15,
      "name": "Rock_Marble"
    },
    {
      "x": -30,
      "y": 4,
      "z": -15,
      "name": "Rock_Marble"
    },
    {
      "x": -30,
      "y": 5,
      "z": -15,
      "name": "Rock_Marble"
    },
    {
      "x": -30,
      "y": 6,
      "z": -15,
      "name": "Soil_Dirt_White"
    },
    {
      "x": -30,
      "y": 7,
      "z": -15,
      "name": "Soil_Dirt_White"
    },
    {
      "x": -30,
      "y": 8,
      "z": -15,
      "name": "Rock_Marble"
    },
    {
      "x": -30,
      "y": 9,
      "z": -15,
      "name": "Soil_Dirt_White"
    },
    {
      "x": -30,
      "y": 10,
      "z": -15,
      "name": "Soil_Grass_Full"
    },
    {
      "x": -30,
      "y": 0,
      "z": -14,
      "name": "Rock_Marble"
    },
    {
      "x": -30,
      "y": 1,
      "z": -14,
      "name": "Rock_Marble"
    },
    {
      "x": -30,
      "y": 2,
      "z": -14,
      "name": "Rock_Marble"
    },
    {
      "x": -30,
      "y": 3,
      "z": -14,
      "name": "Rock_Marble"
    },
    {
      "x": -30,
      "y": 4,
      "z": -14,
      "name": "Rock_Marble"
    },
    {
      "x": -30,
      "y": 5,
      "z": -14,
      "name": "Rock_Marble"
    },
    {
      "x": -30,
      "y": 6,
      "z": -14,
      "name": "Rock_Marble"
    },
    {
      "x": -30,
      "y": 7,
      "z": -14,
      "name": "Soil_Dirt_White"
    },
    {
      "x": -30,
      "y": 8,
      "z": -14,
      "name": "Soil_Dirt_White"
    },
    {
      "x": -30,
      "y": 9,
      "z": -14,
      "name": "Rock_Marble"
    },
    {
      "x": -30,
      "y": 10,
      "z": -14,
      "name": "Soil_Dirt_White"
    },
    {
      "x": -30,
      "y": 11,
      "z": -14,
      "name": "Soil_Grass_Full"
    },
    {
      "x": -30,
      "y": 0,
      "z": -13,
      "name": "Rock_Marble"
    },
    {
      "x": -30,
      "y": 1,
      "z": -13,
      "name": "Rock_Marble"
    },
    {
      "x": -30,
      "y": 2,
      "z": -13,
      "name": "Rock_Marble"
    },
    {
      "x": -30,
      "y": 3,
      "z": -13,
      "name": "Rock_Marble"
    },
    {
      "x": -30,
      "y": 4,
      "z": -13,
      "name": "Rock_Marble"
    },
    {
      "x": -30,
      "y": 5,
      "z": -13,
      "name": "Rock_Marble"
    },
    {
      "x": -30,
      "y": 6,
      "z": -13,
      "name": "Soil_Dirt_White"
    },
    {
      "x": -30,
      "y": 7,
      "z": -13,
      "name": "Soil_Dirt_White"
    },
    {
      "x": -30,
      "y": 8,
      "z": -13,
      "name": "Soil_Dirt_White"
    },
    {
      "x": -30,
      "y": 9,
      "z": -13,
      "name": "Rock_Marble"
    },
    {
      "x": -30,
      "y": 10,
      "z": -13,
      "name": "Soil_Dirt_White"
    },
    {
      "x": -30,
      "y": 11,
      "z": -13,
      "name": "Soil_Grass_Full"
    },
    {
      "x": -30,
      "y": 0,
      "z": -12,
      "name": "Rock_Marble"
    },
    {
      "x": -30,
      "y": 1,
      "z": -12,
      "name": "Rock_Marble"
    },
    {
      "x": -30,
      "y": 2,
      "z": -12,
      "name": "Rock_Marble"
    },
    {
      "x": -30,
      "y": 3,
      "z": -12,
      "name": "Rock_Marble"
    },
    {
      "x": -30,
      "y": 4,
      "z": -12,
      "name": "Rock_Marble"
    },
    {
      "x": -30,
      "y": 5,
      "z": -12,
      "name": "Rock_Marble"
    },
    {
      "x": -30,
      "y": 6,
      "z": -12,
      "name": "Soil_Dirt_White"
    },
    {
      "x": -30,
      "y": 7,
      "z": -12,
      "name": "Soil_Dirt_White"
    },
    {
      "x": -30,
      "y": 8,
      "z": -12,
      "name": "Soil_Dirt_White"
    },
    {
      "x": -30,
      "y": 9,
      "z": -12,
      "name": "Rock_Marble"
    },
    {
      "x": -30,
      "y": 10,
      "z": -12,
      "name": "Soil_Dirt_White"
    },
    {
      "x": -30,
      "y": 11,
      "z": -12,
      "name": "Soil_Grass_Full"
    },
    {
      "x": -30,
      "y": 0,
      "z": -11,
      "name": "Rock_Marble"
    },
    {
      "x": -30,
      "y": 1,
      "z": -11,
      "name": "Rock_Marble"
    },
    {
      "x": -30,
      "y": 2,
      "z": -11,
      "name": "Rock_Marble"
    },
    {
      "x": -30,
      "y": 3,
      "z": -11,
      "name": "Rock_Marble"
    },
    {
      "x": -30,
      "y": 4,
      "z": -11,
      "name": "Rock_Marble"
    },
    {
      "x": -30,
      "y": 5,
      "z": -11,
      "name": "Rock_Marble"
    },
    {
      "x": -30,
      "y": 6,
      "z": -11,
      "name": "Soil_Dirt_White"
    },
    {
      "x": -30,
      "y": 7,
      "z": -11,
      "name": "Soil_Dirt_White"
    },
    {
      "x": -30,
      "y": 8,
      "z": -11,
      "name": "Soil_Dirt_White"
    },
    {
      "x": -30,
      "y": 9,
      "z": -11,
      "name": "Rock_Marble"
    },
    {
      "x": -30,
      "y": 10,
      "z": -11,
      "name": "Soil_Dirt_White"
    },
    {
      "x": -30,
      "y": 11,
      "z": -11,
      "name": "Soil_Grass_Full"
    },
    {
      "x": -30,
      "y": 0,
      "z": -10,
      "name": "Rock_Marble"
    },
    {
      "x": -30,
      "y": 1,
      "z": -10,
      "name": "Rock_Marble"
    },
    {
      "x": -30,
      "y": 2,
      "z": -10,
      "name": "Rock_Marble"
    },
    {
      "x": -30,
      "y": 3,
      "z": -10,
      "name": "Rock_Marble"
    },
    {
      "x": -30,
      "y": 4,
      "z": -10,
      "name": "Rock_Marble"
    },
    {
      "x": -30,
      "y": 5,
      "z": -10,
      "name": "Rock_Marble"
    },
    {
      "x": -30,
      "y": 6,
      "z": -10,
      "name": "Soil_Dirt_White"
    },
    {
      "x": -30,
      "y": 7,
      "z": -10,
      "name": "Soil_Dirt_White"
    },
    {
      "x": -30,
      "y": 8,
      "z": -10,
      "name": "Soil_Dirt_White"
    },
    {
      "x": -30,
      "y": 9,
      "z": -10,
      "name": "Rock_Marble"
    },
    {
      "x": -30,
      "y": 10,
      "z": -10,
      "name": "Soil_Dirt_White"
    },
    {
      "x": -30,
      "y": 11,
      "z": -10,
      "name": "Soil_Grass_Full"
    },
    {
      "x": -30,
      "y": 0,
      "z": -9,
      "name": "Rock_Marble"
    },
    {
      "x": -30,
      "y": 1,
      "z": -9,
      "name": "Rock_Marble"
    },
    {
      "x": -30,
      "y": 2,
      "z": -9,
      "name": "Rock_Marble"
    },
    {
      "x": -30,
      "y": 3,
      "z": -9,
      "name": "Rock_Marble"
    },
    {
      "x": -30,
      "y": 4,
      "z": -9,
      "name": "Rock_Marble"
    },
    {
      "x": -30,
      "y": 5,
      "z": -9,
      "name": "Rock_Marble"
    },
    {
      "x": -30,
      "y": 6,
      "z": -9,
      "name": "Soil_Dirt_White"
    },
    {
      "x": -30,
      "y": 7,
      "z": -9,
      "name": "Soil_Dirt_White"
    },
    {
      "x": -30,
      "y": 8,
      "z": -9,
      "name": "Soil_Dirt_White"
    },
    {
      "x": -30,
      "y": 9,
      "z": -9,
      "name": "Rock_Marble"
    },
    {
      "x": -30,
      "y": 10,
      "z": -9,
      "name": "Soil_Dirt_White"
    },
    {
      "x": -30,
      "y": 11,
      "z": -9,
      "name": "Soil_Grass_Full"
    },
    {
      "x": -30,
      "y": 0,
      "z": -8,
      "name": "Rock_Marble"
    },
    {
      "x": -30,
      "y": 1,
      "z": -8,
      "name": "Rock_Marble"
    },
    {
      "x": -30,
      "y": 2,
      "z": -8,
      "name": "Rock_Marble"
    },
    {
      "x": -30,
      "y": 3,
      "z": -8,
      "name": "Rock_Marble"
    },
    {
      "x": -30,
      "y": 4,
      "z": -8,
      "name": "Rock_Marble"
    },
    {
      "x": -30,
      "y": 5,
      "z": -8,
      "name": "Soil_Dirt_White"
    },
    {
      "x": -30,
      "y": 6,
      "z": -8,
      "name": "Soil_Dirt_White"
    },
    {
      "x": -30,
      "y": 7,
      "z": -8,
      "name": "Soil_Dirt_White"
    },
    {
      "x": -30,
      "y": 8,
      "z": -8,
      "name": "Rock_Marble"
    },
    {
      "x": -30,
      "y": 9,
      "z": -8,
      "name": "Soil_Dirt_White"
    },
    {
      "x": -30,
      "y": 10,
      "z": -8,
      "name": "Soil_Grass_Full"
    },
    {
      "x": -30,
      "y": 0,
      "z": -7,
      "name": "Rock_Marble"
    },
    {
      "x": -30,
      "y": 1,
      "z": -7,
      "name": "Rock_Marble"
    },
    {
      "x": -30,
      "y": 2,
      "z": -7,
      "name": "Rock_Marble"
    },
    {
      "x": -30,
      "y": 3,
      "z": -7,
      "name": "Rock_Marble"
    },
    {
      "x": -30,
      "y": 4,
      "z": -7,
      "name": "Rock_Marble"
    },
    {
      "x": -30,
      "y": 5,
      "z": -7,
      "name": "Soil_Dirt_White"
    },
    {
      "x": -30,
      "y": 6,
      "z": -7,
      "name": "Soil_Dirt_White"
    },
    {
      "x": -30,
      "y": 7,
      "z": -7,
      "name": "Soil_Dirt_White"
    },
    {
      "x": -30,
      "y": 8,
      "z": -7,
      "name": "Rock_Marble"
    },
    {
      "x": -30,
      "y": 9,
      "z": -7,
      "name": "Soil_Dirt_White"
    },
    {
      "x": -30,
      "y": 10,
      "z": -7,
      "name": "Soil_Grass_Full"
    },
    {
      "x": -30,
      "y": 0,
      "z": -6,
      "name": "Rock_Marble"
    },
    {
      "x": -30,
      "y": 1,
      "z": -6,
      "name": "Rock_Marble"
    },
    {
      "x": -30,
      "y": 2,
      "z": -6,
      "name": "Rock_Marble"
    },
    {
      "x": -30,
      "y": 3,
      "z": -6,
      "name": "Rock_Marble"
    },
    {
      "x": -30,
      "y": 4,
      "z": -6,
      "name": "Rock_Marble"
    },
    {
      "x": -30,
      "y": 5,
      "z": -6,
      "name": "Soil_Dirt_White"
    },
    {
      "x": -30,
      "y": 6,
      "z": -6,
      "name": "Soil_Dirt_White"
    },
    {
      "x": -30,
      "y": 7,
      "z": -6,
      "name": "Soil_Dirt_White"
    },
    {
      "x": -30,
      "y": 8,
      "z": -6,
      "name": "Rock_Marble"
    },
    {
      "x": -30,
      "y": 9,
      "z": -6,
      "name": "Soil_Dirt_White"
    },
    {
      "x": -30,
      "y": 10,
      "z": -6,
      "name": "Soil_Grass_Full"
    },
    {
      "x": -30,
      "y": 0,
      "z": -5,
      "name": "Rock_Marble"
    },
    {
      "x": -30,
      "y": 1,
      "z": -5,
      "name": "Rock_Marble"
    },
    {
      "x": -30,
      "y": 2,
      "z": -5,
      "name": "Rock_Marble"
    },
    {
      "x": -30,
      "y": 3,
      "z": -5,
      "name": "Rock_Marble"
    },
    {
      "x": -30,
      "y": 4,
      "z": -5,
      "name": "Rock_Marble"
    },
    {
      "x": -30,
      "y": 5,
      "z": -5,
      "name": "Soil_Dirt_White"
    },
    {
      "x": -30,
      "y": 6,
      "z": -5,
      "name": "Soil_Dirt_White"
    },
    {
      "x": -30,
      "y": 7,
      "z": -5,
      "name": "Soil_Dirt_White"
    },
    {
      "x": -30,
      "y": 8,
      "z": -5,
      "name": "Soil_Dirt_White"
    },
    {
      "x": -30,
      "y": 9,
      "z": -5,
      "name": "Soil_Dirt_White"
    },
    {
      "x": -30,
      "y": 10,
      "z": -5,
      "name": "Soil_Grass_Full"
    },
    {
      "x": -30,
      "y": 0,
      "z": -4,
      "name": "Rock_Marble"
    },
    {
      "x": -30,
      "y": 1,
      "z": -4,
      "name": "Rock_Marble"
    },
    {
      "x": -30,
      "y": 2,
      "z": -4,
      "name": "Rock_Marble"
    },
    {
      "x": -30,
      "y": 3,
      "z": -4,
      "name": "Rock_Marble"
    },
    {
      "x": -30,
      "y": 4,
      "z": -4,
      "name": "Rock_Marble"
    },
    {
      "x": -30,
      "y": 5,
      "z": -4,
      "name": "Rock_Marble"
    },
    {
      "x": -30,
      "y": 6,
      "z": -4,
      "name": "Soil_Dirt_White"
    },
    {
      "x": -30,
      "y": 7,
      "z": -4,
      "name": "Soil_Dirt_White"
    },
    {
      "x": -30,
      "y": 8,
      "z": -4,
      "name": "Soil_Dirt_White"
    },
    {
      "x": -30,
      "y": 9,
      "z": -4,
      "name": "Soil_Grass_Full"
    },
    {
      "x": -30,
      "y": 0,
      "z": -3,
      "name": "Rock_Marble"
    },
    {
      "x": -30,
      "y": 1,
      "z": -3,
      "name": "Rock_Marble"
    },
    {
      "x": -30,
      "y": 2,
      "z": -3,
      "name": "Rock_Marble"
    },
    {
      "x": -30,
      "y": 3,
      "z": -3,
      "name": "Rock_Marble"
    },
    {
      "x": -30,
      "y": 4,
      "z": -3,
      "name": "Rock_Marble"
    },
    {
      "x": -30,
      "y": 5,
      "z": -3,
      "name": "Rock_Marble"
    },
    {
      "x": -30,
      "y": 6,
      "z": -3,
      "name": "Soil_Dirt_White"
    },
    {
      "x": -30,
      "y": 7,
      "z": -3,
      "name": "Soil_Dirt_White"
    },
    {
      "x": -30,
      "y": 8,
      "z": -3,
      "name": "Soil_Dirt_White"
    },
    {
      "x": -30,
      "y": 9,
      "z": -3,
      "name": "Soil_Grass_Full"
    },
    {
      "x": -30,
      "y": 0,
      "z": -2,
      "name": "Rock_Marble"
    },
    {
      "x": -30,
      "y": 1,
      "z": -2,
      "name": "Rock_Marble"
    },
    {
      "x": -30,
      "y": 2,
      "z": -2,
      "name": "Rock_Marble"
    },
    {
      "x": -30,
      "y": 3,
      "z": -2,
      "name": "Rock_Marble"
    },
    {
      "x": -30,
      "y": 4,
      "z": -2,
      "name": "Rock_Marble"
    },
    {
      "x": -30,
      "y": 5,
      "z": -2,
      "name": "Rock_Marble"
    },
    {
      "x": -30,
      "y": 6,
      "z": -2,
      "name": "Soil_Dirt_White"
    },
    {
      "x": -30,
      "y": 7,
      "z": -2,
      "name": "Soil_Dirt_White"
    },
    {
      "x": -30,
      "y": 8,
      "z": -2,
      "name": "Soil_Dirt_White"
    },
    {
      "x": -30,
      "y": 9,
      "z": -2,
      "name": "Soil_Grass_Full"
    },
    {
      "x": -30,
      "y": 0,
      "z": -1,
      "name": "Rock_Marble"
    },
    {
      "x": -30,
      "y": 1,
      "z": -1,
      "name": "Rock_Marble"
    },
    {
      "x": -30,
      "y": 2,
      "z": -1,
      "name": "Rock_Marble"
    },
    {
      "x": -30,
      "y": 3,
      "z": -1,
      "name": "Rock_Marble"
    },
    {
      "x": -30,
      "y": 4,
      "z": -1,
      "name": "Rock_Marble"
    },
    {
      "x": -30,
      "y": 5,
      "z": -1,
      "name": "Rock_Marble"
    },
    {
      "x": -30,
      "y": 6,
      "z": -1,
      "name": "Soil_Dirt_White"
    },
    {
      "x": -30,
      "y": 7,
      "z": -1,
      "name": "Soil_Dirt_White"
    },
    {
      "x": -30,
      "y": 8,
      "z": -1,
      "name": "Soil_Dirt_White"
    },
    {
      "x": -30,
      "y": 9,
      "z": -1,
      "name": "Soil_Grass_Full"
    },
    {
      "x": -30,
      "y": 0,
      "z": 0,
      "name": "Rock_Marble"
    },
    {
      "x": -30,
      "y": 1,
      "z": 0,
      "name": "Rock_Marble"
    },
    {
      "x": -30,
      "y": 2,
      "z": 0,
      "name": "Rock_Marble"
    },
    {
      "x": -30,
      "y": 3,
      "z": 0,
      "name": "Rock_Marble"
    },
    {
      "x": -30,
      "y": 4,
      "z": 0,
      "name": "Rock_Marble"
    },
    {
      "x": -30,
      "y": 5,
      "z": 0,
      "name": "Rock_Marble"
    },
    {
      "x": -30,
      "y": 6,
      "z": 0,
      "name": "Rock_Marble"
    },
    {
      "x": -30,
      "y": 7,
      "z": 0,
      "name": "Soil_Dirt_White"
    },
    {
      "x": -30,
      "y": 8,
      "z": 0,
      "name": "Soil_Dirt_White"
    },
    {
      "x": -30,
      "y": 9,
      "z": 0,
      "name": "Soil_Grass_White"
    },
    {
      "x": -30,
      "y": 0,
      "z": 1,
      "name": "Rock_Marble"
    },
    {
      "x": -30,
      "y": 1,
      "z": 1,
      "name": "Rock_Marble"
    },
    {
      "x": -30,
      "y": 2,
      "z": 1,
      "name": "Rock_Marble"
    },
    {
      "x": -30,
      "y": 3,
      "z": 1,
      "name": "Rock_Marble"
    },
    {
      "x": -30,
      "y": 4,
      "z": 1,
      "name": "Rock_Marble"
    },
    {
      "x": -30,
      "y": 5,
      "z": 1,
      "name": "Rock_Marble"
    },
    {
      "x": -30,
      "y": 6,
      "z": 1,
      "name": "Rock_Marble"
    },
    {
      "x": -30,
      "y": 7,
      "z": 1,
      "name": "Soil_Dirt_White"
    },
    {
      "x": -30,
      "y": 8,
      "z": 1,
      "name": "Soil_Dirt_White"
    },
    {
      "x": -30,
      "y": 0,
      "z": 2,
      "name": "Rock_Marble"
    },
    {
      "x": -30,
      "y": 1,
      "z": 2,
      "name": "Rock_Marble"
    },
    {
      "x": -30,
      "y": 2,
      "z": 2,
      "name": "Rock_Marble"
    },
    {
      "x": -30,
      "y": 3,
      "z": 2,
      "name": "Rock_Marble"
    },
    {
      "x": -30,
      "y": 4,
      "z": 2,
      "name": "Rock_Marble"
    },
    {
      "x": -30,
      "y": 5,
      "z": 2,
      "name": "Rock_Marble"
    },
    {
      "x": -30,
      "y": 6,
      "z": 2,
      "name": "Soil_Dirt_White"
    },
    {
      "x": -30,
      "y": 7,
      "z": 2,
      "name": "Soil_Dirt_White"
    },
    {
      "x": -30,
      "y": 8,
      "z": 2,
      "name": "Soil_Dirt_White"
    },
    {
      "x": -30,
      "y": 0,
      "z": 3,
      "name": "Rock_Marble"
    },
    {
      "x": -30,
      "y": 1,
      "z": 3,
      "name": "Rock_Marble"
    },
    {
      "x": -30,
      "y": 2,
      "z": 3,
      "name": "Rock_Marble"
    },
    {
      "x": -30,
      "y": 3,
      "z": 3,
      "name": "Rock_Marble"
    },
    {
      "x": -30,
      "y": 4,
      "z": 3,
      "name": "Rock_Marble"
    },
    {
      "x": -30,
      "y": 5,
      "z": 3,
      "name": "Rock_Marble"
    },
    {
      "x": -30,
      "y": 6,
      "z": 3,
      "name": "Soil_Dirt_White"
    },
    {
      "x": -30,
      "y": 7,
      "z": 3,
      "name": "Soil_Dirt_White"
    },
    {
      "x": -30,
      "y": 8,
      "z": 3,
      "name": "Soil_Dirt_White"
    },
    {
      "x": -30,
      "y": 0,
      "z": 4,
      "name": "Rock_Marble"
    },
    {
      "x": -30,
      "y": 1,
      "z": 4,
      "name": "Rock_Marble"
    },
    {
      "x": -30,
      "y": 2,
      "z": 4,
      "name": "Rock_Marble"
    },
    {
      "x": -30,
      "y": 3,
      "z": 4,
      "name": "Rock_Marble"
    },
    {
      "x": -30,
      "y": 4,
      "z": 4,
      "name": "Rock_Marble"
    },
    {
      "x": -30,
      "y": 5,
      "z": 4,
      "name": "Rock_Marble"
    },
    {
      "x": -30,
      "y": 6,
      "z": 4,
      "name": "Soil_Dirt_White"
    },
    {
      "x": -30,
      "y": 7,
      "z": 4,
      "name": "Soil_Dirt_White"
    },
    {
      "x": -30,
      "y": 8,
      "z": 4,
      "name": "Soil_Grass_White"
    },
    {
      "x": -30,
      "y": 0,
      "z": 5,
      "name": "Rock_Marble"
    },
    {
      "x": -30,
      "y": 1,
      "z": 5,
      "name": "Rock_Marble"
    },
    {
      "x": -30,
      "y": 2,
      "z": 5,
      "name": "Rock_Marble"
    },
    {
      "x": -30,
      "y": 3,
      "z": 5,
      "name": "Rock_Marble"
    },
    {
      "x": -30,
      "y": 4,
      "z": 5,
      "name": "Rock_Marble"
    },
    {
      "x": -30,
      "y": 5,
      "z": 5,
      "name": "Rock_Marble"
    },
    {
      "x": -30,
      "y": 6,
      "z": 5,
      "name": "Soil_Dirt_White"
    },
    {
      "x": -30,
      "y": 7,
      "z": 5,
      "name": "Soil_Dirt_White"
    },
    {
      "x": -30,
      "y": 8,
      "z": 5,
      "name": "Soil_Dirt_White"
    },
    {
      "x": -30,
      "y": 0,
      "z": 6,
      "name": "Rock_Marble"
    },
    {
      "x": -30,
      "y": 1,
      "z": 6,
      "name": "Rock_Marble"
    },
    {
      "x": -30,
      "y": 2,
      "z": 6,
      "name": "Rock_Marble"
    },
    {
      "x": -30,
      "y": 3,
      "z": 6,
      "name": "Rock_Marble"
    },
    {
      "x": -30,
      "y": 4,
      "z": 6,
      "name": "Rock_Marble"
    },
    {
      "x": -30,
      "y": 5,
      "z": 6,
      "name": "Rock_Marble"
    },
    {
      "x": -30,
      "y": 6,
      "z": 6,
      "name": "Soil_Dirt_White"
    },
    {
      "x": -30,
      "y": 7,
      "z": 6,
      "name": "Soil_Dirt_White"
    },
    {
      "x": -30,
      "y": 8,
      "z": 6,
      "name": "Soil_Dirt_White"
    },
    {
      "x": -30,
      "y": 0,
      "z": 7,
      "name": "Rock_Marble"
    },
    {
      "x": -30,
      "y": 1,
      "z": 7,
      "name": "Rock_Marble"
    },
    {
      "x": -30,
      "y": 2,
      "z": 7,
      "name": "Rock_Marble"
    },
    {
      "x": -30,
      "y": 3,
      "z": 7,
      "name": "Rock_Marble"
    },
    {
      "x": -30,
      "y": 4,
      "z": 7,
      "name": "Rock_Marble"
    },
    {
      "x": -30,
      "y": 5,
      "z": 7,
      "name": "Rock_Marble"
    },
    {
      "x": -30,
      "y": 6,
      "z": 7,
      "name": "Soil_Dirt_White"
    },
    {
      "x": -30,
      "y": 7,
      "z": 7,
      "name": "Soil_Dirt_White"
    },
    {
      "x": -30,
      "y": 0,
      "z": 8,
      "name": "Rock_Marble"
    },
    {
      "x": -30,
      "y": 2,
      "z": 8,
      "name": "Rock_Marble"
    },
    {
      "x": -30,
      "y": 3,
      "z": 8,
      "name": "Rock_Marble"
    },
    {
      "x": -30,
      "y": 4,
      "z": 8,
      "name": "Rock_Marble"
    },
    {
      "x": -30,
      "y": 5,
      "z": 8,
      "name": "Soil_Dirt_White"
    },
    {
      "x": -30,
      "y": 6,
      "z": 8,
      "name": "Soil_Dirt_White"
    },
    {
      "x": -30,
      "y": 3,
      "z": 9,
      "name": "Rock_Marble"
    },
    {
      "x": -30,
      "y": 4,
      "z": 9,
      "name": "Rock_Marble"
    },
    {
      "x": -30,
      "y": 5,
      "z": 9,
      "name": "Soil_Dirt_White"
    },
    {
      "x": -30,
      "y": 6,
      "z": 9,
      "name": "Soil_Dirt_White"
    },
    {
      "x": -30,
      "y": 3,
      "z": 10,
      "name": "Rock_Marble"
    },
    {
      "x": -30,
      "y": 4,
      "z": 10,
      "name": "Rock_Marble"
    },
    {
      "x": -30,
      "y": 5,
      "z": 10,
      "name": "Soil_Dirt_White"
    },
    {
      "x": -30,
      "y": 6,
      "z": 10,
      "name": "Soil_Dirt_White"
    },
    {
      "x": -29,
      "y": 3,
      "z": -24,
      "name": "Rock_Marble"
    },
    {
      "x": -29,
      "y": 4,
      "z": -24,
      "name": "Rock_Marble"
    },
    {
      "x": -29,
      "y": 5,
      "z": -24,
      "name": "Soil_Dirt_White"
    },
    {
      "x": -29,
      "y": 6,
      "z": -24,
      "name": "Soil_Grass_Full"
    },
    {
      "x": -29,
      "y": 1,
      "z": -23,
      "name": "Rock_Marble"
    },
    {
      "x": -29,
      "y": 2,
      "z": -23,
      "name": "Rock_Marble"
    },
    {
      "x": -29,
      "y": 3,
      "z": -23,
      "name": "Rock_Marble"
    },
    {
      "x": -29,
      "y": 4,
      "z": -23,
      "name": "Rock_Marble"
    },
    {
      "x": -29,
      "y": 5,
      "z": -23,
      "name": "Rock_Marble"
    },
    {
      "x": -29,
      "y": 6,
      "z": -23,
      "name": "Soil_Dirt_White"
    },
    {
      "x": -29,
      "y": 7,
      "z": -23,
      "name": "Soil_Grass_Full"
    },
    {
      "x": -29,
      "y": 1,
      "z": -22,
      "name": "Rock_Marble"
    },
    {
      "x": -29,
      "y": 2,
      "z": -22,
      "name": "Rock_Marble"
    },
    {
      "x": -29,
      "y": 3,
      "z": -22,
      "name": "Rock_Marble"
    },
    {
      "x": -29,
      "y": 4,
      "z": -22,
      "name": "Rock_Marble"
    },
    {
      "x": -29,
      "y": 5,
      "z": -22,
      "name": "Rock_Marble"
    },
    {
      "x": -29,
      "y": 6,
      "z": -22,
      "name": "Soil_Dirt_White"
    },
    {
      "x": -29,
      "y": 7,
      "z": -22,
      "name": "Soil_Dirt_White"
    },
    {
      "x": -29,
      "y": 8,
      "z": -22,
      "name": "Soil_Grass_Full"
    },
    {
      "x": -29,
      "y": 0,
      "z": -21,
      "name": "Rock_Marble"
    },
    {
      "x": -29,
      "y": 1,
      "z": -21,
      "name": "Rock_Marble"
    },
    {
      "x": -29,
      "y": 2,
      "z": -21,
      "name": "Rock_Marble"
    },
    {
      "x": -29,
      "y": 3,
      "z": -21,
      "name": "Rock_Marble"
    },
    {
      "x": -29,
      "y": 4,
      "z": -21,
      "name": "Rock_Marble"
    },
    {
      "x": -29,
      "y": 5,
      "z": -21,
      "name": "Rock_Marble"
    },
    {
      "x": -29,
      "y": 6,
      "z": -21,
      "name": "Soil_Dirt_White"
    },
    {
      "x": -29,
      "y": 7,
      "z": -21,
      "name": "Rock_Marble"
    },
    {
      "x": -29,
      "y": 8,
      "z": -21,
      "name": "Soil_Dirt_White"
    },
    {
      "x": -29,
      "y": 9,
      "z": -21,
      "name": "Soil_Grass_Full"
    },
    {
      "x": -29,
      "y": 0,
      "z": -20,
      "name": "Rock_Marble"
    },
    {
      "x": -29,
      "y": 1,
      "z": -20,
      "name": "Rock_Marble"
    },
    {
      "x": -29,
      "y": 2,
      "z": -20,
      "name": "Rock_Marble"
    },
    {
      "x": -29,
      "y": 3,
      "z": -20,
      "name": "Rock_Marble"
    },
    {
      "x": -29,
      "y": 4,
      "z": -20,
      "name": "Rock_Marble"
    },
    {
      "x": -29,
      "y": 5,
      "z": -20,
      "name": "Rock_Marble"
    },
    {
      "x": -29,
      "y": 6,
      "z": -20,
      "name": "Soil_Dirt_White"
    },
    {
      "x": -29,
      "y": 7,
      "z": -20,
      "name": "Soil_Dirt_White"
    },
    {
      "x": -29,
      "y": 8,
      "z": -20,
      "name": "Rock_Marble"
    },
    {
      "x": -29,
      "y": 9,
      "z": -20,
      "name": "Soil_Dirt_White"
    },
    {
      "x": -29,
      "y": 10,
      "z": -20,
      "name": "Soil_Grass_Full"
    },
    {
      "x": -29,
      "y": 0,
      "z": -19,
      "name": "Rock_Marble"
    },
    {
      "x": -29,
      "y": 1,
      "z": -19,
      "name": "Rock_Marble"
    },
    {
      "x": -29,
      "y": 2,
      "z": -19,
      "name": "Rock_Marble"
    },
    {
      "x": -29,
      "y": 3,
      "z": -19,
      "name": "Rock_Marble"
    },
    {
      "x": -29,
      "y": 4,
      "z": -19,
      "name": "Rock_Marble"
    },
    {
      "x": -29,
      "y": 5,
      "z": -19,
      "name": "Rock_Marble"
    },
    {
      "x": -29,
      "y": 6,
      "z": -19,
      "name": "Soil_Dirt_White"
    },
    {
      "x": -29,
      "y": 7,
      "z": -19,
      "name": "Soil_Dirt_White"
    },
    {
      "x": -29,
      "y": 8,
      "z": -19,
      "name": "Soil_Dirt_White"
    },
    {
      "x": -29,
      "y": 9,
      "z": -19,
      "name": "Rock_Marble"
    },
    {
      "x": -29,
      "y": 10,
      "z": -19,
      "name": "Soil_Dirt_White"
    },
    {
      "x": -29,
      "y": 11,
      "z": -19,
      "name": "Soil_Grass_Full"
    },
    {
      "x": -29,
      "y": 0,
      "z": -18,
      "name": "Rock_Marble"
    },
    {
      "x": -29,
      "y": 1,
      "z": -18,
      "name": "Rock_Marble"
    },
    {
      "x": -29,
      "y": 2,
      "z": -18,
      "name": "Rock_Marble"
    },
    {
      "x": -29,
      "y": 3,
      "z": -18,
      "name": "Rock_Marble"
    },
    {
      "x": -29,
      "y": 4,
      "z": -18,
      "name": "Rock_Marble"
    },
    {
      "x": -29,
      "y": 5,
      "z": -18,
      "name": "Rock_Marble"
    },
    {
      "x": -29,
      "y": 6,
      "z": -18,
      "name": "Soil_Dirt_White"
    },
    {
      "x": -29,
      "y": 7,
      "z": -18,
      "name": "Soil_Dirt_White"
    },
    {
      "x": -29,
      "y": 8,
      "z": -18,
      "name": "Soil_Dirt_White"
    },
    {
      "x": -29,
      "y": 9,
      "z": -18,
      "name": "Rock_Marble"
    },
    {
      "x": -29,
      "y": 10,
      "z": -18,
      "name": "Soil_Dirt_White"
    },
    {
      "x": -29,
      "y": 11,
      "z": -18,
      "name": "Soil_Grass_Full"
    },
    {
      "x": -29,
      "y": 0,
      "z": -17,
      "name": "Rock_Marble"
    },
    {
      "x": -29,
      "y": 1,
      "z": -17,
      "name": "Rock_Marble"
    },
    {
      "x": -29,
      "y": 2,
      "z": -17,
      "name": "Rock_Marble"
    },
    {
      "x": -29,
      "y": 3,
      "z": -17,
      "name": "Rock_Marble"
    },
    {
      "x": -29,
      "y": 4,
      "z": -17,
      "name": "Rock_Marble"
    },
    {
      "x": -29,
      "y": 5,
      "z": -17,
      "name": "Rock_Marble"
    },
    {
      "x": -29,
      "y": 6,
      "z": -17,
      "name": "Soil_Dirt_White"
    },
    {
      "x": -29,
      "y": 7,
      "z": -17,
      "name": "Soil_Dirt_White"
    },
    {
      "x": -29,
      "y": 8,
      "z": -17,
      "name": "Soil_Dirt_White"
    },
    {
      "x": -29,
      "y": 9,
      "z": -17,
      "name": "Rock_Marble"
    },
    {
      "x": -29,
      "y": 10,
      "z": -17,
      "name": "Soil_Dirt_White"
    },
    {
      "x": -29,
      "y": 11,
      "z": -17,
      "name": "Soil_Grass_Full"
    },
    {
      "x": -29,
      "y": 0,
      "z": -16,
      "name": "Rock_Marble"
    },
    {
      "x": -29,
      "y": 1,
      "z": -16,
      "name": "Rock_Marble"
    },
    {
      "x": -29,
      "y": 2,
      "z": -16,
      "name": "Rock_Marble"
    },
    {
      "x": -29,
      "y": 3,
      "z": -16,
      "name": "Rock_Marble"
    },
    {
      "x": -29,
      "y": 4,
      "z": -16,
      "name": "Rock_Marble"
    },
    {
      "x": -29,
      "y": 5,
      "z": -16,
      "name": "Rock_Marble"
    },
    {
      "x": -29,
      "y": 6,
      "z": -16,
      "name": "Soil_Dirt_White"
    },
    {
      "x": -29,
      "y": 7,
      "z": -16,
      "name": "Soil_Dirt_White"
    },
    {
      "x": -29,
      "y": 8,
      "z": -16,
      "name": "Soil_Dirt_White"
    },
    {
      "x": -29,
      "y": 9,
      "z": -16,
      "name": "Soil_Dirt_White"
    },
    {
      "x": -29,
      "y": 10,
      "z": -16,
      "name": "Soil_Dirt_White"
    },
    {
      "x": -29,
      "y": 11,
      "z": -16,
      "name": "Soil_Grass_Full"
    },
    {
      "x": -29,
      "y": 0,
      "z": -15,
      "name": "Rock_Marble"
    },
    {
      "x": -29,
      "y": 1,
      "z": -15,
      "name": "Rock_Marble"
    },
    {
      "x": -29,
      "y": 2,
      "z": -15,
      "name": "Rock_Marble"
    },
    {
      "x": -29,
      "y": 3,
      "z": -15,
      "name": "Rock_Marble"
    },
    {
      "x": -29,
      "y": 4,
      "z": -15,
      "name": "Rock_Marble"
    },
    {
      "x": -29,
      "y": 5,
      "z": -15,
      "name": "Rock_Marble"
    },
    {
      "x": -29,
      "y": 6,
      "z": -15,
      "name": "Soil_Dirt_White"
    },
    {
      "x": -29,
      "y": 7,
      "z": -15,
      "name": "Soil_Dirt_White"
    },
    {
      "x": -29,
      "y": 8,
      "z": -15,
      "name": "Soil_Dirt_White"
    },
    {
      "x": -29,
      "y": 9,
      "z": -15,
      "name": "Rock_Marble"
    },
    {
      "x": -29,
      "y": 10,
      "z": -15,
      "name": "Soil_Dirt_White"
    },
    {
      "x": -29,
      "y": 11,
      "z": -15,
      "name": "Soil_Grass_Full"
    },
    {
      "x": -29,
      "y": 0,
      "z": -14,
      "name": "Rock_Marble"
    },
    {
      "x": -29,
      "y": 1,
      "z": -14,
      "name": "Rock_Marble"
    },
    {
      "x": -29,
      "y": 2,
      "z": -14,
      "name": "Rock_Marble"
    },
    {
      "x": -29,
      "y": 3,
      "z": -14,
      "name": "Rock_Marble"
    },
    {
      "x": -29,
      "y": 4,
      "z": -14,
      "name": "Rock_Marble"
    },
    {
      "x": -29,
      "y": 5,
      "z": -14,
      "name": "Rock_Marble"
    },
    {
      "x": -29,
      "y": 6,
      "z": -14,
      "name": "Rock_Marble"
    },
    {
      "x": -29,
      "y": 7,
      "z": -14,
      "name": "Soil_Dirt_White"
    },
    {
      "x": -29,
      "y": 8,
      "z": -14,
      "name": "Soil_Dirt_White"
    },
    {
      "x": -29,
      "y": 9,
      "z": -14,
      "name": "Soil_Dirt_White"
    },
    {
      "x": -29,
      "y": 10,
      "z": -14,
      "name": "Rock_Marble"
    },
    {
      "x": -29,
      "y": 11,
      "z": -14,
      "name": "Soil_Dirt_White"
    },
    {
      "x": -29,
      "y": 12,
      "z": -14,
      "name": "Soil_Grass_Full"
    },
    {
      "x": -29,
      "y": 0,
      "z": -13,
      "name": "Rock_Marble"
    },
    {
      "x": -29,
      "y": 1,
      "z": -13,
      "name": "Rock_Marble"
    },
    {
      "x": -29,
      "y": 2,
      "z": -13,
      "name": "Rock_Marble"
    },
    {
      "x": -29,
      "y": 3,
      "z": -13,
      "name": "Rock_Marble"
    },
    {
      "x": -29,
      "y": 4,
      "z": -13,
      "name": "Rock_Marble"
    },
    {
      "x": -29,
      "y": 5,
      "z": -13,
      "name": "Rock_Marble"
    },
    {
      "x": -29,
      "y": 6,
      "z": -13,
      "name": "Rock_Marble"
    },
    {
      "x": -29,
      "y": 7,
      "z": -13,
      "name": "Soil_Dirt_White"
    },
    {
      "x": -29,
      "y": 8,
      "z": -13,
      "name": "Soil_Dirt_White"
    },
    {
      "x": -29,
      "y": 9,
      "z": -13,
      "name": "Soil_Dirt_White"
    },
    {
      "x": -29,
      "y": 10,
      "z": -13,
      "name": "Rock_Marble"
    },
    {
      "x": -29,
      "y": 11,
      "z": -13,
      "name": "Soil_Dirt_White"
    },
    {
      "x": -29,
      "y": 12,
      "z": -13,
      "name": "Soil_Grass_Full"
    },
    {
      "x": -29,
      "y": 0,
      "z": -12,
      "name": "Rock_Marble"
    },
    {
      "x": -29,
      "y": 1,
      "z": -12,
      "name": "Rock_Marble"
    },
    {
      "x": -29,
      "y": 2,
      "z": -12,
      "name": "Rock_Marble"
    },
    {
      "x": -29,
      "y": 3,
      "z": -12,
      "name": "Rock_Marble"
    },
    {
      "x": -29,
      "y": 4,
      "z": -12,
      "name": "Rock_Marble"
    },
    {
      "x": -29,
      "y": 5,
      "z": -12,
      "name": "Rock_Marble"
    },
    {
      "x": -29,
      "y": 6,
      "z": -12,
      "name": "Soil_Dirt_White"
    },
    {
      "x": -29,
      "y": 7,
      "z": -12,
      "name": "Soil_Dirt_White"
    },
    {
      "x": -29,
      "y": 8,
      "z": -12,
      "name": "Soil_Dirt_White"
    },
    {
      "x": -29,
      "y": 9,
      "z": -12,
      "name": "Soil_Dirt_White"
    },
    {
      "x": -29,
      "y": 10,
      "z": -12,
      "name": "Rock_Marble"
    },
    {
      "x": -29,
      "y": 11,
      "z": -12,
      "name": "Soil_Dirt_White"
    },
    {
      "x": -29,
      "y": 12,
      "z": -12,
      "name": "Soil_Grass_Full"
    },
    {
      "x": -29,
      "y": 0,
      "z": -11,
      "name": "Rock_Marble"
    },
    {
      "x": -29,
      "y": 1,
      "z": -11,
      "name": "Rock_Marble"
    },
    {
      "x": -29,
      "y": 2,
      "z": -11,
      "name": "Rock_Marble"
    },
    {
      "x": -29,
      "y": 3,
      "z": -11,
      "name": "Rock_Marble"
    },
    {
      "x": -29,
      "y": 4,
      "z": -11,
      "name": "Rock_Marble"
    },
    {
      "x": -29,
      "y": 5,
      "z": -11,
      "name": "Rock_Marble"
    },
    {
      "x": -29,
      "y": 6,
      "z": -11,
      "name": "Soil_Dirt_White"
    },
    {
      "x": -29,
      "y": 7,
      "z": -11,
      "name": "Soil_Dirt_White"
    },
    {
      "x": -29,
      "y": 8,
      "z": -11,
      "name": "Soil_Dirt_White"
    },
    {
      "x": -29,
      "y": 9,
      "z": -11,
      "name": "Soil_Dirt_White"
    },
    {
      "x": -29,
      "y": 10,
      "z": -11,
      "name": "Rock_Marble"
    },
    {
      "x": -29,
      "y": 11,
      "z": -11,
      "name": "Soil_Dirt_White"
    },
    {
      "x": -29,
      "y": 12,
      "z": -11,
      "name": "Soil_Grass_Full"
    },
    {
      "x": -29,
      "y": 0,
      "z": -10,
      "name": "Rock_Marble"
    },
    {
      "x": -29,
      "y": 1,
      "z": -10,
      "name": "Rock_Marble"
    },
    {
      "x": -29,
      "y": 2,
      "z": -10,
      "name": "Rock_Marble"
    },
    {
      "x": -29,
      "y": 3,
      "z": -10,
      "name": "Rock_Marble"
    },
    {
      "x": -29,
      "y": 4,
      "z": -10,
      "name": "Rock_Marble"
    },
    {
      "x": -29,
      "y": 5,
      "z": -10,
      "name": "Rock_Marble"
    },
    {
      "x": -29,
      "y": 6,
      "z": -10,
      "name": "Soil_Dirt_White"
    },
    {
      "x": -29,
      "y": 7,
      "z": -10,
      "name": "Soil_Dirt_White"
    },
    {
      "x": -29,
      "y": 8,
      "z": -10,
      "name": "Soil_Dirt_White"
    },
    {
      "x": -29,
      "y": 9,
      "z": -10,
      "name": "Soil_Dirt_White"
    },
    {
      "x": -29,
      "y": 10,
      "z": -10,
      "name": "Rock_Marble"
    },
    {
      "x": -29,
      "y": 11,
      "z": -10,
      "name": "Soil_Dirt_White"
    },
    {
      "x": -29,
      "y": 12,
      "z": -10,
      "name": "Soil_Grass_Full"
    },
    {
      "x": -29,
      "y": 0,
      "z": -9,
      "name": "Rock_Marble"
    },
    {
      "x": -29,
      "y": 1,
      "z": -9,
      "name": "Rock_Marble"
    },
    {
      "x": -29,
      "y": 2,
      "z": -9,
      "name": "Rock_Marble"
    },
    {
      "x": -29,
      "y": 3,
      "z": -9,
      "name": "Rock_Marble"
    },
    {
      "x": -29,
      "y": 4,
      "z": -9,
      "name": "Rock_Marble"
    },
    {
      "x": -29,
      "y": 5,
      "z": -9,
      "name": "Rock_Marble"
    },
    {
      "x": -29,
      "y": 6,
      "z": -9,
      "name": "Soil_Dirt_White"
    },
    {
      "x": -29,
      "y": 7,
      "z": -9,
      "name": "Soil_Dirt_White"
    },
    {
      "x": -29,
      "y": 8,
      "z": -9,
      "name": "Soil_Dirt_White"
    },
    {
      "x": -29,
      "y": 9,
      "z": -9,
      "name": "Soil_Dirt_White"
    },
    {
      "x": -29,
      "y": 10,
      "z": -9,
      "name": "Rock_Marble"
    },
    {
      "x": -29,
      "y": 11,
      "z": -9,
      "name": "Soil_Dirt_White"
    },
    {
      "x": -29,
      "y": 12,
      "z": -9,
      "name": "Soil_Grass_Full"
    },
    {
      "x": -29,
      "y": 0,
      "z": -8,
      "name": "Rock_Marble"
    },
    {
      "x": -29,
      "y": 1,
      "z": -8,
      "name": "Rock_Marble"
    },
    {
      "x": -29,
      "y": 2,
      "z": -8,
      "name": "Rock_Marble"
    },
    {
      "x": -29,
      "y": 3,
      "z": -8,
      "name": "Rock_Marble"
    },
    {
      "x": -29,
      "y": 4,
      "z": -8,
      "name": "Rock_Marble"
    },
    {
      "x": -29,
      "y": 5,
      "z": -8,
      "name": "Rock_Marble"
    },
    {
      "x": -29,
      "y": 6,
      "z": -8,
      "name": "Soil_Dirt_White"
    },
    {
      "x": -29,
      "y": 7,
      "z": -8,
      "name": "Soil_Dirt_White"
    },
    {
      "x": -29,
      "y": 8,
      "z": -8,
      "name": "Soil_Dirt_White"
    },
    {
      "x": -29,
      "y": 9,
      "z": -8,
      "name": "Rock_Marble"
    },
    {
      "x": -29,
      "y": 10,
      "z": -8,
      "name": "Soil_Dirt_White"
    },
    {
      "x": -29,
      "y": 11,
      "z": -8,
      "name": "Soil_Grass_Full"
    },
    {
      "x": -29,
      "y": 0,
      "z": -7,
      "name": "Rock_Marble"
    },
    {
      "x": -29,
      "y": 1,
      "z": -7,
      "name": "Rock_Marble"
    },
    {
      "x": -29,
      "y": 2,
      "z": -7,
      "name": "Rock_Marble"
    },
    {
      "x": -29,
      "y": 3,
      "z": -7,
      "name": "Rock_Marble"
    },
    {
      "x": -29,
      "y": 4,
      "z": -7,
      "name": "Rock_Marble"
    },
    {
      "x": -29,
      "y": 5,
      "z": -7,
      "name": "Soil_Dirt_White"
    },
    {
      "x": -29,
      "y": 6,
      "z": -7,
      "name": "Soil_Dirt_White"
    },
    {
      "x": -29,
      "y": 7,
      "z": -7,
      "name": "Soil_Dirt_White"
    },
    {
      "x": -29,
      "y": 8,
      "z": -7,
      "name": "Soil_Dirt_White"
    },
    {
      "x": -29,
      "y": 9,
      "z": -7,
      "name": "Rock_Marble"
    },
    {
      "x": -29,
      "y": 10,
      "z": -7,
      "name": "Soil_Dirt_White"
    },
    {
      "x": -29,
      "y": 11,
      "z": -7,
      "name": "Soil_Grass_Full"
    },
    {
      "x": -29,
      "y": 0,
      "z": -6,
      "name": "Rock_Marble"
    },
    {
      "x": -29,
      "y": 1,
      "z": -6,
      "name": "Rock_Marble"
    },
    {
      "x": -29,
      "y": 2,
      "z": -6,
      "name": "Rock_Marble"
    },
    {
      "x": -29,
      "y": 3,
      "z": -6,
      "name": "Rock_Marble"
    },
    {
      "x": -29,
      "y": 4,
      "z": -6,
      "name": "Rock_Marble"
    },
    {
      "x": -29,
      "y": 5,
      "z": -6,
      "name": "Soil_Dirt_White"
    },
    {
      "x": -29,
      "y": 6,
      "z": -6,
      "name": "Soil_Dirt_White"
    },
    {
      "x": -29,
      "y": 7,
      "z": -6,
      "name": "Soil_Dirt_White"
    },
    {
      "x": -29,
      "y": 8,
      "z": -6,
      "name": "Soil_Dirt_White"
    },
    {
      "x": -29,
      "y": 9,
      "z": -6,
      "name": "Rock_Marble"
    },
    {
      "x": -29,
      "y": 10,
      "z": -6,
      "name": "Soil_Dirt_White"
    },
    {
      "x": -29,
      "y": 11,
      "z": -6,
      "name": "Soil_Grass_Full"
    },
    {
      "x": -29,
      "y": 0,
      "z": -5,
      "name": "Rock_Marble"
    },
    {
      "x": -29,
      "y": 1,
      "z": -5,
      "name": "Rock_Marble"
    },
    {
      "x": -29,
      "y": 2,
      "z": -5,
      "name": "Rock_Marble"
    },
    {
      "x": -29,
      "y": 3,
      "z": -5,
      "name": "Rock_Marble"
    },
    {
      "x": -29,
      "y": 4,
      "z": -5,
      "name": "Rock_Marble"
    },
    {
      "x": -29,
      "y": 5,
      "z": -5,
      "name": "Soil_Dirt_White"
    },
    {
      "x": -29,
      "y": 6,
      "z": -5,
      "name": "Soil_Dirt_White"
    },
    {
      "x": -29,
      "y": 7,
      "z": -5,
      "name": "Soil_Dirt_White"
    },
    {
      "x": -29,
      "y": 8,
      "z": -5,
      "name": "Rock_Marble"
    },
    {
      "x": -29,
      "y": 9,
      "z": -5,
      "name": "Soil_Dirt_White"
    },
    {
      "x": -29,
      "y": 10,
      "z": -5,
      "name": "Soil_Grass_Full"
    },
    {
      "x": -29,
      "y": 0,
      "z": -4,
      "name": "Rock_Marble"
    },
    {
      "x": -29,
      "y": 1,
      "z": -4,
      "name": "Rock_Marble"
    },
    {
      "x": -29,
      "y": 2,
      "z": -4,
      "name": "Rock_Marble"
    },
    {
      "x": -29,
      "y": 3,
      "z": -4,
      "name": "Rock_Marble"
    },
    {
      "x": -29,
      "y": 4,
      "z": -4,
      "name": "Rock_Marble"
    },
    {
      "x": -29,
      "y": 5,
      "z": -4,
      "name": "Rock_Marble"
    },
    {
      "x": -29,
      "y": 6,
      "z": -4,
      "name": "Soil_Dirt_White"
    },
    {
      "x": -29,
      "y": 7,
      "z": -4,
      "name": "Soil_Dirt_White"
    },
    {
      "x": -29,
      "y": 8,
      "z": -4,
      "name": "Rock_Marble"
    },
    {
      "x": -29,
      "y": 9,
      "z": -4,
      "name": "Soil_Dirt_White"
    },
    {
      "x": -29,
      "y": 10,
      "z": -4,
      "name": "Soil_Grass_Full"
    },
    {
      "x": -29,
      "y": 0,
      "z": -3,
      "name": "Rock_Marble"
    },
    {
      "x": -29,
      "y": 1,
      "z": -3,
      "name": "Rock_Marble"
    },
    {
      "x": -29,
      "y": 2,
      "z": -3,
      "name": "Rock_Marble"
    },
    {
      "x": -29,
      "y": 3,
      "z": -3,
      "name": "Rock_Marble"
    },
    {
      "x": -29,
      "y": 4,
      "z": -3,
      "name": "Rock_Marble"
    },
    {
      "x": -29,
      "y": 5,
      "z": -3,
      "name": "Rock_Marble"
    },
    {
      "x": -29,
      "y": 6,
      "z": -3,
      "name": "Soil_Dirt_White"
    },
    {
      "x": -29,
      "y": 7,
      "z": -3,
      "name": "Soil_Dirt_White"
    },
    {
      "x": -29,
      "y": 8,
      "z": -3,
      "name": "Rock_Marble"
    },
    {
      "x": -29,
      "y": 9,
      "z": -3,
      "name": "Soil_Dirt_White"
    },
    {
      "x": -29,
      "y": 10,
      "z": -3,
      "name": "Soil_Grass_Full"
    },
    {
      "x": -29,
      "y": 0,
      "z": -2,
      "name": "Rock_Marble"
    },
    {
      "x": -29,
      "y": 1,
      "z": -2,
      "name": "Rock_Marble"
    },
    {
      "x": -29,
      "y": 2,
      "z": -2,
      "name": "Rock_Marble"
    },
    {
      "x": -29,
      "y": 3,
      "z": -2,
      "name": "Rock_Marble"
    },
    {
      "x": -29,
      "y": 4,
      "z": -2,
      "name": "Rock_Marble"
    },
    {
      "x": -29,
      "y": 5,
      "z": -2,
      "name": "Rock_Marble"
    },
    {
      "x": -29,
      "y": 6,
      "z": -2,
      "name": "Soil_Dirt_White"
    },
    {
      "x": -29,
      "y": 7,
      "z": -2,
      "name": "Soil_Dirt_White"
    },
    {
      "x": -29,
      "y": 8,
      "z": -2,
      "name": "Soil_Dirt_White"
    },
    {
      "x": -29,
      "y": 9,
      "z": -2,
      "name": "Soil_Grass_Full"
    },
    {
      "x": -29,
      "y": 0,
      "z": -1,
      "name": "Rock_Marble"
    },
    {
      "x": -29,
      "y": 1,
      "z": -1,
      "name": "Rock_Marble"
    },
    {
      "x": -29,
      "y": 2,
      "z": -1,
      "name": "Rock_Marble"
    },
    {
      "x": -29,
      "y": 3,
      "z": -1,
      "name": "Rock_Marble"
    },
    {
      "x": -29,
      "y": 4,
      "z": -1,
      "name": "Rock_Marble"
    },
    {
      "x": -29,
      "y": 5,
      "z": -1,
      "name": "Rock_Marble"
    },
    {
      "x": -29,
      "y": 6,
      "z": -1,
      "name": "Soil_Dirt_White"
    },
    {
      "x": -29,
      "y": 7,
      "z": -1,
      "name": "Soil_Dirt_White"
    },
    {
      "x": -29,
      "y": 8,
      "z": -1,
      "name": "Soil_Dirt_White"
    },
    {
      "x": -29,
      "y": 9,
      "z": -1,
      "name": "Soil_Grass_Full"
    },
    {
      "x": -29,
      "y": 0,
      "z": 0,
      "name": "Rock_Marble"
    },
    {
      "x": -29,
      "y": 1,
      "z": 0,
      "name": "Rock_Marble"
    },
    {
      "x": -29,
      "y": 2,
      "z": 0,
      "name": "Rock_Marble"
    },
    {
      "x": -29,
      "y": 3,
      "z": 0,
      "name": "Rock_Marble"
    },
    {
      "x": -29,
      "y": 4,
      "z": 0,
      "name": "Rock_Marble"
    },
    {
      "x": -29,
      "y": 5,
      "z": 0,
      "name": "Rock_Marble"
    },
    {
      "x": -29,
      "y": 6,
      "z": 0,
      "name": "Rock_Marble"
    },
    {
      "x": -29,
      "y": 7,
      "z": 0,
      "name": "Soil_Dirt_White"
    },
    {
      "x": -29,
      "y": 8,
      "z": 0,
      "name": "Soil_Dirt_White"
    },
    {
      "x": -29,
      "y": 9,
      "z": 0,
      "name": "Soil_Grass_Full"
    },
    {
      "x": -29,
      "y": 0,
      "z": 1,
      "name": "Rock_Marble"
    },
    {
      "x": -29,
      "y": 1,
      "z": 1,
      "name": "Rock_Marble"
    },
    {
      "x": -29,
      "y": 2,
      "z": 1,
      "name": "Rock_Marble"
    },
    {
      "x": -29,
      "y": 3,
      "z": 1,
      "name": "Rock_Marble"
    },
    {
      "x": -29,
      "y": 4,
      "z": 1,
      "name": "Rock_Marble"
    },
    {
      "x": -29,
      "y": 5,
      "z": 1,
      "name": "Rock_Marble"
    },
    {
      "x": -29,
      "y": 6,
      "z": 1,
      "name": "Rock_Marble"
    },
    {
      "x": -29,
      "y": 7,
      "z": 1,
      "name": "Soil_Dirt_White"
    },
    {
      "x": -29,
      "y": 8,
      "z": 1,
      "name": "Soil_Dirt_White"
    },
    {
      "x": -29,
      "y": 9,
      "z": 1,
      "name": "Soil_Grass_White"
    },
    {
      "x": -29,
      "y": 0,
      "z": 2,
      "name": "Rock_Marble"
    },
    {
      "x": -29,
      "y": 1,
      "z": 2,
      "name": "Rock_Marble"
    },
    {
      "x": -29,
      "y": 2,
      "z": 2,
      "name": "Rock_Marble"
    },
    {
      "x": -29,
      "y": 3,
      "z": 2,
      "name": "Rock_Marble"
    },
    {
      "x": -29,
      "y": 4,
      "z": 2,
      "name": "Rock_Marble"
    },
    {
      "x": -29,
      "y": 5,
      "z": 2,
      "name": "Rock_Marble"
    },
    {
      "x": -29,
      "y": 6,
      "z": 2,
      "name": "Soil_Dirt_White"
    },
    {
      "x": -29,
      "y": 7,
      "z": 2,
      "name": "Soil_Dirt_White"
    },
    {
      "x": -29,
      "y": 8,
      "z": 2,
      "name": "Soil_Dirt_White"
    },
    {
      "x": -29,
      "y": 9,
      "z": 2,
      "name": "Soil_Grass_White"
    },
    {
      "x": -29,
      "y": 0,
      "z": 3,
      "name": "Rock_Marble"
    },
    {
      "x": -29,
      "y": 1,
      "z": 3,
      "name": "Rock_Marble"
    },
    {
      "x": -29,
      "y": 2,
      "z": 3,
      "name": "Rock_Marble"
    },
    {
      "x": -29,
      "y": 3,
      "z": 3,
      "name": "Rock_Marble"
    },
    {
      "x": -29,
      "y": 4,
      "z": 3,
      "name": "Rock_Marble"
    },
    {
      "x": -29,
      "y": 5,
      "z": 3,
      "name": "Rock_Marble"
    },
    {
      "x": -29,
      "y": 6,
      "z": 3,
      "name": "Soil_Dirt_White"
    },
    {
      "x": -29,
      "y": 7,
      "z": 3,
      "name": "Soil_Dirt_White"
    },
    {
      "x": -29,
      "y": 8,
      "z": 3,
      "name": "Soil_Dirt_White"
    },
    {
      "x": -29,
      "y": 9,
      "z": 3,
      "name": "Soil_Grass_White"
    },
    {
      "x": -29,
      "y": 0,
      "z": 4,
      "name": "Rock_Marble"
    },
    {
      "x": -29,
      "y": 1,
      "z": 4,
      "name": "Rock_Marble"
    },
    {
      "x": -29,
      "y": 2,
      "z": 4,
      "name": "Rock_Marble"
    },
    {
      "x": -29,
      "y": 3,
      "z": 4,
      "name": "Rock_Marble"
    },
    {
      "x": -29,
      "y": 4,
      "z": 4,
      "name": "Rock_Marble"
    },
    {
      "x": -29,
      "y": 5,
      "z": 4,
      "name": "Rock_Marble"
    },
    {
      "x": -29,
      "y": 6,
      "z": 4,
      "name": "Soil_Dirt_White"
    },
    {
      "x": -29,
      "y": 7,
      "z": 4,
      "name": "Soil_Dirt_White"
    },
    {
      "x": -29,
      "y": 8,
      "z": 4,
      "name": "Soil_Dirt_White"
    },
    {
      "x": -29,
      "y": 9,
      "z": 4,
      "name": "Soil_Dirt_White"
    },
    {
      "x": -29,
      "y": 10,
      "z": 4,
      "name": "Soil_Grass_White"
    },
    {
      "x": -29,
      "y": 0,
      "z": 5,
      "name": "Rock_Marble"
    },
    {
      "x": -29,
      "y": 1,
      "z": 5,
      "name": "Rock_Marble"
    },
    {
      "x": -29,
      "y": 2,
      "z": 5,
      "name": "Rock_Marble"
    },
    {
      "x": -29,
      "y": 3,
      "z": 5,
      "name": "Rock_Marble"
    },
    {
      "x": -29,
      "y": 4,
      "z": 5,
      "name": "Rock_Marble"
    },
    {
      "x": -29,
      "y": 5,
      "z": 5,
      "name": "Rock_Marble"
    },
    {
      "x": -29,
      "y": 6,
      "z": 5,
      "name": "Soil_Dirt_White"
    },
    {
      "x": -29,
      "y": 7,
      "z": 5,
      "name": "Soil_Dirt_White"
    },
    {
      "x": -29,
      "y": 8,
      "z": 5,
      "name": "Soil_Dirt_White"
    },
    {
      "x": -29,
      "y": 9,
      "z": 5,
      "name": "Soil_Dirt_White"
    },
    {
      "x": -29,
      "y": 10,
      "z": 5,
      "name": "Soil_Grass_White"
    },
    {
      "x": -29,
      "y": 0,
      "z": 6,
      "name": "Rock_Marble"
    },
    {
      "x": -29,
      "y": 1,
      "z": 6,
      "name": "Rock_Marble"
    },
    {
      "x": -29,
      "y": 2,
      "z": 6,
      "name": "Rock_Marble"
    },
    {
      "x": -29,
      "y": 3,
      "z": 6,
      "name": "Rock_Marble"
    },
    {
      "x": -29,
      "y": 4,
      "z": 6,
      "name": "Rock_Marble"
    },
    {
      "x": -29,
      "y": 5,
      "z": 6,
      "name": "Rock_Marble"
    },
    {
      "x": -29,
      "y": 6,
      "z": 6,
      "name": "Soil_Dirt_White"
    },
    {
      "x": -29,
      "y": 7,
      "z": 6,
      "name": "Soil_Dirt_White"
    },
    {
      "x": -29,
      "y": 8,
      "z": 6,
      "name": "Soil_Dirt_White"
    },
    {
      "x": -29,
      "y": 9,
      "z": 6,
      "name": "Soil_Dirt_White"
    },
    {
      "x": -29,
      "y": 10,
      "z": 6,
      "name": "Soil_Grass_Full"
    },
    {
      "x": -29,
      "y": 0,
      "z": 7,
      "name": "Rock_Marble"
    },
    {
      "x": -29,
      "y": 1,
      "z": 7,
      "name": "Rock_Marble"
    },
    {
      "x": -29,
      "y": 2,
      "z": 7,
      "name": "Rock_Marble"
    },
    {
      "x": -29,
      "y": 3,
      "z": 7,
      "name": "Rock_Marble"
    },
    {
      "x": -29,
      "y": 4,
      "z": 7,
      "name": "Rock_Marble"
    },
    {
      "x": -29,
      "y": 5,
      "z": 7,
      "name": "Rock_Marble"
    },
    {
      "x": -29,
      "y": 6,
      "z": 7,
      "name": "Soil_Dirt_White"
    },
    {
      "x": -29,
      "y": 7,
