{
  "version": 8,
  "blockIdVersion": 11,
  "anchorX": 0,
  "anchorY": 0,
  "anchorZ": 0,
  "blocks": [
    {
      "x": -8,
      "y": 28,
      "z": -1,
      "name": "Plant_Leaves_Redwood"
    },
    {
      "x": -8,
      "y": 28,
      "z": 0,
      "name": "Plant_Leaves_Redwood"
    },
    {
      "x": -8,
      "y": 29,
      "z": 0,
      "name": "Plant_Leaves_Redwood"
    },
    {
      "x": -7,
      "y": 28,
      "z": -2,
      "name": "Plant_Leaves_Redwood"
    },
    {
      "x": -7,
      "y": 34,
      "z": -2,
      "name": "Plant_Leaves_Redwood",
      "support": 15
    },
    {
      "x": -7,
      "y": 35,
      "z": -2,
      "name": "Plant_Leaves_Redwood",
      "support": 15
    },
    {
      "x": -7,
      "y": 36,
      "z": -2,
      "name": "Plant_Leaves_Redwood",
      "support": 15
    },
    {
      "x": -7,
      "y": 37,
      "z": -2,
      "name": "Plant_Leaves_Redwood",
      "support": 15
    },
    {
      "x": -7,
      "y": 45,
      "z": -2,
      "name": "Plant_Leaves_Redwood"
    },
    {
      "x": -7,
      "y": 26,
      "z": -1,
      "name": "Plant_Leaves_Redwood",
      "support": 15
    },
    {
      "x": -7,
      "y": 27,
      "z": -1,
      "name": "Plant_Leaves_Redwood",
      "support": 15
    },
    {
      "x": -7,
      "y": 28,
      "z": -1,
      "name": "Plant_Leaves_Redwood",
      "support": 15
    },
    {
      "x": -7,
      "y": 29,
      "z": -1,
      "name": "Plant_Leaves_Redwood",
      "support": 15
    },
    {
      "x": -7,
      "y": 34,
      "z": -1,
      "name": "Plant_Leaves_Redwood",
      "support": 15
    },
    {
      "x": -7,
      "y": 45,
      "z": -1,
      "name": "Plant_Leaves_Redwood"
    },
    {
      "x": -7,
      "y": 46,
      "z": -1,
      "name": "Plant_Leaves_Redwood"
    },
    {
      "x": -7,
      "y": 26,
      "z": 0,
      "name": "Plant_Leaves_Redwood",
      "support": 15
    },
    {
      "x": -7,
      "y": 27,
      "z": 0,
      "name": "Plant_Leaves_Redwood"
    },
    {
      "x": -7,
      "y": 29,
      "z": 0,
      "name": "Plant_Leaves_Redwood"
    },
    {
      "x": -7,
      "y": 30,
      "z": 0,
      "name": "Plant_Leaves_Redwood"
    },
    {
      "x": -7,
      "y": 43,
      "z": 0,
      "name": "Plant_Leaves_Redwood",
      "support": 15
    },
    {
      "x": -7,
      "y": 44,
      "z": 0,
      "name": "Plant_Leaves_Redwood",
      "support": 15
    },
    {
      "x": -7,
      "y": 45,
      "z": 0,
      "name": "Plant_Leaves_Redwood",
      "support": 15
    },
    {
      "x": -7,
      "y": 46,
      "z": 0,
      "name": "Plant_Leaves_Redwood",
      "support": 15
    },
    {
      "x": -7,
      "y": 28,
      "z": 1,
      "name": "Plant_Leaves_Redwood"
    },
    {
      "x": -7,
      "y": 29,
      "z": 1,
      "name": "Plant_Leaves_Redwood"
    },
    {
      "x": -7,
      "y": 43,
      "z": 1,
      "name": "Plant_Leaves_Redwood",
      "support": 15
    },
    {
      "x": -6,
      "y": 34,
      "z": -3,
      "name": "Plant_Leaves_Redwood",
      "support": 15
    },
    {
      "x": -6,
      "y": 35,
      "z": -3,
      "name": "Plant_Leaves_Redwood",
      "support": 15
    },
    {
      "x": -6,
      "y": 36,
      "z": -3,
      "name": "Plant_Leaves_Redwood",
      "support": 15
    },
    {
      "x": -6,
      "y": 26,
      "z": -2,
      "name": "Plant_Leaves_Redwood",
      "support": 15
    },
    {
      "x": -6,
      "y": 27,
      "z": -2,
      "name": "Plant_Leaves_Redwood",
      "support": 15
    },
    {
      "x": -6,
      "y": 28,
      "z": -2,
      "name": "Plant_Leaves_Redwood",
      "support": 15
    },
    {
      "x": -6,
      "y": 34,
      "z": -2,
      "name": "Wood_Redwood_Branch_Long",
      "support": 15,
      "rotation": 5
    },
    {
      "x": -6,
      "y": 35,
      "z": -2,
      "name": "Plant_Leaves_Redwood",
      "support": 15
    },
    {
      "x": -6,
      "y": 36,
      "z": -2,
      "name": "Plant_Leaves_Redwood",
      "support": 15
    },
    {
      "x": -6,
      "y": 44,
      "z": -2,
      "name": "Plant_Leaves_Redwood"
    },
    {
      "x": -6,
      "y": 45,
      "z": -2,
      "name": "Plant_Leaves_Redwood"
    },
    {
      "x": -6,
      "y": 46,
      "z": -2,
      "name": "Plant_Leaves_Redwood"
    },
    {
      "x": -6,
      "y": 57,
      "z": -2,
      "name": "Plant_Leaves_Redwood"
    },
    {
      "x": -6,
      "y": 59,
      "z": -2,
      "name": "Plant_Leaves_Redwood"
    },
    {
      "x": -6,
      "y": 26,
      "z": -1,
      "name": "Wood_Redwood_Branch_Long",
      "support": 15,
      "rotation": 5
    },
    {
      "x": -6,
      "y": 27,
      "z": -1,
      "name": "Plant_Leaves_Redwood",
      "support": 15
    },
    {
      "x": -6,
      "y": 28,
      "z": -1,
      "name": "Plant_Leaves_Redwood",
      "support": 15
    },
    {
      "x": -6,
      "y": 34,
      "z": -1,
      "name": "Plant_Leaves_Redwood",
      "support": 15
    },
    {
      "x": -6,
      "y": 35,
      "z": -1,
      "name": "Plant_Leaves_Redwood",
      "support": 15
    },
    {
      "x": -6,
      "y": 36,
      "z": -1,
      "name": "Plant_Leaves_Redwood",
      "support": 15
    },
    {
      "x": -6,
      "y": 39,
      "z": -1,
      "name": "Plant_Leaves_Redwood"
    },
    {
      "x": -6,
      "y": 43,
      "z": -1,
      "name": "Plant_Leaves_Redwood",
      "support": 15
    },
    {
      "x": -6,
      "y": 44,
      "z": -1,
      "name": "Plant_Leaves_Redwood",
      "support": 15
    },
    {
      "x": -6,
      "y": 45,
      "z": -1,
      "name": "Plant_Leaves_Redwood",
      "support": 15
    },
    {
      "x": -6,
      "y": 46,
      "z": -1,
      "name": "Plant_Leaves_Redwood"
    },
    {
      "x": -6,
      "y": 47,
      "z": -1,
      "name": "Plant_Leaves_Redwood"
    },
    {
      "x": -6,
      "y": 56,
      "z": -1,
      "name": "Plant_Leaves_Redwood",
      "support": 15
    },
    {
      "x": -6,
      "y": 57,
      "z": -1,
      "name": "Plant_Leaves_Redwood",
      "support": 15
    },
    {
      "x": -6,
      "y": 58,
      "z": -1,
      "name": "Plant_Leaves_Redwood",
      "support": 15
    },
    {
      "x": -6,
      "y": 59,
      "z": -1,
      "name": "Plant_Leaves_Redwood",
      "support": 15
    },
    {
      "x": -6,
      "y": 26,
      "z": 0,
      "name": "Plant_Leaves_Redwood",
      "support": 15
    },
    {
      "x": -6,
      "y": 27,
      "z": 0,
      "name": "Plant_Leaves_Redwood",
      "support": 15
    },
    {
      "x": -6,
      "y": 28,
      "z": 0,
      "name": "Plant_Leaves_Redwood",
      "support": 15
    },
    {
      "x": -6,
      "y": 29,
      "z": 0,
      "name": "Plant_Leaves_Redwood"
    },
    {
      "x": -6,
      "y": 30,
      "z": 0,
      "name": "Plant_Leaves_Redwood"
    },
    {
      "x": -6,
      "y": 38,
      "z": 0,
      "name": "Plant_Leaves_Redwood"
    },
    {
      "x": -6,
      "y": 39,
      "z": 0,
      "name": "Plant_Leaves_Redwood"
    },
    {
      "x": -6,
      "y": 40,
      "z": 0,
      "name": "Plant_Leaves_Redwood"
    },
    {
      "x": -6,
      "y": 43,
      "z": 0,
      "name": "Wood_Redwood_Branch_Long",
      "support": 15,
      "rotation": 5
    },
    {
      "x": -6,
      "y": 44,
      "z": 0,
      "name": "Plant_Leaves_Redwood",
      "support": 15
    },
    {
      "x": -6,
      "y": 45,
      "z": 0,
      "name": "Plant_Leaves_Redwood",
      "support": 15
    },
    {
      "x": -6,
      "y": 46,
      "z": 0,
      "name": "Plant_Leaves_Redwood"
    },
    {
      "x": -6,
      "y": 56,
      "z": 0,
      "name": "Plant_Leaves_Redwood",
      "support": 15
    },
    {
      "x": -6,
      "y": 26,
      "z": 1,
      "name": "Plant_Leaves_Redwood"
    },
    {
      "x": -6,
      "y": 27,
      "z": 1,
      "name": "Plant_Leaves_Redwood"
    },
    {
      "x": -6,
      "y": 28,
      "z": 1,
      "name": "Plant_Leaves_Redwood"
    },
    {
      "x": -6,
      "y": 29,
      "z": 1,
      "name": "Plant_Leaves_Redwood"
    },
    {
      "x": -6,
      "y": 43,
      "z": 1,
      "name": "Plant_Leaves_Redwood",
      "support": 15
    },
    {
      "x": -6,
      "y": 44,
      "z": 1,
      "name": "Plant_Leaves_Redwood",
      "support": 15
    },
    {
      "x": -6,
      "y": 45,
      "z": 1,
      "name": "Plant_Leaves_Redwood",
      "support": 15
    },
    {
      "x": -6,
      "y": 27,
      "z": 2,
      "name": "Plant_Leaves_Redwood"
    },
    {
      "x": -6,
      "y": 28,
      "z": 2,
      "name": "Plant_Leaves_Redwood"
    },
    {
      "x": -6,
      "y": 29,
      "z": 2,
      "name": "Plant_Leaves_Redwood"
    },
    {
      "x": -5,
      "y": 27,
      "z": -4,
      "name": "Plant_Leaves_Redwood"
    },
    {
      "x": -5,
      "y": 34,
      "z": -4,
      "name": "Plant_Leaves_Redwood",
      "support": 15
    },
    {
      "x": -5,
      "y": 58,
      "z": -4,
      "name": "Plant_Leaves_Redwood"
    },
    {
      "x": -5,
      "y": 26,
      "z": -3,
      "name": "Plant_Leaves_Redwood",
      "support": 15
    },
    {
      "x": -5,
      "y": 27,
      "z": -3,
      "name": "Plant_Leaves_Redwood"
    },
    {
      "x": -5,
      "y": 28,
      "z": -3,
      "name": "Plant_Leaves_Redwood"
    },
    {
      "x": -5,
      "y": 34,
      "z": -3,
      "name": "Wood_Redwood_Branch_Long",
      "support": 15,
      "rotation": 5
    },
    {
      "x": -5,
      "y": 35,
      "z": -3,
      "name": "Plant_Leaves_Redwood",
      "support": 15
    },
    {
      "x": -5,
      "y": 36,
      "z": -3,
      "name": "Plant_Leaves_Redwood",
      "support": 15
    },
    {
      "x": -5,
      "y": 46,
      "z": -3,
      "name": "Plant_Leaves_Redwood"
    },
    {
      "x": -5,
      "y": 57,
      "z": -3,
      "name": "Plant_Leaves_Redwood"
    },
    {
      "x": -5,
      "y": 58,
      "z": -3,
      "name": "Plant_Leaves_Redwood"
    },
    {
      "x": -5,
      "y": 25,
      "z": -2,
      "name": "Plant_Leaves_Redwood"
    },
    {
      "x": -5,
      "y": 26,
      "z": -2,
      "name": "Wood_Redwood_Branch_Long",
      "support": 15,
      "rotation": 5
    },
    {
      "x": -5,
      "y": 27,
      "z": -2,
      "name": "Plant_Leaves_Redwood",
      "support": 15
    },
    {
      "x": -5,
      "y": 28,
      "z": -2,
      "name": "Plant_Leaves_Redwood",
      "support": 15
    },
    {
      "x": -5,
      "y": 34,
      "z": -2,
      "name": "Wood_Redwood_Branch_Long",
      "support": 15,
      "rotation": 5
    },
    {
      "x": -5,
      "y": 35,
      "z": -2,
      "name": "Plant_Leaves_Redwood",
      "support": 15
    },
    {
      "x": -5,
      "y": 36,
      "z": -2,
      "name": "Plant_Leaves_Redwood",
      "support": 15
    },
    {
      "x": -5,
      "y": 37,
      "z": -2,
      "name": "Plant_Leaves_Redwood",
      "support": 15
    },
    {
      "x": -5,
      "y": 39,
      "z": -2,
      "name": "Plant_Leaves_Redwood"
    },
    {
      "x": -5,
      "y": 43,
      "z": -2,
      "name": "Plant_Leaves_Redwood",
      "support": 15
    },
    {
      "x": -5,
      "y": 45,
      "z": -2,
      "name": "Plant_Leaves_Redwood"
    },
    {
      "x": -5,
      "y": 47,
      "z": -2,
      "name": "Plant_Leaves_Redwood"
    },
    {
      "x": -5,
      "y": 56,
      "z": -2,
      "name": "Plant_Leaves_Redwood",
      "support": 15
    },
    {
      "x": -5,
      "y": 57,
      "z": -2,
      "name": "Plant_Leaves_Redwood",
      "support": 15
    },
    {
      "x": -5,
      "y": 58,
      "z": -2,
      "name": "Plant_Leaves_Redwood",
      "support": 15
    },
    {
      "x": -5,
      "y": 59,
      "z": -2,
      "name": "Plant_Leaves_Redwood"
    },
    {
      "x": -5,
      "y": 26,
      "z": -1,
      "name": "Wood_Redwood_Branch_Long",
      "support": 15,
      "rotation": 5
    },
    {
      "x": -5,
      "y": 27,
      "z": -1,
      "name": "Plant_Leaves_Redwood",
      "support": 15
    },
    {
      "x": -5,
      "y": 28,
      "z": -1,
      "name": "Plant_Leaves_Redwood",
      "support": 15
    },
    {
      "x": -5,
      "y": 29,
      "z": -1,
      "name": "Plant_Leaves_Redwood",
      "support": 15
    },
    {
      "x": -5,
      "y": 34,
      "z": -1,
      "name": "Plant_Leaves_Redwood",
      "support": 15
    },
    {
      "x": -5,
      "y": 35,
      "z": -1,
      "name": "Plant_Leaves_Redwood",
      "support": 15
    },
    {
      "x": -5,
      "y": 36,
      "z": -1,
      "name": "Plant_Leaves_Redwood",
      "support": 15
    },
    {
      "x": -5,
      "y": 39,
      "z": -1,
      "name": "Plant_Leaves_Redwood"
    },
    {
      "x": -5,
      "y": 40,
      "z": -1,
      "name": "Plant_Leaves_Redwood"
    },
    {
      "x": -5,
      "y": 43,
      "z": -1,
      "name": "Wood_Redwood_Branch_Long",
      "support": 15,
      "rotation": 5
    },
    {
      "x": -5,
      "y": 44,
      "z": -1,
      "name": "Plant_Leaves_Redwood",
      "support": 15
    },
    {
      "x": -5,
      "y": 45,
      "z": -1,
      "name": "Plant_Leaves_Redwood",
      "support": 15
    },
    {
      "x": -5,
      "y": 46,
      "z": -1,
      "name": "Plant_Leaves_Redwood"
    },
    {
      "x": -5,
      "y": 56,
      "z": -1,
      "name": "Wood_Redwood_Branch_Long",
      "support": 15,
      "rotation": 5
    },
    {
      "x": -5,
      "y": 57,
      "z": -1,
      "name": "Plant_Leaves_Redwood",
      "support": 15
    },
    {
      "x": -5,
      "y": 58,
      "z": -1,
      "name": "Plant_Leaves_Redwood",
      "support": 15
    },
    {
      "x": -5,
      "y": 26,
      "z": 0,
      "name": "Plant_Leaves_Redwood",
      "support": 15
    },
    {
      "x": -5,
      "y": 27,
      "z": 0,
      "name": "Plant_Leaves_Redwood",
      "support": 15
    },
    {
      "x": -5,
      "y": 28,
      "z": 0,
      "name": "Plant_Leaves_Redwood",
      "support": 15
    },
    {
      "x": -5,
      "y": 37,
      "z": 0,
      "name": "Plant_Leaves_Redwood"
    },
    {
      "x": -5,
      "y": 38,
      "z": 0,
      "name": "Plant_Leaves_Redwood"
    },
    {
      "x": -5,
      "y": 39,
      "z": 0,
      "name": "Plant_Leaves_Redwood"
    },
    {
      "x": -5,
      "y": 40,
      "z": 0,
      "name": "Plant_Leaves_Redwood"
    },
    {
      "x": -5,
      "y": 43,
      "z": 0,
      "name": "Wood_Redwood_Branch_Long",
      "support": 15,
      "rotation": 5
    },
    {
      "x": -5,
      "y": 44,
      "z": 0,
      "name": "Plant_Leaves_Redwood",
      "support": 15
    },
    {
      "x": -5,
      "y": 45,
      "z": 0,
      "name": "Plant_Leaves_Redwood",
      "support": 15
    },
    {
      "x": -5,
      "y": 46,
      "z": 0,
      "name": "Plant_Leaves_Redwood",
      "support": 15
    },
    {
      "x": -5,
      "y": 56,
      "z": 0,
      "name": "Plant_Leaves_Redwood",
      "support": 15
    },
    {
      "x": -5,
      "y": 57,
      "z": 0,
      "name": "Plant_Leaves_Redwood",
      "support": 15
    },
    {
      "x": -5,
      "y": 58,
      "z": 0,
      "name": "Plant_Leaves_Redwood",
      "support": 15
    },
    {
      "x": -5,
      "y": 27,
      "z": 1,
      "name": "Plant_Leaves_Redwood"
    },
    {
      "x": -5,
      "y": 28,
      "z": 1,
      "name": "Plant_Leaves_Redwood"
    },
    {
      "x": -5,
      "y": 29,
      "z": 1,
      "name": "Plant_Leaves_Redwood"
    },
    {
      "x": -5,
      "y": 30,
      "z": 1,
      "name": "Plant_Leaves_Redwood"
    },
    {
      "x": -5,
      "y": 31,
      "z": 1,
      "name": "Plant_Leaves_Redwood"
    },
    {
      "x": -5,
      "y": 32,
      "z": 1,
      "name": "Plant_Leaves_Redwood"
    },
    {
      "x": -5,
      "y": 39,
      "z": 1,
      "name": "Plant_Leaves_Redwood"
    },
    {
      "x": -5,
      "y": 40,
      "z": 1,
      "name": "Plant_Leaves_Redwood"
    },
    {
      "x": -5,
      "y": 43,
      "z": 1,
      "name": "Plant_Leaves_Redwood",
      "support": 15
    },
    {
      "x": -5,
      "y": 44,
      "z": 1,
      "name": "Plant_Leaves_Redwood",
      "support": 15
    },
    {
      "x": -5,
      "y": 45,
      "z": 1,
      "name": "Plant_Leaves_Redwood",
      "support": 15
    },
    {
      "x": -5,
      "y": 28,
      "z": 2,
      "name": "Plant_Leaves_Redwood"
    },
    {
      "x": -5,
      "y": 31,
      "z": 2,
      "name": "Plant_Leaves_Redwood"
    },
    {
      "x": -5,
      "y": 39,
      "z": 2,
      "name": "Plant_Leaves_Redwood"
    },
    {
      "x": -4,
      "y": 26,
      "z": -4,
      "name": "Plant_Leaves_Redwood"
    },
    {
      "x": -4,
      "y": 27,
      "z": -4,
      "name": "Plant_Leaves_Redwood"
    },
    {
      "x": -4,
      "y": 28,
      "z": -4,
      "name": "Plant_Leaves_Redwood"
    },
    {
      "x": -4,
      "y": 34,
      "z": -4,
      "name": "Plant_Leaves_Redwood",
      "support": 15
    },
    {
      "x": -4,
      "y": 57,
      "z": -4,
      "name": "Plant_Leaves_Redwood"
    },
    {
      "x": -4,
      "y": 58,
      "z": -4,
      "name": "Plant_Leaves_Redwood"
    },
    {
      "x": -4,
      "y": 59,
      "z": -4,
      "name": "Plant_Leaves_Redwood"
    },
    {
      "x": -4,
      "y": 23,
      "z": -3,
      "name": "Plant_Leaves_Redwood",
      "support": 15
    },
    {
      "x": -4,
      "y": 24,
      "z": -3,
      "name": "Plant_Leaves_Redwood",
      "support": 15
    },
    {
      "x": -4,
      "y": 25,
      "z": -3,
      "name": "Plant_Leaves_Redwood"
    },
    {
      "x": -4,
      "y": 26,
      "z": -3,
      "name": "Plant_Leaves_Redwood",
      "support": 15
    },
    {
      "x": -4,
      "y": 27,
      "z": -3,
      "name": "Plant_Leaves_Redwood"
    },
    {
      "x": -4,
      "y": 29,
      "z": -3,
      "name": "Plant_Leaves_Redwood"
    },
    {
      "x": -4,
      "y": 34,
      "z": -3,
      "name": "Wood_Redwood_Branch_Long",
      "support": 15,
      "rotation": 5
    },
    {
      "x": -4,
      "y": 35,
      "z": -3,
      "name": "Plant_Leaves_Redwood",
      "support": 15
    },
    {
      "x": -4,
      "y": 45,
      "z": -3,
      "name": "Plant_Leaves_Redwood"
    },
    {
      "x": -4,
      "y": 56,
      "z": -3,
      "name": "Plant_Leaves_Redwood",
      "support": 15
    },
    {
      "x": -4,
      "y": 58,
      "z": -3,
      "name": "Plant_Leaves_Redwood"
    },
    {
      "x": -4,
      "y": 22,
      "z": -2,
      "name": "Plant_Leaves_Redwood",
      "support": 15
    },
    {
      "x": -4,
      "y": 23,
      "z": -2,
      "name": "Plant_Leaves_Redwood",
      "support": 15
    },
    {
      "x": -4,
      "y": 25,
      "z": -2,
      "name": "Plant_Leaves_Redwood"
    },
    {
      "x": -4,
      "y": 26,
      "z": -2,
      "name": "Wood_Redwood_Branch_Long",
      "support": 15,
      "rotation": 5
    },
    {
      "x": -4,
      "y": 27,
      "z": -2,
      "name": "Plant_Leaves_Redwood",
      "support": 15
    },
    {
      "x": -4,
      "y": 28,
      "z": -2,
      "name": "Plant_Leaves_Redwood"
    },
    {
      "x": -4,
      "y": 29,
      "z": -2,
      "name": "Plant_Leaves_Redwood"
    },
    {
      "x": -4,
      "y": 34,
      "z": -2,
      "name": "Wood_Redwood_Branch_Long",
      "support": 15,
      "rotation": 5
    },
    {
      "x": -4,
      "y": 35,
      "z": -2,
      "name": "Plant_Leaves_Redwood",
      "support": 15
    },
    {
      "x": -4,
      "y": 36,
      "z": -2,
      "name": "Plant_Leaves_Redwood",
      "support": 15
    },
    {
      "x": -4,
      "y": 37,
      "z": -2,
      "name": "Plant_Leaves_Redwood",
      "support": 15
    },
    {
      "x": -4,
      "y": 38,
      "z": -2,
      "name": "Plant_Leaves_Redwood"
    },
    {
      "x": -4,
      "y": 40,
      "z": -2,
      "name": "Plant_Leaves_Redwood"
    },
    {
      "x": -4,
      "y": 43,
      "z": -2,
      "name": "Plant_Leaves_Redwood",
      "support": 15
    },
    {
      "x": -4,
      "y": 44,
      "z": -2,
      "name": "Plant_Leaves_Redwood"
    },
    {
      "x": -4,
      "y": 50,
      "z": -2,
      "name": "Plant_Leaves_Redwood",
      "support": 15
    },
    {
      "x": -4,
      "y": 51,
      "z": -2,
      "name": "Plant_Leaves_Redwood",
      "support": 15
    },
    {
      "x": -4,
      "y": 56,
      "z": -2,
      "name": "Wood_Redwood_Branch_Long",
      "support": 15,
      "rotation": 5
    },
    {
      "x": -4,
      "y": 57,
      "z": -2,
      "name": "Plant_Leaves_Redwood",
      "support": 15
    },
    {
      "x": -4,
      "y": 58,
      "z": -2,
      "name": "Plant_Leaves_Redwood",
      "support": 15
    },
    {
      "x": -4,
      "y": 59,
      "z": -2,
      "name": "Plant_Leaves_Redwood"
    },
    {
      "x": -4,
      "y": 60,
      "z": -2,
      "name": "Plant_Leaves_Redwood"
    },
    {
      "x": -4,
      "y": 25,
      "z": -1,
      "name": "Plant_Leaves_Redwood"
    },
    {
      "x": -4,
      "y": 26,
      "z": -1,
      "name": "Wood_Redwood_Branch_Long",
      "support": 15,
      "rotation": 5
    },
    {
      "x": -4,
      "y": 27,
      "z": -1,
      "name": "Plant_Leaves_Redwood",
      "support": 15
    },
    {
      "x": -4,
      "y": 28,
      "z": -1,
      "name": "Plant_Leaves_Redwood",
      "support": 15
    },
    {
      "x": -4,
      "y": 29,
      "z": -1,
      "name": "Plant_Leaves_Redwood",
      "support": 15
    },
    {
      "x": -4,
      "y": 31,
      "z": -1,
      "name": "Plant_Leaves_Redwood"
    },
    {
      "x": -4,
      "y": 35,
      "z": -1,
      "name": "Plant_Leaves_Redwood",
      "support": 15
    },
    {
      "x": -4,
      "y": 37,
      "z": -1,
      "name": "Plant_Leaves_Redwood"
    },
    {
      "x": -4,
      "y": 38,
      "z": -1,
      "name": "Plant_Leaves_Redwood"
    },
    {
      "x": -4,
      "y": 39,
      "z": -1,
      "name": "Plant_Leaves_Redwood",
      "support": 15
    },
    {
      "x": -4,
      "y": 40,
      "z": -1,
      "name": "Plant_Leaves_Redwood",
      "support": 15
    },
    {
      "x": -4,
      "y": 41,
      "z": -1,
      "name": "Plant_Leaves_Redwood"
    },
    {
      "x": -4,
      "y": 43,
      "z": -1,
      "name": "Wood_Redwood_Branch_Long",
      "support": 15,
      "rotation": 5
    },
    {
      "x": -4,
      "y": 44,
      "z": -1,
      "name": "Plant_Leaves_Redwood",
      "support": 15
    },
    {
      "x": -4,
      "y": 45,
      "z": -1,
      "name": "Plant_Leaves_Redwood"
    },
    {
      "x": -4,
      "y": 46,
      "z": -1,
      "name": "Plant_Leaves_Redwood"
    },
    {
      "x": -4,
      "y": 47,
      "z": -1,
      "name": "Plant_Leaves_Redwood"
    },
    {
      "x": -4,
      "y": 49,
      "z": -1,
      "name": "Plant_Leaves_Redwood",
      "support": 15
    },
    {
      "x": -4,
      "y": 50,
      "z": -1,
      "name": "Plant_Leaves_Redwood",
      "support": 15
    },
    {
      "x": -4,
      "y": 56,
      "z": -1,
      "name": "Wood_Redwood_Branch_Long",
      "support": 15,
      "rotation": 5
    },
    {
      "x": -4,
      "y": 57,
      "z": -1,
      "name": "Plant_Leaves_Redwood",
      "support": 15
    },
    {
      "x": -4,
      "y": 58,
      "z": -1,
      "name": "Plant_Leaves_Redwood",
      "support": 15
    },
    {
      "x": -4,
      "y": 59,
      "z": -1,
      "name": "Plant_Leaves_Redwood",
      "support": 15
    },
    {
      "x": -4,
      "y": 60,
      "z": -1,
      "name": "Plant_Leaves_Redwood"
    },
    {
      "x": -4,
      "y": 26,
      "z": 0,
      "name": "Plant_Leaves_Redwood"
    },
    {
      "x": -4,
      "y": 27,
      "z": 0,
      "name": "Plant_Leaves_Redwood",
      "support": 15
    },
    {
      "x": -4,
      "y": 28,
      "z": 0,
      "name": "Plant_Leaves_Redwood"
    },
    {
      "x": -4,
      "y": 30,
      "z": 0,
      "name": "Plant_Leaves_Redwood"
    },
    {
      "x": -4,
      "y": 31,
      "z": 0,
      "name": "Plant_Leaves_Redwood",
      "support": 15
    },
    {
      "x": -4,
      "y": 38,
      "z": 0,
      "name": "Plant_Leaves_Redwood",
      "support": 15
    },
    {
      "x": -4,
      "y": 39,
      "z": 0,
      "name": "Plant_Leaves_Redwood",
      "support": 15
    },
    {
      "x": -4,
      "y": 41,
      "z": 0,
      "name": "Plant_Leaves_Redwood"
    },
    {
      "x": -4,
      "y": 43,
      "z": 0,
      "name": "Wood_Redwood_Branch_Long",
      "support": 15,
      "rotation": 5
    },
    {
      "x": -4,
      "y": 44,
      "z": 0,
      "name": "Plant_Leaves_Redwood",
      "support": 15
    },
    {
      "x": -4,
      "y": 45,
      "z": 0,
      "name": "Plant_Leaves_Redwood",
      "support": 15
    },
    {
      "x": -4,
      "y": 46,
      "z": 0,
      "name": "Plant_Leaves_Redwood",
      "support": 15
    },
    {
      "x": -4,
      "y": 56,
      "z": 0,
      "name": "Plant_Leaves_Redwood",
      "support": 15
    },
    {
      "x": -4,
      "y": 57,
      "z": 0,
      "name": "Plant_Leaves_Redwood",
      "support": 15
    },
    {
      "x": -4,
      "y": 58,
      "z": 0,
      "name": "Plant_Leaves_Redwood",
      "support": 15
    },
    {
      "x": -4,
      "y": 59,
      "z": 0,
      "name": "Plant_Leaves_Redwood"
    },
    {
      "x": -4,
      "y": 28,
      "z": 1,
      "name": "Plant_Leaves_Redwood"
    },
    {
      "x": -4,
      "y": 30,
      "z": 1,
      "name": "Plant_Leaves_Redwood"
    },
    {
      "x": -4,
      "y": 31,
      "z": 1,
      "name": "Plant_Leaves_Redwood"
    },
    {
      "x": -4,
      "y": 32,
      "z": 1,
      "name": "Plant_Leaves_Redwood"
    },
    {
      "x": -4,
      "y": 39,
      "z": 1,
      "name": "Plant_Leaves_Redwood"
    },
    {
      "x": -4,
      "y": 40,
      "z": 1,
      "name": "Plant_Leaves_Redwood"
    },
    {
      "x": -4,
      "y": 41,
      "z": 1,
      "name": "Plant_Leaves_Redwood"
    },
    {
      "x": -4,
      "y": 44,
      "z": 1,
      "name": "Plant_Leaves_Redwood",
      "support": 15
    },
    {
      "x": -3,
      "y": 39,
      "z": -6,
      "name": "Plant_Leaves_Redwood"
    },
    {
      "x": -3,
      "y": 41,
      "z": -6,
      "name": "Plant_Leaves_Redwood"
    },
    {
      "x": -3,
      "y": 40,
      "z": -5,
      "name": "Plant_Leaves_Redwood"
    },
    {
      "x": -3,
      "y": 27,
      "z": -4,
      "name": "Plant_Leaves_Redwood"
    },
    {
      "x": -3,
      "y": 35,
      "z": -4,
      "name": "Plant_Leaves_Redwood",
      "support": 15
    },
    {
      "x": -3,
      "y": 22,
      "z": -3,
      "name": "Plant_Leaves_Redwood",
      "support": 15
    },
    {
      "x": -3,
      "y": 23,
      "z": -3,
      "name": "Plant_Leaves_Redwood",
      "support": 15
    },
    {
      "x": -3,
      "y": 26,
      "z": -3,
      "name": "Plant_Leaves_Redwood"
    },
    {
      "x": -3,
      "y": 27,
      "z": -3,
      "name": "Plant_Leaves_Redwood",
      "support": 15
    },
    {
      "x": -3,
      "y": 28,
      "z": -3,
      "name": "Plant_Leaves_Redwood"
    },
    {
      "x": -3,
      "y": 34,
      "z": -3,
      "name": "Wood_Redwood_Branch_Corner",
      "support": 15,
      "rotation": 50
    },
    {
      "x": -3,
      "y": 35,
      "z": -3,
      "name": "Plant_Leaves_Redwood",
      "support": 15
    },
    {
      "x": -3,
      "y": 36,
      "z": -3,
      "name": "Plant_Leaves_Redwood",
      "support": 15
    },
    {
      "x": -3,
      "y": 56,
      "z": -3,
      "name": "Plant_Leaves_Redwood",
      "support": 15
    },
    {
      "x": -3,
      "y": 57,
      "z": -3,
      "name": "Plant_Leaves_Redwood"
    },
    {
      "x": -3,
      "y": 58,
      "z": -3,
      "name": "Plant_Leaves_Redwood"
    },
    {
      "x": -3,
      "y": 59,
      "z": -3,
      "name": "Plant_Leaves_Redwood"
    },
    {
      "x": -3,
      "y": 63,
      "z": -3,
      "name": "Plant_Leaves_Redwood",
      "support": 15
    },
    {
      "x": -3,
      "y": 64,
      "z": -3,
      "name": "Plant_Leaves_Redwood",
      "support": 15
    },
    {
      "x": -3,
      "y": 22,
      "z": -2,
      "name": "Wood_Redwood_Branch_Long",
      "support": 15,
      "rotation": 5
    },
    {
      "x": -3,
      "y": 23,
      "z": -2,
      "name": "Plant_Leaves_Redwood",
      "support": 15
    },
    {
      "x": -3,
      "y": 25,
      "z": -2,
      "name": "Plant_Leaves_Redwood"
    },
    {
      "x": -3,
      "y": 26,
      "z": -2,
      "name": "Wood_Redwood_Branch_Corner",
      "support": 15,
      "rotation": 24
    },
    {
      "x": -3,
      "y": 27,
      "z": -2,
      "name": "Plant_Leaves_Redwood",
      "support": 15
    },
    {
      "x": -3,
      "y": 28,
      "z": -2,
      "name": "Plant_Leaves_Redwood",
      "support": 15
    },
    {
      "x": -3,
      "y": 32,
      "z": -2,
      "name": "Plant_Leaves_Redwood",
      "support": 15
    },
    {
      "x": -3,
      "y": 34,
      "z": -2,
      "name": "Wood_Redwood_Trunk",
      "support": 15,
      "rotation": 5
    },
    {
      "x": -3,
      "y": 35,
      "z": -2,
      "name": "Plant_Leaves_Redwood",
      "support": 15
    },
    {
      "x": -3,
      "y": 36,
      "z": -2,
      "name": "Plant_Leaves_Redwood",
      "support": 15
    },
    {
      "x": -3,
      "y": 44,
      "z": -2,
      "name": "Plant_Leaves_Redwood",
      "support": 15
    },
    {
      "x": -3,
      "y": 45,
      "z": -2,
      "name": "Plant_Leaves_Redwood"
    },
    {
      "x": -3,
      "y": 49,
      "z": -2,
      "name": "Plant_Leaves_Redwood",
      "support": 15
    },
    {
      "x": -3,
      "y": 50,
      "z": -2,
      "name": "Plant_Leaves_Redwood",
      "support": 15
    },
    {
      "x": -3,
      "y": 56,
      "z": -2,
      "name": "Wood_Redwood_Branch_Long",
      "support": 15,
      "rotation": 5
    },
    {
      "x": -3,
      "y": 57,
      "z": -2,
      "name": "Plant_Leaves_Redwood",
      "support": 15
    },
    {
      "x": -3,
      "y": 58,
      "z": -2,
      "name": "Plant_Leaves_Redwood"
    },
    {
      "x": -3,
      "y": 59,
      "z": -2,
      "name": "Plant_Leaves_Redwood"
    },
    {
      "x": -3,
      "y": 60,
      "z": -2,
      "name": "Plant_Leaves_Redwood"
    },
    {
      "x": -3,
      "y": 62,
      "z": -2,
      "name": "Plant_Leaves_Redwood",
      "support": 15
    },
    {
      "x": -3,
      "y": 63,
      "z": -2,
      "name": "Plant_Leaves_Redwood",
      "support": 15
    },
    {
      "x": -3,
      "y": 22,
      "z": -1,
      "name": "Plant_Leaves_Redwood",
      "support": 15
    },
    {
      "x": -3,
      "y": 23,
      "z": -1,
      "name": "Plant_Leaves_Redwood",
      "support": 15
    },
    {
      "x": -3,
      "y": 26,
      "z": -1,
      "name": "Wood_Redwood_Trunk",
      "support": 15,
      "rotation": 5
    },
    {
      "x": -3,
      "y": 27,
      "z": -1,
      "name": "Plant_Leaves_Redwood",
      "support": 15
    },
    {
      "x": -3,
      "y": 28,
      "z": -1,
      "name": "Plant_Leaves_Redwood",
      "support": 15
    },
    {
      "x": -3,
      "y": 30,
      "z": -1,
      "name": "Plant_Leaves_Redwood"
    },
    {
      "x": -3,
      "y": 31,
      "z": -1,
      "name": "Plant_Leaves_Redwood",
      "support": 15
    },
    {
      "x": -3,
      "y": 32,
      "z": -1,
      "name": "Plant_Leaves_Redwood",
      "support": 15
    },
    {
      "x": -3,
      "y": 34,
      "z": -1,
      "name": "Plant_Leaves_Redwood",
      "support": 15
    },
    {
      "x": -3,
      "y": 35,
      "z": -1,
      "name": "Plant_Leaves_Redwood",
      "support": 15
    },
    {
      "x": -3,
      "y": 38,
      "z": -1,
      "name": "Plant_Leaves_Redwood",
      "support": 15
    },
    {
      "x": -3,
      "y": 39,
      "z": -1,
      "name": "Plant_Leaves_Redwood",
      "support": 15
    },
    {
      "x": -3,
      "y": 43,
      "z": -1,
      "name": "Wood_Redwood_Branch_Corner",
      "support": 15,
      "rotation": 50
    },
    {
      "x": -3,
      "y": 44,
      "z": -1,
      "name": "Plant_Leaves_Redwood",
      "support": 15
    },
    {
      "x": -3,
      "y": 45,
      "z": -1,
      "name": "Plant_Leaves_Redwood",
      "support": 15
    },
    {
      "x": -3,
      "y": 49,
      "z": -1,
      "name": "Wood_Redwood_Branch_Long",
      "support": 15,
      "rotation": 5
    },
    {
      "x": -3,
      "y": 50,
      "z": -1,
      "name": "Plant_Leaves_Redwood",
      "support": 15
    },
    {
      "x": -3,
      "y": 56,
      "z": -1,
      "name": "Wood_Redwood_Branch_Long",
      "support": 15,
      "rotation": 5
    },
    {
      "x": -3,
      "y": 57,
      "z": -1,
      "name": "Plant_Leaves_Redwood",
      "support": 15
    },
    {
      "x": -3,
      "y": 58,
      "z": -1,
      "name": "Plant_Leaves_Redwood",
      "support": 15
    },
    {
      "x": -3,
      "y": 59,
      "z": -1,
      "name": "Plant_Leaves_Redwood",
      "support": 15
    },
    {
      "x": -3,
      "y": 26,
      "z": 0,
      "name": "Plant_Leaves_Redwood",
      "support": 15
    },
    {
      "x": -3,
      "y": 27,
      "z": 0,
      "name": "Plant_Leaves_Redwood",
      "support": 15
    },
    {
      "x": -3,
      "y": 29,
      "z": 0,
      "name": "Plant_Leaves_Redwood"
    },
    {
      "x": -3,
      "y": 30,
      "z": 0,
      "name": "Plant_Leaves_Redwood"
    },
    {
      "x": -3,
      "y": 31,
      "z": 0,
      "name": "Wood_Redwood_Branch_Long",
      "support": 15,
      "rotation": 5
    },
    {
      "x": -3,
      "y": 32,
      "z": 0,
      "name": "Plant_Leaves_Redwood",
      "support": 15
    },
    {
      "x": -3,
      "y": 38,
      "z": 0,
      "name": "Wood_Redwood_Branch_Long",
      "support": 15,
      "rotation": 5
    },
    {
      "x": -3,
      "y": 39,
      "z": 0,
      "name": "Plant_Leaves_Redwood",
      "support": 15
    },
    {
      "x": -3,
      "y": 43,
      "z": 0,
      "name": "Wood_Redwood_Trunk",
      "support": 15,
      "rotation": 5
    },
    {
      "x": -3,
      "y": 44,
      "z": 0,
      "name": "Plant_Leaves_Redwood",
      "support": 15
    },
    {
      "x": -3,
      "y": 45,
      "z": 0,
      "name": "Plant_Leaves_Redwood",
      "support": 15
    },
    {
      "x": -3,
      "y": 49,
      "z": 0,
      "name": "Plant_Leaves_Redwood",
      "support": 15
    },
    {
      "x": -3,
      "y": 50,
      "z": 0,
      "name": "Plant_Leaves_Redwood",
      "support": 15
    },
    {
      "x": -3,
      "y": 57,
      "z": 0,
      "name": "Plant_Leaves_Redwood",
      "support": 15
    },
    {
      "x": -3,
      "y": 58,
      "z": 0,
      "name": "Plant_Leaves_Redwood"
    },
    {
      "x": -3,
      "y": 29,
      "z": 1,
      "name": "Plant_Leaves_Redwood"
    },
    {
      "x": -3,
      "y": 31,
      "z": 1,
      "name": "Plant_Leaves_Redwood",
      "support": 15
    },
    {
      "x": -3,
      "y": 32,
      "z": 1,
      "name": "Plant_Leaves_Redwood"
    },
    {
      "x": -3,
      "y": 33,
      "z": 1,
      "name": "Plant_Leaves_Redwood"
    },
    {
      "x": -3,
      "y": 38,
      "z": 1,
      "name": "Plant_Leaves_Redwood",
      "support": 15
    },
    {
      "x": -3,
      "y": 39,
      "z": 1,
      "name": "Plant_Leaves_Redwood",
      "support": 15
    },
    {
      "x": -3,
      "y": 40,
      "z": 1,
      "name": "Plant_Leaves_Redwood"
    },
    {
      "x": -3,
      "y": 43,
      "z": 1,
      "name": "Plant_Leaves_Redwood",
      "support": 15
    },
    {
      "x": -3,
      "y": 44,
      "z": 1,
      "name": "Plant_Leaves_Redwood",
      "support": 15
    },
    {
      "x": -3,
      "y": 30,
      "z": 2,
      "name": "Plant_Leaves_Redwood"
    },
    {
      "x": -3,
      "y": 31,
      "z": 2,
      "name": "Plant_Leaves_Redwood"
    },
    {
      "x": -3,
      "y": 32,
      "z": 2,
      "name": "Plant_Leaves_Redwood"
    },
    {
      "x": -3,
      "y": 33,
      "z": 2,
      "name": "Plant_Leaves_Redwood"
    },
    {
      "x": -3,
      "y": 39,
      "z": 2,
      "name": "Plant_Leaves_Redwood"
    },
    {
      "x": -3,
      "y": 30,
      "z": 3,
      "name": "Plant_Leaves_Redwood"
    },
    {
      "x": -3,
      "y": 31,
      "z": 3,
      "name": "Plant_Leaves_Redwood"
    },
    {
      "x": -3,
      "y": 38,
      "z": 3,
      "name": "Plant_Leaves_Redwood"
    },
    {
      "x": -3,
      "y": 39,
      "z": 3,
      "name": "Plant_Leaves_Redwood"
    },
    {
      "x": -3,
      "y": 40,
      "z": 3,
      "name": "Plant_Leaves_Redwood"
    },
    {
      "x": -3,
      "y": 48,
      "z": 3,
      "name": "Plant_Leaves_Redwood"
    },
    {
      "x": -3,
      "y": 39,
      "z": 4,
      "name": "Plant_Leaves_Redwood"
    },
    {
      "x": -3,
      "y": 47,
      "z": 4,
      "name": "Plant_Leaves_Redwood"
    },
    {
      "x": -3,
      "y": 49,
      "z": 4,
      "name": "Plant_Leaves_Redwood"
    },
    {
      "x": -3,
      "y": 48,
      "z": 5,
      "name": "Plant_Leaves_Redwood"
    },
    {
      "x": -2,
      "y": 40,
      "z": -8,
      "name": "Plant_Leaves_Redwood"
    },
    {
      "x": -2,
      "y": 39,
      "z": -7,
      "name": "Plant_Leaves_Redwood"
    },
    {
      "x": -2,
      "y": 40,
      "z": -7,
      "name": "Plant_Leaves_Redwood"
    },
    {
      "x": -2,
      "y": 41,
      "z": -7,
      "name": "Plant_Leaves_Redwood"
    },
    {
      "x": -2,
      "y": 38,
      "z": -6,
      "name": "Plant_Leaves_Redwood"
    },
    {
      "x": -2,
      "y": 40,
      "z": -6,
      "name": "Plant_Leaves_Redwood"
    },
    {
      "x": -2,
      "y": 41,
      "z": -6,
      "name": "Plant_Leaves_Redwood"
    },
    {
      "x": -2,
      "y": 39,
      "z": -5,
      "name": "Plant_Leaves_Redwood"
    },
    {
      "x": -2,
      "y": 40,
      "z": -5,
      "name": "Plant_Leaves_Redwood"
    },
    {
      "x": -2,
      "y": 41,
      "z": -5,
      "name": "Plant_Leaves_Redwood"
    },
    {
      "x": -2,
      "y": 40,
      "z": -4,
      "name": "Plant_Leaves_Redwood"
    },
    {
      "x": -2,
      "y": 22,
      "z": -3,
      "name": "Plant_Leaves_Redwood",
      "support": 15
    },
    {
      "x": -2,
      "y": 23,
      "z": -3,
      "name": "Plant_Leaves_Redwood",
      "support": 15
    },
    {
      "x": -2,
      "y": 57,
      "z": -3,
      "name": "Plant_Leaves_Redwood",
      "support": 15
    },
    {
      "x": -2,
      "y": 62,
      "z": -3,
      "name": "Plant_Leaves_Redwood",
      "support": 15
    },
    {
      "x": -2,
      "y": 63,
      "z": -3,
      "name": "Plant_Leaves_Redwood",
      "support": 15
    },
    {
      "x": -2,
      "y": 17,
      "z": -2,
      "name": "Wood_Redwood_Branch_Long",
      "support": 15,
      "rotation": 5
    },
    {
      "x": -2,
      "y": 22,
      "z": -2,
      "name": "Wood_Redwood_Branch_Long",
      "support": 15,
      "rotation": 5
    },
    {
      "x": -2,
      "y": 23,
      "z": -2,
      "name": "Plant_Leaves_Redwood",
      "support": 15
    },
    {
      "x": -2,
      "y": 24,
      "z": -2,
      "name": "Plant_Leaves_Redwood",
      "support": 15
    },
    {
      "x": -2,
      "y": 27,
      "z": -2,
      "name": "Plant_Leaves_Redwood"
    },
    {
      "x": -2,
      "y": 28,
      "z": -2,
      "name": "Plant_Leaves_Redwood"
    },
    {
      "x": -2,
      "y": 34,
      "z": -2,
      "name": "Wood_Redwood_Trunk",
      "support": 15,
      "rotation": 5
    },
    {
      "x": -2,
      "y": 35,
      "z": -2,
      "name": "Plant_Leaves_Redwood",
      "support": 15
    },
    {
      "x": -2,
      "y": 49,
      "z": -2,
      "name": "Plant_Leaves_Redwood",
      "support": 15
    },
    {
      "x": -2,
      "y": 50,
      "z": -2,
      "name": "Plant_Leaves_Redwood",
      "support": 15
    },
    {
      "x": -2,
      "y": 56,
      "z": -2,
      "name": "Wood_Redwood_Branch_Corner",
      "support": 15,
      "rotation": 50
    },
    {
      "x": -2,
      "y": 57,
      "z": -2,
      "name": "Plant_Leaves_Redwood",
      "support": 15
    },
    {
      "x": -2,
      "y": 58,
      "z": -2,
      "name": "Plant_Leaves_Redwood",
      "support": 15
    },
    {
      "x": -2,
      "y": 62,
      "z": -2,
      "name": "Wood_Redwood_Branch_Long",
      "support": 15,
      "rotation": 5
    },
    {
      "x": -2,
      "y": 63,
      "z": -2,
      "name": "Plant_Leaves_Redwood",
      "support": 15
    },
    {
      "x": -2,
      "y": 66,
      "z": -2,
      "name": "Plant_Leaves_Redwood",
      "support": 15
    },
    {
      "x": -2,
      "y": 67,
      "z": -2,
      "name": "Plant_Leaves_Redwood",
      "support": 15
    },
    {
      "x": -2,
      "y": 22,
      "z": -1,
      "name": "Plant_Leaves_Redwood",
      "support": 15
    },
    {
      "x": -2,
      "y": 23,
      "z": -1,
      "name": "Plant_Leaves_Redwood",
      "support": 15
    },
    {
      "x": -2,
      "y": 26,
      "z": -1,
      "name": "Wood_Redwood_Trunk",
      "support": 15,
      "rotation": 5
    },
    {
      "x": -2,
      "y": 27,
      "z": -1,
      "name": "Plant_Leaves_Redwood",
      "support": 15
    },
    {
      "x": -2,
      "y": 31,
      "z": -1,
      "name": "Plant_Leaves_Redwood"
    },
    {
      "x": -2,
      "y": 32,
      "z": -1,
      "name": "Plant_Leaves_Redwood",
      "support": 15
    },
    {
      "x": -2,
      "y": 35,
      "z": -1,
      "name": "Plant_Leaves_Redwood",
      "support": 15
    },
    {
      "x": -2,
      "y": 38,
      "z": -1,
      "name": "Plant_Leaves_Redwood",
      "support": 15
    },
    {
      "x": -2,
      "y": 39,
      "z": -1,
      "name": "Plant_Leaves_Redwood",
      "support": 15
    },
    {
      "x": -2,
      "y": 49,
      "z": -1,
      "name": "Wood_Redwood_Branch_Long",
      "support": 15,
      "rotation": 5
    },
    {
      "x": -2,
      "y": 50,
      "z": -1,
      "name": "Plant_Leaves_Redwood",
      "support": 15
    },
    {
      "x": -2,
      "y": 51,
      "z": -1,
      "name": "Plant_Leaves_Redwood",
      "support": 15
    },
    {
      "x": -2,
      "y": 56,
      "z": -1,
      "name": "Wood_Redwood_Trunk",
      "support": 15,
      "rotation": 5
    },
    {
      "x": -2,
      "y": 57,
      "z": -1,
      "name": "Plant_Leaves_Redwood",
      "support": 15
    },
    {
      "x": -2,
      "y": 58,
      "z": -1,
      "name": "Plant_Leaves_Redwood",
      "support": 15
    },
    {
      "x": -2,
      "y": 62,
      "z": -1,
      "name": "Plant_Leaves_Redwood",
      "support": 15
    },
    {
      "x": -2,
      "y": 63,
      "z": -1,
      "name": "Plant_Leaves_Redwood",
      "support": 15
    },
    {
      "x": -2,
      "y": 0,
      "z": 0,
      "name": "Wood_Redwood_Trunk",
      "support": 15
    },
    {
      "x": -2,
      "y": 1,
      "z": 0,
      "name": "Wood_Redwood_Trunk",
      "support": 15
    },
    {
      "x": -2,
      "y": 2,
      "z": 0,
      "name": "Wood_Redwood_Trunk",
      "support": 15
    },
    {
      "x": -2,
      "y": 3,
      "z": 0,
      "name": "Wood_Redwood_Trunk",
      "support": 15
    },
    {
      "x": -2,
      "y": 4,
      "z": 0,
      "name": "Wood_Redwood_Trunk",
      "support": 15
    },
    {
      "x": -2,
      "y": 5,
      "z": 0,
      "name": "Wood_Redwood_Trunk",
      "support": 15
    },
    {
      "x": -2,
      "y": 6,
      "z": 0,
      "name": "Wood_Redwood_Trunk",
      "support": 15
    },
    {
      "x": -2,
      "y": 7,
      "z": 0,
      "name": "Wood_Redwood_Trunk"
    },
    {
      "x": -2,
      "y": 27,
      "z": 0,
      "name": "Plant_Leaves_Redwood",
      "support": 15
    },
    {
      "x": -2,
      "y": 31,
      "z": 0,
      "name": "Wood_Redwood_Branch_Long",
      "support": 15,
      "rotation": 5
    },
    {
      "x": -2,
      "y": 32,
      "z": 0,
      "name": "Plant_Leaves_Redwood",
      "support": 15
    },
    {
      "x": -2,
      "y": 38,
      "z": 0,
      "name": "Wood_Redwood_Branch_Long",
      "support": 15,
      "rotation": 5
    },
    {
      "x": -2,
      "y": 39,
      "z": 0,
      "name": "Plant_Leaves_Redwood",
      "support": 15
    },
    {
      "x": -2,
      "y": 40,
      "z": 0,
      "name": "Plant_Leaves_Redwood",
      "support": 15
    },
    {
      "x": -2,
      "y": 43,
      "z": 0,
      "name": "Wood_Redwood_Trunk",
      "support": 15,
      "rotation": 5
    },
    {
      "x": -2,
      "y": 44,
      "z": 0,
      "name": "Plant_Leaves_Redwood",
      "support": 15
    },
    {
      "x": -2,
      "y": 49,
      "z": 0,
      "name": "Plant_Leaves_Redwood",
      "support": 15
    },
    {
      "x": -2,
      "y": 50,
      "z": 0,
      "name": "Plant_Leaves_Redwood",
      "support": 15
    },
    {
      "x": -2,
      "y": 56,
      "z": 0,
      "name": "Plant_Leaves_Redwood",
      "support": 15
    },
    {
      "x": -2,
      "y": 57,
      "z": 0,
      "name": "Plant_Leaves_Redwood",
      "support": 15
    },
    {
      "x": -2,
      "y": 7,
      "z": 1,
      "name": "Wood_Redwood_Trunk"
    },
    {
      "x": -2,
      "y": 29,
      "z": 1,
      "name": "Plant_Leaves_Redwood"
    },
    {
      "x": -2,
      "y": 30,
      "z": 1,
      "name": "Plant_Leaves_Redwood"
    },
    {
      "x": -2,
      "y": 31,
      "z": 1,
      "name": "Plant_Leaves_Redwood",
      "support": 15
    },
    {
      "x": -2,
      "y": 32,
      "z": 1,
      "name": "Plant_Leaves_Redwood",
      "support": 15
    },
    {
      "x": -2,
      "y": 33,
      "z": 1,
      "name": "Plant_Leaves_Redwood"
    },
    {
      "x": -2,
      "y": 38,
      "z": 1,
      "name": "Plant_Leaves_Redwood",
      "support": 15
    },
    {
      "x": -2,
      "y": 39,
      "z": 1,
      "name": "Plant_Leaves_Redwood",
      "support": 15
    },
    {
      "x": -2,
      "y": 44,
      "z": 1,
      "name": "Plant_Leaves_Redwood",
      "support": 15
    },
    {
      "x": -2,
      "y": 32,
      "z": 2,
      "name": "Plant_Leaves_Redwood"
    },
    {
      "x": -2,
      "y": 38,
      "z": 2,
      "name": "Plant_Leaves_Redwood"
    },
    {
      "x": -2,
      "y": 40,
      "z": 2,
      "name": "Plant_Leaves_Redwood"
    },
    {
      "x": -2,
      "y": 48,
      "z": 2,
      "name": "Plant_Leaves_Redwood"
    },
    {
      "x": -2,
      "y": 27,
      "z": 3,
      "name": "Plant_Leaves_Redwood"
    },
    {
      "x": -2,
      "y": 28,
      "z": 3,
      "name": "Plant_Leaves_Redwood"
    },
    {
      "x": -2,
      "y": 31,
      "z": 3,
      "name": "Plant_Leaves_Redwood"
    },
    {
      "x": -2,
      "y": 38,
      "z": 3,
      "name": "Plant_Leaves_Redwood",
      "support": 15,
      "rotation": 1
    },
    {
      "x": -2,
      "y": 39,
      "z": 3,
      "name": "Plant_Leaves_Redwood"
    },
    {
      "x": -2,
      "y": 47,
      "z": 3,
      "name": "Plant_Leaves_Redwood"
    },
    {
      "x": -2,
      "y": 48,
      "z": 3,
      "name": "Plant_Leaves_Redwood"
    },
    {
      "x": -2,
      "y": 49,
      "z": 3,
      "name": "Plant_Leaves_Redwood"
    },
    {
      "x": -2,
      "y": 37,
      "z": 4,
      "name": "Plant_Leaves_Redwood",
      "support": 15,
      "rotation": 1
    },
    {
      "x": -2,
      "y": 38,
      "z": 4,
      "name": "Plant_Leaves_Redwood"
    },
    {
      "x": -2,
      "y": 40,
      "z": 4,
      "name": "Plant_Leaves_Redwood"
    },
    {
      "x": -2,
      "y": 47,
      "z": 4,
      "name": "Plant_Leaves_Redwood"
    },
    {
      "x": -2,
      "y": 48,
      "z": 4,
      "name": "Plant_Leaves_Redwood"
    },
    {
      "x": -2,
      "y": 37,
      "z": 5,
      "name": "Plant_Leaves_Redwood",
      "support": 15,
      "rotation": 1
    },
    {
      "x": -2,
      "y": 39,
      "z": 5,
      "name": "Plant_Leaves_Redwood"
    },
    {
      "x": -2,
      "y": 48,
      "z": 6,
      "name": "Plant_Leaves_Redwood"
    },
    {
      "x": -1,
      "y": 39,
      "z": -9,
      "name": "Plant_Leaves_Redwood",
      "support": 15,
      "rotation": 3
    },
    {
      "x": -1,
      "y": 39,
      "z": -8,
      "name": "Plant_Leaves_Redwood",
      "support": 15,
      "rotation": 3
    },
    {
      "x": -1,
      "y": 40,
      "z": -8,
      "name": "Plant_Leaves_Redwood",
      "support": 15,
      "rotation": 3
    },
    {
      "x": -1,
      "y": 41,
      "z": -8,
      "name": "Plant_Leaves_Redwood",
      "support": 15,
      "rotation": 3
    },
    {
      "x": -1,
      "y": 47,
      "z": -8,
      "name": "Plant_Leaves_Redwood",
      "support": 15,
      "rotation": 3
    },
    {
      "x": -1,
      "y": 38,
      "z": -7,
      "name": "Plant_Leaves_Redwood"
    },
    {
      "x": -1,
      "y": 39,
      "z": -7,
      "name": "Plant_Leaves_Redwood",
      "support": 15,
      "rotation": 3
    },
    {
      "x": -1,
      "y": 40,
      "z": -7,
      "name": "Plant_Leaves_Redwood",
      "support": 15,
      "rotation": 3
    },
    {
      "x": -1,
      "y": 41,
      "z": -7,
      "name": "Plant_Leaves_Redwood",
      "support": 15,
      "rotation": 3
    },
    {
      "x": -1,
      "y": 42,
      "z": -7,
      "name": "Plant_Leaves_Redwood"
    },
    {
      "x": -1,
      "y": 47,
      "z": -7,
      "name": "Plant_Leaves_Redwood",
      "support": 15,
      "rotation": 3
    },
    {
      "x": -1,
      "y": 48,
      "z": -7,
      "name": "Plant_Leaves_Redwood",
      "support": 15,
      "rotation": 3
    },
    {
      "x": -1,
      "y": 49,
      "z": -7,
      "name": "Plant_Leaves_Redwood",
      "support": 15,
      "rotation": 3
    },
    {
      "x": -1,
      "y": 38,
      "z": -6,
      "name": "Plant_Leaves_Redwood"
    },
    {
      "x": -1,
      "y": 39,
      "z": -6,
      "name": "Plant_Leaves_Redwood"
    },
    {
      "x": -1,
      "y": 40,
      "z": -6,
      "name": "Plant_Leaves_Redwood",
      "support": 15,
      "rotation": 3
    },
    {
      "x": -1,
      "y": 42,
      "z": -6,
      "name": "Plant_Leaves_Redwood"
    },
    {
      "x": -1,
      "y": 44,
      "z": -6,
      "name": "Plant_Leaves_Redwood"
    },
    {
      "x": -1,
      "y": 47,
      "z": -6,
      "name": "Plant_Leaves_Redwood",
      "support": 15,
      "rotation": 3
    },
    {
      "x": -1,
      "y": 48,
      "z": -6,
      "name": "Plant_Leaves_Redwood",
      "support": 15,
      "rotation": 3
    },
    {
      "x": -1,
      "y": 49,
      "z": -6,
      "name": "Plant_Leaves_Redwood",
      "support": 15,
      "rotation": 3
    },
    {
      "x": -1,
      "y": 4,
      "z": -5,
      "name": "Wood_Redwood_Trunk",
      "support": 15
    },
    {
      "x": -1,
      "y": 5,
      "z": -5,
      "name": "Wood_Redwood_Trunk",
      "support": 15
    },
    {
      "x": -1,
      "y": 6,
      "z": -5,
      "name": "Wood_Redwood_Trunk"
    },
    {
      "x": -1,
      "y": 7,
      "z": -5,
      "name": "Wood_Redwood_Trunk"
    },
    {
      "x": -1,
      "y": 36,
      "z": -5,
      "name": "Plant_Leaves_Redwood",
      "support": 15,
      "rotation": 3
    },
    {
      "x": -1,
      "y": 38,
      "z": -5,
      "name": "Plant_Leaves_Redwood"
    },
    {
      "x": -1,
      "y": 39,
      "z": -5,
      "name": "Plant_Leaves_Redwood",
      "support": 15,
      "rotation": 3
    },
    {
      "x": -1,
      "y": 40,
      "z": -5,
      "name": "Plant_Leaves_Redwood",
      "support": 15,
      "rotation": 3
    },
    {
      "x": -1,
      "y": 42,
      "z": -5,
      "name": "Plant_Leaves_Redwood"
    },
    {
      "x": -1,
      "y": 43,
      "z": -5,
      "name": "Plant_Leaves_Redwood"
    },
    {
      "x": -1,
      "y": 44,
      "z": -5,
      "name": "Plant_Leaves_Redwood"
    },
    {
      "x": -1,
      "y": 45,
      "z": -5,
      "name": "Plant_Leaves_Redwood"
    },
    {
      "x": -1,
      "y": 48,
      "z": -5,
      "name": "Plant_Leaves_Redwood",
      "support": 15,
      "rotation": 3
    },
    {
      "x": -1,
      "y": 59,
      "z": -5,
      "name": "Plant_Leaves_Redwood"
    },
    {
      "x": -1,
      "y": 6,
      "z": -4,
      "name": "Wood_Redwood_Trunk"
    },
    {
      "x": -1,
      "y": 7,
      "z": -4,
      "name": "Wood_Redwood_Trunk"
    },
    {
      "x": -1,
      "y": 8,
      "z": -4,
      "name": "Wood_Redwood_Trunk"
    },
    {
      "x": -1,
      "y": 9,
      "z": -4,
      "name": "Wood_Redwood_Trunk"
    },
    {
      "x": -1,
      "y": 36,
      "z": -4,
      "name": "Plant_Leaves_Redwood",
      "support": 15,
      "rotation": 3
    },
    {
      "x": -1,
      "y": 37,
      "z": -4,
      "name": "Plant_Leaves_Redwood",
      "support": 15,
      "rotation": 3
    },
    {
      "x": -1,
      "y": 40,
      "z": -4,
      "name": "Plant_Leaves_Redwood",
      "support": 15,
      "rotation": 3
    },
    {
      "x": -1,
      "y": 44,
      "z": -4,
      "name": "Plant_Leaves_Redwood"
    },
    {
      "x": -1,
      "y": 47,
      "z": -4,
      "name": "Plant_Leaves_Redwood",
      "support": 15,
      "rotation": 3
    },
    {
      "x": -1,
      "y": 48,
      "z": -4,
      "name": "Plant_Leaves_Redwood",
      "support": 15,
      "rotation": 3
    },
    {
      "x": -1,
      "y": 59,
      "z": -4,
      "name": "Plant_Leaves_Redwood"
    },
    {
      "x": -1,
      "y": 8,
      "z": -3,
      "name": "Wood_Redwood_Trunk"
    },
    {
      "x": -1,
      "y": 9,
      "z": -3,
      "name": "Wood_Redwood_Trunk"
    },
    {
      "x": -1,
      "y": 10,
      "z": -3,
      "name": "Wood_Redwood_Trunk"
    },
    {
      "x": -1,
      "y": 11,
      "z": -3,
      "name": "Wood_Redwood_Trunk"
    },
    {
      "x": -1,
      "y": 12,
      "z": -3,
      "name": "Wood_Redwood_Trunk"
    },
    {
      "x": -1,
      "y": 22,
      "z": -3,
      "name": "Plant_Leaves_Redwood",
      "support": 15
    },
    {
      "x": -1,
      "y": 23,
      "z": -3,
      "name": "Plant_Leaves_Redwood",
      "support": 15
    },
    {
      "x": -1,
      "y": 48,
      "z": -3,
      "name": "Plant_Leaves_Redwood",
      "support": 15,
      "rotation": 3
    },
    {
      "x": -1,
      "y": 62,
      "z": -3,
      "name": "Plant_Leaves_Redwood",
      "support": 15
    },
    {
      "x": -1,
      "y": 63,
      "z": -3,
      "name": "Plant_Leaves_Redwood",
      "support": 15
    },
    {
      "x": -1,
      "y": 66,
      "z": -3,
      "name": "Plant_Leaves_Redwood",
      "support": 15
    },
    {
      "x": -1,
      "y": 10,
      "z": -2,
      "name": "Wood_Redwood_Trunk"
    },
    {
      "x": -1,
      "y": 11,
      "z": -2,
      "name": "Wood_Redwood_Trunk"
    },
    {
      "x": -1,
      "y": 12,
      "z": -2,
      "name": "Wood_Redwood_Trunk"
    },
    {
      "x": -1,
      "y": 13,
      "z": -2,
      "name": "Wood_Redwood_Trunk"
    },
    {
      "x": -1,
      "y": 17,
      "z": -2,
      "name": "Wood_Redwood_Trunk_Full",
      "support": 15,
      "rotation": 5
    },
    {
      "x": -1,
      "y": 22,
      "z": -2,
      "name": "Wood_Redwood_Trunk",
      "support": 15,
      "rotation": 5
    },
    {
      "x": -1,
      "y": 23,
      "z": -2,
      "name": "Plant_Leaves_Redwood",
      "support": 15
    },
    {
      "x": -1,
      "y": 34,
      "z": -2,
      "name": "Wood_Redwood_Trunk",
      "support": 15,
      "rotation": 5
    },
    {
      "x": -1,
      "y": 49,
      "z": -2,
      "name": "Plant_Leaves_Redwood",
      "support": 15
    },
    {
      "x": -1,
      "y": 50,
      "z": -2,
      "name": "Plant_Leaves_Redwood",
      "support": 15
    },
    {
      "x": -1,
      "y": 62,
      "z": -2,
      "name": "Wood_Redwood_Branch_Long",
      "support": 15,
      "rotation": 5
    },
    {
      "x": -1,
      "y": 63,
      "z": -2,
      "name": "Plant_Leaves_Redwood",
      "support": 15
    },
    {
      "x": -1,
      "y": 64,
      "z": -2,
      "name": "Plant_Leaves_Redwood",
      "support": 15
    },
    {
      "x": -1,
      "y": 65,
      "z": -2,
      "name": "Plant_Leaves_Redwood",
      "support": 15
    },
    {
      "x": -1,
      "y": 66,
      "z": -2,
      "name": "Plant_Leaves_Redwood",
      "support": 15
    },
    {
      "x": -1,
      "y": 12,
      "z": -1,
      "name": "Wood_Redwood_Trunk_Full",
      "support": 15
    },
    {
      "x": -1,
      "y": 13,
      "z": -1,
      "name": "Wood_Redwood_Trunk"
    },
    {
      "x": -1,
      "y": 14,
      "z": -1,
      "name": "Wood_Redwood_Trunk"
    },
    {
      "x": -1,
      "y": 22,
      "z": -1,
      "name": "Plant_Leaves_Redwood",
      "support": 15
    },
    {
      "x": -1,
      "y": 26,
      "z": -1,
      "name": "Wood_Redwood_Trunk",
      "support": 15,
      "rotation": 5
    },
    {
      "x": -1,
      "y": 31,
      "z": -1,
      "name": "Plant_Leaves_Redwood",
      "support": 15
    },
    {
      "x": -1,
      "y": 38,
      "z": -1,
      "name": "Plant_Leaves_Redwood",
      "support": 15
    },
    {
      "x": -1,
      "y": 39,
      "z": -1,
      "name": "Plant_Leaves_Redwood",
      "support": 15
    },
    {
      "x": -1,
      "y": 49,
      "z": -1,
      "name": "Wood_Redwood_Trunk",
      "support": 15,
      "rotation": 5
    },
    {
      "x": -1,
      "y": 50,
      "z": -1,
      "name": "Plant_Leaves_Redwood",
      "support": 15
    },
    {
      "x": -1,
      "y": 56,
      "z": -1,
      "name": "Wood_Redwood_Trunk",
      "support": 15,
      "rotation": 5
    },
    {
      "x": -1,
      "y": 57,
      "z": -1,
      "name": "Plant_Leaves_Redwood",
      "support": 15
    },
    {
      "x": -1,
      "y": 62,
      "z": -1,
      "name": "Plant_Leaves_Redwood",
      "support": 15
    },
    {
      "x": -1,
      "y": 63,
      "z": -1,
      "name": "Plant_Leaves_Redwood",
      "support": 15
    },
    {
      "x": -1,
      "y": 1,
      "z": 0,
      "name": "Wood_Redwood_Trunk",
      "support": 15
    },
    {
      "x": -1,
      "y": 2,
      "z": 0,
      "name": "Wood_Redwood_Trunk",
      "support": 15
    },
    {
      "x": -1,
      "y": 3,
      "z": 0,
      "name": "Wood_Redwood_Trunk",
      "support": 15
    },
    {
      "x": -1,
      "y": 4,
      "z": 0,
      "name": "Wood_Redwood_Trunk",
      "support": 15
    },
    {
      "x": -1,
      "y": 5,
      "z": 0,
      "name": "Wood_Redwood_Trunk"
    },
    {
      "x": -1,
      "y": 6,
      "z": 0,
      "name": "Wood_Redwood_Trunk"
    },
    {
      "x": -1,
      "y": 7,
      "z": 0,
      "name": "Wood_Redwood_Trunk"
    },
    {
      "x": -1,
      "y": 8,
      "z": 0,
      "name": "Wood_Redwood_Trunk"
    },
    {
      "x": -1,
      "y": 31,
      "z": 0,
      "name": "Wood_Redwood_Branch_Long",
      "support": 15,
      "rotation": 5
    },
    {
      "x": -1,
      "y": 32,
      "z": 0,
      "name": "Plant_Leaves_Redwood",
      "support": 15
    },
    {
      "x": -1,
      "y": 38,
      "z": 0,
      "name": "Wood_Redwood_Trunk",
      "support": 15,
      "rotation": 5
    },
    {
      "x": -1,
      "y": 39,
      "z": 0,
      "name": "Plant_Leaves_Redwood",
      "support": 15
    },
    {
      "x": -1,
      "y": 43,
      "z": 0,
      "name": "Wood_Redwood_Trunk",
      "support": 15,
      "rotation": 5
    },
    {
      "x": -1,
      "y": 49,
      "z": 0,
      "name": "Plant_Leaves_Redwood",
      "support": 15
    },
    {
      "x": -1,
      "y": 57,
      "z": 0,
      "name": "Plant_Leaves_Redwood",
      "support": 15
    },
    {
      "x": -1,
      "y": 66,
      "z": 0,
      "name": "Plant_Leaves_Redwood",
      "support": 15
    },
    {
      "x": -1,
      "y": 3,
      "z": 1,
      "name": "Wood_Redwood_Trunk",
      "support": 15
    },
    {
      "x": -1,
      "y": 4,
      "z": 1,
      "name": "Wood_Redwood_Trunk",
      "support": 15
    },
    {
      "x": -1,
      "y": 5,
      "z": 1,
      "name": "Wood_Redwood_Trunk"
    },
    {
      "x": -1,
      "y": 6,
      "z": 1,
      "name": "Wood_Redwood_Trunk"
    },
    {
      "x": -1,
      "y": 7,
      "z": 1,
      "name": "Wood_Redwood_Trunk"
    },
    {
      "x": -1,
      "y": 8,
      "z": 1,
      "name": "Wood_Redwood_Trunk"
    },
    {
      "x": -1,
      "y": 9,
      "z": 1,
      "name": "Wood_Redwood_Trunk"
    },
    {
      "x": -1,
      "y": 38,
      "z": 1,
      "name": "Plant_Leaves_Redwood",
      "support": 15
    },
    {
      "x": -1,
      "y": 39,
      "z": 1,
      "name": "Plant_Leaves_Redwood"
    },
    {
      "x": -1,
      "y": 40,
      "z": 1,
      "name": "Plant_Leaves_Redwood"
    },
    {
      "x": -1,
      "y": 6,
      "z": 2,
      "name": "Wood_Redwood_Trunk"
    },
    {
      "x": -1,
      "y": 7,
      "z": 2,
      "name": "Wood_Redwood_Trunk"
    },
    {
      "x": -1,
      "y": 8,
      "z": 2,
      "name": "Wood_Redwood_Trunk"
    },
    {
      "x": -1,
      "y": 26,
      "z": 2,
      "name": "Plant_Leaves_Redwood"
    },
    {
      "x": -1,
      "y": 27,
      "z": 2,
      "name": "Plant_Leaves_Redwood"
    },
    {
      "x": -1,
      "y": 31,
      "z": 2,
      "name": "Plant_Leaves_Redwood"
    },
    {
      "x": -1,
      "y": 33,
      "z": 2,
      "name": "Plant_Leaves_Redwood",
      "support": 15,
      "rotation": 1
    },
    {
      "x": -1,
      "y": 37,
      "z": 2,
      "name": "Plant_Leaves_Redwood"
    },
    {
      "x": -1,
      "y": 38,
      "z": 2,
      "name": "Plant_Leaves_Redwood"
    },
    {
      "x": -1,
      "y": 40,
      "z": 2,
      "name": "Plant_Leaves_Redwood"
    },
    {
      "x": -1,
      "y": 47,
      "z": 2,
      "name": "Plant_Leaves_Redwood"
    },
    {
      "x": -1,
      "y": 48,
      "z": 2,
      "name": "Plant_Leaves_Redwood"
    },
    {
      "x": -1,
      "y": 52,
      "z": 2,
      "name": "Plant_Leaves_Redwood"
    },
    {
      "x": -1,
      "y": 53,
      "z": 2,
      "name": "Plant_Leaves_Redwood",
      "support": 15,
      "rotation": 1
    },
    {
      "x": -1,
      "y": 58,
      "z": 2,
      "name": "Plant_Leaves_Redwood",
      "support": 15,
      "rotation": 1
    },
    {
      "x": -1,
      "y": 7,
      "z": 3,
      "name": "Wood_Redwood_Trunk"
    },
    {
      "x": -1,
      "y": 26,
      "z": 3,
      "name": "Plant_Leaves_Redwood"
    },
    {
      "x": -1,
      "y": 27,
      "z": 3,
      "name": "Plant_Leaves_Redwood",
      "support": 15,
      "rotation": 1
    },
    {
      "x": -1,
      "y": 28,
      "z": 3,
      "name": "Plant_Leaves_Redwood"
    },
    {
      "x": -1,
      "y": 29,
      "z": 3,
      "name": "Plant_Leaves_Redwood"
    },
    {
      "x": -1,
      "y": 32,
      "z": 3,
      "name": "Plant_Leaves_Redwood",
      "support": 15,
      "rotation": 1
    },
    {
      "x": -1,
      "y": 37,
      "z": 3,
      "name": "Wood_Redwood_Branch_Corner",
      "support": 15,
      "rotation": 51
    },
    {
      "x": -1,
      "y": 38,
      "z": 3,
      "name": "Plant_Leaves_Redwood",
      "support": 15,
      "rotation": 1
    },
    {
      "x": -1,
      "y": 39,
      "z": 3,
      "name": "Plant_Leaves_Redwood",
      "support": 15,
      "rotation": 1
    },
    {
      "x": -1,
      "y": 40,
      "z": 3,
      "name": "Plant_Leaves_Redwood"
    },
    {
      "x": -1,
      "y": 41,
      "z": 3,
      "name": "Plant_Leaves_Redwood"
    },
    {
      "x": -1,
      "y": 45,
      "z": 3,
      "name": "Plant_Leaves_Redwood"
    },
    {
      "x": -1,
      "y": 46,
      "z": 3,
      "name": "Plant_Leaves_Redwood"
    },
    {
      "x": -1,
      "y": 47,
      "z": 3,
      "name": "Plant_Leaves_Redwood"
    },
    {
      "x": -1,
      "y": 49,
      "z": 3,
      "name": "Plant_Leaves_Redwood"
    },
    {
      "x": -1,
      "y": 51,
      "z": 3,
      "name": "Plant_Leaves_Redwood"
    },
    {
      "x": -1,
      "y": 52,
      "z": 3,
      "name": "Plant_Leaves_Redwood"
    },
    {
      "x": -1,
      "y": 53,
      "z": 3,
      "name": "Plant_Leaves_Redwood"
    },
    {
      "x": -1,
      "y": 57,
      "z": 3,
      "name": "Plant_Leaves_Redwood",
      "support": 15,
      "rotation": 1
    },
    {
      "x": -1,
      "y": 26,
      "z": 4,
      "name": "Plant_Leaves_Redwood"
    },
    {
      "x": -1,
      "y": 27,
      "z": 4,
      "name": "Plant_Leaves_Redwood"
    },
    {
      "x": -1,
      "y": 32,
      "z": 4,
      "name": "Plant_Leaves_Redwood",
      "support": 15,
      "rotation": 1
    },
    {
      "x": -1,
      "y": 37,
      "z": 4,
      "name": "Wood_Redwood_Branch_Long",
      "support": 15,
      "rotation": 6
    },
    {
      "x": -1,
      "y": 38,
      "z": 4,
      "name": "Plant_Leaves_Redwood",
      "support": 15,
      "rotation": 1
    },
    {
      "x": -1,
      "y": 39,
      "z": 4,
      "name": "Plant_Leaves_Redwood"
    },
    {
      "x": -1,
      "y": 40,
      "z": 4,
      "name": "Plant_Leaves_Redwood"
    },
    {
      "x": -1,
      "y": 47,
      "z": 4,
      "name": "Plant_Leaves_Redwood"
    },
    {
      "x": -1,
      "y": 48,
      "z": 4,
      "name": "Plant_Leaves_Redwood"
    },
    {
      "x": -1,
      "y": 49,
      "z": 4,
      "name": "Plant_Leaves_Redwood"
    },
    {
      "x": -1,
      "y": 52,
      "z": 4,
      "name": "Plant_Leaves_Redwood"
    },
    {
      "x": -1,
      "y": 53,
      "z": 4,
      "name": "Plant_Leaves_Redwood"
    },
    {
      "x": -1,
      "y": 57,
      "z": 4,
      "name": "Plant_Leaves_Redwood",
      "support": 15,
      "rotation": 1
    },
    {
      "x": -1,
      "y": 27,
      "z": 5,
      "name": "Plant_Leaves_Redwood"
    },
    {
      "x": -1,
      "y": 37,
      "z": 5,
      "name": "Wood_Redwood_Branch_Long",
      "support": 15,
      "rotation": 6
    },
    {
      "x": -1,
      "y": 38,
      "z": 5,
      "name": "Plant_Leaves_Redwood",
      "support": 15,
      "rotation": 1
    },
    {
      "x": -1,
      "y": 39,
      "z": 5,
      "name": "Plant_Leaves_Redwood",
      "support": 15,
      "rotation": 1
    },
    {
      "x": -1,
      "y": 40,
      "z": 5,
      "name": "Plant_Leaves_Redwood"
    },
    {
      "x": -1,
      "y": 47,
      "z": 5,
      "name": "Plant_Leaves_Redwood"
    },
    {
      "x": -1,
      "y": 48,
      "z": 5,
      "name": "Plant_Leaves_Redwood"
    },
    {
      "x": -1,
      "y": 50,
      "z": 5,
      "name": "Plant_Leaves_Redwood"
    },
    {
      "x": -1,
      "y": 54,
      "z": 5,
      "name": "Plant_Leaves_Redwood"
    },
    {
      "x": -1,
      "y": 60,
      "z": 5,
      "name": "Plant_Leaves_Redwood"
    },
    {
      "x": -1,
      "y": 37,
      "z": 6,
      "name": "Plant_Leaves_Redwood",
      "support": 15,
      "rotation": 1
    },
    {
      "x": -1,
      "y": 38,
      "z": 6,
      "name": "Plant_Leaves_Redwood",
      "support": 15,
      "rotation": 1
    },
    {
      "x": -1,
      "y": 39,
      "z": 6,
      "name": "Plant_Leaves_Redwood",
      "support": 15,
      "rotation": 1
    },
    {
      "x": -1,
      "y": 47,
      "z": 6,
      "name": "Plant_Leaves_Redwood"
    },
    {
      "x": -1,
      "y": 48,
      "z": 6,
      "name": "Plant_Leaves_Redwood"
    },
    {
      "x": -1,
      "y": 49,
      "z": 6,
      "name": "Plant_Leaves_Redwood"
    },
    {
      "x": -1,
      "y": 59,
      "z": 6,
      "name": "Plant_Leaves_Redwood"
    },
    {
      "x": -1,
      "y": 61,
      "z": 6,
      "name": "Plant_Leaves_Redwood"
    },
    {
      "x": -1,
      "y": 37,
      "z": 7,
      "name": "Plant_Leaves_Redwood"
    },
    {
      "x": -1,
      "y": 60,
      "z": 7,
      "name": "Plant_Leaves_Redwood"
    },
    {
      "x": -1,
      "y": 37,
      "z": 8,
      "name": "Plant_Leaves_Redwood"
    },
    {
      "x": 0,
      "y": 39,
      "z": -9,
      "name": "Plant_Leaves_Redwood",
      "support": 15,
      "rotation": 3
    },
    {
      "x": 0,
      "y": 40,
      "z": -9,
      "name": "Plant_Leaves_Redwood",
      "support": 15,
      "rotation": 3
    },
    {
      "x": 0,
      "y": 41,
      "z": -9,
      "name": "Plant_Leaves_Redwood",
      "support": 15,
      "rotation": 3
    },
    {
      "x": 0,
      "y": 42,
      "z": -9,
      "name": "Plant_Leaves_Redwood",
      "support": 15,
      "rotation": 3
    },
    {
      "x": 0,
      "y": 31,
      "z": -8,
      "name": "Plant_Leaves_Redwood",
      "support": 15,
      "rotation": 3
    },
    {
      "x": 0,
      "y": 32,
      "z": -8,
      "name": "Plant_Leaves_Redwood"
    },
    {
      "x": 0,
      "y": 39,
      "z": -8,
      "name": "Wood_Redwood_Branch_Long",
      "support": 15,
      "rotation": 4
    },
    {
      "x": 0,
      "y": 40,
      "z": -8,
      "name": "Plant_Leaves_Redwood",
      "support": 15,
      "rotation": 3
    },
    {
      "x": 0,
      "y": 41,
      "z": -8,
      "name": "Plant_Leaves_Redwood",
      "support": 15,
      "rotation": 3
    },
    {
      "x": 0,
      "y": 47,
      "z": -8,
      "name": "Plant_Leaves_Redwood",
      "support": 15,
      "rotation": 3
    },
    {
      "x": 0,
      "y": 48,
      "z": -8,
      "name": "Plant_Leaves_Redwood",
      "support": 15,
      "rotation": 3
    },
    {
      "x": 0,
      "y": 49,
      "z": -8,
      "name": "Plant_Leaves_Redwood",
      "support": 15,
      "rotation": 3
    },
    {
      "x": 0,
      "y": 50,
      "z": -8,
      "name": "Plant_Leaves_Redwood",
      "support": 15,
      "rotation": 3
    },
    {
      "x": 0,
      "y": 31,
      "z": -7,
      "name": "Plant_Leaves_Redwood",
      "support": 15,
      "rotation": 3
    },
    {
      "x": 0,
      "y": 32,
      "z": -7,
      "name": "Plant_Leaves_Redwood",
      "support": 15,
      "rotation": 3
    },
    {
      "x": 0,
      "y": 33,
      "z": -7,
      "name": "Plant_Leaves_Redwood",
      "support": 15,
      "rotation": 3
    },
    {
      "x": 0,
      "y": 39,
      "z": -7,
      "name": "Wood_Redwood_Branch_Long",
      "support": 15,
      "rotation": 4
    },
    {
      "x": 0,
      "y": 40,
      "z": -7,
      "name": "Plant_Leaves_Redwood",
      "support": 15,
      "rotation": 3
    },
    {
      "x": 0,
      "y": 41,
      "z": -7,
      "name": "Plant_Leaves_Redwood",
      "support": 15,
      "rotation": 3
    },
    {
      "x": 0,
      "y": 42,
      "z": -7,
      "name": "Plant_Leaves_Redwood",
      "support": 15,
      "rotation": 3
    },
    {
      "x": 0,
      "y": 47,
      "z": -7,
      "name": "Wood_Redwood_Branch_Long",
      "support": 15,
      "rotation": 4
    },
    {
      "x": 0,
      "y": 48,
      "z": -7,
      "name": "Plant_Leaves_Redwood",
      "support": 15,
      "rotation": 3
    },
    {
      "x": 0,
      "y": 49,
      "z": -7,
      "name": "Plant_Leaves_Redwood",
      "support": 15,
      "rotation": 3
    },
    {
      "x": 0,
      "y": 59,
      "z": -7,
      "name": "Plant_Leaves_Redwood"
    },
    {
      "x": 0,
      "y": 4,
      "z": -6,
      "name": "Wood_Redwood_Trunk",
      "support": 15
    },
    {
      "x": 0,
      "y": 5,
      "z": -6,
      "name": "Wood_Redwood_Trunk",
      "support": 15
    },
    {
      "x": 0,
      "y": 6,
      "z": -6,
      "name": "Wood_Redwood_Trunk",
      "support": 15
    },
    {
      "x": 0,
      "y": 7,
      "z": -6,
      "name": "Wood_Redwood_Trunk"
    },
    {
      "x": 0,
      "y": 31,
      "z": -6,
      "name": "Plant_Leaves_Redwood",
      "support": 15,
      "rotation": 3
    },
    {
      "x": 0,
      "y": 32,
      "z": -6,
      "name": "Plant_Leaves_Redwood",
      "support": 15,
      "rotation": 3
    },
    {
      "x": 0,
      "y": 33,
      "z": -6,
      "name": "Plant_Leaves_Redwood",
      "support": 15,
      "rotation": 3
    },
    {
      "x": 0,
      "y": 36,
      "z": -6,
      "name": "Plant_Leaves_Redwood",
      "support": 15,
      "rotation": 3
    },
    {
      "x": 0,
      "y": 38,
      "z": -6,
      "name": "Plant_Leaves_Redwood"
    },
    {
      "x": 0,
      "y": 39,
      "z": -6,
      "name": "Wood_Redwood_Branch_Long",
      "support": 15,
      "rotation": 4
    },
    {
      "x": 0,
      "y": 40,
      "z": -6,
      "name": "Plant_Leaves_Redwood",
      "support": 15,
      "rotation": 3
    },
    {
      "x": 0,
      "y": 41,
      "z": -6,
      "name": "Plant_Leaves_Redwood",
      "support": 15,
      "rotation": 3
    },
    {
      "x": 0,
      "y": 42,
      "z": -6,
      "name": "Plant_Leaves_Redwood",
      "support": 15,
      "rotation": 3
    },
    {
      "x": 0,
      "y": 44,
      "z": -6,
      "name": "Plant_Leaves_Redwood"
    },
    {
      "x": 0,
      "y": 47,
      "z": -6,
      "name": "Wood_Redwood_Branch_Long",
      "support": 15,
      "rotation": 4
    },
    {
      "x": 0,
      "y": 48,
      "z": -6,
      "name": "Plant_Leaves_Redwood",
      "support": 15,
      "rotation": 3
    },
    {
      "x": 0,
      "y": 49,
      "z": -6,
      "name": "Plant_Leaves_Redwood",
      "support": 15,
      "rotation": 3
    },
    {
      "x": 0,
      "y": 50,
      "z": -6,
      "name": "Plant_Leaves_Redwood",
      "support": 15,
      "rotation": 3
    },
    {
      "x": 0,
      "y": 54,
      "z": -6,
      "name": "Plant_Leaves_Redwood"
    },
    {
      "x": 0,
      "y": 58,
      "z": -6,
      "name": "Plant_Leaves_Redwood"
    },
    {
      "x": 0,
      "y": 59,
      "z": -6,
      "name": "Plant_Leaves_Redwood"
    },
    {
      "x": 0,
      "y": 60,
      "z": -6,
      "name": "Plant_Leaves_Redwood"
    },
    {
      "x": 0,
      "y": 2,
      "z": -5,
      "name": "Wood_Redwood_Trunk",
      "support": 15
    },
    {
      "x": 0,
      "y": 3,
      "z": -5,
      "name": "Wood_Redwood_Trunk",
      "support": 15
    },
    {
      "x": 0,
      "y": 4,
      "z": -5,
      "name": "Wood_Redwood_Trunk",
      "support": 15,
      "rotation": 5
    },
    {
      "x": 0,
      "y": 5,
      "z": -5,
      "name": "Wood_Redwood_Trunk"
    },
    {
      "x": 0,
      "y": 6,
      "z": -5,
      "name": "Wood_Redwood_Trunk"
    },
    {
      "x": 0,
      "y": 7,
      "z": -5,
      "name": "Wood_Redwood_Trunk"
    },
    {
      "x": 0,
      "y": 8,
      "z": -5,
      "name": "Wood_Redwood_Trunk"
    },
    {
      "x": 0,
      "y": 32,
      "z": -5,
      "name": "Plant_Leaves_Redwood",
      "support": 15,
      "rotation": 3
    },
    {
      "x": 0,
      "y": 36,
      "z": -5,
      "name": "Wood_Redwood_Branch_Long",
      "support": 15,
      "rotation": 4
    },
    {
      "x": 0,
      "y": 37,
      "z": -5,
      "name": "Plant_Leaves_Redwood",
      "support": 15,
      "rotation": 3
    },
    {
      "x": 0,
      "y": 39,
      "z": -5,
      "name": "Wood_Redwood_Trunk",
      "support": 15,
      "rotation": 4
    },
    {
      "x": 0,
      "y": 40,
      "z": -5,
      "name": "Plant_Leaves_Redwood",
      "support": 15,
      "rotation": 3
    },
    {
      "x": 0,
      "y": 41,
      "z": -5,
      "name": "Plant_Leaves_Redwood",
      "support": 15,
      "rotation": 3
    },
    {
      "x": 0,
      "y": 42,
      "z": -5,
      "name": "Plant_Leaves_Redwood"
    },
    {
      "x": 0,
      "y": 43,
      "z": -5,
      "name": "Plant_Leaves_Redwood",
      "support": 15,
      "rotation": 3
    },
    {
      "x": 0,
      "y": 44,
      "z": -5,
      "name": "Plant_Leaves_Redwood"
    },
    {
      "x": 0,
      "y": 45,
      "z": -5,
      "name": "Plant_Leaves_Redwood"
    },
    {
      "x": 0,
      "y": 46,
      "z": -5,
      "name": "Plant_Leaves_Redwood"
    },
    {
      "x": 0,
      "y": 47,
      "z": -5,
      "name": "Wood_Redwood_Branch_Long",
      "support": 15,
      "rotation": 4
    },
    {
      "x": 0,
      "y": 48,
      "z": -5,
      "name": "Plant_Leaves_Redwood",
      "support": 15,
      "rotation": 3
    },
    {
      "x": 0,
      "y": 49,
      "z": -5,
      "name": "Plant_Leaves_Redwood",
      "support": 15,
      "rotation": 3
    },
    {
      "x": 0,
      "y": 50,
      "z": -5,
      "name": "Plant_Leaves_Redwood",
      "support": 15,
      "rotation": 3
    },
    {
      "x": 0,
      "y": 55,
      "z": -5,
      "name": "Plant_Leaves_Redwood"
    },
    {
      "x": 0,
      "y": 57,
      "z": -5,
      "name": "Plant_Leaves_Redwood"
    },
    {
      "x": 0,
      "y": 58,
      "z": -5,
      "name": "Plant_Leaves_Redwood"
    },
    {
      "x": 0,
      "y": 60,
      "z": -5,
      "name": "Plant_Leaves_Redwood"
    },
    {
      "x": 0,
      "y": 62,
      "z": -5,
      "name": "Plant_Leaves_Redwood",
      "support": 15,
      "rotation": 3
    },
    {
      "x": 0,
      "y": 4,
      "z": -4,
      "name": "Wood_Redwood_Trunk",
      "support": 15
    },
    {
      "x": 0,
      "y": 5,
      "z": -4,
      "name": "Wood_Redwood_Trunk"
    },
    {
      "x": 0,
      "y": 6,
      "z": -4,
      "name": "Wood_Redwood_Trunk"
    },
    {
      "x": 0,
      "y": 7,
      "z": -4,
      "name": "Wood_Redwood_Trunk"
    },
    {
      "x": 0,
      "y": 8,
      "z": -4,
      "name": "Wood_Redwood_Trunk"
    },
    {
      "x": 0,
      "y": 9,
      "z": -4,
      "name": "Wood_Redwood_Trunk"
    },
    {
      "x": 0,
      "y": 10,
      "z": -4,
      "name": "Wood_Redwood_Trunk"
    },
    {
      "x": 0,
      "y": 11,
      "z": -4,
      "name": "Wood_Redwood_Trunk"
    },
    {
      "x": 0,
      "y": 31,
      "z": -4,
      "name": "Plant_Leaves_Redwood",
      "support": 15,
      "rotation": 3
    },
    {
      "x": 0,
      "y": 32,
      "z": -4,
      "name": "Plant_Leaves_Redwood",
      "support": 15,
      "rotation": 3
    },
    {
      "x": 0,
      "y": 36,
      "z": -4,
      "name": "Wood_Redwood_Branch_Long",
      "support": 15,
      "rotation": 4
    },
    {
      "x": 0,
      "y": 37,
      "z": -4,
      "name": "Plant_Leaves_Redwood",
      "support": 15,
      "rotation": 3
    },
    {
      "x": 0,
      "y": 39,
      "z": -4,
      "name": "Wood_Redwood_Trunk",
      "support": 15,
      "rotation": 4
    },
    {
      "x": 0,
      "y": 40,
      "z": -4,
      "name": "Plant_Leaves_Redwood",
      "support": 15,
      "rotation": 3
    },
    {
      "x": 0,
      "y": 43,
      "z": -4,
      "name": "Plant_Leaves_Redwood",
      "support": 15,
      "rotation": 3
    },
    {
      "x": 0,
      "y": 44,
      "z": -4,
      "name": "Plant_Leaves_Redwood",
      "support": 15,
      "rotation": 3
    },
    {
      "x": 0,
      "y": 45,
      "z": -4,
      "name": "Plant_Leaves_Redwood"
    },
    {
      "x": 0,
      "y": 47,
      "z": -4,
      "name": "Wood_Redwood_Trunk",
      "support": 15,
      "rotation": 4
    },
    {
      "x": 0,
      "y": 48,
      "z": -4,
      "name": "Plant_Leaves_Redwood",
      "support": 15,
      "rotation": 3
    },
    {
      "x": 0,
      "y": 49,
      "z": -4,
      "name": "Plant_Leaves_Redwood",
      "support": 15,
      "rotation": 3
    },
    {
      "x": 0,
      "y": 54,
      "z": -4,
      "name": "Plant_Leaves_Redwood"
    },
    {
      "x": 0,
      "y": 58,
      "z": -4,
      "name": "Plant_Leaves_Redwood"
    },
    {
      "x": 0,
      "y": 59,
      "z": -4,
      "name": "Plant_Leaves_Redwood"
    },
    {
      "x": 0,
      "y": 60,
      "z": -4,
      "name": "Plant_Leaves_Redwood"
    },
    {
      "x": 0,
      "y": 62,
      "z": -4,
      "name": "Plant_Leaves_Redwood",
      "support": 15,
      "rotation": 3
    },
    {
      "x": 0,
      "y": 63,
      "z": -4,
      "name": "Plant_Leaves_Redwood",
      "support": 15,
      "rotation": 3
    },
    {
      "x": 0,
      "y": 7,
      "z": -3,
      "name": "Wood_Redwood_Trunk"
    },
    {
      "x": 0,
      "y": 8,
      "z": -3,
      "name": "Wood_Redwood_Trunk"
    },
    {
      "x": 0,
      "y": 9,
      "z": -3,
      "name": "Wood_Redwood_Trunk"
    },
    {
      "x": 0,
      "y": 10,
      "z": -3,
      "name": "Wood_Redwood_Trunk"
    },
    {
      "x": 0,
      "y": 11,
      "z": -3,
      "name": "Wood_Redwood_Trunk"
    },
    {
      "x": 0,
      "y": 12,
      "z": -3,
      "name": "Wood_Redwood_Trunk"
    },
    {
      "x": 0,
      "y": 13,
      "z": -3,
      "name": "Wood_Redwood_Trunk"
    },
    {
      "x": 0,
      "y": 32,
      "z": -3,
      "name": "Plant_Leaves_Redwood",
      "support": 15,
      "rotation": 3
    },
    {
      "x": 0,
      "y": 36,
      "z": -3,
      "name": "Wood_Redwood_Branch_Long",
      "support": 15,
      "rotation": 4
    },
    {
      "x": 0,
      "y": 37,
      "z": -3,
      "name": "Plant_Leaves_Redwood",
      "support": 15,
      "rotation": 3
    },
    {
      "x": 0,
      "y": 39,
      "z": -3,
      "name": "Wood_Redwood_Trunk",
      "support": 15,
      "rotation": 4
    },
    {
      "x": 0,
      "y": 47,
      "z": -3,
      "name": "Wood_Redwood_Trunk",
      "support": 15,
      "rotation": 4
    },
    {
      "x": 0,
      "y": 48,
      "z": -3,
      "name": "Plant_Leaves_Redwood",
      "support": 15,
      "rotation": 3
    },
    {
      "x": 0,
      "y": 59,
      "z": -3,
      "name": "Plant_Leaves_Redwood"
    },
    {
      "x": 0,
      "y": 62,
      "z": -3,
      "name": "Plant_Leaves_Redwood",
      "support": 15
    },
    {
      "x": 0,
      "y": 63,
      "z": -3,
      "name": "Plant_Leaves_Redwood",
      "support": 15
    },
    {
      "x": 0,
      "y": 66,
      "z": -3,
      "name": "Plant_Leaves_Redwood",
      "support": 15
    },
    {
      "x": 0,
      "y": 8,
      "z": -2,
      "name": "Wood_Redwood_Trunk"
    },
    {
      "x": 0,
      "y": 9,
      "z": -2,
      "name": "Wood_Redwood_Trunk"
    },
    {
      "x": 0,
      "y": 10,
      "z": -2,
      "name": "Wood_Redwood_Trunk"
    },
    {
      "x": 0,
      "y": 11,
      "z": -2,
      "name": "Wood_Redwood_Trunk"
    },
    {
      "x": 0,
      "y": 12,
      "z": -2,
      "name": "Wood_Redwood_Trunk"
    },
    {
      "x": 0,
      "y": 13,
      "z": -2,
      "name": "Wood_Redwood_Trunk"
    },
    {
      "x": 0,
      "y": 14,
      "z": -2,
      "name": "Wood_Redwood_Trunk"
    },
    {
      "x": 0,
      "y": 15,
      "z": -2,
      "name": "Wood_Redwood_Trunk"
    },
    {
      "x": 0,
      "y": 16,
      "z": -2,
      "name": "Wood_Redwood_Trunk"
    },
    {
      "x": 0,
      "y": 17,
      "z": -2,
      "name": "Wood_Redwood_Trunk"
    },
    {
      "x": 0,
      "y": 18,
      "z": -2,
      "name": "Wood_Redwood_Trunk"
    },
    {
      "x": 0,
      "y": 19,
      "z": -2,
      "name": "Wood_Redwood_Trunk"
    },
    {
      "x": 0,
      "y": 20,
      "z": -2,
      "name": "Wood_Redwood_Trunk"
    },
    {
      "x": 0,
      "y": 21,
      "z": -2,
      "name": "Wood_Redwood_Trunk"
    },
    {
      "x": 0,
      "y": 22,
      "z": -2,
      "name": "Wood_Redwood_Trunk"
    },
    {
      "x": 0,
      "y": 23,
      "z": -2,
      "name": "Wood_Redwood_Trunk"
    },
    {
      "x": 0,
      "y": 24,
      "z": -2,
      "name": "Wood_Redwood_Trunk"
    },
    {
      "x": 0,
      "y": 25,
      "z": -2,
      "name": "Wood_Redwood_Trunk"
    },
    {
      "x": 0,
      "y": 26,
      "z": -2,
      "name": "Wood_Redwood_Trunk"
    },
    {
      "x": 0,
      "y": 27,
      "z": -2,
      "name": "Wood_Redwood_Trunk"
    },
    {
      "x": 0,
      "y": 28,
      "z": -2,
      "name": "Wood_Redwood_Trunk"
    },
    {
      "x": 0,
      "y": 29,
      "z": -2,
      "name": "Wood_Redwood_Trunk"
    },
    {
      "x": 0,
      "y": 30,
      "z": -2,
      "name": "Wood_Redwood_Trunk"
    },
    {
      "x": 0,
      "y": 31,
      "z": -2,
      "name": "Wood_Redwood_Trunk"
    },
    {
      "x": 0,
      "y": 32,
      "z": -2,
      "name": "Wood_Redwood_Trunk"
    },
    {
      "x": 0,
      "y": 33,
      "z": -2,
      "name": "Wood_Redwood_Trunk"
    },
    {
      "x": 0,
      "y": 34,
      "z": -2,
      "name": "Wood_Redwood_Trunk"
    },
    {
      "x": 0,
      "y": 35,
      "z": -2,
      "name": "Wood_Redwood_Trunk"
    },
    {
      "x": 0,
      "y": 36,
      "z": -2,
      "name": "Wood_Redwood_Trunk"
    },
    {
      "x": 0,
      "y": 37,
      "z": -2,
      "name": "Wood_Redwood_Trunk"
    },
    {
      "x": 0,
      "y": 38,
      "z": -2,
      "name": "Wood_Redwood_Trunk"
    },
    {
      "x": 0,
      "y": 39,
      "z": -2,
      "name": "Wood_Redwood_Trunk"
    },
    {
      "x": 0,
      "y": 40,
      "z": -2,
      "name": "Wood_Redwood_Trunk"
    },
    {
      "x": 0,
      "y": 47,
      "z": -2,
      "name": "Wood_Redwood_Trunk",
      "support": 15,
      "rotation": 4
    },
    {
      "x": 0,
      "y": 62,
      "z": -2,
      "name": "Wood_Redwood_Trunk",
      "support": 15,
      "rotation": 5
    },
    {
      "x": 0,
      "y": 63,
      "z": -2,
      "name": "Plant_Leaves_Redwood",
      "support": 15
    },
    {
      "x": 0,
      "y": 64,
      "z": -2,
      "name": "Plant_Leaves_Redwood",
      "support": 15
    },
    {
      "x": 0,
      "y": 65,
      "z": -2,
      "name": "Plant_Leaves_Redwood",
      "support": 15
    },
    {
      "x": 0,
      "y": 67,
      "z": -2,
      "name": "Plant_Leaves_Redwood",
      "support": 15
    },
    {
      "x": 0,
      "y": 7,
      "z": -1,
      "name": "Wood_Redwood_Trunk"
    },
    {
      "x": 0,
      "y": 8,
      "z": -1,
      "name": "Wood_Redwood_Trunk"
    },
    {
      "x": 0,
      "y": 9,
      "z": -1,
      "name": "Wood_Redwood_Trunk"
    },
    {
      "x": 0,
      "y": 10,
      "z": -1,
      "name": "Wood_Redwood_Trunk"
    },
    {
      "x": 0,
      "y": 11,
      "z": -1,
      "name": "Wood_Redwood_Trunk"
    },
    {
      "x": 0,
      "y": 12,
      "z": -1,
      "name": "Wood_Redwood_Trunk"
    },
    {
      "x": 0,
      "y": 13,
      "z": -1,
      "name": "Wood_Redwood_Trunk"
    },
    {
      "x": 0,
      "y": 14,
      "z": -1,
      "name": "Wood_Redwood_Trunk"
    },
    {
      "x": 0,
      "y": 15,
      "z": -1,
      "name": "Wood_Redwood_Trunk"
    },
    {
      "x": 0,
      "y": 16,
      "z": -1,
      "name": "Wood_Redwood_Trunk"
    },
    {
      "x": 0,
      "y": 17,
      "z": -1,
      "name": "Wood_Redwood_Trunk"
    },
    {
      "x": 0,
      "y": 18,
      "z": -1,
      "name": "Wood_Redwood_Trunk"
    },
    {
      "x": 0,
      "y": 19,
      "z": -1,
      "name": "Wood_Redwood_Trunk"
    },
    {
      "x": 0,
      "y": 20,
      "z": -1,
      "name": "Wood_Redwood_Trunk"
    },
    {
      "x": 0,
      "y": 21,
      "z": -1,
      "name": "Wood_Redwood_Trunk"
    },
    {
      "x": 0,
      "y": 22,
      "z": -1,
      "name": "Wood_Redwood_Trunk"
    },
    {
      "x": 0,
      "y": 23,
      "z": -1,
      "name": "Wood_Redwood_Trunk"
    },
    {
      "x": 0,
      "y": 24,
      "z": -1,
      "name": "Wood_Redwood_Trunk"
    },
    {
      "x": 0,
      "y": 25,
      "z": -1,
      "name": "Wood_Redwood_Trunk"
    },
    {
      "x": 0,
      "y": 26,
      "z": -1,
      "name": "Wood_Redwood_Trunk"
    },
    {
      "x": 0,
      "y": 27,
      "z": -1,
      "name": "Wood_Redwood_Trunk"
    },
    {
      "x": 0,
      "y": 28,
      "z": -1,
      "name": "Wood_Redwood_Trunk"
    },
    {
      "x": 0,
      "y": 29,
      "z": -1,
      "name": "Wood_Redwood_Trunk"
    },
    {
      "x": 0,
      "y": 30,
      "z": -1,
      "name": "Wood_Redwood_Trunk"
    },
    {
      "x": 0,
      "y": 31,
      "z": -1,
      "name": "Wood_Redwood_Trunk"
    },
    {
      "x": 0,
      "y": 32,
      "z": -1,
      "name": "Wood_Redwood_Trunk"
    },
    {
      "x": 0,
      "y": 33,
      "z": -1,
      "name": "Wood_Redwood_Trunk"
    },
    {
      "x": 0,
      "y": 34,
      "z": -1,
      "name": "Wood_Redwood_Trunk"
    },
    {
      "x": 0,
      "y": 35,
      "z": -1,
      "name": "Wood_Redwood_Trunk"
    },
    {
      "x": 0,
      "y": 36,
      "z": -1,
      "name": "Wood_Redwood_Trunk"
    },
    {
      "x": 0,
      "y": 37,
      "z": -1,
      "name": "Wood_Redwood_Trunk"
    },
    {
      "x": 0,
      "y": 38,
      "z": -1,
      "name": "Wood_Redwood_Trunk"
    },
    {
      "x": 0,
      "y": 39,
      "z": -1,
      "name": "Wood_Redwood_Trunk"
    },
    {
      "x": 0,
      "y": 40,
      "z": -1,
      "name": "Wood_Redwood_Trunk"
    },
    {
      "x": 0,
      "y": 41,
      "z": -1,
      "name": "Wood_Redwood_Trunk"
    },
    {
      "x": 0,
      "y": 42,
      "z": -1,
      "name": "Wood_Redwood_Trunk"
    },
    {
      "x": 0,
      "y": 43,
      "z": -1,
      "name": "Wood_Redwood_Trunk"
    },
    {
      "x": 0,
      "y": 44,
      "z": -1,
      "name": "Wood_Redwood_Trunk"
    },
    {
      "x": 0,
      "y": 45,
      "z": -1,
      "name": "Wood_Redwood_Trunk"
    },
    {
      "x": 0,
      "y": 46,
      "z": -1,
      "name": "Wood_Redwood_Trunk"
    },
    {
      "x": 0,
      "y": 47,
      "z": -1,
      "name": "Wood_Redwood_Trunk"
    },
    {
      "x": 0,
      "y": 48,
      "z": -1,
      "name": "Wood_Redwood_Trunk"
    },
    {
      "x": 0,
      "y": 49,
      "z": -1,
      "name": "Wood_Redwood_Trunk"
    },
    {
      "x": 0,
      "y": 56,
      "z": -1,
      "name": "Wood_Redwood_Trunk",
      "support": 15,
      "rotation": 5
    },
    {
      "x": 0,
      "y": 62,
      "z": -1,
      "name": "Plant_Leaves_Redwood",
      "support": 15
    },
    {
      "x": 0,
      "y": 63,
      "z": -1,
      "name": "Plant_Leaves_Redwood",
      "support": 15
    },
    {
      "x": 0,
      "y": 65,
      "z": -1,
      "name": "Plant_Leaves_Redwood",
      "support": 15
    },
    {
      "x": 0,
      "y": 66,
      "z": -1,
      "name": "Plant_Leaves_Redwood",
      "support": 15
    },
    {
      "x": 0,
      "y": 67,
      "z": -1,
      "name": "Plant_Leaves_Redwood",
      "support": 15
    },
    {
      "x": 0,
      "y": 68,
      "z": -1,
      "name": "Plant_Leaves_Redwood",
      "support": 15
    },
    {
      "x": 0,
      "y": 4,
      "z": 0,
      "name": "Wood_Redwood_Trunk",
      "support": 15
    },
    {
      "x": 0,
      "y": 5,
      "z": 0,
      "name": "Wood_Redwood_Trunk"
    },
    {
      "x": 0,
      "y": 6,
      "z": 0,
      "name": "Wood_Redwood_Trunk"
    },
    {
      "x": 0,
      "y": 7,
      "z": 0,
      "name": "Wood_Redwood_Trunk"
    },
    {
      "x": 0,
      "y": 8,
      "z": 0,
      "name": "Wood_Redwood_Trunk"
    },
    {
      "x": 0,
      "y": 9,
      "z": 0,
      "name": "Wood_Redwood_Trunk_Full",
      "support": 15
    },
    {
      "x": 0,
      "y": 10,
      "z": 0,
      "name": "Wood_Redwood_Trunk"
    },
    {
      "x": 0,
      "y": 11,
      "z": 0,
      "name": "Wood_Redwood_Trunk"
    },
    {
      "x": 0,
      "y": 12,
      "z": 0,
      "name": "Wood_Redwood_Trunk"
    },
    {
      "x": 0,
      "y": 13,
      "z": 0,
      "name": "Wood_Redwood_Trunk"
    },
    {
      "x": 0,
      "y": 14,
      "z": 0,
      "name": "Wood_Redwood_Trunk"
    },
    {
      "x": 0,
      "y": 15,
      "z": 0,
      "name": "Wood_Redwood_Trunk"
    },
    {
      "x": 0,
      "y": 16,
      "z": 0,
      "name": "Wood_Redwood_Trunk"
    },
    {
      "x": 0,
      "y": 17,
      "z": 0,
      "name": "Wood_Redwood_Trunk"
    },
    {
      "x": 0,
      "y": 18,
      "z": 0,
      "name": "Wood_Redwood_Trunk"
    },
    {
      "x": 0,
      "y": 19,
      "z": 0,
      "name": "Wood_Redwood_Trunk"
    },
    {
      "x": 0,
      "y": 20,
      "z": 0,
      "name": "Wood_Redwood_Trunk"
    },
    {
      "x": 0,
      "y": 21,
      "z": 0,
      "name": "Wood_Redwood_Trunk"
    },
    {
      "x": 0,
      "y": 22,
      "z": 0,
      "name": "Wood_Redwood_Trunk"
    },
    {
      "x": 0,
      "y": 23,
      "z": 0,
      "name": "Wood_Redwood_Trunk"
    },
    {
      "x": 0,
      "y": 24,
      "z": 0,
      "name": "Wood_Redwood_Trunk"
    },
    {
      "x": 0,
      "y": 25,
      "z": 0,
      "name": "Wood_Redwood_Trunk"
    },
    {
      "x": 0,
      "y": 26,
      "z": 0,
      "name": "Wood_Redwood_Trunk"
    },
    {
      "x": 0,
      "y": 27,
      "z": 0,
      "name": "Wood_Redwood_Trunk"
    },
    {
      "x": 0,
      "y": 28,
      "z": 0,
      "name": "Wood_Redwood_Trunk"
    },
    {
      "x": 0,
      "y": 29,
      "z": 0,
      "name": "Wood_Redwood_Trunk"
    },
    {
      "x": 0,
      "y": 30,
      "z": 0,
      "name": "Wood_Redwood_Trunk"
    },
    {
      "x": 0,
      "y": 31,
      "z": 0,
      "name": "Wood_Redwood_Trunk"
    },
    {
      "x": 0,
      "y": 32,
      "z": 0,
      "name": "Wood_Redwood_Trunk"
    },
    {
      "x": 0,
      "y": 33,
      "z": 0,
      "name": "Wood_Redwood_Trunk"
    },
    {
      "x": 0,
      "y": 34,
      "z": 0,
      "name": "Wood_Redwood_Trunk"
    },
    {
      "x": 0,
      "y": 35,
      "z": 0,
      "name": "Wood_Redwood_Trunk"
    },
    {
      "x": 0,
      "y": 36,
      "z": 0,
      "name": "Wood_Redwood_Trunk"
    },
    {
      "x": 0,
      "y": 37,
      "z": 0,
      "name": "Wood_Redwood_Trunk"
    },
    {
      "x": 0,
      "y": 38,
      "z": 0,
      "name": "Wood_Redwood_Trunk"
    },
    {
      "x": 0,
      "y": 39,
      "z": 0,
      "name": "Wood_Redwood_Trunk"
    },
    {
      "x": 0,
      "y": 40,
      "z": 0,
      "name": "Wood_Redwood_Trunk"
    },
    {
      "x": 0,
      "y": 41,
      "z": 0,
      "name": "Wood_Redwood_Trunk"
    },
    {
      "x": 0,
      "y": 42,
      "z": 0,
      "name": "Wood_Redwood_Trunk"
    },
    {
      "x": 0,
      "y": 43,
      "z": 0,
      "name": "Wood_Redwood_Trunk"
    },
    {
      "x": 0,
      "y": 44,
      "z": 0,
      "name": "Wood_Redwood_Trunk"
    },
    {
      "x": 0,
      "y": 45,
      "z": 0,
      "name": "Wood_Redwood_Trunk"
    },
    {
      "x": 0,
      "y": 46,
      "z": 0,
      "name": "Wood_Redwood_Trunk"
    },
    {
      "x": 0,
      "y": 47,
      "z": 0,
      "name": "Wood_Redwood_Trunk"
    },
    {
      "x": 0,
      "y": 48,
      "z": 0,
      "name": "Wood_Redwood_Trunk"
    },
    {
      "x": 0,
      "y": 49,
      "z": 0,
      "name": "Wood_Redwood_Trunk"
    },
    {
      "x": 0,
      "y": 52,
      "z": 0,
      "name": "Plant_Leaves_Redwood",
      "support": 15,
      "rotation": 1
    },
    {
      "x": 0,
      "y": 66,
      "z": 0,
      "name": "Plant_Leaves_Redwood",
      "support": 15
    },
    {
      "x": 0,
      "y": 67,
      "z": 0,
      "name": "Plant_Leaves_Redwood",
      "support": 15
    },
    {
      "x": 0,
      "y": 4,
      "z": 1,
      "name": "Wood_Redwood_Trunk",
      "support": 15
    },
    {
      "x": 0,
      "y": 5,
      "z": 1,
      "name": "Wood_Redwood_Trunk"
    },
    {
      "x": 0,
      "y": 6,
      "z": 1,
      "name": "Wood_Redwood_Trunk"
    },
    {
      "x": 0,
      "y": 7,
      "z": 1,
      "name": "Wood_Redwood_Trunk"
    },
    {
      "x": 0,
      "y": 8,
      "z": 1,
      "name": "Wood_Redwood_Trunk"
    },
    {
      "x": 0,
      "y": 9,
      "z": 1,
      "name": "Wood_Redwood_Trunk"
    },
    {
      "x": 0,
      "y": 10,
      "z": 1,
      "name": "Wood_Redwood_Trunk"
    },
    {
      "x": 0,
      "y": 11,
      "z": 1,
      "name": "Wood_Redwood_Trunk"
    },
    {
      "x": 0,
      "y": 26,
      "z": 1,
      "name": "Plant_Leaves_Redwood",
      "support": 15,
      "rotation": 1
    },
    {
      "x": 0,
      "y": 28,
      "z": 1,
      "name": "Plant_Leaves_Redwood"
    },
    {
      "x": 0,
      "y": 37,
      "z": 1,
      "name": "Wood_Redwood_Trunk",
      "support": 15,
      "rotation": 6
    },
    {
      "x": 0,
      "y": 46,
      "z": 1,
      "name": "Plant_Leaves_Redwood"
    },
    {
      "x": 0,
      "y": 47,
      "z": 1,
      "name": "Plant_Leaves_Redwood",
      "support": 15,
      "rotation": 1
    },
    {
      "x": 0,
      "y": 48,
      "z": 1,
      "name": "Plant_Leaves_Redwood",
      "support": 15,
      "rotation": 1
    },
    {
      "x": 0,
      "y": 53,
      "z": 1,
      "name": "Plant_Leaves_Redwood",
      "support": 15,
      "rotation": 1
    },
    {
      "x": 0,
      "y": 5,
      "z": 2,
      "name": "Wood_Redwood_Trunk"
    },
    {
      "x": 0,
      "y": 6,
      "z": 2,
      "name": "Wood_Redwood_Trunk"
    },
    {
      "x": 0,
      "y": 7,
      "z": 2,
      "name": "Wood_Redwood_Trunk"
    },
    {
      "x": 0,
      "y": 8,
      "z": 2,
      "name": "Wood_Redwood_Trunk"
    },
    {
      "x": 0,
      "y": 9,
      "z": 2,
      "name": "Wood_Redwood_Trunk"
    },
    {
      "x": 0,
      "y": 10,
      "z": 2,
      "name": "Wood_Redwood_Trunk"
    },
    {
      "x": 0,
      "y": 25,
      "z": 2,
      "name": "Plant_Leaves_Redwood"
    },
    {
      "x": 0,
      "y": 26,
      "z": 2,
      "name": "Plant_Leaves_Redwood"
    },
    {
      "x": 0,
      "y": 27,
      "z": 2,
      "name": "Plant_Leaves_Redwood",
      "support": 15,
      "rotation": 1
    },
    {
      "x": 0,
      "y": 28,
      "z": 2,
      "name": "Plant_Leaves_Redwood"
    },
    {
      "x": 0,
      "y": 29,
      "z": 2,
      "name": "Plant_Leaves_Redwood"
    },
    {
      "x": 0,
      "y": 32,
      "z": 2,
      "name": "Wood_Redwood_Branch_Corner",
      "support": 15,
      "rotation": 51
    },
    {
      "x": 0,
      "y": 33,
      "z": 2,
      "name": "Plant_Leaves_Redwood",
      "support": 15,
      "rotation": 1
    },
    {
      "x": 0,
      "y": 34,
      "z": 2,
      "name": "Plant_Leaves_Redwood",
      "support": 15,
      "rotation": 1
    },
    {
      "x": 0,
      "y": 37,
      "z": 2,
      "name": "Wood_Redwood_Trunk",
      "support": 15,
      "rotation": 6
    },
    {
      "x": 0,
      "y": 38,
      "z": 2,
      "name": "Plant_Leaves_Redwood",
      "support": 15,
      "rotation": 1
    },
    {
      "x": 0,
      "y": 39,
      "z": 2,
      "name": "Plant_Leaves_Redwood"
    },
    {
      "x": 0,
      "y": 40,
      "z": 2,
      "name": "Plant_Leaves_Redwood"
    },
    {
      "x": 0,
      "y": 45,
      "z": 2,
      "name": "Plant_Leaves_Redwood"
    },
    {
      "x": 0,
      "y": 46,
      "z": 2,
      "name": "Plant_Leaves_Redwood"
    },
    {
      "x": 0,
      "y": 47,
      "z": 2,
      "name": "Plant_Leaves_Redwood",
      "support": 15,
      "rotation": 1
    },
    {
      "x": 0,
      "y": 48,
      "z": 2,
      "name": "Plant_Leaves_Redwood",
      "support": 15,
      "rotation": 1
    },
    {
      "x": 0,
      "y": 49,
      "z": 2,
      "name": "Plant_Leaves_Redwood"
    },
    {
      "x": 0,
      "y": 51,
      "z": 2,
      "name": "Plant_Leaves_Redwood"
    },
    {
      "x": 0,
      "y": 52,
      "z": 2,
      "name": "Plant_Leaves_Redwood",
      "support": 15,
      "rotation": 1
    },
    {
      "x": 0,
      "y": 53,
      "z": 2,
      "name": "Plant_Leaves_Redwood",
      "support": 15,
      "rotation": 1
    },
    {
      "x": 0,
      "y": 57,
      "z": 2,
      "name": "Wood_Redwood_Branch_Corner",
      "support": 15,
      "rotation": 51
    },
    {
      "x": 0,
      "y": 58,
      "z": 2,
      "name": "Plant_Leaves_Redwood",
      "support": 15,
      "rotation": 1
    },
    {
      "x": 0,
      "y": 59,
      "z": 2,
      "name": "Plant_Leaves_Redwood",
      "support": 15,
      "rotation": 1
    },
    {
      "x": 0,
      "y": 6,
      "z": 3,
      "name": "Wood_Redwood_Trunk"
    },
    {
