{
  "version": 8,
  "blockIdVersion": 11,
  "anchorX": 2,
  "anchorY": 4,
  "anchorZ": -3,
  "blocks": [
    {
      "x": -20,
      "y": 11,
      "z": -2,
      "name": "Wood_Darkwood_Stairs",
      "rotation": 9
    },
    {
      "x": -20,
      "y": 12,
      "z": -2,
      "name": "Wood_Darkwood_Planks"
    },
    {
      "x": -19,
      "y": 10,
      "z": -2,
      "name": "Wood_Darkwood_Stairs",
      "rotation": 9
    },
    {
      "x": -19,
      "y": 11,
      "z": -2,
      "name": "Wood_Darkwood_Planks"
    },
    {
      "x": -19,
      "y": 12,
      "z": -2,
      "name": "Wood_Darkwood_Stairs",
      "rotation": 1
    },
    {
      "x": -18,
      "y": 10,
      "z": -4,
      "name": "Wood_Ash_Trunk",
      "support": 15,
      "rotation": 4
    },
    {
      "x": -18,
      "y": 9,
      "z": -3,
      "name": "Wood_Darkwood_Stairs",
      "rotation": 9
    },
    {
      "x": -18,
      "y": 10,
      "z": -3,
      "name": "Wood_Ash_Trunk",
      "support": 15,
      "rotation": 4
    },
    {
      "x": -18,
      "y": 10,
      "z": -2,
      "name": "Wood_Darkwood_Planks"
    },
    {
      "x": -18,
      "y": 11,
      "z": -2,
      "name": "Wood_Darkwood_Planks"
    },
    {
      "x": -17,
      "y": 8,
      "z": -3,
      "name": "Wood_Darkwood_Stairs",
      "rotation": 9
    },
    {
      "x": -17,
      "y": 9,
      "z": -3,
      "name": "Wood_Darkwood_Planks"
    },
    {
      "x": -17,
      "y": 10,
      "z": -2,
      "name": "Wood_Darkwood_Stairs",
      "rotation": 1
    },
    {
      "x": -17,
      "y": 12,
      "z": -2,
      "name": "Deco_Rope_Diagonal",
      "rotation": 3
    },
    {
      "x": -16,
      "y": 7,
      "z": -3,
      "name": "Wood_Darkwood_Stairs",
      "rotation": 9
    },
    {
      "x": -16,
      "y": 8,
      "z": -3,
      "name": "Wood_Darkwood_Planks"
    },
    {
      "x": -16,
      "y": 13,
      "z": -2,
      "name": "Deco_Rope_Diagonal",
      "rotation": 3
    },
    {
      "x": -15,
      "y": 8,
      "z": -4,
      "name": "Wood_Deadwood_Planks"
    },
    {
      "x": -15,
      "y": 6,
      "z": -3,
      "name": "Wood_Darkwood_Stairs",
      "rotation": 9
    },
    {
      "x": -15,
      "y": 7,
      "z": -3,
      "name": "Wood_Darkwood_Planks"
    },
    {
      "x": -15,
      "y": 8,
      "z": -3,
      "name": "Wood_Deadwood_Planks"
    },
    {
      "x": -15,
      "y": 7,
      "z": -2,
      "name": "Wood_Deadwood_Planks"
    },
    {
      "x": -15,
      "y": 11,
      "z": -2,
      "name": "Wood_Darkwood_Planks_Half",
      "rotation": 7
    },
    {
      "x": -15,
      "y": 12,
      "z": -2,
      "name": "Wood_Darkwood_Planks"
    },
    {
      "x": -15,
      "y": 13,
      "z": -2,
      "name": "Wood_Darkwood_Planks"
    },
    {
      "x": -14,
      "y": 5,
      "z": -4,
      "name": "Wood_Darkwood_Stairs",
      "rotation": 9
    },
    {
      "x": -14,
      "y": 7,
      "z": -4,
      "name": "Wood_Deadwood_Planks"
    },
    {
      "x": -14,
      "y": 8,
      "z": -4,
      "name": "Wood_Deadwood_Planks"
    },
    {
      "x": -14,
      "y": 9,
      "z": -4,
      "name": "Wood_Deadwood_Planks"
    },
    {
      "x": -14,
      "y": 6,
      "z": -3,
      "name": "Wood_Darkwood_Planks"
    },
    {
      "x": -14,
      "y": 7,
      "z": -3,
      "name": "Wood_Deadwood_Planks"
    },
    {
      "x": -14,
      "y": 8,
      "z": -3,
      "name": "Wood_Deadwood_Planks"
    },
    {
      "x": -14,
      "y": 9,
      "z": -3,
      "name": "Wood_Deadwood_Planks"
    },
    {
      "x": -14,
      "y": 6,
      "z": -2,
      "name": "Wood_Deadwood_Planks"
    },
    {
      "x": -14,
      "y": 7,
      "z": -2,
      "name": "Wood_Deadwood_Planks"
    },
    {
      "x": -14,
      "y": 8,
      "z": -2,
      "name": "Wood_Deadwood_Planks"
    },
    {
      "x": -14,
      "y": 9,
      "z": -2,
      "name": "Wood_Deadwood_Planks"
    },
    {
      "x": -14,
      "y": 10,
      "z": -2,
      "name": "Wood_Darkwood_Planks"
    },
    {
      "x": -14,
      "y": 11,
      "z": -2,
      "name": "Wood_Darkwood_Planks"
    },
    {
      "x": -14,
      "y": 12,
      "z": -2,
      "name": "Wood_Darkwood_Planks_Half",
      "rotation": 5
    },
    {
      "x": -13,
      "y": 5,
      "z": -5,
      "name": "Wood_Deadwood_Planks"
    },
    {
      "x": -13,
      "y": 8,
      "z": -5,
      "name": "Wood_Deadwood_Planks"
    },
    {
      "x": -13,
      "y": 9,
      "z": -5,
      "name": "Wood_Deadwood_Planks"
    },
    {
      "x": -13,
      "y": 4,
      "z": -4,
      "name": "Wood_Darkwood_Stairs",
      "rotation": 9
    },
    {
      "x": -13,
      "y": 5,
      "z": -4,
      "name": "Wood_Darkwood_Planks"
    },
    {
      "x": -13,
      "y": 6,
      "z": -4,
      "name": "Wood_Deadwood_Planks"
    },
    {
      "x": -13,
      "y": 7,
      "z": -4,
      "name": "Wood_Deadwood_Planks"
    },
    {
      "x": -13,
      "y": 8,
      "z": -4,
      "name": "Wood_Deadwood_Planks"
    },
    {
      "x": -13,
      "y": 9,
      "z": -4,
      "name": "Wood_Deadwood_Planks"
    },
    {
      "x": -13,
      "y": 5,
      "z": -3,
      "name": "Wood_Deadwood_Planks"
    },
    {
      "x": -13,
      "y": 6,
      "z": -3,
      "name": "Wood_Darkwood_Planks"
    },
    {
      "x": -13,
      "y": 7,
      "z": -3,
      "name": "Wood_Darkwood_Planks"
    },
    {
      "x": -13,
      "y": 8,
      "z": -3,
      "name": "Wood_Darkwood_Planks"
    },
    {
      "x": -13,
      "y": 9,
      "z": -3,
      "name": "Wood_Darkwood_Planks"
    },
    {
      "x": -13,
      "y": 6,
      "z": -2,
      "name": "Wood_Deadwood_Planks"
    },
    {
      "x": -13,
      "y": 7,
      "z": -2,
      "name": "Wood_Deadwood_Planks"
    },
    {
      "x": -13,
      "y": 8,
      "z": -2,
      "name": "Wood_Deadwood_Planks"
    },
    {
      "x": -13,
      "y": 9,
      "z": -2,
      "name": "Wood_Deadwood_Planks"
    },
    {
      "x": -13,
      "y": 10,
      "z": -2,
      "name": "Soil_Snow_Half"
    },
    {
      "x": -13,
      "y": 7,
      "z": -1,
      "name": "Wood_Deadwood_Planks"
    },
    {
      "x": -13,
      "y": 8,
      "z": -1,
      "name": "Wood_Deadwood_Planks"
    },
    {
      "x": -12,
      "y": 5,
      "z": -6,
      "name": "Wood_Deadwood_Planks"
    },
    {
      "x": -12,
      "y": 9,
      "z": -6,
      "name": "Wood_Deadwood_Planks"
    },
    {
      "x": -12,
      "y": 4,
      "z": -5,
      "name": "Wood_Deadwood_Planks"
    },
    {
      "x": -12,
      "y": 6,
      "z": -5,
      "name": "Wood_Deadwood_Planks"
    },
    {
      "x": -12,
      "y": 7,
      "z": -5,
      "name": "Wood_Deadwood_Planks"
    },
    {
      "x": -12,
      "y": 8,
      "z": -5,
      "name": "Wood_Deadwood_Planks"
    },
    {
      "x": -12,
      "y": 9,
      "z": -5,
      "name": "Wood_Deadwood_Planks"
    },
    {
      "x": -12,
      "y": 4,
      "z": -4,
      "name": "Wood_Darkwood_Planks"
    },
    {
      "x": -12,
      "y": 5,
      "z": -4,
      "name": "Wood_Darkwood_Planks"
    },
    {
      "x": -12,
      "y": 7,
      "z": -4,
      "name": "Wood_Darkwood_Planks"
    },
    {
      "x": -12,
      "y": 8,
      "z": -4,
      "name": "Soil_Pebbles_Frozen"
    },
    {
      "x": -12,
      "y": 9,
      "z": -4,
      "name": "Soil_Snow_Half"
    },
    {
      "x": -12,
      "y": 4,
      "z": -3,
      "name": "Wood_Deadwood_Planks"
    },
    {
      "x": -12,
      "y": 6,
      "z": -3,
      "name": "Wood_Darkwood_Planks"
    },
    {
      "x": -12,
      "y": 7,
      "z": -3,
      "name": "Wood_Darkwood_Planks"
    },
    {
      "x": -12,
      "y": 8,
      "z": -3,
      "name": "Soil_Pebbles_Frozen"
    },
    {
      "x": -12,
      "y": 4,
      "z": -2,
      "name": "Wood_Deadwood_Planks"
    },
    {
      "x": -12,
      "y": 5,
      "z": -2,
      "name": "Wood_Deadwood_Planks"
    },
    {
      "x": -12,
      "y": 6,
      "z": -2,
      "name": "Wood_Darkwood_Planks"
    },
    {
      "x": -12,
      "y": 7,
      "z": -2,
      "name": "Wood_Darkwood_Planks"
    },
    {
      "x": -12,
      "y": 8,
      "z": -2,
      "name": "Soil_Snow_Half"
    },
    {
      "x": -12,
      "y": 9,
      "z": -2,
      "name": "Soil_Snow_Half"
    },
    {
      "x": -12,
      "y": 6,
      "z": -1,
      "name": "Wood_Deadwood_Planks"
    },
    {
      "x": -12,
      "y": 7,
      "z": -1,
      "name": "Wood_Deadwood_Planks"
    },
    {
      "x": -12,
      "y": 8,
      "z": -1,
      "name": "Wood_Deadwood_Planks"
    },
    {
      "x": -12,
      "y": 7,
      "z": 0,
      "name": "Wood_Deadwood_Planks"
    },
    {
      "x": -12,
      "y": 8,
      "z": 0,
      "name": "Wood_Deadwood_Planks"
    },
    {
      "x": -11,
      "y": 4,
      "z": -6,
      "name": "Wood_Deadwood_Planks"
    },
    {
      "x": -11,
      "y": 5,
      "z": -6,
      "name": "Wood_Deadwood_Planks"
    },
    {
      "x": -11,
      "y": 6,
      "z": -6,
      "name": "Wood_Deadwood_Planks"
    },
    {
      "x": -11,
      "y": 7,
      "z": -6,
      "name": "Wood_Deadwood_Planks"
    },
    {
      "x": -11,
      "y": 8,
      "z": -6,
      "name": "Wood_Deadwood_Planks"
    },
    {
      "x": -11,
      "y": 9,
      "z": -6,
      "name": "Wood_Deadwood_Planks"
    },
    {
      "x": -11,
      "y": 3,
      "z": -5,
      "name": "Wood_Deadwood_Planks"
    },
    {
      "x": -11,
      "y": 4,
      "z": -5,
      "name": "Wood_Darkwood_Planks"
    },
    {
      "x": -11,
      "y": 6,
      "z": -5,
      "name": "Wood_Deadwood_Planks"
    },
    {
      "x": -11,
      "y": 7,
      "z": -5,
      "name": "Wood_Darkwood_Planks"
    },
    {
      "x": -11,
      "y": 8,
      "z": -5,
      "name": "Soil_Pebbles_Frozen"
    },
    {
      "x": -11,
      "y": 3,
      "z": -4,
      "name": "Wood_Darkwood_Planks"
    },
    {
      "x": -11,
      "y": 4,
      "z": -4,
      "name": "Wood_Ash_Trunk",
      "support": 15,
      "rotation": 5
    },
    {
      "x": -11,
      "y": 5,
      "z": -4,
      "name": "Wood_Darkwood_Planks"
    },
    {
      "x": -11,
      "y": 7,
      "z": -4,
      "name": "Wood_Darkwood_Planks"
    },
    {
      "x": -11,
      "y": 8,
      "z": -4,
      "name": "Soil_Pebbles_Frozen"
    },
    {
      "x": -11,
      "y": 3,
      "z": -3,
      "name": "Wood_Deadwood_Planks"
    },
    {
      "x": -11,
      "y": 4,
      "z": -3,
      "name": "Wood_Darkwood_Planks"
    },
    {
      "x": -11,
      "y": 7,
      "z": -3,
      "name": "Wood_Ash_Trunk",
      "support": 15,
      "rotation": 5
    },
    {
      "x": -11,
      "y": 8,
      "z": -3,
      "name": "Soil_Pebbles_Frozen"
    },
    {
      "x": -11,
      "y": 9,
      "z": -3,
      "name": "Soil_Snow_Half"
    },
    {
      "x": -11,
      "y": 3,
      "z": -2,
      "name": "Wood_Deadwood_Planks"
    },
    {
      "x": -11,
      "y": 4,
      "z": -2,
      "name": "Wood_Deadwood_Planks"
    },
    {
      "x": -11,
      "y": 5,
      "z": -2,
      "name": "Wood_Deadwood_Planks"
    },
    {
      "x": -11,
      "y": 6,
      "z": -2,
      "name": "Wood_Darkwood_Planks"
    },
    {
      "x": -11,
      "y": 7,
      "z": -2,
      "name": "Wood_Darkwood_Planks"
    },
    {
      "x": -11,
      "y": 8,
      "z": -2,
      "name": "Soil_Snow_Half"
    },
    {
      "x": -11,
      "y": 9,
      "z": -2,
      "name": "Soil_Snow_Half"
    },
    {
      "x": -11,
      "y": 5,
      "z": -1,
      "name": "Wood_Deadwood_Planks"
    },
    {
      "x": -11,
      "y": 6,
      "z": -1,
      "name": "Wood_Darkwood_Planks"
    },
    {
      "x": -11,
      "y": 7,
      "z": -1,
      "name": "Wood_Darkwood_Planks"
    },
    {
      "x": -11,
      "y": 8,
      "z": -1,
      "name": "Soil_Snow_Half"
    },
    {
      "x": -11,
      "y": 6,
      "z": 0,
      "name": "Wood_Deadwood_Planks"
    },
    {
      "x": -11,
      "y": 7,
      "z": 0,
      "name": "Wood_Deadwood_Planks"
    },
    {
      "x": -11,
      "y": 8,
      "z": 0,
      "name": "Wood_Deadwood_Planks"
    },
    {
      "x": -11,
      "y": 9,
      "z": 0,
      "name": "Soil_Snow_Half"
    },
    {
      "x": -11,
      "y": 7,
      "z": 1,
      "name": "Rock_Ice_Icicles",
      "rotation": 8
    },
    {
      "x": -11,
      "y": 8,
      "z": 1,
      "name": "Wood_Deadwood_Planks"
    },
    {
      "x": -11,
      "y": 9,
      "z": 1,
      "name": "Soil_Snow_Half"
    },
    {
      "x": -10,
      "y": 3,
      "z": -6,
      "name": "Wood_Deadwood_Planks"
    },
    {
      "x": -10,
      "y": 4,
      "z": -6,
      "name": "Wood_Deadwood_Planks"
    },
    {
      "x": -10,
      "y": 3,
      "z": -5,
      "name": "Wood_Deadwood_Planks"
    },
    {
      "x": -10,
      "y": 4,
      "z": -5,
      "name": "Wood_Darkwood_Planks"
    },
    {
      "x": -10,
      "y": 7,
      "z": -5,
      "name": "Soil_Pebbles_Frozen"
    },
    {
      "x": -10,
      "y": 3,
      "z": -4,
      "name": "Wood_Darkwood_Planks"
    },
    {
      "x": -10,
      "y": 4,
      "z": -4,
      "name": "Wood_Ash_Trunk",
      "support": 15,
      "rotation": 5
    },
    {
      "x": -10,
      "y": 7,
      "z": -4,
      "name": "Wood_Darkwood_Planks"
    },
    {
      "x": -10,
      "y": 8,
      "z": -4,
      "name": "Wood_Darkwood_Planks"
    },
    {
      "x": -10,
      "y": 3,
      "z": -3,
      "name": "Wood_Deadwood_Planks"
    },
    {
      "x": -10,
      "y": 4,
      "z": -3,
      "name": "Wood_Darkwood_Planks"
    },
    {
      "x": -10,
      "y": 7,
      "z": -3,
      "name": "Wood_Ash_Trunk",
      "support": 15,
      "rotation": 5
    },
    {
      "x": -10,
      "y": 8,
      "z": -3,
      "name": "Wood_Darkwood_Planks"
    },
    {
      "x": -10,
      "y": 2,
      "z": -2,
      "name": "Wood_Deadwood_Planks"
    },
    {
      "x": -10,
      "y": 3,
      "z": -2,
      "name": "Wood_Deadwood_Planks"
    },
    {
      "x": -10,
      "y": 6,
      "z": -2,
      "name": "Wood_Darkwood_Planks"
    },
    {
      "x": -10,
      "y": 7,
      "z": -2,
      "name": "Wood_Darkwood_Planks"
    },
    {
      "x": -10,
      "y": 4,
      "z": -1,
      "name": "Wood_Deadwood_Planks"
    },
    {
      "x": -10,
      "y": 5,
      "z": -1,
      "name": "Wood_Darkwood_Planks"
    },
    {
      "x": -10,
      "y": 6,
      "z": -1,
      "name": "Wood_Darkwood_Planks"
    },
    {
      "x": -10,
      "y": 7,
      "z": -1,
      "name": "Wood_Darkwood_Planks"
    },
    {
      "x": -10,
      "y": 10,
      "z": -1,
      "name": "Deco_Rope"
    },
    {
      "x": -10,
      "y": 11,
      "z": -1,
      "name": "Deco_Rope"
    },
    {
      "x": -10,
      "y": 12,
      "z": -1,
      "name": "Deco_Rope"
    },
    {
      "x": -10,
      "y": 13,
      "z": -1,
      "name": "Deco_Rope"
    },
    {
      "x": -10,
      "y": 14,
      "z": -1,
      "name": "Deco_Rope"
    },
    {
      "x": -10,
      "y": 15,
      "z": -1,
      "name": "Deco_Rope"
    },
    {
      "x": -10,
      "y": 16,
      "z": -1,
      "name": "Deco_Rope"
    },
    {
      "x": -10,
      "y": 17,
      "z": -1,
      "name": "Wood_Ash_Trunk",
      "support": 15,
      "rotation": 5
    },
    {
      "x": -10,
      "y": 6,
      "z": 0,
      "name": "Wood_Darkwood_Planks"
    },
    {
      "x": -10,
      "y": 7,
      "z": 0,
      "name": "Wood_Darkwood_Planks"
    },
    {
      "x": -10,
      "y": 6,
      "z": 1,
      "name": "Wood_Darkwood_Planks"
    },
    {
      "x": -10,
      "y": 7,
      "z": 1,
      "name": "Wood_Deadwood_Planks"
    },
    {
      "x": -10,
      "y": 8,
      "z": 1,
      "name": "Wood_Deadwood_Planks"
    },
    {
      "x": -9,
      "y": 6,
      "z": -6,
      "name": "Rock_Ice_Icicles",
      "rotation": 8
    },
    {
      "x": -9,
      "y": 7,
      "z": -6,
      "name": "Wood_Ash_Trunk",
      "support": 15,
      "rotation": 4
    },
    {
      "x": -9,
      "y": 8,
      "z": -6,
      "name": "Wood_Ash_Trunk",
      "support": 15,
      "rotation": 4
    },
    {
      "x": -9,
      "y": 7,
      "z": -5,
      "name": "Wood_Ash_Trunk",
      "support": 15,
      "rotation": 4
    },
    {
      "x": -9,
      "y": 16,
      "z": -5,
      "name": "Cloth_Roof_Hide_Flap_White",
      "rotation": 1
    },
    {
      "x": -9,
      "y": 17,
      "z": -5,
      "name": "Cloth_Roof_Hide_Vertical_White",
      "rotation": 1
    },
    {
      "x": -9,
      "y": 18,
      "z": -5,
      "name": "Wood_Ash_Trunk",
      "support": 15,
      "rotation": 4
    },
    {
      "x": -9,
      "y": 4,
      "z": -4,
      "name": "Wood_Ash_Trunk",
      "support": 15,
      "rotation": 5
    },
    {
      "x": -9,
      "y": 5,
      "z": -4,
      "name": "Wood_Ash_Trunk",
      "support": 15
    },
    {
      "x": -9,
      "y": 7,
      "z": -4,
      "name": "Wood_Ash_Trunk",
      "support": 15,
      "rotation": 4
    },
    {
      "x": -9,
      "y": 16,
      "z": -4,
      "name": "Cloth_Roof_Hide_Vertical_White",
      "rotation": 1
    },
    {
      "x": -9,
      "y": 17,
      "z": -4,
      "name": "Wood_Ash_Trunk",
      "support": 15,
      "rotation": 4
    },
    {
      "x": -9,
      "y": 18,
      "z": -4,
      "name": "Wood_Ash_Trunk_Half"
    },
    {
      "x": -9,
      "y": 3,
      "z": -3,
      "name": "Wood_Deadwood_Planks"
    },
    {
      "x": -9,
      "y": 4,
      "z": -3,
      "name": "Wood_Ash_Trunk",
      "support": 15,
      "rotation": 4
    },
    {
      "x": -9,
      "y": 6,
      "z": -3,
      "name": "Wood_Ash_Trunk",
      "support": 15
    },
    {
      "x": -9,
      "y": 7,
      "z": -3,
      "name": "Wood_Ash_Trunk",
      "support": 15
    },
    {
      "x": -9,
      "y": 8,
      "z": -3,
      "name": "Wood_Ash_Trunk",
      "support": 15
    },
    {
      "x": -9,
      "y": 9,
      "z": -3,
      "name": "Wood_Ash_Trunk",
      "support": 15
    },
    {
      "x": -9,
      "y": 15,
      "z": -3,
      "name": "Cloth_Roof_Hide_Flap_White",
      "rotation": 1
    },
    {
      "x": -9,
      "y": 16,
      "z": -3,
      "name": "Cloth_Roof_Hide_Vertical_White",
      "rotation": 1
    },
    {
      "x": -9,
      "y": 17,
      "z": -3,
      "name": "Wood_Ash_Trunk",
      "support": 15,
      "rotation": 4
    },
    {
      "x": -9,
      "y": 18,
      "z": -3,
      "name": "Rubble_Ice",
      "support": 15
    },
    {
      "x": -9,
      "y": 2,
      "z": -2,
      "name": "Wood_Deadwood_Planks"
    },
    {
      "x": -9,
      "y": 3,
      "z": -2,
      "name": "Wood_Ash_Trunk",
      "support": 15,
      "rotation": 4
    },
    {
      "x": -9,
      "y": 6,
      "z": -2,
      "name": "Wood_Ash_Trunk",
      "support": 15,
      "rotation": 4
    },
    {
      "x": -9,
      "y": 10,
      "z": -2,
      "name": "Wood_Ash_Trunk",
      "support": 15
    },
    {
      "x": -9,
      "y": 11,
      "z": -2,
      "name": "Wood_Ash_Trunk",
      "support": 15
    },
    {
      "x": -9,
      "y": 12,
      "z": -2,
      "name": "Wood_Ash_Trunk",
      "support": 15
    },
    {
      "x": -9,
      "y": 13,
      "z": -2,
      "name": "Wood_Ash_Trunk",
      "support": 15
    },
    {
      "x": -9,
      "y": 14,
      "z": -2,
      "name": "Cloth_Roof_Hide_Flap_White",
      "rotation": 1
    },
    {
      "x": -9,
      "y": 15,
      "z": -2,
      "name": "Cloth_Roof_Hide_Vertical_White",
      "rotation": 1
    },
    {
      "x": -9,
      "y": 16,
      "z": -2,
      "name": "Cloth_Roof_Hide_Vertical_White",
      "rotation": 1
    },
    {
      "x": -9,
      "y": 17,
      "z": -2,
      "name": "Wood_Ash_Trunk",
      "support": 15,
      "rotation": 4
    },
    {
      "x": -9,
      "y": 18,
      "z": -2,
      "name": "Soil_Snow_Half"
    },
    {
      "x": -9,
      "y": 3,
      "z": -1,
      "name": "Wood_Deadwood_Planks"
    },
    {
      "x": -9,
      "y": 4,
      "z": -1,
      "name": "Wood_Deadwood_Planks"
    },
    {
      "x": -9,
      "y": 5,
      "z": -1,
      "name": "Wood_Darkwood_Planks"
    },
    {
      "x": -9,
      "y": 6,
      "z": -1,
      "name": "Wood_Ash_Trunk",
      "support": 15,
      "rotation": 4
    },
    {
      "x": -9,
      "y": 10,
      "z": -1,
      "name": "Deco_Rope"
    },
    {
      "x": -9,
      "y": 11,
      "z": -1,
      "name": "Deco_Rope"
    },
    {
      "x": -9,
      "y": 12,
      "z": -1,
      "name": "Deco_Rope"
    },
    {
      "x": -9,
      "y": 13,
      "z": -1,
      "name": "Wood_Ash_Trunk",
      "support": 15
    },
    {
      "x": -9,
      "y": 14,
      "z": -1,
      "name": "Wood_Ash_Trunk",
      "support": 15
    },
    {
      "x": -9,
      "y": 15,
      "z": -1,
      "name": "Wood_Ash_Trunk",
      "support": 15
    },
    {
      "x": -9,
      "y": 16,
      "z": -1,
      "name": "Wood_Ash_Trunk",
      "support": 15
    },
    {
      "x": -9,
      "y": 17,
      "z": -1,
      "name": "Wood_Ash_Trunk",
      "support": 15,
      "rotation": 4
    },
    {
      "x": -9,
      "y": 18,
      "z": -1,
      "name": "Soil_Snow_Half"
    },
    {
      "x": -9,
      "y": 5,
      "z": 0,
      "name": "Wood_Darkwood_Planks"
    },
    {
      "x": -9,
      "y": 6,
      "z": 0,
      "name": "Wood_Ash_Trunk",
      "support": 15,
      "rotation": 4
    },
    {
      "x": -9,
      "y": 15,
      "z": 0,
      "name": "Cloth_Roof_Hide_Vertical_White",
      "rotation": 1
    },
    {
      "x": -9,
      "y": 16,
      "z": 0,
      "name": "Wood_Ash_Trunk",
      "support": 15,
      "rotation": 4
    },
    {
      "x": -9,
      "y": 17,
      "z": 0,
      "name": "Wood_Ash_Trunk",
      "support": 15
    },
    {
      "x": -9,
      "y": 18,
      "z": 0,
      "name": "Wood_Ash_Trunk",
      "support": 15
    },
    {
      "x": -9,
      "y": 19,
      "z": 0,
      "name": "Soil_Snow_Half"
    },
    {
      "x": -9,
      "y": 6,
      "z": 1,
      "name": "Wood_Darkwood_Planks"
    },
    {
      "x": -9,
      "y": 7,
      "z": 1,
      "name": "Wood_Deadwood_Planks"
    },
    {
      "x": -9,
      "y": 8,
      "z": 1,
      "name": "Wood_Deadwood_Planks"
    },
    {
      "x": -9,
      "y": 13,
      "z": 1,
      "name": "Cloth_Roof_Hide_Flap_White",
      "rotation": 1
    },
    {
      "x": -9,
      "y": 14,
      "z": 1,
      "name": "Cloth_Roof_Hide_Vertical_White",
      "rotation": 1
    },
    {
      "x": -9,
      "y": 15,
      "z": 1,
      "name": "Cloth_Roof_Hide_Vertical_White",
      "rotation": 1
    },
    {
      "x": -9,
      "y": 16,
      "z": 1,
      "name": "Wood_Ash_Trunk",
      "support": 15,
      "rotation": 4
    },
    {
      "x": -9,
      "y": 5,
      "z": 2,
      "name": "Rock_Ice_Stalactite_Large",
      "filler": 31744,
      "rotation": 8
    },
    {
      "x": -9,
      "y": 6,
      "z": 2,
      "name": "Rock_Ice_Stalactite_Large",
      "rotation": 8
    },
    {
      "x": -9,
      "y": 7,
      "z": 2,
      "name": "Wood_Deadwood_Planks"
    },
    {
      "x": -9,
      "y": 8,
      "z": 2,
      "name": "Deco_Rope_Diagonal"
    },
    {
      "x": -9,
      "y": 12,
      "z": 2,
      "name": "Cloth_Roof_Hide_Flap_White",
      "rotation": 1
    },
    {
      "x": -9,
      "y": 13,
      "z": 2,
      "name": "Cloth_Roof_Hide_Flap_White",
      "rotation": 1
    },
    {
      "x": -9,
      "y": 14,
      "z": 2,
      "name": "Cloth_Roof_Hide_Vertical_White",
      "rotation": 1
    },
    {
      "x": -9,
      "y": 15,
      "z": 2,
      "name": "Wood_Ash_Trunk_Half",
      "rotation": 8
    },
    {
      "x": -9,
      "y": 16,
      "z": 2,
      "name": "Wood_Ash_Trunk_Full",
      "support": 15,
      "rotation": 4
    },
    {
      "x": -9,
      "y": 17,
      "z": 2,
      "name": "Rubble_Ice",
      "support": 15
    },
    {
      "x": -9,
      "y": 13,
      "z": 3,
      "name": "Cloth_Roof_Hide_Vertical_White",
      "rotation": 1
    },
    {
      "x": -9,
      "y": 14,
      "z": 3,
      "name": "Cloth_Roof_Hide_Vertical_White",
      "rotation": 1
    },
    {
      "x": -9,
      "y": 15,
      "z": 3,
      "name": "Wood_Ash_Trunk",
      "support": 15,
      "rotation": 4
    },
    {
      "x": -9,
      "y": 16,
      "z": 3,
      "name": "Soil_Snow_Half"
    },
    {
      "x": -9,
      "y": 14,
      "z": 4,
      "name": "Rock_Ice_Icicles",
      "rotation": 8
    },
    {
      "x": -9,
      "y": 15,
      "z": 4,
      "name": "Wood_Ash_Trunk",
      "support": 15,
      "rotation": 4
    },
    {
      "x": -9,
      "y": 16,
      "z": 4,
      "name": "Rubble_Ice",
      "support": 15
    },
    {
      "x": -8,
      "y": 4,
      "z": -4,
      "name": "Wood_Ash_Trunk",
      "support": 15,
      "rotation": 5
    },
    {
      "x": -8,
      "y": 4,
      "z": -3,
      "name": "Wood_Darkwood_Planks"
    },
    {
      "x": -8,
      "y": 7,
      "z": -3,
      "name": "Wood_Ash_Trunk",
      "support": 15,
      "rotation": 5
    },
    {
      "x": -8,
      "y": 2,
      "z": -2,
      "name": "Wood_Deadwood_Planks"
    },
    {
      "x": -8,
      "y": 3,
      "z": -2,
      "name": "Wood_Darkwood_Planks"
    },
    {
      "x": -8,
      "y": 6,
      "z": -2,
      "name": "Wood_Darkwood_Planks"
    },
    {
      "x": -8,
      "y": 3,
      "z": -1,
      "name": "Wood_Deadwood_Planks"
    },
    {
      "x": -8,
      "y": 6,
      "z": -1,
      "name": "Wood_Darkwood_Planks"
    },
    {
      "x": -8,
      "y": 4,
      "z": 0,
      "name": "Wood_Deadwood_Planks"
    },
    {
      "x": -8,
      "y": 5,
      "z": 0,
      "name": "Wood_Darkwood_Planks"
    },
    {
      "x": -8,
      "y": 6,
      "z": 0,
      "name": "Wood_Darkwood_Planks"
    },
    {
      "x": -8,
      "y": 17,
      "z": 0,
      "name": "Deco_Rope_Diagonal",
      "rotation": 3
    },
    {
      "x": -8,
      "y": 6,
      "z": 1,
      "name": "Wood_Ash_Trunk",
      "support": 15,
      "rotation": 5
    },
    {
      "x": -8,
      "y": 7,
      "z": 1,
      "name": "Wood_Deadwood_Planks"
    },
    {
      "x": -8,
      "y": 5,
      "z": 2,
      "name": "Wood_Darkwood_Planks"
    },
    {
      "x": -8,
      "y": 6,
      "z": 2,
      "name": "Wood_Deadwood_Planks"
    },
    {
      "x": -8,
      "y": 7,
      "z": 2,
      "name": "Wood_Deadwood_Planks"
    },
    {
      "x": -7,
      "y": 4,
      "z": -4,
      "name": "Wood_Ash_Trunk",
      "support": 15,
      "rotation": 5
    },
    {
      "x": -7,
      "y": 7,
      "z": -3,
      "name": "Wood_Ash_Trunk",
      "support": 15,
      "rotation": 5
    },
    {
      "x": -7,
      "y": 3,
      "z": -1,
      "name": "Wood_Darkwood_Planks"
    },
    {
      "x": -7,
      "y": 4,
      "z": 0,
      "name": "Wood_Deadwood_Planks"
    },
    {
      "x": -7,
      "y": 18,
      "z": 0,
      "name": "Deco_Rope_Diagonal",
      "rotation": 3
    },
    {
      "x": -7,
      "y": 5,
      "z": 1,
      "name": "Wood_Darkwood_Planks"
    },
    {
      "x": -7,
      "y": 6,
      "z": 1,
      "name": "Wood_Ash_Trunk",
      "support": 15,
      "rotation": 5
    },
    {
      "x": -7,
      "y": 5,
      "z": 2,
      "name": "Wood_Darkwood_Planks"
    },
    {
      "x": -7,
      "y": 6,
      "z": 2,
      "name": "Wood_Deadwood_Planks"
    },
    {
      "x": -6,
      "y": 7,
      "z": -8,
      "name": "Wood_Darkwood_Planks"
    },
    {
      "x": -6,
      "y": 8,
      "z": -8,
      "name": "Wood_Darkwood_Planks"
    },
    {
      "x": -6,
      "y": 4,
      "z": -4,
      "name": "Wood_Ash_Trunk",
      "support": 15,
      "rotation": 5
    },
    {
      "x": -6,
      "y": 7,
      "z": -3,
      "name": "Wood_Ash_Trunk",
      "support": 15,
      "rotation": 5
    },
    {
      "x": -6,
      "y": 19,
      "z": 0,
      "name": "Deco_Rope_Diagonal",
      "rotation": 3
    },
    {
      "x": -6,
      "y": 6,
      "z": 1,
      "name": "Wood_Ash_Trunk",
      "support": 15,
      "rotation": 5
    },
    {
      "x": -5,
      "y": 6,
      "z": -9,
      "name": "Wood_Deadwood_Planks"
    },
    {
      "x": -5,
      "y": 4,
      "z": -8,
      "name": "Wood_Darkwood_Planks"
    },
    {
      "x": -5,
      "y": 5,
      "z": -8,
      "name": "Wood_Darkwood_Planks"
    },
    {
      "x": -5,
      "y": 7,
      "z": -8,
      "name": "Wood_Darkwood_Planks"
    },
    {
      "x": -5,
      "y": 8,
      "z": -8,
      "name": "Wood_Darkwood_Planks"
    },
    {
      "x": -5,
      "y": 9,
      "z": -8,
      "name": "Wood_Deadwood_Planks"
    },
    {
      "x": -5,
      "y": 3,
      "z": -7,
      "name": "Wood_Deadwood_Planks"
    },
    {
      "x": -5,
      "y": 4,
      "z": -7,
      "name": "Wood_Darkwood_Planks"
    },
    {
      "x": -5,
      "y": 5,
      "z": -7,
      "name": "Wood_Darkwood_Planks"
    },
    {
      "x": -5,
      "y": 8,
      "z": -7,
      "name": "Wood_Ash_Trunk",
      "support": 15,
      "rotation": 5
    },
    {
      "x": -5,
      "y": 1,
      "z": -6,
      "name": "Wood_Deadwood_Planks"
    },
    {
      "x": -5,
      "y": 2,
      "z": -6,
      "name": "Wood_Deadwood_Planks"
    },
    {
      "x": -5,
      "y": 4,
      "z": -6,
      "name": "Wood_Darkwood_Planks"
    },
    {
      "x": -5,
      "y": 1,
      "z": -5,
      "name": "Wood_Darkwood_Planks"
    },
    {
      "x": -5,
      "y": 2,
      "z": -5,
      "name": "Wood_Deadwood_Planks"
    },
    {
      "x": -5,
      "y": 4,
      "z": -4,
      "name": "Wood_Ash_Trunk",
      "support": 15,
      "rotation": 5
    },
    {
      "x": -5,
      "y": 7,
      "z": -3,
      "name": "Wood_Ash_Trunk",
      "support": 15,
      "rotation": 5
    },
    {
      "x": -5,
      "y": 20,
      "z": 0,
      "name": "Deco_Rope_Diagonal",
      "rotation": 3
    },
    {
      "x": -5,
      "y": 6,
      "z": 1,
      "name": "Wood_Ash_Trunk",
      "support": 15,
      "rotation": 5
    },
    {
      "x": -4,
      "y": 6,
      "z": -9,
      "name": "Wood_Deadwood_Planks"
    },
    {
      "x": -4,
      "y": 4,
      "z": -8,
      "name": "Wood_Darkwood_Planks"
    },
    {
      "x": -4,
      "y": 5,
      "z": -8,
      "name": "Wood_Darkwood_Planks"
    },
    {
      "x": -4,
      "y": 8,
      "z": -8,
      "name": "Wood_Darkwood_Planks"
    },
    {
      "x": -4,
      "y": 9,
      "z": -8,
      "name": "Wood_Deadwood_Planks"
    },
    {
      "x": -4,
      "y": 2,
      "z": -7,
      "name": "Wood_Deadwood_Planks"
    },
    {
      "x": -4,
      "y": 3,
      "z": -7,
      "name": "Wood_Deadwood_Planks"
    },
    {
      "x": -4,
      "y": 4,
      "z": -7,
      "name": "Wood_Darkwood_Planks"
    },
    {
      "x": -4,
      "y": 5,
      "z": -7,
      "name": "Wood_Darkwood_Planks"
    },
    {
      "x": -4,
      "y": 8,
      "z": -7,
      "name": "Wood_Ash_Trunk",
      "support": 15,
      "rotation": 5
    },
    {
      "x": -4,
      "y": 1,
      "z": -6,
      "name": "Wood_Deadwood_Planks"
    },
    {
      "x": -4,
      "y": 4,
      "z": -6,
      "name": "Wood_Darkwood_Planks"
    },
    {
      "x": -4,
      "y": 7,
      "z": -6,
      "name": "Wood_Darkwood_Planks"
    },
    {
      "x": -4,
      "y": 8,
      "z": -6,
      "name": "Wood_Darkwood_Planks"
    },
    {
      "x": -4,
      "y": 1,
      "z": -5,
      "name": "Wood_Darkwood_Planks"
    },
    {
      "x": -4,
      "y": 4,
      "z": -5,
      "name": "Wood_Darkwood_Planks"
    },
    {
      "x": -4,
      "y": 7,
      "z": -5,
      "name": "Wood_Darkwood_Planks"
    },
    {
      "x": -4,
      "y": 1,
      "z": -4,
      "name": "Wood_Deadwood_Planks"
    },
    {
      "x": -4,
      "y": 4,
      "z": -4,
      "name": "Wood_Ash_Trunk",
      "support": 15,
      "rotation": 5
    },
    {
      "x": -4,
      "y": 7,
      "z": -4,
      "name": "Wood_Darkwood_Planks"
    },
    {
      "x": -4,
      "y": 0,
      "z": -3,
      "name": "Wood_Deadwood_Planks"
    },
    {
      "x": -4,
      "y": 1,
      "z": -3,
      "name": "Wood_Deadwood_Planks"
    },
    {
      "x": -4,
      "y": 4,
      "z": -3,
      "name": "Wood_Darkwood_Planks"
    },
    {
      "x": -4,
      "y": 6,
      "z": -3,
      "name": "Rock_Ice_Icicles",
      "rotation": 8
    },
    {
      "x": -4,
      "y": 7,
      "z": -3,
      "name": "Wood_Ash_Trunk",
      "support": 15,
      "rotation": 5
    },
    {
      "x": -4,
      "y": 8,
      "z": -3,
      "name": "Soil_Snow_Half"
    },
    {
      "x": -4,
      "y": 6,
      "z": 1,
      "name": "Wood_Ash_Trunk",
      "support": 15,
      "rotation": 5
    },
    {
      "x": -4,
      "y": 21,
      "z": 1,
      "name": "Deco_Rope_Diagonal",
      "rotation": 3
    },
    {
      "x": -3,
      "y": 5,
      "z": -9,
      "name": "Wood_Darkwood_Planks"
    },
    {
      "x": -3,
      "y": 6,
      "z": -9,
      "name": "Wood_Deadwood_Planks"
    },
    {
      "x": -3,
      "y": 4,
      "z": -8,
      "name": "Wood_Darkwood_Planks"
    },
    {
      "x": -3,
      "y": 5,
      "z": -8,
      "name": "Wood_Ash_Trunk",
      "support": 15,
      "rotation": 5
    },
    {
      "x": -3,
      "y": 7,
      "z": -8,
      "name": "Wood_Darkwood_Planks"
    },
    {
      "x": -3,
      "y": 8,
      "z": -8,
      "name": "Wood_Darkwood_Planks"
    },
    {
      "x": -3,
      "y": 9,
      "z": -8,
      "name": "Wood_Deadwood_Planks"
    },
    {
      "x": -3,
      "y": 2,
      "z": -7,
      "name": "Wood_Deadwood_Planks"
    },
    {
      "x": -3,
      "y": 3,
      "z": -7,
      "name": "Wood_Deadwood_Planks"
    },
    {
      "x": -3,
      "y": 4,
      "z": -7,
      "name": "Wood_Darkwood_Planks"
    },
    {
      "x": -3,
      "y": 5,
      "z": -7,
      "name": "Wood_Darkwood_Planks"
    },
    {
      "x": -3,
      "y": 8,
      "z": -7,
      "name": "Wood_Ash_Trunk",
      "support": 15,
      "rotation": 5
    },
    {
      "x": -3,
      "y": 9,
      "z": -7,
      "name": "Soil_Snow_Half"
    },
    {
      "x": -3,
      "y": 1,
      "z": -6,
      "name": "Wood_Deadwood_Planks"
    },
    {
      "x": -3,
      "y": 4,
      "z": -6,
      "name": "Wood_Darkwood_Planks"
    },
    {
      "x": -3,
      "y": 7,
      "z": -6,
      "name": "Wood_Darkwood_Planks"
    },
    {
      "x": -3,
      "y": 8,
      "z": -6,
      "name": "Wood_Darkwood_Planks"
    },
    {
      "x": -3,
      "y": 1,
      "z": -5,
      "name": "Wood_Darkwood_Planks"
    },
    {
      "x": -3,
      "y": 4,
      "z": -5,
      "name": "Wood_Darkwood_Planks"
    },
    {
      "x": -3,
      "y": 7,
      "z": -5,
      "name": "Wood_Darkwood_Planks"
    },
    {
      "x": -3,
      "y": 1,
      "z": -4,
      "name": "Wood_Deadwood_Planks"
    },
    {
      "x": -3,
      "y": 4,
      "z": -4,
      "name": "Wood_Ash_Trunk",
      "support": 15,
      "rotation": 5
    },
    {
      "x": -3,
      "y": 7,
      "z": -4,
      "name": "Wood_Darkwood_Planks"
    },
    {
      "x": -3,
      "y": 8,
      "z": -4,
      "name": "Soil_Snow_Half"
    },
    {
      "x": -3,
      "y": 0,
      "z": -3,
      "name": "Wood_Deadwood_Planks"
    },
    {
      "x": -3,
      "y": 1,
      "z": -3,
      "name": "Wood_Deadwood_Planks"
    },
    {
      "x": -3,
      "y": 4,
      "z": -3,
      "name": "Soil_Pebbles_Frozen"
    },
    {
      "x": -3,
      "y": 7,
      "z": -3,
      "name": "Wood_Ash_Trunk",
      "support": 15,
      "rotation": 5
    },
    {
      "x": -3,
      "y": 8,
      "z": -3,
      "name": "Soil_Snow_Half"
    },
    {
      "x": -3,
      "y": 1,
      "z": -2,
      "name": "Wood_Deadwood_Planks"
    },
    {
      "x": -3,
      "y": 3,
      "z": -2,
      "name": "Wood_Darkwood_Planks"
    },
    {
      "x": -3,
      "y": 6,
      "z": -2,
      "name": "Wood_Darkwood_Planks"
    },
    {
      "x": -3,
      "y": 7,
      "z": -2,
      "name": "Soil_Snow_Half"
    },
    {
      "x": -3,
      "y": 2,
      "z": -1,
      "name": "Wood_Darkwood_Planks"
    },
    {
      "x": -3,
      "y": 3,
      "z": -1,
      "name": "Wood_Darkwood_Planks"
    },
    {
      "x": -3,
      "y": 6,
      "z": -1,
      "name": "Wood_Darkwood_Planks"
    },
    {
      "x": -3,
      "y": 7,
      "z": -1,
      "name": "Soil_Snow_Half"
    },
    {
      "x": -3,
      "y": 2,
      "z": 0,
      "name": "Wood_Darkwood_Planks"
    },
    {
      "x": -3,
      "y": 3,
      "z": 0,
      "name": "Wood_Ash_Trunk",
      "support": 15,
      "rotation": 5
    },
    {
      "x": -3,
      "y": 5,
      "z": 1,
      "name": "Wood_Darkwood_Planks"
    },
    {
      "x": -3,
      "y": 6,
      "z": 1,
      "name": "Wood_Ash_Trunk",
      "support": 15,
      "rotation": 5
    },
    {
      "x": -3,
      "y": 22,
      "z": 1,
      "name": "Deco_Rope_Diagonal",
      "rotation": 3
    },
    {
      "x": -3,
      "y": 5,
      "z": 2,
      "name": "Wood_Darkwood_Planks"
    },
    {
      "x": -3,
      "y": 6,
      "z": 2,
      "name": "Wood_Deadwood_Planks"
    },
    {
      "x": -2,
      "y": 5,
      "z": -9,
      "name": "Wood_Darkwood_Planks"
    },
    {
      "x": -2,
      "y": 6,
      "z": -9,
      "name": "Wood_Deadwood_Planks"
    },
    {
      "x": -2,
      "y": 3,
      "z": -8,
      "name": "Wood_Deadwood_Planks"
    },
    {
      "x": -2,
      "y": 4,
      "z": -8,
      "name": "Wood_Darkwood_Planks"
    },
    {
      "x": -2,
      "y": 5,
      "z": -8,
      "name": "Wood_Ash_Trunk",
      "support": 15,
      "rotation": 5
    },
    {
      "x": -2,
      "y": 8,
      "z": -8,
      "name": "Wood_Darkwood_Planks"
    },
    {
      "x": -2,
      "y": 9,
      "z": -8,
      "name": "Wood_Deadwood_Planks"
    },
    {
      "x": -2,
      "y": 2,
      "z": -7,
      "name": "Wood_Deadwood_Planks"
    },
    {
      "x": -2,
      "y": 3,
      "z": -7,
      "name": "Wood_Deadwood_Planks"
    },
    {
      "x": -2,
      "y": 5,
      "z": -7,
      "name": "Wood_Darkwood_Planks"
    },
    {
      "x": -2,
      "y": 8,
      "z": -7,
      "name": "Wood_Ash_Trunk",
      "support": 15,
      "rotation": 5
    },
    {
      "x": -2,
      "y": 9,
      "z": -7,
      "name": "Soil_Snow_Half"
    },
    {
      "x": -2,
      "y": 1,
      "z": -6,
      "name": "Wood_Deadwood_Planks"
    },
    {
      "x": -2,
      "y": 4,
      "z": -6,
      "name": "Wood_Darkwood_Planks"
    },
    {
      "x": -2,
      "y": 7,
      "z": -6,
      "name": "Rock_Calcite_Cobble"
    },
    {
      "x": -2,
      "y": 8,
      "z": -6,
      "name": "Rock_Calcite_Cobble"
    },
    {
      "x": -2,
      "y": 9,
      "z": -6,
      "name": "Soil_Snow_Half"
    },
    {
      "x": -2,
      "y": 1,
      "z": -5,
      "name": "Wood_Darkwood_Planks"
    },
    {
      "x": -2,
      "y": 4,
      "z": -5,
      "name": "Wood_Darkwood_Planks"
    },
    {
      "x": -2,
      "y": 7,
      "z": -5,
      "name": "Rock_Calcite_Cobble"
    },
    {
      "x": -2,
      "y": 8,
      "z": -5,
      "name": "Soil_Snow_Half"
    },
    {
      "x": -2,
      "y": 1,
      "z": -4,
      "name": "Wood_Deadwood_Planks"
    },
    {
      "x": -2,
      "y": 4,
      "z": -4,
      "name": "Wood_Ash_Trunk",
      "support": 15,
      "rotation": 5
    },
    {
      "x": -2,
      "y": 7,
      "z": -4,
      "name": "Wood_Darkwood_Planks"
    },
    {
      "x": -2,
      "y": 8,
      "z": -4,
      "name": "Soil_Snow_Half"
    },
    {
      "x": -2,
      "y": 0,
      "z": -3,
      "name": "Wood_Deadwood_Planks"
    },
    {
      "x": -2,
      "y": 1,
      "z": -3,
      "name": "Wood_Deadwood_Planks"
    },
    {
      "x": -2,
      "y": 4,
      "z": -3,
      "name": "Soil_Pebbles_Frozen"
    },
    {
      "x": -2,
      "y": 7,
      "z": -3,
      "name": "Wood_Ash_Trunk",
      "support": 15,
      "rotation": 5
    },
    {
      "x": -2,
      "y": 8,
      "z": -3,
      "name": "*Soil_Snow_Half_State_Definitions_Block"
    },
    {
      "x": -2,
      "y": 1,
      "z": -2,
      "name": "Wood_Deadwood_Planks"
    },
    {
      "x": -2,
      "y": 3,
      "z": -2,
      "name": "Soil_Pebbles_Frozen"
    },
    {
      "x": -2,
      "y": 6,
      "z": -2,
      "name": "Wood_Darkwood_Planks"
    },
    {
      "x": -2,
      "y": 7,
      "z": -2,
      "name": "Soil_Snow_Half"
    },
    {
      "x": -2,
      "y": 1,
      "z": -1,
      "name": "Wood_Deadwood_Planks"
    },
    {
      "x": -2,
      "y": 3,
      "z": -1,
      "name": "Wood_Darkwood_Planks"
    },
    {
      "x": -2,
      "y": 6,
      "z": -1,
      "name": "Wood_Darkwood_Planks"
    },
    {
      "x": -2,
      "y": 2,
      "z": 0,
      "name": "Wood_Darkwood_Planks"
    },
    {
      "x": -2,
      "y": 3,
      "z": 0,
      "name": "Wood_Ash_Trunk",
      "support": 15,
      "rotation": 5
    },
    {
      "x": -2,
      "y": 6,
      "z": 0,
      "name": "Wood_Darkwood_Planks"
    },
    {
      "x": -2,
      "y": 7,
      "z": 0,
      "name": "Furniture_Ancient_Barrel"
    },
    {
      "x": -2,
      "y": 3,
      "z": 1,
      "name": "Wood_Darkwood_Planks"
    },
    {
      "x": -2,
      "y": 4,
      "z": 1,
      "name": "Wood_Deadwood_Planks"
    },
    {
      "x": -2,
      "y": 5,
      "z": 1,
      "name": "Furniture_Frozen_Castle_Window"
    },
    {
      "x": -2,
      "y": 6,
      "z": 1,
      "name": "Wood_Ash_Trunk",
      "support": 15,
      "rotation": 5
    },
    {
      "x": -2,
      "y": 7,
      "z": 1,
      "name": "Furniture_Ancient_Barrel"
    },
    {
      "x": -2,
      "y": 23,
      "z": 1,
      "name": "Deco_Rope_Diagonal",
      "rotation": 3
    },
    {
      "x": -2,
      "y": 3,
      "z": 2,
      "name": "Furniture_Tavern_Shelf"
    },
    {
      "x": -2,
      "y": 5,
      "z": 2,
      "name": "Wood_Darkwood_Planks"
    },
    {
      "x": -2,
      "y": 6,
      "z": 2,
      "name": "Wood_Deadwood_Planks"
    },
    {
      "x": -1,
      "y": 5,
      "z": -9,
      "name": "Wood_Darkwood_Planks"
    },
    {
      "x": -1,
      "y": 6,
      "z": -9,
      "name": "Wood_Deadwood_Planks"
    },
    {
      "x": -1,
      "y": 3,
      "z": -8,
      "name": "Wood_Deadwood_Planks"
    },
    {
      "x": -1,
      "y": 4,
      "z": -8,
      "name": "Wood_Darkwood_Planks"
    },
    {
      "x": -1,
      "y": 5,
      "z": -8,
      "name": "Wood_Ash_Trunk",
      "support": 15,
      "rotation": 5
    },
    {
      "x": -1,
      "y": 6,
      "z": -8,
      "name": "Furniture_Ancient_Barrel"
    },
    {
      "x": -1,
      "y": 7,
      "z": -8,
      "name": "Wood_Darkwood_Planks"
    },
    {
      "x": -1,
      "y": 8,
      "z": -8,
      "name": "Wood_Darkwood_Planks"
    },
    {
      "x": -1,
      "y": 9,
      "z": -8,
      "name": "Wood_Deadwood_Planks"
    },
    {
      "x": -1,
      "y": 2,
      "z": -7,
      "name": "Wood_Deadwood_Planks"
    },
    {
      "x": -1,
      "y": 3,
      "z": -7,
      "name": "Wood_Deadwood_Planks"
    },
    {
      "x": -1,
      "y": 5,
      "z": -7,
      "name": "Wood_Darkwood_Planks"
    },
    {
      "x": -1,
      "y": 8,
      "z": -7,
      "name": "Wood_Ash_Trunk",
      "support": 15,
      "rotation": 5
    },
    {
      "x": -1,
      "y": 9,
      "z": -7,
      "name": "*Soil_Snow_Half_State_Definitions_Block"
    },
    {
      "x": -1,
      "y": 1,
      "z": -6,
      "name": "Wood_Deadwood_Planks"
    },
    {
      "x": -1,
      "y": 4,
      "z": -6,
      "name": "Wood_Darkwood_Planks"
    },
    {
      "x": -1,
      "y": 7,
      "z": -6,
      "name": "Rock_Calcite_Cobble"
    },
    {
      "x": -1,
      "y": 8,
      "z": -6,
      "name": "Rock_Calcite_Cobble"
    },
    {
      "x": -1,
      "y": 9,
      "z": -6,
      "name": "Soil_Snow_Half"
    },
    {
      "x": -1,
      "y": 1,
      "z": -5,
      "name": "Wood_Darkwood_Planks"
    },
    {
      "x": -1,
      "y": 4,
      "z": -5,
      "name": "Wood_Darkwood_Planks"
    },
    {
      "x": -1,
      "y": 7,
      "z": -5,
      "name": "Rock_Calcite_Cobble"
    },
    {
      "x": -1,
      "y": 1,
      "z": -4,
      "name": "Wood_Deadwood_Planks"
    },
    {
      "x": -1,
      "y": 4,
      "z": -4,
      "name": "Wood_Ash_Trunk",
      "support": 15,
      "rotation": 5
    },
    {
      "x": -1,
      "y": 7,
      "z": -4,
      "name": "Wood_Darkwood_Planks"
    },
    {
      "x": -1,
      "y": 8,
      "z": -4,
      "name": "Soil_Snow_Half"
    },
    {
      "x": -1,
      "y": 0,
      "z": -3,
      "name": "Wood_Deadwood_Planks"
    },
    {
      "x": -1,
      "y": 1,
      "z": -3,
      "name": "Wood_Deadwood_Planks"
    },
    {
      "x": -1,
      "y": 4,
      "z": -3,
      "name": "Wood_Darkwood_Planks"
    },
    {
      "x": -1,
      "y": 7,
      "z": -3,
      "name": "Wood_Ash_Trunk",
      "support": 15,
      "rotation": 5
    },
    {
      "x": -1,
      "y": 8,
      "z": -3,
      "name": "Soil_Snow_Half"
    },
    {
      "x": -1,
      "y": 1,
      "z": -2,
      "name": "Wood_Deadwood_Planks"
    },
    {
      "x": -1,
      "y": 3,
      "z": -2,
      "name": "Wood_Darkwood_Planks"
    },
    {
      "x": -1,
      "y": 6,
      "z": -2,
      "name": "Wood_Darkwood_Planks"
    },
    {
      "x": -1,
      "y": 1,
      "z": -1,
      "name": "Wood_Deadwood_Planks"
    },
    {
      "x": -1,
      "y": 3,
      "z": -1,
      "name": "Wood_Darkwood_Planks"
    },
    {
      "x": -1,
      "y": 6,
      "z": -1,
      "name": "Wood_Darkwood_Planks"
    },
    {
      "x": -1,
      "y": 2,
      "z": 0,
      "name": "Wood_Darkwood_Planks"
    },
    {
      "x": -1,
      "y": 3,
      "z": 0,
      "name": "Wood_Ash_Trunk",
      "support": 15,
      "rotation": 5
    },
    {
      "x": -1,
      "y": 6,
      "z": 0,
      "name": "Wood_Darkwood_Planks"
    },
    {
      "x": -1,
      "y": 3,
      "z": 1,
      "name": "Wood_Darkwood_Planks"
    },
    {
      "x": -1,
      "y": 4,
      "z": 1,
      "name": "Wood_Deadwood_Planks"
    },
    {
      "x": -1,
      "y": 5,
      "z": 1,
      "name": "Wood_Darkwood_Planks"
    },
    {
      "x": -1,
      "y": 6,
      "z": 1,
      "name": "Wood_Ash_Trunk",
      "support": 15,
      "rotation": 5
    },
    {
      "x": -1,
      "y": 7,
      "z": 1,
      "name": "Furniture_Ancient_Barrel"
    },
    {
      "x": -1,
      "y": 24,
      "z": 1,
      "name": "Deco_Rope_Diagonal",
      "rotation": 3
    },
    {
      "x": -1,
      "y": 5,
      "z": 2,
      "name": "Wood_Darkwood_Planks"
    },
    {
      "x": -1,
      "y": 6,
      "z": 2,
      "name": "Wood_Deadwood_Planks"
    },
    {
      "x": 0,
      "y": 5,
      "z": -9,
      "name": "Wood_Darkwood_Planks"
    },
    {
      "x": 0,
      "y": 6,
      "z": -9,
      "name": "Wood_Deadwood_Planks"
    },
    {
      "x": 0,
      "y": 3,
      "z": -8,
      "name": "Wood_Deadwood_Planks"
    },
    {
      "x": 0,
      "y": 4,
      "z": -8,
      "name": "Wood_Darkwood_Planks"
    },
    {
      "x": 0,
      "y": 5,
      "z": -8,
      "name": "Wood_Ash_Trunk",
      "support": 15,
      "rotation": 5
    },
    {
      "x": 0,
      "y": 6,
      "z": -8,
      "name": "Furniture_Ancient_Barrel"
    },
    {
      "x": 0,
      "y": 8,
      "z": -8,
      "name": "Wood_Darkwood_Planks"
    },
    {
      "x": 0,
      "y": 9,
      "z": -8,
      "name": "Wood_Deadwood_Planks"
    },
    {
      "x": 0,
      "y": 2,
      "z": -7,
      "name": "Wood_Deadwood_Planks"
    },
    {
      "x": 0,
      "y": 3,
      "z": -7,
      "name": "Wood_Deadwood_Planks"
    },
    {
      "x": 0,
      "y": 5,
      "z": -7,
      "name": "Wood_Darkwood_Planks"
    },
    {
      "x": 0,
      "y": 8,
      "z": -7,
      "name": "Wood_Ash_Trunk",
      "support": 15,
      "rotation": 5
    },
    {
      "x": 0,
      "y": 9,
      "z": -7,
      "name": "Soil_Snow_Half"
    },
    {
      "x": 0,
      "y": 1,
      "z": -6,
      "name": "Wood_Deadwood_Planks"
    },
    {
      "x": 0,
      "y": 4,
      "z": -6,
      "name": "Wood_Darkwood_Planks"
    },
    {
      "x": 0,
      "y": 7,
      "z": -6,
      "name": "Rock_Calcite_Cobble"
    },
    {
      "x": 0,
      "y": 8,
      "z": -6,
      "name": "Rock_Calcite_Cobble"
    },
    {
      "x": 0,
      "y": 9,
      "z": -6,
      "name": "Soil_Snow_Half"
    },
    {
      "x": 0,
      "y": 1,
      "z": -5,
      "name": "Wood_Darkwood_Planks"
    },
    {
      "x": 0,
      "y": 4,
      "z": -5,
      "name": "Wood_Darkwood_Planks"
    },
    {
      "x": 0,
      "y": 7,
      "z": -5,
      "name": "Wood_Darkwood_Planks"
    },
    {
      "x": 0,
      "y": 1,
      "z": -4,
      "name": "Wood_Deadwood_Planks"
    },
    {
      "x": 0,
      "y": 4,
      "z": -4,
      "name": "Wood_Ash_Trunk",
      "support": 15,
      "rotation": 5
    },
    {
      "x": 0,
      "y": 7,
      "z": -4,
      "name": "Wood_Darkwood_Planks"
    },
    {
      "x": 0,
      "y": 0,
      "z": -3,
      "name": "Wood_Deadwood_Planks"
    },
    {
      "x": 0,
      "y": 1,
      "z": -3,
      "name": "Wood_Deadwood_Planks"
    },
    {
      "x": 0,
      "y": 4,
      "z": -3,
      "name": "Wood_Darkwood_Planks"
    },
    {
      "x": 0,
      "y": 7,
      "z": -3,
      "name": "Wood_Ash_Trunk",
      "support": 15,
      "rotation": 5
    },
    {
      "x": 0,
      "y": 1,
      "z": -2,
      "name": "Wood_Deadwood_Planks"
    },
    {
      "x": 0,
      "y": 3,
      "z": -2,
      "name": "Wood_Darkwood_Planks"
    },
    {
      "x": 0,
      "y": 6,
      "z": -2,
      "name": "Wood_Darkwood_Planks"
    },
    {
      "x": 0,
      "y": 1,
      "z": -1,
      "name": "Wood_Deadwood_Planks"
    },
    {
      "x": 0,
      "y": 3,
      "z": -1,
      "name": "Wood_Darkwood_Planks"
    },
    {
      "x": 0,
      "y": 6,
      "z": -1,
      "name": "Wood_Darkwood_Planks"
    },
    {
      "x": 0,
      "y": 2,
      "z": 0,
      "name": "Wood_Darkwood_Planks"
    },
    {
      "x": 0,
      "y": 3,
      "z": 0,
      "name": "Wood_Ash_Trunk",
      "support": 15,
      "rotation": 5
    },
    {
      "x": 0,
      "y": 4,
      "z": 0,
      "name": "Block_Spawner_Block",
      "components": {
        "Components": {
          "PlacedByInteraction": {
            "WhoPlacedUuid": {
              "$binary": "+u0Lek23TWiDpMOn5L2LqA==",
              "$type": "04"
            }
          },
          "BlockSpawner": {
            "BlockSpawnerId": "Zone3_Encounters_Tier2"
          }
        }
      },
      "rotation": 2
    },
    {
      "x": 0,
      "y": 6,
      "z": 0,
      "name": "Wood_Darkwood_Planks"
    },
    {
      "x": 0,
      "y": 3,
      "z": 1,
      "name": "Wood_Darkwood_Planks"
    },
    {
      "x": 0,
      "y": 4,
      "z": 1,
      "name": "Wood_Deadwood_Planks"
    },
    {
      "x": 0,
      "y": 6,
      "z": 1,
      "name": "Wood_Ash_Trunk",
      "support": 15,
      "rotation": 5
    },
    {
      "x": 0,
      "y": 7,
      "z": 1,
      "name": "Furniture_Ancient_Crate",
      "rotation": 2
    },
    {
      "x": 0,
      "y": 3,
      "z": 2,
      "name": "Furniture_Tavern_Shelf"
    },
    {
      "x": 0,
      "y": 5,
      "z": 2,
      "name": "Wood_Darkwood_Planks"
    },
    {
      "x": 0,
      "y": 6,
      "z": 2,
      "name": "Wood_Deadwood_Planks"
    },
    {
      "x": 0,
      "y": 7,
      "z": 2,
      "name": "Soil_Snow_Half"
    },
    {
      "x": 0,
      "y": 25,
      "z": 2,
      "name": "Deco_Rope_Diagonal",
      "rotation": 3
    },
    {
      "x": 1,
      "y": 5,
      "z": -9,
      "name": "Wood_Darkwood_Planks"
    },
    {
      "x": 1,
      "y": 6,
      "z": -9,
      "name": "Wood_Deadwood_Planks"
    },
    {
      "x": 1,
      "y": 3,
      "z": -8,
      "name": "Wood_Deadwood_Planks"
    },
    {
      "x": 1,
      "y": 4,
      "z": -8,
      "name": "Wood_Darkwood_Planks"
    },
    {
      "x": 1,
      "y": 5,
      "z": -8,
      "name": "Wood_Ash_Trunk",
      "support": 15,
      "rotation": 5
    },
    {
      "x": 1,
      "y": 7,
      "z": -8,
      "name": "Wood_Darkwood_Planks"
    },
    {
      "x": 1,
      "y": 8,
      "z": -8,
      "name": "Wood_Darkwood_Planks"
    },
    {
      "x": 1,
      "y": 9,
      "z": -8,
      "name": "Wood_Deadwood_Planks"
    },
    {
      "x": 1,
      "y": 2,
      "z": -7,
      "name": "Wood_Deadwood_Planks"
    },
    {
      "x": 1,
      "y": 3,
      "z": -7,
      "name": "Wood_Deadwood_Planks"
    },
    {
      "x": 1,
      "y": 5,
      "z": -7,
      "name": "Wood_Darkwood_Planks"
    },
    {
      "x": 1,
      "y": 8,
      "z": -7,
      "name": "Wood_Ash_Trunk",
      "support": 15,
      "rotation": 5
    },
    {
      "x": 1,
      "y": 9,
      "z": -7,
      "name": "Soil_Snow_Half"
    },
    {
      "x": 1,
      "y": 1,
      "z": -6,
      "name": "Wood_Deadwood_Planks"
    },
    {
      "x": 1,
      "y": 4,
      "z": -6,
      "name": "Wood_Darkwood_Planks"
    },
    {
      "x": 1,
      "y": 7,
      "z": -6,
      "name": "Wood_Darkwood_Planks"
    },
    {
      "x": 1,
      "y": 8,
      "z": -6,
      "name": "Wood_Darkwood_Planks"
    },
    {
      "x": 1,
      "y": 1,
      "z": -5,
      "name": "Wood_Darkwood_Planks"
    },
    {
      "x": 1,
      "y": 4,
      "z": -5,
      "name": "Wood_Darkwood_Planks"
    },
    {
      "x": 1,
      "y": 7,
      "z": -5,
      "name": "Wood_Darkwood_Planks"
    },
    {
      "x": 1,
      "y": 1,
      "z": -4,
      "name": "Wood_Deadwood_Planks"
    },
    {
      "x": 1,
      "y": 4,
      "z": -4,
      "name": "Wood_Ash_Trunk",
      "support": 15,
      "rotation": 5
    },
    {
      "x": 1,
      "y": 7,
      "z": -4,
      "name": "Wood_Darkwood_Planks"
    },
    {
      "x": 1,
      "y": 0,
      "z": -3,
      "name": "Wood_Deadwood_Planks"
    },
    {
      "x": 1,
      "y": 1,
      "z": -3,
      "name": "Wood_Deadwood_Planks"
    },
    {
      "x": 1,
      "y": 4,
      "z": -3,
      "name": "Wood_Darkwood_Planks"
    },
    {
      "x": 1,
      "y": 7,
      "z": -3,
      "name": "Wood_Ash_Trunk",
      "support": 15,
      "rotation": 5
    },
    {
      "x": 1,
      "y": 1,
      "z": -2,
      "name": "Wood_Deadwood_Planks"
    },
    {
      "x": 1,
      "y": 3,
      "z": -2,
      "name": "Wood_Darkwood_Planks"
    },
    {
      "x": 1,
      "y": 6,
      "z": -2,
      "name": "Wood_Darkwood_Planks"
    },
    {
      "x": 1,
      "y": 1,
      "z": -1,
      "name": "Wood_Deadwood_Planks"
    },
    {
      "x": 1,
      "y": 3,
      "z": -1,
      "name": "Wood_Darkwood_Planks"
    },
    {
      "x": 1,
      "y": 6,
      "z": -1,
      "name": "Wood_Darkwood_Planks"
    },
    {
      "x": 1,
      "y": 2,
      "z": 0,
      "name": "Wood_Darkwood_Planks"
    },
    {
      "x": 1,
      "y": 3,
      "z": 0,
      "name": "Wood_Ash_Trunk",
      "support": 15,
      "rotation": 5
    },
    {
      "x": 1,
      "y": 6,
      "z": 0,
      "name": "Wood_Darkwood_Planks"
    },
    {
      "x": 1,
      "y": 3,
      "z": 1,
      "name": "Wood_Darkwood_Planks"
    },
    {
      "x": 1,
      "y": 4,
      "z": 1,
      "name": "Wood_Deadwood_Planks"
    },
    {
      "x": 1,
      "y": 5,
      "z": 1,
      "name": "Wood_Darkwood_Planks"
    },
    {
      "x": 1,
      "y": 6,
      "z": 1,
      "name": "Wood_Ash_Trunk",
      "support": 15,
      "rotation": 5
    },
    {
      "x": 1,
      "y": 5,
      "z": 2,
      "name": "Wood_Darkwood_Planks"
    },
    {
      "x": 1,
      "y": 6,
      "z": 2,
      "name": "Wood_Deadwood_Planks"
    },
    {
      "x": 1,
      "y": 7,
      "z": 2,
      "name": "Soil_Snow_Half"
    },
    {
      "x": 1,
      "y": 26,
      "z": 2,
      "name": "Deco_Rope_Diagonal",
      "rotation": 3
    },
    {
      "x": 2,
      "y": 5,
      "z": -9,
      "name": "Wood_Darkwood_Planks"
    },
    {
      "x": 2,
      "y": 6,
      "z": -9,
      "name": "Wood_Deadwood_Planks"
    },
    {
      "x": 2,
      "y": 3,
      "z": -8,
      "name": "Wood_Deadwood_Planks"
    },
    {
      "x": 2,
      "y": 4,
      "z": -8,
      "name": "Wood_Darkwood_Planks"
    },
    {
      "x": 2,
      "y": 5,
      "z": -8,
      "name": "Wood_Ash_Trunk",
      "support": 15,
      "rotation": 5
    },
    {
      "x": 2,
      "y": 7,
      "z": -8,
      "name": "Wood_Darkwood_Planks"
    },
    {
      "x": 2,
      "y": 8,
      "z": -8,
      "name": "Wood_Darkwood_Planks"
    },
    {
      "x": 2,
      "y": 9,
      "z": -8,
      "name": "Wood_Deadwood_Planks"
    },
    {
      "x": 2,
      "y": 2,
      "z": -7,
      "name": "Wood_Deadwood_Planks"
    },
    {
      "x": 2,
      "y": 3,
      "z": -7,
      "name": "Wood_Deadwood_Planks"
    },
    {
      "x": 2,
      "y": 5,
      "z": -7,
      "name": "Wood_Darkwood_Planks"
    },
    {
      "x": 2,
      "y": 8,
      "z": -7,
      "name": "Wood_Ash_Trunk",
      "support": 15,
      "rotation": 5
    },
    {
      "x": 2,
      "y": 9,
      "z": -7,
      "name": "Soil_Snow_Half"
    },
    {
      "x": 2,
      "y": 1,
      "z": -6,
      "name": "Wood_Deadwood_Planks"
    },
    {
      "x": 2,
      "y": 4,
      "z": -6,
      "name": "Wood_Darkwood_Planks"
    },
    {
      "x": 2,
      "y": 7,
      "z": -6,
      "name": "Wood_Darkwood_Planks"
    },
    {
      "x": 2,
      "y": 8,
      "z": -6,
      "name": "Wood_Darkwood_Planks"
    },
    {
      "x": 2,
      "y": 1,
      "z": -5,
      "name": "Wood_Darkwood_Planks"
    },
    {
      "x": 2,
      "y": 4,
      "z": -5,
      "name": "Wood_Darkwood_Planks"
    },
    {
      "x": 2,
      "y": 7,
      "z": -5,
      "name": "Wood_Darkwood_Planks"
    },
    {
      "x": 2,
      "y": 25,
      "z": -5,
      "name": "Cloth_Roof_Hide_Flap_White",
      "rotation": 1
    },
    {
      "x": 2,
      "y": 26,
      "z": -5,
      "name": "Wood_Ash_Trunk_Full",
      "support": 15,
      "rotation": 4
    },
    {
      "x": 2,
      "y": 1,
      "z": -4,
      "name": "Wood_Deadwood_Planks"
    },
    {
      "x": 2,
      "y": 4,
      "z": -4,
      "name": "Wood_Ash_Trunk",
      "support": 15,
      "rotation": 5
    },
    {
      "x": 2,
      "y": 7,
      "z": -4,
      "name": "Wood_Darkwood_Planks"
    },
    {
      "x": 2,
      "y": 20,
      "z": -4,
      "name": "Cloth_Roof_Hide_Flap_White",
      "rotation": 1
    },
    {
      "x": 2,
      "y": 21,
      "z": -4,
      "name": "Cloth_Roof_Hide_Vertical_White",
      "rotation": 1
    },
    {
      "x": 2,
      "y": 22,
      "z": -4,
      "name": "Cloth_Roof_Hide_Vertical_White",
      "rotation": 1
    },
    {
      "x": 2,
      "y": 23,
      "z": -4,
      "name": "Cloth_Roof_Hide_Vertical_White",
      "rotation": 1
    },
    {
      "x": 2,
      "y": 24,
      "z": -4,
      "name": "Cloth_Roof_Hide_Vertical_White",
      "rotation": 1
    },
    {
      "x": 2,
      "y": 25,
      "z": -4,
      "name": "Cloth_Roof_Hide_Vertical_White",
      "rotation": 1
    },
    {
      "x": 2,
      "y": 26,
      "z": -4,
      "name": "Wood_Ash_Trunk_Full",
      "support": 15,
      "rotation": 4
    },
    {
      "x": 2,
      "y": 0,
      "z": -3,
      "name": "Wood_Deadwood_Planks"
    },
    {
      "x": 2,
      "y": 1,
      "z": -3,
      "name": "Wood_Deadwood_Planks"
    },
    {
      "x": 2,
      "y": 4,
      "z": -3,
      "name": "Wood_Darkwood_Planks"
    },
    {
      "x": 2,
      "y": 7,
      "z": -3,
      "name": "Wood_Ash_Trunk",
      "support": 15,
      "rotation": 5
    },
    {
      "x": 2,
      "y": 21,
      "z": -3,
      "name": "Cloth_Roof_Hide_Flap_White",
      "rotation": 1
    },
    {
      "x": 2,
      "y": 22,
      "z": -3,
      "name": "Cloth_Roof_Hide_Vertical_White",
      "rotation": 1
    },
    {
      "x": 2,
      "y": 23,
      "z": -3,
      "name": "Cloth_Roof_Hide_Flap_White",
      "rotation": 11
    },
    {
      "x": 2,
      "y": 24,
      "z": -3,
      "name": "Cloth_Roof_Hide_Flap_White",
      "rotation": 1
    },
    {
      "x": 2,
      "y": 25,
      "z": -3,
      "name": "Wood_Ash_Trunk_Half",
      "rotation": 8
    },
    {
      "x": 2,
      "y": 26,
      "z": -3,
      "name": "Wood_Ash_Trunk_Half"
    },
    {
      "x": 2,
      "y": 1,
      "z": -2,
      "name": "Wood_Deadwood_Planks"
    },
    {
      "x": 2,
      "y": 3,
      "z": -2,
      "name": "Wood_Darkwood_Planks"
    },
    {
      "x": 2,
      "y": 6,
      "z": -2,
      "name": "Wood_Darkwood_Planks"
    },
    {
      "x": 2,
      "y": 21,
      "z": -2,
      "name": "Cloth_Roof_Hide_Flap_White",
      "rotation": 1
    },
    {
      "x": 2,
      "y": 22,
      "z": -2,
      "name": "Cloth_Roof_Hide_Vertical_White",
      "rotation": 1
    },
    {
      "x": 2,
      "y": 23,
      "z": -2,
      "name": "Cloth_Roof_Hide_Flap_White",
      "rotation": 11
    },
    {
      "x": 2,
      "y": 24,
      "z": -2,
      "name": "Cloth_Roof_Hide_Flap_White",
      "rotation": 1
    },
    {
      "x": 2,
      "y": 25,
      "z": -2,
      "name": "Wood_Ash_Trunk_Half",
      "rotation": 8
    },
    {
      "x": 2,
      "y": 26,
      "z": -2,
      "name": "Wood_Ash_Trunk_Half"
    },
    {
      "x": 2,
      "y": 1,
      "z": -1,
      "name": "Wood_Deadwood_Planks"
    },
    {
      "x": 2,
      "y": 3,
      "z": -1,
      "name": "Wood_Darkwood_Planks"
    },
    {
      "x": 2,
      "y": 6,
      "z": -1,
      "name": "Wood_Darkwood_Planks"
    },
    {
      "x": 2,
      "y": 22,
      "z": -1,
      "name": "Cloth_Roof_Hide_Flap_White",
      "rotation": 1
    },
    {
      "x": 2,
      "y": 23,
      "z": -1,
      "name": "Cloth_Roof_Hide_Vertical_White",
      "rotation": 1
    },
    {
      "x": 2,
      "y": 24,
      "z": -1,
      "name": "Cloth_Roof_Hide_Vertical_White",
      "rotation": 1
    },
    {
      "x": 2,
      "y": 25,
      "z": -1,
      "name": "Wood_Ash_Trunk_Full",
      "support": 15,
      "rotation": 4
    },
    {
      "x": 2,
      "y": 26,
      "z": -1,
      "name": "Wood_Ash_Trunk_Half"
    },
    {
      "x": 2,
      "y": 2,
      "z": 0,
      "name": "Wood_Darkwood_Planks"
    },
    {
      "x": 2,
      "y": 3,
      "z": 0,
      "name": "Wood_Ash_Trunk",
      "support": 15,
      "rotation": 5
    },
    {
      "x": 2,
      "y": 6,
      "z": 0,
      "name": "Wood_Darkwood_Planks"
    },
    {
      "x": 2,
      "y": 22,
      "z": 0,
      "name": "Cloth_Roof_Hide_Flap_White",
      "rotation": 1
    },
    {
      "x": 2,
      "y": 23,
      "z": 0,
      "name": "Cloth_Roof_Hide_Vertical_White",
      "rotation": 1
    },
    {
      "x": 2,
      "y": 24,
      "z": 0,
      "name": "Cloth_Roof_Hide_Vertical_White",
      "rotation": 1
    },
    {
      "x": 2,
      "y": 25,
      "z": 0,
      "name": "Wood_Ash_Trunk_Full",
      "support": 15,
      "rotation": 4
    },
    {
      "x": 2,
      "y": 3,
      "z": 1,
      "name": "Wood_Darkwood_Planks"
    },
    {
      "x": 2,
      "y": 4,
      "z": 1,
      "name": "Wood_Deadwood_Planks"
    },
    {
      "x": 2,
      "y": 5,
      "z": 1,
      "name": "Wood_Darkwood_Planks"
    },
    {
      "x": 2,
      "y": 6,
      "z": 1,
      "name": "Wood_Ash_Trunk",
      "support": 15,
      "rotation": 5
    },
    {
      "x": 2,
      "y": 23,
      "z": 1,
      "name": "Rock_Ice_Icicles",
      "rotation": 8
    },
    {
      "x": 2,
      "y": 24,
      "z": 1,
      "name": "Wood_Ash_Trunk",
      "support": 15,
      "rotation": 4
    },
    {
      "x": 2,
      "y": 25,
      "z": 1,
      "name": "Wood_Ash_Trunk_Half"
    },
    {
      "x": 2,
      "y": 4,
      "z": 2,
      "name": "Wood_Darkwood_Planks"
    },
    {
      "x": 2,
      "y": 5,
      "z": 2,
      "name": "Wood_Darkwood_Planks"
    },
    {
      "x": 2,
      "y": 6,
      "z": 2,
      "name": "Wood_Deadwood_Planks"
    },
    {
      "x": 2,
      "y": 22,
      "z": 2,
      "name": "Cloth_Roof_Hide_Flap_White",
      "rotation": 1
    },
    {
      "x": 2,
      "y": 23,
      "z": 2,
      "name": "Cloth_Roof_Hide_Vertical_White",
      "rotation": 1
    },
    {
      "x": 2,
      "y": 24,
      "z": 2,
      "name": "Wood_Ash_Trunk",
      "support": 15,
      "rotation": 4
    },
    {
      "x": 2,
      "y": 25,
      "z": 2,
      "name": "Wood_Fir_Trunk",
      "support": 15,
      "rotation": 5
    },
    {
      "x": 2,
      "y": 26,
      "z": 2,
      "name": "Soil_Snow_Half"
    },
    {
      "x": 2,
      "y": 27,
      "z": 2,
      "name": "Deco_Rope_Diagonal",
      "rotation": 3
    },
    {
      "x": 2,
      "y": 22,
      "z": 3,
      "name": "Rock_Ice_Stalactite_Large",
      "filler": 31744,
      "rotation": 8
    },
    {
      "x": 2,
      "y": 23,
      "z": 3,
      "name": "Rock_Ice_Stalactite_Large",
      "rotation": 8
    },
    {
      "x": 2,
      "y": 24,
      "z": 3,
      "name": "Wood_Ash_Trunk",
      "support": 15,
      "rotation": 4
    },
    {
      "x": 2,
      "y": 25,
      "z": 3,
      "name": "Soil_Snow_Half"
    },
    {
      "x": 2,
      "y": 19,
      "z": 4,
      "name": "Cloth_Roof_Hide_Flap_White",
      "rotation": 1
    },
    {
      "x": 2,
      "y": 20,
      "z": 4,
      "name": "Cloth_Roof_Hide_Vertical_White",
      "rotation": 1
    },
    {
      "x": 2,
      "y": 21,
      "z": 4,
      "name": "Cloth_Roof_Hide_Vertical_White",
      "rotation": 1
    },
    {
      "x": 2,
      "y": 22,
      "z": 4,
      "name": "Cloth_Roof_Hide_Vertical_White",
      "rotation": 1
    },
    {
      "x": 2,
      "y": 23,
      "z": 4,
      "name": "Wood_Ash_Trunk",
      "support": 15,
      "rotation": 4
    },
    {
      "x": 2,
      "y": 24,
      "z": 4,
      "name": "Soil_Snow_Half"
    },
    {
      "x": 2,
      "y": 25,
      "z": 4,
      "name": "Soil_Snow_Half"
    },
    {
      "x": 2,
      "y": 18,
      "z": 5,
      "name": "Cloth_Roof_Hide_Flap_White",
      "rotation": 1
    },
    {
      "x": 2,
      "y": 19,
      "z": 5,
      "name": "Cloth_Roof_Hide_Vertical_White",
      "rotation": 1
    },
    {
      "x": 2,
      "y": 20,
      "z": 5,
      "name": "Cloth_Roof_Hide_Vertical_White",
      "rotation": 1
    },
    {
      "x": 2,
      "y": 21,
      "z": 5,
      "name": "Cloth_Roof_Hide_Vertical_White",
      "rotation": 1
    },
    {
      "x": 2,
      "y": 22,
      "z": 5,
      "name": "Cloth_Roof_Hide_Vertical_White",
      "rotation": 1
    },
    {
      "x": 2,
      "y": 23,
      "z": 5,
      "name": "Wood_Fir_Trunk",
      "support": 15,
      "rotation": 4
    },
    {
      "x": 2,
      "y": 24,
      "z": 5,
      "name": "Rubble_Ice",
      "support": 15
    },
    {
      "x": 2,
      "y": 20,
      "z": 6,
      "name": "Cloth_Roof_Hide_Flap_White",
      "rotation": 11
    },
    {
      "x": 2,
      "y": 21,
      "z": 6,
      "name": "Cloth_Roof_Hide_Flap_White",
      "rotation": 1
    },
    {
      "x": 2,
      "y": 22,
      "z": 6,
      "name": "Cloth_Roof_Hide_Vertical_White",
      "rotation": 1
    },
    {
      "x": 2,
      "y": 23,
      "z": 6,
      "name": "Wood_Fir_Trunk",
      "support": 15,
      "rotation": 4
    },
    {
      "x": 2,
      "y": 17,
      "z": 7,
      "name": "Cloth_Roof_Hide_Flap_White",
      "rotation": 1
    },
    {
      "x": 2,
      "y": 18,
      "z": 7,
      "name": "Cloth_Roof_Hide_Vertical_White",
      "rotation": 1
    },
    {
      "x": 2,
      "y": 19,
      "z": 7,
      "name": "Cloth_Roof_Hide_Vertical_White",
      "rotation": 1
    },
    {
      "x": 2,
      "y": 20,
      "z": 7,
      "name": "Cloth_Roof_Hide_Vertical_White",
      "rotation": 1
    },
    {
      "x": 2,
      "y": 21,
      "z": 7,
      "name": "Cloth_Roof_Hide_Vertical_White",
      "rotation": 1
    },
    {
      "x": 2,
      "y": 22,
      "z": 7,
      "name": "Cloth_Roof_Hide_Vertical_White",
      "rotation": 1
    },
    {
      "x": 2,
      "y": 23,
      "z": 7,
      "name": "Wood_Ash_Trunk",
      "support": 15,
      "rotation": 4
    },
    {
      "x": 2,
      "y": 20,
      "z": 8,
      "name": "Cloth_Roof_Hide_Vertical_White",
      "rotation": 1
    },
    {
      "x": 2,
      "y": 21,
      "z": 8,
      "name": "Cloth_Roof_Hide_Vertical_White",
      "rotation": 1
    },
    {
      "x": 2,
      "y": 22,
      "z": 8,
      "name": "Wood_Ash_Trunk",
      "support": 15,
      "rotation": 4
    },
    {
      "x": 2,
      "y": 23,
      "z": 8,
      "name": "Soil_Snow_Half"
    },
    {
      "x": 2,
      "y": 19,
      "z": 9,
      "name": "Cloth_Roof_Hide_Flap_White",
      "rotation": 1
    },
    {
      "x": 2,
      "y": 20,
      "z": 9,
      "name": "Cloth_Roof_Hide_Vertical_White",
      "rotation": 1
    },
    {
      "x": 2,
      "y": 21,
      "z": 9,
      "name": "Cloth_Roof_Hide_Vertical_White",
      "rotation": 1
    },
    {
      "x": 2,
      "y": 22,
      "z": 9,
      "name": "Wood_Ash_Trunk",
      "support": 15,
      "rotation": 4
    },
    {
      "x": 2,
      "y": 23,
      "z": 9,
      "name": "Rubble_Ice",
      "support": 15
    },
    {
      "x": 3,
      "y": 5,
      "z": -9,
      "name": "Wood_Darkwood_Planks"
    },
    {
      "x": 3,
      "y": 6,
      "z": -9,
      "name": "Wood_Deadwood_Planks"
    },
    {
      "x": 3,
      "y": 3,
      "z": -8,
      "name": "Wood_Deadwood_Planks"
    },
    {
      "x": 3,
      "y": 4,
      "z": -8,
      "name": "Wood_Darkwood_Planks"
    },
    {
      "x": 3,
      "y": 5,
      "z": -8,
      "name": "Wood_Ash_Trunk",
      "support": 15,
      "rotation": 4
    },
    {
      "x": 3,
      "y": 7,
      "z": -8,
      "name": "Wood_Darkwood_Planks"
    },
    {
      "x": 3,
      "y": 8,
      "z": -8,
      "name": "Wood_Darkwood_Planks"
    },
    {
      "x": 3,
      "y": 9,
      "z": -8,
      "name": "Wood_Deadwood_Planks"
    },
    {
      "x": 3,
      "y": 2,
      "z": -7,
      "name": "Wood_Deadwood_Planks"
    },
    {
      "x": 3,
      "y": 3,
      "z": -7,
      "name": "Wood_Deadwood_Planks"
    },
    {
      "x": 3,
      "y": 5,
      "z": -7,
      "name": "Wood_Ash_Trunk",
      "support": 15,
      "rotation": 4
    },
    {
      "x": 3,
      "y": 8,
      "z": -7,
      "name": "Wood_Ash_Trunk",
      "support": 15,
      "rotation": 4
    },
    {
      "x": 3,
      "y": 9,
      "z": -7,
      "name": "Deco_Rope_Diagonal",
      "rotation": 2
    },
    {
      "x": 3,
      "y": 1,
      "z": -6,
      "name": "Wood_Deadwood_Planks"
    },
    {
      "x": 3,
      "y": 4,
      "z": -6,
      "name": "Wood_Ash_Trunk",
      "support": 15,
      "rotation": 4
    },
    {
      "x": 3,
      "y": 7,
      "z": -6,
      "name": "Wood_Ash_Trunk",
      "support": 15,
      "rotation": 4
    },
    {
      "x": 3,
      "y": 8,
      "z": -6,
      "name": "Wood_Ash_Trunk",
      "support": 15,
      "rotation": 4
    },
    {
      "x": 3,
      "y": 10,
      "z": -6,
      "name": "Deco_Rope_Diagonal",
      "rotation": 2
    },
    {
      "x": 3,
      "y": 1,
      "z": -5,
      "name": "Wood_Darkwood_Planks"
    },
    {
      "x": 3,
      "y": 4,
      "z": -5,
      "name": "Wood_Ash_Trunk",
      "support": 15,
      "rotation": 4
    },
    {
      "x": 3,
      "y": 7,
      "z": -5,
      "name": "Wood_Ash_Trunk",
      "support": 15,
      "rotation": 4
    },
    {
      "x": 3,
      "y": 11,
      "z": -5,
      "name": "Deco_Rope_Diagonal",
      "rotation": 2
    },
    {
      "x": 3,
      "y": 1,
      "z": -4,
      "name": "Wood_Deadwood_Planks"
    },
    {
      "x": 3,
      "y": 2,
      "z": -4,
      "name": "Wood_Ash_Trunk",
      "support": 15
    },
    {
      "x": 3,
      "y": 3,
      "z": -4,
      "name": "Wood_Ash_Trunk",
      "support": 15
    },
    {
      "x": 3,
      "y": 4,
      "z": -4,
      "name": "Wood_Ash_Trunk",
      "support": 15,
      "rotation": 5
    },
    {
      "x": 3,
      "y": 5,
      "z": -4,
      "name": "Wood_Ash_Trunk",
      "support": 15
    },
    {
      "x": 3,
      "y": 7,
      "z": -4,
      "name": "Wood_Ash_Trunk",
      "support": 15,
      "rotation": 4
    },
    {
      "x": 3,
      "y": 12,
      "z": -4,
      "name": "Deco_Rope_Diagonal",
      "rotation": 2
    },
    {
      "x": 3,
      "y": 0,
      "z": -3,
      "name": "Wood_Deadwood_Planks"
    },
    {
      "x": 3,
      "y": 1,
      "z": -3,
      "name": "Wood_Deadwood_Planks"
    },
    {
      "x": 3,
      "y": 4,
      "z": -3,
      "name": "Wood_Ash_Trunk",
      "support": 15,
      "rotation": 4
    },
    {
      "x": 3,
      "y": 6,
      "z": -3,
      "name": "Wood_Ash_Trunk",
      "support": 15
    },
    {
      "x": 3,
      "y": 7,
      "z": -3,
      "name": "Wood_Ash_Trunk_Full",
      "support": 15
    },
    {
      "x": 3,
      "y": 8,
      "z": -3,
      "name": "Wood_Ash_Trunk_Half",
      "rotation": 6
    },
    {
      "x": 3,
      "y": 13,
      "z": -3,
      "name": "Deco_Rope_Diagonal",
      "rotation": 2
    },
    {
      "x": 3,
      "y": 3,
      "z": -2,
      "name": "Wood_Ash_Trunk",
      "support": 15,
      "rotation": 4
    },
    {
      "x": 3,
      "y": 6,
      "z": -2,
      "name": "Wood_Ash_Trunk",
      "support": 15,
      "rotation": 4
    },
    {
      "x": 3,
      "y": 7,
      "z": -2,
      "name": "Wood_Ash_Trunk_Half",
      "rotation": 4
    },
    {
      "x": 3,
      "y": 8,
      "z": -2,
      "name": "Wood_Ash_Trunk_Half",
      "rotation": 4
    },
    {
      "x": 3,
      "y": 9,
      "z": -2,
      "name": "Wood_Ash_Trunk",
      "support": 15
    },
    {
      "x": 3,
      "y": 10,
      "z": -2,
      "name": "Wood_Ash_Trunk_Full",
      "support": 15
    },
    {
      "x": 3,
      "y": 11,
      "z": -2,
      "name": "Wood_Ash_Trunk_Half",
      "rotation": 6
    },
    {
      "x": 3,
      "y": 12,
      "z": -2,
      "name": "Wood_Ash_Trunk_Half",
      "rotation": 6
    },
    {
      "x": 3,
      "y": 14,
      "z": -2,
      "name": "Deco_Rope_Diagonal",
      "rotation": 2
    },
    {
      "x": 3,
      "y": 3,
      "z": -1,
      "name": "Wood_Ash_Trunk",
      "support": 15,
      "rotation": 4
    },
    {
      "x": 3,
      "y": 6,
      "z": -1,
      "name": "Wood_Ash_Trunk",
      "support": 15,
      "rotation": 4
    },
    {
      "x": 3,
      "y": 11,
      "z": -1,
      "name": "Wood_Ash_Trunk_Half",
      "rotation": 4
    },
    {
      "x": 3,
      "y": 12,
      "z": -1,
      "name": "Wood_Ash_Trunk_Half",
      "rotation": 4
    },
    {
      "x": 3,
      "y": 13,
      "z": -1,
      "name": "Wood_Ash_Trunk",
      "support": 15
    },
    {
      "x": 3,
      "y": 14,
      "z": -1,
      "name": "Wood_Ash_Trunk_Full",
      "support": 15
    },
    {
      "x": 3,
      "y": 15,
      "z": -1,
      "name": "Wood_Ash_Trunk_Half",
      "rotation": 6
    },
    {
      "x": 3,
      "y": 16,
      "z": -1,
      "name": "Wood_Ash_Trunk_Half",
      "rotation": 6
    },
    {
      "x": 3,
      "y": 3,
      "z": 0,
      "name": "Wood_Ash_Trunk",
      "support": 15,
      "rotation": 4
    },
    {
      "x": 3,
      "y": 6,
      "z": 0,
      "name": "Wood_Ash_Trunk",
      "support": 15,
      "rotation": 4
    },
    {
      "x": 3,
      "y": 15,
      "z": 0,
      "name": "Wood_Ash_Trunk_Half",
      "rotation": 4
    },
    {
      "x": 3,
      "y": 16,
      "z": 0,
      "name": "Wood_Ash_Trunk_Half",
      "rotation": 4
    },
    {
      "x": 3,
      "y": 17,
      "z": 0,
      "name": "Wood_Ash_Trunk",
      "support": 15
    },
    {
      "x": 3,
      "y": 18,
      "z": 0,
      "name": "Wood_Ash_Trunk_Full",
      "support": 15
    },
    {
      "x": 3,
      "y": 19,
      "z": 0,
      "name": "Wood_Ash_Trunk_Half",
      "rotation": 6
    },
    {
      "x": 3,
      "y": 20,
      "z": 0,
      "name": "Wood_Ash_Trunk_Half",
      "rotation": 6
    },
    {
      "x": 3,
      "y": 3,
      "z": 1,
      "name": "Wood_Darkwood_Planks"
    },
    {
      "x": 3,
      "y": 4,
      "z": 1,
      "name": "Wood_Deadwood_Planks"
    },
    {
      "x": 3,
      "y": 5,
      "z": 1,
      "name": "Wood_Darkwood_Planks"
    },
    {
      "x": 3,
      "y": 6,
      "z": 1,
      "name": "Wood_Ash_Trunk",
      "support": 15,
      "rotation": 4
    },
    {
      "x": 3,
      "y": 19,
      "z": 1,
      "name": "Wood_Ash_Trunk_Half",
      "rotation": 4
    },
    {
      "x": 3,
      "y": 20,
      "z": 1,
      "name": "Wood_Ash_Trunk_Half",
      "rotation": 4
    },
    {
      "x": 3,
      "y": 21,
      "z": 1,
      "name": "Wood_Ash_Trunk",
      "support": 15
    },
    {
      "x": 3,
      "y": 22,
      "z": 1,
      "name": "Wood_Ash_Trunk",
      "support": 15
    },
    {
      "x": 3,
      "y": 23,
      "z": 1,
      "name": "Wood_Ash_Trunk",
      "support": 15
    },
    {
      "x": 3,
      "y": 24,
      "z": 1,
      "name": "Wood_Ash_Trunk",
      "support": 15
    },
    {
      "x": 3,
      "y": 25,
      "z": 1,
      "name": "Wood_Ash_Trunk",
      "support": 15,
      "rotation": 4
    },
    {
      "x": 3,
      "y": 26,
      "z": 1,
      "name": "Soil_Snow_Half"
    },
    {
      "x": 3,
      "y": 5,
      "z": 2,
      "name": "Wood_Darkwood_Planks"
    },
    {
      "x": 3,
      "y": 6,
      "z": 2,
      "name": "Wood_Deadwood_Planks"
    },
    {
      "x": 3,
      "y": 25,
      "z": 2,
      "name": "Wood_Ash_Trunk",
      "support": 15
    },
    {
      "x": 3,
      "y": 26,
      "z": 2,
      "name": "Wood_Ash_Trunk",
      "support": 15
    },
    {
      "x": 3,
      "y": 27,
      "z": 2,
      "name": "Wood_Ash_Trunk",
      "support": 15
    },
    {
      "x": 3,
      "y": 28,
      "z": 2,
      "name": "Wood_Ash_Trunk",
      "support": 15
    },
    {
      "x": 3,
      "y": 25,
      "z": 3,
      "name": "Wood_Ash_Trunk",
      "support": 15,
      "rotation": 4
    },
    {
      "x": 3,
      "y": 26,
      "z": 3,
      "name": "Rubble_Ice",
      "support": 15
    },
    {
      "x": 3,
      "y": 28,
      "z": 3,
      "name": "Wood_Ash_Trunk",
      "support": 15
    },
    {
      "x": 3,
      "y": 29,
      "z": 3,
      "name": "Wood_Ash_Trunk",
      "support": 15
    },
    {
      "x": 3,
      "y": 30,
      "z": 3,
      "name": "Rubble_Ice",
      "support": 15
    },
    {
      "x": 4,
      "y": 5,
      "z": -9,
      "name": "Wood_Darkwood_Planks"
    },
    {
      "x": 4,
      "y": 5,
      "z": -8,
      "name": "Wood_Ash_Trunk",
      "support": 15,
      "rotation": 5
    },
    {
      "x": 4,
      "y": 6,
      "z": -7,
      "name": "Rock_Ice_Stalactite_Large",
      "filler": 31744,
      "rotation": 8
    },
    {
      "x": 4,
      "y": 7,
      "z": -7,
      "name": "Rock_Ice_Stalactite_Large",
      "rotation": 8
    },
    {
      "x": 4,
      "y": 8,
      "z": -7,
      "name": "Wood_Ash_Trunk",
      "support": 15,
      "rotation": 5
    },
    {
      "x": 4,
      "y": 7,
      "z": -6,
      "name": "Wood_Darkwood_Planks"
    },
    {
      "x": 4,
      "y": 8,
      "z": -6,
      "name": "Wood_Darkwood_Planks"
    },
    {
      "x": 4,
      "y": 4,
      "z": -5,
      "name": "Wood_Darkwood_Planks"
    },
    {
      "x": 4,
      "y": 7,
      "z": -5,
      "name": "Wood_Darkwood_Planks"
    },
    {
      "x": 4,
      "y": 4,
      "z": -4,
      "name": "Wood_Ash_Trunk",
      "support": 15,
      "rotation": 5
    },
    {
      "x": 4,
      "y": 7,
      "z": -4,
      "name": "Wood_Darkwood_Planks"
    },
    {
      "x": 4,
      "y": 4,
      "z": -3,
      "name": "Wood_Darkwood_Planks"
    },
    {
      "x": 4,
      "y": 7,
      "z": -3,
      "name": "Wood_Ash_Trunk",
      "support": 15,
      "rotation": 5
    },
    {
      "x": 4,
      "y": 3,
      "z": -2,
      "name": "Wood_Darkwood_Planks"
    },
    {
      "x": 4,
      "y": 6,
      "z": -2,
      "name": "Wood_Darkwood_Planks"
    },
    {
      "x": 4,
      "y": 3,
      "z": -1,
      "name": "Wood_Darkwood_Planks"
    },
    {
      "x": 4,
      "y": 6,
      "z": -1,
      "name": "Wood_Darkwood_Planks"
    },
    {
      "x": 4,
      "y": 3,
      "z": 0,
      "name": "Wood_Ash_Trunk",
      "support": 15,
      "rotation": 5
    },
    {
      "x": 4,
      "y": 6,
      "z": 0,
      "name": "Wood_Darkwood_Planks"
    },
    {
      "x": 4,
      "y": 5,
      "z": 1,
      "name": "Wood_Darkwood_Planks"
    },
    {
      "x": 4,
      "y": 6,
      "z": 1,
      "name": "Wood_Ash_Trunk",
      "support": 15,
      "rotation": 5
    },
    {
      "x": 4,
      "y": 9,
      "z": 1,
      "name": "Deco_Rope"
    },
    {
      "x": 4,
      "y": 10,
      "z": 1,
      "name": "Deco_Rope"
    },
    {
      "x": 4,
      "y": 11,
      "z": 1,
      "name": "Deco_Rope"
    },
    {
      "x": 4,
      "y": 12,
      "z": 1,
      "name": "Deco_Rope"
    },
    {
      "x": 4,
      "y": 13,
      "z": 1,
      "name": "Deco_Rope"
    },
    {
      "x": 4,
      "y": 14,
      "z": 1,
      "name": "Deco_Rope"
    },
    {
      "x": 4,
      "y": 15,
      "z": 1,
      "name": "Deco_Rope"
    },
    {
      "x": 4,
      "y": 16,
      "z": 1,
      "name": "Deco_Rope"
    },
    {
      "x": 4,
      "y": 17,
      "z": 1,
      "name": "Deco_Rope"
    },
    {
      "x": 4,
      "y": 18,
      "z": 1,
      "name": "Deco_Rope"
    },
    {
      "x": 4,
      "y": 19,
      "z": 1,
      "name": "Deco_Rope"
    },
    {
      "x": 4,
      "y": 20,
      "z": 1,
      "name": "Deco_Rope"
    },
    {
      "x": 4,
      "y": 21,
      "z": 1,
      "name": "Deco_Rope"
    },
    {
      "x": 4,
      "y": 22,
      "z": 1,
      "name": "Deco_Rope"
    },
    {
      "x": 4,
      "y": 23,
      "z": 1,
      "name": "Deco_Rope"
    },
    {
      "x": 4,
      "y": 24,
      "z": 1,
      "name": "Deco_Rope"
    },
    {
      "x": 4,
      "y": 25,
      "z": 1,
      "name": "Wood_Ash_Trunk_Full",
      "support": 15,
      "rotation": 5
    },
    {
      "x": 4,
      "y": 5,
      "z": 2,
      "name": "Wood_Darkwood_Planks"
    },
    {
      "x": 4,
      "y": 6,
      "z": 2,
      "name": "Wood_Deadwood_Planks"
    },
    {
      "x": 5,
      "y": 5,
      "z": -8,
      "name": "Wood_Ash_Trunk",
      "support": 15,
      "rotation": 5
    },
    {
      "x": 5,
      "y": 8,
      "z": -7,
      "name": "Wood_Ash_Trunk",
      "support": 15,
      "rotation": 5
    },
    {
      "x": 5,
      "y": 7,
      "z": -6,
      "name": "Wood_Darkwood_Planks"
    },
    {
      "x": 5,
      "y": 8,
      "z": -6,
      "name": "Wood_Darkwood_Planks"
    },
    {
      "x": 5,
      "y": 4,
      "z": -5,
      "name": "Wood_Darkwood_Planks"
    },
    {
      "x": 5,
      "y": 7,
      "z": -5,
      "name": "Rock_Calcite_Cobble"
    },
    {
      "x": 5,
      "y": 4,
      "z": -4,
      "name": "Wood_Ash_Trunk",
      "support": 15,
      "rotation": 5
    },
    {
      "x": 5,
      "y": 7,
      "z": -4,
      "name": "Rock_Calcite_Cobble"
    },
    {
      "x": 5,
      "y": 4,
      "z": -3,
      "name": "Wood_Darkwood_Planks"
    },
    {
      "x": 5,
      "y": 7,
      "z": -3,
      "name": "Wood_Ash_Trunk",
      "support": 15,
      "rotation": 5
    },
    {
      "x": 5,
      "y": 3,
      "z": -2,
      "name": "Wood_Darkwood_Planks"
    },
    {
      "x": 5,
      "y": 6,
      "z": -2,
      "name": "Wood_Darkwood_Planks"
    },
    {
      "x": 5,
      "y": 3,
      "z": -1,
      "name": "Wood_Darkwood_Planks"
    },
    {
      "x": 5,
      "y": 6,
      "z": -1,
      "name": "Wood_Darkwood_Planks"
    },
    {
      "x": 5,
      "y": 6,
      "z": 0,
      "name": "Wood_Darkwood_Planks"
    },
    {
      "x": 6,
      "y": 5,
      "z": -8,
      "name": "Wood_Ash_Trunk",
      "support": 15,
      "rotation": 5
    },
    {
      "x": 6,
      "y": 4,
      "z": -6,
      "name": "Wood_Darkwood_Planks"
    },
    {
      "x": 6,
      "y": 7,
      "z": -6,
      "name": "Wood_Darkwood_Planks"
    },
    {
      "x": 6,
      "y": 8,
      "z": -6,
      "name": "Wood_Darkwood_Planks"
    },
    {
      "x": 6,
      "y": 4,
      "z": -5,
      "name": "Wood_Darkwood_Planks"
    },
    {
      "x": 6,
      "y": 7,
      "z": -5,
      "name": "Rock_Calcite_Cobble"
    },
    {
      "x": 6,
      "y": 4,
      "z": -4,
      "name": "Wood_Ash_Trunk",
      "support": 15,
      "rotation": 5
    },
    {
      "x": 6,
      "y": 7,
      "z": -4,
      "name": "Rock_Calcite_Cobble"
    },
    {
      "x": 6,
      "y": 4,
      "z": -3,
      "name": "Wood_Darkwood_Planks"
    },
    {
      "x": 6,
      "y": 7,
      "z": -3,
      "name": "Wood_Ash_Trunk",
      "support": 15,
      "rotation": 5
    },
    {
      "x": 6,
      "y": 3,
      "z": -2,
      "name": "Wood_Darkwood_Planks"
    },
    {
      "x": 6,
      "y": 6,
      "z": -2,
      "name": "Rock_Calcite_Cobble"
    },
    {
      "x": 6,
      "y": 3,
      "z": -1,
      "name": "Wood_Darkwood_Planks"
    },
    {
      "x": 6,
      "y": 6,
      "z": -1,
      "name": "Rock_Calcite_Cobble"
    },
    {
      "x": 6,
      "y": 6,
      "z": 0,
      "name": "Wood_Darkwood_Planks"
    },
    {
      "x": 7,
      "y": 4,
      "z": -8,
      "name": "Wood_Darkwood_Planks"
    },
    {
      "x": 7,
      "y": 5,
      "z": -8,
      "name": "Wood_Ash_Trunk",
      "support": 15,
      "rotation": 5
    },
    {
      "x": 7,
      "y": 2,
      "z": -7,
      "name": "Wood_Deadwood_Planks"
    },
    {
      "x": 7,
      "y": 5,
      "z": -7,
      "name": "Wood_Darkwood_Planks"
    },
    {
      "x": 7,
      "y": 1,
      "z": -6,
      "name": "Wood_Deadwood_Planks"
    },
    {
      "x": 7,
      "y": 4,
      "z": -6,
      "name": "Wood_Darkwood_Planks"
    },
    {
      "x": 7,
      "y": 7,
      "z": -6,
      "name": "Wood_Darkwood_Planks"
    },
    {
      "x": 7,
      "y": 8,
      "z": -6,
      "name": "Wood_Darkwood_Planks"
    },
    {
      "x": 7,
      "y": 4,
      "z": -5,
      "name": "Wood_Darkwood_Planks"
    },
    {
      "x": 7,
      "y": 7,
      "z": -5,
      "name": "Wood_Darkwood_Planks"
    },
    {
      "x": 7,
      "y": 4,
      "z": -4,
      "name": "Wood_Ash_Trunk",
      "support": 15,
      "rotation": 5
    },
    {
      "x": 7,
      "y": 7,
      "z": -4,
      "name": "Rock_Calcite_Cobble"
    },
    {
      "x": 7,
      "y": 4,
      "z": -3,
      "name": "Wood_Darkwood_Planks"
    },
    {
      "x": 7,
      "y": 7,
      "z": -3,
      "name": "Wood_Ash_Trunk",
      "support": 15,
      "rotation": 5
    },
    {
      "x": 7,
      "y": 1,
      "z": -2,
      "name": "Wood_Deadwood_Planks"
    },
    {
      "x": 7,
      "y": 3,
      "z": -2,
      "name": "Wood_Darkwood_Planks"
    },
    {
      "x": 7,
      "y": 6,
      "z": -2,
      "name": "Rock_Calcite_Cobble"
    },
    {
      "x": 7,
      "y": 1,
      "z": -1,
      "name": "Wood_Deadwood_Planks"
    },
    {
      "x": 7,
      "y": 3,
      "z": -1,
      "name": "Wood_Darkwood_Planks"
    },
    {
      "x": 7,
      "y": 6,
      "z": -1,
      "name": "Rock_Calcite_Cobble"
    },
    {
      "x": 7,
      "y": 2,
      "z": 0,
      "name": "Wood_Darkwood_Planks"
    },
    {
      "x": 7,
      "y": 3,
      "z": 0,
      "name": "Wood_Ash_Trunk",
      "support": 15,
      "rotation": 5
    },
    {
      "x": 7,
      "y": 6,
      "z": 0,
      "name": "Wood_Darkwood_Planks"
    },
    {
      "x": 7,
      "y": 3,
      "z": 1,
      "name": "Wood_Darkwood_Planks"
    },
    {
      "x": 7,
      "y": 6,
      "z": 1,
      "name": "Wood_Ash_Trunk",
      "support": 15,
      "rotation": 5
    },
    {
      "x": 8,
      "y": 5,
      "z": -9,
      "name": "Wood_Darkwood_Planks"
    },
    {
      "x": 8,
      "y": 6,
      "z": -9,
      "name": "Wood_Deadwood_Planks"
    },
    {
      "x": 8,
      "y": 3,
      "z": -8,
      "name": "Wood_Deadwood_Planks"
    },
    {
      "x": 8,
      "y": 4,
      "z": -8,
      "name": "Wood_Darkwood_Planks"
    },
    {
      "x": 8,
      "y": 5,
      "z": -8,
      "name": "Wood_Ash_Trunk",
      "support": 15,
      "rotation": 5
    },
    {
      "x": 8,
      "y": 2,
      "z": -7,
      "name": "Wood_Deadwood_Planks"
    },
    {
      "x": 8,
      "y": 3,
      "z": -7,
      "name": "Wood_Deadwood_Planks"
    },
    {
      "x": 8,
      "y": 5,
      "z": -7,
      "name": "Wood_Darkwood_Planks"
    },
    {
      "x": 8,
      "y": 8,
      "z": -7,
      "name": "Wood_Ash_Trunk",
      "support": 15,
      "rotation": 5
    },
    {
      "x": 8,
      "y": 1,
      "z": -6,
      "name": "Wood_Deadwood_Planks"
    },
    {
      "x": 8,
      "y": 4,
      "z": -6,
      "name": "Wood_Darkwood_Planks"
    },
    {
      "x": 8,
      "y": 7,
      "z": -6,
      "name": "Wood_Darkwood_Planks"
    },
    {
      "x": 8,
      "y": 8,
      "z": -6,
      "name": "Wood_Darkwood_Planks"
    },
    {
      "x": 8,
      "y": 1,
      "z": -5,
      "name": "Wood_Darkwood_Planks"
    },
    {
      "x": 8,
      "y": 4,
      "z": -5,
      "name": "Wood_Darkwood_Planks"
    },
    {
      "x": 8,
      "y": 7,
      "z": -5,
      "name": "Wood_Darkwood_Planks"
    },
    {
      "x": 8,
      "y": 1,
      "z": -4,
      "name": "Wood_Deadwood_Planks"
    },
    {
      "x": 8,
      "y": 4,
      "z": -4,
      "name": "Wood_Ash_Trunk",
      "support": 15,
      "rotation": 5
    },
    {
      "x": 8,
      "y": 7,
      "z": -4,
      "name": "Wood_Darkwood_Planks"
    },
    {
      "x": 8,
      "y": 0,
      "z": -3,
      "name": "Wood_Deadwood_Planks"
    },
    {
      "x": 8,
      "y": 1,
      "z": -3,
      "name": "Wood_Deadwood_Planks"
    },
    {
      "x": 8,
      "y": 4,
      "z": -3,
      "name": "Wood_Darkwood_Planks"
    },
    {
      "x": 8,
      "y": 7,
      "z": -3,
      "name": "Wood_Ash_Trunk",
      "support": 15,
      "rotation": 5
    },
    {
      "x": 8,
      "y": 1,
      "z": -2,
      "name": "Wood_Deadwood_Planks"
    },
    {
      "x": 8,
      "y": 3,
      "z": -2,
      "name": "Wood_Darkwood_Planks"
    },
    {
      "x": 8,
      "y": 6,
      "z": -2,
      "name": "Rock_Calcite_Cobble"
    },
    {
      "x": 8,
      "y": 1,
      "z": -1,
      "name": "Wood_Deadwood_Planks"
    },
    {
      "x": 8,
      "y": 3,
      "z": -1,
      "name": "Wood_Darkwood_Planks"
    },
    {
      "x": 8,
      "y": 6,
      "z": -1,
      "name": "Rock_Calcite_Cobble"
    },
    {
      "x": 8,
      "y": 2,
      "z": 0,
      "name": "Wood_Darkwood_Planks"
    },
    {
      "x": 8,
      "y": 3,
      "z": 0,
      "name": "Wood_Ash_Trunk",
      "support": 15,
      "rotation": 5
    },
    {
      "x": 8,
      "y": 6,
      "z": 0,
      "name": "Wood_Darkwood_Planks"
    },
    {
      "x": 8,
      "y": 3,
      "z": 1,
      "name": "Wood_Darkwood_Planks"
    },
    {
      "x": 8,
      "y": 4,
      "z": 1,
      "name": "Wood_Deadwood_Planks"
    },
    {
      "x": 8,
      "y": 6,
      "z": 1,
      "name": "Wood_Ash_Trunk",
      "support": 15,
      "rotation": 5
    },
    {
      "x": 8,
      "y": 3,
      "z": 2,
      "name": "Furniture_Tavern_Shelf"
    },
    {
      "x": 8,
      "y": 5,
      "z": 2,
      "name": "Wood_Darkwood_Planks"
    },
    {
      "x": 8,
      "y": 6,
      "z": 2,
      "name": "Wood_Deadwood_Planks"
    },
    {
      "x": 9,
      "y": 5,
      "z": -9,
      "name": "Wood_Darkwood_Planks"
    },
    {
      "x": 9,
      "y": 6,
      "z": -9,
      "name": "Wood_Deadwood_Planks"
    },
    {
      "x": 9,
      "y": 3,
      "z": -8,
      "name": "Wood_Deadwood_Planks"
    },
    {
      "x": 9,
      "y": 4,
      "z": -8,
      "name": "Wood_Darkwood_Planks"
    },
    {
      "x": 9,
      "y": 5,
      "z": -8,
      "name": "Wood_Ash_Trunk",
      "support": 15,
      "rotation": 5
    },
    {
      "x": 9,
      "y": 7,
      "z": -8,
      "name": "Wood_Darkwood_Planks"
    },
    {
      "x": 9,
      "y": 8,
      "z": -8,
      "name": "Wood_Darkwood_Planks"
    },
    {
      "x": 9,
      "y": 9,
      "z": -8,
      "name": "Wood_Deadwood_Planks"
    },
    {
      "x": 9,
      "y": 2,
      "z": -7,
      "name": "Wood_Deadwood_Planks"
    },
    {
      "x": 9,
      "y": 3,
      "z": -7,
      "name": "Wood_Deadwood_Planks"
    },
    {
      "x": 9,
      "y": 5,
      "z": -7,
      "name": "Wood_Darkwood_Planks"
    },
    {
      "x": 9,
      "y": 8,
      "z": -7,
      "name": "Wood_Ash_Trunk",
      "support": 15,
      "rotation": 5
    },
    {
      "x": 9,
      "y": 1,
      "z": -6,
      "name": "Wood_Deadwood_Planks"
    },
    {
      "x": 9,
      "y": 4,
      "z": -6,
      "name": "Wood_Darkwood_Planks"
    },
    {
      "x": 9,
      "y": 7,
      "z": -6,
      "name": "Wood_Darkwood_Planks"
    },
    {
      "x": 9,
      "y": 8,
      "z": -6,
      "name": "Wood_Darkwood_Planks"
    },
    {
      "x": 9,
      "y": 1,
      "z": -5,
      "name": "Wood_Darkwood_Planks"
    },
    {
      "x": 9,
      "y": 4,
      "z": -5,
      "name": "Wood_Darkwood_Planks"
    },
    {
      "x": 9,
      "y": 7,
      "z": -5,
      "name": "Wood_Darkwood_Planks"
    },
    {
      "x": 9,
      "y": 1,
      "z": -4,
      "name": "Wood_Deadwood_Planks"
    },
    {
      "x": 9,
      "y": 4,
      "z": -4,
      "name": "Wood_Ash_Trunk",
      "support": 15,
      "rotation": 5
    },
    {
      "x": 9,
      "y": 7,
      "z": -4,
      "name": "Wood_Darkwood_Planks"
    },
    {
      "x": 9,
      "y": 0,
      "z": -3,
      "name": "Wood_Deadwood_Planks"
    },
    {
      "x": 9,
      "y": 1,
      "z": -3,
      "name": "Wood_Deadwood_Planks"
    },
    {
      "x": 9,
      "y": 4,
      "z": -3,
      "name": "Wood_Darkwood_Planks"
    },
    {
      "x": 9,
      "y": 7,
      "z": -3,
      "name": "Wood_Ash_Trunk",
      "support": 15,
      "rotation": 5
    },
    {
      "x": 9,
      "y": 1,
      "z": -2,
      "name": "Wood_Deadwood_Planks"
    },
    {
      "x": 9,
      "y": 3,
      "z": -2,
      "name": "Wood_Darkwood_Planks"
    },
    {
      "x": 9,
      "y": 6,
      "z": -2,
      "name": "Rock_Calcite_Cobble"
    },
    {
      "x": 9,
      "y": 1,
      "z": -1,
      "name": "Wood_Deadwood_Planks"
    },
    {
      "x": 9,
      "y": 3,
      "z": -1,
      "name": "Wood_Darkwood_Planks"
    },
    {
      "x": 9,
      "y": 6,
      "z": -1,
      "name": "Wood_Darkwood_Planks"
    },
    {
      "x": 9,
      "y": 2,
      "z": 0,
      "name": "Wood_Darkwood_Planks"
    },
    {
      "x": 9,
      "y": 3,
      "z": 0,
      "name": "Wood_Ash_Trunk",
      "support": 15,
      "rotation": 5
    },
    {
      "x": 9,
      "y": 6,
      "z": 0,
      "name": "Wood_Darkwood_Planks"
    },
    {
      "x": 9,
      "y": 3,
      "z": 1,
      "name": "Wood_Darkwood_Planks"
    },
    {
      "x": 9,
      "y": 4,
      "z": 1,
      "name": "Wood_Deadwood_Planks"
    },
    {
      "x": 9,
      "y": 5,
      "z": 1,
      "name": "Wood_Darkwood_Planks"
    },
    {
      "x": 9,
      "y": 6,
      "z": 1,
      "name": "Wood_Ash_Trunk",
      "support": 15,
      "rotation": 5
    },
    {
      "x": 9,
      "y": 5,
      "z": 2,
      "name": "Wood_Darkwood_Planks"
    },
    {
      "x": 9,
      "y": 6,
      "z": 2,
      "name": "Wood_Deadwood_Planks"
    },
    {
      "x": 10,
      "y": 5,
      "z": -9,
      "name": "Wood_Darkwood_Planks"
    },
    {
      "x": 10,
      "y": 6,
      "z": -9,
      "name": "Wood_Deadwood_Planks"
    },
    {
      "x": 10,
      "y": 3,
      "z": -8,
      "name": "Wood_Deadwood_Planks"
    },
    {
      "x": 10,
      "y": 4,
      "z": -8,
      "name": "Wood_Darkwood_Planks"
    },
    {
      "x": 10,
      "y": 5,
      "z": -8,
      "name": "Wood_Ash_Trunk",
      "support": 15,
      "rotation": 5
    },
    {
      "x": 10,
      "y": 8,
      "z": -8,
      "name": "Wood_Darkwood_Planks"
    },
    {
      "x": 10,
      "y": 9,
      "z": -8,
      "name": "Wood_Deadwood_Planks"
    },
    {
      "x": 10,
      "y": 2,
      "z": -7,
      "name": "Wood_Deadwood_Planks"
    },
    {
      "x": 10,
      "y": 3,
      "z": -7,
      "name": "Wood_Deadwood_Planks"
    },
    {
      "x": 10,
      "y": 8,
      "z": -7,
      "name": "Wood_Ash_Trunk",
      "support": 15,
      "rotation": 5
    },
    {
      "x": 10,
      "y": 9,
      "z": -7,
      "name": "Rock_Ice_Icicles"
    },
    {
      "x": 10,
      "y": 1,
      "z": -6,
      "name": "Wood_Deadwood_Planks"
    },
    {
      "x": 10,
      "y": 7,
      "z": -6,
      "name": "Wood_Darkwood_Planks"
    },
    {
      "x": 10,
      "y": 8,
      "z": -6,
      "name": "Wood_Darkwood_Planks"
    },
    {
      "x": 10,
      "y": 1,
      "z": -5,
      "name": "Wood_Darkwood_Planks"
    },
    {
      "x": 10,
      "y": 4,
      "z": -5,
      "name": "Wood_Darkwood_Planks"
    },
    {
      "x": 10,
      "y": 7,
      "z": -5,
      "name": "Wood_Darkwood_Planks"
    },
    {
      "x": 10,
      "y": 1,
      "z": -4,
      "name": "Wood_Deadwood_Planks"
    },
    {
      "x": 10,
      "y": 4,
      "z": -4,
      "name": "Wood_Ash_Trunk",
      "support": 15,
      "rotation": 5
    },
    {
      "x": 10,
      "y": 7,
      "z": -4,
      "name": "Wood_Darkwood_Planks"
    },
    {
      "x": 10,
      "y": 0,
      "z": -3,
      "name": "Wood_Deadwood_Planks"
    },
    {
      "x": 10,
      "y": 1,
      "z": -3,
      "name": "Wood_Deadwood_Planks"
    },
    {
      "x": 10,
      "y": 4,
      "z": -3,
      "name": "Wood_Darkwood_Planks"
    },
    {
      "x": 10,
      "y": 7,
      "z": -3,
      "name": "Wood_Ash_Trunk",
      "support": 15,
      "rotation": 5
    },
    {
      "x": 10,
      "y": 1,
      "z": -2,
      "name": "Wood_Deadwood_Planks"
    },
    {
      "x": 10,
      "y": 3,
      "z": -2,
      "name": "Wood_Darkwood_Planks"
    },
    {
      "x": 10,
      "y": 6,
      "z": -2,
      "name": "Wood_Darkwood_Planks"
    },
    {
      "x": 10,
      "y": 1,
      "z": -1,
      "name": "Wood_Deadwood_Planks"
    },
    {
      "x": 10,
      "y": 3,
      "z": -1,
      "name": "Wood_Darkwood_Planks"
    },
    {
      "x": 10,
      "y": 6,
      "z": -1,
      "name": "Wood_Darkwood_Planks"
    },
    {
      "x": 10,
      "y": 7,
      "z": -1,
      "name": "Rubble_Ice",
      "support": 15
    },
    {
      "x": 10,
      "y": 2,
      "z": 0,
      "name": "Wood_Darkwood_Planks"
    },
    {
      "x": 10,
      "y": 3,
      "z": 0,
      "name": "Wood_Ash_Trunk",
      "support": 15,
      "rotation": 5
    },
    {
      "x": 10,
      "y": 6,
      "z": 0,
      "name": "Wood_Darkwood_Planks"
    },
    {
      "x": 10,
      "y": 3,
      "z": 1,
      "name": "Wood_Darkwood_Planks"
    },
    {
      "x": 10,
      "y": 4,
      "z": 1,
      "name": "Wood_Deadwood_Planks"
    },
    {
      "x": 10,
      "y": 5,
      "z": 1,
      "name": "Furniture_Frozen_Castle_Window"
    },
    {
      "x": 10,
      "y": 6,
      "z": 1,
      "name": "Wood_Ash_Trunk",
      "support": 15,
      "rotation": 5
    },
    {
      "x": 10,
      "y": 7,
      "z": 1,
      "name": "Soil_Snow_Half"
    },
    {
